Workbook
Name date_DIADC: 'Mode opératoire'!#REF!
Name notice_DIADC: 'Mode opératoire'!#REF!
Name notice_ENCHN: 'Mode opératoire'!$B$1:$B$4
Name notice_ICA: 'Mode opératoire'!#REF!

Sheet Mode opératoire
B1: MODE OPERATOIRE
B2: La description d'une position sortante dans un dossier agent, nécessite la MAJ des données portées par les 3 sous-rubriques suivantes : Position statutaire/situation administrative Détachement, affectation ou MAD sortant Compteurs de périodes de positions/situations La spécification métier regroupe au sein d'un évènement unique l'articulation des RG mobilisant des données appartenant à ces deux sous-rubriques. Ainsi, le métier considère que les données associées à ces deux sous rubriques sont mises à jour dans la même transaction. Les positions concernées sont les codes de positions mobilisés dans l'axe1.

Sheet Axe 1 Enchainement des RG
A1: Version | B1: Type de mise à jour | C1: Date de mise à jour | D1: Identifiant Domaine | E1: Libellé du Domaine | F1: Identifiant Sous-domaine | G1: Libellé du Sous-domaine | H1: Identifiant Evénement | I1: Libellé de l'évènement | J1: Libellé condition déclenchement Evènement | K1: Condition déclenchement Evènement | L1: Identifiant type d'évènement | M1: Libellé type d'évènement | N1: Type de mise à jour | O1: Libellé condition déclenchement Type Evènement | P1: Condition déclenchement Type Evènement | Q1: Libellé Population | R1: Codification Population | S1: Typologie de population | T1: Général / Particulier | U1: Passant / Exclu | V1: Date de début | W1: Date de fin | X1: Règles mobilisées | Y1: Identifiant Règle de contrôle intellectuel 1 | Z1: Libellé Règle de contrôle intellectuel 1 | AA1: Identifiant Règle de contrôle intellectuel 2 | AB1: Libellé Règle de contrôle intellectuel 2 | AC1: Identifiant Règle de contrôle intellectuel 3 | AD1: Libellé Règle de contrôle intellectuel 3 | AE1: Identifiant Règle de contrôle intellectuel 4 | AF1: Libellé Règle de contrôle intellectuel 4 | AG1: Identifiant Règle de contrôle intellectuel 5 | AH1: Libellé Règle de contrôle intellectuel 5 | AI1: Identifiant Règle de contrôle intellectuel 6 | AJ1: Libellé Règle de contrôle intellectuel 6 | AK1: Identifiant Règle de contrôle intellectuel 7 | AL1: Libellé Règle de contrôle intellectuel 7 | AM1: Identifiant Règle de contrôle intellectuel 8 | AN1: Libellé Règle de contrôle intellectuel 8 | AO1: Identifiant Règle de contrôle intellectuel 9 | AP1: Libellé Règle de contrôle intellectuel 9 | AQ1: Identifiant Règle de contrôle intellectuel 10 | AR1: Libellé Règle de contrôle intellectuel 10 | AS1: Identifiant Règle de contrôle intellectuel 11 | AT1: Libellé Règle de contrôle intellectuel 11 | AU1: Identifiant Règle de contrôle intellectuel 12 | AV1: Libellé Règle de contrôle intellectuel 12 | AW1: Identifiant Règle de condition 1 | AX1: Libellé Règle de condition 1 | AY1: Identifiant Règle de condition 2 | AZ1: Libellé Règle de condition 2 | BA1: Identifiant Règle de condition 3 | BB1: Libellé Règle de condition 3 | BC1: Identifiant Règle de condition 4 | BD1: Libellé Règle de condition 4 | BE1: Identifiant Règle de condition 5 | BF1: Libellé Règle de condition 5 | BG1: Identifiant Règle de condition 6 | BH1: Libellé Règle de condition 6 | BI1: Identifiant Règle de condition 7 | BJ1: Libellé Règle de condition 7 | BK1: Identifiant Règle de condition 8 | BL1: Libellé Règle de condition 8 | BM1: Identifiant Règle de contrôle 1 | BN1: Libellé Règle de contrôle 1 | BO1: Identifiant Règle de contrôle 2 | BP1: Libellé Règle de contrôle 2 | BQ1: Identifiant Règle de contrôle 3 | BR1: Libellé Règle de contrôle 3 | BS1: Identifiant Règle de contrôle 4 | BT1: Libellé Règle de contrôle 4 | BU1: Identifiant Règle de contrôle 5 | BV1: Libellé Règle de contrôle 5 | BW1: Identifiant Règle de contrôle 6 | BX1: Libellé Règle de contrôle 6 | BY1: Identifiant Règle de contrôle 7 | BZ1: Libellé Règle de contrôle 7 | CA1: Identifiant Règle de contrôle 8 | CB1: Libellé Règle de contrôle 8 | CC1: Identifiant Règle de contrôle 9 | CD1: Libellé Règle de contrôle 9 | CE1: Identifiant Règle de contrôle 10 | CF1: Libellé Règle de contrôle 10 | CG1: Identifiant Règle de contrôle 11 | CH1: Libellé Règle de contrôle 11 | CI1: Identifiant Règle de contrôle 12 | CJ1: Libellé Règle de contrôle 12 | CK1: Identifiant Règle de contrôle 13 | CL1: Libellé Règle de contrôle 13 | CM1: Identifiant Règle de contrôle 14 | CN1: Libellé Règle de contrôle 14 | CO1: Identifiant Règle de contrôle 15 | CP1: Libellé Règle de contrôle 15 | CQ1: Identifiant Règle de contrôle 16 | CR1: Libellé Règle de contrôle 16 | CS1: FIME | CT1: Statut de travail
A2: 21.00.00 | B2: M | C2: 44358.705 | D2: D0004 | E2: Position | F2: S0008 | G2: Détachement sortant | H2: E0101 | I2: Détachement sortant sur demande auprès d'une administration, d'un office ou d'un EP de l'Etat conduisant à pension | J2: Position administrative Saisie égale à 'Détachement sortant sur demande auprès d'une administration ou d'un EP de l'Etat conduisant à pension' ET Indicateur de maintien saisi = Non | K2: A_POS_POSIAD [Saisi] = 'DET01' ET A_POS_SITPAR [Saisi] = Vide ET A_POS_INDMAI [Saisi] = '0' | L2: T0204 | M2: Détachement sortant sur demande auprès d'une administration ou d'un EP de l'Etat conduisant à pension - Demande | N2: Création Modification | O2: Indicateur de renouvellement saisi = Non ET (Indicateur de renouvellement saisi différent d'Indicateur de renouvellement avant saisi OU Indicateur de maintien saisi différent de Indicateur de maintien avant saisi) | P2: A_POS_INDREN [Saisi] = '0' ET (A_POS_INDREN [Saisi] <> A_POS_INDREN [Valeur avant saisie] OU A_POS_INDMAI [Saisi] <> A_POS_INDMAI [Valeur avant saisie]) | Q2: Titulaire ou magistrat | R2: P0001 | S2: T | T2: Général | U2: Passant | V2: 40725 | W2: 43830 | X2: DET_I_002 ET DET_I_005 ET DET_I_007 ET DET_I_004 ET DET_I_006 ET DET_D_006 ET DET_D_406 ET DET_D_510 ET DET_D_910 ET DET_D_007 ET DET_D_407 ET POS_C_100 ET POS_C_004 ET POS_C_005 ET POS_C_007 ET POS_C_010 ET POS_C_012 ET POS_C_022 ET POS_C_037 ET POS_C_111 ET POS_C_431 ET POS_C_434 ET POS_C_435 | Y2: DET_I_002 | Z2: =VLOOKUP(Y2,'Axe 2 Règles de gestion'!$D$2:$F$190,3, FALSE) -> L'agent doit formuler une demande. | AA2: DET_I_005 | AB2: =VLOOKUP(AA2,'Axe 2 Règles de gestion'!$D$2:$F$190,3, FALSE) -> Le silence de l'administration gardé pendant 2 mois à compter de la réception de la demande de l'agent vaut acceptation. | AC2: DET_I_007 | AD2: =VLOOKUP(AC2,'Axe 2 Règles de gestion'!$D$2:$F$190,3, FALSE) -> Le détachement est accordé après avis des commissions administratives paritaires compétentes. | AE2: DET_I_004 | AF2: =VLOOKUP(AE2,'Axe 2 Règles de gestion'!$D$2:$F$190,3, FALSE) -> Suite à accord de l'organisme d'accueil, le refus par l'administration d'origine est possible pour nécessité de service ou suite à un avis d'incompatibilité de la commission de déontologie. | AG2: DET_I_006 | AH2: =VLOOKUP(AG2,'Axe 2 Règles de gestion'!$D$2:$F$190,3, FALSE) -> Un préavis, d'un délai maximal de 3 mois, peut être exigé par l'administration d'origine. | AW2: DET_D_006 | AX2: =VLOOKUP(AW2,'Axe 2 Règles de gestion'!$D$2:$F$190,3, FALSE) -> Un détachement de courte durée ne peut excéder six mois entre la date de début et la date de fin prévisionnelle | AY2: DET_D_406 | AZ2: =VLOOKUP(AY2,'Axe 2 Règles de gestion'!$D$2:$F$190,3, FALSE) -> Un détachement de courte durée ne peut excéder six mois entre la date de début et la date de fin réelle | BA2: DET_D_510 | BB2: =VLOOKUP(BA2,'Axe 2 Règles de gestion'!$D$2:$F$190,3, FALSE) -> Un détachement de courte durée ne peut excéder 1 an entre la date de début et la date de fin prévisionnelle, pour les personnels détachés pour servir dans les collectivités d'outre-mer, la Nouvelle-Calédonie ou à l'étranger. | BC2: DET_D_910 | BD2: =VLOOKUP(BC2,'Axe 2 Règles de gestion'!$D$2:$F$190,3, FALSE) -> Un détachement de courte durée ne peut excéder 1 an entre la date de début et la date de fin réelle, pour les personnels détachés pour servir dans les collectivités d'outre-mer, la Nouvelle-Calédonie ou à l'étranger. | BE2: DET_D_007 | BF2: =VLOOKUP(BE2,'Axe 2 Règles de gestion'!$D$2:$F$190,3, FALSE) -> Chaque période de détachement de longue durée ne peut excéder 5 ans entre la date de début et la date de fin prévisionnelle. | BG2: DET_D_407 | BH2: =VLOOKUP(BG2,'Axe 2 Règles de gestion'!$D$2:$F$190,3, FALSE) -> Chaque période de détachement de longue durée ne peut excéder 5 ans entre la date de début et la date de fin réelle. | BM2: POS_C_100 | BN2: =VLOOKUP(BM2,'Axe 2 Règles de gestion'!$D$2:$F$190,3, FALSE) -> Lors de la demande initiale, l'agent doit être en activité. | BO2: POS_C_004 | BP2: =VLOOKUP(BO2,'Axe 2 Règles de gestion'!$D$2:$F$190,3, FALSE) -> La date de début de position doit être antérieure ou égale à la date de fin prévisionnelle de position. | BQ2: POS_C_005 | BR2: =VLOOKUP(BQ2,'Axe 2 Règles de gestion'!$D$2:$F$190,3, FALSE) -> La date de début de la position doit être postérieure ou égale à la date d'entrée dans la FPE ou dans la carrière militaire. | BS2: POS_C_007 | BT2: =VLOOKUP(BS2,'Axe 2 Règles de gestion'!$D$2:$F$190,3, FALSE) -> La date de fin réelle de la position doit être antérieure à la date limite de départ à la retraite. | BU2: POS_C_010 | BV2: =VLOOKUP(BU2,'Axe 2 Règles de gestion'!$D$2:$F$190,3, FALSE) -> La date de début de position doit être antérieure ou égale à la date de fin réelle de position. | BW2: POS_C_012 | BX2: =VLOOKUP(BW2,'Axe 2 Règles de gestion'!$D$2:$F$190,3, FALSE) -> La date de fin prévisionnelle de la position doit être antérieure à la date limite de départ à la retraite. | BY2: POS_C_022 | BZ2: =VLOOKUP(BY2,'Axe 2 Règles de gestion'!$D$2:$F$190,3, FALSE) -> La date de début de position est à J+1 de la date de fin de position de l'occurrence précédente. | CA2: POS_C_037 | CB2: =VLOOKUP(CA2,'Axe 2 Règles de gestion'!$D$2:$F$190,3, FALSE) -> Les champs "Type d'organisme d'accueil" et "Pays" de l'organisme d'accueil doivent être renseignés. | CC2: POS_C_111 | CD2: =VLOOKUP(CC2,'Axe 2 Règles de gestion'!$D$2:$F$190,3, FALSE) -> La date de fin ou la date de fin prévisionnelle doit être saisie. | CE2: POS_C_431 | CF2: =VLOOKUP(CE2,'Axe 2 Règles de gestion'!$D$2:$F$190,3, FALSE) -> Les champs "Ministère (ou institution de la République) d'accueil", "Corps d'accueil en détachement" et "Grade d'accueil en détachement" ou "Ministère (ou institution de la République) d'accueil", "Emploi fonctionnel d'accueil en détachement" et "Groupe dans un emploi fonctionnel d'accueil" sont renseignés si le "Type d'organisme d'accueil" est valorisé à FPE. | CG2: POS_C_434 | CH2: =VLOOKUP(CG2,'Axe 2 Règles de gestion'!$D$2:$F$190,3, FALSE) -> Le champ "Organisme d'accueil" doit être alimenté si le type d'organisme d'accueil est égal à 'Autre organisme', 'Fonction publique d'un état de l'Union Européenne' ou 'Fonction publique Européenne'. | CI2: POS_C_435 | CJ2: =VLOOKUP(CI2,'Axe 2 Règles de gestion'!$D$2:$F$190,3, FALSE) -> Le champ « Libellé corps/grade/emploi de détachement » est renseigné si le « Type d'organisme d'accueil » n'est pas valorisé à FPE.
A3: 22.00.00 | B3: M | C3: 44362.458 | D3: D0004 | E3: Position | F3: S0008 | G3: Détachement sortant | H3: E0101 | I3: Détachement sortant sur demande auprès d'une administration, d'un office ou d'un EP de l'Etat conduisant à pension | J3: Position administrative Saisie égale à 'Détachement sortant sur demande auprès d'une administration ou d'un EP de l'Etat conduisant à pension' ET Indicateur de maintien saisi = Non | K3: A_POS_POSIAD [Saisi] = 'DET01' ET A_POS_SITPAR [Saisi] = Vide ET A_POS_INDMAI [Saisi] = '0' | L3: T0204 | M3: Détachement sortant sur demande auprès d'une administration ou d'un EP de l'Etat conduisant à pension - Demande | N3: Création Modification | O3: Indicateur de renouvellement saisi = Non ET (Indicateur de renouvellement saisi différent d'Indicateur de renouvellement avant saisi OU Indicateur de maintien saisi différent de Indicateur de maintien avant saisi) | P3: A_POS_INDREN [Saisi] = '0' ET (A_POS_INDREN [Saisi] <> A_POS_INDREN [Valeur avant saisie] OU A_POS_INDMAI [Saisi] <> A_POS_INDMAI [Valeur avant saisie]) | Q3: Titulaire ou magistrat | R3: P0001 | S3: T | T3: Général | U3: Passant | V3: 43831 | W3: 43861 | X3: DET_I_002 ET DET_I_005 ET DET_I_004 ET DET_I_006 ET DET_I_085 ET DET_I_081 ET DET_I_082 ET DET_I_083 ET DET_D_006 ET DET_D_406 ET DET_D_510 ET DET_D_910 ET DET_D_007 ET DET_D_407 ET POS_C_100 ET POS_C_004 ET POS_C_005 ET POS_C_007 ET POS_C_010 ET POS_C_012 ET POS_C_022 ET POS_C_037 ET POS_C_111 ET POS_C_431 ET POS_C_434 ET POS_C_120 ET POS_C_121 ET POS_C_435 | Y3: DET_I_002 | Z3: =VLOOKUP(Y3,'Axe 2 Règles de gestion'!$D$2:$F$190,3, FALSE) -> L'agent doit formuler une demande. | AA3: DET_I_005 | AB3: =VLOOKUP(AA3,'Axe 2 Règles de gestion'!$D$2:$F$190,3, FALSE) -> Le silence de l'administration gardé pendant 2 mois à compter de la réception de la demande de l'agent vaut acceptation. | AC3: DET_I_004 | AD3: =VLOOKUP(AC3,'Axe 2 Règles de gestion'!$D$2:$F$190,3, FALSE) -> Suite à accord de l'organisme d'accueil, le refus par l'administration d'origine est possible pour nécessité de service ou suite à un avis d'incompatibilité de la commission de déontologie. | AE3: DET_I_006 | AF3: =VLOOKUP(AE3,'Axe 2 Règles de gestion'!$D$2:$F$190,3, FALSE) -> Un préavis, d'un délai maximal de 3 mois, peut être exigé par l'administration d'origine. | AG3: DET_I_085 | AH3: =VLOOKUP(AG3,'Axe 2 Règles de gestion'!$D$2:$F$190,3, FALSE) -> L'agent nommé dans un emploi de direction est placé en position de détachement. | AI3: DET_I_081 | AJ3: =VLOOKUP(AI3,'Axe 2 Règles de gestion'!$D$2:$F$190,3, FALSE) -> Le détachement sur un emploi de direction comporte une période probatoire d'une durée maximale de 6 mois. | AK3: DET_I_082 | AL3: =VLOOKUP(AK3,'Axe 2 Règles de gestion'!$D$2:$F$190,3, FALSE) -> Au cours de la période probatoire, l'autorité de recrutement, sur proposition de l'autorité dont relève l'emploi de direction, peut mettre fin au détachement pour tout motif et à tout moment, sans préavis ni indemnité. | AM3: DET_I_083 | AN3: =VLOOKUP(AM3,'Axe 2 Règles de gestion'!$D$2:$F$190,3, FALSE) -> Cette décision de fin du détachement pendant la période probatoire ne peut intervenir qu'à l'issue d'un entretien préalable et doit être notifiée à l'agent sur emploi de direction. | AW3: DET_D_006 | AX3: =VLOOKUP(AW3,'Axe 2 Règles de gestion'!$D$2:$F$190,3, FALSE) -> Un détachement de courte durée ne peut excéder six mois entre la date de début et la date de fin prévisionnelle | AY3: DET_D_406 | AZ3: =VLOOKUP(AY3,'Axe 2 Règles de gestion'!$D$2:$F$190,3, FALSE) -> Un détachement de courte durée ne peut excéder six mois entre la date de début et la date de fin réelle | BA3: DET_D_510 | BB3: =VLOOKUP(BA3,'Axe 2 Règles de gestion'!$D$2:$F$190,3, FALSE) -> Un détachement de courte durée ne peut excéder 1 an entre la date de début et la date de fin prévisionnelle, pour les personnels détachés pour servir dans les collectivités d'outre-mer, la Nouvelle-Calédonie ou à l'étranger. | BC3: DET_D_910 | BD3: =VLOOKUP(BC3,'Axe 2 Règles de gestion'!$D$2:$F$190,3, FALSE) -> Un détachement de courte durée ne peut excéder 1 an entre la date de début et la date de fin réelle, pour les personnels détachés pour servir dans les collectivités d'outre-mer, la Nouvelle-Calédonie ou à l'étranger. | BE3: DET_D_007 | BF3: =VLOOKUP(BE3,'Axe 2 Règles de gestion'!$D$2:$F$190,3, FALSE) -> Chaque période de détachement de longue durée ne peut excéder 5 ans entre la date de début et la date de fin prévisionnelle. | BG3: DET_D_407 | BH3: =VLOOKUP(BG3,'Axe 2 Règles de gestion'!$D$2:$F$190,3, FALSE) -> Chaque période de détachement de longue durée ne peut excéder 5 ans entre la date de début et la date de fin réelle. | BM3: POS_C_100 | BN3: =VLOOKUP(BM3,'Axe 2 Règles de gestion'!$D$2:$F$190,3, FALSE) -> Lors de la demande initiale, l'agent doit être en activité. | BO3: POS_C_004 | BP3: =VLOOKUP(BO3,'Axe 2 Règles de gestion'!$D$2:$F$190,3, FALSE) -> La date de début de position doit être antérieure ou égale à la date de fin prévisionnelle de position. | BQ3: POS_C_005 | BR3: =VLOOKUP(BQ3,'Axe 2 Règles de gestion'!$D$2:$F$190,3, FALSE) -> La date de début de la position doit être postérieure ou égale à la date d'entrée dans la FPE ou dans la carrière militaire. | BS3: POS_C_007 | BT3: =VLOOKUP(BS3,'Axe 2 Règles de gestion'!$D$2:$F$190,3, FALSE) -> La date de fin réelle de la position doit être antérieure à la date limite de départ à la retraite. | BU3: POS_C_010 | BV3: =VLOOKUP(BU3,'Axe 2 Règles de gestion'!$D$2:$F$190,3, FALSE) -> La date de début de position doit être antérieure ou égale à la date de fin réelle de position. | BW3: POS_C_012 | BX3: =VLOOKUP(BW3,'Axe 2 Règles de gestion'!$D$2:$F$190,3, FALSE) -> La date de fin prévisionnelle de la position doit être antérieure à la date limite de départ à la retraite. | BY3: POS_C_022 | BZ3: =VLOOKUP(BY3,'Axe 2 Règles de gestion'!$D$2:$F$190,3, FALSE) -> La date de début de position est à J+1 de la date de fin de position de l'occurrence précédente. | CA3: POS_C_037 | CB3: =VLOOKUP(CA3,'Axe 2 Règles de gestion'!$D$2:$F$190,3, FALSE) -> Les champs "Type d'organisme d'accueil" et "Pays" de l'organisme d'accueil doivent être renseignés. | CC3: POS_C_111 | CD3: =VLOOKUP(CC3,'Axe 2 Règles de gestion'!$D$2:$F$190,3, FALSE) -> La date de fin ou la date de fin prévisionnelle doit être saisie. | CE3: POS_C_431 | CF3: =VLOOKUP(CE3,'Axe 2 Règles de gestion'!$D$2:$F$190,3, FALSE) -> Les champs "Ministère (ou institution de la République) d'accueil", "Corps d'accueil en détachement" et "Grade d'accueil en détachement" ou "Ministère (ou institution de la République) d'accueil", "Emploi fonctionnel d'accueil en détachement" et "Groupe dans un emploi fonctionnel d'accueil" sont renseignés si le "Type d'organisme d'accueil" est valorisé à FPE. | CG3: POS_C_434 | CH3: =VLOOKUP(CG3,'Axe 2 Règles de gestion'!$D$2:$F$190,3, FALSE) -> Le champ "Organisme d'accueil" doit être alimenté si le type d'organisme d'accueil est égal à 'Autre organisme', 'Fonction publique d'un état de l'Union Européenne' ou 'Fonction publique Européenne'. | CI3: POS_C_120 | CJ3: =VLOOKUP(CI3,'Axe 2 Règles de gestion'!$D$2:$F$190,3, FALSE) -> La saisie d'une occurrence de congés/absences est interdite (date de fin réelle) | CK3: POS_C_121 | CL3: =VLOOKUP(CK3,'Axe 2 Règles de gestion'!$D$2:$F$190,3, FALSE) -> La saisie d'une occurrence de congés/absences est interdite (date de fin prévisionnelle) | CM3: POS_C_435 | CN3: =VLOOKUP(CM3,'Axe 2 Règles de gestion'!$D$2:$F$190,3, FALSE) -> Le champ « Libellé corps/grade/emploi de détachement » est renseigné si le « Type d'organisme d'accueil » n'est pas valorisé à FPE.
A4: 25.00.00 | B4: M | C4: 45807.419 | D4: D0004 | E4: Position | F4: S0008 | G4: Détachement sortant | H4: E0101 | I4: Détachement sortant sur demande auprès d'une administration, d'un office ou d'un EP de l'Etat conduisant à pension | J4: Position administrative Saisie égale à 'Détachement sortant sur demande auprès d'une administration ou d'un EP de l'Etat conduisant à pension' ET Indicateur de maintien saisi = Non | K4: A_POS_POSIAD [Saisi] = 'DET01' ET A_POS_SITPAR [Saisi] = Vide ET A_POS_INDMAI [Saisi] = '0' | L4: T0204 | M4: Détachement sortant sur demande auprès d'une administration ou d'un EP de l'Etat conduisant à pension - Demande | N4: Création Modification | O4: Indicateur de renouvellement saisi = Non ET (Indicateur de renouvellement saisi différent d'Indicateur de renouvellement avant saisi OU Indicateur de maintien saisi différent de Indicateur de maintien avant saisi) | P4: A_POS_INDREN [Saisi] = '0' ET (A_POS_INDREN [Saisi] <> A_POS_INDREN [Valeur avant saisie] OU A_POS_INDMAI [Saisi] <> A_POS_INDMAI [Valeur avant saisie]) | Q4: Titulaire ou magistrat | R4: P0001 | S4: T | T4: Général | U4: Passant | V4: 43862 | X4: DET_I_002 ET DET_I_005 ET DET_I_436 ET DET_I_006 ET DET_I_085 ET DET_I_081 ET DET_I_082 ET DET_I_083 ET DET_I_200 ET DET_I_201 ET DET_I_202 ET DET_I_203 ET DET_D_006 ET DET_D_406 ET DET_D_510 ET DET_D_910 ET DET_D_007 ET DET_D_407 ET POS_C_100 ET POS_C_004 ET POS_C_005 ET POS_C_007 ET POS_C_010 ET POS_C_012 ET POS_C_022 ET POS_C_037 ET POS_C_111 ET POS_C_431 ET POS_C_434 ET POS_C_120 ET POS_C_121 ET POS_C_435 | Y4: DET_I_002 | Z4: =VLOOKUP(Y4,'Axe 2 Règles de gestion'!$D$2:$F$190,3, FALSE) -> L'agent doit formuler une demande. | AA4: DET_I_005 | AB4: =VLOOKUP(AA4,'Axe 2 Règles de gestion'!$D$2:$F$190,3, FALSE) -> Le silence de l'administration gardé pendant 2 mois à compter de la réception de la demande de l'agent vaut acceptation. | AC4: DET_I_436 | AD4: =VLOOKUP(AC4,'Axe 2 Règles de gestion'!$D$2:$F$190,3, FALSE) -> Suite à accord de l'organisme d'accueil, le refus par l'administration d'origine est possible pour nécessité de service ou suite à un avis rendu par la Haute Autorité pour la transparence de la vie publique. | AE4: DET_I_006 | AF4: =VLOOKUP(AE4,'Axe 2 Règles de gestion'!$D$2:$F$190,3, FALSE) -> Un préavis, d'un délai maximal de 3 mois, peut être exigé par l'administration d'origine. | AG4: DET_I_085 | AH4: =VLOOKUP(AG4,'Axe 2 Règles de gestion'!$D$2:$F$190,3, FALSE) -> L'agent nommé dans un emploi de direction est placé en position de détachement. | AI4: DET_I_081 | AJ4: =VLOOKUP(AI4,'Axe 2 Règles de gestion'!$D$2:$F$190,3, FALSE) -> Le détachement sur un emploi de direction comporte une période probatoire d'une durée maximale de 6 mois. | AK4: DET_I_082 | AL4: =VLOOKUP(AK4,'Axe 2 Règles de gestion'!$D$2:$F$190,3, FALSE) -> Au cours de la période probatoire, l'autorité de recrutement, sur proposition de l'autorité dont relève l'emploi de direction, peut mettre fin au détachement pour tout motif et à tout moment, sans préavis ni indemnité. | AM4: DET_I_083 | AN4: =VLOOKUP(AM4,'Axe 2 Règles de gestion'!$D$2:$F$190,3, FALSE) -> Cette décision de fin du détachement pendant la période probatoire ne peut intervenir qu'à l'issue d'un entretien préalable et doit être notifiée à l'agent sur emploi de direction. | AO4: DET_I_200 | AP4: =VLOOKUP(AO4,'Axe 2 Règles de gestion'!$D$2:$F$190,3, FALSE) -> L'agent peut être détaché dans un corps ou un cadre d'emplois de même catégorie et de niveau comparable à celui de son corps ou cadre d'emplois d'origine. | AQ4: DET_I_201 | AR4: =VLOOKUP(AQ4,'Axe 2 Règles de gestion'!$D$2:$F$190,3, FALSE) -> Toutefois, l'agent dont au moins l'un des grades d'avancement de son corps ou cadre d'emplois est accessible par la voie d'un concours de recrutement peut être détaché dans un corps ou cadre d'emplois de niveau différent. | AS4: DET_I_202 | AT4: =VLOOKUP(AS4,'Axe 2 Règles de gestion'!$D$2:$F$190,3, FALSE) -> Lorsque le corps ou cadre d'emplois d'origine ou le corps ou cadre d'emplois d'accueil ne relève pas d'une catégorie, le détachement s'effectue entre corps et cadres d'emplois de niveau comparable. | AU4: DET_I_203 | AV4: =VLOOKUP(AU4,'Axe 2 Règles de gestion'!$D$2:$F$190,3, FALSE) -> L'agent doit détenir le titre ou le diplôme requis pour l'exercice des fonctions du corps d'accueil. | AW4: DET_D_006 | AX4: =VLOOKUP(AW4,'Axe 2 Règles de gestion'!$D$2:$F$190,3, FALSE) -> Un détachement de courte durée ne peut excéder six mois entre la date de début et la date de fin prévisionnelle | AY4: DET_D_406 | AZ4: =VLOOKUP(AY4,'Axe 2 Règles de gestion'!$D$2:$F$190,3, FALSE) -> Un détachement de courte durée ne peut excéder six mois entre la date de début et la date de fin réelle | BA4: DET_D_510 | BB4: =VLOOKUP(BA4,'Axe 2 Règles de gestion'!$D$2:$F$190,3, FALSE) -> Un détachement de courte durée ne peut excéder 1 an entre la date de début et la date de fin prévisionnelle, pour les personnels détachés pour servir dans les collectivités d'outre-mer, la Nouvelle-Calédonie ou à l'étranger. | BC4: DET_D_910 | BD4: =VLOOKUP(BC4,'Axe 2 Règles de gestion'!$D$2:$F$190,3, FALSE) -> Un détachement de courte durée ne peut excéder 1 an entre la date de début et la date de fin réelle, pour les personnels détachés pour servir dans les collectivités d'outre-mer, la Nouvelle-Calédonie ou à l'étranger. | BE4: DET_D_007 | BF4: =VLOOKUP(BE4,'Axe 2 Règles de gestion'!$D$2:$F$190,3, FALSE) -> Chaque période de détachement de longue durée ne peut excéder 5 ans entre la date de début et la date de fin prévisionnelle. | BG4: DET_D_407 | BH4: =VLOOKUP(BG4,'Axe 2 Règles de gestion'!$D$2:$F$190,3, FALSE) -> Chaque période de détachement de longue durée ne peut excéder 5 ans entre la date de début et la date de fin réelle. | BM4: POS_C_100 | BN4: =VLOOKUP(BM4,'Axe 2 Règles de gestion'!$D$2:$F$190,3, FALSE) -> Lors de la demande initiale, l'agent doit être en activité. | BO4: POS_C_004 | BP4: =VLOOKUP(BO4,'Axe 2 Règles de gestion'!$D$2:$F$190,3, FALSE) -> La date de début de position doit être antérieure ou égale à la date de fin prévisionnelle de position. | BQ4: POS_C_005 | BR4: =VLOOKUP(BQ4,'Axe 2 Règles de gestion'!$D$2:$F$190,3, FALSE) -> La date de début de la position doit être postérieure ou égale à la date d'entrée dans la FPE ou dans la carrière militaire. | BS4: POS_C_007 | BT4: =VLOOKUP(BS4,'Axe 2 Règles de gestion'!$D$2:$F$190,3, FALSE) -> La date de fin réelle de la position doit être antérieure à la date limite de départ à la retraite. | BU4: POS_C_010 | BV4: =VLOOKUP(BU4,'Axe 2 Règles de gestion'!$D$2:$F$190,3, FALSE) -> La date de début de position doit être antérieure ou égale à la date de fin réelle de position. | BW4: POS_C_012 | BX4: =VLOOKUP(BW4,'Axe 2 Règles de gestion'!$D$2:$F$190,3, FALSE) -> La date de fin prévisionnelle de la position doit être antérieure à la date limite de départ à la retraite. | BY4: POS_C_022 | BZ4: =VLOOKUP(BY4,'Axe 2 Règles de gestion'!$D$2:$F$190,3, FALSE) -> La date de début de position est à J+1 de la date de fin de position de l'occurrence précédente. | CA4: POS_C_037 | CB4: =VLOOKUP(CA4,'Axe 2 Règles de gestion'!$D$2:$F$190,3, FALSE) -> Les champs "Type d'organisme d'accueil" et "Pays" de l'organisme d'accueil doivent être renseignés. | CC4: POS_C_111 | CD4: =VLOOKUP(CC4,'Axe 2 Règles de gestion'!$D$2:$F$190,3, FALSE) -> La date de fin ou la date de fin prévisionnelle doit être saisie. | CE4: POS_C_431 | CF4: =VLOOKUP(CE4,'Axe 2 Règles de gestion'!$D$2:$F$190,3, FALSE) -> Les champs "Ministère (ou institution de la République) d'accueil", "Corps d'accueil en détachement" et "Grade d'accueil en détachement" ou "Ministère (ou institution de la République) d'accueil", "Emploi fonctionnel d'accueil en détachement" et "Groupe dans un emploi fonctionnel d'accueil" sont renseignés si le "Type d'organisme d'accueil" est valorisé à FPE. | CG4: POS_C_434 | CH4: =VLOOKUP(CG4,'Axe 2 Règles de gestion'!$D$2:$F$190,3, FALSE) -> Le champ "Organisme d'accueil" doit être alimenté si le type d'organisme d'accueil est égal à 'Autre organisme', 'Fonction publique d'un état de l'Union Européenne' ou 'Fonction publique Européenne'. | CI4: POS_C_120 | CJ4: =VLOOKUP(CI4,'Axe 2 Règles de gestion'!$D$2:$F$190,3, FALSE) -> La saisie d'une occurrence de congés/absences est interdite (date de fin réelle) | CK4: POS_C_121 | CL4: =VLOOKUP(CK4,'Axe 2 Règles de gestion'!$D$2:$F$190,3, FALSE) -> La saisie d'une occurrence de congés/absences est interdite (date de fin prévisionnelle) | CM4: POS_C_435 | CN4: =VLOOKUP(CM4,'Axe 2 Règles de gestion'!$D$2:$F$190,3, FALSE) -> Le champ « Libellé corps/grade/emploi de détachement » est renseigné si le « Type d'organisme d'accueil » n'est pas valorisé à FPE.
A5: 21.00.00 | B5: M | C5: 44358.708 | D5: D0004 | E5: Position | F5: S0008 | G5: Détachement sortant | H5: E0101 | I5: Détachement sortant sur demande auprès d'une administration, d'un office ou d'un EP de l'Etat conduisant à pension | J5: Position administrative Saisie égale à 'Détachement sortant sur demande auprès d'une administration ou d'un EP de l'Etat conduisant à pension' ET Indicateur de maintien saisi = Non | K5: A_POS_POSIAD [Saisi] = 'DET01' ET A_POS_SITPAR [Saisi] = Vide ET A_POS_INDMAI [Saisi] = '0' | L5: T0205 | M5: Détachement sortant sur demande auprès d'une administration ou d'un EP de l'Etat conduisant à pension - Renouvellement | N5: Création Modification | O5: Indicateur de renouvellement saisi = Oui ET (Indicateur de renouvellement saisi différent d'Indicateur de renouvellement avant saisi OU Indicateur de maintien saisi différent de Indicateur de maintien avant saisi) | P5: A_POS_INDREN [Saisi] = '1' ET (A_POS_INDREN [Saisi] <> A_POS_INDREN [Valeur avant saisie] OU A_POS_INDMAI [Saisi] <> A_POS_INDMAI [Valeur avant saisie]) | Q5: Titulaire ou magistrat | R5: P0001 | S5: T | T5: Général | U5: Passant | V5: 40725 | W5: 43830 | X5: DET_I_009 ET DET_I_007 ET DET_I_011 ET DET_D_007 ET DET_D_407 ET DET_D_504 ET POS_C_004 ET POS_C_005 ET POS_C_007 ET POS_C_010 ET POS_C_012 ET POS_C_022 ET POS_C_037 ET POS_C_111 ET POS_C_431 ET POS_C_434 ET POS_C_435 | Y5: DET_I_009 | Z5: =VLOOKUP(Y5,'Axe 2 Règles de gestion'!$D$2:$F$190,3, FALSE) -> L'agent doit formuler une demande de renouvellement à son administration d'origine 3 mois au moins avant l'expiration de la période de détachement de longue durée. | AA5: DET_I_007 | AB5: =VLOOKUP(AA5,'Axe 2 Règles de gestion'!$D$2:$F$190,3, FALSE) -> Le détachement est accordé après avis des commissions administratives paritaires compétentes. | AC5: DET_I_011 | AD5: =VLOOKUP(AC5,'Axe 2 Règles de gestion'!$D$2:$F$190,3, FALSE) -> L'organisme d'accueil adresse sa décision à l'agent et à l'administration d'origine 2 mois au moins avant l'expiration de la période de détachement. | AW5: DET_D_007 | AX5: =VLOOKUP(AW5,'Axe 2 Règles de gestion'!$D$2:$F$190,3, FALSE) -> Chaque période de détachement de longue durée ne peut excéder 5 ans entre la date de début et la date de fin prévisionnelle. | AY5: DET_D_407 | AZ5: =VLOOKUP(AY5,'Axe 2 Règles de gestion'!$D$2:$F$190,3, FALSE) -> Chaque période de détachement de longue durée ne peut excéder 5 ans entre la date de début et la date de fin réelle. | BA5: DET_D_504 | BB5: =VLOOKUP(BA5,'Axe 2 Règles de gestion'!$D$2:$F$190,3, FALSE) -> Le renouvellement d'un détachement de courte durée est interdit. | BM5: POS_C_004 | BN5: =VLOOKUP(BM5,'Axe 2 Règles de gestion'!$D$2:$F$190,3, FALSE) -> La date de début de position doit être antérieure ou égale à la date de fin prévisionnelle de position. | BO5: POS_C_005 | BP5: =VLOOKUP(BO5,'Axe 2 Règles de gestion'!$D$2:$F$190,3, FALSE) -> La date de début de la position doit être postérieure ou égale à la date d'entrée dans la FPE ou dans la carrière militaire. | BQ5: POS_C_007 | BR5: =VLOOKUP(BQ5,'Axe 2 Règles de gestion'!$D$2:$F$190,3, FALSE) -> La date de fin réelle de la position doit être antérieure à la date limite de départ à la retraite. | BS5: POS_C_010 | BT5: =VLOOKUP(BS5,'Axe 2 Règles de gestion'!$D$2:$F$190,3, FALSE) -> La date de début de position doit être antérieure ou égale à la date de fin réelle de position. | BU5: POS_C_012 | BV5: =VLOOKUP(BU5,'Axe 2 Règles de gestion'!$D$2:$F$190,3, FALSE) -> La date de fin prévisionnelle de la position doit être antérieure à la date limite de départ à la retraite. | BW5: POS_C_022 | BX5: =VLOOKUP(BW5,'Axe 2 Règles de gestion'!$D$2:$F$190,3, FALSE) -> La date de début de position est à J+1 de la date de fin de position de l'occurrence précédente. | BY5: POS_C_037 | BZ5: =VLOOKUP(BY5,'Axe 2 Règles de gestion'!$D$2:$F$190,3, FALSE) -> Les champs "Type d'organisme d'accueil" et "Pays" de l'organisme d'accueil doivent être renseignés. | CA5: POS_C_111 | CB5: =VLOOKUP(CA5,'Axe 2 Règles de gestion'!$D$2:$F$190,3, FALSE) -> La date de fin ou la date de fin prévisionnelle doit être saisie. | CC5: POS_C_431 | CD5: =VLOOKUP(CC5,'Axe 2 Règles de gestion'!$D$2:$F$190,3, FALSE) -> Les champs "Ministère (ou institution de la République) d'accueil", "Corps d'accueil en détachement" et "Grade d'accueil en détachement" ou "Ministère (ou institution de la République) d'accueil", "Emploi fonctionnel d'accueil en détachement" et "Groupe dans un emploi fonctionnel d'accueil" sont renseignés si le "Type d'organisme d'accueil" est valorisé à FPE. | CE5: POS_C_434 | CF5: =VLOOKUP(CE5,'Axe 2 Règles de gestion'!$D$2:$F$190,3, FALSE) -> Le champ "Organisme d'accueil" doit être alimenté si le type d'organisme d'accueil est égal à 'Autre organisme', 'Fonction publique d'un état de l'Union Européenne' ou 'Fonction publique Européenne'. | CG5: POS_C_435 | CH5: =VLOOKUP(CG5,'Axe 2 Règles de gestion'!$D$2:$F$190,3, FALSE) -> Le champ « Libellé corps/grade/emploi de détachement » est renseigné si le « Type d'organisme d'accueil » n'est pas valorisé à FPE.
A6: 21.00.00 | B6: M | C6: 44362.46 | D6: D0004 | E6: Position | F6: S0008 | G6: Détachement sortant | H6: E0101 | I6: Détachement sortant sur demande auprès d'une administration, d'un office ou d'un EP de l'Etat conduisant à pension | J6: Position administrative Saisie égale à 'Détachement sortant sur demande auprès d'une administration ou d'un EP de l'Etat conduisant à pension' ET Indicateur de maintien saisi = Non | K6: A_POS_POSIAD [Saisi] = 'DET01' ET A_POS_SITPAR [Saisi] = Vide ET A_POS_INDMAI [Saisi] = '0' | L6: T0205 | M6: Détachement sortant sur demande auprès d'une administration ou d'un EP de l'Etat conduisant à pension - Renouvellement | N6: Création Modification | O6: Indicateur de renouvellement saisi = Oui ET (Indicateur de renouvellement saisi différent d'Indicateur de renouvellement avant saisi OU Indicateur de maintien saisi différent de Indicateur de maintien avant saisi) | P6: A_POS_INDREN [Saisi] = '1' ET (A_POS_INDREN [Saisi] <> A_POS_INDREN [Valeur avant saisie] OU A_POS_INDMAI [Saisi] <> A_POS_INDMAI [Valeur avant saisie]) | Q6: Titulaire ou magistrat | R6: P0001 | S6: T | T6: Général | U6: Passant | V6: 43831 | X6: DET_I_009 ET DET_I_011 ET DET_I_079 ET DET_I_080 ET DET_I_084 ET DET_D_007 ET DET_D_407 ET DET_D_504 ET POS_C_004 ET POS_C_005 ET POS_C_007 ET POS_C_010 ET POS_C_012 ET POS_C_022 ET POS_C_037 ET POS_C_111 ET POS_C_431 ET POS_C_434 ET POS_C_120 ET POS_C_121 ET POS_C_435 | Y6: DET_I_009 | Z6: =VLOOKUP(Y6,'Axe 2 Règles de gestion'!$D$2:$F$190,3, FALSE) -> L'agent doit formuler une demande de renouvellement à son administration d'origine 3 mois au moins avant l'expiration de la période de détachement de longue durée. | AA6: DET_I_011 | AB6: =VLOOKUP(AA6,'Axe 2 Règles de gestion'!$D$2:$F$190,3, FALSE) -> L'organisme d'accueil adresse sa décision à l'agent et à l'administration d'origine 2 mois au moins avant l'expiration de la période de détachement. | AC6: DET_I_079 | AD6: =VLOOKUP(AC6,'Axe 2 Règles de gestion'!$D$2:$F$190,3, FALSE) -> L'agent peut demander à être reconduit dans ses fonctions 3 mois au moins avant le terme de son détachement sur un emploi de direction. | AE6: DET_I_080 | AF6: =VLOOKUP(AE6,'Axe 2 Règles de gestion'!$D$2:$F$190,3, FALSE) -> Au moins 2 mois avant le terme de son détachement, l'autorité dont relève l'emploi de direction notifie sa décision à l'agent. | AG6: DET_I_084 | AH6: =VLOOKUP(AG6,'Axe 2 Règles de gestion'!$D$2:$F$190,3, FALSE) -> La période probatoire ne s'applique pas en cas de reconduction de l'agent dans le même emploi de direction. | AW6: DET_D_007 | AX6: =VLOOKUP(AW6,'Axe 2 Règles de gestion'!$D$2:$F$190,3, FALSE) -> Chaque période de détachement de longue durée ne peut excéder 5 ans entre la date de début et la date de fin prévisionnelle. | AY6: DET_D_407 | AZ6: =VLOOKUP(AY6,'Axe 2 Règles de gestion'!$D$2:$F$190,3, FALSE) -> Chaque période de détachement de longue durée ne peut excéder 5 ans entre la date de début et la date de fin réelle. | BA6: DET_D_504 | BB6: =VLOOKUP(BA6,'Axe 2 Règles de gestion'!$D$2:$F$190,3, FALSE) -> Le renouvellement d'un détachement de courte durée est interdit. | BM6: POS_C_004 | BN6: =VLOOKUP(BM6,'Axe 2 Règles de gestion'!$D$2:$F$190,3, FALSE) -> La date de début de position doit être antérieure ou égale à la date de fin prévisionnelle de position. | BO6: POS_C_005 | BP6: =VLOOKUP(BO6,'Axe 2 Règles de gestion'!$D$2:$F$190,3, FALSE) -> La date de début de la position doit être postérieure ou égale à la date d'entrée dans la FPE ou dans la carrière militaire. | BQ6: POS_C_007 | BR6: =VLOOKUP(BQ6,'Axe 2 Règles de gestion'!$D$2:$F$190,3, FALSE) -> La date de fin réelle de la position doit être antérieure à la date limite de départ à la retraite. | BS6: POS_C_010 | BT6: =VLOOKUP(BS6,'Axe 2 Règles de gestion'!$D$2:$F$190,3, FALSE) -> La date de début de position doit être antérieure ou égale à la date de fin réelle de position. | BU6: POS_C_012 | BV6: =VLOOKUP(BU6,'Axe 2 Règles de gestion'!$D$2:$F$190,3, FALSE) -> La date de fin prévisionnelle de la position doit être antérieure à la date limite de départ à la retraite. | BW6: POS_C_022 | BX6: =VLOOKUP(BW6,'Axe 2 Règles de gestion'!$D$2:$F$190,3, FALSE) -> La date de début de position est à J+1 de la date de fin de position de l'occurrence précédente. | BY6: POS_C_037 | BZ6: =VLOOKUP(BY6,'Axe 2 Règles de gestion'!$D$2:$F$190,3, FALSE) -> Les champs "Type d'organisme d'accueil" et "Pays" de l'organisme d'accueil doivent être renseignés. | CA6: POS_C_111 | CB6: =VLOOKUP(CA6,'Axe 2 Règles de gestion'!$D$2:$F$190,3, FALSE) -> La date de fin ou la date de fin prévisionnelle doit être saisie. | CC6: POS_C_431 | CD6: =VLOOKUP(CC6,'Axe 2 Règles de gestion'!$D$2:$F$190,3, FALSE) -> Les champs "Ministère (ou institution de la République) d'accueil", "Corps d'accueil en détachement" et "Grade d'accueil en détachement" ou "Ministère (ou institution de la République) d'accueil", "Emploi fonctionnel d'accueil en détachement" et "Groupe dans un emploi fonctionnel d'accueil" sont renseignés si le "Type d'organisme d'accueil" est valorisé à FPE. | CE6: POS_C_434 | CF6: =VLOOKUP(CE6,'Axe 2 Règles de gestion'!$D$2:$F$190,3, FALSE) -> Le champ "Organisme d'accueil" doit être alimenté si le type d'organisme d'accueil est égal à 'Autre organisme', 'Fonction publique d'un état de l'Union Européenne' ou 'Fonction publique Européenne'. | CG6: POS_C_120 | CH6: =VLOOKUP(CG6,'Axe 2 Règles de gestion'!$D$2:$F$190,3, FALSE) -> La saisie d'une occurrence de congés/absences est interdite (date de fin réelle) | CI6: POS_C_121 | CJ6: =VLOOKUP(CI6,'Axe 2 Règles de gestion'!$D$2:$F$190,3, FALSE) -> La saisie d'une occurrence de congés/absences est interdite (date de fin prévisionnelle) | CK6: POS_C_435 | CL6: =VLOOKUP(CK6,'Axe 2 Règles de gestion'!$D$2:$F$190,3, FALSE) -> Le champ « Libellé corps/grade/emploi de détachement » est renseigné si le « Type d'organisme d'accueil » n'est pas valorisé à FPE.
A7: 21.00.00 | B7: M | C7: 44362.463 | D7: D0004 | E7: Position | F7: S0008 | G7: Détachement sortant | H7: E0101 | I7: Détachement sortant sur demande auprès d'une administration, d'un office ou d'un EP de l'Etat conduisant à pension | J7: Position administrative Saisie égale à 'Détachement sortant sur demande auprès d'une administration ou d'un EP de l'Etat conduisant à pension' ET Indicateur de maintien saisi = Non | K7: A_POS_POSIAD [Saisi] = 'DET01' ET A_POS_SITPAR [Saisi] = Vide ET A_POS_INDMAI [Saisi] = '0' | L7: T0206 | M7: Détachement sortant sur demande auprès d'une administration ou d'un EP de l'Etat conduisant à pension - Réintégration | N7: Modification | O7: Indicateur de renouvellement saisi identique à Indicateur de renouvellement avant saisi ET Indicateur de maintien saisi identique à Indicateur de maintien avant saisi | P7: A_POS_INDREN [Saisi] = A_POS_INDREN [Valeur avant saisie] ET A_POS_INDMAI [Saisi] = A_POS_INDMAI [Valeur avant saisie] | Q7: Titulaire ou magistrat | R7: P0001 | S7: T | T7: Général | U7: Passant | V7: 40725 | X7: DET_I_044 ET DET_I_046 ET DET_I_042 ET DET_I_038 ET DET_I_040 ET DET_I_039 ET DET_D_006 ET DET_D_406 ET DET_D_510 ET DET_D_910 ET DET_D_007 ET DET_D_407 ET POS_C_004 ET POS_C_007 ET POS_C_010 ET POS_C_012 ET POS_C_037 ET POS_C_111 ET POS_C_431 ET POS_C_434 ET POS_C_120 ET POS_C_121 ET POS_C_435 | Y7: DET_I_044 | Z7: =VLOOKUP(Y7,'Axe 2 Règles de gestion'!$D$2:$F$190,3, FALSE) -> En cas de réintégration anticipée à l'initiative de l'agent, si l'administration d'origine ne peut pas réintégrer l'agent immédiatement, l'agent est placé en disponibilité jusqu'à ce qu'il soit réintégré à l'une des 3 premières vacances dans son grade. | AA7: DET_I_046 | AB7: =VLOOKUP(AA7,'Axe 2 Règles de gestion'!$D$2:$F$190,3, FALSE) -> En cas de réintégration anticipée à l'initiative de l'agent, s'il refuse successivement 3 postes, il peut être licencié après avis de la commission administrative paritaire. Il est maintenu en disponibilité entre chaque proposition. | AC7: DET_I_042 | AD7: =VLOOKUP(AC7,'Axe 2 Règles de gestion'!$D$2:$F$190,3, FALSE) -> En cas de réintégration anticipée à l'initiative de l'organisme d'accueil, si l'administration d'origine ne peut pas réintégrer l'agent immédiatement, il reste en détachement jusqu'à ce qu'il soit réintégré à la première vacance. | AE7: DET_I_038 | AF7: =VLOOKUP(AE7,'Axe 2 Règles de gestion'!$D$2:$F$190,3, FALSE) -> L'agent doit adresser une demande de réintégration à l'administration d'origine 3 mois au moins avant l'expiration de la période de détachement de longue durée. | AG7: DET_I_040 | AH7: =VLOOKUP(AG7,'Axe 2 Règles de gestion'!$D$2:$F$190,3, FALSE) -> En l'absence de poste vacant, l'agent est affecté dans un emploi correspondant à son grade. | AI7: DET_I_039 | AJ7: =VLOOKUP(AI7,'Axe 2 Règles de gestion'!$D$2:$F$190,3, FALSE) -> Si l'agent n'adresse pas sa demande dans les délais, il est obligatoirement réintégré à la première vacance dans son corps d'origine et affecté à un emploi correspondant à son grade. | AW7: DET_D_006 | AX7: =VLOOKUP(AW7,'Axe 2 Règles de gestion'!$D$2:$F$190,3, FALSE) -> Un détachement de courte durée ne peut excéder six mois entre la date de début et la date de fin prévisionnelle | AY7: DET_D_406 | AZ7: =VLOOKUP(AY7,'Axe 2 Règles de gestion'!$D$2:$F$190,3, FALSE) -> Un détachement de courte durée ne peut excéder six mois entre la date de début et la date de fin réelle | BA7: DET_D_510 | BB7: =VLOOKUP(BA7,'Axe 2 Règles de gestion'!$D$2:$F$190,3, FALSE) -> Un détachement de courte durée ne peut excéder 1 an entre la date de début et la date de fin prévisionnelle, pour les personnels détachés pour servir dans les collectivités d'outre-mer, la Nouvelle-Calédonie ou à l'étranger. | BC7: DET_D_910 | BD7: =VLOOKUP(BC7,'Axe 2 Règles de gestion'!$D$2:$F$190,3, FALSE) -> Un détachement de courte durée ne peut excéder 1 an entre la date de début et la date de fin réelle, pour les personnels détachés pour servir dans les collectivités d'outre-mer, la Nouvelle-Calédonie ou à l'étranger. | BE7: DET_D_007 | BF7: =VLOOKUP(BE7,'Axe 2 Règles de gestion'!$D$2:$F$190,3, FALSE) -> Chaque période de détachement de longue durée ne peut excéder 5 ans entre la date de début et la date de fin prévisionnelle. | BG7: DET_D_407 | BH7: =VLOOKUP(BG7,'Axe 2 Règles de gestion'!$D$2:$F$190,3, FALSE) -> Chaque période de détachement de longue durée ne peut excéder 5 ans entre la date de début et la date de fin réelle. | BM7: POS_C_004 | BN7: =VLOOKUP(BM7,'Axe 2 Règles de gestion'!$D$2:$F$190,3, FALSE) -> La date de début de position doit être antérieure ou égale à la date de fin prévisionnelle de position. | BO7: POS_C_007 | BP7: =VLOOKUP(BO7,'Axe 2 Règles de gestion'!$D$2:$F$190,3, FALSE) -> La date de fin réelle de la position doit être antérieure à la date limite de départ à la retraite. | BQ7: POS_C_010 | BR7: =VLOOKUP(BQ7,'Axe 2 Règles de gestion'!$D$2:$F$190,3, FALSE) -> La date de début de position doit être antérieure ou égale à la date de fin réelle de position. | BS7: POS_C_012 | BT7: =VLOOKUP(BS7,'Axe 2 Règles de gestion'!$D$2:$F$190,3, FALSE) -> La date de fin prévisionnelle de la position doit être antérieure à la date limite de départ à la retraite. | BU7: POS_C_037 | BV7: =VLOOKUP(BU7,'Axe 2 Règles de gestion'!$D$2:$F$190,3, FALSE) -> Les champs "Type d'organisme d'accueil" et "Pays" de l'organisme d'accueil doivent être renseignés. | BW7: POS_C_111 | BX7: =VLOOKUP(BW7,'Axe 2 Règles de gestion'!$D$2:$F$190,3, FALSE) -> La date de fin ou la date de fin prévisionnelle doit être saisie. | BY7: POS_C_431 | BZ7: =VLOOKUP(BY7,'Axe 2 Règles de gestion'!$D$2:$F$190,3, FALSE) -> Les champs "Ministère (ou institution de la République) d'accueil", "Corps d'accueil en détachement" et "Grade d'accueil en détachement" ou "Ministère (ou institution de la République) d'accueil", "Emploi fonctionnel d'accueil en détachement" et "Groupe dans un emploi fonctionnel d'accueil" sont renseignés si le "Type d'organisme d'accueil" est valorisé à FPE. | CA7: POS_C_434 | CB7: =VLOOKUP(CA7,'Axe 2 Règles de gestion'!$D$2:$F$190,3, FALSE) -> Le champ "Organisme d'accueil" doit être alimenté si le type d'organisme d'accueil est égal à 'Autre organisme', 'Fonction publique d'un état de l'Union Européenne' ou 'Fonction publique Européenne'. | CC7: POS_C_120 | CD7: =VLOOKUP(CC7,'Axe 2 Règles de gestion'!$D$2:$F$190,3, FALSE) -> La saisie d'une occurrence de congés/absences est interdite (date de fin réelle) | CE7: POS_C_121 | CF7: =VLOOKUP(CE7,'Axe 2 Règles de gestion'!$D$2:$F$190,3, FALSE) -> La saisie d'une occurrence de congés/absences est interdite (date de fin prévisionnelle) | CG7: POS_C_435 | CH7: =VLOOKUP(CG7,'Axe 2 Règles de gestion'!$D$2:$F$190,3, FALSE) -> Le champ « Libellé corps/grade/emploi de détachement » est renseigné si le « Type d'organisme d'accueil » n'est pas valorisé à FPE.
A8: 17.10.00 | B8: A | C8: 43152.5 | D8: D0004 | E8: Position | F8: S0008 | G8: Détachement sortant | H8: E0101 | I8: Détachement sortant sur demande auprès d'une administration, d'un office ou d'un EP de l'Etat conduisant à pension | J8: Position administrative Saisie égale à 'Détachement sortant sur demande auprès d'une administration ou d'un EP de l'Etat conduisant à pension' ET Indicateur de maintien saisi = Non | K8: A_POS_POSIAD [Saisi] = 'DET01' ET A_POS_SITPAR [Saisi] = Vide ET A_POS_INDMAI [Saisi] = '0' | L8: T0204 | M8: Détachement sortant sur demande auprès d'une administration ou d'un EP de l'Etat conduisant à pension - Demande | N8: Création Modification | O8: Indicateur de renouvellement saisi = Non ET (Indicateur de renouvellement saisi différent d'Indicateur de renouvellement avant saisi OU Indicateur de maintien saisi différent de Indicateur de maintien avant saisi) | P8: A_POS_INDREN [Saisi] = '0' ET (A_POS_INDREN [Saisi] <> A_POS_INDREN [Valeur avant saisie] OU A_POS_INDMAI [Saisi] <> A_POS_INDMAI [Valeur avant saisie]) | Q8: Contractuel | R8: P0003 | S8: N | T8: Général | U8: Exclu | V8: 40725
A9: 17.10.00 | B9: A | C9: 43152.5 | D9: D0004 | E9: Position | F9: S0008 | G9: Détachement sortant | H9: E0101 | I9: Détachement sortant sur demande auprès d'une administration, d'un office ou d'un EP de l'Etat conduisant à pension | J9: Position administrative Saisie égale à 'Détachement sortant sur demande auprès d'une administration ou d'un EP de l'Etat conduisant à pension' ET Indicateur de maintien saisi = Non | K9: A_POS_POSIAD [Saisi] = 'DET01' ET A_POS_SITPAR [Saisi] = Vide ET A_POS_INDMAI [Saisi] = '0' | L9: T0205 | M9: Détachement sortant sur demande auprès d'une administration ou d'un EP de l'Etat conduisant à pension - Renouvellement | N9: Création Modification | O9: Indicateur de renouvellement saisi = Oui ET (Indicateur de renouvellement saisi différent d'Indicateur de renouvellement avant saisi OU Indicateur de maintien saisi différent de Indicateur de maintien avant saisi) | P9: A_POS_INDREN [Saisi] = '1' ET (A_POS_INDREN [Saisi] <> A_POS_INDREN [Valeur avant saisie] OU A_POS_INDMAI [Saisi] <> A_POS_INDMAI [Valeur avant saisie]) | Q9: Contractuel | R9: P0003 | S9: N | T9: Général | U9: Exclu | V9: 40725
A10: 17.10.00 | B10: A | C10: 43152.5 | D10: D0004 | E10: Position | F10: S0008 | G10: Détachement sortant | H10: E0101 | I10: Détachement sortant sur demande auprès d'une administration, d'un office ou d'un EP de l'Etat conduisant à pension | J10: Position administrative Saisie égale à 'Détachement sortant sur demande auprès d'une administration ou d'un EP de l'Etat conduisant à pension' ET Indicateur de maintien saisi = Non | K10: A_POS_POSIAD [Saisi] = 'DET01' ET A_POS_SITPAR [Saisi] = Vide ET A_POS_INDMAI [Saisi] = '0' | L10: T0206 | M10: Détachement sortant sur demande auprès d'une administration ou d'un EP de l'Etat conduisant à pension - Réintégration | N10: Modification | O10: Indicateur de renouvellement saisi identique à Indicateur de renouvellement avant saisi ET Indicateur de maintien saisi identique à Indicateur de maintien avant saisi | P10: A_POS_INDREN [Saisi] = A_POS_INDREN [Valeur avant saisie] ET A_POS_INDMAI [Saisi] = A_POS_INDMAI [Valeur avant saisie] | Q10: Contractuel | R10: P0003 | S10: N | T10: Général | U10: Exclu | V10: 40725
A11: 21.00.00 | B11: A | C11: 44295.72 | D11: D0004 | E11: Position | F11: S0008 | G11: Détachement sortant | H11: E0101 | I11: Détachement sortant sur demande auprès d'une administration, d'un office ou d'un EP de l'Etat conduisant à pension | J11: Position administrative Saisie égale à 'Détachement sortant sur demande auprès d'une administration ou d'un EP de l'Etat conduisant à pension' ET Indicateur de maintien saisi = Non | K11: A_POS_POSIAD [Saisi] = 'DET01' ET A_POS_SITPAR [Saisi] = Vide ET A_POS_INDMAI [Saisi] = '0' | L11: T0204 | M11: Détachement sortant sur demande auprès d'une administration ou d'un EP de l'Etat conduisant à pension - Demande | N11: Création Modification | O11: Indicateur de renouvellement saisi = Non ET (Indicateur de renouvellement saisi différent d'Indicateur de renouvellement avant saisi OU Indicateur de maintien saisi différent de Indicateur de maintien avant saisi) | P11: A_POS_INDREN [Saisi] = '0' ET (A_POS_INDREN [Saisi] <> A_POS_INDREN [Valeur avant saisie] OU A_POS_INDMAI [Saisi] <> A_POS_INDMAI [Valeur avant saisie]) | Q11: Stagiaire ou auditeur ou élève | R11: P0004 | S11: S | T11: Général | U11: Exclu | V11: 40725
A12: 21.00.00 | B12: A | C12: 44299.432 | D12: D0004 | E12: Position | F12: S0008 | G12: Détachement sortant | H12: E0101 | I12: Détachement sortant sur demande auprès d'une administration, d'un office ou d'un EP de l'Etat conduisant à pension | J12: Position administrative Saisie égale à 'Détachement sortant sur demande auprès d'une administration ou d'un EP de l'Etat conduisant à pension' ET Indicateur de maintien saisi = Non | K12: A_POS_POSIAD [Saisi] = 'DET01' ET A_POS_SITPAR [Saisi] = Vide ET A_POS_INDMAI [Saisi] = '0' | L12: T0205 | M12: Détachement sortant sur demande auprès d'une administration ou d'un EP de l'Etat conduisant à pension - Renouvellement | N12: Création Modification | O12: Indicateur de renouvellement saisi = Oui ET (Indicateur de renouvellement saisi différent d'Indicateur de renouvellement avant saisi OU Indicateur de maintien saisi différent de Indicateur de maintien avant saisi) | P12: A_POS_INDREN [Saisi] = '1' ET (A_POS_INDREN [Saisi] <> A_POS_INDREN [Valeur avant saisie] OU A_POS_INDMAI [Saisi] <> A_POS_INDMAI [Valeur avant saisie]) | Q12: Stagiaire ou auditeur ou élève | R12: P0004 | S12: S | T12: Général | U12: Exclu | V12: 40725
A13: 21.00.00 | B13: A | C13: 44299.433 | D13: D0004 | E13: Position | F13: S0008 | G13: Détachement sortant | H13: E0101 | I13: Détachement sortant sur demande auprès d'une administration, d'un office ou d'un EP de l'Etat conduisant à pension | J13: Position administrative Saisie égale à 'Détachement sortant sur demande auprès d'une administration ou d'un EP de l'Etat conduisant à pension' ET Indicateur de maintien saisi = Non | K13: A_POS_POSIAD [Saisi] = 'DET01' ET A_POS_SITPAR [Saisi] = Vide ET A_POS_INDMAI [Saisi] = '0' | L13: T0206 | M13: Détachement sortant sur demande auprès d'une administration ou d'un EP de l'Etat conduisant à pension - Réintégration | N13: Modification | O13: Indicateur de renouvellement saisi identique à Indicateur de renouvellement avant saisi ET Indicateur de maintien saisi identique à Indicateur de maintien avant saisi | P13: A_POS_INDREN [Saisi] = A_POS_INDREN [Valeur avant saisie] ET A_POS_INDMAI [Saisi] = A_POS_INDMAI [Valeur avant saisie] | Q13: Stagiaire ou auditeur ou élève | R13: P0004 | S13: S | T13: Général | U13: Exclu | V13: 40725
A14: 17.10.00 | B14: A | C14: 43152.5 | D14: D0004 | E14: Position | F14: S0008 | G14: Détachement sortant | H14: E0101 | I14: Détachement sortant sur demande auprès d'une administration, d'un office ou d'un EP de l'Etat conduisant à pension | J14: Position administrative Saisie égale à 'Détachement sortant sur demande auprès d'une administration ou d'un EP de l'Etat conduisant à pension' ET Indicateur de maintien saisi = Non | K14: A_POS_POSIAD [Saisi] = 'DET01' ET A_POS_SITPAR [Saisi] = Vide ET A_POS_INDMAI [Saisi] = '0' | L14: T0204 | M14: Détachement sortant sur demande auprès d'une administration ou d'un EP de l'Etat conduisant à pension - Demande | N14: Création Modification | O14: Indicateur de renouvellement saisi = Non ET (Indicateur de renouvellement saisi différent d'Indicateur de renouvellement avant saisi OU Indicateur de maintien saisi différent de Indicateur de maintien avant saisi) | P14: A_POS_INDREN [Saisi] = '0' ET (A_POS_INDREN [Saisi] <> A_POS_INDREN [Valeur avant saisie] OU A_POS_INDMAI [Saisi] <> A_POS_INDMAI [Valeur avant saisie]) | Q14: Ouvrier d'état | R14: P0005 | S14: O | T14: Général | U14: Exclu | V14: 40725
A15: 17.10.00 | B15: A | C15: 43152.5 | D15: D0004 | E15: Position | F15: S0008 | G15: Détachement sortant | H15: E0101 | I15: Détachement sortant sur demande auprès d'une administration, d'un office ou d'un EP de l'Etat conduisant à pension | J15: Position administrative Saisie égale à 'Détachement sortant sur demande auprès d'une administration ou d'un EP de l'Etat conduisant à pension' ET Indicateur de maintien saisi = Non | K15: A_POS_POSIAD [Saisi] = 'DET01' ET A_POS_SITPAR [Saisi] = Vide ET A_POS_INDMAI [Saisi] = '0' | L15: T0205 | M15: Détachement sortant sur demande auprès d'une administration ou d'un EP de l'Etat conduisant à pension - Renouvellement | N15: Création Modification | O15: Indicateur de renouvellement saisi = Oui ET (Indicateur de renouvellement saisi différent d'Indicateur de renouvellement avant saisi OU Indicateur de maintien saisi différent de Indicateur de maintien avant saisi) | P15: A_POS_INDREN [Saisi] = '1' ET (A_POS_INDREN [Saisi] <> A_POS_INDREN [Valeur avant saisie] OU A_POS_INDMAI [Saisi] <> A_POS_INDMAI [Valeur avant saisie]) | Q15: Ouvrier d'état | R15: P0005 | S15: O | T15: Général | U15: Exclu | V15: 40725
A16: 17.10.00 | B16: A | C16: 43152.5 | D16: D0004 | E16: Position | F16: S0008 | G16: Détachement sortant | H16: E0101 | I16: Détachement sortant sur demande auprès d'une administration, d'un office ou d'un EP de l'Etat conduisant à pension | J16: Position administrative Saisie égale à 'Détachement sortant sur demande auprès d'une administration ou d'un EP de l'Etat conduisant à pension' ET Indicateur de maintien saisi = Non | K16: A_POS_POSIAD [Saisi] = 'DET01' ET A_POS_SITPAR [Saisi] = Vide ET A_POS_INDMAI [Saisi] = '0' | L16: T0206 | M16: Détachement sortant sur demande auprès d'une administration ou d'un EP de l'Etat conduisant à pension - Réintégration | N16: Modification | O16: Indicateur de renouvellement saisi identique à Indicateur de renouvellement avant saisi ET Indicateur de maintien saisi identique à Indicateur de maintien avant saisi | P16: A_POS_INDREN [Saisi] = A_POS_INDREN [Valeur avant saisie] ET A_POS_INDMAI [Saisi] = A_POS_INDMAI [Valeur avant saisie] | Q16: Ouvrier d'état | R16: P0005 | S16: O | T16: Général | U16: Exclu | V16: 40725
