Workbook
Name date_DIADC: 'Mode opératoire'!#REF!
Name notice_DIADC: 'Mode opératoire'!#REF!
Name notice_ENCHN: 'Mode opératoire'!$B$1:$B$4
Name notice_ICA: 'Mode opératoire'!#REF!

Sheet Mode opératoire
B1: MODE OPERATOIRE
B2: La description d'une position entrante dans un dossier agent, nécessite la MAJ des données portées par les 2 sous-rubriques suivantes : - Position statutaire/situation administrative - Détachement, affectation ou MAD entrant La spécification métier regroupe au sein d'un évènement unique l'articulation des RG mobilisant des données appartenant à ces deux sous-rubriques. Ainsi, le métier considère que les données associées à ces deux sous rubriques sont mises à jour dans la même transaction. !N!Les positions concernées sont les codes de positions mobilisés dans l'axe1.

Sheet Axe 1 Enchainement des RG
A1: Version | B1: Type de mise à jour | C1: Date de mise à jour | D1: Identifiant Domaine | E1: Libellé du Domaine | F1: Identifiant Sous-domaine | G1: Libellé du Sous-domaine | H1: Identifiant Evénement | I1: Libellé de l'évènement | J1: Libellé condition déclenchement Evènement | K1: Condition déclenchement Evènement | L1: Identifiant type d'évènement | M1: Libellé type d'évènement | N1: Type de mise à jour | O1: Libellé condition déclenchement Type Evènement | P1: Condition déclenchement Type Evènement | Q1: Libellé Population | R1: Codification Population | S1: Typologie de population | T1: Général / Particulier | U1: Passant / Exclu | V1: Date de début | W1: Date de fin | X1: Règles mobilisées | Y1: Identifiant Règle de contrôle intellectuel 1 | Z1: Libellé Règle de contrôle intellectuel 1 | AA1: Identifiant Règle de contrôle intellectuel 2 | AB1: Libellé Règle de contrôle intellectuel 2 | AC1: Identifiant Règle de contrôle intellectuel 3 | AD1: Libellé Règle de contrôle intellectuel 3 | AE1: Identifiant Règle de contrôle intellectuel 4 | AF1: Libellé Règle de contrôle intellectuel 4 | AG1: Identifiant Règle de contrôle intellectuel 5 | AH1: Libellé Règle de contrôle intellectuel 5 | AI1: Identifiant Règle de contrôle intellectuel 6 | AJ1: Libellé Règle de contrôle intellectuel 6 | AK1: Identifiant Règle de contrôle intellectuel 7 | AL1: Libellé Règle de contrôle intellectuel 7 | AM1: Identifiant Règle de contrôle intellectuel 8 | AN1: Libellé Règle de contrôle intellectuel 8 | AO1: Identifiant Règle de contrôle intellectuel 9 | AP1: Libellé Règle de contrôle intellectuel 9 | AQ1: Identifiant Règle de condition 1 | AR1: Libellé Règle de condition 1 | AS1: Identifiant Règle de condition 2 | AT1: Libellé Règle de condition 2 | AU1: Identifiant Règle de contrôle 1 | AV1: Libellé Règle de contrôle 1 | AW1: Identifiant Règle de contrôle 2 | AX1: Libellé Règle de contrôle 2 | AY1: Identifiant Règle de contrôle 3 | AZ1: Libellé Règle de contrôle 3 | BA1: Identifiant Règle de contrôle 4 | BB1: Libellé Règle de contrôle 4 | BC1: Identifiant Règle de contrôle 5 | BD1: Libellé Règle de contrôle 5 | BE1: Identifiant Règle de contrôle 6 | BF1: Libellé Règle de contrôle 6 | BG1: Identifiant Règle de contrôle 7 | BH1: Libellé Règle de contrôle 7 | BI1: Identifiant Règle de contrôle 8 | BJ1: Libellé Règle de contrôle 8 | BK1: Identifiant Règle de contrôle 9 | BL1: Libellé Règle de contrôle 9 | BM1: Identifiant Règle de contrôle 10 | BN1: Libellé Règle de contrôle 10 | BO1: Identifiant Règle de contrôle 11 | BP1: Libellé Règle de contrôle 11 | BQ1: FIME | BR1: Statut de travail
A2: 22.00.00 | B2: M | C2: 44711.679 | D2: D0004 | E2: Position | F2: S0011 | G2: Position normale d'activité entrante et entrante sortante | H2: E0158 | I2: Position normale d'activité entrante payée ancien dispositif | J2: Position / Situation saisie égale à 'Position normale d'activité entrante payée' ET Date de début position < 18/04/2020 | K2: A_POS_POSIAD [Saisi] = 'ACI0A' ET A_POS_DATEB [Saisi] < 18/04/2020 | L2: T0465 | M2: Position normale d'activité entrante payée - Demande | N2: Création | Q2: Titulaire ou magistrat | R2: P0001 | S2: T | T2: Général | U2: Passant | V2: 40725 | W2: 43861 | X2: PNE_I_002 ET PNE_I_001 ET PNE_I_006 ET PNE_I_004 ET PNE_I_005 ET PNE_I_003 ET PNE_I_007 ET PNE_I_014 ET POS_C_005 ET POS_C_022 ET POS_C_010 ET POS_C_004 ET POS_C_007 ET POS_C_012 ET POS_C_030 ET POS_C_031 ET POS_C_034 ET POS_C_035 ET POS_C_036 | Y2: PNE_I_002 | Z2: =VLOOKUP(Y2,'Axe 2 Règles de gestion'!$D$2:$F$41,3, FALSE) -> L'agent doit effectuer une demande. | AA2: PNE_I_001 | AB2: =VLOOKUP(AA2,'Axe 2 Règles de gestion'!$D$2:$F$41,3, FALSE) -> L'affectation intervient à l'initiative de l'agent ou de l'administration. | AC2: PNE_I_006 | AD2: =VLOOKUP(AC2,'Axe 2 Règles de gestion'!$D$2:$F$41,3, FALSE) -> L'administration ne peut s'opposer à un changement d'affectation d'un agent qui a obtenu l'accord de l'organisme d'accueil que pour des motifs liés aux nécessités du service ou liés à un avis d'incompatibilité rendu par la commission de déontologie. | AE2: PNE_I_004 | AF2: =VLOOKUP(AE2,'Axe 2 Règles de gestion'!$D$2:$F$41,3, FALSE) -> Un avis conforme de l'administration d'accueil a préalablement été transmis à l'administration d'origine sauf dans le cadre d'un transfert de service. | AG2: PNE_I_005 | AH2: =VLOOKUP(AG2,'Axe 2 Règles de gestion'!$D$2:$F$41,3, FALSE) -> Lorsque l'affectation de l'agent est prononcée dans un établissement public, le ministère de tutelle en est préalablement informé. | AI2: PNE_I_003 | AJ2: =VLOOKUP(AI2,'Axe 2 Règles de gestion'!$D$2:$F$41,3, FALSE) -> L'affectation en position normale d'activité hors de l'administration d'origine est prononcée sans limitation de durée. | AK2: PNE_I_007 | AL2: =VLOOKUP(AK2,'Axe 2 Règles de gestion'!$D$2:$F$41,3, FALSE) -> L'administration peut exiger que l'agent respecte un délai maximal de préavis de 3 mois. Ce délai peut être porté à une durée plus longue, qui ne saurait toutefois excéder 6 mois. | AM2: PNE_I_014 | AN2: =VLOOKUP(AM2,'Axe 2 Règles de gestion'!$D$2:$F$41,3, FALSE) -> Le silence de l'administration gardé pendant 2 mois à compter de la réception de la demande de l'agent vaut acceptation. | AU2: POS_C_005 | AV2: =VLOOKUP(AU2,'Axe 2 Règles de gestion'!$D$2:$F$41,3, FALSE) -> La date de début de la position doit être postérieure ou égale à la date d'entrée dans la FPE ou dans la carrière militaire. | AW2: POS_C_022 | AX2: =VLOOKUP(AW2,'Axe 2 Règles de gestion'!$D$2:$F$41,3, FALSE) -> La date de début de position est à J+1 de la date de fin de position de l'occurrence précédente. | AY2: POS_C_010 | AZ2: =VLOOKUP(AY2,'Axe 2 Règles de gestion'!$D$2:$F$41,3, FALSE) -> La date de début de position doit être antérieure ou égale à la date de fin réelle de position. | BA2: POS_C_004 | BB2: =VLOOKUP(BA2,'Axe 2 Règles de gestion'!$D$2:$F$41,3, FALSE) -> La date de début de position doit être antérieure ou égale à la date de fin prévisionnelle de position. | BC2: POS_C_007 | BD2: =VLOOKUP(BC2,'Axe 2 Règles de gestion'!$D$2:$F$41,3, FALSE) -> La date de fin réelle de la position doit être antérieure à la date limite de départ à la retraite. | BE2: POS_C_012 | BF2: =VLOOKUP(BE2,'Axe 2 Règles de gestion'!$D$2:$F$41,3, FALSE) -> La date de fin prévisionnelle de la position doit être antérieure à la date limite de départ à la retraite. | BG2: POS_C_030 | BH2: =VLOOKUP(BG2,'Axe 2 Règles de gestion'!$D$2:$F$41,3, FALSE) -> Les champs "Type d'organisme d'origine", "Catégorie statutaire d'origine" et "Pays" de l'organisme d'origine doivent être renseignés. | BI2: POS_C_031 | BJ2: =VLOOKUP(BI2,'Axe 2 Règles de gestion'!$D$2:$F$41,3, FALSE) -> Les champs "Ministère (ou institution de la République) d'origine", "Corps d'origine", "Grade d'origine", "Echelon d'origine" sont renseignés si le "Type d'organisme d'origine" est valorisé à FPE. | BK2: POS_C_034 | BL2: =VLOOKUP(BK2,'Axe 2 Règles de gestion'!$D$2:$F$41,3, FALSE) -> Le champ "Organisme d'origine" doit être alimenté si le type d'organisme d'origine est égal à 'Autre organisme', 'Fonction publique d'un état de l'Union Européenne' ou 'Fonction publique Européenne'. | BM2: POS_C_035 | BN2: =VLOOKUP(BM2,'Axe 2 Règles de gestion'!$D$2:$F$41,3, FALSE) -> Le champ "Code emploi statutaire FPT (NET)" est renseigné si le "Type d'organisme d'origine" est valorisé à FPT. | BO2: POS_C_036 | BP2: =VLOOKUP(BO2,'Axe 2 Règles de gestion'!$D$2:$F$41,3, FALSE) -> Le champ "Code emploi statutaire FPH (NEH)" est renseigné si le "Type d'organisme d'origine" est valorisé à FPH.
A3: 22.00.00 | B3: A | C3: 44711.422 | D3: D0004 | E3: Position | F3: S0011 | G3: Position normale d'activité entrante et entrante sortante | H3: E0158 | I3: Position normale d'activité entrante payée ancien dispositif | J3: Position / Situation saisie égale à 'Position normale d'activité entrante payée' ET Date de début position < 18/04/2020 | K3: A_POS_POSIAD [Saisi] = 'ACI0A' ET A_POS_DATEB [Saisi] < 18/04/2020 | L3: T0465 | M3: Position normale d'activité entrante payée - Demande | N3: Création | Q3: Titulaire ou magistrat | R3: P0001 | S3: T | T3: Général | U3: Passant | V3: 43862 | W3: 43938 | X3: PNE_I_002 ET PNE_I_001 ET PNE_I_013 ET PNE_I_004 ET PNE_I_005 ET PNE_I_003 ET PNE_I_007 ET PNE_I_014 ET POS_C_005 ET POS_C_022 ET POS_C_010 ET POS_C_004 ET POS_C_007 ET POS_C_012 ET POS_C_030 ET POS_C_031 ET POS_C_034 ET POS_C_035 ET POS_C_036 | Y3: PNE_I_002 | Z3: =VLOOKUP(Y3,'Axe 2 Règles de gestion'!$D$2:$F$41,3, FALSE) -> L'agent doit effectuer une demande. | AA3: PNE_I_001 | AB3: =VLOOKUP(AA3,'Axe 2 Règles de gestion'!$D$2:$F$41,3, FALSE) -> L'affectation intervient à l'initiative de l'agent ou de l'administration. | AC3: PNE_I_013 | AD3: =VLOOKUP(AC3,'Axe 2 Règles de gestion'!$D$2:$F$41,3, FALSE) -> L'administration ne peut s'opposer au changement d'affectation d'un agent qui a obtenu l'accord de l'organisme d'accueil que pour des motifs liés aux nécessités du service ou à un avis rendu par la Haute Autorité pour la transparence de la vie publique. | AE3: PNE_I_004 | AF3: =VLOOKUP(AE3,'Axe 2 Règles de gestion'!$D$2:$F$41,3, FALSE) -> Un avis conforme de l'administration d'accueil a préalablement été transmis à l'administration d'origine sauf dans le cadre d'un transfert de service. | AG3: PNE_I_005 | AH3: =VLOOKUP(AG3,'Axe 2 Règles de gestion'!$D$2:$F$41,3, FALSE) -> Lorsque l'affectation de l'agent est prononcée dans un établissement public, le ministère de tutelle en est préalablement informé. | AI3: PNE_I_003 | AJ3: =VLOOKUP(AI3,'Axe 2 Règles de gestion'!$D$2:$F$41,3, FALSE) -> L'affectation en position normale d'activité hors de l'administration d'origine est prononcée sans limitation de durée. | AK3: PNE_I_007 | AL3: =VLOOKUP(AK3,'Axe 2 Règles de gestion'!$D$2:$F$41,3, FALSE) -> L'administration peut exiger que l'agent respecte un délai maximal de préavis de 3 mois. Ce délai peut être porté à une durée plus longue, qui ne saurait toutefois excéder 6 mois. | AM3: PNE_I_014 | AN3: =VLOOKUP(AM3,'Axe 2 Règles de gestion'!$D$2:$F$41,3, FALSE) -> Le silence de l'administration gardé pendant 2 mois à compter de la réception de la demande de l'agent vaut acceptation. | AU3: POS_C_005 | AV3: =VLOOKUP(AU3,'Axe 2 Règles de gestion'!$D$2:$F$41,3, FALSE) -> La date de début de la position doit être postérieure ou égale à la date d'entrée dans la FPE ou dans la carrière militaire. | AW3: POS_C_022 | AX3: =VLOOKUP(AW3,'Axe 2 Règles de gestion'!$D$2:$F$41,3, FALSE) -> La date de début de position est à J+1 de la date de fin de position de l'occurrence précédente. | AY3: POS_C_010 | AZ3: =VLOOKUP(AY3,'Axe 2 Règles de gestion'!$D$2:$F$41,3, FALSE) -> La date de début de position doit être antérieure ou égale à la date de fin réelle de position. | BA3: POS_C_004 | BB3: =VLOOKUP(BA3,'Axe 2 Règles de gestion'!$D$2:$F$41,3, FALSE) -> La date de début de position doit être antérieure ou égale à la date de fin prévisionnelle de position. | BC3: POS_C_007 | BD3: =VLOOKUP(BC3,'Axe 2 Règles de gestion'!$D$2:$F$41,3, FALSE) -> La date de fin réelle de la position doit être antérieure à la date limite de départ à la retraite. | BE3: POS_C_012 | BF3: =VLOOKUP(BE3,'Axe 2 Règles de gestion'!$D$2:$F$41,3, FALSE) -> La date de fin prévisionnelle de la position doit être antérieure à la date limite de départ à la retraite. | BG3: POS_C_030 | BH3: =VLOOKUP(BG3,'Axe 2 Règles de gestion'!$D$2:$F$41,3, FALSE) -> Les champs "Type d'organisme d'origine", "Catégorie statutaire d'origine" et "Pays" de l'organisme d'origine doivent être renseignés. | BI3: POS_C_031 | BJ3: =VLOOKUP(BI3,'Axe 2 Règles de gestion'!$D$2:$F$41,3, FALSE) -> Les champs "Ministère (ou institution de la République) d'origine", "Corps d'origine", "Grade d'origine", "Echelon d'origine" sont renseignés si le "Type d'organisme d'origine" est valorisé à FPE. | BK3: POS_C_034 | BL3: =VLOOKUP(BK3,'Axe 2 Règles de gestion'!$D$2:$F$41,3, FALSE) -> Le champ "Organisme d'origine" doit être alimenté si le type d'organisme d'origine est égal à 'Autre organisme', 'Fonction publique d'un état de l'Union Européenne' ou 'Fonction publique Européenne'. | BM3: POS_C_035 | BN3: =VLOOKUP(BM3,'Axe 2 Règles de gestion'!$D$2:$F$41,3, FALSE) -> Le champ "Code emploi statutaire FPT (NET)" est renseigné si le "Type d'organisme d'origine" est valorisé à FPT. | BO3: POS_C_036 | BP3: =VLOOKUP(BO3,'Axe 2 Règles de gestion'!$D$2:$F$41,3, FALSE) -> Le champ "Code emploi statutaire FPH (NEH)" est renseigné si le "Type d'organisme d'origine" est valorisé à FPH.
A4: 20.00.00 | B4: M | C4: 43999.454 | D4: D0004 | E4: Position | F4: S0011 | G4: Position normale d'activité entrante et entrante sortante | H4: E0158 | I4: Position normale d'activité entrante payée ancien dispositif | J4: Position / Situation saisie égale à 'Position normale d'activité entrante payée' ET Date de début position < 18/04/2020 | K4: A_POS_POSIAD [Saisi] = 'ACI0A' ET A_POS_DATEB [Saisi] < 18/04/2020 | L4: T0466 | M4: Position normale d'activité entrante payée- Fin | N4: Modification | Q4: Titulaire ou magistrat | R4: P0001 | S4: T | T4: Général | U4: Passant | V4: 40725 | W4: 43938 | X4: PNE_I_003 ET POS_C_010 ET POS_C_004 ET POS_C_007 ET POS_C_012 ET POS_C_030 ET POS_C_031 ET POS_C_034 ET POS_C_035 ET POS_C_036 | Y4: PNE_I_003 | Z4: =VLOOKUP(Y4,'Axe 2 Règles de gestion'!$D$2:$F$41,3, FALSE) -> L'affectation en position normale d'activité hors de l'administration d'origine est prononcée sans limitation de durée. | AU4: POS_C_010 | AV4: =VLOOKUP(AU4,'Axe 2 Règles de gestion'!$D$2:$F$41,3, FALSE) -> La date de début de position doit être antérieure ou égale à la date de fin réelle de position. | AW4: POS_C_004 | AX4: =VLOOKUP(AW4,'Axe 2 Règles de gestion'!$D$2:$F$41,3, FALSE) -> La date de début de position doit être antérieure ou égale à la date de fin prévisionnelle de position. | AY4: POS_C_007 | AZ4: =VLOOKUP(AY4,'Axe 2 Règles de gestion'!$D$2:$F$41,3, FALSE) -> La date de fin réelle de la position doit être antérieure à la date limite de départ à la retraite. | BA4: POS_C_012 | BB4: =VLOOKUP(BA4,'Axe 2 Règles de gestion'!$D$2:$F$41,3, FALSE) -> La date de fin prévisionnelle de la position doit être antérieure à la date limite de départ à la retraite. | BC4: POS_C_030 | BD4: =VLOOKUP(BC4,'Axe 2 Règles de gestion'!$D$2:$F$41,3, FALSE) -> Les champs "Type d'organisme d'origine", "Catégorie statutaire d'origine" et "Pays" de l'organisme d'origine doivent être renseignés. | BE4: POS_C_031 | BF4: =VLOOKUP(BE4,'Axe 2 Règles de gestion'!$D$2:$F$41,3, FALSE) -> Les champs "Ministère (ou institution de la République) d'origine", "Corps d'origine", "Grade d'origine", "Echelon d'origine" sont renseignés si le "Type d'organisme d'origine" est valorisé à FPE. | BG4: POS_C_034 | BH4: =VLOOKUP(BG4,'Axe 2 Règles de gestion'!$D$2:$F$41,3, FALSE) -> Le champ "Organisme d'origine" doit être alimenté si le type d'organisme d'origine est égal à 'Autre organisme', 'Fonction publique d'un état de l'Union Européenne' ou 'Fonction publique Européenne'. | BI4: POS_C_035 | BJ4: =VLOOKUP(BI4,'Axe 2 Règles de gestion'!$D$2:$F$41,3, FALSE) -> Le champ "Code emploi statutaire FPT (NET)" est renseigné si le "Type d'organisme d'origine" est valorisé à FPT. | BK4: POS_C_036 | BL4: =VLOOKUP(BK4,'Axe 2 Règles de gestion'!$D$2:$F$41,3, FALSE) -> Le champ "Code emploi statutaire FPH (NEH)" est renseigné si le "Type d'organisme d'origine" est valorisé à FPH.
A5: 20.00.00 | B5: M | C5: 43999.642 | D5: D0004 | E5: Position | F5: S0011 | G5: Position normale d'activité entrante et entrante sortante | H5: E0158 | I5: Position normale d'activité entrante payée ancien dispositif | J5: Position / Situation saisie égale à 'Position normale d'activité entrante payée' ET Date de début position < 18/04/2020 | K5: A_POS_POSIAD [Saisi] = 'ACI0A' ET A_POS_DATEB [Saisi] < 18/04/2020 | L5: T0465 | M5: Position normale d'activité entrante payée - Demande | N5: Création | Q5: Militaire | R5: P0002 | S5: M | T5: Général | U5: Exclu | V5: 40725 | W5: 43938
A6: 20.00.00 | B6: M | C6: 43999.64 | D6: D0004 | E6: Position | F6: S0011 | G6: Position normale d'activité entrante et entrante sortante | H6: E0158 | I6: Position normale d'activité entrante payée ancien dispositif | J6: Position / Situation saisie égale à 'Position normale d'activité entrante payée' ET Date de début position < 18/04/2020 | K6: A_POS_POSIAD [Saisi] = 'ACI0A' ET A_POS_DATEB [Saisi] < 18/04/2020 | L6: T0466 | M6: Position normale d'activité entrante payée- Fin | N6: Modification | Q6: Militaire | R6: P0002 | S6: M | T6: Général | U6: Exclu | V6: 40725 | W6: 43938
A7: 20.00.00 | B7: M | C7: 43999.642 | D7: D0004 | E7: Position | F7: S0011 | G7: Position normale d'activité entrante et entrante sortante | H7: E0158 | I7: Position normale d'activité entrante payée ancien dispositif | J7: Position / Situation saisie égale à 'Position normale d'activité entrante payée' ET Date de début position < 18/04/2020 | K7: A_POS_POSIAD [Saisi] = 'ACI0A' ET A_POS_DATEB [Saisi] < 18/04/2020 | L7: T0465 | M7: Position normale d'activité entrante payée - Demande | N7: Création | Q7: Contractuel | R7: P0003 | S7: N | T7: Général | U7: Exclu | V7: 40725 | W7: 43938
A8: 20.00.00 | B8: M | C8: 43999.641 | D8: D0004 | E8: Position | F8: S0011 | G8: Position normale d'activité entrante et entrante sortante | H8: E0158 | I8: Position normale d'activité entrante payée ancien dispositif | J8: Position / Situation saisie égale à 'Position normale d'activité entrante payée' ET Date de début position < 18/04/2020 | K8: A_POS_POSIAD [Saisi] = 'ACI0A' ET A_POS_DATEB [Saisi] < 18/04/2020 | L8: T0466 | M8: Position normale d'activité entrante payée- Fin | N8: Modification | Q8: Contractuel | R8: P0003 | S8: N | T8: Général | U8: Exclu | V8: 40725 | W8: 43938
A9: 22.00.00 | B9: M | C9: 44711.426 | D9: D0004 | E9: Position | F9: S0011 | G9: Position normale d'activité entrante et entrante sortante | H9: E0158 | I9: Position normale d'activité entrante payée ancien dispositif | J9: Position / Situation saisie égale à 'Position normale d'activité entrante payée' ET Date de début position < 18/04/2020 | K9: A_POS_POSIAD [Saisi] = 'ACI0A' ET A_POS_DATEB [Saisi] < 18/04/2020 | L9: T0465 | M9: Position normale d'activité entrante payée - Demande | N9: Création | Q9: Stagiaire ou auditeur ou élève | R9: P0004 | S9: S | T9: Général | U9: Passant | V9: 40725 | W9: 43938 | X9: PNE_I_002 ET PNE_I_001 ET PNE_I_004 ET PNE_I_005 ET PNE_I_003 ET POS_C_005 ET POS_C_022 ET POS_C_010 ET POS_C_004 ET POS_C_007 ET POS_C_012 ET POS_C_030 ET POS_C_031 ET POS_C_034 ET POS_C_035 ET POS_C_036 | Y9: PNE_I_002 | Z9: =VLOOKUP(Y9,'Axe 2 Règles de gestion'!$D$2:$F$41,3, FALSE) -> L'agent doit effectuer une demande. | AA9: PNE_I_001 | AB9: =VLOOKUP(AA9,'Axe 2 Règles de gestion'!$D$2:$F$41,3, FALSE) -> L'affectation intervient à l'initiative de l'agent ou de l'administration. | AC9: PNE_I_004 | AD9: =VLOOKUP(AC9,'Axe 2 Règles de gestion'!$D$2:$F$41,3, FALSE) -> Un avis conforme de l'administration d'accueil a préalablement été transmis à l'administration d'origine sauf dans le cadre d'un transfert de service. | AE9: PNE_I_005 | AF9: =VLOOKUP(AE9,'Axe 2 Règles de gestion'!$D$2:$F$41,3, FALSE) -> Lorsque l'affectation de l'agent est prononcée dans un établissement public, le ministère de tutelle en est préalablement informé. | AG9: PNE_I_003 | AH9: =VLOOKUP(AG9,'Axe 2 Règles de gestion'!$D$2:$F$41,3, FALSE) -> L'affectation en position normale d'activité hors de l'administration d'origine est prononcée sans limitation de durée. | AU9: POS_C_005 | AV9: =VLOOKUP(AU9,'Axe 2 Règles de gestion'!$D$2:$F$41,3, FALSE) -> La date de début de la position doit être postérieure ou égale à la date d'entrée dans la FPE ou dans la carrière militaire. | AW9: POS_C_022 | AX9: =VLOOKUP(AW9,'Axe 2 Règles de gestion'!$D$2:$F$41,3, FALSE) -> La date de début de position est à J+1 de la date de fin de position de l'occurrence précédente. | AY9: POS_C_010 | AZ9: =VLOOKUP(AY9,'Axe 2 Règles de gestion'!$D$2:$F$41,3, FALSE) -> La date de début de position doit être antérieure ou égale à la date de fin réelle de position. | BA9: POS_C_004 | BB9: =VLOOKUP(BA9,'Axe 2 Règles de gestion'!$D$2:$F$41,3, FALSE) -> La date de début de position doit être antérieure ou égale à la date de fin prévisionnelle de position. | BC9: POS_C_007 | BD9: =VLOOKUP(BC9,'Axe 2 Règles de gestion'!$D$2:$F$41,3, FALSE) -> La date de fin réelle de la position doit être antérieure à la date limite de départ à la retraite. | BE9: POS_C_012 | BF9: =VLOOKUP(BE9,'Axe 2 Règles de gestion'!$D$2:$F$41,3, FALSE) -> La date de fin prévisionnelle de la position doit être antérieure à la date limite de départ à la retraite. | BG9: POS_C_030 | BH9: =VLOOKUP(BG9,'Axe 2 Règles de gestion'!$D$2:$F$41,3, FALSE) -> Les champs "Type d'organisme d'origine", "Catégorie statutaire d'origine" et "Pays" de l'organisme d'origine doivent être renseignés. | BI9: POS_C_031 | BJ9: =VLOOKUP(BI9,'Axe 2 Règles de gestion'!$D$2:$F$41,3, FALSE) -> Les champs "Ministère (ou institution de la République) d'origine", "Corps d'origine", "Grade d'origine", "Echelon d'origine" sont renseignés si le "Type d'organisme d'origine" est valorisé à FPE. | BK9: POS_C_034 | BL9: =VLOOKUP(BK9,'Axe 2 Règles de gestion'!$D$2:$F$41,3, FALSE) -> Le champ "Organisme d'origine" doit être alimenté si le type d'organisme d'origine est égal à 'Autre organisme', 'Fonction publique d'un état de l'Union Européenne' ou 'Fonction publique Européenne'. | BM9: POS_C_035 | BN9: =VLOOKUP(BM9,'Axe 2 Règles de gestion'!$D$2:$F$41,3, FALSE) -> Le champ "Code emploi statutaire FPT (NET)" est renseigné si le "Type d'organisme d'origine" est valorisé à FPT. | BO9: POS_C_036 | BP9: =VLOOKUP(BO9,'Axe 2 Règles de gestion'!$D$2:$F$41,3, FALSE) -> Le champ "Code emploi statutaire FPH (NEH)" est renseigné si le "Type d'organisme d'origine" est valorisé à FPH.
A10: 20.00.00 | B10: M | C10: 43999.453 | D10: D0004 | E10: Position | F10: S0011 | G10: Position normale d'activité entrante et entrante sortante | H10: E0158 | I10: Position normale d'activité entrante payée ancien dispositif | J10: Position / Situation saisie égale à 'Position normale d'activité entrante payée' ET Date de début position < 18/04/2020 | K10: A_POS_POSIAD [Saisi] = 'ACI0A' ET A_POS_DATEB [Saisi] < 18/04/2020 | L10: T0466 | M10: Position normale d'activité entrante payée- Fin | N10: Modification | Q10: Stagiaire ou auditeur ou élève | R10: P0004 | S10: S | T10: Général | U10: Passant | V10: 40725 | W10: 43938 | X10: PNE_I_003 ET POS_C_010 ET POS_C_004 ET POS_C_007 ET POS_C_012 ET POS_C_030 ET POS_C_031 ET POS_C_034 ET POS_C_035 ET POS_C_036 | Y10: PNE_I_003 | Z10: =VLOOKUP(Y10,'Axe 2 Règles de gestion'!$D$2:$F$41,3, FALSE) -> L'affectation en position normale d'activité hors de l'administration d'origine est prononcée sans limitation de durée. | AU10: POS_C_010 | AV10: =VLOOKUP(AU10,'Axe 2 Règles de gestion'!$D$2:$F$41,3, FALSE) -> La date de début de position doit être antérieure ou égale à la date de fin réelle de position. | AW10: POS_C_004 | AX10: =VLOOKUP(AW10,'Axe 2 Règles de gestion'!$D$2:$F$41,3, FALSE) -> La date de début de position doit être antérieure ou égale à la date de fin prévisionnelle de position. | AY10: POS_C_007 | AZ10: =VLOOKUP(AY10,'Axe 2 Règles de gestion'!$D$2:$F$41,3, FALSE) -> La date de fin réelle de la position doit être antérieure à la date limite de départ à la retraite. | BA10: POS_C_012 | BB10: =VLOOKUP(BA10,'Axe 2 Règles de gestion'!$D$2:$F$41,3, FALSE) -> La date de fin prévisionnelle de la position doit être antérieure à la date limite de départ à la retraite. | BC10: POS_C_030 | BD10: =VLOOKUP(BC10,'Axe 2 Règles de gestion'!$D$2:$F$41,3, FALSE) -> Les champs "Type d'organisme d'origine", "Catégorie statutaire d'origine" et "Pays" de l'organisme d'origine doivent être renseignés. | BE10: POS_C_031 | BF10: =VLOOKUP(BE10,'Axe 2 Règles de gestion'!$D$2:$F$41,3, FALSE) -> Les champs "Ministère (ou institution de la République) d'origine", "Corps d'origine", "Grade d'origine", "Echelon d'origine" sont renseignés si le "Type d'organisme d'origine" est valorisé à FPE. | BG10: POS_C_034 | BH10: =VLOOKUP(BG10,'Axe 2 Règles de gestion'!$D$2:$F$41,3, FALSE) -> Le champ "Organisme d'origine" doit être alimenté si le type d'organisme d'origine est égal à 'Autre organisme', 'Fonction publique d'un état de l'Union Européenne' ou 'Fonction publique Européenne'. | BI10: POS_C_035 | BJ10: =VLOOKUP(BI10,'Axe 2 Règles de gestion'!$D$2:$F$41,3, FALSE) -> Le champ "Code emploi statutaire FPT (NET)" est renseigné si le "Type d'organisme d'origine" est valorisé à FPT. | BK10: POS_C_036 | BL10: =VLOOKUP(BK10,'Axe 2 Règles de gestion'!$D$2:$F$41,3, FALSE) -> Le champ "Code emploi statutaire FPH (NEH)" est renseigné si le "Type d'organisme d'origine" est valorisé à FPH.
A11: 20.00.00 | B11: M | C11: 43999.642 | D11: D0004 | E11: Position | F11: S0011 | G11: Position normale d'activité entrante et entrante sortante | H11: E0158 | I11: Position normale d'activité entrante payée ancien dispositif | J11: Position / Situation saisie égale à 'Position normale d'activité entrante payée' ET Date de début position < 18/04/2020 | K11: A_POS_POSIAD [Saisi] = 'ACI0A' ET A_POS_DATEB [Saisi] < 18/04/2020 | L11: T0465 | M11: Position normale d'activité entrante payée - Demande | N11: Création | Q11: Ouvrier d'état | R11: P0005 | S11: O | T11: Général | U11: Exclu | V11: 40725 | W11: 43938
A12: 20.00.00 | B12: M | C12: 43999.642 | D12: D0004 | E12: Position | F12: S0011 | G12: Position normale d'activité entrante et entrante sortante | H12: E0158 | I12: Position normale d'activité entrante payée ancien dispositif | J12: Position / Situation saisie égale à 'Position normale d'activité entrante payée' ET Date de début position < 18/04/2020 | K12: A_POS_POSIAD [Saisi] = 'ACI0A' ET A_POS_DATEB [Saisi] < 18/04/2020 | L12: T0466 | M12: Position normale d'activité entrante payée- Fin | N12: Modification | Q12: Ouvrier d'état | R12: P0005 | S12: O | T12: Général | U12: Exclu | V12: 40725 | W12: 43938
A13: 20.00.00 | B13: M | C13: 43999.643 | D13: D0004 | E13: Position | F13: S0011 | G13: Position normale d'activité entrante et entrante sortante | H13: E0158 | I13: Position normale d'activité entrante payée ancien dispositif | J13: Position / Situation saisie égale à 'Position normale d'activité entrante payée' ET Date de début position < 18/04/2020 | K13: A_POS_POSIAD [Saisi] = 'ACI0A' ET A_POS_DATEB [Saisi] < 18/04/2020 | L13: T0465 | M13: Position normale d'activité entrante payée - Demande | N13: Création | Q13: Magistrat de l'ordre judiciaire | R13: P0007 | S13: T | T13: Particulier | U13: Exclu | V13: 40725 | W13: 43938
A14: 20.00.00 | B14: M | C14: 43999.644 | D14: D0004 | E14: Position | F14: S0011 | G14: Position normale d'activité entrante et entrante sortante | H14: E0158 | I14: Position normale d'activité entrante payée ancien dispositif | J14: Position / Situation saisie égale à 'Position normale d'activité entrante payée' ET Date de début position < 18/04/2020 | K14: A_POS_POSIAD [Saisi] = 'ACI0A' ET A_POS_DATEB [Saisi] < 18/04/2020 | L14: T0466 | M14: Position normale d'activité entrante payée- Fin | N14: Modification | Q14: Magistrat de l'ordre judiciaire | R14: P0007 | S14: T | T14: Particulier | U14: Exclu | V14: 40725 | W14: 43938
A15: 20.00.00 | B15: M | C15: 43999.643 | D15: D0004 | E15: Position | F15: S0011 | G15: Position normale d'activité entrante et entrante sortante | H15: E0158 | I15: Position normale d'activité entrante payée ancien dispositif | J15: Position / Situation saisie égale à 'Position normale d'activité entrante payée' ET Date de début position < 18/04/2020 | K15: A_POS_POSIAD [Saisi] = 'ACI0A' ET A_POS_DATEB [Saisi] < 18/04/2020 | L15: T0465 | M15: Position normale d'activité entrante payée - Demande | N15: Création | Q15: Auditeur de justice ou élève | R15: P0034 | S15: S | T15: Particulier | U15: Exclu | V15: 40725 | W15: 43938
A16: 20.00.00 | B16: M | C16: 43999.644 | D16: D0004 | E16: Position | F16: S0011 | G16: Position normale d'activité entrante et entrante sortante | H16: E0158 | I16: Position normale d'activité entrante payée ancien dispositif | J16: Position / Situation saisie égale à 'Position normale d'activité entrante payée' ET Date de début position < 18/04/2020 | K16: A_POS_POSIAD [Saisi] = 'ACI0A' ET A_POS_DATEB [Saisi] < 18/04/2020 | L16: T0466 | M16: Position normale d'activité entrante payée- Fin | N16: Modification | Q16: Auditeur de justice ou élève | R16: P0034 | S16: S | T16: Particulier | U16: Exclu | V16: 40725 | W16: 43938
A17: 22.00.00 | B17: M | C17: 44711.68 | D17: D0004 | E17: Position | F17: S0011 | G17: Position normale d'activité entrante et entrante sortante | H17: E0159 | I17: Position normale d'activité entrante non payée ancien dispositif | J17: Position / Situation saisie égale à 'Position normale d'activité entrante non payée' ET Date de début position < 18/04/2020 | K17: A_POS_POSIAD [Saisi] = 'ACI0B' ET A_POS_DATEB [Saisi] < 18/04/2020 | L17: T0467 | M17: Position normale d'activité entrante non payée - Demande | N17: Création | Q17: Titulaire ou magistrat | R17: P0001 | S17: T | T17: Général | U17: Passant | V17: 40725 | W17: 43861 | X17: PNE_I_002 ET PNE_I_001 ET PNE_I_006 ET PNE_I_004 ET PNE_I_005 ET PNE_I_003 ET PNE_I_007 ET PNE_I_014 ET POS_C_005 ET POS_C_022 ET POS_C_010 ET POS_C_004 ET POS_C_007 ET POS_C_012 ET POS_C_030 ET POS_C_031 ET POS_C_034 ET POS_C_035 ET POS_C_036 | Y17: PNE_I_002 | Z17: =VLOOKUP(Y17,'Axe 2 Règles de gestion'!$D$2:$F$41,3, FALSE) -> L'agent doit effectuer une demande. | AA17: PNE_I_001 | AB17: =VLOOKUP(AA17,'Axe 2 Règles de gestion'!$D$2:$F$41,3, FALSE) -> L'affectation intervient à l'initiative de l'agent ou de l'administration. | AC17: PNE_I_006 | AD17: =VLOOKUP(AC17,'Axe 2 Règles de gestion'!$D$2:$F$41,3, FALSE) -> L'administration ne peut s'opposer à un changement d'affectation d'un agent qui a obtenu l'accord de l'organisme d'accueil que pour des motifs liés aux nécessités du service ou liés à un avis d'incompatibilité rendu par la commission de déontologie. | AE17: PNE_I_004 | AF17: =VLOOKUP(AE17,'Axe 2 Règles de gestion'!$D$2:$F$41,3, FALSE) -> Un avis conforme de l'administration d'accueil a préalablement été transmis à l'administration d'origine sauf dans le cadre d'un transfert de service. | AG17: PNE_I_005 | AH17: =VLOOKUP(AG17,'Axe 2 Règles de gestion'!$D$2:$F$41,3, FALSE) -> Lorsque l'affectation de l'agent est prononcée dans un établissement public, le ministère de tutelle en est préalablement informé. | AI17: PNE_I_003 | AJ17: =VLOOKUP(AI17,'Axe 2 Règles de gestion'!$D$2:$F$41,3, FALSE) -> L'affectation en position normale d'activité hors de l'administration d'origine est prononcée sans limitation de durée. | AK17: PNE_I_007 | AL17: =VLOOKUP(AK17,'Axe 2 Règles de gestion'!$D$2:$F$41,3, FALSE) -> L'administration peut exiger que l'agent respecte un délai maximal de préavis de 3 mois. Ce délai peut être porté à une durée plus longue, qui ne saurait toutefois excéder 6 mois. | AM17: PNE_I_014 | AN17: =VLOOKUP(AM17,'Axe 2 Règles de gestion'!$D$2:$F$41,3, FALSE) -> Le silence de l'administration gardé pendant 2 mois à compter de la réception de la demande de l'agent vaut acceptation. | AU17: POS_C_005 | AV17: =VLOOKUP(AU17,'Axe 2 Règles de gestion'!$D$2:$F$41,3, FALSE) -> La date de début de la position doit être postérieure ou égale à la date d'entrée dans la FPE ou dans la carrière militaire. | AW17: POS_C_022 | AX17: =VLOOKUP(AW17,'Axe 2 Règles de gestion'!$D$2:$F$41,3, FALSE) -> La date de début de position est à J+1 de la date de fin de position de l'occurrence précédente. | AY17: POS_C_010 | AZ17: =VLOOKUP(AY17,'Axe 2 Règles de gestion'!$D$2:$F$41,3, FALSE) -> La date de début de position doit être antérieure ou égale à la date de fin réelle de position. | BA17: POS_C_004 | BB17: =VLOOKUP(BA17,'Axe 2 Règles de gestion'!$D$2:$F$41,3, FALSE) -> La date de début de position doit être antérieure ou égale à la date de fin prévisionnelle de position. | BC17: POS_C_007 | BD17: =VLOOKUP(BC17,'Axe 2 Règles de gestion'!$D$2:$F$41,3, FALSE) -> La date de fin réelle de la position doit être antérieure à la date limite de départ à la retraite. | BE17: POS_C_012 | BF17: =VLOOKUP(BE17,'Axe 2 Règles de gestion'!$D$2:$F$41,3, FALSE) -> La date de fin prévisionnelle de la position doit être antérieure à la date limite de départ à la retraite. | BG17: POS_C_030 | BH17: =VLOOKUP(BG17,'Axe 2 Règles de gestion'!$D$2:$F$41,3, FALSE) -> Les champs "Type d'organisme d'origine", "Catégorie statutaire d'origine" et "Pays" de l'organisme d'origine doivent être renseignés. | BI17: POS_C_031 | BJ17: =VLOOKUP(BI17,'Axe 2 Règles de gestion'!$D$2:$F$41,3, FALSE) -> Les champs "Ministère (ou institution de la République) d'origine", "Corps d'origine", "Grade d'origine", "Echelon d'origine" sont renseignés si le "Type d'organisme d'origine" est valorisé à FPE. | BK17: POS_C_034 | BL17: =VLOOKUP(BK17,'Axe 2 Règles de gestion'!$D$2:$F$41,3, FALSE) -> Le champ "Organisme d'origine" doit être alimenté si le type d'organisme d'origine est égal à 'Autre organisme', 'Fonction publique d'un état de l'Union Européenne' ou 'Fonction publique Européenne'. | BM17: POS_C_035 | BN17: =VLOOKUP(BM17,'Axe 2 Règles de gestion'!$D$2:$F$41,3, FALSE) -> Le champ "Code emploi statutaire FPT (NET)" est renseigné si le "Type d'organisme d'origine" est valorisé à FPT. | BO17: POS_C_036 | BP17: =VLOOKUP(BO17,'Axe 2 Règles de gestion'!$D$2:$F$41,3, FALSE) -> Le champ "Code emploi statutaire FPH (NEH)" est renseigné si le "Type d'organisme d'origine" est valorisé à FPH.
A18: 22.00.00 | B18: A | C18: 44711.428 | D18: D0004 | E18: Position | F18: S0011 | G18: Position normale d'activité entrante et entrante sortante | H18: E0159 | I18: Position normale d'activité entrante non payée ancien dispositif | J18: Position / Situation saisie égale à 'Position normale d'activité entrante non payée' ET Date de début position < 18/04/2020 | K18: A_POS_POSIAD [Saisi] = 'ACI0B' ET A_POS_DATEB [Saisi] < 18/04/2020 | L18: T0467 | M18: Position normale d'activité entrante non payée - Demande | N18: Création | Q18: Titulaire ou magistrat | R18: P0001 | S18: T | T18: Général | U18: Passant | V18: 43862 | W18: 43938 | X18: PNE_I_002 ET PNE_I_001 ET PNE_I_013 ET PNE_I_004 ET PNE_I_005 ET PNE_I_003 ET PNE_I_007 ET PNE_I_014 ET POS_C_005 ET POS_C_022 ET POS_C_010 ET POS_C_004 ET POS_C_007 ET POS_C_012 ET POS_C_030 ET POS_C_031 ET POS_C_034 ET POS_C_035 ET POS_C_036 | Y18: PNE_I_002 | Z18: =VLOOKUP(Y18,'Axe 2 Règles de gestion'!$D$2:$F$41,3, FALSE) -> L'agent doit effectuer une demande. | AA18: PNE_I_001 | AB18: =VLOOKUP(AA18,'Axe 2 Règles de gestion'!$D$2:$F$41,3, FALSE) -> L'affectation intervient à l'initiative de l'agent ou de l'administration. | AC18: PNE_I_013 | AD18: =VLOOKUP(AC18,'Axe 2 Règles de gestion'!$D$2:$F$41,3, FALSE) -> L'administration ne peut s'opposer au changement d'affectation d'un agent qui a obtenu l'accord de l'organisme d'accueil que pour des motifs liés aux nécessités du service ou à un avis rendu par la Haute Autorité pour la transparence de la vie publique. | AE18: PNE_I_004 | AF18: =VLOOKUP(AE18,'Axe 2 Règles de gestion'!$D$2:$F$41,3, FALSE) -> Un avis conforme de l'administration d'accueil a préalablement été transmis à l'administration d'origine sauf dans le cadre d'un transfert de service. | AG18: PNE_I_005 | AH18: =VLOOKUP(AG18,'Axe 2 Règles de gestion'!$D$2:$F$41,3, FALSE) -> Lorsque l'affectation de l'agent est prononcée dans un établissement public, le ministère de tutelle en est préalablement informé. | AI18: PNE_I_003 | AJ18: =VLOOKUP(AI18,'Axe 2 Règles de gestion'!$D$2:$F$41,3, FALSE) -> L'affectation en position normale d'activité hors de l'administration d'origine est prononcée sans limitation de durée. | AK18: PNE_I_007 | AL18: =VLOOKUP(AK18,'Axe 2 Règles de gestion'!$D$2:$F$41,3, FALSE) -> L'administration peut exiger que l'agent respecte un délai maximal de préavis de 3 mois. Ce délai peut être porté à une durée plus longue, qui ne saurait toutefois excéder 6 mois. | AM18: PNE_I_014 | AN18: =VLOOKUP(AM18,'Axe 2 Règles de gestion'!$D$2:$F$41,3, FALSE) -> Le silence de l'administration gardé pendant 2 mois à compter de la réception de la demande de l'agent vaut acceptation. | AU18: POS_C_005 | AV18: =VLOOKUP(AU18,'Axe 2 Règles de gestion'!$D$2:$F$41,3, FALSE) -> La date de début de la position doit être postérieure ou égale à la date d'entrée dans la FPE ou dans la carrière militaire. | AW18: POS_C_022 | AX18: =VLOOKUP(AW18,'Axe 2 Règles de gestion'!$D$2:$F$41,3, FALSE) -> La date de début de position est à J+1 de la date de fin de position de l'occurrence précédente. | AY18: POS_C_010 | AZ18: =VLOOKUP(AY18,'Axe 2 Règles de gestion'!$D$2:$F$41,3, FALSE) -> La date de début de position doit être antérieure ou égale à la date de fin réelle de position. | BA18: POS_C_004 | BB18: =VLOOKUP(BA18,'Axe 2 Règles de gestion'!$D$2:$F$41,3, FALSE) -> La date de début de position doit être antérieure ou égale à la date de fin prévisionnelle de position. | BC18: POS_C_007 | BD18: =VLOOKUP(BC18,'Axe 2 Règles de gestion'!$D$2:$F$41,3, FALSE) -> La date de fin réelle de la position doit être antérieure à la date limite de départ à la retraite. | BE18: POS_C_012 | BF18: =VLOOKUP(BE18,'Axe 2 Règles de gestion'!$D$2:$F$41,3, FALSE) -> La date de fin prévisionnelle de la position doit être antérieure à la date limite de départ à la retraite. | BG18: POS_C_030 | BH18: =VLOOKUP(BG18,'Axe 2 Règles de gestion'!$D$2:$F$41,3, FALSE) -> Les champs "Type d'organisme d'origine", "Catégorie statutaire d'origine" et "Pays" de l'organisme d'origine doivent être renseignés. | BI18: POS_C_031 | BJ18: =VLOOKUP(BI18,'Axe 2 Règles de gestion'!$D$2:$F$41,3, FALSE) -> Les champs "Ministère (ou institution de la République) d'origine", "Corps d'origine", "Grade d'origine", "Echelon d'origine" sont renseignés si le "Type d'organisme d'origine" est valorisé à FPE. | BK18: POS_C_034 | BL18: =VLOOKUP(BK18,'Axe 2 Règles de gestion'!$D$2:$F$41,3, FALSE) -> Le champ "Organisme d'origine" doit être alimenté si le type d'organisme d'origine est égal à 'Autre organisme', 'Fonction publique d'un état de l'Union Européenne' ou 'Fonction publique Européenne'. | BM18: POS_C_035 | BN18: =VLOOKUP(BM18,'Axe 2 Règles de gestion'!$D$2:$F$41,3, FALSE) -> Le champ "Code emploi statutaire FPT (NET)" est renseigné si le "Type d'organisme d'origine" est valorisé à FPT. | BO18: POS_C_036 | BP18: =VLOOKUP(BO18,'Axe 2 Règles de gestion'!$D$2:$F$41,3, FALSE) -> Le champ "Code emploi statutaire FPH (NEH)" est renseigné si le "Type d'organisme d'origine" est valorisé à FPH.
A19: 20.00.00 | B19: M | C19: 43999.456 | D19: D0004 | E19: Position | F19: S0011 | G19: Position normale d'activité entrante et entrante sortante | H19: E0159 | I19: Position normale d'activité entrante non payée ancien dispositif | J19: Position / Situation saisie égale à 'Position normale d'activité entrante non payée' ET Date de début position < 18/04/2020 | K19: A_POS_POSIAD [Saisi] = 'ACI0B' ET A_POS_DATEB [Saisi] < 18/04/2020 | L19: T0468 | M19: Position normale d'activité entrante non payée - Fin | N19: Modification | Q19: Titulaire ou magistrat | R19: P0001 | S19: T | T19: Général | U19: Passant | V19: 40725 | W19: 43938 | X19: PNE_I_003 ET POS_C_010 ET POS_C_004 ET POS_C_007 ET POS_C_012 ET POS_C_030 ET POS_C_031 ET POS_C_034 ET POS_C_035 ET POS_C_036 | Y19: PNE_I_003 | Z19: =VLOOKUP(Y19,'Axe 2 Règles de gestion'!$D$2:$F$41,3, FALSE) -> L'affectation en position normale d'activité hors de l'administration d'origine est prononcée sans limitation de durée. | AU19: POS_C_010 | AV19: =VLOOKUP(AU19,'Axe 2 Règles de gestion'!$D$2:$F$41,3, FALSE) -> La date de début de position doit être antérieure ou égale à la date de fin réelle de position. | AW19: POS_C_004 | AX19: =VLOOKUP(AW19,'Axe 2 Règles de gestion'!$D$2:$F$41,3, FALSE) -> La date de début de position doit être antérieure ou égale à la date de fin prévisionnelle de position. | AY19: POS_C_007 | AZ19: =VLOOKUP(AY19,'Axe 2 Règles de gestion'!$D$2:$F$41,3, FALSE) -> La date de fin réelle de la position doit être antérieure à la date limite de départ à la retraite. | BA19: POS_C_012 | BB19: =VLOOKUP(BA19,'Axe 2 Règles de gestion'!$D$2:$F$41,3, FALSE) -> La date de fin prévisionnelle de la position doit être antérieure à la date limite de départ à la retraite. | BC19: POS_C_030 | BD19: =VLOOKUP(BC19,'Axe 2 Règles de gestion'!$D$2:$F$41,3, FALSE) -> Les champs "Type d'organisme d'origine", "Catégorie statutaire d'origine" et "Pays" de l'organisme d'origine doivent être renseignés. | BE19: POS_C_031 | BF19: =VLOOKUP(BE19,'Axe 2 Règles de gestion'!$D$2:$F$41,3, FALSE) -> Les champs "Ministère (ou institution de la République) d'origine", "Corps d'origine", "Grade d'origine", "Echelon d'origine" sont renseignés si le "Type d'organisme d'origine" est valorisé à FPE. | BG19: POS_C_034 | BH19: =VLOOKUP(BG19,'Axe 2 Règles de gestion'!$D$2:$F$41,3, FALSE) -> Le champ "Organisme d'origine" doit être alimenté si le type d'organisme d'origine est égal à 'Autre organisme', 'Fonction publique d'un état de l'Union Européenne' ou 'Fonction publique Européenne'. | BI19: POS_C_035 | BJ19: =VLOOKUP(BI19,'Axe 2 Règles de gestion'!$D$2:$F$41,3, FALSE) -> Le champ "Code emploi statutaire FPT (NET)" est renseigné si le "Type d'organisme d'origine" est valorisé à FPT. | BK19: POS_C_036 | BL19: =VLOOKUP(BK19,'Axe 2 Règles de gestion'!$D$2:$F$41,3, FALSE) -> Le champ "Code emploi statutaire FPH (NEH)" est renseigné si le "Type d'organisme d'origine" est valorisé à FPH.
A20: 20.00.00 | B20: M | C20: 43999.645 | D20: D0004 | E20: Position | F20: S0011 | G20: Position normale d'activité entrante et entrante sortante | H20: E0159 | I20: Position normale d'activité entrante non payée ancien dispositif | J20: Position / Situation saisie égale à 'Position normale d'activité entrante non payée' ET Date de début position < 18/04/2020 | K20: A_POS_POSIAD [Saisi] = 'ACI0B' ET A_POS_DATEB [Saisi] < 18/04/2020 | L20: T0467 | M20: Position normale d'activité entrante non payée - Demande | N20: Création | Q20: Militaire | R20: P0002 | S20: M | T20: Général | U20: Exclu | V20: 40725 | W20: 43938
A21: 20.00.00 | B21: M | C21: 43999.647 | D21: D0004 | E21: Position | F21: S0011 | G21: Position normale d'activité entrante et entrante sortante | H21: E0159 | I21: Position normale d'activité entrante non payée ancien dispositif | J21: Position / Situation saisie égale à 'Position normale d'activité entrante non payée' ET Date de début position < 18/04/2020 | K21: A_POS_POSIAD [Saisi] = 'ACI0B' ET A_POS_DATEB [Saisi] < 18/04/2020 | L21: T0468 | M21: Position normale d'activité entrante non payée - Fin | N21: Modification | Q21: Militaire | R21: P0002 | S21: M | T21: Général | U21: Exclu | V21: 40725 | W21: 43938
A22: 20.00.00 | B22: M | C22: 43999.646 | D22: D0004 | E22: Position | F22: S0011 | G22: Position normale d'activité entrante et entrante sortante | H22: E0159 | I22: Position normale d'activité entrante non payée ancien dispositif | J22: Position / Situation saisie égale à 'Position normale d'activité entrante non payée' ET Date de début position < 18/04/2020 | K22: A_POS_POSIAD [Saisi] = 'ACI0B' ET A_POS_DATEB [Saisi] < 18/04/2020 | L22: T0467 | M22: Position normale d'activité entrante non payée - Demande | N22: Création | Q22: Contractuel | R22: P0003 | S22: N | T22: Général | U22: Exclu | V22: 40725 | W22: 43938
A23: 20.00.00 | B23: M | C23: 43999.647 | D23: D0004 | E23: Position | F23: S0011 | G23: Position normale d'activité entrante et entrante sortante | H23: E0159 | I23: Position normale d'activité entrante non payée ancien dispositif | J23: Position / Situation saisie égale à 'Position normale d'activité entrante non payée' ET Date de début position < 18/04/2020 | K23: A_POS_POSIAD [Saisi] = 'ACI0B' ET A_POS_DATEB [Saisi] < 18/04/2020 | L23: T0468 | M23: Position normale d'activité entrante non payée - Fin | N23: Modification | Q23: Contractuel | R23: P0003 | S23: N | T23: Général | U23: Exclu | V23: 40725 | W23: 43938
A24: 22.00.00 | B24: M | C24: 44711.435 | D24: D0004 | E24: Position | F24: S0011 | G24: Position normale d'activité entrante et entrante sortante | H24: E0159 | I24: Position normale d'activité entrante non payée ancien dispositif | J24: Position / Situation saisie égale à 'Position normale d'activité entrante non payée' ET Date de début position < 18/04/2020 | K24: A_POS_POSIAD [Saisi] = 'ACI0B' ET A_POS_DATEB [Saisi] < 18/04/2020 | L24: T0467 | M24: Position normale d'activité entrante non payée - Demande | N24: Création | Q24: Stagiaire ou auditeur ou élève | R24: P0004 | S24: S | T24: Général | U24: Passant | V24: 40725 | W24: 43938 | X24: PNE_I_002 ET PNE_I_001 ET PNE_I_004 ET PNE_I_005 ET PNE_I_003 ET POS_C_005 ET POS_C_022 ET POS_C_010 ET POS_C_004 ET POS_C_007 ET POS_C_012 ET POS_C_030 ET POS_C_031 ET POS_C_034 ET POS_C_035 ET POS_C_036 | Y24: PNE_I_002 | Z24: =VLOOKUP(Y24,'Axe 2 Règles de gestion'!$D$2:$F$41,3, FALSE) -> L'agent doit effectuer une demande. | AA24: PNE_I_001 | AB24: =VLOOKUP(AA24,'Axe 2 Règles de gestion'!$D$2:$F$41,3, FALSE) -> L'affectation intervient à l'initiative de l'agent ou de l'administration. | AC24: PNE_I_004 | AD24: =VLOOKUP(AC24,'Axe 2 Règles de gestion'!$D$2:$F$41,3, FALSE) -> Un avis conforme de l'administration d'accueil a préalablement été transmis à l'administration d'origine sauf dans le cadre d'un transfert de service. | AE24: PNE_I_005 | AF24: =VLOOKUP(AE24,'Axe 2 Règles de gestion'!$D$2:$F$41,3, FALSE) -> Lorsque l'affectation de l'agent est prononcée dans un établissement public, le ministère de tutelle en est préalablement informé. | AG24: PNE_I_003 | AH24: =VLOOKUP(AG24,'Axe 2 Règles de gestion'!$D$2:$F$41,3, FALSE) -> L'affectation en position normale d'activité hors de l'administration d'origine est prononcée sans limitation de durée. | AU24: POS_C_005 | AV24: =VLOOKUP(AU24,'Axe 2 Règles de gestion'!$D$2:$F$41,3, FALSE) -> La date de début de la position doit être postérieure ou égale à la date d'entrée dans la FPE ou dans la carrière militaire. | AW24: POS_C_022 | AX24: =VLOOKUP(AW24,'Axe 2 Règles de gestion'!$D$2:$F$41,3, FALSE) -> La date de début de position est à J+1 de la date de fin de position de l'occurrence précédente. | AY24: POS_C_010 | AZ24: =VLOOKUP(AY24,'Axe 2 Règles de gestion'!$D$2:$F$41,3, FALSE) -> La date de début de position doit être antérieure ou égale à la date de fin réelle de position. | BA24: POS_C_004 | BB24: =VLOOKUP(BA24,'Axe 2 Règles de gestion'!$D$2:$F$41,3, FALSE) -> La date de début de position doit être antérieure ou égale à la date de fin prévisionnelle de position. | BC24: POS_C_007 | BD24: =VLOOKUP(BC24,'Axe 2 Règles de gestion'!$D$2:$F$41,3, FALSE) -> La date de fin réelle de la position doit être antérieure à la date limite de départ à la retraite. | BE24: POS_C_012 | BF24: =VLOOKUP(BE24,'Axe 2 Règles de gestion'!$D$2:$F$41,3, FALSE) -> La date de fin prévisionnelle de la position doit être antérieure à la date limite de départ à la retraite. | BG24: POS_C_030 | BH24: =VLOOKUP(BG24,'Axe 2 Règles de gestion'!$D$2:$F$41,3, FALSE) -> Les champs "Type d'organisme d'origine", "Catégorie statutaire d'origine" et "Pays" de l'organisme d'origine doivent être renseignés. | BI24: POS_C_031 | BJ24: =VLOOKUP(BI24,'Axe 2 Règles de gestion'!$D$2:$F$41,3, FALSE) -> Les champs "Ministère (ou institution de la République) d'origine", "Corps d'origine", "Grade d'origine", "Echelon d'origine" sont renseignés si le "Type d'organisme d'origine" est valorisé à FPE. | BK24: POS_C_034 | BL24: =VLOOKUP(BK24,'Axe 2 Règles de gestion'!$D$2:$F$41,3, FALSE) -> Le champ "Organisme d'origine" doit être alimenté si le type d'organisme d'origine est égal à 'Autre organisme', 'Fonction publique d'un état de l'Union Européenne' ou 'Fonction publique Européenne'. | BM24: POS_C_035 | BN24: =VLOOKUP(BM24,'Axe 2 Règles de gestion'!$D$2:$F$41,3, FALSE) -> Le champ "Code emploi statutaire FPT (NET)" est renseigné si le "Type d'organisme d'origine" est valorisé à FPT. | BO24: POS_C_036 | BP24: =VLOOKUP(BO24,'Axe 2 Règles de gestion'!$D$2:$F$41,3, FALSE) -> Le champ "Code emploi statutaire FPH (NEH)" est renseigné si le "Type d'organisme d'origine" est valorisé à FPH.
A25: 20.00.00 | B25: M | C25: 43999.456 | D25: D0004 | E25: Position | F25: S0011 | G25: Position normale d'activité entrante et entrante sortante | H25: E0159 | I25: Position normale d'activité entrante non payée ancien dispositif | J25: Position / Situation saisie égale à 'Position normale d'activité entrante non payée' ET Date de début position < 18/04/2020 | K25: A_POS_POSIAD [Saisi] = 'ACI0B' ET A_POS_DATEB [Saisi] < 18/04/2020 | L25: T0468 | M25: Position normale d'activité entrante non payée - Fin | N25: Modification | Q25: Stagiaire ou auditeur ou élève | R25: P0004 | S25: S | T25: Général | U25: Passant | V25: 40725 | W25: 43938 | X25: PNE_I_003 ET POS_C_010 ET POS_C_004 ET POS_C_007 ET POS_C_012 ET POS_C_030 ET POS_C_031 ET POS_C_034 ET POS_C_035 ET POS_C_036 | Y25: PNE_I_003 | Z25: =VLOOKUP(Y25,'Axe 2 Règles de gestion'!$D$2:$F$41,3, FALSE) -> L'affectation en position normale d'activité hors de l'administration d'origine est prononcée sans limitation de durée. | AU25: POS_C_010 | AV25: =VLOOKUP(AU25,'Axe 2 Règles de gestion'!$D$2:$F$41,3, FALSE) -> La date de début de position doit être antérieure ou égale à la date de fin réelle de position. | AW25: POS_C_004 | AX25: =VLOOKUP(AW25,'Axe 2 Règles de gestion'!$D$2:$F$41,3, FALSE) -> La date de début de position doit être antérieure ou égale à la date de fin prévisionnelle de position. | AY25: POS_C_007 | AZ25: =VLOOKUP(AY25,'Axe 2 Règles de gestion'!$D$2:$F$41,3, FALSE) -> La date de fin réelle de la position doit être antérieure à la date limite de départ à la retraite. | BA25: POS_C_012 | BB25: =VLOOKUP(BA25,'Axe 2 Règles de gestion'!$D$2:$F$41,3, FALSE) -> La date de fin prévisionnelle de la position doit être antérieure à la date limite de départ à la retraite. | BC25: POS_C_030 | BD25: =VLOOKUP(BC25,'Axe 2 Règles de gestion'!$D$2:$F$41,3, FALSE) -> Les champs "Type d'organisme d'origine", "Catégorie statutaire d'origine" et "Pays" de l'organisme d'origine doivent être renseignés. | BE25: POS_C_031 | BF25: =VLOOKUP(BE25,'Axe 2 Règles de gestion'!$D$2:$F$41,3, FALSE) -> Les champs "Ministère (ou institution de la République) d'origine", "Corps d'origine", "Grade d'origine", "Echelon d'origine" sont renseignés si le "Type d'organisme d'origine" est valorisé à FPE. | BG25: POS_C_034 | BH25: =VLOOKUP(BG25,'Axe 2 Règles de gestion'!$D$2:$F$41,3, FALSE) -> Le champ "Organisme d'origine" doit être alimenté si le type d'organisme d'origine est égal à 'Autre organisme', 'Fonction publique d'un état de l'Union Européenne' ou 'Fonction publique Européenne'. | BI25: POS_C_035 | BJ25: =VLOOKUP(BI25,'Axe 2 Règles de gestion'!$D$2:$F$41,3, FALSE) -> Le champ "Code emploi statutaire FPT (NET)" est renseigné si le "Type d'organisme d'origine" est valorisé à FPT. | BK25: POS_C_036 | BL25: =VLOOKUP(BK25,'Axe 2 Règles de gestion'!$D$2:$F$41,3, FALSE) -> Le champ "Code emploi statutaire FPH (NEH)" est renseigné si le "Type d'organisme d'origine" est valorisé à FPH.
A26: 20.00.00 | B26: M | C26: 43999.646 | D26: D0004 | E26: Position | F26: S0011 | G26: Position normale d'activité entrante et entrante sortante | H26: E0159 | I26: Position normale d'activité entrante non payée ancien dispositif | J26: Position / Situation saisie égale à 'Position normale d'activité entrante non payée' ET Date de début position < 18/04/2020 | K26: A_POS_POSIAD [Saisi] = 'ACI0B' ET A_POS_DATEB [Saisi] < 18/04/2020 | L26: T0467 | M26: Position normale d'activité entrante non payée - Demande | N26: Création | Q26: Ouvrier d'état | R26: P0005 | S26: O | T26: Général | U26: Exclu | V26: 40725 | W26: 43938
A27: 20.00.00 | B27: M | C27: 43999.647 | D27: D0004 | E27: Position | F27: S0011 | G27: Position normale d'activité entrante et entrante sortante | H27: E0159 | I27: Position normale d'activité entrante non payée ancien dispositif | J27: Position / Situation saisie égale à 'Position normale d'activité entrante non payée' ET Date de début position < 18/04/2020 | K27: A_POS_POSIAD [Saisi] = 'ACI0B' ET A_POS_DATEB [Saisi] < 18/04/2020 | L27: T0468 | M27: Position normale d'activité entrante non payée - Fin | N27: Modification | Q27: Ouvrier d'état | R27: P0005 | S27: O | T27: Général | U27: Exclu | V27: 40725 | W27: 43938
A28: 20.00.00 | B28: M | C28: 43999.645 | D28: D0004 | E28: Position | F28: S0011 | G28: Position normale d'activité entrante et entrante sortante | H28: E0159 | I28: Position normale d'activité entrante non payée ancien dispositif | J28: Position / Situation saisie égale à 'Position normale d'activité entrante non payée' ET Date de début position < 18/04/2020 | K28: A_POS_POSIAD [Saisi] = 'ACI0B' ET A_POS_DATEB [Saisi] < 18/04/2020 | L28: T0467 | M28: Position normale d'activité entrante non payée - Demande | N28: Création | Q28: Magistrat de l'ordre judiciaire | R28: P0007 | S28: T | T28: Particulier | U28: Exclu | V28: 40725 | W28: 43938
A29: 20.00.00 | B29: M | C29: 43999.647 | D29: D0004 | E29: Position | F29: S0011 | G29: Position normale d'activité entrante et entrante sortante | H29: E0159 | I29: Position normale d'activité entrante non payée ancien dispositif | J29: Position / Situation saisie égale à 'Position normale d'activité entrante non payée' ET Date de début position < 18/04/2020 | K29: A_POS_POSIAD [Saisi] = 'ACI0B' ET A_POS_DATEB [Saisi] < 18/04/2020 | L29: T0468 | M29: Position normale d'activité entrante non payée - Fin | N29: Modification | Q29: Magistrat de l'ordre judiciaire | R29: P0007 | S29: T | T29: Particulier | U29: Exclu | V29: 40725 | W29: 43938
A30: 20.00.00 | B30: M | C30: 43999.644 | D30: D0004 | E30: Position | F30: S0011 | G30: Position normale d'activité entrante et entrante sortante | H30: E0159 | I30: Position normale d'activité entrante non payée ancien dispositif | J30: Position / Situation saisie égale à 'Position normale d'activité entrante non payée' ET Date de début position < 18/04/2020 | K30: A_POS_POSIAD [Saisi] = 'ACI0B' ET A_POS_DATEB [Saisi] < 18/04/2020 | L30: T0467 | M30: Position normale d'activité entrante non payée - Demande | N30: Création | Q30: Auditeur de justice ou élève | R30: P0034 | S30: S | T30: Particulier | U30: Exclu | V30: 40725 | W30: 43938
A31: 20.00.00 | B31: M | C31: 43999.647 | D31: D0004 | E31: Position | F31: S0011 | G31: Position normale d'activité entrante et entrante sortante | H31: E0159 | I31: Position normale d'activité entrante non payée ancien dispositif | J31: Position / Situation saisie égale à 'Position normale d'activité entrante non payée' ET Date de début position < 18/04/2020 | K31: A_POS_POSIAD [Saisi] = 'ACI0B' ET A_POS_DATEB [Saisi] < 18/04/2020 | L31: T0468 | M31: Position normale d'activité entrante non payée - Fin | N31: Modification | Q31: Auditeur de justice ou élève | R31: P0034 | S31: S | T31: Particulier | U31: Exclu | V31: 40725 | W31: 43938
