Workbook

Sheet Mode opératoire
B1: MODE OPERATOIRE
B2: La description d'une position sortante dans un dossier agent, nécessite la MAJ des données portées par les 3 sous-rubriques suivantes : Position statutaire/situation administrative Détachement, affectation ou MAD sortant Compteurs de périodes de positions/situations La spécification métier regroupe au sein d'un évènement unique l'articulation des RG mobilisant des données appartenant à ces trois sous-rubriques. Ainsi, le métier considère que les données associées à ces trois sous rubriques sont mises à jour dans la même transaction. Les positions concernées sont les codes de positions mobilisés dans l'axe1.

Sheet Axe 1 Enchainement des RG
A1: Version | B1: Type de mise à jour | C1: Date de mise à jour | D1: Identifiant Domaine | E1: Libellé du Domaine | F1: Identifiant Sous-domaine | G1: Libellé du Sous-domaine | H1: Identifiant Evénement | I1: Libellé de l'évènement | J1: Libellé condition déclenchement Evènement | K1: Condition déclenchement Evènement | L1: Identifiant type d'évènement | M1: Libellé type d'évènement | N1: Type de mise à jour | O1: Libellé condition déclenchement Type Evènement | P1: Condition déclenchement Type Evènement | Q1: Libellé Population | R1: Codification Population | S1: Général / Particulier | T1: Passant / Exclu | U1: Date de début | V1: Date de fin | W1: Règles mobilisées | X1: Identifiant Règle de contrôle intellectuel 1 | Y1: Libellé Règle de contrôle intellectuel 1 | Z1: Identifiant Règle de contrôle intellectuel 2 | AA1: Libellé Règle de contrôle intellectuel 2 | AB1: Identifiant Règle de contrôle intellectuel 3 | AC1: Libellé Règle de contrôle intellectuel 3 | AD1: Identifiant Règle de contrôle intellectuel 4 | AE1: Libellé Règle de contrôle intellectuel 4 | AF1: Identifiant Règle de contrôle intellectuel 5 | AG1: Libellé Règle de contrôle intellectuel 5 | AH1: Identifiant Règle de contrôle intellectuel 6 | AI1: Libellé Règle de contrôle intellectuel 6 | AJ1: Identifiant Règle de contrôle intellectuel 7 | AK1: Libellé Règle de contrôle intellectuel 7 | AL1: Identifiant Règle de contrôle intellectuel 8 | AM1: Libellé Règle de contrôle intellectuel 8 | AN1: Identifiant Règle de contrôle intellectuel 9 | AO1: Libellé Règle de contrôle intellectuel 9 | AP1: Identifiant Règle de contrôle intellectuel 10 | AQ1: Libellé Règle de contrôle intellectuel 10 | AR1: Identifiant Règle de contrôle intellectuel 11 | AS1: Libellé Règle de contrôle intellectuel 11 | AT1: Identifiant Règle de contrôle intellectuel 12 | AU1: Libellé Règle de contrôle intellectuel 12 | AV1: Identifiant Règle de contrôle intellectuel 13 | AW1: Libellé Règle de contrôle intellectuel 13 | AX1: Identifiant Règle de contrôle intellectuel 14 | AY1: Libellé Règle de contrôle intellectuel 14 | AZ1: Identifiant Règle de contrôle intellectuel 15 | BA1: Libellé Règle de contrôle intellectuel 15 | BB1: Identifiant Règle de condition 1 | BC1: Libellé Règle de condition 1 | BD1: Identifiant Règle de condition 2 | BE1: Libellé Règle de condition 2 | BF1: Identifiant Règle de condition 3 | BG1: Libellé Règle de condition 3 | BH1: Identifiant Règle de condition 4 | BI1: Libellé Règle de condition 4 | BJ1: Identifiant Règle de condition 5 | BK1: Libellé Règle de condition 5 | BL1: Identifiant Règle de condition 6 | BM1: Libellé Règle de condition 6 | BN1: Identifiant Règle de condition 7 | BO1: Libellé Règle de condition 7 | BP1: Identifiant Règle de condition 8 | BQ1: Libellé Règle de condition 8 | BR1: Identifiant Règle de contrôle 1 | BS1: Libellé Règle de contrôle 1 | BT1: Identifiant Règle de contrôle 2 | BU1: Libellé Règle de contrôle 2 | BV1: Identifiant Règle de contrôle 3 | BW1: Libellé Règle de contrôle 3 | BX1: Identifiant Règle de contrôle 4 | BY1: Libellé Règle de contrôle 4 | BZ1: Identifiant Règle de contrôle 5 | CA1: Libellé Règle de contrôle 5 | CB1: Identifiant Règle de contrôle 6 | CC1: Libellé Règle de contrôle 6 | CD1: Identifiant Règle de contrôle 7 | CE1: Libellé Règle de contrôle 7 | CF1: Identifiant Règle de contrôle 8 | CG1: Libellé Règle de contrôle 8 | CH1: Identifiant Règle de contrôle 9 | CI1: Libellé Règle de contrôle 9 | CJ1: Identifiant Règle de contrôle 10 | CK1: Libellé Règle de contrôle 10 | CL1: Identifiant Règle de contrôle 11 | CM1: Libellé Règle de contrôle 11 | CN1: Identifiant Règle de contrôle 12 | CO1: Libellé Règle de contrôle 12 | CP1: Identifiant Règle de contrôle 13 | CQ1: Libellé Règle de contrôle 13 | CR1: Identifiant Règle de contrôle 14 | CS1: Libellé Règle de contrôle 14 | CT1: FIME | CU1: Statut de travail
A2: 23.00.00 | B2: M | C2: 45071.719 | D2: D0004 | E2: Position | F2: S0017 | G2: Mise à disposition sortante | H2: E0202 | I2: MAD sortante à titre gratuit auprès d'une autre administration ou d'un EPA de l'Etat | J2: Position administrative saisie égale à 'MAD sortante à titre gratuit auprès d'une autre administration ou d'un EPA de l'Etat' | K2: A_POS_POSIAD [Saisi] = 'MAD11' | L2: T0592 | M2: MADS à titre gratuit auprès d'une autre administration ou d'un EPA de l'Etat - Demande | N2: Création Modification | O2: Indicateur Renouvellement Position est non activé ET l'indicateur de renouvellement saisi est différent de l'indicateur de renouvellement avant saisie | P2: A_POS_INDREN [Saisi] = '0' ET A_POS_INDREN [Saisi] <> A_POS_INDREN [Valeur avant saisie] | Q2: Titulaire ou magistrat | R2: P0001 | S2: Général | T2: Passant | U2: 40725 | V2: 44497 | W2: MAD_I_001 ET MAD_I_002 ET MAD_I_003 ET MAD_I_006 ET MAD_I_009 ET MAD_I_004 ET MAD_I_005 ET MAD_I_008 ET MAD_I_007 ET MAD_I_026 ET MAD_I_025 ET MAD_I_027 ET MAD_D_011 ET MAD_D_411 ET MAD_D_001 ET POS_C_004 ET POS_C_005 ET POS_C_007 ET POS_C_010 ET POS_C_012 ET POS_C_022 ET POS_C_037 ET POS_C_111 ET POS_C_431 ET POS_C_434 | X2: MAD_I_001 | Y2: =VLOOKUP(X2,'Axe 2 Règles de gestion'!$D$2:$F$271,3, FALSE) -> Les statuts particuliers peuvent prévoir des conditions d'âge ou d'ancienneté comme pré requis à une mise à disposition sortante. | Z2: MAD_I_002 | AA2: =VLOOKUP(Z2,'Axe 2 Règles de gestion'!$D$2:$F$271,3, FALSE) -> L'agent peut être mis à disposition d'un ou plusieurs organismes d'accueil. | AB2: MAD_I_003 | AC2: =VLOOKUP(AB2,'Axe 2 Règles de gestion'!$D$2:$F$271,3, FALSE) -> L'agent peut être mis à disposition pour tout ou partie de son service. | AD2: MAD_I_006 | AE2: =VLOOKUP(AD2,'Axe 2 Règles de gestion'!$D$2:$F$271,3, FALSE) -> L'accord du ou des organismes d'accueil est nécessaire. | AF2: MAD_I_009 | AG2: =VLOOKUP(AF2,'Axe 2 Règles de gestion'!$D$2:$F$271,3, FALSE) -> En cas de pluralité d'organismes d'accueil, autant de conventions sont nécessaires. | AH2: MAD_I_004 | AI2: =VLOOKUP(AH2,'Axe 2 Règles de gestion'!$D$2:$F$271,3, FALSE) -> La convention ou les conventions doivent être transmises à l'agent avant signature. | AJ2: MAD_I_005 | AK2: =VLOOKUP(AJ2,'Axe 2 Règles de gestion'!$D$2:$F$271,3, FALSE) -> L'accord de l'agent est nécessaire. | AL2: MAD_I_008 | AM2: =VLOOKUP(AL2,'Axe 2 Règles de gestion'!$D$2:$F$271,3, FALSE) -> Une convention entre l'organisme d'origine et l'organisme d'accueil doit être signée. | AN2: MAD_I_007 | AO2: =VLOOKUP(AN2,'Axe 2 Règles de gestion'!$D$2:$F$271,3, FALSE) -> La mise à disposition est prononcée par arrêté du ministre dont relève l'agent, ou par arrêté du préfet dont relève l'agent, ou par décision de l'autorité investie du pouvoir de nomination dans l'établissement. | AP2: MAD_I_026 | AQ2: =VLOOKUP(AP2,'Axe 2 Règles de gestion'!$D$2:$F$271,3, FALSE) -> La modification d'un des éléments constitutifs de la convention doit faire l'objet d'un avenant à cette convention. | AR2: MAD_I_025 | AS2: =VLOOKUP(AR2,'Axe 2 Règles de gestion'!$D$2:$F$271,3, FALSE) -> Tout avenant implique la même procédure notamment l'accord de l'agent et du (ou des) organisme(s) d'accueil, les arrêtés ou les décisions. | AT2: MAD_I_027 | AU2: =VLOOKUP(AT2,'Axe 2 Règles de gestion'!$D$2:$F$271,3, FALSE) -> Les avenants à la convention doivent être transmis à l'agent avant signature. | BB2: MAD_D_011 | BC2: =VLOOKUP(BB2,'Axe 2 Règles de gestion'!$D$2:$F$271,3, FALSE) -> La durée prévisionnelle est fixée à 3 ans maximum renouvelable pour chaque période. | BD2: MAD_D_411 | BE2: =VLOOKUP(BD2,'Axe 2 Règles de gestion'!$D$2:$F$271,3, FALSE) -> La durée réelle est fixée à 3 ans maximum renouvelable pour chaque période. | BF2: MAD_D_001 | BG2: =VLOOKUP(BF2,'Axe 2 Règles de gestion'!$D$2:$F$271,3, FALSE) -> L'agent doit être en activité. | BR2: POS_C_004 | BS2: =VLOOKUP(BR2,'Axe 2 Règles de gestion'!$D$2:$F$271,3, FALSE) -> La date de début de position doit être antérieure ou égale à la date de fin prévisionnelle de position. | BT2: POS_C_005 | BU2: =VLOOKUP(BT2,'Axe 2 Règles de gestion'!$D$2:$F$271,3, FALSE) -> La date de début de la position doit être postérieure ou égale à la date d'entrée dans la FPE ou dans la carrière militaire. | BV2: POS_C_007 | BW2: =VLOOKUP(BV2,'Axe 2 Règles de gestion'!$D$2:$F$271,3, FALSE) -> La date de fin réelle de la position doit être antérieure à la date limite de départ à la retraite. | BX2: POS_C_010 | BY2: =VLOOKUP(BX2,'Axe 2 Règles de gestion'!$D$2:$F$271,3, FALSE) -> La date de début de position doit être antérieure ou égale à la date de fin réelle de position. | BZ2: POS_C_012 | CA2: =VLOOKUP(BZ2,'Axe 2 Règles de gestion'!$D$2:$F$271,3, FALSE) -> La date de fin prévisionnelle de la position doit être antérieure à la date limite de départ à la retraite. | CB2: POS_C_022 | CC2: =VLOOKUP(CB2,'Axe 2 Règles de gestion'!$D$2:$F$271,3, FALSE) -> La date de début de position est à J+1 de la date de fin de position de l'occurrence précédente. | CD2: POS_C_037 | CE2: =VLOOKUP(CD2,'Axe 2 Règles de gestion'!$D$2:$F$271,3, FALSE) -> Les champs "Type d'organisme d'accueil" et "Pays" de l'organisme d'accueil doivent être renseignés. | CF2: POS_C_111 | CG2: =VLOOKUP(CF2,'Axe 2 Règles de gestion'!$D$2:$F$271,3, FALSE) -> La date de fin ou la date de fin prévisionnelle doit être saisie. | CH2: POS_C_431 | CI2: =VLOOKUP(CH2,'Axe 2 Règles de gestion'!$D$2:$F$271,3, FALSE) -> Les champs "Ministère (ou institution de la République) d'accueil", "Corps d'accueil en détachement" et "Grade d'accueil en détachement" ou "Ministère (ou institution de la République) d'accueil", "Emploi fonctionnel d'accueil en détachement" et "Groupe dans un emploi fonctionnel d'accueil" sont renseignés si le "Type d'organisme d'accueil" est valorisé à FPE. | CJ2: POS_C_434 | CK2: =VLOOKUP(CJ2,'Axe 2 Règles de gestion'!$D$2:$F$271,3, FALSE) -> Le champ "Organisme d'accueil" doit être alimenté si le type d'organisme d'accueil est égal à 'Autre organisme', 'Fonction publique d'un état de l'Union Européenne' ou 'Fonction publique Européenne'.
A3: 23.00.00 | B3: A | C3: 45071.719 | D3: D0004 | E3: Position | F3: S0017 | G3: Mise à disposition sortante | H3: E0202 | I3: MAD sortante à titre gratuit auprès d'une autre administration ou d'un EPA de l'Etat | J3: Position administrative saisie égale à 'MAD sortante à titre gratuit auprès d'une autre administration ou d'un EPA de l'Etat' | K3: A_POS_POSIAD [Saisi] = 'MAD11' | L3: T0592 | M3: MADS à titre gratuit auprès d'une autre administration ou d'un EPA de l'Etat - Demande | N3: Création Modification | O3: Indicateur Renouvellement Position est non activé ET l'indicateur de renouvellement saisi est différent de l'indicateur de renouvellement avant saisie | P3: A_POS_INDREN [Saisi] = '0' ET A_POS_INDREN [Saisi] <> A_POS_INDREN [Valeur avant saisie] | Q3: Titulaire ou magistrat | R3: P0001 | S3: Général | T3: Passant | U3: 44498 | W3: MAD_I_001 ET MAD_I_002 ET MAD_I_003 ET MAD_I_006 ET MAD_I_009 ET MAD_I_004 ET MAD_I_005 ET MAD_I_008 ET MAD_I_007 ET MAD_I_026 ET MAD_I_025 ET MAD_I_027 ET MAD_D_011 ET MAD_D_411 ET MAD_D_001 ET POS_C_004 ET POS_C_005 ET POS_C_007 ET POS_C_010 ET POS_C_012 ET POS_C_022 ET POS_C_037 ET POS_C_111 ET POS_C_431 ET POS_C_434 | X3: MAD_I_001 | Y3: =VLOOKUP(X3,'Axe 2 Règles de gestion'!$D$2:$F$271,3, FALSE) -> Les statuts particuliers peuvent prévoir des conditions d'âge ou d'ancienneté comme pré requis à une mise à disposition sortante. | Z3: MAD_I_002 | AA3: =VLOOKUP(Z3,'Axe 2 Règles de gestion'!$D$2:$F$271,3, FALSE) -> L'agent peut être mis à disposition d'un ou plusieurs organismes d'accueil. | AB3: MAD_I_003 | AC3: =VLOOKUP(AB3,'Axe 2 Règles de gestion'!$D$2:$F$271,3, FALSE) -> L'agent peut être mis à disposition pour tout ou partie de son service. | AD3: MAD_I_006 | AE3: =VLOOKUP(AD3,'Axe 2 Règles de gestion'!$D$2:$F$271,3, FALSE) -> L'accord du ou des organismes d'accueil est nécessaire. | AF3: MAD_I_009 | AG3: =VLOOKUP(AF3,'Axe 2 Règles de gestion'!$D$2:$F$271,3, FALSE) -> En cas de pluralité d'organismes d'accueil, autant de conventions sont nécessaires. | AH3: MAD_I_004 | AI3: =VLOOKUP(AH3,'Axe 2 Règles de gestion'!$D$2:$F$271,3, FALSE) -> La convention ou les conventions doivent être transmises à l'agent avant signature. | AJ3: MAD_I_005 | AK3: =VLOOKUP(AJ3,'Axe 2 Règles de gestion'!$D$2:$F$271,3, FALSE) -> L'accord de l'agent est nécessaire. | AL3: MAD_I_008 | AM3: =VLOOKUP(AL3,'Axe 2 Règles de gestion'!$D$2:$F$271,3, FALSE) -> Une convention entre l'organisme d'origine et l'organisme d'accueil doit être signée. | AN3: MAD_I_007 | AO3: =VLOOKUP(AN3,'Axe 2 Règles de gestion'!$D$2:$F$271,3, FALSE) -> La mise à disposition est prononcée par arrêté du ministre dont relève l'agent, ou par arrêté du préfet dont relève l'agent, ou par décision de l'autorité investie du pouvoir de nomination dans l'établissement. | AP3: MAD_I_026 | AQ3: =VLOOKUP(AP3,'Axe 2 Règles de gestion'!$D$2:$F$271,3, FALSE) -> La modification d'un des éléments constitutifs de la convention doit faire l'objet d'un avenant à cette convention. | AR3: MAD_I_025 | AS3: =VLOOKUP(AR3,'Axe 2 Règles de gestion'!$D$2:$F$271,3, FALSE) -> Tout avenant implique la même procédure notamment l'accord de l'agent et du (ou des) organisme(s) d'accueil, les arrêtés ou les décisions. | AT3: MAD_I_027 | AU3: =VLOOKUP(AT3,'Axe 2 Règles de gestion'!$D$2:$F$271,3, FALSE) -> Les avenants à la convention doivent être transmis à l'agent avant signature. | BB3: MAD_D_011 | BC3: =VLOOKUP(BB3,'Axe 2 Règles de gestion'!$D$2:$F$271,3, FALSE) -> La durée prévisionnelle est fixée à 3 ans maximum renouvelable pour chaque période. | BD3: MAD_D_411 | BE3: =VLOOKUP(BD3,'Axe 2 Règles de gestion'!$D$2:$F$271,3, FALSE) -> La durée réelle est fixée à 3 ans maximum renouvelable pour chaque période. | BF3: MAD_D_001 | BG3: =VLOOKUP(BF3,'Axe 2 Règles de gestion'!$D$2:$F$271,3, FALSE) -> L'agent doit être en activité. | BR3: POS_C_004 | BS3: =VLOOKUP(BR3,'Axe 2 Règles de gestion'!$D$2:$F$271,3, FALSE) -> La date de début de position doit être antérieure ou égale à la date de fin prévisionnelle de position. | BT3: POS_C_005 | BU3: =VLOOKUP(BT3,'Axe 2 Règles de gestion'!$D$2:$F$271,3, FALSE) -> La date de début de la position doit être postérieure ou égale à la date d'entrée dans la FPE ou dans la carrière militaire. | BV3: POS_C_007 | BW3: =VLOOKUP(BV3,'Axe 2 Règles de gestion'!$D$2:$F$271,3, FALSE) -> La date de fin réelle de la position doit être antérieure à la date limite de départ à la retraite. | BX3: POS_C_010 | BY3: =VLOOKUP(BX3,'Axe 2 Règles de gestion'!$D$2:$F$271,3, FALSE) -> La date de début de position doit être antérieure ou égale à la date de fin réelle de position. | BZ3: POS_C_012 | CA3: =VLOOKUP(BZ3,'Axe 2 Règles de gestion'!$D$2:$F$271,3, FALSE) -> La date de fin prévisionnelle de la position doit être antérieure à la date limite de départ à la retraite. | CB3: POS_C_022 | CC3: =VLOOKUP(CB3,'Axe 2 Règles de gestion'!$D$2:$F$271,3, FALSE) -> La date de début de position est à J+1 de la date de fin de position de l'occurrence précédente. | CD3: POS_C_037 | CE3: =VLOOKUP(CD3,'Axe 2 Règles de gestion'!$D$2:$F$271,3, FALSE) -> Les champs "Type d'organisme d'accueil" et "Pays" de l'organisme d'accueil doivent être renseignés. | CF3: POS_C_111 | CG3: =VLOOKUP(CF3,'Axe 2 Règles de gestion'!$D$2:$F$271,3, FALSE) -> La date de fin ou la date de fin prévisionnelle doit être saisie. | CH3: POS_C_431 | CI3: =VLOOKUP(CH3,'Axe 2 Règles de gestion'!$D$2:$F$271,3, FALSE) -> Les champs "Ministère (ou institution de la République) d'accueil", "Corps d'accueil en détachement" et "Grade d'accueil en détachement" ou "Ministère (ou institution de la République) d'accueil", "Emploi fonctionnel d'accueil en détachement" et "Groupe dans un emploi fonctionnel d'accueil" sont renseignés si le "Type d'organisme d'accueil" est valorisé à FPE. | CJ3: POS_C_434 | CK3: =VLOOKUP(CJ3,'Axe 2 Règles de gestion'!$D$2:$F$271,3, FALSE) -> Le champ "Organisme d'accueil" doit être alimenté si le type d'organisme d'accueil est égal à 'Autre organisme', 'Fonction publique d'un état de l'Union Européenne' ou 'Fonction publique Européenne'.
A4: 23.00.00 | B4: M | C4: 45071.722 | D4: D0004 | E4: Position | F4: S0017 | G4: Mise à disposition sortante | H4: E0202 | I4: MAD sortante à titre gratuit auprès d'une autre administration ou d'un EPA de l'Etat | J4: Position administrative saisie égale à 'MAD sortante à titre gratuit auprès d'une autre administration ou d'un EPA de l'Etat' | K4: A_POS_POSIAD [Saisi] = 'MAD11' | L4: T0593 | M4: MADS à titre gratuit auprès d'une autre administration ou d'un EPA de l'Etat - Renouvellement | N4: Création Modification | O4: Indicateur Renouvellement Position est activé ET l'indicateur de renouvellement saisi est différent de l'indicateur de renouvellement avant saisie | P4: A_POS_INDREN [Saisi] = '1' ET A_POS_INDREN [Saisi] <> A_POS_INDREN [Valeur avant saisie] | Q4: Titulaire ou magistrat | R4: P0001 | S4: Général | T4: Passant | U4: 40725 | V4: 44497 | W4: MAD_I_005 ET MAD_I_006 ET MAD_I_026 ET MAD_I_025 ET MAD_I_027 ET MAD_D_011 ET MAD_D_411 ET POS_C_004 ET POS_C_005 ET POS_C_007 ET POS_C_010 ET POS_C_012 ET POS_C_022 ET POS_C_037 ET POS_C_111 ET POS_C_431 ET POS_C_434 | X4: MAD_I_005 | Y4: =VLOOKUP(X4,'Axe 2 Règles de gestion'!$D$2:$F$271,3, FALSE) -> L'accord de l'agent est nécessaire. | Z4: MAD_I_006 | AA4: =VLOOKUP(Z4,'Axe 2 Règles de gestion'!$D$2:$F$271,3, FALSE) -> L'accord du ou des organismes d'accueil est nécessaire. | AB4: MAD_I_026 | AC4: =VLOOKUP(AB4,'Axe 2 Règles de gestion'!$D$2:$F$271,3, FALSE) -> La modification d'un des éléments constitutifs de la convention doit faire l'objet d'un avenant à cette convention. | AD4: MAD_I_025 | AE4: =VLOOKUP(AD4,'Axe 2 Règles de gestion'!$D$2:$F$271,3, FALSE) -> Tout avenant implique la même procédure notamment l'accord de l'agent et du (ou des) organisme(s) d'accueil, les arrêtés ou les décisions. | AF4: MAD_I_027 | AG4: =VLOOKUP(AF4,'Axe 2 Règles de gestion'!$D$2:$F$271,3, FALSE) -> Les avenants à la convention doivent être transmis à l'agent avant signature. | BB4: MAD_D_011 | BC4: =VLOOKUP(BB4,'Axe 2 Règles de gestion'!$D$2:$F$271,3, FALSE) -> La durée prévisionnelle est fixée à 3 ans maximum renouvelable pour chaque période. | BD4: MAD_D_411 | BE4: =VLOOKUP(BD4,'Axe 2 Règles de gestion'!$D$2:$F$271,3, FALSE) -> La durée réelle est fixée à 3 ans maximum renouvelable pour chaque période. | BR4: POS_C_004 | BS4: =VLOOKUP(BR4,'Axe 2 Règles de gestion'!$D$2:$F$271,3, FALSE) -> La date de début de position doit être antérieure ou égale à la date de fin prévisionnelle de position. | BT4: POS_C_005 | BU4: =VLOOKUP(BT4,'Axe 2 Règles de gestion'!$D$2:$F$271,3, FALSE) -> La date de début de la position doit être postérieure ou égale à la date d'entrée dans la FPE ou dans la carrière militaire. | BV4: POS_C_007 | BW4: =VLOOKUP(BV4,'Axe 2 Règles de gestion'!$D$2:$F$271,3, FALSE) -> La date de fin réelle de la position doit être antérieure à la date limite de départ à la retraite. | BX4: POS_C_010 | BY4: =VLOOKUP(BX4,'Axe 2 Règles de gestion'!$D$2:$F$271,3, FALSE) -> La date de début de position doit être antérieure ou égale à la date de fin réelle de position. | BZ4: POS_C_012 | CA4: =VLOOKUP(BZ4,'Axe 2 Règles de gestion'!$D$2:$F$271,3, FALSE) -> La date de fin prévisionnelle de la position doit être antérieure à la date limite de départ à la retraite. | CB4: POS_C_022 | CC4: =VLOOKUP(CB4,'Axe 2 Règles de gestion'!$D$2:$F$271,3, FALSE) -> La date de début de position est à J+1 de la date de fin de position de l'occurrence précédente. | CD4: POS_C_037 | CE4: =VLOOKUP(CD4,'Axe 2 Règles de gestion'!$D$2:$F$271,3, FALSE) -> Les champs "Type d'organisme d'accueil" et "Pays" de l'organisme d'accueil doivent être renseignés. | CF4: POS_C_111 | CG4: =VLOOKUP(CF4,'Axe 2 Règles de gestion'!$D$2:$F$271,3, FALSE) -> La date de fin ou la date de fin prévisionnelle doit être saisie. | CH4: POS_C_431 | CI4: =VLOOKUP(CH4,'Axe 2 Règles de gestion'!$D$2:$F$271,3, FALSE) -> Les champs "Ministère (ou institution de la République) d'accueil", "Corps d'accueil en détachement" et "Grade d'accueil en détachement" ou "Ministère (ou institution de la République) d'accueil", "Emploi fonctionnel d'accueil en détachement" et "Groupe dans un emploi fonctionnel d'accueil" sont renseignés si le "Type d'organisme d'accueil" est valorisé à FPE. | CJ4: POS_C_434 | CK4: =VLOOKUP(CJ4,'Axe 2 Règles de gestion'!$D$2:$F$271,3, FALSE) -> Le champ "Organisme d'accueil" doit être alimenté si le type d'organisme d'accueil est égal à 'Autre organisme', 'Fonction publique d'un état de l'Union Européenne' ou 'Fonction publique Européenne'.
A5: 23.00.00 | B5: A | C5: 45071.722 | D5: D0004 | E5: Position | F5: S0017 | G5: Mise à disposition sortante | H5: E0202 | I5: MAD sortante à titre gratuit auprès d'une autre administration ou d'un EPA de l'Etat | J5: Position administrative saisie égale à 'MAD sortante à titre gratuit auprès d'une autre administration ou d'un EPA de l'Etat' | K5: A_POS_POSIAD [Saisi] = 'MAD11' | L5: T0593 | M5: MADS à titre gratuit auprès d'une autre administration ou d'un EPA de l'Etat - Renouvellement | N5: Création Modification | O5: Indicateur Renouvellement Position est activé ET l'indicateur de renouvellement saisi est différent de l'indicateur de renouvellement avant saisie | P5: A_POS_INDREN [Saisi] = '1' ET A_POS_INDREN [Saisi] <> A_POS_INDREN [Valeur avant saisie] | Q5: Titulaire ou magistrat | R5: P0001 | S5: Général | T5: Passant | U5: 44498 | W5: MAD_I_005 ET MAD_I_006 ET MAD_I_026 ET MAD_I_025 ET MAD_I_027 ET MAD_D_011 ET MAD_D_411 ET POS_C_004 ET POS_C_005 ET POS_C_007 ET POS_C_010 ET POS_C_012 ET POS_C_022 ET POS_C_037 ET POS_C_111 ET POS_C_431 ET POS_C_434 | X5: MAD_I_005 | Y5: =VLOOKUP(X5,'Axe 2 Règles de gestion'!$D$2:$F$271,3, FALSE) -> L'accord de l'agent est nécessaire. | Z5: MAD_I_006 | AA5: =VLOOKUP(Z5,'Axe 2 Règles de gestion'!$D$2:$F$271,3, FALSE) -> L'accord du ou des organismes d'accueil est nécessaire. | AB5: MAD_I_026 | AC5: =VLOOKUP(AB5,'Axe 2 Règles de gestion'!$D$2:$F$271,3, FALSE) -> La modification d'un des éléments constitutifs de la convention doit faire l'objet d'un avenant à cette convention. | AD5: MAD_I_025 | AE5: =VLOOKUP(AD5,'Axe 2 Règles de gestion'!$D$2:$F$271,3, FALSE) -> Tout avenant implique la même procédure notamment l'accord de l'agent et du (ou des) organisme(s) d'accueil, les arrêtés ou les décisions. | AF5: MAD_I_027 | AG5: =VLOOKUP(AF5,'Axe 2 Règles de gestion'!$D$2:$F$271,3, FALSE) -> Les avenants à la convention doivent être transmis à l'agent avant signature. | BB5: MAD_D_011 | BC5: =VLOOKUP(BB5,'Axe 2 Règles de gestion'!$D$2:$F$271,3, FALSE) -> La durée prévisionnelle est fixée à 3 ans maximum renouvelable pour chaque période. | BD5: MAD_D_411 | BE5: =VLOOKUP(BD5,'Axe 2 Règles de gestion'!$D$2:$F$271,3, FALSE) -> La durée réelle est fixée à 3 ans maximum renouvelable pour chaque période. | BR5: POS_C_004 | BS5: =VLOOKUP(BR5,'Axe 2 Règles de gestion'!$D$2:$F$271,3, FALSE) -> La date de début de position doit être antérieure ou égale à la date de fin prévisionnelle de position. | BT5: POS_C_005 | BU5: =VLOOKUP(BT5,'Axe 2 Règles de gestion'!$D$2:$F$271,3, FALSE) -> La date de début de la position doit être postérieure ou égale à la date d'entrée dans la FPE ou dans la carrière militaire. | BV5: POS_C_007 | BW5: =VLOOKUP(BV5,'Axe 2 Règles de gestion'!$D$2:$F$271,3, FALSE) -> La date de fin réelle de la position doit être antérieure à la date limite de départ à la retraite. | BX5: POS_C_010 | BY5: =VLOOKUP(BX5,'Axe 2 Règles de gestion'!$D$2:$F$271,3, FALSE) -> La date de début de position doit être antérieure ou égale à la date de fin réelle de position. | BZ5: POS_C_012 | CA5: =VLOOKUP(BZ5,'Axe 2 Règles de gestion'!$D$2:$F$271,3, FALSE) -> La date de fin prévisionnelle de la position doit être antérieure à la date limite de départ à la retraite. | CB5: POS_C_022 | CC5: =VLOOKUP(CB5,'Axe 2 Règles de gestion'!$D$2:$F$271,3, FALSE) -> La date de début de position est à J+1 de la date de fin de position de l'occurrence précédente. | CD5: POS_C_037 | CE5: =VLOOKUP(CD5,'Axe 2 Règles de gestion'!$D$2:$F$271,3, FALSE) -> Les champs "Type d'organisme d'accueil" et "Pays" de l'organisme d'accueil doivent être renseignés. | CF5: POS_C_111 | CG5: =VLOOKUP(CF5,'Axe 2 Règles de gestion'!$D$2:$F$271,3, FALSE) -> La date de fin ou la date de fin prévisionnelle doit être saisie. | CH5: POS_C_431 | CI5: =VLOOKUP(CH5,'Axe 2 Règles de gestion'!$D$2:$F$271,3, FALSE) -> Les champs "Ministère (ou institution de la République) d'accueil", "Corps d'accueil en détachement" et "Grade d'accueil en détachement" ou "Ministère (ou institution de la République) d'accueil", "Emploi fonctionnel d'accueil en détachement" et "Groupe dans un emploi fonctionnel d'accueil" sont renseignés si le "Type d'organisme d'accueil" est valorisé à FPE. | CJ5: POS_C_434 | CK5: =VLOOKUP(CJ5,'Axe 2 Règles de gestion'!$D$2:$F$271,3, FALSE) -> Le champ "Organisme d'accueil" doit être alimenté si le type d'organisme d'accueil est égal à 'Autre organisme', 'Fonction publique d'un état de l'Union Européenne' ou 'Fonction publique Européenne'.
A6: 20.00.00 | B6: M | C6: 43152.5 | D6: D0004 | E6: Position | F6: S0017 | G6: Mise à disposition sortante | H6: E0202 | I6: MAD sortante à titre gratuit auprès d'une autre administration ou d'un EPA de l'Etat | J6: Position administrative saisie égale à 'MAD sortante à titre gratuit auprès d'une autre administration ou d'un EPA de l'Etat' | K6: A_POS_POSIAD [Saisi] = 'MAD11' | L6: T0594 | M6: MADS à titre gratuit auprès d'une autre administration ou d'un EPA de l'Etat - Fin | N6: Modification | O6: L'indicateur de renouvellement saisi est égal à l'indicateur de renouvellement avant saisie | P6: A_POS_INDREN [Saisi] = A_POS_INDREN [Valeur avant saisie] | Q6: Titulaire ou magistrat | R6: P0001 | S6: Général | T6: Passant | U6: 40725 | W6: MAD_I_028 ET MAD_I_029 ET MAD_I_030 ET MAD_I_031 ET MAD_I_032 ET MAD_I_034 ET MAD_D_011 ET MAD_D_411 ET POS_C_004 ET POS_C_007 ET POS_C_010 ET POS_C_012 ET POS_C_037 ET POS_C_111 ET POS_C_431 ET POS_C_434 | X6: MAD_I_028 | Y6: =VLOOKUP(X6,'Axe 2 Règles de gestion'!$D$2:$F$271,3, FALSE) -> La mise à disposition peut prendre fin de manière anticipée à l'initiative de l'agent, de l'administration d'origine ou de l'organisme d'accueil. | Z6: MAD_I_029 | AA6: =VLOOKUP(Z6,'Axe 2 Règles de gestion'!$D$2:$F$271,3, FALSE) -> En cas de pluralité d'organismes d'accueil, la fin anticipée de la mise à disposition peut s'appliquer vis-à-vis d'une partie seulement d'entre eux. Dans ce cas, les autres organismes d'accueil doivent en être informés. | AB6: MAD_I_030 | AC6: =VLOOKUP(AB6,'Axe 2 Règles de gestion'!$D$2:$F$271,3, FALSE) -> Si un préavis est prévu dans la convention, il doit être respecté. | AD6: MAD_I_031 | AE6: =VLOOKUP(AD6,'Axe 2 Règles de gestion'!$D$2:$F$271,3, FALSE) -> En cas de faute disciplinaire, la mise à disposition peut prendre fin sans préavis par accord entre l'administration d'origine et l'organisme d'accueil. | AF6: MAD_I_032 | AG6: =VLOOKUP(AF6,'Axe 2 Règles de gestion'!$D$2:$F$271,3, FALSE) -> L'agent est affecté soit aux mêmes fonctions dans son service d'origine soit dans l'un des emplois que son grade lui donne vocation à occuper. | AH6: MAD_I_034 | AI6: =VLOOKUP(AH6,'Axe 2 Règles de gestion'!$D$2:$F$271,3, FALSE) -> L'agent mis à disposition qui accepte la proposition d'intégration émise par son administration d'accueil est intégré dans un corps comparable à son corps d'origine. | BB6: MAD_D_011 | BC6: =VLOOKUP(BB6,'Axe 2 Règles de gestion'!$D$2:$F$271,3, FALSE) -> La durée prévisionnelle est fixée à 3 ans maximum renouvelable pour chaque période. | BD6: MAD_D_411 | BE6: =VLOOKUP(BD6,'Axe 2 Règles de gestion'!$D$2:$F$271,3, FALSE) -> La durée réelle est fixée à 3 ans maximum renouvelable pour chaque période. | BR6: POS_C_004 | BS6: =VLOOKUP(BR6,'Axe 2 Règles de gestion'!$D$2:$F$271,3, FALSE) -> La date de début de position doit être antérieure ou égale à la date de fin prévisionnelle de position. | BT6: POS_C_007 | BU6: =VLOOKUP(BT6,'Axe 2 Règles de gestion'!$D$2:$F$271,3, FALSE) -> La date de fin réelle de la position doit être antérieure à la date limite de départ à la retraite. | BV6: POS_C_010 | BW6: =VLOOKUP(BV6,'Axe 2 Règles de gestion'!$D$2:$F$271,3, FALSE) -> La date de début de position doit être antérieure ou égale à la date de fin réelle de position. | BX6: POS_C_012 | BY6: =VLOOKUP(BX6,'Axe 2 Règles de gestion'!$D$2:$F$271,3, FALSE) -> La date de fin prévisionnelle de la position doit être antérieure à la date limite de départ à la retraite. | BZ6: POS_C_037 | CA6: =VLOOKUP(BZ6,'Axe 2 Règles de gestion'!$D$2:$F$271,3, FALSE) -> Les champs "Type d'organisme d'accueil" et "Pays" de l'organisme d'accueil doivent être renseignés. | CB6: POS_C_111 | CC6: =VLOOKUP(CB6,'Axe 2 Règles de gestion'!$D$2:$F$271,3, FALSE) -> La date de fin ou la date de fin prévisionnelle doit être saisie. | CD6: POS_C_431 | CE6: =VLOOKUP(CD6,'Axe 2 Règles de gestion'!$D$2:$F$271,3, FALSE) -> Les champs "Ministère (ou institution de la République) d'accueil", "Corps d'accueil en détachement" et "Grade d'accueil en détachement" ou "Ministère (ou institution de la République) d'accueil", "Emploi fonctionnel d'accueil en détachement" et "Groupe dans un emploi fonctionnel d'accueil" sont renseignés si le "Type d'organisme d'accueil" est valorisé à FPE. | CF6: POS_C_434 | CG6: =VLOOKUP(CF6,'Axe 2 Règles de gestion'!$D$2:$F$271,3, FALSE) -> Le champ "Organisme d'accueil" doit être alimenté si le type d'organisme d'accueil est égal à 'Autre organisme', 'Fonction publique d'un état de l'Union Européenne' ou 'Fonction publique Européenne'.
A7: 20.00.00 | B7: M | C7: 43152.5 | D7: D0004 | E7: Position | F7: S0017 | G7: Mise à disposition sortante | H7: E0202 | I7: MAD sortante à titre gratuit auprès d'une autre administration ou d'un EPA de l'Etat | J7: Position administrative saisie égale à 'MAD sortante à titre gratuit auprès d'une autre administration ou d'un EPA de l'Etat' | K7: A_POS_POSIAD [Saisi] = 'MAD11' | L7: T0592 | M7: MADS à titre gratuit auprès d'une autre administration ou d'un EPA de l'Etat - Demande | N7: Création Modification | O7: Indicateur Renouvellement Position est non activé ET l'indicateur de renouvellement saisi est différent de l'indicateur de renouvellement avant saisie | P7: A_POS_INDREN [Saisi] = '0' ET A_POS_INDREN [Saisi] <> A_POS_INDREN [Valeur avant saisie] | Q7: Contractuel | R7: P0003 | S7: Général | T7: Passant | U7: 40725 | V7: 41721 | W7: MAD_D_019 ET MAD_D_816 ET MAD_D_014 ET POS_C_100 ET POS_C_004 ET POS_C_006 ET POS_C_007 ET POS_C_009 ET POS_C_010 ET POS_C_012 ET POS_C_022 ET POS_C_037 ET POS_C_106 ET POS_C_111 ET POS_C_431 ET POS_C_434 | BB7: MAD_D_019 | BC7: =VLOOKUP(BB7,'Axe 2 Règles de gestion'!$D$2:$F$271,3, FALSE) -> La durée prévisionnelle est fixée à 3 ans maximum renouvelable pour chaque période. | BD7: MAD_D_816 | BE7: =VLOOKUP(BD7,'Axe 2 Règles de gestion'!$D$2:$F$271,3, FALSE) -> La durée réelle est fixée à 3 ans maximum renouvelable pour chaque période. | BF7: MAD_D_014 | BG7: =VLOOKUP(BF7,'Axe 2 Règles de gestion'!$D$2:$F$271,3, FALSE) -> Le type de contrat doit être un CDI. | BR7: POS_C_100 | BS7: =VLOOKUP(BR7,'Axe 2 Règles de gestion'!$D$2:$F$271,3, FALSE) -> Lors de la demande initiale, l'agent doit être en activité. | BT7: POS_C_004 | BU7: =VLOOKUP(BT7,'Axe 2 Règles de gestion'!$D$2:$F$271,3, FALSE) -> La date de début de position doit être antérieure ou égale à la date de fin prévisionnelle de position. | BV7: POS_C_006 | BW7: =VLOOKUP(BV7,'Axe 2 Règles de gestion'!$D$2:$F$271,3, FALSE) -> La date de fin réelle de la position doit être antérieure ou égale à la date de fin réelle ou prévisionnelle du lien juridique. | BX7: POS_C_007 | BY7: =VLOOKUP(BX7,'Axe 2 Règles de gestion'!$D$2:$F$271,3, FALSE) -> La date de fin réelle de la position doit être antérieure à la date limite de départ à la retraite. | BZ7: POS_C_009 | CA7: =VLOOKUP(BZ7,'Axe 2 Règles de gestion'!$D$2:$F$271,3, FALSE) -> La date de début de la position doit être postérieure ou égale à la date de début du lien juridique. | CB7: POS_C_010 | CC7: =VLOOKUP(CB7,'Axe 2 Règles de gestion'!$D$2:$F$271,3, FALSE) -> La date de début de position doit être antérieure ou égale à la date de fin réelle de position. | CD7: POS_C_012 | CE7: =VLOOKUP(CD7,'Axe 2 Règles de gestion'!$D$2:$F$271,3, FALSE) -> La date de fin prévisionnelle de la position doit être antérieure à la date limite de départ à la retraite. | CF7: POS_C_022 | CG7: =VLOOKUP(CF7,'Axe 2 Règles de gestion'!$D$2:$F$271,3, FALSE) -> La date de début de position est à J+1 de la date de fin de position de l'occurrence précédente. | CH7: POS_C_037 | CI7: =VLOOKUP(CH7,'Axe 2 Règles de gestion'!$D$2:$F$271,3, FALSE) -> Les champs "Type d'organisme d'accueil" et "Pays" de l'organisme d'accueil doivent être renseignés. | CJ7: POS_C_106 | CK7: =VLOOKUP(CJ7,'Axe 2 Règles de gestion'!$D$2:$F$271,3, FALSE) -> La date de fin prévisionnelle de la position doit être antérieure ou égale à la date de fin réelle ou prévisionnelle du lien juridique. | CL7: POS_C_111 | CM7: =VLOOKUP(CL7,'Axe 2 Règles de gestion'!$D$2:$F$271,3, FALSE) -> La date de fin ou la date de fin prévisionnelle doit être saisie. | CN7: POS_C_431 | CO7: =VLOOKUP(CN7,'Axe 2 Règles de gestion'!$D$2:$F$271,3, FALSE) -> Les champs "Ministère (ou institution de la République) d'accueil", "Corps d'accueil en détachement" et "Grade d'accueil en détachement" ou "Ministère (ou institution de la République) d'accueil", "Emploi fonctionnel d'accueil en détachement" et "Groupe dans un emploi fonctionnel d'accueil" sont renseignés si le "Type d'organisme d'accueil" est valorisé à FPE. | CP7: POS_C_434 | CQ7: =VLOOKUP(CP7,'Axe 2 Règles de gestion'!$D$2:$F$271,3, FALSE) -> Le champ "Organisme d'accueil" doit être alimenté si le type d'organisme d'accueil est égal à 'Autre organisme', 'Fonction publique d'un état de l'Union Européenne' ou 'Fonction publique Européenne'.
A8: 22.10.00 | B8: M | C8: 44832.36 | D8: D0004 | E8: Position | F8: S0017 | G8: Mise à disposition sortante | H8: E0202 | I8: MAD sortante à titre gratuit auprès d'une autre administration ou d'un EPA de l'Etat | J8: Position administrative saisie égale à 'MAD sortante à titre gratuit auprès d'une autre administration ou d'un EPA de l'Etat' | K8: A_POS_POSIAD [Saisi] = 'MAD11' | L8: T0592 | M8: MADS à titre gratuit auprès d'une autre administration ou d'un EPA de l'Etat - Demande | N8: Création Modification | O8: Indicateur Renouvellement Position est non activé ET l'indicateur de renouvellement saisi est différent de l'indicateur de renouvellement avant saisie | P8: A_POS_INDREN [Saisi] = '0' ET A_POS_INDREN [Saisi] <> A_POS_INDREN [Valeur avant saisie] | Q8: Contractuel | R8: P0003 | S8: Général | T8: Passant | U8: 41722 | V8: 44677 | W8: MAD_I_012 ET MAD_I_013 ET MAD_I_014 ET MAD_D_019 ET MAD_D_816 ET MAD_D_014 ET POS_C_100 ET POS_C_004 ET POS_C_006 ET POS_C_007 ET POS_C_009 ET POS_C_010 ET POS_C_012 ET POS_C_022 ET POS_C_037 ET POS_C_106 ET POS_C_111 ET POS_C_431 ET POS_C_434 | X8: MAD_I_012 | Y8: =VLOOKUP(X8,'Axe 2 Règles de gestion'!$D$2:$F$271,3, FALSE) -> L'accord de l'agent est nécessaire. | Z8: MAD_I_013 | AA8: =VLOOKUP(Z8,'Axe 2 Règles de gestion'!$D$2:$F$271,3, FALSE) -> L'accord du ou des organismes d'accueil est nécessaire. | AB8: MAD_I_014 | AC8: =VLOOKUP(AB8,'Axe 2 Règles de gestion'!$D$2:$F$271,3, FALSE) -> Une convention entre l'organisme d'origine et l'organisme d'accueil doit être signée. | BB8: MAD_D_019 | BC8: =VLOOKUP(BB8,'Axe 2 Règles de gestion'!$D$2:$F$271,3, FALSE) -> La durée prévisionnelle est fixée à 3 ans maximum renouvelable pour chaque période. | BD8: MAD_D_816 | BE8: =VLOOKUP(BD8,'Axe 2 Règles de gestion'!$D$2:$F$271,3, FALSE) -> La durée réelle est fixée à 3 ans maximum renouvelable pour chaque période. | BF8: MAD_D_014 | BG8: =VLOOKUP(BF8,'Axe 2 Règles de gestion'!$D$2:$F$271,3, FALSE) -> Le type de contrat doit être un CDI. | BR8: POS_C_100 | BS8: =VLOOKUP(BR8,'Axe 2 Règles de gestion'!$D$2:$F$271,3, FALSE) -> Lors de la demande initiale, l'agent doit être en activité. | BT8: POS_C_004 | BU8: =VLOOKUP(BT8,'Axe 2 Règles de gestion'!$D$2:$F$271,3, FALSE) -> La date de début de position doit être antérieure ou égale à la date de fin prévisionnelle de position. | BV8: POS_C_006 | BW8: =VLOOKUP(BV8,'Axe 2 Règles de gestion'!$D$2:$F$271,3, FALSE) -> La date de fin réelle de la position doit être antérieure ou égale à la date de fin réelle ou prévisionnelle du lien juridique. | BX8: POS_C_007 | BY8: =VLOOKUP(BX8,'Axe 2 Règles de gestion'!$D$2:$F$271,3, FALSE) -> La date de fin réelle de la position doit être antérieure à la date limite de départ à la retraite. | BZ8: POS_C_009 | CA8: =VLOOKUP(BZ8,'Axe 2 Règles de gestion'!$D$2:$F$271,3, FALSE) -> La date de début de la position doit être postérieure ou égale à la date de début du lien juridique. | CB8: POS_C_010 | CC8: =VLOOKUP(CB8,'Axe 2 Règles de gestion'!$D$2:$F$271,3, FALSE) -> La date de début de position doit être antérieure ou égale à la date de fin réelle de position. | CD8: POS_C_012 | CE8: =VLOOKUP(CD8,'Axe 2 Règles de gestion'!$D$2:$F$271,3, FALSE) -> La date de fin prévisionnelle de la position doit être antérieure à la date limite de départ à la retraite. | CF8: POS_C_022 | CG8: =VLOOKUP(CF8,'Axe 2 Règles de gestion'!$D$2:$F$271,3, FALSE) -> La date de début de position est à J+1 de la date de fin de position de l'occurrence précédente. | CH8: POS_C_037 | CI8: =VLOOKUP(CH8,'Axe 2 Règles de gestion'!$D$2:$F$271,3, FALSE) -> Les champs "Type d'organisme d'accueil" et "Pays" de l'organisme d'accueil doivent être renseignés. | CJ8: POS_C_106 | CK8: =VLOOKUP(CJ8,'Axe 2 Règles de gestion'!$D$2:$F$271,3, FALSE) -> La date de fin prévisionnelle de la position doit être antérieure ou égale à la date de fin réelle ou prévisionnelle du lien juridique. | CL8: POS_C_111 | CM8: =VLOOKUP(CL8,'Axe 2 Règles de gestion'!$D$2:$F$271,3, FALSE) -> La date de fin ou la date de fin prévisionnelle doit être saisie. | CN8: POS_C_431 | CO8: =VLOOKUP(CN8,'Axe 2 Règles de gestion'!$D$2:$F$271,3, FALSE) -> Les champs "Ministère (ou institution de la République) d'accueil", "Corps d'accueil en détachement" et "Grade d'accueil en détachement" ou "Ministère (ou institution de la République) d'accueil", "Emploi fonctionnel d'accueil en détachement" et "Groupe dans un emploi fonctionnel d'accueil" sont renseignés si le "Type d'organisme d'accueil" est valorisé à FPE. | CP8: POS_C_434 | CQ8: =VLOOKUP(CP8,'Axe 2 Règles de gestion'!$D$2:$F$271,3, FALSE) -> Le champ "Organisme d'accueil" doit être alimenté si le type d'organisme d'accueil est égal à 'Autre organisme', 'Fonction publique d'un état de l'Union Européenne' ou 'Fonction publique Européenne'.
A9: 22.10.00 | B9: A | C9: 44832.361 | D9: D0004 | E9: Position | F9: S0017 | G9: Mise à disposition sortante | H9: E0202 | I9: MAD sortante à titre gratuit auprès d'une autre administration ou d'un EPA de l'Etat | J9: Position administrative saisie égale à 'MAD sortante à titre gratuit auprès d'une autre administration ou d'un EPA de l'Etat' | K9: A_POS_POSIAD [Saisi] = 'MAD11' | L9: T0592 | M9: MADS à titre gratuit auprès d'une autre administration ou d'un EPA de l'Etat - Demande | N9: Création Modification | O9: Indicateur Renouvellement Position est non activé ET l'indicateur de renouvellement saisi est différent de l'indicateur de renouvellement avant saisie | P9: A_POS_INDREN [Saisi] = '0' ET A_POS_INDREN [Saisi] <> A_POS_INDREN [Valeur avant saisie] | Q9: Contractuel | R9: P0003 | S9: Général | T9: Passant | U9: 44678 | W9: MAD_I_021 ET MAD_I_012 ET MAD_I_013 ET MAD_I_014 ET MAD_D_019 ET MAD_D_816 ET MAD_D_014 ET POS_C_100 ET POS_C_004 ET POS_C_006 ET POS_C_007 ET POS_C_009 ET POS_C_010 ET POS_C_012 ET POS_C_022 ET POS_C_037 ET POS_C_106 ET POS_C_111 ET POS_C_431 ET POS_C_434 | X9: MAD_I_021 | Y9: =VLOOKUP(X9,'Axe 2 Règles de gestion'!$D$2:$F$271,3, FALSE) -> L'agent peut être mis à disposition d'un ou plusieurs organismes d'accueil. | Z9: MAD_I_012 | AA9: =VLOOKUP(Z9,'Axe 2 Règles de gestion'!$D$2:$F$271,3, FALSE) -> L'accord de l'agent est nécessaire. | AB9: MAD_I_013 | AC9: =VLOOKUP(AB9,'Axe 2 Règles de gestion'!$D$2:$F$271,3, FALSE) -> L'accord du ou des organismes d'accueil est nécessaire. | AD9: MAD_I_014 | AE9: =VLOOKUP(AD9,'Axe 2 Règles de gestion'!$D$2:$F$271,3, FALSE) -> Une convention entre l'organisme d'origine et l'organisme d'accueil doit être signée. | BB9: MAD_D_019 | BC9: =VLOOKUP(BB9,'Axe 2 Règles de gestion'!$D$2:$F$271,3, FALSE) -> La durée prévisionnelle est fixée à 3 ans maximum renouvelable pour chaque période. | BD9: MAD_D_816 | BE9: =VLOOKUP(BD9,'Axe 2 Règles de gestion'!$D$2:$F$271,3, FALSE) -> La durée réelle est fixée à 3 ans maximum renouvelable pour chaque période. | BF9: MAD_D_014 | BG9: =VLOOKUP(BF9,'Axe 2 Règles de gestion'!$D$2:$F$271,3, FALSE) -> Le type de contrat doit être un CDI. | BR9: POS_C_100 | BS9: =VLOOKUP(BR9,'Axe 2 Règles de gestion'!$D$2:$F$271,3, FALSE) -> Lors de la demande initiale, l'agent doit être en activité. | BT9: POS_C_004 | BU9: =VLOOKUP(BT9,'Axe 2 Règles de gestion'!$D$2:$F$271,3, FALSE) -> La date de début de position doit être antérieure ou égale à la date de fin prévisionnelle de position. | BV9: POS_C_006 | BW9: =VLOOKUP(BV9,'Axe 2 Règles de gestion'!$D$2:$F$271,3, FALSE) -> La date de fin réelle de la position doit être antérieure ou égale à la date de fin réelle ou prévisionnelle du lien juridique. | BX9: POS_C_007 | BY9: =VLOOKUP(BX9,'Axe 2 Règles de gestion'!$D$2:$F$271,3, FALSE) -> La date de fin réelle de la position doit être antérieure à la date limite de départ à la retraite. | BZ9: POS_C_009 | CA9: =VLOOKUP(BZ9,'Axe 2 Règles de gestion'!$D$2:$F$271,3, FALSE) -> La date de début de la position doit être postérieure ou égale à la date de début du lien juridique. | CB9: POS_C_010 | CC9: =VLOOKUP(CB9,'Axe 2 Règles de gestion'!$D$2:$F$271,3, FALSE) -> La date de début de position doit être antérieure ou égale à la date de fin réelle de position. | CD9: POS_C_012 | CE9: =VLOOKUP(CD9,'Axe 2 Règles de gestion'!$D$2:$F$271,3, FALSE) -> La date de fin prévisionnelle de la position doit être antérieure à la date limite de départ à la retraite. | CF9: POS_C_022 | CG9: =VLOOKUP(CF9,'Axe 2 Règles de gestion'!$D$2:$F$271,3, FALSE) -> La date de début de position est à J+1 de la date de fin de position de l'occurrence précédente. | CH9: POS_C_037 | CI9: =VLOOKUP(CH9,'Axe 2 Règles de gestion'!$D$2:$F$271,3, FALSE) -> Les champs "Type d'organisme d'accueil" et "Pays" de l'organisme d'accueil doivent être renseignés. | CJ9: POS_C_106 | CK9: =VLOOKUP(CJ9,'Axe 2 Règles de gestion'!$D$2:$F$271,3, FALSE) -> La date de fin prévisionnelle de la position doit être antérieure ou égale à la date de fin réelle ou prévisionnelle du lien juridique. | CL9: POS_C_111 | CM9: =VLOOKUP(CL9,'Axe 2 Règles de gestion'!$D$2:$F$271,3, FALSE) -> La date de fin ou la date de fin prévisionnelle doit être saisie. | CN9: POS_C_431 | CO9: =VLOOKUP(CN9,'Axe 2 Règles de gestion'!$D$2:$F$271,3, FALSE) -> Les champs "Ministère (ou institution de la République) d'accueil", "Corps d'accueil en détachement" et "Grade d'accueil en détachement" ou "Ministère (ou institution de la République) d'accueil", "Emploi fonctionnel d'accueil en détachement" et "Groupe dans un emploi fonctionnel d'accueil" sont renseignés si le "Type d'organisme d'accueil" est valorisé à FPE. | CP9: POS_C_434 | CQ9: =VLOOKUP(CP9,'Axe 2 Règles de gestion'!$D$2:$F$271,3, FALSE) -> Le champ "Organisme d'accueil" doit être alimenté si le type d'organisme d'accueil est égal à 'Autre organisme', 'Fonction publique d'un état de l'Union Européenne' ou 'Fonction publique Européenne'.
A10: 20.00.00 | B10: M | C10: 43152.5 | D10: D0004 | E10: Position | F10: S0017 | G10: Mise à disposition sortante | H10: E0202 | I10: MAD sortante à titre gratuit auprès d'une autre administration ou d'un EPA de l'Etat | J10: Position administrative saisie égale à 'MAD sortante à titre gratuit auprès d'une autre administration ou d'un EPA de l'Etat' | K10: A_POS_POSIAD [Saisi] = 'MAD11' | L10: T0593 | M10: MADS à titre gratuit auprès d'une autre administration ou d'un EPA de l'Etat - Renouvellement | N10: Création Modification | O10: Indicateur Renouvellement Position est activé ET l'indicateur de renouvellement saisi est différent de l'indicateur de renouvellement avant saisie | P10: A_POS_INDREN [Saisi] = '1' ET A_POS_INDREN [Saisi] <> A_POS_INDREN [Valeur avant saisie] | Q10: Contractuel | R10: P0003 | S10: Général | T10: Passant | U10: 40725 | V10: 41721 | W10: MAD_D_019 ET MAD_D_816 ET MAD_D_014 ET MAD_D_039 ET MAD_D_817 ET POS_C_004 ET POS_C_006 ET POS_C_007 ET POS_C_009 ET POS_C_010 ET POS_C_012 ET POS_C_022 ET POS_C_037 ET POS_C_106 ET POS_C_111 ET POS_C_431 ET POS_C_434 | BB10: MAD_D_019 | BC10: =VLOOKUP(BB10,'Axe 2 Règles de gestion'!$D$2:$F$271,3, FALSE) -> La durée prévisionnelle est fixée à 3 ans maximum renouvelable pour chaque période. | BD10: MAD_D_816 | BE10: =VLOOKUP(BD10,'Axe 2 Règles de gestion'!$D$2:$F$271,3, FALSE) -> La durée réelle est fixée à 3 ans maximum renouvelable pour chaque période. | BF10: MAD_D_014 | BG10: =VLOOKUP(BF10,'Axe 2 Règles de gestion'!$D$2:$F$271,3, FALSE) -> Le type de contrat doit être un CDI. | BH10: MAD_D_039 | BI10: =VLOOKUP(BH10,'Axe 2 Règles de gestion'!$D$2:$F$271,3, FALSE) -> La durée totale prévisionnelle de la mise à disposition ne peut excéder 6 années consécutives. | BJ10: MAD_D_817 | BK10: =VLOOKUP(BJ10,'Axe 2 Règles de gestion'!$D$2:$F$271,3, FALSE) -> La durée totale réelle de la mise à disposition ne peut excéder 6 années consécutives. | BR10: POS_C_004 | BS10: =VLOOKUP(BR10,'Axe 2 Règles de gestion'!$D$2:$F$271,3, FALSE) -> La date de début de position doit être antérieure ou égale à la date de fin prévisionnelle de position. | BT10: POS_C_006 | BU10: =VLOOKUP(BT10,'Axe 2 Règles de gestion'!$D$2:$F$271,3, FALSE) -> La date de fin réelle de la position doit être antérieure ou égale à la date de fin réelle ou prévisionnelle du lien juridique. | BV10: POS_C_007 | BW10: =VLOOKUP(BV10,'Axe 2 Règles de gestion'!$D$2:$F$271,3, FALSE) -> La date de fin réelle de la position doit être antérieure à la date limite de départ à la retraite. | BX10: POS_C_009 | BY10: =VLOOKUP(BX10,'Axe 2 Règles de gestion'!$D$2:$F$271,3, FALSE) -> La date de début de la position doit être postérieure ou égale à la date de début du lien juridique. | BZ10: POS_C_010 | CA10: =VLOOKUP(BZ10,'Axe 2 Règles de gestion'!$D$2:$F$271,3, FALSE) -> La date de début de position doit être antérieure ou égale à la date de fin réelle de position. | CB10: POS_C_012 | CC10: =VLOOKUP(CB10,'Axe 2 Règles de gestion'!$D$2:$F$271,3, FALSE) -> La date de fin prévisionnelle de la position doit être antérieure à la date limite de départ à la retraite. | CD10: POS_C_022 | CE10: =VLOOKUP(CD10,'Axe 2 Règles de gestion'!$D$2:$F$271,3, FALSE) -> La date de début de position est à J+1 de la date de fin de position de l'occurrence précédente. | CF10: POS_C_037 | CG10: =VLOOKUP(CF10,'Axe 2 Règles de gestion'!$D$2:$F$271,3, FALSE) -> Les champs "Type d'organisme d'accueil" et "Pays" de l'organisme d'accueil doivent être renseignés. | CH10: POS_C_106 | CI10: =VLOOKUP(CH10,'Axe 2 Règles de gestion'!$D$2:$F$271,3, FALSE) -> La date de fin prévisionnelle de la position doit être antérieure ou égale à la date de fin réelle ou prévisionnelle du lien juridique. | CJ10: POS_C_111 | CK10: =VLOOKUP(CJ10,'Axe 2 Règles de gestion'!$D$2:$F$271,3, FALSE) -> La date de fin ou la date de fin prévisionnelle doit être saisie. | CL10: POS_C_431 | CM10: =VLOOKUP(CL10,'Axe 2 Règles de gestion'!$D$2:$F$271,3, FALSE) -> Les champs "Ministère (ou institution de la République) d'accueil", "Corps d'accueil en détachement" et "Grade d'accueil en détachement" ou "Ministère (ou institution de la République) d'accueil", "Emploi fonctionnel d'accueil en détachement" et "Groupe dans un emploi fonctionnel d'accueil" sont renseignés si le "Type d'organisme d'accueil" est valorisé à FPE. | CN10: POS_C_434 | CO10: =VLOOKUP(CN10,'Axe 2 Règles de gestion'!$D$2:$F$271,3, FALSE) -> Le champ "Organisme d'accueil" doit être alimenté si le type d'organisme d'accueil est égal à 'Autre organisme', 'Fonction publique d'un état de l'Union Européenne' ou 'Fonction publique Européenne'.
A11: 20.00.00 | B11: M | C11: 43152.5 | D11: D0004 | E11: Position | F11: S0017 | G11: Mise à disposition sortante | H11: E0202 | I11: MAD sortante à titre gratuit auprès d'une autre administration ou d'un EPA de l'Etat | J11: Position administrative saisie égale à 'MAD sortante à titre gratuit auprès d'une autre administration ou d'un EPA de l'Etat' | K11: A_POS_POSIAD [Saisi] = 'MAD11' | L11: T0593 | M11: MADS à titre gratuit auprès d'une autre administration ou d'un EPA de l'Etat - Renouvellement | N11: Création Modification | O11: Indicateur Renouvellement Position est activé ET l'indicateur de renouvellement saisi est différent de l'indicateur de renouvellement avant saisie | P11: A_POS_INDREN [Saisi] = '1' ET A_POS_INDREN [Saisi] <> A_POS_INDREN [Valeur avant saisie] | Q11: Contractuel | R11: P0003 | S11: Général | T11: Passant | U11: 41722 | W11: MAD_D_019 ET MAD_D_816 ET MAD_D_221 ET MAD_D_818 ET MAD_D_014 ET POS_C_004 ET POS_C_006 ET POS_C_007 ET POS_C_009 ET POS_C_010 ET POS_C_012 ET POS_C_022 ET POS_C_037 ET POS_C_106 ET POS_C_111 ET POS_C_431 ET POS_C_434 | BB11: MAD_D_019 | BC11: =VLOOKUP(BB11,'Axe 2 Règles de gestion'!$D$2:$F$271,3, FALSE) -> La durée prévisionnelle est fixée à 3 ans maximum renouvelable pour chaque période. | BD11: MAD_D_816 | BE11: =VLOOKUP(BD11,'Axe 2 Règles de gestion'!$D$2:$F$271,3, FALSE) -> La durée réelle est fixée à 3 ans maximum renouvelable pour chaque période. | BF11: MAD_D_221 | BG11: =VLOOKUP(BF11,'Axe 2 Règles de gestion'!$D$2:$F$271,3, FALSE) -> La durée totale prévisionnelle de la mise à disposition ne peut excéder 10 années consécutives. | BH11: MAD_D_818 | BI11: =VLOOKUP(BH11,'Axe 2 Règles de gestion'!$D$2:$F$271,3, FALSE) -> La durée totale réelle de la mise à disposition ne peut excéder 10 années consécutives. | BJ11: MAD_D_014 | BK11: =VLOOKUP(BJ11,'Axe 2 Règles de gestion'!$D$2:$F$271,3, FALSE) -> Le type de contrat doit être un CDI. | BR11: POS_C_004 | BS11: =VLOOKUP(BR11,'Axe 2 Règles de gestion'!$D$2:$F$271,3, FALSE) -> La date de début de position doit être antérieure ou égale à la date de fin prévisionnelle de position. | BT11: POS_C_006 | BU11: =VLOOKUP(BT11,'Axe 2 Règles de gestion'!$D$2:$F$271,3, FALSE) -> La date de fin réelle de la position doit être antérieure ou égale à la date de fin réelle ou prévisionnelle du lien juridique. | BV11: POS_C_007 | BW11: =VLOOKUP(BV11,'Axe 2 Règles de gestion'!$D$2:$F$271,3, FALSE) -> La date de fin réelle de la position doit être antérieure à la date limite de départ à la retraite. | BX11: POS_C_009 | BY11: =VLOOKUP(BX11,'Axe 2 Règles de gestion'!$D$2:$F$271,3, FALSE) -> La date de début de la position doit être postérieure ou égale à la date de début du lien juridique. | BZ11: POS_C_010 | CA11: =VLOOKUP(BZ11,'Axe 2 Règles de gestion'!$D$2:$F$271,3, FALSE) -> La date de début de position doit être antérieure ou égale à la date de fin réelle de position. | CB11: POS_C_012 | CC11: =VLOOKUP(CB11,'Axe 2 Règles de gestion'!$D$2:$F$271,3, FALSE) -> La date de fin prévisionnelle de la position doit être antérieure à la date limite de départ à la retraite. | CD11: POS_C_022 | CE11: =VLOOKUP(CD11,'Axe 2 Règles de gestion'!$D$2:$F$271,3, FALSE) -> La date de début de position est à J+1 de la date de fin de position de l'occurrence précédente. | CF11: POS_C_037 | CG11: =VLOOKUP(CF11,'Axe 2 Règles de gestion'!$D$2:$F$271,3, FALSE) -> Les champs "Type d'organisme d'accueil" et "Pays" de l'organisme d'accueil doivent être renseignés. | CH11: POS_C_106 | CI11: =VLOOKUP(CH11,'Axe 2 Règles de gestion'!$D$2:$F$271,3, FALSE) -> La date de fin prévisionnelle de la position doit être antérieure ou égale à la date de fin réelle ou prévisionnelle du lien juridique. | CJ11: POS_C_111 | CK11: =VLOOKUP(CJ11,'Axe 2 Règles de gestion'!$D$2:$F$271,3, FALSE) -> La date de fin ou la date de fin prévisionnelle doit être saisie. | CL11: POS_C_431 | CM11: =VLOOKUP(CL11,'Axe 2 Règles de gestion'!$D$2:$F$271,3, FALSE) -> Les champs "Ministère (ou institution de la République) d'accueil", "Corps d'accueil en détachement" et "Grade d'accueil en détachement" ou "Ministère (ou institution de la République) d'accueil", "Emploi fonctionnel d'accueil en détachement" et "Groupe dans un emploi fonctionnel d'accueil" sont renseignés si le "Type d'organisme d'accueil" est valorisé à FPE. | CN11: POS_C_434 | CO11: =VLOOKUP(CN11,'Axe 2 Règles de gestion'!$D$2:$F$271,3, FALSE) -> Le champ "Organisme d'accueil" doit être alimenté si le type d'organisme d'accueil est égal à 'Autre organisme', 'Fonction publique d'un état de l'Union Européenne' ou 'Fonction publique Européenne'. | CU11: Finalisé
A12: 20.00.00 | B12: M | C12: 43152.5 | D12: D0004 | E12: Position | F12: S0017 | G12: Mise à disposition sortante | H12: E0202 | I12: MAD sortante à titre gratuit auprès d'une autre administration ou d'un EPA de l'Etat | J12: Position administrative saisie égale à 'MAD sortante à titre gratuit auprès d'une autre administration ou d'un EPA de l'Etat' | K12: A_POS_POSIAD [Saisi] = 'MAD11' | L12: T0594 | M12: MADS à titre gratuit auprès d'une autre administration ou d'un EPA de l'Etat - Fin | N12: Modification | O12: L'indicateur de renouvellement saisi est égal à l'indicateur de renouvellement avant saisie | P12: A_POS_INDREN [Saisi] = A_POS_INDREN [Valeur avant saisie] | Q12: Contractuel | R12: P0003 | S12: Général | T12: Passant | U12: 40725 | V12: 41721 | W12: MAD_D_019 ET MAD_D_816 ET MAD_D_014 ET MAD_D_039 ET MAD_D_817 ET POS_C_004 ET POS_C_006 ET POS_C_007 ET POS_C_010 ET POS_C_012 ET POS_C_037 ET POS_C_106 ET POS_C_111 ET POS_C_431 ET POS_C_434 | BB12: MAD_D_019 | BC12: =VLOOKUP(BB12,'Axe 2 Règles de gestion'!$D$2:$F$271,3, FALSE) -> La durée prévisionnelle est fixée à 3 ans maximum renouvelable pour chaque période. | BD12: MAD_D_816 | BE12: =VLOOKUP(BD12,'Axe 2 Règles de gestion'!$D$2:$F$271,3, FALSE) -> La durée réelle est fixée à 3 ans maximum renouvelable pour chaque période. | BF12: MAD_D_014 | BG12: =VLOOKUP(BF12,'Axe 2 Règles de gestion'!$D$2:$F$271,3, FALSE) -> Le type de contrat doit être un CDI. | BH12: MAD_D_039 | BI12: =VLOOKUP(BH12,'Axe 2 Règles de gestion'!$D$2:$F$271,3, FALSE) -> La durée totale prévisionnelle de la mise à disposition ne peut excéder 6 années consécutives. | BJ12: MAD_D_817 | BK12: =VLOOKUP(BJ12,'Axe 2 Règles de gestion'!$D$2:$F$271,3, FALSE) -> La durée totale réelle de la mise à disposition ne peut excéder 6 années consécutives. | BR12: POS_C_004 | BS12: =VLOOKUP(BR12,'Axe 2 Règles de gestion'!$D$2:$F$271,3, FALSE) -> La date de début de position doit être antérieure ou égale à la date de fin prévisionnelle de position. | BT12: POS_C_006 | BU12: =VLOOKUP(BT12,'Axe 2 Règles de gestion'!$D$2:$F$271,3, FALSE) -> La date de fin réelle de la position doit être antérieure ou égale à la date de fin réelle ou prévisionnelle du lien juridique. | BV12: POS_C_007 | BW12: =VLOOKUP(BV12,'Axe 2 Règles de gestion'!$D$2:$F$271,3, FALSE) -> La date de fin réelle de la position doit être antérieure à la date limite de départ à la retraite. | BX12: POS_C_010 | BY12: =VLOOKUP(BX12,'Axe 2 Règles de gestion'!$D$2:$F$271,3, FALSE) -> La date de début de position doit être antérieure ou égale à la date de fin réelle de position. | BZ12: POS_C_012 | CA12: =VLOOKUP(BZ12,'Axe 2 Règles de gestion'!$D$2:$F$271,3, FALSE) -> La date de fin prévisionnelle de la position doit être antérieure à la date limite de départ à la retraite. | CB12: POS_C_037 | CC12: =VLOOKUP(CB12,'Axe 2 Règles de gestion'!$D$2:$F$271,3, FALSE) -> Les champs "Type d'organisme d'accueil" et "Pays" de l'organisme d'accueil doivent être renseignés. | CD12: POS_C_106 | CE12: =VLOOKUP(CD12,'Axe 2 Règles de gestion'!$D$2:$F$271,3, FALSE) -> La date de fin prévisionnelle de la position doit être antérieure ou égale à la date de fin réelle ou prévisionnelle du lien juridique. | CF12: POS_C_111 | CG12: =VLOOKUP(CF12,'Axe 2 Règles de gestion'!$D$2:$F$271,3, FALSE) -> La date de fin ou la date de fin prévisionnelle doit être saisie. | CH12: POS_C_431 | CI12: =VLOOKUP(CH12,'Axe 2 Règles de gestion'!$D$2:$F$271,3, FALSE) -> Les champs "Ministère (ou institution de la République) d'accueil", "Corps d'accueil en détachement" et "Grade d'accueil en détachement" ou "Ministère (ou institution de la République) d'accueil", "Emploi fonctionnel d'accueil en détachement" et "Groupe dans un emploi fonctionnel d'accueil" sont renseignés si le "Type d'organisme d'accueil" est valorisé à FPE. | CJ12: POS_C_434 | CK12: =VLOOKUP(CJ12,'Axe 2 Règles de gestion'!$D$2:$F$271,3, FALSE) -> Le champ "Organisme d'accueil" doit être alimenté si le type d'organisme d'accueil est égal à 'Autre organisme', 'Fonction publique d'un état de l'Union Européenne' ou 'Fonction publique Européenne'.
