Workbook

Sheet Mode opératoire
B1: MODE OPERATOIRE
B2: La transaction s'effectue au niveau de la sous-rubrique Position statutaire/situation administrative.

Sheet Axe 1 Enchainement des RG
A1: Version | B1: Type de mise à jour | C1: Date de mise à jour | D1: Identifiant Domaine | E1: Libellé du Domaine | F1: Identifiant Sous-domaine | G1: Libellé du Sous-domaine | H1: Identifiant Evénement | I1: Libellé de l'évènement | J1: Libellé condition déclenchement Evènement | K1: Condition déclenchement Evènement | L1: Identifiant type d'évènement | M1: Libellé type d'évènement | N1: Type de mise à jour | O1: Libellé condition déclenchement Type Evènement | P1: Condition déclenchement Type Evènement | Q1: Libellé Population | R1: Codification Population | S1: Général / Particulier | T1: Passant / Exclu | U1: Date de début | V1: Date de fin | W1: Règles mobilisées | X1: Identifiant Règle de contrôle intellectuel 1 | Y1: Libellé Règle de contrôle intellectuel 1 | Z1: Identifiant Règle de contrôle intellectuel 2 | AA1: Libellé Règle de contrôle intellectuel 2 | AB1: Identifiant Règle de contrôle intellectuel 3 | AC1: Libellé Règle de contrôle intellectuel 3 | AD1: Identifiant Règle de contrôle intellectuel 4 | AE1: Libellé Règle de contrôle intellectuel 4 | AF1: Identifiant Règle de contrôle intellectuel 5 | AG1: Libellé Règle de contrôle intellectuel 5 | AH1: Identifiant Règle de contrôle intellectuel 6 | AI1: Libellé Règle de contrôle intellectuel 6 | AJ1: Identifiant Règle de contrôle intellectuel 7 | AK1: Libellé Règle de contrôle intellectuel 7 | AL1: Identifiant Règle de contrôle intellectuel 8 | AM1: Libellé Règle de contrôle intellectuel 8 | AN1: Identifiant Règle de condition 1 | AO1: Libellé Règle de condition 1 | AP1: Identifiant Règle de condition 2 | AQ1: Libellé Règle de condition 2 | AR1: Identifiant Règle de condition 3 | AS1: Libellé Règle de condition 3 | AT1: Identifiant Règle de condition 4 | AU1: Libellé Règle de condition 4 | AV1: Identifiant Règle de condition 5 | AW1: Libellé Règle de condition 5 | AX1: Identifiant Règle de condition 6 | AY1: Libellé Règle de condition 6 | AZ1: Identifiant Règle de condition 7 | BA1: Libellé Règle de condition 7 | BB1: Identifiant Règle de contrôle 1 | BC1: Libellé Règle de contrôle 1 | BD1: Identifiant Règle de contrôle 2 | BE1: Libellé Règle de contrôle 2 | BF1: Identifiant Règle de contrôle 3 | BG1: Libellé Règle de contrôle 3 | BH1: Identifiant Règle de contrôle 4 | BI1: Libellé Règle de contrôle 4 | BJ1: Identifiant Règle de contrôle 5 | BK1: Libellé Règle de contrôle 5 | BL1: Identifiant Règle de contrôle 6 | BM1: Libellé Règle de contrôle 6 | BN1: Identifiant Règle de contrôle 7 | BO1: Libellé Règle de contrôle 7 | BP1: Identifiant Règle de contrôle 8 | BQ1: Libellé Règle de contrôle 8 | BR1: Identifiant Règle de contrôle 9 | BS1: Libellé Règle de contrôle 9 | BT1: Identifiant Règle de contrôle 10 | BU1: Libellé Règle de contrôle 10 | BV1: Identifiant Règle de contrôle 11 | BW1: Libellé Règle de contrôle 11 | BX1: Identifiant Règle de contrôle 12 | BY1: Libellé Règle de contrôle 12 | BZ1: Identifiant Règle de contrôle 13 | CA1: Libellé Règle de contrôle 13 | CB1: FIME | CC1: Statut de travail
A2: 22.10.00 | B2: A | C2: 44970.484 | D2: D0004 | E2: Position | F2: S0166 | G2: Congé pour convenances personnelles (militaire) | H2: E0918 | I2: Congé pour convenances personnelles militaire | J2: La position saisie est 'Congé pour convenances personnelles militaire' | K2: A_POS_POSIAD [Saisi] = 'NAM25' | L2: T2240 | M2: Congé pour convenances personnelles (militaire) - Demande | N2: Création Modification | O2: Indicateur de renouvellement saisi = Non ET (Indicateur de renouvellement saisi différent d'Indicateur de renouvellement avant saisi) | P2: A_POS_INDREN [Saisi] = '0' ET (A_POS_INDREN [Saisi] <> A_POS_INDREN [Valeur avant saisie]) | Q2: Titulaire ou magistrat | R2: P0001 | S2: Général | T2: Exclu | U2: 43831
A3: 22.10.00 | B3: A | C3: 44970.486 | D3: D0004 | E3: Position | F3: S0166 | G3: Congé pour convenances personnelles (militaire) | H3: E0918 | I3: Congé pour convenances personnelles militaire | J3: La position saisie est 'Congé pour convenances personnelles militaire' | K3: A_POS_POSIAD [Saisi] = 'NAM25' | L3: T2241 | M3: Congé pour convenances personnelles (militaire) - Renouvellement | N3: Création Modification | O3: Indicateur de renouvellement saisi = Oui ET (Indicateur de renouvellement saisi différent d'Indicateur de renouvellement avant saisi) | P3: A_POS_INDREN [Saisi] = '1' ET (A_POS_INDREN [Saisi] <> A_POS_INDREN [Valeur avant saisie] | Q3: Titulaire ou magistrat | R3: P0001 | S3: Général | T3: Exclu | U3: 43831
A4: 22.10.00 | B4: A | C4: 44970.493 | D4: D0004 | E4: Position | F4: S0166 | G4: Congé pour convenances personnelles (militaire) | H4: E0918 | I4: Congé pour convenances personnelles militaire | J4: La position saisie est 'Congé pour convenances personnelles militaire' | K4: A_POS_POSIAD [Saisi] = 'NAM25' | L4: T2242 | M4: Congé pour convenances personnelles (militaire) - Fin | N4: Modification | O4: Indicateur de renouvellement saisi identique à Indicateur de renouvellement avant saisi | P4: A_POS_INDREN [Saisi] = A_POS_INDREN [Valeur avant saisie] | Q4: Titulaire ou magistrat | R4: P0001 | S4: Général | T4: Exclu | U4: 43831
A5: 22.10.00 | B5: A | C5: 44970.485 | D5: D0004 | E5: Position | F5: S0166 | G5: Congé pour convenances personnelles (militaire) | H5: E0918 | I5: Congé pour convenances personnelles militaire | J5: La position saisie est 'Congé pour convenances personnelles militaire' | K5: A_POS_POSIAD [Saisi] = 'NAM25' | L5: T2240 | M5: Congé pour convenances personnelles (militaire) - Demande | N5: Création Modification | O5: Indicateur de renouvellement saisi = Non ET (Indicateur de renouvellement saisi différent d'Indicateur de renouvellement avant saisi) | P5: A_POS_INDREN [Saisi] = '0' ET (A_POS_INDREN [Saisi] <> A_POS_INDREN [Valeur avant saisie]) | Q5: Militaire | R5: P0002 | S5: Général | T5: Exclu | U5: 43831
A6: 22.10.00 | B6: A | C6: 44970.487 | D6: D0004 | E6: Position | F6: S0166 | G6: Congé pour convenances personnelles (militaire) | H6: E0918 | I6: Congé pour convenances personnelles militaire | J6: La position saisie est 'Congé pour convenances personnelles militaire' | K6: A_POS_POSIAD [Saisi] = 'NAM25' | L6: T2241 | M6: Congé pour convenances personnelles (militaire) - Renouvellement | N6: Création Modification | O6: Indicateur de renouvellement saisi = Oui ET (Indicateur de renouvellement saisi différent d'Indicateur de renouvellement avant saisi) | P6: A_POS_INDREN [Saisi] = '1' ET (A_POS_INDREN [Saisi] <> A_POS_INDREN [Valeur avant saisie] | Q6: Militaire | R6: P0002 | S6: Général | T6: Exclu | U6: 43831
A7: 22.10.00 | B7: A | C7: 44970.493 | D7: D0004 | E7: Position | F7: S0166 | G7: Congé pour convenances personnelles (militaire) | H7: E0918 | I7: Congé pour convenances personnelles militaire | J7: La position saisie est 'Congé pour convenances personnelles militaire' | K7: A_POS_POSIAD [Saisi] = 'NAM25' | L7: T2242 | M7: Congé pour convenances personnelles (militaire) - Fin | N7: Modification | O7: Indicateur de renouvellement saisi identique à Indicateur de renouvellement avant saisi | P7: A_POS_INDREN [Saisi] = A_POS_INDREN [Valeur avant saisie] | Q7: Militaire | R7: P0002 | S7: Général | T7: Exclu | U7: 43831
A8: 22.10.00 | B8: A | C8: 44970.485 | D8: D0004 | E8: Position | F8: S0166 | G8: Congé pour convenances personnelles (militaire) | H8: E0918 | I8: Congé pour convenances personnelles militaire | J8: La position saisie est 'Congé pour convenances personnelles militaire' | K8: A_POS_POSIAD [Saisi] = 'NAM25' | L8: T2240 | M8: Congé pour convenances personnelles (militaire) - Demande | N8: Création Modification | O8: Indicateur de renouvellement saisi = Non ET (Indicateur de renouvellement saisi différent d'Indicateur de renouvellement avant saisi) | P8: A_POS_INDREN [Saisi] = '0' ET (A_POS_INDREN [Saisi] <> A_POS_INDREN [Valeur avant saisie]) | Q8: Contractuel | R8: P0003 | S8: Général | T8: Exclu | U8: 43831
A9: 22.10.00 | B9: A | C9: 44970.488 | D9: D0004 | E9: Position | F9: S0166 | G9: Congé pour convenances personnelles (militaire) | H9: E0918 | I9: Congé pour convenances personnelles militaire | J9: La position saisie est 'Congé pour convenances personnelles militaire' | K9: A_POS_POSIAD [Saisi] = 'NAM25' | L9: T2241 | M9: Congé pour convenances personnelles (militaire) - Renouvellement | N9: Création Modification | O9: Indicateur de renouvellement saisi = Oui ET (Indicateur de renouvellement saisi différent d'Indicateur de renouvellement avant saisi) | P9: A_POS_INDREN [Saisi] = '1' ET (A_POS_INDREN [Saisi] <> A_POS_INDREN [Valeur avant saisie] | Q9: Contractuel | R9: P0003 | S9: Général | T9: Exclu | U9: 43831
A10: 22.10.00 | B10: A | C10: 44970.493 | D10: D0004 | E10: Position | F10: S0166 | G10: Congé pour convenances personnelles (militaire) | H10: E0918 | I10: Congé pour convenances personnelles militaire | J10: La position saisie est 'Congé pour convenances personnelles militaire' | K10: A_POS_POSIAD [Saisi] = 'NAM25' | L10: T2242 | M10: Congé pour convenances personnelles (militaire) - Fin | N10: Modification | O10: Indicateur de renouvellement saisi identique à Indicateur de renouvellement avant saisi | P10: A_POS_INDREN [Saisi] = A_POS_INDREN [Valeur avant saisie] | Q10: Contractuel | R10: P0003 | S10: Général | T10: Exclu | U10: 43831
A11: 22.10.00 | B11: A | C11: 44970.486 | D11: D0004 | E11: Position | F11: S0166 | G11: Congé pour convenances personnelles (militaire) | H11: E0918 | I11: Congé pour convenances personnelles militaire | J11: La position saisie est 'Congé pour convenances personnelles militaire' | K11: A_POS_POSIAD [Saisi] = 'NAM25' | L11: T2240 | M11: Congé pour convenances personnelles (militaire) - Demande | N11: Création Modification | O11: Indicateur de renouvellement saisi = Non ET (Indicateur de renouvellement saisi différent d'Indicateur de renouvellement avant saisi) | P11: A_POS_INDREN [Saisi] = '0' ET (A_POS_INDREN [Saisi] <> A_POS_INDREN [Valeur avant saisie]) | Q11: Stagiaire ou auditeur ou élève | R11: P0004 | S11: Général | T11: Exclu | U11: 43831
A12: 22.10.00 | B12: A | C12: 44974.546 | D12: D0004 | E12: Position | F12: S0166 | G12: Congé pour convenances personnelles (militaire) | H12: E0918 | I12: Congé pour convenances personnelles militaire | J12: La position saisie est 'Congé pour convenances personnelles militaire' | K12: A_POS_POSIAD [Saisi] = 'NAM25' | L12: T2241 | M12: Congé pour convenances personnelles (militaire) - Renouvellement | N12: Création Modification | O12: Indicateur de renouvellement saisi = Oui ET (Indicateur de renouvellement saisi différent d'Indicateur de renouvellement avant saisi) | P12: A_POS_INDREN [Saisi] = '1' ET (A_POS_INDREN [Saisi] <> A_POS_INDREN [Valeur avant saisie] | Q12: Stagiaire ou auditeur ou élève | R12: P0004 | S12: Général | T12: Exclu | U12: 43832
A13: 22.10.00 | B13: A | C13: 44974.552 | D13: D0004 | E13: Position | F13: S0166 | G13: Congé pour convenances personnelles (militaire) | H13: E0918 | I13: Congé pour convenances personnelles militaire | J13: La position saisie est 'Congé pour convenances personnelles militaire' | K13: A_POS_POSIAD [Saisi] = 'NAM25' | L13: T2242 | M13: Congé pour convenances personnelles (militaire) - Fin | N13: Modification | O13: Indicateur de renouvellement saisi identique à Indicateur de renouvellement avant saisi | P13: A_POS_INDREN [Saisi] = A_POS_INDREN [Valeur avant saisie] | Q13: Stagiaire ou auditeur ou élève | R13: P0004 | S13: Général | T13: Exclu | U13: 43832
... A16: 22.10.00 | B16: A | C16: 44970.494 | D16: D0004 | E16: Position | F16: S0166 | G16: Congé pour convenances personnelles (militaire) | H16: E0918 | I16: Congé pour convenances personnelles militaire | J16: La position saisie est 'Congé pour convenances personnelles militaire' | K16: A_POS_POSIAD [Saisi] = 'NAM25' | L16: T2242 | M16: Congé pour convenances personnelles (militaire) - Fin | N16: Modification | O16: Indicateur de renouvellement saisi identique à Indicateur de renouvellement avant saisi | P16: A_POS_INDREN [Saisi] = A_POS_INDREN [Valeur avant saisie] | Q16: Ouvrier d'état | R16: P0005 | S16: Général | T16: Exclu | U16: 43831
A17: 24.00.00 | B17: M | C17: 45428.472 | D17: D0004 | E17: Position | F17: S0166 | G17: Congé pour convenances personnelles (militaire) | H17: E0918 | I17: Congé pour convenances personnelles militaire | J17: La position saisie est 'Congé pour convenances personnelles militaire' | K17: A_POS_POSIAD [Saisi] = 'NAM25' | L17: T2240 | M17: Congé pour convenances personnelles (militaire) - Demande | N17: Création Modification | O17: Indicateur de renouvellement saisi = Non ET (Indicateur de renouvellement saisi différent d'Indicateur de renouvellement avant saisi) | P17: A_POS_INDREN [Saisi] = '0' ET (A_POS_INDREN [Saisi] <> A_POS_INDREN [Valeur avant saisie]) | Q17: Militaire sous contrat | R17: P0145 | S17: Particulier | T17: Passant | U17: 43831 | V17: 45123 | W17: CCP_I_003 ET CCP_I_011 ET CCP_I_012 ET CCP_I_013 ET CCP_I_001 ET CCP_I_002 ET CCP_I_004 ET CCP_I_014 ET CCP_D_004 ET CCP_D_001 ET CCP_D_005 ET CCP_D_002 ET CCP_D_003 ET POS_C_004 ET POS_C_007 ET POS_C_009 ET POS_C_010 ET POS_C_012 ET POS_C_022 ET POS_C_111 ET POS_C_120 ET POS_C_121 | X17: CCP_I_003 | Y17: =VLOOKUP(X17,'Axe 2 Règles de gestion'!$D$2:$F$49,3, FALSE) -> Le militaire doit avoir accompli au moins 4 ans de services, dont 2 ans pour les officiers en cette qualité, sauf exceptions. | Z17: CCP_I_011 | AA17: =VLOOKUP(Z17,'Axe 2 Règles de gestion'!$D$2:$F$49,3, FALSE) -> La condition de service n'est pas exigée pour suivre son conjoint ou son partenaire lié par un PACS lorsque celui-ci est astreint à établir sa résidence habituelle, en raison de sa profession, en un lieu éloigné d'affectation du militaire. | AB17: CCP_I_012 | AC17: =VLOOKUP(AB17,'Axe 2 Règles de gestion'!$D$2:$F$49,3, FALSE) -> La condition de service n'est pas exigée du militaire qui sollicite un congé pour donner des soins à un enfant à charge, au conjoint, au partenaire avec lequel il est lié par un PACS, ou à un ascendant. | AD17: CCP_I_013 | AE17: =VLOOKUP(AD17,'Axe 2 Règles de gestion'!$D$2:$F$49,3, FALSE) -> Les soins font suite à un accident ou une maladie grave ou à un handicap nécessitant la présence d'une tierce personne. | AF17: CCP_I_001 | AG17: =VLOOKUP(AF17,'Axe 2 Règles de gestion'!$D$2:$F$49,3, FALSE) -> Le militaire doit présenter une demande. | AH17: CCP_I_002 | AI17: =VLOOKUP(AH17,'Axe 2 Règles de gestion'!$D$2:$F$49,3, FALSE) -> Le militaire est placé en congé par décision du ministre compétent. | AJ17: CCP_I_004 | AK17: =VLOOKUP(AJ17,'Axe 2 Règles de gestion'!$D$2:$F$49,3, FALSE) -> Le militaire officier qui demande à être placé dans ce congé, est tenu d'informer sans délai par écrit le ministre compétent de la nature de l'activité privée lucrative qu'il se propose d'exercer. | AL17: CCP_I_014 | AM17: =VLOOKUP(AL17,'Axe 2 Règles de gestion'!$D$2:$F$49,3, FALSE) -> Le militaire officier est tenu d'informer sans délai par écrit le ministre compétent de tout changement d'activité privée lucrative. | AN17: CCP_D_004 | AO17: =VLOOKUP(AN17,'Axe 2 Règles de gestion'!$D$2:$F$49,3, FALSE) -> La durée prévisionnelle du congé ne peut pas excéder 2 ans pour chaque période. | AP17: CCP_D_001 | AQ17: =VLOOKUP(AP17,'Axe 2 Règles de gestion'!$D$2:$F$49,3, FALSE) -> La durée réelle du congé ne peut pas excéder 2 ans pour chaque période. | AR17: CCP_D_005 | AS17: =VLOOKUP(AR17,'Axe 2 Règles de gestion'!$D$2:$F$49,3, FALSE) -> La durée cumulée de l'ensemble des congés pour convenances personnelles ne doit pas excéder 10 ans. | AT17: CCP_D_002 | AU17: =VLOOKUP(AT17,'Axe 2 Règles de gestion'!$D$2:$F$49,3, FALSE) -> La date de fin réelle du congé doit être antérieure ou égale à la date limite de fin réelle ou prévisionnelle du lien juridique. Le militaire ne voit pas son contrat prorogé jusqu'à la date de fin du congé. | AV17: CCP_D_003 | AW17: =VLOOKUP(AV17,'Axe 2 Règles de gestion'!$D$2:$F$49,3, FALSE) -> La date de fin prévisionnelle du congé doit être antérieure ou égale à la date limite de fin réelle ou prévisionnelle du lien juridique. Le militaire ne voit pas son contrat prorogé jusqu'à la date de fin du congé. | BB17: POS_C_004 | BC17: =VLOOKUP(BB17,'Axe 2 Règles de gestion'!$D$2:$F$49,3, FALSE) -> La date de début de position doit être antérieure ou égale à la date de fin prévisionnelle de position. | BD17: POS_C_007 | BE17: =VLOOKUP(BD17,'Axe 2 Règles de gestion'!$D$2:$F$49,3, FALSE) -> La date de fin réelle de la position doit être antérieure à la date limite de départ à la retraite. | BF17: POS_C_009 | BG17: =VLOOKUP(BF17,'Axe 2 Règles de gestion'!$D$2:$F$49,3, FALSE) -> La date de début de la position doit être postérieure ou égale à la date de début du lien juridique. | BH17: POS_C_010 | BI17: =VLOOKUP(BH17,'Axe 2 Règles de gestion'!$D$2:$F$49,3, FALSE) -> La date de début de position doit être antérieure ou égale à la date de fin réelle de position. | BJ17: POS_C_012 | BK17: =VLOOKUP(BJ17,'Axe 2 Règles de gestion'!$D$2:$F$49,3, FALSE) -> La date de fin prévisionnelle de la position doit être antérieure à la date limite de départ à la retraite. | BL17: POS_C_022 | BM17: =VLOOKUP(BL17,'Axe 2 Règles de gestion'!$D$2:$F$49,3, FALSE) -> La date de début de position est à J+1 de la date de fin de position de l'occurrence précédente. | BN17: POS_C_111 | BO17: =VLOOKUP(BN17,'Axe 2 Règles de gestion'!$D$2:$F$49,3, FALSE) -> La date de fin ou la date de fin prévisionnelle doit être saisie. | BP17: POS_C_120 | BQ17: =VLOOKUP(BP17,'Axe 2 Règles de gestion'!$D$2:$F$49,3, FALSE) -> La saisie d'une occurrence de congés/absences est interdite (date de fin réelle) | BR17: POS_C_121 | BS17: =VLOOKUP(BR17,'Axe 2 Règles de gestion'!$D$2:$F$49,3, FALSE) -> La saisie d'une occurrence de congés/absences est interdite (date de fin prévisionnelle)
A18: 24.00.00 | B18: A | C18: 45428.472 | D18: D0004 | E18: Position | F18: S0166 | G18: Congé pour convenances personnelles (militaire) | H18: E0918 | I18: Congé pour convenances personnelles militaire | J18: La position saisie est 'Congé pour convenances personnelles militaire' | K18: A_POS_POSIAD [Saisi] = 'NAM25' | L18: T2240 | M18: Congé pour convenances personnelles (militaire) - Demande | N18: Création Modification | O18: Indicateur de renouvellement saisi = Non ET (Indicateur de renouvellement saisi différent d'Indicateur de renouvellement avant saisi) | P18: A_POS_INDREN [Saisi] = '0' ET (A_POS_INDREN [Saisi] <> A_POS_INDREN [Valeur avant saisie]) | Q18: Militaire sous contrat | R18: P0145 | S18: Particulier | T18: Passant | U18: 45124 | W18: CCP_I_003 ET CCP_I_012 ET CCP_I_013 ET CCP_I_001 ET CCP_I_002 ET CCP_I_004 ET CCP_I_014 ET CCP_D_004 ET CCP_D_001 ET CCP_D_005 ET CCP_D_002 ET CCP_D_003 ET POS_C_004 ET POS_C_007 ET POS_C_009 ET POS_C_010 ET POS_C_012 ET POS_C_022 ET POS_C_111 ET POS_C_120 ET POS_C_121 | X18: CCP_I_003 | Y18: =VLOOKUP(X18,'Axe 2 Règles de gestion'!$D$2:$F$49,3, FALSE) -> Le militaire doit avoir accompli au moins 4 ans de services, dont 2 ans pour les officiers en cette qualité, sauf exceptions. | Z18: CCP_I_012 | AA18: =VLOOKUP(Z18,'Axe 2 Règles de gestion'!$D$2:$F$49,3, FALSE) -> La condition de service n'est pas exigée du militaire qui sollicite un congé pour donner des soins à un enfant à charge, au conjoint, au partenaire avec lequel il est lié par un PACS, ou à un ascendant. | AB18: CCP_I_013 | AC18: =VLOOKUP(AB18,'Axe 2 Règles de gestion'!$D$2:$F$49,3, FALSE) -> Les soins font suite à un accident ou une maladie grave ou à un handicap nécessitant la présence d'une tierce personne. | AD18: CCP_I_001 | AE18: =VLOOKUP(AD18,'Axe 2 Règles de gestion'!$D$2:$F$49,3, FALSE) -> Le militaire doit présenter une demande. | AF18: CCP_I_002 | AG18: =VLOOKUP(AF18,'Axe 2 Règles de gestion'!$D$2:$F$49,3, FALSE) -> Le militaire est placé en congé par décision du ministre compétent. | AH18: CCP_I_004 | AI18: =VLOOKUP(AH18,'Axe 2 Règles de gestion'!$D$2:$F$49,3, FALSE) -> Le militaire officier qui demande à être placé dans ce congé, est tenu d'informer sans délai par écrit le ministre compétent de la nature de l'activité privée lucrative qu'il se propose d'exercer. | AJ18: CCP_I_014 | AK18: =VLOOKUP(AJ18,'Axe 2 Règles de gestion'!$D$2:$F$49,3, FALSE) -> Le militaire officier est tenu d'informer sans délai par écrit le ministre compétent de tout changement d'activité privée lucrative. | AN18: CCP_D_004 | AO18: =VLOOKUP(AN18,'Axe 2 Règles de gestion'!$D$2:$F$49,3, FALSE) -> La durée prévisionnelle du congé ne peut pas excéder 2 ans pour chaque période. | AP18: CCP_D_001 | AQ18: =VLOOKUP(AP18,'Axe 2 Règles de gestion'!$D$2:$F$49,3, FALSE) -> La durée réelle du congé ne peut pas excéder 2 ans pour chaque période. | AR18: CCP_D_005 | AS18: =VLOOKUP(AR18,'Axe 2 Règles de gestion'!$D$2:$F$49,3, FALSE) -> La durée cumulée de l'ensemble des congés pour convenances personnelles ne doit pas excéder 10 ans. | AT18: CCP_D_002 | AU18: =VLOOKUP(AT18,'Axe 2 Règles de gestion'!$D$2:$F$49,3, FALSE) -> La date de fin réelle du congé doit être antérieure ou égale à la date limite de fin réelle ou prévisionnelle du lien juridique. Le militaire ne voit pas son contrat prorogé jusqu'à la date de fin du congé. | AV18: CCP_D_003 | AW18: =VLOOKUP(AV18,'Axe 2 Règles de gestion'!$D$2:$F$49,3, FALSE) -> La date de fin prévisionnelle du congé doit être antérieure ou égale à la date limite de fin réelle ou prévisionnelle du lien juridique. Le militaire ne voit pas son contrat prorogé jusqu'à la date de fin du congé. | BB18: POS_C_004 | BC18: =VLOOKUP(BB18,'Axe 2 Règles de gestion'!$D$2:$F$49,3, FALSE) -> La date de début de position doit être antérieure ou égale à la date de fin prévisionnelle de position. | BD18: POS_C_007 | BE18: =VLOOKUP(BD18,'Axe 2 Règles de gestion'!$D$2:$F$49,3, FALSE) -> La date de fin réelle de la position doit être antérieure à la date limite de départ à la retraite. | BF18: POS_C_009 | BG18: =VLOOKUP(BF18,'Axe 2 Règles de gestion'!$D$2:$F$49,3, FALSE) -> La date de début de la position doit être postérieure ou égale à la date de début du lien juridique. | BH18: POS_C_010 | BI18: =VLOOKUP(BH18,'Axe 2 Règles de gestion'!$D$2:$F$49,3, FALSE) -> La date de début de position doit être antérieure ou égale à la date de fin réelle de position. | BJ18: POS_C_012 | BK18: =VLOOKUP(BJ18,'Axe 2 Règles de gestion'!$D$2:$F$49,3, FALSE) -> La date de fin prévisionnelle de la position doit être antérieure à la date limite de départ à la retraite. | BL18: POS_C_022 | BM18: =VLOOKUP(BL18,'Axe 2 Règles de gestion'!$D$2:$F$49,3, FALSE) -> La date de début de position est à J+1 de la date de fin de position de l'occurrence précédente. | BN18: POS_C_111 | BO18: =VLOOKUP(BN18,'Axe 2 Règles de gestion'!$D$2:$F$49,3, FALSE) -> La date de fin ou la date de fin prévisionnelle doit être saisie. | BP18: POS_C_120 | BQ18: =VLOOKUP(BP18,'Axe 2 Règles de gestion'!$D$2:$F$49,3, FALSE) -> La saisie d'une occurrence de congés/absences est interdite (date de fin réelle) | BR18: POS_C_121 | BS18: =VLOOKUP(BR18,'Axe 2 Règles de gestion'!$D$2:$F$49,3, FALSE) -> La saisie d'une occurrence de congés/absences est interdite (date de fin prévisionnelle)
A19: 22.10.00 | B19: A | C19: 44970.658 | D19: D0004 | E19: Position | F19: S0166 | G19: Congé pour convenances personnelles (militaire) | H19: E0918 | I19: Congé pour convenances personnelles militaire | J19: La position saisie est 'Congé pour convenances personnelles militaire' | K19: A_POS_POSIAD [Saisi] = 'NAM25' | L19: T2241 | M19: Congé pour convenances personnelles (militaire) - Renouvellement | N19: Création Modification | O19: Indicateur de renouvellement saisi = Oui ET (Indicateur de renouvellement saisi différent d'Indicateur de renouvellement avant saisi) | P19: A_POS_INDREN [Saisi] = '1' ET (A_POS_INDREN [Saisi] <> A_POS_INDREN [Valeur avant saisie] | Q19: Militaire sous contrat | R19: P0145 | S19: Particulier | T19: Passant | U19: 43831 | W19: CCP_I_005 ET CCP_I_001 ET CCP_I_002 ET CCP_I_004 ET CCP_I_014 ET CCP_D_004 ET CCP_D_001 ET CCP_D_005 ET CCP_D_002 ET CCP_D_003 ET POS_C_004 ET POS_C_007 ET POS_C_009 ET POS_C_010 ET POS_C_012 ET POS_C_022 ET POS_C_111 ET POS_C_120 ET POS_C_121 | X19: CCP_I_005 | Y19: =VLOOKUP(X19,'Axe 2 Règles de gestion'!$D$2:$F$49,3, FALSE) -> Le militaire peut demander le renouvellement du congé 3 mois avant l'expiration du congé. | Z19: CCP_I_001 | AA19: =VLOOKUP(Z19,'Axe 2 Règles de gestion'!$D$2:$F$49,3, FALSE) -> Le militaire doit présenter une demande. | AB19: CCP_I_002 | AC19: =VLOOKUP(AB19,'Axe 2 Règles de gestion'!$D$2:$F$49,3, FALSE) -> Le militaire est placé en congé par décision du ministre compétent. | AD19: CCP_I_004 | AE19: =VLOOKUP(AD19,'Axe 2 Règles de gestion'!$D$2:$F$49,3, FALSE) -> Le militaire officier qui demande à être placé dans ce congé, est tenu d'informer sans délai par écrit le ministre compétent de la nature de l'activité privée lucrative qu'il se propose d'exercer. | AF19: CCP_I_014 | AG19: =VLOOKUP(AF19,'Axe 2 Règles de gestion'!$D$2:$F$49,3, FALSE) -> Le militaire officier est tenu d'informer sans délai par écrit le ministre compétent de tout changement d'activité privée lucrative. | AN19: CCP_D_004 | AO19: =VLOOKUP(AN19,'Axe 2 Règles de gestion'!$D$2:$F$49,3, FALSE) -> La durée prévisionnelle du congé ne peut pas excéder 2 ans pour chaque période. | AP19: CCP_D_001 | AQ19: =VLOOKUP(AP19,'Axe 2 Règles de gestion'!$D$2:$F$49,3, FALSE) -> La durée réelle du congé ne peut pas excéder 2 ans pour chaque période. | AR19: CCP_D_005 | AS19: =VLOOKUP(AR19,'Axe 2 Règles de gestion'!$D$2:$F$49,3, FALSE) -> La durée cumulée de l'ensemble des congés pour convenances personnelles ne doit pas excéder 10 ans. | AT19: CCP_D_002 | AU19: =VLOOKUP(AT19,'Axe 2 Règles de gestion'!$D$2:$F$49,3, FALSE) -> La date de fin réelle du congé doit être antérieure ou égale à la date limite de fin réelle ou prévisionnelle du lien juridique. Le militaire ne voit pas son contrat prorogé jusqu'à la date de fin du congé. | AV19: CCP_D_003 | AW19: =VLOOKUP(AV19,'Axe 2 Règles de gestion'!$D$2:$F$49,3, FALSE) -> La date de fin prévisionnelle du congé doit être antérieure ou égale à la date limite de fin réelle ou prévisionnelle du lien juridique. Le militaire ne voit pas son contrat prorogé jusqu'à la date de fin du congé. | BB19: POS_C_004 | BC19: =VLOOKUP(BB19,'Axe 2 Règles de gestion'!$D$2:$F$49,3, FALSE) -> La date de début de position doit être antérieure ou égale à la date de fin prévisionnelle de position. | BD19: POS_C_007 | BE19: =VLOOKUP(BD19,'Axe 2 Règles de gestion'!$D$2:$F$49,3, FALSE) -> La date de fin réelle de la position doit être antérieure à la date limite de départ à la retraite. | BF19: POS_C_009 | BG19: =VLOOKUP(BF19,'Axe 2 Règles de gestion'!$D$2:$F$49,3, FALSE) -> La date de début de la position doit être postérieure ou égale à la date de début du lien juridique. | BH19: POS_C_010 | BI19: =VLOOKUP(BH19,'Axe 2 Règles de gestion'!$D$2:$F$49,3, FALSE) -> La date de début de position doit être antérieure ou égale à la date de fin réelle de position. | BJ19: POS_C_012 | BK19: =VLOOKUP(BJ19,'Axe 2 Règles de gestion'!$D$2:$F$49,3, FALSE) -> La date de fin prévisionnelle de la position doit être antérieure à la date limite de départ à la retraite. | BL19: POS_C_022 | BM19: =VLOOKUP(BL19,'Axe 2 Règles de gestion'!$D$2:$F$49,3, FALSE) -> La date de début de position est à J+1 de la date de fin de position de l'occurrence précédente. | BN19: POS_C_111 | BO19: =VLOOKUP(BN19,'Axe 2 Règles de gestion'!$D$2:$F$49,3, FALSE) -> La date de fin ou la date de fin prévisionnelle doit être saisie. | BP19: POS_C_120 | BQ19: =VLOOKUP(BP19,'Axe 2 Règles de gestion'!$D$2:$F$49,3, FALSE) -> La saisie d'une occurrence de congés/absences est interdite (date de fin réelle) | BR19: POS_C_121 | BS19: =VLOOKUP(BR19,'Axe 2 Règles de gestion'!$D$2:$F$49,3, FALSE) -> La saisie d'une occurrence de congés/absences est interdite (date de fin prévisionnelle)
A20: 22.10.00 | B20: A | C20: 44970.503 | D20: D0004 | E20: Position | F20: S0166 | G20: Congé pour convenances personnelles (militaire) | H20: E0918 | I20: Congé pour convenances personnelles militaire | J20: La position saisie est 'Congé pour convenances personnelles militaire' | K20: A_POS_POSIAD [Saisi] = 'NAM25' | L20: T2242 | M20: Congé pour convenances personnelles (militaire) - Fin | N20: Modification | O20: Indicateur de renouvellement saisi identique à Indicateur de renouvellement avant saisi | P20: A_POS_INDREN [Saisi] = A_POS_INDREN [Valeur avant saisie] | Q20: Militaire sous contrat | R20: P0145 | S20: Particulier | T20: Passant | U20: 43831 | W20: CCP_I_006 ET CCP_I_007 ET CCP_D_004 ET CCP_D_001 ET CCP_D_005 ET CCP_D_002 ET CCP_D_003 ET POS_C_004 ET POS_C_007 ET POS_C_010 ET POS_C_012 ET POS_C_111 ET POS_C_120 ET POS_C_121 | X20: CCP_I_006 | Y20: =VLOOKUP(X20,'Axe 2 Règles de gestion'!$D$2:$F$49,3, FALSE) -> Le militaire peut demander la réintégration dans son corps d'origine, laquelle est de droit, 3 mois avant l'expiration du congé. | Z20: CCP_I_007 | AA20: =VLOOKUP(Z20,'Axe 2 Règles de gestion'!$D$2:$F$49,3, FALSE) -> Le militaire qui a formulé avant l'expiration du congé une demande de réintégration est maintenu dans cette situation jusqu'à ce qu'il puisse être affecté dans un emploi correspondant à son grade. | AN20: CCP_D_004 | AO20: =VLOOKUP(AN20,'Axe 2 Règles de gestion'!$D$2:$F$49,3, FALSE) -> La durée prévisionnelle du congé ne peut pas excéder 2 ans pour chaque période. | AP20: CCP_D_001 | AQ20: =VLOOKUP(AP20,'Axe 2 Règles de gestion'!$D$2:$F$49,3, FALSE) -> La durée réelle du congé ne peut pas excéder 2 ans pour chaque période. | AR20: CCP_D_005 | AS20: =VLOOKUP(AR20,'Axe 2 Règles de gestion'!$D$2:$F$49,3, FALSE) -> La durée cumulée de l'ensemble des congés pour convenances personnelles ne doit pas excéder 10 ans. | AT20: CCP_D_002 | AU20: =VLOOKUP(AT20,'Axe 2 Règles de gestion'!$D$2:$F$49,3, FALSE) -> La date de fin réelle du congé doit être antérieure ou égale à la date limite de fin réelle ou prévisionnelle du lien juridique. Le militaire ne voit pas son contrat prorogé jusqu'à la date de fin du congé. | AV20: CCP_D_003 | AW20: =VLOOKUP(AV20,'Axe 2 Règles de gestion'!$D$2:$F$49,3, FALSE) -> La date de fin prévisionnelle du congé doit être antérieure ou égale à la date limite de fin réelle ou prévisionnelle du lien juridique. Le militaire ne voit pas son contrat prorogé jusqu'à la date de fin du congé. | BB20: POS_C_004 | BC20: =VLOOKUP(BB20,'Axe 2 Règles de gestion'!$D$2:$F$49,3, FALSE) -> La date de début de position doit être antérieure ou égale à la date de fin prévisionnelle de position. | BD20: POS_C_007 | BE20: =VLOOKUP(BD20,'Axe 2 Règles de gestion'!$D$2:$F$49,3, FALSE) -> La date de fin réelle de la position doit être antérieure à la date limite de départ à la retraite. | BF20: POS_C_010 | BG20: =VLOOKUP(BF20,'Axe 2 Règles de gestion'!$D$2:$F$49,3, FALSE) -> La date de début de position doit être antérieure ou égale à la date de fin réelle de position. | BH20: POS_C_012 | BI20: =VLOOKUP(BH20,'Axe 2 Règles de gestion'!$D$2:$F$49,3, FALSE) -> La date de fin prévisionnelle de la position doit être antérieure à la date limite de départ à la retraite. | BJ20: POS_C_111 | BK20: =VLOOKUP(BJ20,'Axe 2 Règles de gestion'!$D$2:$F$49,3, FALSE) -> La date de fin ou la date de fin prévisionnelle doit être saisie. | BL20: POS_C_120 | BM20: =VLOOKUP(BL20,'Axe 2 Règles de gestion'!$D$2:$F$49,3, FALSE) -> La saisie d'une occurrence de congés/absences est interdite (date de fin réelle) | BN20: POS_C_121 | BO20: =VLOOKUP(BN20,'Axe 2 Règles de gestion'!$D$2:$F$49,3, FALSE) -> La saisie d'une occurrence de congés/absences est interdite (date de fin prévisionnelle)
A21: 24.00.00 | B21: M | C21: 45428.473 | D21: D0004 | E21: Position | F21: S0166 | G21: Congé pour convenances personnelles (militaire) | H21: E0918 | I21: Congé pour convenances personnelles militaire | J21: La position saisie est 'Congé pour convenances personnelles militaire' | K21: A_POS_POSIAD [Saisi] = 'NAM25' | L21: T2240 | M21: Congé pour convenances personnelles (militaire) - Demande | N21: Création Modification | O21: Indicateur de renouvellement saisi = Non ET (Indicateur de renouvellement saisi différent d'Indicateur de renouvellement avant saisi) | P21: A_POS_INDREN [Saisi] = '0' ET (A_POS_INDREN [Saisi] <> A_POS_INDREN [Valeur avant saisie]) | Q21: Militaire de carrière | R21: P0189 | S21: Particulier | T21: Passant | U21: 43831 | V21: 45123 | W21: CCP_I_003 ET CCP_I_011 ET CCP_I_012 ET CCP_I_013 ET CCP_I_001 ET CCP_I_002 ET CCP_I_004 ET CCP_I_014 ET CCP_D_004 ET CCP_D_001 ET CCP_D_005 ET POS_C_004 ET POS_C_005 ET POS_C_007 ET POS_C_010 ET POS_C_012 ET POS_C_022 ET POS_C_055 ET POS_C_056 ET POS_C_111 ET POS_C_120 ET POS_C_121 | X21: CCP_I_003 | Y21: =VLOOKUP(X21,'Axe 2 Règles de gestion'!$D$2:$F$49,3, FALSE) -> Le militaire doit avoir accompli au moins 4 ans de services, dont 2 ans pour les officiers en cette qualité, sauf exceptions. | Z21: CCP_I_011 | AA21: =VLOOKUP(Z21,'Axe 2 Règles de gestion'!$D$2:$F$49,3, FALSE) -> La condition de service n'est pas exigée pour suivre son conjoint ou son partenaire lié par un PACS lorsque celui-ci est astreint à établir sa résidence habituelle, en raison de sa profession, en un lieu éloigné d'affectation du militaire. | AB21: CCP_I_012 | AC21: =VLOOKUP(AB21,'Axe 2 Règles de gestion'!$D$2:$F$49,3, FALSE) -> La condition de service n'est pas exigée du militaire qui sollicite un congé pour donner des soins à un enfant à charge, au conjoint, au partenaire avec lequel il est lié par un PACS, ou à un ascendant. | AD21: CCP_I_013 | AE21: =VLOOKUP(AD21,'Axe 2 Règles de gestion'!$D$2:$F$49,3, FALSE) -> Les soins font suite à un accident ou une maladie grave ou à un handicap nécessitant la présence d'une tierce personne. | AF21: CCP_I_001 | AG21: =VLOOKUP(AF21,'Axe 2 Règles de gestion'!$D$2:$F$49,3, FALSE) -> Le militaire doit présenter une demande. | AH21: CCP_I_002 | AI21: =VLOOKUP(AH21,'Axe 2 Règles de gestion'!$D$2:$F$49,3, FALSE) -> Le militaire est placé en congé par décision du ministre compétent. | AJ21: CCP_I_004 | AK21: =VLOOKUP(AJ21,'Axe 2 Règles de gestion'!$D$2:$F$49,3, FALSE) -> Le militaire officier qui demande à être placé dans ce congé, est tenu d'informer sans délai par écrit le ministre compétent de la nature de l'activité privée lucrative qu'il se propose d'exercer. | AL21: CCP_I_014 | AM21: =VLOOKUP(AL21,'Axe 2 Règles de gestion'!$D$2:$F$49,3, FALSE) -> Le militaire officier est tenu d'informer sans délai par écrit le ministre compétent de tout changement d'activité privée lucrative. | AN21: CCP_D_004 | AO21: =VLOOKUP(AN21,'Axe 2 Règles de gestion'!$D$2:$F$49,3, FALSE) -> La durée prévisionnelle du congé ne peut pas excéder 2 ans pour chaque période. | AP21: CCP_D_001 | AQ21: =VLOOKUP(AP21,'Axe 2 Règles de gestion'!$D$2:$F$49,3, FALSE) -> La durée réelle du congé ne peut pas excéder 2 ans pour chaque période. | AR21: CCP_D_005 | AS21: =VLOOKUP(AR21,'Axe 2 Règles de gestion'!$D$2:$F$49,3, FALSE) -> La durée cumulée de l'ensemble des congés pour convenances personnelles ne doit pas excéder 10 ans. | BB21: POS_C_004 | BC21: =VLOOKUP(BB21,'Axe 2 Règles de gestion'!$D$2:$F$49,3, FALSE) -> La date de début de position doit être antérieure ou égale à la date de fin prévisionnelle de position. | BD21: POS_C_005 | BE21: =VLOOKUP(BD21,'Axe 2 Règles de gestion'!$D$2:$F$49,3, FALSE) -> La date de début de la position doit être postérieure ou égale à la date d'entrée dans la FPE ou dans la carrière militaire. | BF21: POS_C_007 | BG21: =VLOOKUP(BF21,'Axe 2 Règles de gestion'!$D$2:$F$49,3, FALSE) -> La date de fin réelle de la position doit être antérieure à la date limite de départ à la retraite. | BH21: POS_C_010 | BI21: =VLOOKUP(BH21,'Axe 2 Règles de gestion'!$D$2:$F$49,3, FALSE) -> La date de début de position doit être antérieure ou égale à la date de fin réelle de position. | BJ21: POS_C_012 | BK21: =VLOOKUP(BJ21,'Axe 2 Règles de gestion'!$D$2:$F$49,3, FALSE) -> La date de fin prévisionnelle de la position doit être antérieure à la date limite de départ à la retraite. | BL21: POS_C_022 | BM21: =VLOOKUP(BL21,'Axe 2 Règles de gestion'!$D$2:$F$49,3, FALSE) -> La date de début de position est à J+1 de la date de fin de position de l'occurrence précédente. | BN21: POS_C_055 | BO21: =VLOOKUP(BN21,'Axe 2 Règles de gestion'!$D$2:$F$49,3, FALSE) -> La date de fin réelle de la position doit être antérieure ou égale à la date de décès de l'enfant. | BP21: POS_C_056 | BQ21: =VLOOKUP(BP21,'Axe 2 Règles de gestion'!$D$2:$F$49,3, FALSE) -> La date de fin prévisionnelle de la position doit être antérieure ou égale à la date de décès de l'enfant. | BR21: POS_C_111 | BS21: =VLOOKUP(BR21,'Axe 2 Règles de gestion'!$D$2:$F$49,3, FALSE) -> La date de fin ou la date de fin prévisionnelle doit être saisie. | BT21: POS_C_120 | BU21: =VLOOKUP(BT21,'Axe 2 Règles de gestion'!$D$2:$F$49,3, FALSE) -> La saisie d'une occurrence de congés/absences est interdite (date de fin réelle) | BV21: POS_C_121 | BW21: =VLOOKUP(BV21,'Axe 2 Règles de gestion'!$D$2:$F$49,3, FALSE) -> La saisie d'une occurrence de congés/absences est interdite (date de fin prévisionnelle)
A22: 24.00.00 | B22: A | C22: 45428.473 | D22: D0004 | E22: Position | F22: S0166 | G22: Congé pour convenances personnelles (militaire) | H22: E0918 | I22: Congé pour convenances personnelles militaire | J22: La position saisie est 'Congé pour convenances personnelles militaire' | K22: A_POS_POSIAD [Saisi] = 'NAM25' | L22: T2240 | M22: Congé pour convenances personnelles (militaire) - Demande | N22: Création Modification | O22: Indicateur de renouvellement saisi = Non ET (Indicateur de renouvellement saisi différent d'Indicateur de renouvellement avant saisi) | P22: A_POS_INDREN [Saisi] = '0' ET (A_POS_INDREN [Saisi] <> A_POS_INDREN [Valeur avant saisie]) | Q22: Militaire de carrière | R22: P0189 | S22: Particulier | T22: Passant | U22: 45124 | W22: CCP_I_003 ET CCP_I_012 ET CCP_I_013 ET CCP_I_001 ET CCP_I_002 ET CCP_I_004 ET CCP_I_014 ET CCP_D_004 ET CCP_D_001 ET CCP_D_005 ET POS_C_004 ET POS_C_005 ET POS_C_007 ET POS_C_010 ET POS_C_012 ET POS_C_022 ET POS_C_055 ET POS_C_056 ET POS_C_111 ET POS_C_120 ET POS_C_121 | X22: CCP_I_003 | Y22: =VLOOKUP(X22,'Axe 2 Règles de gestion'!$D$2:$F$49,3, FALSE) -> Le militaire doit avoir accompli au moins 4 ans de services, dont 2 ans pour les officiers en cette qualité, sauf exceptions. | Z22: CCP_I_012 | AA22: =VLOOKUP(Z22,'Axe 2 Règles de gestion'!$D$2:$F$49,3, FALSE) -> La condition de service n'est pas exigée du militaire qui sollicite un congé pour donner des soins à un enfant à charge, au conjoint, au partenaire avec lequel il est lié par un PACS, ou à un ascendant. | AB22: CCP_I_013 | AC22: =VLOOKUP(AB22,'Axe 2 Règles de gestion'!$D$2:$F$49,3, FALSE) -> Les soins font suite à un accident ou une maladie grave ou à un handicap nécessitant la présence d'une tierce personne. | AD22: CCP_I_001 | AE22: =VLOOKUP(AD22,'Axe 2 Règles de gestion'!$D$2:$F$49,3, FALSE) -> Le militaire doit présenter une demande. | AF22: CCP_I_002 | AG22: =VLOOKUP(AF22,'Axe 2 Règles de gestion'!$D$2:$F$49,3, FALSE) -> Le militaire est placé en congé par décision du ministre compétent. | AH22: CCP_I_004 | AI22: =VLOOKUP(AH22,'Axe 2 Règles de gestion'!$D$2:$F$49,3, FALSE) -> Le militaire officier qui demande à être placé dans ce congé, est tenu d'informer sans délai par écrit le ministre compétent de la nature de l'activité privée lucrative qu'il se propose d'exercer. | AJ22: CCP_I_014 | AK22: =VLOOKUP(AJ22,'Axe 2 Règles de gestion'!$D$2:$F$49,3, FALSE) -> Le militaire officier est tenu d'informer sans délai par écrit le ministre compétent de tout changement d'activité privée lucrative. | AN22: CCP_D_004 | AO22: =VLOOKUP(AN22,'Axe 2 Règles de gestion'!$D$2:$F$49,3, FALSE) -> La durée prévisionnelle du congé ne peut pas excéder 2 ans pour chaque période. | AP22: CCP_D_001 | AQ22: =VLOOKUP(AP22,'Axe 2 Règles de gestion'!$D$2:$F$49,3, FALSE) -> La durée réelle du congé ne peut pas excéder 2 ans pour chaque période. | AR22: CCP_D_005 | AS22: =VLOOKUP(AR22,'Axe 2 Règles de gestion'!$D$2:$F$49,3, FALSE) -> La durée cumulée de l'ensemble des congés pour convenances personnelles ne doit pas excéder 10 ans. | BB22: POS_C_004 | BC22: =VLOOKUP(BB22,'Axe 2 Règles de gestion'!$D$2:$F$49,3, FALSE) -> La date de début de position doit être antérieure ou égale à la date de fin prévisionnelle de position. | BD22: POS_C_005 | BE22: =VLOOKUP(BD22,'Axe 2 Règles de gestion'!$D$2:$F$49,3, FALSE) -> La date de début de la position doit être postérieure ou égale à la date d'entrée dans la FPE ou dans la carrière militaire. | BF22: POS_C_007 | BG22: =VLOOKUP(BF22,'Axe 2 Règles de gestion'!$D$2:$F$49,3, FALSE) -> La date de fin réelle de la position doit être antérieure à la date limite de départ à la retraite. | BH22: POS_C_010 | BI22: =VLOOKUP(BH22,'Axe 2 Règles de gestion'!$D$2:$F$49,3, FALSE) -> La date de début de position doit être antérieure ou égale à la date de fin réelle de position. | BJ22: POS_C_012 | BK22: =VLOOKUP(BJ22,'Axe 2 Règles de gestion'!$D$2:$F$49,3, FALSE) -> La date de fin prévisionnelle de la position doit être antérieure à la date limite de départ à la retraite. | BL22: POS_C_022 | BM22: =VLOOKUP(BL22,'Axe 2 Règles de gestion'!$D$2:$F$49,3, FALSE) -> La date de début de position est à J+1 de la date de fin de position de l'occurrence précédente. | BN22: POS_C_055 | BO22: =VLOOKUP(BN22,'Axe 2 Règles de gestion'!$D$2:$F$49,3, FALSE) -> La date de fin réelle de la position doit être antérieure ou égale à la date de décès de l'enfant. | BP22: POS_C_056 | BQ22: =VLOOKUP(BP22,'Axe 2 Règles de gestion'!$D$2:$F$49,3, FALSE) -> La date de fin prévisionnelle de la position doit être antérieure ou égale à la date de décès de l'enfant. | BR22: POS_C_111 | BS22: =VLOOKUP(BR22,'Axe 2 Règles de gestion'!$D$2:$F$49,3, FALSE) -> La date de fin ou la date de fin prévisionnelle doit être saisie. | BT22: POS_C_120 | BU22: =VLOOKUP(BT22,'Axe 2 Règles de gestion'!$D$2:$F$49,3, FALSE) -> La saisie d'une occurrence de congés/absences est interdite (date de fin réelle) | BV22: POS_C_121 | BW22: =VLOOKUP(BV22,'Axe 2 Règles de gestion'!$D$2:$F$49,3, FALSE) -> La saisie d'une occurrence de congés/absences est interdite (date de fin prévisionnelle)
A23: 22.10.00 | B23: A | C23: 44970.67 | D23: D0004 | E23: Position | F23: S0166 | G23: Congé pour convenances personnelles (militaire) | H23: E0918 | I23: Congé pour convenances personnelles militaire | J23: La position saisie est 'Congé pour convenances personnelles militaire' | K23: A_POS_POSIAD [Saisi] = 'NAM25' | L23: T2241 | M23: Congé pour convenances personnelles (militaire) - Renouvellement | N23: Création Modification | O23: Indicateur de renouvellement saisi = Oui ET (Indicateur de renouvellement saisi différent d'Indicateur de renouvellement avant saisi) | P23: A_POS_INDREN [Saisi] = '1' ET (A_POS_INDREN [Saisi] <> A_POS_INDREN [Valeur avant saisie] | Q23: Militaire de carrière | R23: P0189 | S23: Particulier | T23: Passant | U23: 43831 | W23: CCP_I_005 ET CCP_I_001 ET CCP_I_002 ET CCP_I_004 ET CCP_I_014 ET CCP_D_004 ET CCP_D_001 ET CCP_D_005 ET POS_C_004 ET POS_C_005 ET POS_C_007 ET POS_C_010 ET POS_C_012 ET POS_C_022 ET POS_C_055 ET POS_C_056 ET POS_C_111 ET POS_C_120 ET POS_C_121 | X23: CCP_I_005 | Y23: =VLOOKUP(X23,'Axe 2 Règles de gestion'!$D$2:$F$49,3, FALSE) -> Le militaire peut demander le renouvellement du congé 3 mois avant l'expiration du congé. | Z23: CCP_I_001 | AA23: =VLOOKUP(Z23,'Axe 2 Règles de gestion'!$D$2:$F$49,3, FALSE) -> Le militaire doit présenter une demande. | AB23: CCP_I_002 | AC23: =VLOOKUP(AB23,'Axe 2 Règles de gestion'!$D$2:$F$49,3, FALSE) -> Le militaire est placé en congé par décision du ministre compétent. | AD23: CCP_I_004 | AE23: =VLOOKUP(AD23,'Axe 2 Règles de gestion'!$D$2:$F$49,3, FALSE) -> Le militaire officier qui demande à être placé dans ce congé, est tenu d'informer sans délai par écrit le ministre compétent de la nature de l'activité privée lucrative qu'il se propose d'exercer. | AF23: CCP_I_014 | AG23: =VLOOKUP(AF23,'Axe 2 Règles de gestion'!$D$2:$F$49,3, FALSE) -> Le militaire officier est tenu d'informer sans délai par écrit le ministre compétent de tout changement d'activité privée lucrative. | AN23: CCP_D_004 | AO23: =VLOOKUP(AN23,'Axe 2 Règles de gestion'!$D$2:$F$49,3, FALSE) -> La durée prévisionnelle du congé ne peut pas excéder 2 ans pour chaque période. | AP23: CCP_D_001 | AQ23: =VLOOKUP(AP23,'Axe 2 Règles de gestion'!$D$2:$F$49,3, FALSE) -> La durée réelle du congé ne peut pas excéder 2 ans pour chaque période. | AR23: CCP_D_005 | AS23: =VLOOKUP(AR23,'Axe 2 Règles de gestion'!$D$2:$F$49,3, FALSE) -> La durée cumulée de l'ensemble des congés pour convenances personnelles ne doit pas excéder 10 ans. | BB23: POS_C_004 | BC23: =VLOOKUP(BB23,'Axe 2 Règles de gestion'!$D$2:$F$49,3, FALSE) -> La date de début de position doit être antérieure ou égale à la date de fin prévisionnelle de position. | BD23: POS_C_005 | BE23: =VLOOKUP(BD23,'Axe 2 Règles de gestion'!$D$2:$F$49,3, FALSE) -> La date de début de la position doit être postérieure ou égale à la date d'entrée dans la FPE ou dans la carrière militaire. | BF23: POS_C_007 | BG23: =VLOOKUP(BF23,'Axe 2 Règles de gestion'!$D$2:$F$49,3, FALSE) -> La date de fin réelle de la position doit être antérieure à la date limite de départ à la retraite. | BH23: POS_C_010 | BI23: =VLOOKUP(BH23,'Axe 2 Règles de gestion'!$D$2:$F$49,3, FALSE) -> La date de début de position doit être antérieure ou égale à la date de fin réelle de position. | BJ23: POS_C_012 | BK23: =VLOOKUP(BJ23,'Axe 2 Règles de gestion'!$D$2:$F$49,3, FALSE) -> La date de fin prévisionnelle de la position doit être antérieure à la date limite de départ à la retraite. | BL23: POS_C_022 | BM23: =VLOOKUP(BL23,'Axe 2 Règles de gestion'!$D$2:$F$49,3, FALSE) -> La date de début de position est à J+1 de la date de fin de position de l'occurrence précédente. | BN23: POS_C_055 | BO23: =VLOOKUP(BN23,'Axe 2 Règles de gestion'!$D$2:$F$49,3, FALSE) -> La date de fin réelle de la position doit être antérieure ou égale à la date de décès de l'enfant. | BP23: POS_C_056 | BQ23: =VLOOKUP(BP23,'Axe 2 Règles de gestion'!$D$2:$F$49,3, FALSE) -> La date de fin prévisionnelle de la position doit être antérieure ou égale à la date de décès de l'enfant. | BR23: POS_C_111 | BS23: =VLOOKUP(BR23,'Axe 2 Règles de gestion'!$D$2:$F$49,3, FALSE) -> La date de fin ou la date de fin prévisionnelle doit être saisie. | BT23: POS_C_120 | BU23: =VLOOKUP(BT23,'Axe 2 Règles de gestion'!$D$2:$F$49,3, FALSE) -> La saisie d'une occurrence de congés/absences est interdite (date de fin réelle) | BV23: POS_C_121 | BW23: =VLOOKUP(BV23,'Axe 2 Règles de gestion'!$D$2:$F$49,3, FALSE) -> La saisie d'une occurrence de congés/absences est interdite (date de fin prévisionnelle)
A24: 22.10.00 | B24: A | C24: 44970.506 | D24: D0004 | E24: Position | F24: S0166 | G24: Congé pour convenances personnelles (militaire) | H24: E0918 | I24: Congé pour convenances personnelles militaire | J24: La position saisie est 'Congé pour convenances personnelles militaire' | K24: A_POS_POSIAD [Saisi] = 'NAM25' | L24: T2242 | M24: Congé pour convenances personnelles (militaire) - Fin | N24: Modification | O24: Indicateur de renouvellement saisi identique à Indicateur de renouvellement avant saisi | P24: A_POS_INDREN [Saisi] = A_POS_INDREN [Valeur avant saisie] | Q24: Militaire de carrière | R24: P0189 | S24: Particulier | T24: Passant | U24: 43831 | W24: CCP_I_006 ET CCP_I_007 ET CCP_D_004 ET CCP_D_001 ET CCP_D_005 ET POS_C_004 ET POS_C_007 ET POS_C_010 ET POS_C_012 ET POS_C_055 ET POS_C_056 ET POS_C_111 ET POS_C_120 ET POS_C_121 | X24: CCP_I_006 | Y24: =VLOOKUP(X24,'Axe 2 Règles de gestion'!$D$2:$F$49,3, FALSE) -> Le militaire peut demander la réintégration dans son corps d'origine, laquelle est de droit, 3 mois avant l'expiration du congé. | Z24: CCP_I_007 | AA24: =VLOOKUP(Z24,'Axe 2 Règles de gestion'!$D$2:$F$49,3, FALSE) -> Le militaire qui a formulé avant l'expiration du congé une demande de réintégration est maintenu dans cette situation jusqu'à ce qu'il puisse être affecté dans un emploi correspondant à son grade. | AN24: CCP_D_004 | AO24: =VLOOKUP(AN24,'Axe 2 Règles de gestion'!$D$2:$F$49,3, FALSE) -> La durée prévisionnelle du congé ne peut pas excéder 2 ans pour chaque période. | AP24: CCP_D_001 | AQ24: =VLOOKUP(AP24,'Axe 2 Règles de gestion'!$D$2:$F$49,3, FALSE) -> La durée réelle du congé ne peut pas excéder 2 ans pour chaque période. | AR24: CCP_D_005 | AS24: =VLOOKUP(AR24,'Axe 2 Règles de gestion'!$D$2:$F$49,3, FALSE) -> La durée cumulée de l'ensemble des congés pour convenances personnelles ne doit pas excéder 10 ans. | BB24: POS_C_004 | BC24: =VLOOKUP(BB24,'Axe 2 Règles de gestion'!$D$2:$F$49,3, FALSE) -> La date de début de position doit être antérieure ou égale à la date de fin prévisionnelle de position. | BD24: POS_C_007 | BE24: =VLOOKUP(BD24,'Axe 2 Règles de gestion'!$D$2:$F$49,3, FALSE) -> La date de fin réelle de la position doit être antérieure à la date limite de départ à la retraite. | BF24: POS_C_010 | BG24: =VLOOKUP(BF24,'Axe 2 Règles de gestion'!$D$2:$F$49,3, FALSE) -> La date de début de position doit être antérieure ou égale à la date de fin réelle de position. | BH24: POS_C_012 | BI24: =VLOOKUP(BH24,'Axe 2 Règles de gestion'!$D$2:$F$49,3, FALSE) -> La date de fin prévisionnelle de la position doit être antérieure à la date limite de départ à la retraite. | BJ24: POS_C_055 | BK24: =VLOOKUP(BJ24,'Axe 2 Règles de gestion'!$D$2:$F$49,3, FALSE) -> La date de fin réelle de la position doit être antérieure ou égale à la date de décès de l'enfant. | BL24: POS_C_056 | BM24: =VLOOKUP(BL24,'Axe 2 Règles de gestion'!$D$2:$F$49,3, FALSE) -> La date de fin prévisionnelle de la position doit être antérieure ou égale à la date de décès de l'enfant. | BN24: POS_C_111 | BO24: =VLOOKUP(BN24,'Axe 2 Règles de gestion'!$D$2:$F$49,3, FALSE) -> La date de fin ou la date de fin prévisionnelle doit être saisie. | BP24: POS_C_120 | BQ24: =VLOOKUP(BP24,'Axe 2 Règles de gestion'!$D$2:$F$49,3, FALSE) -> La saisie d'une occurrence de congés/absences est interdite (date de fin réelle) | BR24: POS_C_121 | BS24: =VLOOKUP(BR24,'Axe 2 Règles de gestion'!$D$2:$F$49,3, FALSE) -> La saisie d'une occurrence de congés/absences est interdite (date de fin prévisionnelle)
A25: 22.10.00 | B25: A | C25: 44970.494 | D25: D0004 | E25: Position | F25: S0166 | G25: Congé pour convenances personnelles (militaire) | H25: E0919 | I25: Congé pour convenances personnelles pour élever un enfant militaire | J25: La position saisie est 'Congé pour convenances personnelles pour élever un enfant' | K25: A_POS_POSIAD [Saisi] = 'NAM30' | L25: T2243 | M25: Congé pour convenances personnelles pour élever un enfant (militaire) - Demande | N25: Création Modification | O25: Indicateur de renouvellement saisi = Non ET (Indicateur de renouvellement saisi différent d'Indicateur de renouvellement avant saisi) | P25: A_POS_INDREN [Saisi] = '0' ET (A_POS_INDREN [Saisi] <> A_POS_INDREN [Valeur avant saisie]) | Q25: Titulaire ou magistrat | R25: P0001 | S25: Général | T25: Exclu | U25: 43831
A26: 22.10.00 | B26: A | C26: 44970.5 | D26: D0004 | E26: Position | F26: S0166 | G26: Congé pour convenances personnelles (militaire) | H26: E0919 | I26: Congé pour convenances personnelles pour élever un enfant militaire | J26: La position saisie est 'Congé pour convenances personnelles pour élever un enfant' | K26: A_POS_POSIAD [Saisi] = 'NAM30' | L26: T2244 | M26: Congé pour convenances personnelles pour élever un enfant (militaire) - Renouvellement | N26: Création Modification | O26: Indicateur de renouvellement saisi = Oui ET (Indicateur de renouvellement saisi différent d'Indicateur de renouvellement avant saisi) | P26: A_POS_INDREN [Saisi] = '1' ET (A_POS_INDREN [Saisi] <> A_POS_INDREN [Valeur avant saisie] | Q26: Titulaire ou magistrat | R26: P0001 | S26: Général | T26: Exclu | U26: 43831
A27: 22.10.00 | B27: A | C27: 44970.496 | D27: D0004 | E27: Position | F27: S0166 | G27: Congé pour convenances personnelles (militaire) | H27: E0919 | I27: Congé pour convenances personnelles pour élever un enfant militaire | J27: La position saisie est 'Congé pour convenances personnelles pour élever un enfant' | K27: A_POS_POSIAD [Saisi] = 'NAM30' | L27: T2245 | M27: Congé pour convenances personnelles pour élever un enfant (militaire) - Fin | N27: Modification | O27: Indicateur de renouvellement saisi identique à Indicateur de renouvellement avant saisi | P27: A_POS_INDREN [Saisi] = A_POS_INDREN [Valeur avant saisie] | Q27: Titulaire ou magistrat | R27: P0001 | S27: Général | T27: Exclu | U27: 43831
A28: 22.10.00 | B28: A | C28: 44970.495 | D28: D0004 | E28: Position | F28: S0166 | G28: Congé pour convenances personnelles (militaire) | H28: E0919 | I28: Congé pour convenances personnelles pour élever un enfant militaire | J28: La position saisie est 'Congé pour convenances personnelles pour élever un enfant' | K28: A_POS_POSIAD [Saisi] = 'NAM30' | L28: T2243 | M28: Congé pour convenances personnelles pour élever un enfant (militaire) - Demande | N28: Création Modification | O28: Indicateur de renouvellement saisi = Non ET (Indicateur de renouvellement saisi différent d'Indicateur de renouvellement avant saisi) | P28: A_POS_INDREN [Saisi] = '0' ET (A_POS_INDREN [Saisi] <> A_POS_INDREN [Valeur avant saisie]) | Q28: Militaire | R28: P0002 | S28: Général | T28: Exclu | U28: 43831
A29: 22.10.00 | B29: A | C29: 44970.499 | D29: D0004 | E29: Position | F29: S0166 | G29: Congé pour convenances personnelles (militaire) | H29: E0919 | I29: Congé pour convenances personnelles pour élever un enfant militaire | J29: La position saisie est 'Congé pour convenances personnelles pour élever un enfant' | K29: A_POS_POSIAD [Saisi] = 'NAM30' | L29: T2244 | M29: Congé pour convenances personnelles pour élever un enfant (militaire) - Renouvellement | N29: Création Modification | O29: Indicateur de renouvellement saisi = Oui ET (Indicateur de renouvellement saisi différent d'Indicateur de renouvellement avant saisi) | P29: A_POS_INDREN [Saisi] = '1' ET (A_POS_INDREN [Saisi] <> A_POS_INDREN [Valeur avant saisie] | Q29: Militaire | R29: P0002 | S29: Général | T29: Exclu | U29: 43831
A30: 22.10.00 | B30: A | C30: 44970.496 | D30: D0004 | E30: Position | F30: S0166 | G30: Congé pour convenances personnelles (militaire) | H30: E0919 | I30: Congé pour convenances personnelles pour élever un enfant militaire | J30: La position saisie est 'Congé pour convenances personnelles pour élever un enfant' | K30: A_POS_POSIAD [Saisi] = 'NAM30' | L30: T2245 | M30: Congé pour convenances personnelles pour élever un enfant (militaire) - Fin | N30: Modification | O30: Indicateur de renouvellement saisi identique à Indicateur de renouvellement avant saisi | P30: A_POS_INDREN [Saisi] = A_POS_INDREN [Valeur avant saisie] | Q30: Militaire | R30: P0002 | S30: Général | T30: Exclu | U30: 43831
A31: 22.10.00 | B31: A | C31: 44970.495 | D31: D0004 | E31: Position | F31: S0166 | G31: Congé pour convenances personnelles (militaire) | H31: E0919 | I31: Congé pour convenances personnelles pour élever un enfant militaire | J31: La position saisie est 'Congé pour convenances personnelles pour élever un enfant' | K31: A_POS_POSIAD [Saisi] = 'NAM30' | L31: T2243 | M31: Congé pour convenances personnelles pour élever un enfant (militaire) - Demande | N31: Création Modification | O31: Indicateur de renouvellement saisi = Non ET (Indicateur de renouvellement saisi différent d'Indicateur de renouvellement avant saisi) | P31: A_POS_INDREN [Saisi] = '0' ET (A_POS_INDREN [Saisi] <> A_POS_INDREN [Valeur avant saisie]) | Q31: Contractuel | R31: P0003 | S31: Général | T31: Exclu | U31: 43831
A32: 22.10.00 | B32: A | C32: 44970.499 | D32: D0004 | E32: Position | F32: S0166 | G32: Congé pour convenances personnelles (militaire) | H32: E0919 | I32: Congé pour convenances personnelles pour élever un enfant militaire | J32: La position saisie est 'Congé pour convenances personnelles pour élever un enfant' | K32: A_POS_POSIAD [Saisi] = 'NAM30' | L32: T2244 | M32: Congé pour convenances personnelles pour élever un enfant (militaire) - Renouvellement | N32: Création Modification | O32: Indicateur de renouvellement saisi = Oui ET (Indicateur de renouvellement saisi différent d'Indicateur de renouvellement avant saisi) | P32: A_POS_INDREN [Saisi] = '1' ET (A_POS_INDREN [Saisi] <> A_POS_INDREN [Valeur avant saisie] | Q32: Contractuel | R32: P0003 | S32: Général | T32: Exclu | U32: 43831
A33: 22.10.00 | B33: A | C33: 44970.496 | D33: D0004 | E33: Position | F33: S0166 | G33: Congé pour convenances personnelles (militaire) | H33: E0919 | I33: Congé pour convenances personnelles pour élever un enfant militaire | J33: La position saisie est 'Congé pour convenances personnelles pour élever un enfant' | K33: A_POS_POSIAD [Saisi] = 'NAM30' | L33: T2245 | M33: Congé pour convenances personnelles pour élever un enfant (militaire) - Fin | N33: Modification | O33: Indicateur de renouvellement saisi identique à Indicateur de renouvellement avant saisi | P33: A_POS_INDREN [Saisi] = A_POS_INDREN [Valeur avant saisie] | Q33: Contractuel | R33: P0003 | S33: Général | T33: Exclu | U33: 43831
A34: 22.10.00 | B34: A | C34: 44970.495 | D34: D0004 | E34: Position | F34: S0166 | G34: Congé pour convenances personnelles (militaire) | H34: E0919 | I34: Congé pour convenances personnelles pour élever un enfant militaire | J34: La position saisie est 'Congé pour convenances personnelles pour élever un enfant' | K34: A_POS_POSIAD [Saisi] = 'NAM30' | L34: T2243 | M34: Congé pour convenances personnelles pour élever un enfant (militaire) - Demande | N34: Création Modification | O34: Indicateur de renouvellement saisi = Non ET (Indicateur de renouvellement saisi différent d'Indicateur de renouvellement avant saisi) | P34: A_POS_INDREN [Saisi] = '0' ET (A_POS_INDREN [Saisi] <> A_POS_INDREN [Valeur avant saisie]) | Q34: Stagiaire ou auditeur ou élève | R34: P0004 | S34: Général | T34: Exclu | U34: 43831
A35: 22.10.00 | B35: A | C35: 44974.558 | D35: D0004 | E35: Position | F35: S0166 | G35: Congé pour convenances personnelles (militaire) | H35: E0919 | I35: Congé pour convenances personnelles pour élever un enfant militaire | J35: La position saisie est 'Congé pour convenances personnelles pour élever un enfant' | K35: A_POS_POSIAD [Saisi] = 'NAM30' | L35: T2244 | M35: Congé pour convenances personnelles pour élever un enfant (militaire) - Renouvellement | N35: Création Modification | O35: Indicateur de renouvellement saisi = Oui ET (Indicateur de renouvellement saisi différent d'Indicateur de renouvellement avant saisi) | P35: A_POS_INDREN [Saisi] = '1' ET (A_POS_INDREN [Saisi] <> A_POS_INDREN [Valeur avant saisie] | Q35: Stagiaire ou auditeur ou élève | R35: P0004 | S35: Général | T35: Exclu | U35: 43832
A36: 22.10.00 | B36: A | C36: 44974.558 | D36: D0004 | E36: Position | F36: S0166 | G36: Congé pour convenances personnelles (militaire) | H36: E0919 | I36: Congé pour convenances personnelles pour élever un enfant militaire | J36: La position saisie est 'Congé pour convenances personnelles pour élever un enfant' | K36: A_POS_POSIAD [Saisi] = 'NAM30' | L36: T2245 | M36: Congé pour convenances personnelles pour élever un enfant (militaire) - Fin | N36: Modification | O36: Indicateur de renouvellement saisi identique à Indicateur de renouvellement avant saisi | P36: A_POS_INDREN [Saisi] = A_POS_INDREN [Valeur avant saisie] | Q36: Stagiaire ou auditeur ou élève | R36: P0004 | S36: Général | T36: Exclu | U36: 43833
