Workbook
Name date_DIADC: 'Mode opératoire'!#REF!
Name notice_DIADC: 'Mode opératoire'!#REF!
Name notice_ENCHN: 'Mode opératoire'!$B$1:$B$4
Name notice_ICA: 'Mode opératoire'!#REF!

Sheet Mode opératoire
B1: MODE OPERATOIRE
B2: La transaction s'effectue au niveau de la sous rubrique "Position statutaire/situation administrative".

Sheet Axe 1 Enchainement des RG
A1: Version | B1: Type de mise à jour | C1: Date de mise à jour | D1: Identifiant Domaine | E1: Libellé du Domaine | F1: Identifiant Sous-domaine | G1: Libellé du Sous-domaine | H1: Identifiant Evénement | I1: Libellé de l'évènement | J1: Libellé condition déclenchement Evènement | K1: Condition déclenchement Evènement | L1: Identifiant type d'évènement | M1: Libellé type d'évènement | N1: Type de mise à jour | O1: Libellé condition déclenchement Type Evènement | P1: Condition déclenchement Type Evènement | Q1: Libellé Population | R1: Codification Population | S1: Typologie de population | T1: Général / Particulier | U1: Passant / Exclu | V1: Date de début | W1: Date de fin | X1: Règles mobilisées | Y1: Identifiant Règle de contrôle intellectuel 1 | Z1: Libellé Règle de contrôle intellectuel 1 | AA1: Identifiant Règle de contrôle intellectuel 2 | AB1: Libellé Règle de contrôle intellectuel 2 | AC1: Identifiant Règle de contrôle intellectuel 3 | AD1: Libellé Règle de contrôle intellectuel 3 | AE1: Identifiant Règle de contrôle intellectuel 4 | AF1: Libellé Règle de contrôle intellectuel 4 | AG1: Identifiant Règle de condition 1 | AH1: Libellé Règle de condition 1 | AI1: Identifiant Règle de condition 2 | AJ1: Libellé Règle de condition 2 | AK1: Identifiant Règle de condition 3 | AL1: Libellé Règle de condition 3 | AM1: Identifiant Règle de condition 4 | AN1: Libellé Règle de condition 4 | AO1: Identifiant Règle de condition 5 | AP1: Libellé Règle de condition 5 | AQ1: Identifiant Règle de contrôle 1 | AR1: Libellé Règle de contrôle 1 | AS1: Identifiant Règle de contrôle 2 | AT1: Libellé Règle de contrôle 2 | AU1: Identifiant Règle de contrôle 3 | AV1: Libellé Règle de contrôle 3 | AW1: Identifiant Règle de contrôle 4 | AX1: Libellé Règle de contrôle 4 | AY1: Identifiant Règle de contrôle 5 | AZ1: Libellé Règle de contrôle 5 | BA1: Identifiant Règle de contrôle 6 | BB1: Libellé Règle de contrôle 6 | BC1: Identifiant Règle de contrôle 7 | BD1: Libellé Règle de contrôle 7 | BE1: Identifiant Règle de contrôle 8 | BF1: Libellé Règle de contrôle 8 | BG1: Identifiant Règle de contrôle 9 | BH1: Libellé Règle de contrôle 9 | BI1: Identifiant Règle de contrôle 10 | BJ1: Libellé Règle de contrôle 10 | BK1: Identifiant Règle de contrôle 11 | BL1: Libellé Règle de contrôle 11 | BM1: Identifiant Règle de contrôle 12 | BN1: Libellé Règle de contrôle 12 | BO1: Identifiant Règle de contrôle 13 | BP1: Libellé Règle de contrôle 13 | BQ1: Identifiant Règle de contrôle 14 | BR1: Libellé Règle de contrôle 14 | BS1: Identifiant Règle de contrôle 15 | BT1: Libellé Règle de contrôle 15 | BU1: Identifiant Règle de contrôle 16 | BV1: Libellé Règle de contrôle 16 | BW1: FIME | BX1: Statut de travail
A2: 17.10.00 | B2: A | C2: 43152.5 | D2: D0004 | E2: Position | F2: S0028 | G2: Congé sans traitement | H2: E0312 | I2: Congé sans traitement pour élever enfant | J2: Position saisie égale à 'Congé sans traitement pour élever enfant' | K2: A_POS_POSIAD [Saisi] = 'NAC43' | L2: T0907 | M2: Congé sans traitement pour élever un enfant - Demande | N2: Création Modification | O2: Indicateur de renouvellement saisi = Non ET l'indicateur de renouvellement saisi est différent de l'indicateur de renouvellement avant saisie | P2: A_POS_INDREN [Saisi] = '0' ET A_POS_INDREN [Saisi] <> A_POS_INDREN [Valeur avant saisie] | Q2: Titulaire ou magistrat | R2: P0001 | S2: T | T2: Général | U2: Exclu | V2: 40725
A3: 17.10.00 | B3: A | C3: 43152.5 | D3: D0004 | E3: Position | F3: S0028 | G3: Congé sans traitement | H3: E0312 | I3: Congé sans traitement pour élever enfant | J3: Position saisie égale à 'Congé sans traitement pour élever enfant' | K3: A_POS_POSIAD [Saisi] = 'NAC43' | L3: T0908 | M3: Congé sans traitement pour élever un enfant - Renouvellement | N3: Création Modification | O3: Indicateur de renouvellement saisi = Oui ET l'indicateur de renouvellement saisi est différent de l'indicateur de renouvellement avant saisie | P3: A_POS_INDREN [Saisi] = '1' ET A_POS_INDREN [Saisi] <> A_POS_INDREN [Valeur avant saisie] | Q3: Titulaire ou magistrat | R3: P0001 | S3: T | T3: Général | U3: Exclu | V3: 40725
A4: 17.10.00 | B4: A | C4: 43152.5 | D4: D0004 | E4: Position | F4: S0028 | G4: Congé sans traitement | H4: E0312 | I4: Congé sans traitement pour élever enfant | J4: Position saisie égale à 'Congé sans traitement pour élever enfant' | K4: A_POS_POSIAD [Saisi] = 'NAC43' | L4: T0909 | M4: Congé sans traitement pour élever un enfant - Modification/Fin | N4: Modification | O4: L'indicateur de renouvellement saisi est égal à l'indicateur de renouvellement avant saisie | P4: A_POS_INDREN [Saisi] = A_POS_INDREN [Valeur avant saisie] | Q4: Titulaire ou magistrat | R4: P0001 | S4: T | T4: Général | U4: Exclu | V4: 40725
A5: 17.10.00 | B5: A | C5: 43152.5 | D5: D0004 | E5: Position | F5: S0028 | G5: Congé sans traitement | H5: E0312 | I5: Congé sans traitement pour élever enfant | J5: Position saisie égale à 'Congé sans traitement pour élever enfant' | K5: A_POS_POSIAD [Saisi] = 'NAC43' | L5: T0907 | M5: Congé sans traitement pour élever un enfant - Demande | N5: Création Modification | O5: Indicateur de renouvellement saisi = Non ET l'indicateur de renouvellement saisi est différent de l'indicateur de renouvellement avant saisie | P5: A_POS_INDREN [Saisi] = '0' ET A_POS_INDREN [Saisi] <> A_POS_INDREN [Valeur avant saisie] | Q5: Militaire | R5: P0002 | S5: M | T5: Général | U5: Exclu | V5: 40725
A6: 17.10.00 | B6: A | C6: 43152.5 | D6: D0004 | E6: Position | F6: S0028 | G6: Congé sans traitement | H6: E0312 | I6: Congé sans traitement pour élever enfant | J6: Position saisie égale à 'Congé sans traitement pour élever enfant' | K6: A_POS_POSIAD [Saisi] = 'NAC43' | L6: T0908 | M6: Congé sans traitement pour élever un enfant - Renouvellement | N6: Création Modification | O6: Indicateur de renouvellement saisi = Oui ET l'indicateur de renouvellement saisi est différent de l'indicateur de renouvellement avant saisie | P6: A_POS_INDREN [Saisi] = '1' ET A_POS_INDREN [Saisi] <> A_POS_INDREN [Valeur avant saisie] | Q6: Militaire | R6: P0002 | S6: M | T6: Général | U6: Exclu | V6: 40725
A7: 17.10.00 | B7: A | C7: 43152.5 | D7: D0004 | E7: Position | F7: S0028 | G7: Congé sans traitement | H7: E0312 | I7: Congé sans traitement pour élever enfant | J7: Position saisie égale à 'Congé sans traitement pour élever enfant' | K7: A_POS_POSIAD [Saisi] = 'NAC43' | L7: T0909 | M7: Congé sans traitement pour élever un enfant - Modification/Fin | N7: Modification | O7: L'indicateur de renouvellement saisi est égal à l'indicateur de renouvellement avant saisie | P7: A_POS_INDREN [Saisi] = A_POS_INDREN [Valeur avant saisie] | Q7: Militaire | R7: P0002 | S7: M | T7: Général | U7: Exclu | V7: 40725
A8: 17.10.00 | B8: A | C8: 43152.5 | D8: D0004 | E8: Position | F8: S0028 | G8: Congé sans traitement | H8: E0312 | I8: Congé sans traitement pour élever enfant | J8: Position saisie égale à 'Congé sans traitement pour élever enfant' | K8: A_POS_POSIAD [Saisi] = 'NAC43' | L8: T0907 | M8: Congé sans traitement pour élever un enfant - Demande | N8: Création Modification | O8: Indicateur de renouvellement saisi = Non ET l'indicateur de renouvellement saisi est différent de l'indicateur de renouvellement avant saisie | P8: A_POS_INDREN [Saisi] = '0' ET A_POS_INDREN [Saisi] <> A_POS_INDREN [Valeur avant saisie] | Q8: Contractuel | R8: P0003 | S8: N | T8: Général | U8: Exclu | V8: 40725
A9: 17.10.00 | B9: A | C9: 43152.5 | D9: D0004 | E9: Position | F9: S0028 | G9: Congé sans traitement | H9: E0312 | I9: Congé sans traitement pour élever enfant | J9: Position saisie égale à 'Congé sans traitement pour élever enfant' | K9: A_POS_POSIAD [Saisi] = 'NAC43' | L9: T0908 | M9: Congé sans traitement pour élever un enfant - Renouvellement | N9: Création Modification | O9: Indicateur de renouvellement saisi = Oui ET l'indicateur de renouvellement saisi est différent de l'indicateur de renouvellement avant saisie | P9: A_POS_INDREN [Saisi] = '1' ET A_POS_INDREN [Saisi] <> A_POS_INDREN [Valeur avant saisie] | Q9: Contractuel | R9: P0003 | S9: N | T9: Général | U9: Exclu | V9: 40725
A10: 17.10.00 | B10: A | C10: 43152.5 | D10: D0004 | E10: Position | F10: S0028 | G10: Congé sans traitement | H10: E0312 | I10: Congé sans traitement pour élever enfant | J10: Position saisie égale à 'Congé sans traitement pour élever enfant' | K10: A_POS_POSIAD [Saisi] = 'NAC43' | L10: T0909 | M10: Congé sans traitement pour élever un enfant - Modification/Fin | N10: Modification | O10: L'indicateur de renouvellement saisi est égal à l'indicateur de renouvellement avant saisie | P10: A_POS_INDREN [Saisi] = A_POS_INDREN [Valeur avant saisie] | Q10: Contractuel | R10: P0003 | S10: N | T10: Général | U10: Exclu | V10: 40725
A11: 25.00.00 | B11: M | C11: 45805.657 | D11: D0004 | E11: Position | F11: S0028 | G11: Congé sans traitement | H11: E0312 | I11: Congé sans traitement pour élever enfant | J11: Position saisie égale à 'Congé sans traitement pour élever enfant' | K11: A_POS_POSIAD [Saisi] = 'NAC43' | L11: T0907 | M11: Congé sans traitement pour élever un enfant - Demande | N11: Création Modification | O11: Indicateur de renouvellement saisi = Non ET l'indicateur de renouvellement saisi est différent de l'indicateur de renouvellement avant saisie | P11: A_POS_INDREN [Saisi] = '0' ET A_POS_INDREN [Saisi] <> A_POS_INDREN [Valeur avant saisie] | Q11: Stagiaire ou auditeur ou élève | R11: P0004 | S11: S | T11: Général | U11: Passant | V11: 40725 | W11: 45781 | X11: CST_I_001 ET CST_I_002 ET CST_D_003 ET CST_D_200 ET CST_D_004 ET CST_D_005 ET CST_D_202 ET POS_C_100 ET POS_C_005 ET POS_C_022 ET POS_C_004 ET POS_C_010 ET POS_C_012 ET POS_C_007 ET POS_C_111 ET POS_C_050 ET POS_C_051 ET POS_C_055 ET POS_C_056 ET POS_C_120 ET POS_C_121 | Y11: CST_I_001 | Z11: =VLOOKUP(Y11,'Axe 2 Règles de gestion'!$D$2:$F$146,3, FALSE) -> L'agent doit présenter une demande de congé sans traitement. | AA11: CST_I_002 | AB11: =VLOOKUP(AA11,'Axe 2 Règles de gestion'!$D$2:$F$146,3, FALSE) -> La demande est accordée de droit par le supérieur hiérarchique. | AG11: CST_D_003 | AH11: =VLOOKUP(AG11,'Axe 2 Règles de gestion'!$D$2:$F$146,3, FALSE) -> La durée prévisionnelle maximale de chaque période est de un an. | AI11: CST_D_200 | AJ11: =VLOOKUP(AI11,'Axe 2 Règles de gestion'!$D$2:$F$146,3, FALSE) -> La durée réelle maximale de chaque période est de un an. | AK11: CST_D_004 | AL11: =VLOOKUP(AK11,'Axe 2 Règles de gestion'!$D$2:$F$146,3, FALSE) -> L'agent ne peut pas bénéficier de plus de 3 ans cumulés de congé sans traitement quels que soient les motifs de congés sans traitement : pour raisons personnelles ou familiales. | AM11: CST_D_005 | AN11: =VLOOKUP(AM11,'Axe 2 Règles de gestion'!$D$2:$F$146,3, FALSE) -> L'agent doit avoir un enfant lié à cette position et l'enfant doit être âgé de moins de huit ans (date de fin prévisionnelle du congé sans traitement). | AO11: CST_D_202 | AP11: =VLOOKUP(AO11,'Axe 2 Règles de gestion'!$D$2:$F$146,3, FALSE) -> L'agent doit avoir un enfant lié à cette position et l'enfant doit être âgé de moins de huit ans (date de fin réelle du congé sans traitement). | AQ11: POS_C_100 | AR11: =VLOOKUP(AQ11,'Axe 2 Règles de gestion'!$D$2:$F$146,3, FALSE) -> Lors de la demande initiale, l'agent doit être en activité. | AS11: POS_C_005 | AT11: =VLOOKUP(AS11,'Axe 2 Règles de gestion'!$D$2:$F$146,3, FALSE) -> La date de début de la position doit être postérieure ou égale à la date d'entrée dans la FPE ou dans la carrière militaire. | AU11: POS_C_022 | AV11: =VLOOKUP(AU11,'Axe 2 Règles de gestion'!$D$2:$F$146,3, FALSE) -> La date de début de position est à J+1 de la date de fin de position de l'occurrence précédente. | AW11: POS_C_004 | AX11: =VLOOKUP(AW11,'Axe 2 Règles de gestion'!$D$2:$F$146,3, FALSE) -> La date de début de position doit être antérieure ou égale à la date de fin prévisionnelle de position. | AY11: POS_C_010 | AZ11: =VLOOKUP(AY11,'Axe 2 Règles de gestion'!$D$2:$F$146,3, FALSE) -> La date de début de position doit être antérieure ou égale à la date de fin réelle de position. | BA11: POS_C_012 | BB11: =VLOOKUP(BA11,'Axe 2 Règles de gestion'!$D$2:$F$146,3, FALSE) -> La date de fin prévisionnelle de la position doit être antérieure à la date limite de départ à la retraite. | BC11: POS_C_007 | BD11: =VLOOKUP(BC11,'Axe 2 Règles de gestion'!$D$2:$F$146,3, FALSE) -> La date de fin réelle de la position doit être antérieure à la date limite de départ à la retraite. | BE11: POS_C_111 | BF11: =VLOOKUP(BE11,'Axe 2 Règles de gestion'!$D$2:$F$146,3, FALSE) -> La date de fin ou la date de fin prévisionnelle doit être saisie. | BG11: POS_C_050 | BH11: =VLOOKUP(BG11,'Axe 2 Règles de gestion'!$D$2:$F$146,3, FALSE) -> Le lien vers l'enfant doit être renseigné. | BI11: POS_C_051 | BJ11: =VLOOKUP(BI11,'Axe 2 Règles de gestion'!$D$2:$F$146,3, FALSE) -> La date de naissance de l'enfant doit être renseignée. | BK11: POS_C_055 | BL11: =VLOOKUP(BK11,'Axe 2 Règles de gestion'!$D$2:$F$146,3, FALSE) -> La date de fin réelle de la position doit être antérieure ou égale à la date de décès de l'enfant. | BM11: POS_C_056 | BN11: =VLOOKUP(BM11,'Axe 2 Règles de gestion'!$D$2:$F$146,3, FALSE) -> La date de fin prévisionnelle de la position doit être antérieure ou égale à la date de décès de l'enfant. | BO11: POS_C_120 | BP11: =VLOOKUP(BO11,'Axe 2 Règles de gestion'!$D$2:$F$146,3, FALSE) -> La saisie d'une occurrence de congés/absences est interdite (date de fin réelle) | BQ11: POS_C_121 | BR11: =VLOOKUP(BQ11,'Axe 2 Règles de gestion'!$D$2:$F$146,3, FALSE) -> La saisie d'une occurrence de congés/absences est interdite (date de fin prévisionnelle)
A12: 25.00.00 | B12: A | C12: 45805.658 | D12: D0004 | E12: Position | F12: S0028 | G12: Congé sans traitement | H12: E0312 | I12: Congé sans traitement pour élever enfant | J12: Position saisie égale à 'Congé sans traitement pour élever enfant' | K12: A_POS_POSIAD [Saisi] = 'NAC43' | L12: T0907 | M12: Congé sans traitement pour élever un enfant - Demande | N12: Création Modification | O12: Indicateur de renouvellement saisi = Non ET l'indicateur de renouvellement saisi est différent de l'indicateur de renouvellement avant saisie | P12: A_POS_INDREN [Saisi] = '0' ET A_POS_INDREN [Saisi] <> A_POS_INDREN [Valeur avant saisie] | Q12: Stagiaire ou auditeur ou élève | R12: P0004 | S12: S | T12: Général | U12: Passant | V12: 45782 | X12: CST_I_001 ET CST_I_002 ET CST_D_003 ET CST_D_200 ET CST_D_004 ET CST_D_250 ET CST_D_253 ET POS_C_100 ET POS_C_005 ET POS_C_022 ET POS_C_004 ET POS_C_010 ET POS_C_012 ET POS_C_007 ET POS_C_111 ET POS_C_050 ET POS_C_051 ET POS_C_055 ET POS_C_056 ET POS_C_120 ET POS_C_121 | Y12: CST_I_001 | Z12: =VLOOKUP(Y12,'Axe 2 Règles de gestion'!$D$2:$F$146,3, FALSE) -> L'agent doit présenter une demande de congé sans traitement. | AA12: CST_I_002 | AB12: =VLOOKUP(AA12,'Axe 2 Règles de gestion'!$D$2:$F$146,3, FALSE) -> La demande est accordée de droit par le supérieur hiérarchique. | AG12: CST_D_003 | AH12: =VLOOKUP(AG12,'Axe 2 Règles de gestion'!$D$2:$F$146,3, FALSE) -> La durée prévisionnelle maximale de chaque période est de un an. | AI12: CST_D_200 | AJ12: =VLOOKUP(AI12,'Axe 2 Règles de gestion'!$D$2:$F$146,3, FALSE) -> La durée réelle maximale de chaque période est de un an. | AK12: CST_D_004 | AL12: =VLOOKUP(AK12,'Axe 2 Règles de gestion'!$D$2:$F$146,3, FALSE) -> L'agent ne peut pas bénéficier de plus de 3 ans cumulés de congé sans traitement quels que soient les motifs de congés sans traitement : pour raisons personnelles ou familiales. | AM12: CST_D_250 | AN12: =VLOOKUP(AM12,'Axe 2 Règles de gestion'!$D$2:$F$146,3, FALSE) -> L'agent doit avoir un enfant lié à cette position et l'enfant doit être âgé de moins de 12 ans (date de fin prévisionnelle du congé sans traitement). | AO12: CST_D_253 | AP12: =VLOOKUP(AO12,'Axe 2 Règles de gestion'!$D$2:$F$146,3, FALSE) -> L'agent doit avoir un enfant lié à cette position et l'enfant doit être âgé de moins de 12 ans (date de fin réelle du congé sans traitement). | AQ12: POS_C_100 | AR12: =VLOOKUP(AQ12,'Axe 2 Règles de gestion'!$D$2:$F$146,3, FALSE) -> Lors de la demande initiale, l'agent doit être en activité. | AS12: POS_C_005 | AT12: =VLOOKUP(AS12,'Axe 2 Règles de gestion'!$D$2:$F$146,3, FALSE) -> La date de début de la position doit être postérieure ou égale à la date d'entrée dans la FPE ou dans la carrière militaire. | AU12: POS_C_022 | AV12: =VLOOKUP(AU12,'Axe 2 Règles de gestion'!$D$2:$F$146,3, FALSE) -> La date de début de position est à J+1 de la date de fin de position de l'occurrence précédente. | AW12: POS_C_004 | AX12: =VLOOKUP(AW12,'Axe 2 Règles de gestion'!$D$2:$F$146,3, FALSE) -> La date de début de position doit être antérieure ou égale à la date de fin prévisionnelle de position. | AY12: POS_C_010 | AZ12: =VLOOKUP(AY12,'Axe 2 Règles de gestion'!$D$2:$F$146,3, FALSE) -> La date de début de position doit être antérieure ou égale à la date de fin réelle de position. | BA12: POS_C_012 | BB12: =VLOOKUP(BA12,'Axe 2 Règles de gestion'!$D$2:$F$146,3, FALSE) -> La date de fin prévisionnelle de la position doit être antérieure à la date limite de départ à la retraite. | BC12: POS_C_007 | BD12: =VLOOKUP(BC12,'Axe 2 Règles de gestion'!$D$2:$F$146,3, FALSE) -> La date de fin réelle de la position doit être antérieure à la date limite de départ à la retraite. | BE12: POS_C_111 | BF12: =VLOOKUP(BE12,'Axe 2 Règles de gestion'!$D$2:$F$146,3, FALSE) -> La date de fin ou la date de fin prévisionnelle doit être saisie. | BG12: POS_C_050 | BH12: =VLOOKUP(BG12,'Axe 2 Règles de gestion'!$D$2:$F$146,3, FALSE) -> Le lien vers l'enfant doit être renseigné. | BI12: POS_C_051 | BJ12: =VLOOKUP(BI12,'Axe 2 Règles de gestion'!$D$2:$F$146,3, FALSE) -> La date de naissance de l'enfant doit être renseignée. | BK12: POS_C_055 | BL12: =VLOOKUP(BK12,'Axe 2 Règles de gestion'!$D$2:$F$146,3, FALSE) -> La date de fin réelle de la position doit être antérieure ou égale à la date de décès de l'enfant. | BM12: POS_C_056 | BN12: =VLOOKUP(BM12,'Axe 2 Règles de gestion'!$D$2:$F$146,3, FALSE) -> La date de fin prévisionnelle de la position doit être antérieure ou égale à la date de décès de l'enfant. | BO12: POS_C_120 | BP12: =VLOOKUP(BO12,'Axe 2 Règles de gestion'!$D$2:$F$146,3, FALSE) -> La saisie d'une occurrence de congés/absences est interdite (date de fin réelle) | BQ12: POS_C_121 | BR12: =VLOOKUP(BQ12,'Axe 2 Règles de gestion'!$D$2:$F$146,3, FALSE) -> La saisie d'une occurrence de congés/absences est interdite (date de fin prévisionnelle)
A13: 25.00.00 | B13: M | C13: 45805.66 | D13: D0004 | E13: Position | F13: S0028 | G13: Congé sans traitement | H13: E0312 | I13: Congé sans traitement pour élever enfant | J13: Position saisie égale à 'Congé sans traitement pour élever enfant' | K13: A_POS_POSIAD [Saisi] = 'NAC43' | L13: T0908 | M13: Congé sans traitement pour élever un enfant - Renouvellement | N13: Création Modification | O13: Indicateur de renouvellement saisi = Oui ET l'indicateur de renouvellement saisi est différent de l'indicateur de renouvellement avant saisie | P13: A_POS_INDREN [Saisi] = '1' ET A_POS_INDREN [Saisi] <> A_POS_INDREN [Valeur avant saisie] | Q13: Stagiaire ou auditeur ou élève | R13: P0004 | S13: S | T13: Général | U13: Passant | V13: 40725 | W13: 45781 | X13: CST_I_003 ET CST_D_003 ET CST_D_200 ET CST_D_004 ET CST_D_005 ET CST_D_202 ET POS_C_005 ET POS_C_022 ET POS_C_004 ET POS_C_010 ET POS_C_012 ET POS_C_007 ET POS_C_111 ET POS_C_050 ET POS_C_051 ET POS_C_055 ET POS_C_056 ET POS_C_120 ET POS_C_121 | Y13: CST_I_003 | Z13: =VLOOKUP(Y13,'Axe 2 Règles de gestion'!$D$2:$F$146,3, FALSE) -> L'agent peut renouveler le congé sans traitement 2 fois. | AG13: CST_D_003 | AH13: =VLOOKUP(AG13,'Axe 2 Règles de gestion'!$D$2:$F$146,3, FALSE) -> La durée prévisionnelle maximale de chaque période est de un an. | AI13: CST_D_200 | AJ13: =VLOOKUP(AI13,'Axe 2 Règles de gestion'!$D$2:$F$146,3, FALSE) -> La durée réelle maximale de chaque période est de un an. | AK13: CST_D_004 | AL13: =VLOOKUP(AK13,'Axe 2 Règles de gestion'!$D$2:$F$146,3, FALSE) -> L'agent ne peut pas bénéficier de plus de 3 ans cumulés de congé sans traitement quels que soient les motifs de congés sans traitement : pour raisons personnelles ou familiales. | AM13: CST_D_005 | AN13: =VLOOKUP(AM13,'Axe 2 Règles de gestion'!$D$2:$F$146,3, FALSE) -> L'agent doit avoir un enfant lié à cette position et l'enfant doit être âgé de moins de huit ans (date de fin prévisionnelle du congé sans traitement). | AO13: CST_D_202 | AP13: =VLOOKUP(AO13,'Axe 2 Règles de gestion'!$D$2:$F$146,3, FALSE) -> L'agent doit avoir un enfant lié à cette position et l'enfant doit être âgé de moins de huit ans (date de fin réelle du congé sans traitement). | AQ13: POS_C_005 | AR13: =VLOOKUP(AQ13,'Axe 2 Règles de gestion'!$D$2:$F$146,3, FALSE) -> La date de début de la position doit être postérieure ou égale à la date d'entrée dans la FPE ou dans la carrière militaire. | AS13: POS_C_022 | AT13: =VLOOKUP(AS13,'Axe 2 Règles de gestion'!$D$2:$F$146,3, FALSE) -> La date de début de position est à J+1 de la date de fin de position de l'occurrence précédente. | AU13: POS_C_004 | AV13: =VLOOKUP(AU13,'Axe 2 Règles de gestion'!$D$2:$F$146,3, FALSE) -> La date de début de position doit être antérieure ou égale à la date de fin prévisionnelle de position. | AW13: POS_C_010 | AX13: =VLOOKUP(AW13,'Axe 2 Règles de gestion'!$D$2:$F$146,3, FALSE) -> La date de début de position doit être antérieure ou égale à la date de fin réelle de position. | AY13: POS_C_012 | AZ13: =VLOOKUP(AY13,'Axe 2 Règles de gestion'!$D$2:$F$146,3, FALSE) -> La date de fin prévisionnelle de la position doit être antérieure à la date limite de départ à la retraite. | BA13: POS_C_007 | BB13: =VLOOKUP(BA13,'Axe 2 Règles de gestion'!$D$2:$F$146,3, FALSE) -> La date de fin réelle de la position doit être antérieure à la date limite de départ à la retraite. | BC13: POS_C_111 | BD13: =VLOOKUP(BC13,'Axe 2 Règles de gestion'!$D$2:$F$146,3, FALSE) -> La date de fin ou la date de fin prévisionnelle doit être saisie. | BE13: POS_C_050 | BF13: =VLOOKUP(BE13,'Axe 2 Règles de gestion'!$D$2:$F$146,3, FALSE) -> Le lien vers l'enfant doit être renseigné. | BG13: POS_C_051 | BH13: =VLOOKUP(BG13,'Axe 2 Règles de gestion'!$D$2:$F$146,3, FALSE) -> La date de naissance de l'enfant doit être renseignée. | BI13: POS_C_055 | BJ13: =VLOOKUP(BI13,'Axe 2 Règles de gestion'!$D$2:$F$146,3, FALSE) -> La date de fin réelle de la position doit être antérieure ou égale à la date de décès de l'enfant. | BK13: POS_C_056 | BL13: =VLOOKUP(BK13,'Axe 2 Règles de gestion'!$D$2:$F$146,3, FALSE) -> La date de fin prévisionnelle de la position doit être antérieure ou égale à la date de décès de l'enfant. | BM13: POS_C_120 | BN13: =VLOOKUP(BM13,'Axe 2 Règles de gestion'!$D$2:$F$146,3, FALSE) -> La saisie d'une occurrence de congés/absences est interdite (date de fin réelle) | BO13: POS_C_121 | BP13: =VLOOKUP(BO13,'Axe 2 Règles de gestion'!$D$2:$F$146,3, FALSE) -> La saisie d'une occurrence de congés/absences est interdite (date de fin prévisionnelle)
A14: 25.00.00 | B14: A | C14: 45805.66 | D14: D0004 | E14: Position | F14: S0028 | G14: Congé sans traitement | H14: E0312 | I14: Congé sans traitement pour élever enfant | J14: Position saisie égale à 'Congé sans traitement pour élever enfant' | K14: A_POS_POSIAD [Saisi] = 'NAC43' | L14: T0908 | M14: Congé sans traitement pour élever un enfant - Renouvellement | N14: Création Modification | O14: Indicateur de renouvellement saisi = Oui ET l'indicateur de renouvellement saisi est différent de l'indicateur de renouvellement avant saisie | P14: A_POS_INDREN [Saisi] = '1' ET A_POS_INDREN [Saisi] <> A_POS_INDREN [Valeur avant saisie] | Q14: Stagiaire ou auditeur ou élève | R14: P0004 | S14: S | T14: Général | U14: Passant | V14: 45782 | X14: CST_I_003 ET CST_D_003 ET CST_D_200 ET CST_D_004 ET CST_D_250 ET CST_D_253 ET POS_C_005 ET POS_C_022 ET POS_C_004 ET POS_C_010 ET POS_C_012 ET POS_C_007 ET POS_C_111 ET POS_C_050 ET POS_C_051 ET POS_C_055 ET POS_C_056 ET POS_C_120 ET POS_C_121 | Y14: CST_I_003 | Z14: =VLOOKUP(Y14,'Axe 2 Règles de gestion'!$D$2:$F$146,3, FALSE) -> L'agent peut renouveler le congé sans traitement 2 fois. | AG14: CST_D_003 | AH14: =VLOOKUP(AG14,'Axe 2 Règles de gestion'!$D$2:$F$146,3, FALSE) -> La durée prévisionnelle maximale de chaque période est de un an. | AI14: CST_D_200 | AJ14: =VLOOKUP(AI14,'Axe 2 Règles de gestion'!$D$2:$F$146,3, FALSE) -> La durée réelle maximale de chaque période est de un an. | AK14: CST_D_004 | AL14: =VLOOKUP(AK14,'Axe 2 Règles de gestion'!$D$2:$F$146,3, FALSE) -> L'agent ne peut pas bénéficier de plus de 3 ans cumulés de congé sans traitement quels que soient les motifs de congés sans traitement : pour raisons personnelles ou familiales. | AM14: CST_D_250 | AN14: =VLOOKUP(AM14,'Axe 2 Règles de gestion'!$D$2:$F$146,3, FALSE) -> L'agent doit avoir un enfant lié à cette position et l'enfant doit être âgé de moins de 12 ans (date de fin prévisionnelle du congé sans traitement). | AO14: CST_D_253 | AP14: =VLOOKUP(AO14,'Axe 2 Règles de gestion'!$D$2:$F$146,3, FALSE) -> L'agent doit avoir un enfant lié à cette position et l'enfant doit être âgé de moins de 12 ans (date de fin réelle du congé sans traitement). | AQ14: POS_C_005 | AR14: =VLOOKUP(AQ14,'Axe 2 Règles de gestion'!$D$2:$F$146,3, FALSE) -> La date de début de la position doit être postérieure ou égale à la date d'entrée dans la FPE ou dans la carrière militaire. | AS14: POS_C_022 | AT14: =VLOOKUP(AS14,'Axe 2 Règles de gestion'!$D$2:$F$146,3, FALSE) -> La date de début de position est à J+1 de la date de fin de position de l'occurrence précédente. | AU14: POS_C_004 | AV14: =VLOOKUP(AU14,'Axe 2 Règles de gestion'!$D$2:$F$146,3, FALSE) -> La date de début de position doit être antérieure ou égale à la date de fin prévisionnelle de position. | AW14: POS_C_010 | AX14: =VLOOKUP(AW14,'Axe 2 Règles de gestion'!$D$2:$F$146,3, FALSE) -> La date de début de position doit être antérieure ou égale à la date de fin réelle de position. | AY14: POS_C_012 | AZ14: =VLOOKUP(AY14,'Axe 2 Règles de gestion'!$D$2:$F$146,3, FALSE) -> La date de fin prévisionnelle de la position doit être antérieure à la date limite de départ à la retraite. | BA14: POS_C_007 | BB14: =VLOOKUP(BA14,'Axe 2 Règles de gestion'!$D$2:$F$146,3, FALSE) -> La date de fin réelle de la position doit être antérieure à la date limite de départ à la retraite. | BC14: POS_C_111 | BD14: =VLOOKUP(BC14,'Axe 2 Règles de gestion'!$D$2:$F$146,3, FALSE) -> La date de fin ou la date de fin prévisionnelle doit être saisie. | BE14: POS_C_050 | BF14: =VLOOKUP(BE14,'Axe 2 Règles de gestion'!$D$2:$F$146,3, FALSE) -> Le lien vers l'enfant doit être renseigné. | BG14: POS_C_051 | BH14: =VLOOKUP(BG14,'Axe 2 Règles de gestion'!$D$2:$F$146,3, FALSE) -> La date de naissance de l'enfant doit être renseignée. | BI14: POS_C_055 | BJ14: =VLOOKUP(BI14,'Axe 2 Règles de gestion'!$D$2:$F$146,3, FALSE) -> La date de fin réelle de la position doit être antérieure ou égale à la date de décès de l'enfant. | BK14: POS_C_056 | BL14: =VLOOKUP(BK14,'Axe 2 Règles de gestion'!$D$2:$F$146,3, FALSE) -> La date de fin prévisionnelle de la position doit être antérieure ou égale à la date de décès de l'enfant. | BM14: POS_C_120 | BN14: =VLOOKUP(BM14,'Axe 2 Règles de gestion'!$D$2:$F$146,3, FALSE) -> La saisie d'une occurrence de congés/absences est interdite (date de fin réelle) | BO14: POS_C_121 | BP14: =VLOOKUP(BO14,'Axe 2 Règles de gestion'!$D$2:$F$146,3, FALSE) -> La saisie d'une occurrence de congés/absences est interdite (date de fin prévisionnelle)
A15: 22.00.00 | B15: M | C15: 44714.707 | D15: D0004 | E15: Position | F15: S0028 | G15: Congé sans traitement | H15: E0312 | I15: Congé sans traitement pour élever enfant | J15: Position saisie égale à 'Congé sans traitement pour élever enfant' | K15: A_POS_POSIAD [Saisi] = 'NAC43' | L15: T0909 | M15: Congé sans traitement pour élever un enfant - Modification/Fin | N15: Modification | O15: L'indicateur de renouvellement saisi est égal à l'indicateur de renouvellement avant saisie | P15: A_POS_INDREN [Saisi] = A_POS_INDREN [Valeur avant saisie] | Q15: Stagiaire ou auditeur ou élève | R15: P0004 | S15: S | T15: Général | U15: Passant | V15: 40725 | W15: 44633 | X15: CST_I_013 ET CST_I_014 ET CST_D_003 ET CST_D_200 ET CST_D_004 ET CST_D_005 ET CST_D_202 ET POS_C_004 ET POS_C_010 ET POS_C_012 ET POS_C_007 ET POS_C_111 ET POS_C_050 ET POS_C_051 ET POS_C_055 ET POS_C_056 ET POS_C_120 ET POS_C_121 | Y15: CST_I_013 | Z15: =VLOOKUP(Y15,'Axe 2 Règles de gestion'!$D$2:$F$146,3, FALSE) -> L'agent doit demander à reprendre ses fonctions au moins 2 mois avant l'expiration du congé en cours. | AA15: CST_I_014 | AB15: =VLOOKUP(AA15,'Axe 2 Règles de gestion'!$D$2:$F$146,3, FALSE) -> Si l'interruption du stage est d'au moins 1 an, la reprise des fonctions est subordonnée à une vérification de l'aptitude physique à l'exercice des fonctions par un médecin agréé et, éventuellement, par le comité médical compétent. | AG15: CST_D_003 | AH15: =VLOOKUP(AG15,'Axe 2 Règles de gestion'!$D$2:$F$146,3, FALSE) -> La durée prévisionnelle maximale de chaque période est de un an. | AI15: CST_D_200 | AJ15: =VLOOKUP(AI15,'Axe 2 Règles de gestion'!$D$2:$F$146,3, FALSE) -> La durée réelle maximale de chaque période est de un an. | AK15: CST_D_004 | AL15: =VLOOKUP(AK15,'Axe 2 Règles de gestion'!$D$2:$F$146,3, FALSE) -> L'agent ne peut pas bénéficier de plus de 3 ans cumulés de congé sans traitement quels que soient les motifs de congés sans traitement : pour raisons personnelles ou familiales. | AM15: CST_D_005 | AN15: =VLOOKUP(AM15,'Axe 2 Règles de gestion'!$D$2:$F$146,3, FALSE) -> L'agent doit avoir un enfant lié à cette position et l'enfant doit être âgé de moins de huit ans (date de fin prévisionnelle du congé sans traitement). | AO15: CST_D_202 | AP15: =VLOOKUP(AO15,'Axe 2 Règles de gestion'!$D$2:$F$146,3, FALSE) -> L'agent doit avoir un enfant lié à cette position et l'enfant doit être âgé de moins de huit ans (date de fin réelle du congé sans traitement). | AQ15: POS_C_004 | AR15: =VLOOKUP(AQ15,'Axe 2 Règles de gestion'!$D$2:$F$146,3, FALSE) -> La date de début de position doit être antérieure ou égale à la date de fin prévisionnelle de position. | AS15: POS_C_010 | AT15: =VLOOKUP(AS15,'Axe 2 Règles de gestion'!$D$2:$F$146,3, FALSE) -> La date de début de position doit être antérieure ou égale à la date de fin réelle de position. | AU15: POS_C_012 | AV15: =VLOOKUP(AU15,'Axe 2 Règles de gestion'!$D$2:$F$146,3, FALSE) -> La date de fin prévisionnelle de la position doit être antérieure à la date limite de départ à la retraite. | AW15: POS_C_007 | AX15: =VLOOKUP(AW15,'Axe 2 Règles de gestion'!$D$2:$F$146,3, FALSE) -> La date de fin réelle de la position doit être antérieure à la date limite de départ à la retraite. | AY15: POS_C_111 | AZ15: =VLOOKUP(AY15,'Axe 2 Règles de gestion'!$D$2:$F$146,3, FALSE) -> La date de fin ou la date de fin prévisionnelle doit être saisie. | BA15: POS_C_050 | BB15: =VLOOKUP(BA15,'Axe 2 Règles de gestion'!$D$2:$F$146,3, FALSE) -> Le lien vers l'enfant doit être renseigné. | BC15: POS_C_051 | BD15: =VLOOKUP(BC15,'Axe 2 Règles de gestion'!$D$2:$F$146,3, FALSE) -> La date de naissance de l'enfant doit être renseignée. | BE15: POS_C_055 | BF15: =VLOOKUP(BE15,'Axe 2 Règles de gestion'!$D$2:$F$146,3, FALSE) -> La date de fin réelle de la position doit être antérieure ou égale à la date de décès de l'enfant. | BG15: POS_C_056 | BH15: =VLOOKUP(BG15,'Axe 2 Règles de gestion'!$D$2:$F$146,3, FALSE) -> La date de fin prévisionnelle de la position doit être antérieure ou égale à la date de décès de l'enfant. | BI15: POS_C_120 | BJ15: =VLOOKUP(BI15,'Axe 2 Règles de gestion'!$D$2:$F$146,3, FALSE) -> La saisie d'une occurrence de congés/absences est interdite (date de fin réelle) | BK15: POS_C_121 | BL15: =VLOOKUP(BK15,'Axe 2 Règles de gestion'!$D$2:$F$146,3, FALSE) -> La saisie d'une occurrence de congés/absences est interdite (date de fin prévisionnelle)
A16: 25.00.00 | B16: M | C16: 45805.663 | D16: D0004 | E16: Position | F16: S0028 | G16: Congé sans traitement | H16: E0312 | I16: Congé sans traitement pour élever enfant | J16: Position saisie égale à 'Congé sans traitement pour élever enfant' | K16: A_POS_POSIAD [Saisi] = 'NAC43' | L16: T0909 | M16: Congé sans traitement pour élever un enfant - Modification/Fin | N16: Modification | O16: L'indicateur de renouvellement saisi est égal à l'indicateur de renouvellement avant saisie | P16: A_POS_INDREN [Saisi] = A_POS_INDREN [Valeur avant saisie] | Q16: Stagiaire ou auditeur ou élève | R16: P0004 | S16: S | T16: Général | U16: Passant | V16: 44634 | W16: 45781 | X16: CST_I_013 ET CST_I_049 ET CST_D_003 ET CST_D_200 ET CST_D_004 ET CST_D_005 ET CST_D_202 ET POS_C_004 ET POS_C_010 ET POS_C_012 ET POS_C_007 ET POS_C_111 ET POS_C_050 ET POS_C_051 ET POS_C_055 ET POS_C_056 ET POS_C_120 ET POS_C_121 | Y16: CST_I_013 | Z16: =VLOOKUP(Y16,'Axe 2 Règles de gestion'!$D$2:$F$146,3, FALSE) -> L'agent doit demander à reprendre ses fonctions au moins 2 mois avant l'expiration du congé en cours. | AA16: CST_I_049 | AB16: =VLOOKUP(AA16,'Axe 2 Règles de gestion'!$D$2:$F$146,3, FALSE) -> Si l'interruption du stage est d'au moins 1 an, la reprise des fonctions est subordonnée à une vérification des conditions de santé particulières exigées pour l'exercice de certaines fonctions par un médecin agréé et/ou par le conseil médical compétent. | AG16: CST_D_003 | AH16: =VLOOKUP(AG16,'Axe 2 Règles de gestion'!$D$2:$F$146,3, FALSE) -> La durée prévisionnelle maximale de chaque période est de un an. | AI16: CST_D_200 | AJ16: =VLOOKUP(AI16,'Axe 2 Règles de gestion'!$D$2:$F$146,3, FALSE) -> La durée réelle maximale de chaque période est de un an. | AK16: CST_D_004 | AL16: =VLOOKUP(AK16,'Axe 2 Règles de gestion'!$D$2:$F$146,3, FALSE) -> L'agent ne peut pas bénéficier de plus de 3 ans cumulés de congé sans traitement quels que soient les motifs de congés sans traitement : pour raisons personnelles ou familiales. | AM16: CST_D_005 | AN16: =VLOOKUP(AM16,'Axe 2 Règles de gestion'!$D$2:$F$146,3, FALSE) -> L'agent doit avoir un enfant lié à cette position et l'enfant doit être âgé de moins de huit ans (date de fin prévisionnelle du congé sans traitement). | AO16: CST_D_202 | AP16: =VLOOKUP(AO16,'Axe 2 Règles de gestion'!$D$2:$F$146,3, FALSE) -> L'agent doit avoir un enfant lié à cette position et l'enfant doit être âgé de moins de huit ans (date de fin réelle du congé sans traitement). | AQ16: POS_C_004 | AR16: =VLOOKUP(AQ16,'Axe 2 Règles de gestion'!$D$2:$F$146,3, FALSE) -> La date de début de position doit être antérieure ou égale à la date de fin prévisionnelle de position. | AS16: POS_C_010 | AT16: =VLOOKUP(AS16,'Axe 2 Règles de gestion'!$D$2:$F$146,3, FALSE) -> La date de début de position doit être antérieure ou égale à la date de fin réelle de position. | AU16: POS_C_012 | AV16: =VLOOKUP(AU16,'Axe 2 Règles de gestion'!$D$2:$F$146,3, FALSE) -> La date de fin prévisionnelle de la position doit être antérieure à la date limite de départ à la retraite. | AW16: POS_C_007 | AX16: =VLOOKUP(AW16,'Axe 2 Règles de gestion'!$D$2:$F$146,3, FALSE) -> La date de fin réelle de la position doit être antérieure à la date limite de départ à la retraite. | AY16: POS_C_111 | AZ16: =VLOOKUP(AY16,'Axe 2 Règles de gestion'!$D$2:$F$146,3, FALSE) -> La date de fin ou la date de fin prévisionnelle doit être saisie. | BA16: POS_C_050 | BB16: =VLOOKUP(BA16,'Axe 2 Règles de gestion'!$D$2:$F$146,3, FALSE) -> Le lien vers l'enfant doit être renseigné. | BC16: POS_C_051 | BD16: =VLOOKUP(BC16,'Axe 2 Règles de gestion'!$D$2:$F$146,3, FALSE) -> La date de naissance de l'enfant doit être renseignée. | BE16: POS_C_055 | BF16: =VLOOKUP(BE16,'Axe 2 Règles de gestion'!$D$2:$F$146,3, FALSE) -> La date de fin réelle de la position doit être antérieure ou égale à la date de décès de l'enfant. | BG16: POS_C_056 | BH16: =VLOOKUP(BG16,'Axe 2 Règles de gestion'!$D$2:$F$146,3, FALSE) -> La date de fin prévisionnelle de la position doit être antérieure ou égale à la date de décès de l'enfant. | BI16: POS_C_120 | BJ16: =VLOOKUP(BI16,'Axe 2 Règles de gestion'!$D$2:$F$146,3, FALSE) -> La saisie d'une occurrence de congés/absences est interdite (date de fin réelle) | BK16: POS_C_121 | BL16: =VLOOKUP(BK16,'Axe 2 Règles de gestion'!$D$2:$F$146,3, FALSE) -> La saisie d'une occurrence de congés/absences est interdite (date de fin prévisionnelle)
A17: 25.00.00 | B17: A | C17: 45805.663 | D17: D0004 | E17: Position | F17: S0028 | G17: Congé sans traitement | H17: E0312 | I17: Congé sans traitement pour élever enfant | J17: Position saisie égale à 'Congé sans traitement pour élever enfant' | K17: A_POS_POSIAD [Saisi] = 'NAC43' | L17: T0909 | M17: Congé sans traitement pour élever un enfant - Modification/Fin | N17: Modification | O17: L'indicateur de renouvellement saisi est égal à l'indicateur de renouvellement avant saisie | P17: A_POS_INDREN [Saisi] = A_POS_INDREN [Valeur avant saisie] | Q17: Stagiaire ou auditeur ou élève | R17: P0004 | S17: S | T17: Général | U17: Passant | V17: 45782 | X17: CST_I_013 ET CST_I_049 ET CST_D_003 ET CST_D_200 ET CST_D_004 ET CST_D_250 ET CST_D_253 ET POS_C_004 ET POS_C_010 ET POS_C_012 ET POS_C_007 ET POS_C_111 ET POS_C_050 ET POS_C_051 ET POS_C_055 ET POS_C_056 ET POS_C_120 ET POS_C_121 | Y17: CST_I_013 | Z17: =VLOOKUP(Y17,'Axe 2 Règles de gestion'!$D$2:$F$146,3, FALSE) -> L'agent doit demander à reprendre ses fonctions au moins 2 mois avant l'expiration du congé en cours. | AA17: CST_I_049 | AB17: =VLOOKUP(AA17,'Axe 2 Règles de gestion'!$D$2:$F$146,3, FALSE) -> Si l'interruption du stage est d'au moins 1 an, la reprise des fonctions est subordonnée à une vérification des conditions de santé particulières exigées pour l'exercice de certaines fonctions par un médecin agréé et/ou par le conseil médical compétent. | AG17: CST_D_003 | AH17: =VLOOKUP(AG17,'Axe 2 Règles de gestion'!$D$2:$F$146,3, FALSE) -> La durée prévisionnelle maximale de chaque période est de un an. | AI17: CST_D_200 | AJ17: =VLOOKUP(AI17,'Axe 2 Règles de gestion'!$D$2:$F$146,3, FALSE) -> La durée réelle maximale de chaque période est de un an. | AK17: CST_D_004 | AL17: =VLOOKUP(AK17,'Axe 2 Règles de gestion'!$D$2:$F$146,3, FALSE) -> L'agent ne peut pas bénéficier de plus de 3 ans cumulés de congé sans traitement quels que soient les motifs de congés sans traitement : pour raisons personnelles ou familiales. | AM17: CST_D_250 | AN17: =VLOOKUP(AM17,'Axe 2 Règles de gestion'!$D$2:$F$146,3, FALSE) -> L'agent doit avoir un enfant lié à cette position et l'enfant doit être âgé de moins de 12 ans (date de fin prévisionnelle du congé sans traitement). | AO17: CST_D_253 | AP17: =VLOOKUP(AO17,'Axe 2 Règles de gestion'!$D$2:$F$146,3, FALSE) -> L'agent doit avoir un enfant lié à cette position et l'enfant doit être âgé de moins de 12 ans (date de fin réelle du congé sans traitement). | AQ17: POS_C_004 | AR17: =VLOOKUP(AQ17,'Axe 2 Règles de gestion'!$D$2:$F$146,3, FALSE) -> La date de début de position doit être antérieure ou égale à la date de fin prévisionnelle de position. | AS17: POS_C_010 | AT17: =VLOOKUP(AS17,'Axe 2 Règles de gestion'!$D$2:$F$146,3, FALSE) -> La date de début de position doit être antérieure ou égale à la date de fin réelle de position. | AU17: POS_C_012 | AV17: =VLOOKUP(AU17,'Axe 2 Règles de gestion'!$D$2:$F$146,3, FALSE) -> La date de fin prévisionnelle de la position doit être antérieure à la date limite de départ à la retraite. | AW17: POS_C_007 | AX17: =VLOOKUP(AW17,'Axe 2 Règles de gestion'!$D$2:$F$146,3, FALSE) -> La date de fin réelle de la position doit être antérieure à la date limite de départ à la retraite. | AY17: POS_C_111 | AZ17: =VLOOKUP(AY17,'Axe 2 Règles de gestion'!$D$2:$F$146,3, FALSE) -> La date de fin ou la date de fin prévisionnelle doit être saisie. | BA17: POS_C_050 | BB17: =VLOOKUP(BA17,'Axe 2 Règles de gestion'!$D$2:$F$146,3, FALSE) -> Le lien vers l'enfant doit être renseigné. | BC17: POS_C_051 | BD17: =VLOOKUP(BC17,'Axe 2 Règles de gestion'!$D$2:$F$146,3, FALSE) -> La date de naissance de l'enfant doit être renseignée. | BE17: POS_C_055 | BF17: =VLOOKUP(BE17,'Axe 2 Règles de gestion'!$D$2:$F$146,3, FALSE) -> La date de fin réelle de la position doit être antérieure ou égale à la date de décès de l'enfant. | BG17: POS_C_056 | BH17: =VLOOKUP(BG17,'Axe 2 Règles de gestion'!$D$2:$F$146,3, FALSE) -> La date de fin prévisionnelle de la position doit être antérieure ou égale à la date de décès de l'enfant. | BI17: POS_C_120 | BJ17: =VLOOKUP(BI17,'Axe 2 Règles de gestion'!$D$2:$F$146,3, FALSE) -> La saisie d'une occurrence de congés/absences est interdite (date de fin réelle) | BK17: POS_C_121 | BL17: =VLOOKUP(BK17,'Axe 2 Règles de gestion'!$D$2:$F$146,3, FALSE) -> La saisie d'une occurrence de congés/absences est interdite (date de fin prévisionnelle)
A18: 17.10.00 | B18: A | C18: 43152.5 | D18: D0004 | E18: Position | F18: S0028 | G18: Congé sans traitement | H18: E0312 | I18: Congé sans traitement pour élever enfant | J18: Position saisie égale à 'Congé sans traitement pour élever enfant' | K18: A_POS_POSIAD [Saisi] = 'NAC43' | L18: T0907 | M18: Congé sans traitement pour élever un enfant - Demande | N18: Création Modification | O18: Indicateur de renouvellement saisi = Non ET l'indicateur de renouvellement saisi est différent de l'indicateur de renouvellement avant saisie | P18: A_POS_INDREN [Saisi] = '0' ET A_POS_INDREN [Saisi] <> A_POS_INDREN [Valeur avant saisie] | Q18: Ouvrier d'état | R18: P0005 | S18: O | T18: Général | U18: Exclu | V18: 40725
A19: 17.10.00 | B19: A | C19: 43152.5 | D19: D0004 | E19: Position | F19: S0028 | G19: Congé sans traitement | H19: E0312 | I19: Congé sans traitement pour élever enfant | J19: Position saisie égale à 'Congé sans traitement pour élever enfant' | K19: A_POS_POSIAD [Saisi] = 'NAC43' | L19: T0908 | M19: Congé sans traitement pour élever un enfant - Renouvellement | N19: Création Modification | O19: Indicateur de renouvellement saisi = Oui ET l'indicateur de renouvellement saisi est différent de l'indicateur de renouvellement avant saisie | P19: A_POS_INDREN [Saisi] = '1' ET A_POS_INDREN [Saisi] <> A_POS_INDREN [Valeur avant saisie] | Q19: Ouvrier d'état | R19: P0005 | S19: O | T19: Général | U19: Exclu | V19: 40725
A20: 17.10.00 | B20: A | C20: 43152.5 | D20: D0004 | E20: Position | F20: S0028 | G20: Congé sans traitement | H20: E0312 | I20: Congé sans traitement pour élever enfant | J20: Position saisie égale à 'Congé sans traitement pour élever enfant' | K20: A_POS_POSIAD [Saisi] = 'NAC43' | L20: T0909 | M20: Congé sans traitement pour élever un enfant - Modification/Fin | N20: Modification | O20: L'indicateur de renouvellement saisi est égal à l'indicateur de renouvellement avant saisie | P20: A_POS_INDREN [Saisi] = A_POS_INDREN [Valeur avant saisie] | Q20: Ouvrier d'état | R20: P0005 | S20: O | T20: Général | U20: Exclu | V20: 40725
A21: 25.00.00 | B21: M | C21: 45805.675 | D21: D0004 | E21: Position | F21: S0028 | G21: Congé sans traitement | H21: E0312 | I21: Congé sans traitement pour élever enfant | J21: Position saisie égale à 'Congé sans traitement pour élever enfant' | K21: A_POS_POSIAD [Saisi] = 'NAC43' | L21: T0907 | M21: Congé sans traitement pour élever un enfant - Demande | N21: Création Modification | O21: Indicateur de renouvellement saisi = Non ET l'indicateur de renouvellement saisi est différent de l'indicateur de renouvellement avant saisie | P21: A_POS_INDREN [Saisi] = '0' ET A_POS_INDREN [Saisi] <> A_POS_INDREN [Valeur avant saisie] | Q21: Auditeur de justice | R21: P0009 | S21: S | T21: Particulier | U21: Passant | V21: 40725 | W21: 45781 | X21: CST_I_022 ET CST_I_023 ET CST_D_157 ET CST_D_210 ET CST_D_185 ET CST_D_158 ET CST_D_212 ET POS_C_100 ET POS_C_005 ET POS_C_022 ET POS_C_004 ET POS_C_010 ET POS_C_012 ET POS_C_007 ET POS_C_111 ET POS_C_050 ET POS_C_051 ET POS_C_055 ET POS_C_056 ET POS_C_120 ET POS_C_121 | Y21: CST_I_022 | Z21: =VLOOKUP(Y21,'Axe 2 Règles de gestion'!$D$2:$F$146,3, FALSE) -> L'agent doit présenter une demande de congé sans traitement. | AA21: CST_I_023 | AB21: =VLOOKUP(AA21,'Axe 2 Règles de gestion'!$D$2:$F$146,3, FALSE) -> La demande est accordée de droit par le supérieur hiérarchique. | AG21: CST_D_157 | AH21: =VLOOKUP(AG21,'Axe 2 Règles de gestion'!$D$2:$F$146,3, FALSE) -> La durée prévisionnelle maximale de chaque période est de un an. | AI21: CST_D_210 | AJ21: =VLOOKUP(AI21,'Axe 2 Règles de gestion'!$D$2:$F$146,3, FALSE) -> La durée réelle maximale de chaque période est de un an. | AK21: CST_D_185 | AL21: =VLOOKUP(AK21,'Axe 2 Règles de gestion'!$D$2:$F$146,3, FALSE) -> L'agent ne peut pas bénéficier de plus de 3 ans cumulés de congé sans traitement quels que soient les motifs de congés sans traitement : pour raisons personnelles ou familiales. | AM21: CST_D_158 | AN21: =VLOOKUP(AM21,'Axe 2 Règles de gestion'!$D$2:$F$146,3, FALSE) -> L'agent doit avoir un enfant lié à cette position et l'enfant doit être âgé de moins de huit ans (date de fin prévisionnelle du congé sans traitement). | AO21: CST_D_212 | AP21: =VLOOKUP(AO21,'Axe 2 Règles de gestion'!$D$2:$F$146,3, FALSE) -> L'agent doit avoir un enfant lié à cette position et l'enfant doit être âgé de moins de huit ans (date de fin réelle du congé sans traitement). | AQ21: POS_C_100 | AR21: =VLOOKUP(AQ21,'Axe 2 Règles de gestion'!$D$2:$F$146,3, FALSE) -> Lors de la demande initiale, l'agent doit être en activité. | AS21: POS_C_005 | AT21: =VLOOKUP(AS21,'Axe 2 Règles de gestion'!$D$2:$F$146,3, FALSE) -> La date de début de la position doit être postérieure ou égale à la date d'entrée dans la FPE ou dans la carrière militaire. | AU21: POS_C_022 | AV21: =VLOOKUP(AU21,'Axe 2 Règles de gestion'!$D$2:$F$146,3, FALSE) -> La date de début de position est à J+1 de la date de fin de position de l'occurrence précédente. | AW21: POS_C_004 | AX21: =VLOOKUP(AW21,'Axe 2 Règles de gestion'!$D$2:$F$146,3, FALSE) -> La date de début de position doit être antérieure ou égale à la date de fin prévisionnelle de position. | AY21: POS_C_010 | AZ21: =VLOOKUP(AY21,'Axe 2 Règles de gestion'!$D$2:$F$146,3, FALSE) -> La date de début de position doit être antérieure ou égale à la date de fin réelle de position. | BA21: POS_C_012 | BB21: =VLOOKUP(BA21,'Axe 2 Règles de gestion'!$D$2:$F$146,3, FALSE) -> La date de fin prévisionnelle de la position doit être antérieure à la date limite de départ à la retraite. | BC21: POS_C_007 | BD21: =VLOOKUP(BC21,'Axe 2 Règles de gestion'!$D$2:$F$146,3, FALSE) -> La date de fin réelle de la position doit être antérieure à la date limite de départ à la retraite. | BE21: POS_C_111 | BF21: =VLOOKUP(BE21,'Axe 2 Règles de gestion'!$D$2:$F$146,3, FALSE) -> La date de fin ou la date de fin prévisionnelle doit être saisie. | BG21: POS_C_050 | BH21: =VLOOKUP(BG21,'Axe 2 Règles de gestion'!$D$2:$F$146,3, FALSE) -> Le lien vers l'enfant doit être renseigné. | BI21: POS_C_051 | BJ21: =VLOOKUP(BI21,'Axe 2 Règles de gestion'!$D$2:$F$146,3, FALSE) -> La date de naissance de l'enfant doit être renseignée. | BK21: POS_C_055 | BL21: =VLOOKUP(BK21,'Axe 2 Règles de gestion'!$D$2:$F$146,3, FALSE) -> La date de fin réelle de la position doit être antérieure ou égale à la date de décès de l'enfant. | BM21: POS_C_056 | BN21: =VLOOKUP(BM21,'Axe 2 Règles de gestion'!$D$2:$F$146,3, FALSE) -> La date de fin prévisionnelle de la position doit être antérieure ou égale à la date de décès de l'enfant. | BO21: POS_C_120 | BP21: =VLOOKUP(BO21,'Axe 2 Règles de gestion'!$D$2:$F$146,3, FALSE) -> La saisie d'une occurrence de congés/absences est interdite (date de fin réelle) | BQ21: POS_C_121 | BR21: =VLOOKUP(BQ21,'Axe 2 Règles de gestion'!$D$2:$F$146,3, FALSE) -> La saisie d'une occurrence de congés/absences est interdite (date de fin prévisionnelle)
A22: 25.00.00 | B22: A | C22: 45805.675 | D22: D0004 | E22: Position | F22: S0028 | G22: Congé sans traitement | H22: E0312 | I22: Congé sans traitement pour élever enfant | J22: Position saisie égale à 'Congé sans traitement pour élever enfant' | K22: A_POS_POSIAD [Saisi] = 'NAC43' | L22: T0907 | M22: Congé sans traitement pour élever un enfant - Demande | N22: Création Modification | O22: Indicateur de renouvellement saisi = Non ET l'indicateur de renouvellement saisi est différent de l'indicateur de renouvellement avant saisie | P22: A_POS_INDREN [Saisi] = '0' ET A_POS_INDREN [Saisi] <> A_POS_INDREN [Valeur avant saisie] | Q22: Auditeur de justice | R22: P0009 | S22: S | T22: Particulier | U22: Passant | V22: 45782 | X22: CST_I_059 ET CST_I_001 ET CST_I_002 ET CST_D_003 ET CST_D_200 ET CST_D_004 ET CST_D_250 ET CST_D_253 ET POS_C_100 ET POS_C_005 ET POS_C_022 ET POS_C_004 ET POS_C_010 ET POS_C_012 ET POS_C_007 ET POS_C_111 ET POS_C_050 ET POS_C_051 ET POS_C_055 ET POS_C_056 ET POS_C_120 ET POS_C_121 | Y22: CST_I_059 | Z22: =VLOOKUP(Y22,'Axe 2 Règles de gestion'!$D$2:$F$146,3, FALSE) -> L'agent bénéficie des dispositions applicables aux agents stagiaires. | AA22: CST_I_001 | AB22: =VLOOKUP(AA22,'Axe 2 Règles de gestion'!$D$2:$F$146,3, FALSE) -> L'agent doit présenter une demande de congé sans traitement. | AC22: CST_I_002 | AD22: =VLOOKUP(AC22,'Axe 2 Règles de gestion'!$D$2:$F$146,3, FALSE) -> La demande est accordée de droit par le supérieur hiérarchique. | AG22: CST_D_003 | AH22: =VLOOKUP(AG22,'Axe 2 Règles de gestion'!$D$2:$F$146,3, FALSE) -> La durée prévisionnelle maximale de chaque période est de un an. | AI22: CST_D_200 | AJ22: =VLOOKUP(AI22,'Axe 2 Règles de gestion'!$D$2:$F$146,3, FALSE) -> La durée réelle maximale de chaque période est de un an. | AK22: CST_D_004 | AL22: =VLOOKUP(AK22,'Axe 2 Règles de gestion'!$D$2:$F$146,3, FALSE) -> L'agent ne peut pas bénéficier de plus de 3 ans cumulés de congé sans traitement quels que soient les motifs de congés sans traitement : pour raisons personnelles ou familiales. | AM22: CST_D_250 | AN22: =VLOOKUP(AM22,'Axe 2 Règles de gestion'!$D$2:$F$146,3, FALSE) -> L'agent doit avoir un enfant lié à cette position et l'enfant doit être âgé de moins de 12 ans (date de fin prévisionnelle du congé sans traitement). | AO22: CST_D_253 | AP22: =VLOOKUP(AO22,'Axe 2 Règles de gestion'!$D$2:$F$146,3, FALSE) -> L'agent doit avoir un enfant lié à cette position et l'enfant doit être âgé de moins de 12 ans (date de fin réelle du congé sans traitement). | AQ22: POS_C_100 | AR22: =VLOOKUP(AQ22,'Axe 2 Règles de gestion'!$D$2:$F$146,3, FALSE) -> Lors de la demande initiale, l'agent doit être en activité. | AS22: POS_C_005 | AT22: =VLOOKUP(AS22,'Axe 2 Règles de gestion'!$D$2:$F$146,3, FALSE) -> La date de début de la position doit être postérieure ou égale à la date d'entrée dans la FPE ou dans la carrière militaire. | AU22: POS_C_022 | AV22: =VLOOKUP(AU22,'Axe 2 Règles de gestion'!$D$2:$F$146,3, FALSE) -> La date de début de position est à J+1 de la date de fin de position de l'occurrence précédente. | AW22: POS_C_004 | AX22: =VLOOKUP(AW22,'Axe 2 Règles de gestion'!$D$2:$F$146,3, FALSE) -> La date de début de position doit être antérieure ou égale à la date de fin prévisionnelle de position. | AY22: POS_C_010 | AZ22: =VLOOKUP(AY22,'Axe 2 Règles de gestion'!$D$2:$F$146,3, FALSE) -> La date de début de position doit être antérieure ou égale à la date de fin réelle de position. | BA22: POS_C_012 | BB22: =VLOOKUP(BA22,'Axe 2 Règles de gestion'!$D$2:$F$146,3, FALSE) -> La date de fin prévisionnelle de la position doit être antérieure à la date limite de départ à la retraite. | BC22: POS_C_007 | BD22: =VLOOKUP(BC22,'Axe 2 Règles de gestion'!$D$2:$F$146,3, FALSE) -> La date de fin réelle de la position doit être antérieure à la date limite de départ à la retraite. | BE22: POS_C_111 | BF22: =VLOOKUP(BE22,'Axe 2 Règles de gestion'!$D$2:$F$146,3, FALSE) -> La date de fin ou la date de fin prévisionnelle doit être saisie. | BG22: POS_C_050 | BH22: =VLOOKUP(BG22,'Axe 2 Règles de gestion'!$D$2:$F$146,3, FALSE) -> Le lien vers l'enfant doit être renseigné. | BI22: POS_C_051 | BJ22: =VLOOKUP(BI22,'Axe 2 Règles de gestion'!$D$2:$F$146,3, FALSE) -> La date de naissance de l'enfant doit être renseignée. | BK22: POS_C_055 | BL22: =VLOOKUP(BK22,'Axe 2 Règles de gestion'!$D$2:$F$146,3, FALSE) -> La date de fin réelle de la position doit être antérieure ou égale à la date de décès de l'enfant. | BM22: POS_C_056 | BN22: =VLOOKUP(BM22,'Axe 2 Règles de gestion'!$D$2:$F$146,3, FALSE) -> La date de fin prévisionnelle de la position doit être antérieure ou égale à la date de décès de l'enfant. | BO22: POS_C_120 | BP22: =VLOOKUP(BO22,'Axe 2 Règles de gestion'!$D$2:$F$146,3, FALSE) -> La saisie d'une occurrence de congés/absences est interdite (date de fin réelle) | BQ22: POS_C_121 | BR22: =VLOOKUP(BQ22,'Axe 2 Règles de gestion'!$D$2:$F$146,3, FALSE) -> La saisie d'une occurrence de congés/absences est interdite (date de fin prévisionnelle)
A23: 25.00.00 | B23: M | C23: 45805.677 | D23: D0004 | E23: Position | F23: S0028 | G23: Congé sans traitement | H23: E0312 | I23: Congé sans traitement pour élever enfant | J23: Position saisie égale à 'Congé sans traitement pour élever enfant' | K23: A_POS_POSIAD [Saisi] = 'NAC43' | L23: T0908 | M23: Congé sans traitement pour élever un enfant - Renouvellement | N23: Création Modification | O23: Indicateur de renouvellement saisi = Oui ET l'indicateur de renouvellement saisi est différent de l'indicateur de renouvellement avant saisie | P23: A_POS_INDREN [Saisi] = '1' ET A_POS_INDREN [Saisi] <> A_POS_INDREN [Valeur avant saisie] | Q23: Auditeur de justice | R23: P0009 | S23: S | T23: Particulier | U23: Passant | V23: 40725 | W23: 45781 | X23: CST_I_024 ET CST_D_157 ET CST_D_210 ET CST_D_185 ET CST_D_158 ET CST_D_212 ET POS_C_005 ET POS_C_022 ET POS_C_004 ET POS_C_010 ET POS_C_012 ET POS_C_007 ET POS_C_111 ET POS_C_050 ET POS_C_051 ET POS_C_055 ET POS_C_056 ET POS_C_120 ET POS_C_121 | Y23: CST_I_024 | Z23: =VLOOKUP(Y23,'Axe 2 Règles de gestion'!$D$2:$F$146,3, FALSE) -> L'agent peut renouveler le congé sans traitement 2 fois. | AG23: CST_D_157 | AH23: =VLOOKUP(AG23,'Axe 2 Règles de gestion'!$D$2:$F$146,3, FALSE) -> La durée prévisionnelle maximale de chaque période est de un an. | AI23: CST_D_210 | AJ23: =VLOOKUP(AI23,'Axe 2 Règles de gestion'!$D$2:$F$146,3, FALSE) -> La durée réelle maximale de chaque période est de un an. | AK23: CST_D_185 | AL23: =VLOOKUP(AK23,'Axe 2 Règles de gestion'!$D$2:$F$146,3, FALSE) -> L'agent ne peut pas bénéficier de plus de 3 ans cumulés de congé sans traitement quels que soient les motifs de congés sans traitement : pour raisons personnelles ou familiales. | AM23: CST_D_158 | AN23: =VLOOKUP(AM23,'Axe 2 Règles de gestion'!$D$2:$F$146,3, FALSE) -> L'agent doit avoir un enfant lié à cette position et l'enfant doit être âgé de moins de huit ans (date de fin prévisionnelle du congé sans traitement). | AO23: CST_D_212 | AP23: =VLOOKUP(AO23,'Axe 2 Règles de gestion'!$D$2:$F$146,3, FALSE) -> L'agent doit avoir un enfant lié à cette position et l'enfant doit être âgé de moins de huit ans (date de fin réelle du congé sans traitement). | AQ23: POS_C_005 | AR23: =VLOOKUP(AQ23,'Axe 2 Règles de gestion'!$D$2:$F$146,3, FALSE) -> La date de début de la position doit être postérieure ou égale à la date d'entrée dans la FPE ou dans la carrière militaire. | AS23: POS_C_022 | AT23: =VLOOKUP(AS23,'Axe 2 Règles de gestion'!$D$2:$F$146,3, FALSE) -> La date de début de position est à J+1 de la date de fin de position de l'occurrence précédente. | AU23: POS_C_004 | AV23: =VLOOKUP(AU23,'Axe 2 Règles de gestion'!$D$2:$F$146,3, FALSE) -> La date de début de position doit être antérieure ou égale à la date de fin prévisionnelle de position. | AW23: POS_C_010 | AX23: =VLOOKUP(AW23,'Axe 2 Règles de gestion'!$D$2:$F$146,3, FALSE) -> La date de début de position doit être antérieure ou égale à la date de fin réelle de position. | AY23: POS_C_012 | AZ23: =VLOOKUP(AY23,'Axe 2 Règles de gestion'!$D$2:$F$146,3, FALSE) -> La date de fin prévisionnelle de la position doit être antérieure à la date limite de départ à la retraite. | BA23: POS_C_007 | BB23: =VLOOKUP(BA23,'Axe 2 Règles de gestion'!$D$2:$F$146,3, FALSE) -> La date de fin réelle de la position doit être antérieure à la date limite de départ à la retraite. | BC23: POS_C_111 | BD23: =VLOOKUP(BC23,'Axe 2 Règles de gestion'!$D$2:$F$146,3, FALSE) -> La date de fin ou la date de fin prévisionnelle doit être saisie. | BE23: POS_C_050 | BF23: =VLOOKUP(BE23,'Axe 2 Règles de gestion'!$D$2:$F$146,3, FALSE) -> Le lien vers l'enfant doit être renseigné. | BG23: POS_C_051 | BH23: =VLOOKUP(BG23,'Axe 2 Règles de gestion'!$D$2:$F$146,3, FALSE) -> La date de naissance de l'enfant doit être renseignée. | BI23: POS_C_055 | BJ23: =VLOOKUP(BI23,'Axe 2 Règles de gestion'!$D$2:$F$146,3, FALSE) -> La date de fin réelle de la position doit être antérieure ou égale à la date de décès de l'enfant. | BK23: POS_C_056 | BL23: =VLOOKUP(BK23,'Axe 2 Règles de gestion'!$D$2:$F$146,3, FALSE) -> La date de fin prévisionnelle de la position doit être antérieure ou égale à la date de décès de l'enfant. | BM23: POS_C_120 | BN23: =VLOOKUP(BM23,'Axe 2 Règles de gestion'!$D$2:$F$146,3, FALSE) -> La saisie d'une occurrence de congés/absences est interdite (date de fin réelle) | BO23: POS_C_121 | BP23: =VLOOKUP(BO23,'Axe 2 Règles de gestion'!$D$2:$F$146,3, FALSE) -> La saisie d'une occurrence de congés/absences est interdite (date de fin prévisionnelle)
