Workbook

Sheet Mode opératoire
B1: MODE OPERATOIRE
B2: La description d'une position entrante dans un dossier agent, nécessite la MAJ des données portées par les 2 sous-rubriques suivantes : Position statutaire/situation administrative et Détachement, affectation ou MAD entrant. La spécification métier regroupe au sein d'un évènement unique l'articulation des RG mobilisant des données appartenant à ces deux sous-rubriques. Ainsi, le métier considère que les données associées à ces deux sous rubriques sont mises à jour dans la même transaction. Les positions concernées sont les codes de positions mobilisés dans l'axe1.

Sheet Axe 1 Enchainement des RG
A1: Version | B1: Type de mise à jour | C1: Date de mise à jour | D1: Identifiant Domaine | E1: Libellé du Domaine | F1: Identifiant Sous-domaine | G1: Libellé du Sous-domaine | H1: Identifiant Evénement | I1: Libellé de l'évènement | J1: Libellé condition déclenchement Evènement | K1: Condition déclenchement Evènement | L1: Identifiant type d'évènement | M1: Libellé type d'évènement | N1: Type de mise à jour | O1: Libellé condition déclenchement Type Evènement | P1: Condition déclenchement Type Evènement | Q1: Libellé Population | R1: Codification Population | S1: Général / Particulier | T1: Passant / Exclu | U1: Date de début | V1: Date de fin | W1: Règles mobilisées | X1: Identifiant Règle de contrôle intellectuel 1 | Y1: Libellé Règle de contrôle intellectuel 1 | Z1: Identifiant Règle de contrôle intellectuel 2 | AA1: Libellé Règle de contrôle intellectuel 2 | AB1: Identifiant Règle de contrôle intellectuel 3 | AC1: Libellé Règle de contrôle intellectuel 3 | AD1: Identifiant Règle de contrôle intellectuel 4 | AE1: Libellé Règle de contrôle intellectuel 4 | AF1: Identifiant Règle de contrôle intellectuel 5 | AG1: Libellé Règle de contrôle intellectuel 5 | AH1: Identifiant Règle de contrôle intellectuel 6 | AI1: Libellé Règle de contrôle intellectuel 6 | AJ1: Identifiant Règle de contrôle intellectuel 7 | AK1: Libellé Règle de contrôle intellectuel 7 | AL1: Identifiant Règle de contrôle intellectuel 8 | AM1: Libellé Règle de contrôle intellectuel 8 | AN1: Identifiant Règle de contrôle intellectuel 9 | AO1: Libellé Règle de contrôle intellectuel 9 | AP1: Identifiant Règle de condition 1 | AQ1: Libellé Règle de condition 1 | AR1: Identifiant Règle de condition 2 | AS1: Libellé Règle de condition 2 | AT1: Identifiant Règle de condition 3 | AU1: Libellé Règle de condition 3 | AV1: Identifiant Règle de condition 4 | AW1: Libellé Règle de condition 4 | AX1: Identifiant Règle de condition 5 | AY1: Libellé Règle de condition 5 | AZ1: Identifiant Règle de condition 6 | BA1: Libellé Règle de condition 6 | BB1: Identifiant Règle de contrôle 1 | BC1: Libellé Règle de contrôle 1 | BD1: Identifiant Règle de contrôle 2 | BE1: Libellé Règle de contrôle 2 | BF1: Identifiant Règle de contrôle 3 | BG1: Libellé Règle de contrôle 3 | BH1: Identifiant Règle de contrôle 4 | BI1: Libellé Règle de contrôle 4 | BJ1: Identifiant Règle de contrôle 5 | BK1: Libellé Règle de contrôle 5 | BL1: Identifiant Règle de contrôle 6 | BM1: Libellé Règle de contrôle 6 | BN1: Identifiant Règle de contrôle 7 | BO1: Libellé Règle de contrôle 7 | BP1: Identifiant Règle de contrôle 8 | BQ1: Libellé Règle de contrôle 8 | BR1: Identifiant Règle de contrôle 9 | BS1: Libellé Règle de contrôle 9 | BT1: Identifiant Règle de contrôle 10 | BU1: Libellé Règle de contrôle 10 | BV1: Identifiant Règle de contrôle 11 | BW1: Libellé Règle de contrôle 11 | BX1: Identifiant Règle de contrôle 12 | BY1: Libellé Règle de contrôle 12 | BZ1: Identifiant Règle de contrôle 13 | CA1: Libellé Règle de contrôle 13 | CB1: Identifiant Règle de contrôle 14 | CC1: Libellé Règle de contrôle 14 | CD1: Identifiant Règle de contrôle 15 | CE1: Libellé Règle de contrôle 15 | CF1: FIME | CG1: Statut de travail
A2: 20.00.00 | B2: M | C2: 43850.552 | D2: D0004 | E2: Position | F2: S0009 | G2: Détachement entrant/sortant | H2: E0136 | I2: Détachement entrant sur demande auprès d'une administration, d'un office ou d'un EP de l'Etat conduisant à pension | J2: Position administrative Saisie égale à 'Détachement entrant sur demande auprès d'une administration ou d'un EP de l'Etat conduisant à pension' ET Indicateur de maintien saisi = Non | K2: A_POS_POSIAD [Saisi] = 'DEE01' ET A_POS_SITPAR [Saisi] = Vide ET A_POS_INDMAI [Saisi] = '0' | L2: T0390 | M2: Détachement entrant sur demande auprès d'une administration, d'un office ou d'un EP de l'Etat conduisant à pension - Demande | N2: Création Modification | O2: Indicateur de renouvellement saisi = Non ET (Indicateur de renouvellement saisi différent d'Indicateur de renouvellement avant saisi OU Indicateur de maintien saisi différent de Indicateur de maintien avant saisi) | P2: A_POS_INDREN [Saisi] = '0' ET (A_POS_INDREN [Saisi] <> A_POS_INDREN [Valeur avant saisie] OU A_POS_INDMAI [Saisi] <> A_POS_INDMAI [Valeur avant saisie]) | Q2: Titulaire ou magistrat | R2: P0001 | S2: Général | T2: Passant | U2: 40725 | V2: 43830 | W2: DEE_I_002 ET DEE_I_003 ET DEE_I_006 ET DEE_I_004 ET DEE_D_010 ET DEE_D_410 ET DEE_D_520 ET DEE_D_920 ET DEE_D_011 ET DEE_D_411 ET POS_C_004 ET POS_C_005 ET POS_C_007 ET POS_C_010 ET POS_C_012 ET POS_C_013 ET POS_C_022 ET POS_C_030 ET POS_C_031 ET POS_C_034 ET POS_C_035 ET POS_C_036 ET POS_C_111 | X2: DEE_I_002 | Y2: =VLOOKUP(X2,'Axe 2 Règles de gestion'!$D$2:$F$121,3, FALSE) -> L'agent doit détenir le titre ou le diplôme requis pour l'exercice des fonctions du corps d'accueil. | Z2: DEE_I_003 | AA2: =VLOOKUP(Z2,'Axe 2 Règles de gestion'!$D$2:$F$121,3, FALSE) -> L'agent doit formuler une demande. | AB2: DEE_I_006 | AC2: =VLOOKUP(AB2,'Axe 2 Règles de gestion'!$D$2:$F$121,3, FALSE) -> Le détachement est accordé après avis des commissions administratives paritaires compétentes. | AD2: DEE_I_004 | AE2: =VLOOKUP(AD2,'Axe 2 Règles de gestion'!$D$2:$F$121,3, FALSE) -> L'accord de l'administration d'origine est nécessaire. | AP2: DEE_D_010 | AQ2: =VLOOKUP(AP2,'Axe 2 Règles de gestion'!$D$2:$F$121,3, FALSE) -> Un détachement de courte durée à l'étranger ou dans les TOM ne peut excéder 1 an entre la date de début et la date de fin prévisionnelle. | AR2: DEE_D_410 | AS2: =VLOOKUP(AR2,'Axe 2 Règles de gestion'!$D$2:$F$121,3, FALSE) -> Un détachement de courte durée à l'étranger ou dans les TOM ne peut excéder 1 an entre la date de début et la date de fin réelle. | AT2: DEE_D_520 | AU2: =VLOOKUP(AT2,'Axe 2 Règles de gestion'!$D$2:$F$121,3, FALSE) -> Un détachement de courte durée n'ayant pas lieu à l'étranger ou dans les TOM ne peut excéder six mois entre la date de début et la date de fin prévisionnelle. | AV2: DEE_D_920 | AW2: =VLOOKUP(AV2,'Axe 2 Règles de gestion'!$D$2:$F$121,3, FALSE) -> Un détachement de courte durée n'ayant pas lieu à l'étranger ou dans les TOM ne peut excéder six mois entre la date de début et la date de fin réelle. | AX2: DEE_D_011 | AY2: =VLOOKUP(AX2,'Axe 2 Règles de gestion'!$D$2:$F$121,3, FALSE) -> Un détachement de longue durée ne peut excéder 5 ans entre la date de début et la date de fin prévisionnelle. | AZ2: DEE_D_411 | BA2: =VLOOKUP(AZ2,'Axe 2 Règles de gestion'!$D$2:$F$121,3, FALSE) -> Un détachement de longue durée ne peut excéder 5 ans entre la date de début et la date de fin réelle. | BB2: POS_C_004 | BC2: =VLOOKUP(BB2,'Axe 2 Règles de gestion'!$D$2:$F$121,3, FALSE) -> La date de début de position doit être antérieure ou égale à la date de fin prévisionnelle de position. | BD2: POS_C_005 | BE2: =VLOOKUP(BD2,'Axe 2 Règles de gestion'!$D$2:$F$121,3, FALSE) -> La date de début de la position doit être postérieure ou égale à la date d'entrée dans la FPE ou dans la carrière militaire. | BF2: POS_C_007 | BG2: =VLOOKUP(BF2,'Axe 2 Règles de gestion'!$D$2:$F$121,3, FALSE) -> La date de fin réelle de la position doit être antérieure à la date limite de départ à la retraite. | BH2: POS_C_010 | BI2: =VLOOKUP(BH2,'Axe 2 Règles de gestion'!$D$2:$F$121,3, FALSE) -> La date de début de position doit être antérieure ou égale à la date de fin réelle de position. | BJ2: POS_C_012 | BK2: =VLOOKUP(BJ2,'Axe 2 Règles de gestion'!$D$2:$F$121,3, FALSE) -> La date de fin prévisionnelle de la position doit être antérieure à la date limite de départ à la retraite. | BL2: POS_C_013 | BM2: =VLOOKUP(BL2,'Axe 2 Règles de gestion'!$D$2:$F$121,3, FALSE) -> L'indicateur de carrière est sur la valeur "Accueil". | BN2: POS_C_022 | BO2: =VLOOKUP(BN2,'Axe 2 Règles de gestion'!$D$2:$F$121,3, FALSE) -> La date de début de position est à J+1 de la date de fin de position de l'occurrence précédente. | BP2: POS_C_030 | BQ2: =VLOOKUP(BP2,'Axe 2 Règles de gestion'!$D$2:$F$121,3, FALSE) -> Les champs "Type d'organisme d'origine", "Catégorie statutaire d'origine" et "Pays" de l'organisme d'origine doivent être renseignés. | BR2: POS_C_031 | BS2: =VLOOKUP(BR2,'Axe 2 Règles de gestion'!$D$2:$F$121,3, FALSE) -> Les champs "Ministère (ou institution de la République) d'origine", "Corps d'origine", "Grade d'origine", "Echelon d'origine" sont renseignés si le "Type d'organisme d'origine" est valorisé à FPE. | BT2: POS_C_034 | BU2: =VLOOKUP(BT2,'Axe 2 Règles de gestion'!$D$2:$F$121,3, FALSE) -> Le champ "Organisme d'origine" doit être alimenté si le type d'organisme d'origine est égal à 'Autre organisme', 'Fonction publique d'un état de l'Union Européenne' ou 'Fonction publique Européenne'. | BV2: POS_C_035 | BW2: =VLOOKUP(BV2,'Axe 2 Règles de gestion'!$D$2:$F$121,3, FALSE) -> Le champ "Code emploi statutaire FPT (NET)" est renseigné si le "Type d'organisme d'origine" est valorisé à FPT. | BX2: POS_C_036 | BY2: =VLOOKUP(BX2,'Axe 2 Règles de gestion'!$D$2:$F$121,3, FALSE) -> Le champ "Code emploi statutaire FPH (NEH)" est renseigné si le "Type d'organisme d'origine" est valorisé à FPH. | BZ2: POS_C_111 | CA2: =VLOOKUP(BZ2,'Axe 2 Règles de gestion'!$D$2:$F$121,3, FALSE) -> La date de fin ou la date de fin prévisionnelle doit être saisie.
A3: 25.00.00 | B3: A | C3: 45807.449 | D3: D0004 | E3: Position | F3: S0009 | G3: Détachement entrant/sortant | H3: E0136 | I3: Détachement entrant sur demande auprès d'une administration, d'un office ou d'un EP de l'Etat conduisant à pension | J3: Position administrative Saisie égale à 'Détachement entrant sur demande auprès d'une administration ou d'un EP de l'Etat conduisant à pension' ET Indicateur de maintien saisi = Non | K3: A_POS_POSIAD [Saisi] = 'DEE01' ET A_POS_SITPAR [Saisi] = Vide ET A_POS_INDMAI [Saisi] = '0' | L3: T0390 | M3: Détachement entrant sur demande auprès d'une administration, d'un office ou d'un EP de l'Etat conduisant à pension - Demande | N3: Création Modification | O3: Indicateur de renouvellement saisi = Non ET (Indicateur de renouvellement saisi différent d'Indicateur de renouvellement avant saisi OU Indicateur de maintien saisi différent de Indicateur de maintien avant saisi) | P3: A_POS_INDREN [Saisi] = '0' ET (A_POS_INDREN [Saisi] <> A_POS_INDREN [Valeur avant saisie] OU A_POS_INDMAI [Saisi] <> A_POS_INDMAI [Valeur avant saisie]) | Q3: Titulaire ou magistrat | R3: P0001 | S3: Général | T3: Passant | U3: 43831 | W3: DEE_I_002 ET DEE_I_003 ET DEE_I_004 ET DEE_I_046 ET DEE_I_047 ET DEE_I_048 ET DEE_I_100 ET DEE_I_101 ET DEE_I_102 ET DEE_D_010 ET DEE_D_410 ET DEE_D_520 ET DEE_D_920 ET DEE_D_011 ET DEE_D_411 ET POS_C_004 ET POS_C_005 ET POS_C_007 ET POS_C_010 ET POS_C_012 ET POS_C_013 ET POS_C_022 ET POS_C_030 ET POS_C_031 ET POS_C_034 ET POS_C_035 ET POS_C_036 ET POS_C_111 | X3: DEE_I_002 | Y3: =VLOOKUP(X3,'Axe 2 Règles de gestion'!$D$2:$F$121,3, FALSE) -> L'agent doit détenir le titre ou le diplôme requis pour l'exercice des fonctions du corps d'accueil. | Z3: DEE_I_003 | AA3: =VLOOKUP(Z3,'Axe 2 Règles de gestion'!$D$2:$F$121,3, FALSE) -> L'agent doit formuler une demande. | AB3: DEE_I_004 | AC3: =VLOOKUP(AB3,'Axe 2 Règles de gestion'!$D$2:$F$121,3, FALSE) -> L'accord de l'administration d'origine est nécessaire. | AD3: DEE_I_046 | AE3: =VLOOKUP(AD3,'Axe 2 Règles de gestion'!$D$2:$F$121,3, FALSE) -> Le détachement sur un emploi de direction comporte une période probatoire d'une durée maximale de 6 mois. | AF3: DEE_I_047 | AG3: =VLOOKUP(AF3,'Axe 2 Règles de gestion'!$D$2:$F$121,3, FALSE) -> Au cours de la période probatoire, l'autorité de recrutement, sur proposition de l'autorité dont relève l'emploi de direction, peut mettre fin au détachement pour tout motif et à tout moment, sans préavis ni indemnité. | AH3: DEE_I_048 | AI3: =VLOOKUP(AH3,'Axe 2 Règles de gestion'!$D$2:$F$121,3, FALSE) -> Cette décision de fin du détachement pendant la période probatoire ne peut intervenir qu'à l'issue d'un entretien préalable et doit être notifiée à l'agent sur emploi de direction. | AJ3: DEE_I_100 | AK3: =VLOOKUP(AJ3,'Axe 2 Règles de gestion'!$D$2:$F$121,3, FALSE) -> L'agent peut être détaché dans un corps ou un cadre d'emplois de même catégorie et de niveau comparable à celui de son corps ou cadre d'emplois d'origine. | AL3: DEE_I_101 | AM3: =VLOOKUP(AL3,'Axe 2 Règles de gestion'!$D$2:$F$121,3, FALSE) -> Toutefois, l'agent dont au moins l'un des grades d'avancement de son corps ou cadre d'emplois est accessible par la voie d'un concours de recrutement peut être détaché dans un corps ou cadre d'emplois de niveau différent. | AN3: DEE_I_102 | AO3: =VLOOKUP(AN3,'Axe 2 Règles de gestion'!$D$2:$F$121,3, FALSE) -> Lorsque le corps ou cadre d'emplois d'origine ou le corps ou cadre d'emplois d'accueil ne relève pas d'une catégorie, le détachement s'effectue entre corps et cadres d'emplois de niveau comparable. | AP3: DEE_D_010 | AQ3: =VLOOKUP(AP3,'Axe 2 Règles de gestion'!$D$2:$F$121,3, FALSE) -> Un détachement de courte durée à l'étranger ou dans les TOM ne peut excéder 1 an entre la date de début et la date de fin prévisionnelle. | AR3: DEE_D_410 | AS3: =VLOOKUP(AR3,'Axe 2 Règles de gestion'!$D$2:$F$121,3, FALSE) -> Un détachement de courte durée à l'étranger ou dans les TOM ne peut excéder 1 an entre la date de début et la date de fin réelle. | AT3: DEE_D_520 | AU3: =VLOOKUP(AT3,'Axe 2 Règles de gestion'!$D$2:$F$121,3, FALSE) -> Un détachement de courte durée n'ayant pas lieu à l'étranger ou dans les TOM ne peut excéder six mois entre la date de début et la date de fin prévisionnelle. | AV3: DEE_D_920 | AW3: =VLOOKUP(AV3,'Axe 2 Règles de gestion'!$D$2:$F$121,3, FALSE) -> Un détachement de courte durée n'ayant pas lieu à l'étranger ou dans les TOM ne peut excéder six mois entre la date de début et la date de fin réelle. | AX3: DEE_D_011 | AY3: =VLOOKUP(AX3,'Axe 2 Règles de gestion'!$D$2:$F$121,3, FALSE) -> Un détachement de longue durée ne peut excéder 5 ans entre la date de début et la date de fin prévisionnelle. | AZ3: DEE_D_411 | BA3: =VLOOKUP(AZ3,'Axe 2 Règles de gestion'!$D$2:$F$121,3, FALSE) -> Un détachement de longue durée ne peut excéder 5 ans entre la date de début et la date de fin réelle. | BB3: POS_C_004 | BC3: =VLOOKUP(BB3,'Axe 2 Règles de gestion'!$D$2:$F$121,3, FALSE) -> La date de début de position doit être antérieure ou égale à la date de fin prévisionnelle de position. | BD3: POS_C_005 | BE3: =VLOOKUP(BD3,'Axe 2 Règles de gestion'!$D$2:$F$121,3, FALSE) -> La date de début de la position doit être postérieure ou égale à la date d'entrée dans la FPE ou dans la carrière militaire. | BF3: POS_C_007 | BG3: =VLOOKUP(BF3,'Axe 2 Règles de gestion'!$D$2:$F$121,3, FALSE) -> La date de fin réelle de la position doit être antérieure à la date limite de départ à la retraite. | BH3: POS_C_010 | BI3: =VLOOKUP(BH3,'Axe 2 Règles de gestion'!$D$2:$F$121,3, FALSE) -> La date de début de position doit être antérieure ou égale à la date de fin réelle de position. | BJ3: POS_C_012 | BK3: =VLOOKUP(BJ3,'Axe 2 Règles de gestion'!$D$2:$F$121,3, FALSE) -> La date de fin prévisionnelle de la position doit être antérieure à la date limite de départ à la retraite. | BL3: POS_C_013 | BM3: =VLOOKUP(BL3,'Axe 2 Règles de gestion'!$D$2:$F$121,3, FALSE) -> L'indicateur de carrière est sur la valeur "Accueil". | BN3: POS_C_022 | BO3: =VLOOKUP(BN3,'Axe 2 Règles de gestion'!$D$2:$F$121,3, FALSE) -> La date de début de position est à J+1 de la date de fin de position de l'occurrence précédente. | BP3: POS_C_030 | BQ3: =VLOOKUP(BP3,'Axe 2 Règles de gestion'!$D$2:$F$121,3, FALSE) -> Les champs "Type d'organisme d'origine", "Catégorie statutaire d'origine" et "Pays" de l'organisme d'origine doivent être renseignés. | BR3: POS_C_031 | BS3: =VLOOKUP(BR3,'Axe 2 Règles de gestion'!$D$2:$F$121,3, FALSE) -> Les champs "Ministère (ou institution de la République) d'origine", "Corps d'origine", "Grade d'origine", "Echelon d'origine" sont renseignés si le "Type d'organisme d'origine" est valorisé à FPE. | BT3: POS_C_034 | BU3: =VLOOKUP(BT3,'Axe 2 Règles de gestion'!$D$2:$F$121,3, FALSE) -> Le champ "Organisme d'origine" doit être alimenté si le type d'organisme d'origine est égal à 'Autre organisme', 'Fonction publique d'un état de l'Union Européenne' ou 'Fonction publique Européenne'. | BV3: POS_C_035 | BW3: =VLOOKUP(BV3,'Axe 2 Règles de gestion'!$D$2:$F$121,3, FALSE) -> Le champ "Code emploi statutaire FPT (NET)" est renseigné si le "Type d'organisme d'origine" est valorisé à FPT. | BX3: POS_C_036 | BY3: =VLOOKUP(BX3,'Axe 2 Règles de gestion'!$D$2:$F$121,3, FALSE) -> Le champ "Code emploi statutaire FPH (NEH)" est renseigné si le "Type d'organisme d'origine" est valorisé à FPH. | BZ3: POS_C_111 | CA3: =VLOOKUP(BZ3,'Axe 2 Règles de gestion'!$D$2:$F$121,3, FALSE) -> La date de fin ou la date de fin prévisionnelle doit être saisie.
A4: 20.10.00 | B4: M | C4: 44071.418 | D4: D0004 | E4: Position | F4: S0009 | G4: Détachement entrant/sortant | H4: E0136 | I4: Détachement entrant sur demande auprès d'une administration, d'un office ou d'un EP de l'Etat conduisant à pension | J4: Position administrative Saisie égale à 'Détachement entrant sur demande auprès d'une administration ou d'un EP de l'Etat conduisant à pension' ET Indicateur de maintien saisi = Non | K4: A_POS_POSIAD [Saisi] = 'DEE01' ET A_POS_SITPAR [Saisi] = Vide ET A_POS_INDMAI [Saisi] = '0' | L4: T0391 | M4: Détachement entrant sur demande auprès d'une administration, d'un office ou d'un EP de l'Etat conduisant à pension - Renouvellement | N4: Création Modification | O4: Indicateur de renouvellement saisi = Oui ET (Indicateur de renouvellement saisi différent d'Indicateur de renouvellement avant saisi OU Indicateur de maintien saisi différent de Indicateur de maintien avant saisi) | P4: A_POS_INDREN [Saisi] = '1' ET (A_POS_INDREN [Saisi] <> A_POS_INDREN [Valeur avant saisie] OU A_POS_INDMAI [Saisi] <> A_POS_INDMAI [Valeur avant saisie]) | Q4: Titulaire ou magistrat | R4: P0001 | S4: Général | T4: Passant | U4: 40725 | V4: 43830 | W4: DEE_I_011 ET DEE_I_012 ET DEE_D_011 ET DEE_D_411 ET DEE_D_030 ET POS_C_004 ET POS_C_005 ET POS_C_007 ET POS_C_010 ET POS_C_012 ET POS_C_013 ET POS_C_022 ET POS_C_030 ET POS_C_031 ET POS_C_034 ET POS_C_035 ET POS_C_036 ET POS_C_111 | X4: DEE_I_011 | Y4: =VLOOKUP(X4,'Axe 2 Règles de gestion'!$D$2:$F$121,3, FALSE) -> L'agent doit formuler une demande de renouvellement à son administration d'origine 3 mois au moins avant l'expiration de la période de détachement de longue durée. | Z4: DEE_I_012 | AA4: =VLOOKUP(Z4,'Axe 2 Règles de gestion'!$D$2:$F$121,3, FALSE) -> L'organisme d'accueil adresse sa décision à l'agent et à l'administration d'origine 2 mois au moins avant l'expiration de la période de détachement. | AP4: DEE_D_011 | AQ4: =VLOOKUP(AP4,'Axe 2 Règles de gestion'!$D$2:$F$121,3, FALSE) -> Un détachement de longue durée ne peut excéder 5 ans entre la date de début et la date de fin prévisionnelle. | AR4: DEE_D_411 | AS4: =VLOOKUP(AR4,'Axe 2 Règles de gestion'!$D$2:$F$121,3, FALSE) -> Un détachement de longue durée ne peut excéder 5 ans entre la date de début et la date de fin réelle. | AT4: DEE_D_030 | AU4: =VLOOKUP(AT4,'Axe 2 Règles de gestion'!$D$2:$F$121,3, FALSE) -> Le renouvellement d'un détachement de courte durée est interdit. | BB4: POS_C_004 | BC4: =VLOOKUP(BB4,'Axe 2 Règles de gestion'!$D$2:$F$121,3, FALSE) -> La date de début de position doit être antérieure ou égale à la date de fin prévisionnelle de position. | BD4: POS_C_005 | BE4: =VLOOKUP(BD4,'Axe 2 Règles de gestion'!$D$2:$F$121,3, FALSE) -> La date de début de la position doit être postérieure ou égale à la date d'entrée dans la FPE ou dans la carrière militaire. | BF4: POS_C_007 | BG4: =VLOOKUP(BF4,'Axe 2 Règles de gestion'!$D$2:$F$121,3, FALSE) -> La date de fin réelle de la position doit être antérieure à la date limite de départ à la retraite. | BH4: POS_C_010 | BI4: =VLOOKUP(BH4,'Axe 2 Règles de gestion'!$D$2:$F$121,3, FALSE) -> La date de début de position doit être antérieure ou égale à la date de fin réelle de position. | BJ4: POS_C_012 | BK4: =VLOOKUP(BJ4,'Axe 2 Règles de gestion'!$D$2:$F$121,3, FALSE) -> La date de fin prévisionnelle de la position doit être antérieure à la date limite de départ à la retraite. | BL4: POS_C_013 | BM4: =VLOOKUP(BL4,'Axe 2 Règles de gestion'!$D$2:$F$121,3, FALSE) -> L'indicateur de carrière est sur la valeur "Accueil". | BN4: POS_C_022 | BO4: =VLOOKUP(BN4,'Axe 2 Règles de gestion'!$D$2:$F$121,3, FALSE) -> La date de début de position est à J+1 de la date de fin de position de l'occurrence précédente. | BP4: POS_C_030 | BQ4: =VLOOKUP(BP4,'Axe 2 Règles de gestion'!$D$2:$F$121,3, FALSE) -> Les champs "Type d'organisme d'origine", "Catégorie statutaire d'origine" et "Pays" de l'organisme d'origine doivent être renseignés. | BR4: POS_C_031 | BS4: =VLOOKUP(BR4,'Axe 2 Règles de gestion'!$D$2:$F$121,3, FALSE) -> Les champs "Ministère (ou institution de la République) d'origine", "Corps d'origine", "Grade d'origine", "Echelon d'origine" sont renseignés si le "Type d'organisme d'origine" est valorisé à FPE. | BT4: POS_C_034 | BU4: =VLOOKUP(BT4,'Axe 2 Règles de gestion'!$D$2:$F$121,3, FALSE) -> Le champ "Organisme d'origine" doit être alimenté si le type d'organisme d'origine est égal à 'Autre organisme', 'Fonction publique d'un état de l'Union Européenne' ou 'Fonction publique Européenne'. | BV4: POS_C_035 | BW4: =VLOOKUP(BV4,'Axe 2 Règles de gestion'!$D$2:$F$121,3, FALSE) -> Le champ "Code emploi statutaire FPT (NET)" est renseigné si le "Type d'organisme d'origine" est valorisé à FPT. | BX4: POS_C_036 | BY4: =VLOOKUP(BX4,'Axe 2 Règles de gestion'!$D$2:$F$121,3, FALSE) -> Le champ "Code emploi statutaire FPH (NEH)" est renseigné si le "Type d'organisme d'origine" est valorisé à FPH. | BZ4: POS_C_111 | CA4: =VLOOKUP(BZ4,'Axe 2 Règles de gestion'!$D$2:$F$121,3, FALSE) -> La date de fin ou la date de fin prévisionnelle doit être saisie.
A5: 20.10.00 | B5: A | C5: 44071.422 | D5: D0004 | E5: Position | F5: S0009 | G5: Détachement entrant/sortant | H5: E0136 | I5: Détachement entrant sur demande auprès d'une administration, d'un office ou d'un EP de l'Etat conduisant à pension | J5: Position administrative Saisie égale à 'Détachement entrant sur demande auprès d'une administration ou d'un EP de l'Etat conduisant à pension' ET Indicateur de maintien saisi = Non | K5: A_POS_POSIAD [Saisi] = 'DEE01' ET A_POS_SITPAR [Saisi] = Vide ET A_POS_INDMAI [Saisi] = '0' | L5: T0391 | M5: Détachement entrant sur demande auprès d'une administration, d'un office ou d'un EP de l'Etat conduisant à pension - Renouvellement | N5: Création Modification | O5: Indicateur de renouvellement saisi = Oui ET (Indicateur de renouvellement saisi différent d'Indicateur de renouvellement avant saisi OU Indicateur de maintien saisi différent de Indicateur de maintien avant saisi) | P5: A_POS_INDREN [Saisi] = '1' ET (A_POS_INDREN [Saisi] <> A_POS_INDREN [Valeur avant saisie] OU A_POS_INDMAI [Saisi] <> A_POS_INDMAI [Valeur avant saisie]) | Q5: Titulaire ou magistrat | R5: P0001 | S5: Général | T5: Passant | U5: 43831 | W5: DEE_I_011 ET DEE_I_012 ET DEE_I_044 ET DEE_I_045 ET DEE_I_049 ET DEE_D_011 ET DEE_D_411 ET DEE_D_030 ET POS_C_004 ET POS_C_005 ET POS_C_007 ET POS_C_010 ET POS_C_012 ET POS_C_013 ET POS_C_022 ET POS_C_030 ET POS_C_031 ET POS_C_034 ET POS_C_035 ET POS_C_036 ET POS_C_111 | X5: DEE_I_011 | Y5: =VLOOKUP(X5,'Axe 2 Règles de gestion'!$D$2:$F$121,3, FALSE) -> L'agent doit formuler une demande de renouvellement à son administration d'origine 3 mois au moins avant l'expiration de la période de détachement de longue durée. | Z5: DEE_I_012 | AA5: =VLOOKUP(Z5,'Axe 2 Règles de gestion'!$D$2:$F$121,3, FALSE) -> L'organisme d'accueil adresse sa décision à l'agent et à l'administration d'origine 2 mois au moins avant l'expiration de la période de détachement. | AB5: DEE_I_044 | AC5: =VLOOKUP(AB5,'Axe 2 Règles de gestion'!$D$2:$F$121,3, FALSE) -> L'agent peut demander à être reconduit dans ses fonctions 3 mois au moins avant le terme de son détachement sur un emploi de direction. | AD5: DEE_I_045 | AE5: =VLOOKUP(AD5,'Axe 2 Règles de gestion'!$D$2:$F$121,3, FALSE) -> Au moins 2 mois avant le terme de son détachement, l'autorité dont relève l'emploi de direction notifie la décision à l'agent. | AF5: DEE_I_049 | AG5: =VLOOKUP(AF5,'Axe 2 Règles de gestion'!$D$2:$F$121,3, FALSE) -> La période probatoire ne s'applique pas en cas de reconduction de l'agent dans le même emploi de direction. | AP5: DEE_D_011 | AQ5: =VLOOKUP(AP5,'Axe 2 Règles de gestion'!$D$2:$F$121,3, FALSE) -> Un détachement de longue durée ne peut excéder 5 ans entre la date de début et la date de fin prévisionnelle. | AR5: DEE_D_411 | AS5: =VLOOKUP(AR5,'Axe 2 Règles de gestion'!$D$2:$F$121,3, FALSE) -> Un détachement de longue durée ne peut excéder 5 ans entre la date de début et la date de fin réelle. | AT5: DEE_D_030 | AU5: =VLOOKUP(AT5,'Axe 2 Règles de gestion'!$D$2:$F$121,3, FALSE) -> Le renouvellement d'un détachement de courte durée est interdit. | BB5: POS_C_004 | BC5: =VLOOKUP(BB5,'Axe 2 Règles de gestion'!$D$2:$F$121,3, FALSE) -> La date de début de position doit être antérieure ou égale à la date de fin prévisionnelle de position. | BD5: POS_C_005 | BE5: =VLOOKUP(BD5,'Axe 2 Règles de gestion'!$D$2:$F$121,3, FALSE) -> La date de début de la position doit être postérieure ou égale à la date d'entrée dans la FPE ou dans la carrière militaire. | BF5: POS_C_007 | BG5: =VLOOKUP(BF5,'Axe 2 Règles de gestion'!$D$2:$F$121,3, FALSE) -> La date de fin réelle de la position doit être antérieure à la date limite de départ à la retraite. | BH5: POS_C_010 | BI5: =VLOOKUP(BH5,'Axe 2 Règles de gestion'!$D$2:$F$121,3, FALSE) -> La date de début de position doit être antérieure ou égale à la date de fin réelle de position. | BJ5: POS_C_012 | BK5: =VLOOKUP(BJ5,'Axe 2 Règles de gestion'!$D$2:$F$121,3, FALSE) -> La date de fin prévisionnelle de la position doit être antérieure à la date limite de départ à la retraite. | BL5: POS_C_013 | BM5: =VLOOKUP(BL5,'Axe 2 Règles de gestion'!$D$2:$F$121,3, FALSE) -> L'indicateur de carrière est sur la valeur "Accueil". | BN5: POS_C_022 | BO5: =VLOOKUP(BN5,'Axe 2 Règles de gestion'!$D$2:$F$121,3, FALSE) -> La date de début de position est à J+1 de la date de fin de position de l'occurrence précédente. | BP5: POS_C_030 | BQ5: =VLOOKUP(BP5,'Axe 2 Règles de gestion'!$D$2:$F$121,3, FALSE) -> Les champs "Type d'organisme d'origine", "Catégorie statutaire d'origine" et "Pays" de l'organisme d'origine doivent être renseignés. | BR5: POS_C_031 | BS5: =VLOOKUP(BR5,'Axe 2 Règles de gestion'!$D$2:$F$121,3, FALSE) -> Les champs "Ministère (ou institution de la République) d'origine", "Corps d'origine", "Grade d'origine", "Echelon d'origine" sont renseignés si le "Type d'organisme d'origine" est valorisé à FPE. | BT5: POS_C_034 | BU5: =VLOOKUP(BT5,'Axe 2 Règles de gestion'!$D$2:$F$121,3, FALSE) -> Le champ "Organisme d'origine" doit être alimenté si le type d'organisme d'origine est égal à 'Autre organisme', 'Fonction publique d'un état de l'Union Européenne' ou 'Fonction publique Européenne'. | BV5: POS_C_035 | BW5: =VLOOKUP(BV5,'Axe 2 Règles de gestion'!$D$2:$F$121,3, FALSE) -> Le champ "Code emploi statutaire FPT (NET)" est renseigné si le "Type d'organisme d'origine" est valorisé à FPT. | BX5: POS_C_036 | BY5: =VLOOKUP(BX5,'Axe 2 Règles de gestion'!$D$2:$F$121,3, FALSE) -> Le champ "Code emploi statutaire FPH (NEH)" est renseigné si le "Type d'organisme d'origine" est valorisé à FPH. | BZ5: POS_C_111 | CA5: =VLOOKUP(BZ5,'Axe 2 Règles de gestion'!$D$2:$F$121,3, FALSE) -> La date de fin ou la date de fin prévisionnelle doit être saisie.
A6: 20.00.00 | B6: M | C6: 43850.552 | D6: D0004 | E6: Position | F6: S0009 | G6: Détachement entrant/sortant | H6: E0136 | I6: Détachement entrant sur demande auprès d'une administration, d'un office ou d'un EP de l'Etat conduisant à pension | J6: Position administrative Saisie égale à 'Détachement entrant sur demande auprès d'une administration ou d'un EP de l'Etat conduisant à pension' ET Indicateur de maintien saisi = Non | K6: A_POS_POSIAD [Saisi] = 'DEE01' ET A_POS_SITPAR [Saisi] = Vide ET A_POS_INDMAI [Saisi] = '0' | L6: T0392 | M6: Détachement entrant sur demande auprès d'une administration, d'un office ou d'un EP de l'Etat conduisant à pension - Réintégration | N6: Modification | O6: Indicateur de renouvellement saisi identique à Indicateur de renouvellement avant saisi ET Indicateur de maintien saisi identique à Indicateur de maintien avant saisi | P6: A_POS_INDREN [Saisi] = A_POS_INDREN [Valeur avant saisie] ET A_POS_INDMAI [Saisi] = A_POS_INDMAI [Valeur avant saisie] | Q6: Titulaire ou magistrat | R6: P0001 | S6: Général | T6: Passant | U6: 40725 | W6: DEE_I_018 ET DEE_I_026 ET DEE_I_016 ET DEE_I_012 ET DEE_I_017 ET DEE_I_037 ET DEE_D_010 ET DEE_D_410 ET DEE_D_520 ET DEE_D_920 ET DEE_D_011 ET DEE_D_411 ET POS_C_004 ET POS_C_007 ET POS_C_010 ET POS_C_012 ET POS_C_030 ET POS_C_031 ET POS_C_034 ET POS_C_035 ET POS_C_036 ET POS_C_111 | X6: DEE_I_018 | Y6: =VLOOKUP(X6,'Axe 2 Règles de gestion'!$D$2:$F$121,3, FALSE) -> Le détachement peut prendre fin de manière anticipée à l'initiative de l'administration d'accueil, de l'administration d'origine ou de l'agent. | Z6: DEE_I_026 | AA6: =VLOOKUP(Z6,'Axe 2 Règles de gestion'!$D$2:$F$121,3, FALSE) -> En cas de réintégration anticipée à l'initiative de l'organisme d'accueil, si l'administration d'origine ne peut pas réintégrer l'agent immédiatement, il reste en détachement jusqu'à ce qu'il soit réintégré à la première vacance. | AB6: DEE_I_016 | AC6: =VLOOKUP(AB6,'Axe 2 Règles de gestion'!$D$2:$F$121,3, FALSE) -> L'agent doit adresser une demande de réintégration à l'administration d'origine 3 mois au moins avant l'expiration de la période de détachement de longue durée. | AD6: DEE_I_012 | AE6: =VLOOKUP(AD6,'Axe 2 Règles de gestion'!$D$2:$F$121,3, FALSE) -> L'organisme d'accueil adresse sa décision à l'agent et à l'administration d'origine 2 mois au moins avant l'expiration de la période de détachement. | AF6: DEE_I_017 | AG6: =VLOOKUP(AF6,'Axe 2 Règles de gestion'!$D$2:$F$121,3, FALSE) -> Si l'agent n'adresse pas sa demande dans les délais, il est obligatoirement réintégré à la première vacance dans son corps d'origine et affecté à un emploi correspondant à son grade. | AH6: DEE_I_037 | AI6: =VLOOKUP(AH6,'Axe 2 Règles de gestion'!$D$2:$F$121,3, FALSE) -> Les dispositions relatives à la réintégration au terme d'un détachement de longue durée ne sont pas applicables aux préfets et sous-préfets. | AP6: DEE_D_010 | AQ6: =VLOOKUP(AP6,'Axe 2 Règles de gestion'!$D$2:$F$121,3, FALSE) -> Un détachement de courte durée à l'étranger ou dans les TOM ne peut excéder 1 an entre la date de début et la date de fin prévisionnelle. | AR6: DEE_D_410 | AS6: =VLOOKUP(AR6,'Axe 2 Règles de gestion'!$D$2:$F$121,3, FALSE) -> Un détachement de courte durée à l'étranger ou dans les TOM ne peut excéder 1 an entre la date de début et la date de fin réelle. | AT6: DEE_D_520 | AU6: =VLOOKUP(AT6,'Axe 2 Règles de gestion'!$D$2:$F$121,3, FALSE) -> Un détachement de courte durée n'ayant pas lieu à l'étranger ou dans les TOM ne peut excéder six mois entre la date de début et la date de fin prévisionnelle. | AV6: DEE_D_920 | AW6: =VLOOKUP(AV6,'Axe 2 Règles de gestion'!$D$2:$F$121,3, FALSE) -> Un détachement de courte durée n'ayant pas lieu à l'étranger ou dans les TOM ne peut excéder six mois entre la date de début et la date de fin réelle. | AX6: DEE_D_011 | AY6: =VLOOKUP(AX6,'Axe 2 Règles de gestion'!$D$2:$F$121,3, FALSE) -> Un détachement de longue durée ne peut excéder 5 ans entre la date de début et la date de fin prévisionnelle. | AZ6: DEE_D_411 | BA6: =VLOOKUP(AZ6,'Axe 2 Règles de gestion'!$D$2:$F$121,3, FALSE) -> Un détachement de longue durée ne peut excéder 5 ans entre la date de début et la date de fin réelle. | BB6: POS_C_004 | BC6: =VLOOKUP(BB6,'Axe 2 Règles de gestion'!$D$2:$F$121,3, FALSE) -> La date de début de position doit être antérieure ou égale à la date de fin prévisionnelle de position. | BD6: POS_C_007 | BE6: =VLOOKUP(BD6,'Axe 2 Règles de gestion'!$D$2:$F$121,3, FALSE) -> La date de fin réelle de la position doit être antérieure à la date limite de départ à la retraite. | BF6: POS_C_010 | BG6: =VLOOKUP(BF6,'Axe 2 Règles de gestion'!$D$2:$F$121,3, FALSE) -> La date de début de position doit être antérieure ou égale à la date de fin réelle de position. | BH6: POS_C_012 | BI6: =VLOOKUP(BH6,'Axe 2 Règles de gestion'!$D$2:$F$121,3, FALSE) -> La date de fin prévisionnelle de la position doit être antérieure à la date limite de départ à la retraite. | BJ6: POS_C_030 | BK6: =VLOOKUP(BJ6,'Axe 2 Règles de gestion'!$D$2:$F$121,3, FALSE) -> Les champs "Type d'organisme d'origine", "Catégorie statutaire d'origine" et "Pays" de l'organisme d'origine doivent être renseignés. | BL6: POS_C_031 | BM6: =VLOOKUP(BL6,'Axe 2 Règles de gestion'!$D$2:$F$121,3, FALSE) -> Les champs "Ministère (ou institution de la République) d'origine", "Corps d'origine", "Grade d'origine", "Echelon d'origine" sont renseignés si le "Type d'organisme d'origine" est valorisé à FPE. | BN6: POS_C_034 | BO6: =VLOOKUP(BN6,'Axe 2 Règles de gestion'!$D$2:$F$121,3, FALSE) -> Le champ "Organisme d'origine" doit être alimenté si le type d'organisme d'origine est égal à 'Autre organisme', 'Fonction publique d'un état de l'Union Européenne' ou 'Fonction publique Européenne'. | BP6: POS_C_035 | BQ6: =VLOOKUP(BP6,'Axe 2 Règles de gestion'!$D$2:$F$121,3, FALSE) -> Le champ "Code emploi statutaire FPT (NET)" est renseigné si le "Type d'organisme d'origine" est valorisé à FPT. | BR6: POS_C_036 | BS6: =VLOOKUP(BR6,'Axe 2 Règles de gestion'!$D$2:$F$121,3, FALSE) -> Le champ "Code emploi statutaire FPH (NEH)" est renseigné si le "Type d'organisme d'origine" est valorisé à FPH. | BT6: POS_C_111 | BU6: =VLOOKUP(BT6,'Axe 2 Règles de gestion'!$D$2:$F$121,3, FALSE) -> La date de fin ou la date de fin prévisionnelle doit être saisie.
A7: 17.10.00 | B7: A | C7: 43152.5 | D7: D0004 | E7: Position | F7: S0009 | G7: Détachement entrant/sortant | H7: E0136 | I7: Détachement entrant sur demande auprès d'une administration, d'un office ou d'un EP de l'Etat conduisant à pension | J7: Position administrative Saisie égale à 'Détachement entrant sur demande auprès d'une administration ou d'un EP de l'Etat conduisant à pension' ET Indicateur de maintien saisi = Non | K7: A_POS_POSIAD [Saisi] = 'DEE01' ET A_POS_SITPAR [Saisi] = Vide ET A_POS_INDMAI [Saisi] = '0' | L7: T0390 | M7: Détachement entrant sur demande auprès d'une administration, d'un office ou d'un EP de l'Etat conduisant à pension - Demande | N7: Création Modification | O7: Indicateur de renouvellement saisi = Non ET (Indicateur de renouvellement saisi différent d'Indicateur de renouvellement avant saisi OU Indicateur de maintien saisi différent de Indicateur de maintien avant saisi) | P7: A_POS_INDREN [Saisi] = '0' ET (A_POS_INDREN [Saisi] <> A_POS_INDREN [Valeur avant saisie] OU A_POS_INDMAI [Saisi] <> A_POS_INDMAI [Valeur avant saisie]) | Q7: Contractuel | R7: P0003 | S7: Général | T7: Exclu | U7: 40725
A8: 17.10.00 | B8: A | C8: 43152.5 | D8: D0004 | E8: Position | F8: S0009 | G8: Détachement entrant/sortant | H8: E0136 | I8: Détachement entrant sur demande auprès d'une administration, d'un office ou d'un EP de l'Etat conduisant à pension | J8: Position administrative Saisie égale à 'Détachement entrant sur demande auprès d'une administration ou d'un EP de l'Etat conduisant à pension' ET Indicateur de maintien saisi = Non | K8: A_POS_POSIAD [Saisi] = 'DEE01' ET A_POS_SITPAR [Saisi] = Vide ET A_POS_INDMAI [Saisi] = '0' | L8: T0391 | M8: Détachement entrant sur demande auprès d'une administration, d'un office ou d'un EP de l'Etat conduisant à pension - Renouvellement | N8: Création Modification | O8: Indicateur de renouvellement saisi = Oui ET (Indicateur de renouvellement saisi différent d'Indicateur de renouvellement avant saisi OU Indicateur de maintien saisi différent de Indicateur de maintien avant saisi) | P8: A_POS_INDREN [Saisi] = '1' ET (A_POS_INDREN [Saisi] <> A_POS_INDREN [Valeur avant saisie] OU A_POS_INDMAI [Saisi] <> A_POS_INDMAI [Valeur avant saisie]) | Q8: Contractuel | R8: P0003 | S8: Général | T8: Exclu | U8: 40725
A9: 17.10.00 | B9: A | C9: 43152.5 | D9: D0004 | E9: Position | F9: S0009 | G9: Détachement entrant/sortant | H9: E0136 | I9: Détachement entrant sur demande auprès d'une administration, d'un office ou d'un EP de l'Etat conduisant à pension | J9: Position administrative Saisie égale à 'Détachement entrant sur demande auprès d'une administration ou d'un EP de l'Etat conduisant à pension' ET Indicateur de maintien saisi = Non | K9: A_POS_POSIAD [Saisi] = 'DEE01' ET A_POS_SITPAR [Saisi] = Vide ET A_POS_INDMAI [Saisi] = '0' | L9: T0392 | M9: Détachement entrant sur demande auprès d'une administration, d'un office ou d'un EP de l'Etat conduisant à pension - Réintégration | N9: Modification | O9: Indicateur de renouvellement saisi identique à Indicateur de renouvellement avant saisi ET Indicateur de maintien saisi identique à Indicateur de maintien avant saisi | P9: A_POS_INDREN [Saisi] = A_POS_INDREN [Valeur avant saisie] ET A_POS_INDMAI [Saisi] = A_POS_INDMAI [Valeur avant saisie] | Q9: Contractuel | R9: P0003 | S9: Général | T9: Exclu | U9: 40725
A10: 17.10.00 | B10: A | C10: 43152.5 | D10: D0004 | E10: Position | F10: S0009 | G10: Détachement entrant/sortant | H10: E0136 | I10: Détachement entrant sur demande auprès d'une administration, d'un office ou d'un EP de l'Etat conduisant à pension | J10: Position administrative Saisie égale à 'Détachement entrant sur demande auprès d'une administration ou d'un EP de l'Etat conduisant à pension' ET Indicateur de maintien saisi = Non | K10: A_POS_POSIAD [Saisi] = 'DEE01' ET A_POS_SITPAR [Saisi] = Vide ET A_POS_INDMAI [Saisi] = '0' | L10: T0390 | M10: Détachement entrant sur demande auprès d'une administration, d'un office ou d'un EP de l'Etat conduisant à pension - Demande | N10: Création Modification | O10: Indicateur de renouvellement saisi = Non ET (Indicateur de renouvellement saisi différent d'Indicateur de renouvellement avant saisi OU Indicateur de maintien saisi différent de Indicateur de maintien avant saisi) | P10: A_POS_INDREN [Saisi] = '0' ET (A_POS_INDREN [Saisi] <> A_POS_INDREN [Valeur avant saisie] OU A_POS_INDMAI [Saisi] <> A_POS_INDMAI [Valeur avant saisie]) | Q10: Stagiaire ou auditeur ou élève | R10: P0004 | S10: Général | T10: Exclu | U10: 40725
A11: 17.10.00 | B11: A | C11: 43152.5 | D11: D0004 | E11: Position | F11: S0009 | G11: Détachement entrant/sortant | H11: E0136 | I11: Détachement entrant sur demande auprès d'une administration, d'un office ou d'un EP de l'Etat conduisant à pension | J11: Position administrative Saisie égale à 'Détachement entrant sur demande auprès d'une administration ou d'un EP de l'Etat conduisant à pension' ET Indicateur de maintien saisi = Non | K11: A_POS_POSIAD [Saisi] = 'DEE01' ET A_POS_SITPAR [Saisi] = Vide ET A_POS_INDMAI [Saisi] = '0' | L11: T0391 | M11: Détachement entrant sur demande auprès d'une administration, d'un office ou d'un EP de l'Etat conduisant à pension - Renouvellement | N11: Création Modification | O11: Indicateur de renouvellement saisi = Oui ET (Indicateur de renouvellement saisi différent d'Indicateur de renouvellement avant saisi OU Indicateur de maintien saisi différent de Indicateur de maintien avant saisi) | P11: A_POS_INDREN [Saisi] = '1' ET (A_POS_INDREN [Saisi] <> A_POS_INDREN [Valeur avant saisie] OU A_POS_INDMAI [Saisi] <> A_POS_INDMAI [Valeur avant saisie]) | Q11: Stagiaire ou auditeur ou élève | R11: P0004 | S11: Général | T11: Exclu | U11: 40725
A12: 17.10.00 | B12: A | C12: 43152.5 | D12: D0004 | E12: Position | F12: S0009 | G12: Détachement entrant/sortant | H12: E0136 | I12: Détachement entrant sur demande auprès d'une administration, d'un office ou d'un EP de l'Etat conduisant à pension | J12: Position administrative Saisie égale à 'Détachement entrant sur demande auprès d'une administration ou d'un EP de l'Etat conduisant à pension' ET Indicateur de maintien saisi = Non | K12: A_POS_POSIAD [Saisi] = 'DEE01' ET A_POS_SITPAR [Saisi] = Vide ET A_POS_INDMAI [Saisi] = '0' | L12: T0392 | M12: Détachement entrant sur demande auprès d'une administration, d'un office ou d'un EP de l'Etat conduisant à pension - Réintégration | N12: Modification | O12: Indicateur de renouvellement saisi identique à Indicateur de renouvellement avant saisi ET Indicateur de maintien saisi identique à Indicateur de maintien avant saisi | P12: A_POS_INDREN [Saisi] = A_POS_INDREN [Valeur avant saisie] ET A_POS_INDMAI [Saisi] = A_POS_INDMAI [Valeur avant saisie] | Q12: Stagiaire ou auditeur ou élève | R12: P0004 | S12: Général | T12: Exclu | U12: 40725
A13: 17.10.00 | B13: A | C13: 43152.5 | D13: D0004 | E13: Position | F13: S0009 | G13: Détachement entrant/sortant | H13: E0136 | I13: Détachement entrant sur demande auprès d'une administration, d'un office ou d'un EP de l'Etat conduisant à pension | J13: Position administrative Saisie égale à 'Détachement entrant sur demande auprès d'une administration ou d'un EP de l'Etat conduisant à pension' ET Indicateur de maintien saisi = Non | K13: A_POS_POSIAD [Saisi] = 'DEE01' ET A_POS_SITPAR [Saisi] = Vide ET A_POS_INDMAI [Saisi] = '0' | L13: T0390 | M13: Détachement entrant sur demande auprès d'une administration, d'un office ou d'un EP de l'Etat conduisant à pension - Demande | N13: Création Modification | O13: Indicateur de renouvellement saisi = Non ET (Indicateur de renouvellement saisi différent d'Indicateur de renouvellement avant saisi OU Indicateur de maintien saisi différent de Indicateur de maintien avant saisi) | P13: A_POS_INDREN [Saisi] = '0' ET (A_POS_INDREN [Saisi] <> A_POS_INDREN [Valeur avant saisie] OU A_POS_INDMAI [Saisi] <> A_POS_INDMAI [Valeur avant saisie]) | Q13: Ouvrier d'état | R13: P0005 | S13: Général | T13: Exclu | U13: 40725
A14: 17.10.00 | B14: A | C14: 43152.5 | D14: D0004 | E14: Position | F14: S0009 | G14: Détachement entrant/sortant | H14: E0136 | I14: Détachement entrant sur demande auprès d'une administration, d'un office ou d'un EP de l'Etat conduisant à pension | J14: Position administrative Saisie égale à 'Détachement entrant sur demande auprès d'une administration ou d'un EP de l'Etat conduisant à pension' ET Indicateur de maintien saisi = Non | K14: A_POS_POSIAD [Saisi] = 'DEE01' ET A_POS_SITPAR [Saisi] = Vide ET A_POS_INDMAI [Saisi] = '0' | L14: T0391 | M14: Détachement entrant sur demande auprès d'une administration, d'un office ou d'un EP de l'Etat conduisant à pension - Renouvellement | N14: Création Modification | O14: Indicateur de renouvellement saisi = Oui ET (Indicateur de renouvellement saisi différent d'Indicateur de renouvellement avant saisi OU Indicateur de maintien saisi différent de Indicateur de maintien avant saisi) | P14: A_POS_INDREN [Saisi] = '1' ET (A_POS_INDREN [Saisi] <> A_POS_INDREN [Valeur avant saisie] OU A_POS_INDMAI [Saisi] <> A_POS_INDMAI [Valeur avant saisie]) | Q14: Ouvrier d'état | R14: P0005 | S14: Général | T14: Exclu | U14: 40725
A15: 17.10.00 | B15: A | C15: 43152.5 | D15: D0004 | E15: Position | F15: S0009 | G15: Détachement entrant/sortant | H15: E0136 | I15: Détachement entrant sur demande auprès d'une administration, d'un office ou d'un EP de l'Etat conduisant à pension | J15: Position administrative Saisie égale à 'Détachement entrant sur demande auprès d'une administration ou d'un EP de l'Etat conduisant à pension' ET Indicateur de maintien saisi = Non | K15: A_POS_POSIAD [Saisi] = 'DEE01' ET A_POS_SITPAR [Saisi] = Vide ET A_POS_INDMAI [Saisi] = '0' | L15: T0392 | M15: Détachement entrant sur demande auprès d'une administration, d'un office ou d'un EP de l'Etat conduisant à pension - Réintégration | N15: Modification | O15: Indicateur de renouvellement saisi identique à Indicateur de renouvellement avant saisi ET Indicateur de maintien saisi identique à Indicateur de maintien avant saisi | P15: A_POS_INDREN [Saisi] = A_POS_INDREN [Valeur avant saisie] ET A_POS_INDMAI [Saisi] = A_POS_INDMAI [Valeur avant saisie] | Q15: Ouvrier d'état | R15: P0005 | S15: Général | T15: Exclu | U15: 40725
A16: 20.00.00 | B16: M | C16: 43850.552 | D16: D0004 | E16: Position | F16: S0009 | G16: Détachement entrant/sortant | H16: E0136 | I16: Détachement entrant sur demande auprès d'une administration, d'un office ou d'un EP de l'Etat conduisant à pension | J16: Position administrative Saisie égale à 'Détachement entrant sur demande auprès d'une administration ou d'un EP de l'Etat conduisant à pension' ET Indicateur de maintien saisi = Non | K16: A_POS_POSIAD [Saisi] = 'DEE01' ET A_POS_SITPAR [Saisi] = Vide ET A_POS_INDMAI [Saisi] = '0' | L16: T0390 | M16: Détachement entrant sur demande auprès d'une administration, d'un office ou d'un EP de l'Etat conduisant à pension - Demande | N16: Création Modification | O16: Indicateur de renouvellement saisi = Non ET (Indicateur de renouvellement saisi différent d'Indicateur de renouvellement avant saisi OU Indicateur de maintien saisi différent de Indicateur de maintien avant saisi) | P16: A_POS_INDREN [Saisi] = '0' ET (A_POS_INDREN [Saisi] <> A_POS_INDREN [Valeur avant saisie] OU A_POS_INDMAI [Saisi] <> A_POS_INDMAI [Valeur avant saisie]) | Q16: Préfet ou sous-préfet | R16: P0016 | S16: Particulier | T16: Passant | U16: 40725 | V16: 43830 | W16: DEE_I_002 ET DEE_I_003 ET DEE_I_006 ET DEE_I_004 ET DEE_D_505 ET DEE_D_011 ET DEE_D_411 ET POS_C_004 ET POS_C_005 ET POS_C_007 ET POS_C_010 ET POS_C_012 ET POS_C_013 ET POS_C_022 ET POS_C_030 ET POS_C_031 ET POS_C_034 ET POS_C_035 ET POS_C_036 ET POS_C_111 | X16: DEE_I_002 | Y16: =VLOOKUP(X16,'Axe 2 Règles de gestion'!$D$2:$F$121,3, FALSE) -> L'agent doit détenir le titre ou le diplôme requis pour l'exercice des fonctions du corps d'accueil. | Z16: DEE_I_003 | AA16: =VLOOKUP(Z16,'Axe 2 Règles de gestion'!$D$2:$F$121,3, FALSE) -> L'agent doit formuler une demande. | AB16: DEE_I_006 | AC16: =VLOOKUP(AB16,'Axe 2 Règles de gestion'!$D$2:$F$121,3, FALSE) -> Le détachement est accordé après avis des commissions administratives paritaires compétentes. | AD16: DEE_I_004 | AE16: =VLOOKUP(AD16,'Axe 2 Règles de gestion'!$D$2:$F$121,3, FALSE) -> L'accord de l'administration d'origine est nécessaire. | AP16: DEE_D_505 | AQ16: =VLOOKUP(AP16,'Axe 2 Règles de gestion'!$D$2:$F$121,3, FALSE) -> Le détachement de courte durée est interdit. | AR16: DEE_D_011 | AS16: =VLOOKUP(AR16,'Axe 2 Règles de gestion'!$D$2:$F$121,3, FALSE) -> Un détachement de longue durée ne peut excéder 5 ans entre la date de début et la date de fin prévisionnelle. | AT16: DEE_D_411 | AU16: =VLOOKUP(AT16,'Axe 2 Règles de gestion'!$D$2:$F$121,3, FALSE) -> Un détachement de longue durée ne peut excéder 5 ans entre la date de début et la date de fin réelle. | BB16: POS_C_004 | BC16: =VLOOKUP(BB16,'Axe 2 Règles de gestion'!$D$2:$F$121,3, FALSE) -> La date de début de position doit être antérieure ou égale à la date de fin prévisionnelle de position. | BD16: POS_C_005 | BE16: =VLOOKUP(BD16,'Axe 2 Règles de gestion'!$D$2:$F$121,3, FALSE) -> La date de début de la position doit être postérieure ou égale à la date d'entrée dans la FPE ou dans la carrière militaire. | BF16: POS_C_007 | BG16: =VLOOKUP(BF16,'Axe 2 Règles de gestion'!$D$2:$F$121,3, FALSE) -> La date de fin réelle de la position doit être antérieure à la date limite de départ à la retraite. | BH16: POS_C_010 | BI16: =VLOOKUP(BH16,'Axe 2 Règles de gestion'!$D$2:$F$121,3, FALSE) -> La date de début de position doit être antérieure ou égale à la date de fin réelle de position. | BJ16: POS_C_012 | BK16: =VLOOKUP(BJ16,'Axe 2 Règles de gestion'!$D$2:$F$121,3, FALSE) -> La date de fin prévisionnelle de la position doit être antérieure à la date limite de départ à la retraite. | BL16: POS_C_013 | BM16: =VLOOKUP(BL16,'Axe 2 Règles de gestion'!$D$2:$F$121,3, FALSE) -> L'indicateur de carrière est sur la valeur "Accueil". | BN16: POS_C_022 | BO16: =VLOOKUP(BN16,'Axe 2 Règles de gestion'!$D$2:$F$121,3, FALSE) -> La date de début de position est à J+1 de la date de fin de position de l'occurrence précédente. | BP16: POS_C_030 | BQ16: =VLOOKUP(BP16,'Axe 2 Règles de gestion'!$D$2:$F$121,3, FALSE) -> Les champs "Type d'organisme d'origine", "Catégorie statutaire d'origine" et "Pays" de l'organisme d'origine doivent être renseignés. | BR16: POS_C_031 | BS16: =VLOOKUP(BR16,'Axe 2 Règles de gestion'!$D$2:$F$121,3, FALSE) -> Les champs "Ministère (ou institution de la République) d'origine", "Corps d'origine", "Grade d'origine", "Echelon d'origine" sont renseignés si le "Type d'organisme d'origine" est valorisé à FPE. | BT16: POS_C_034 | BU16: =VLOOKUP(BT16,'Axe 2 Règles de gestion'!$D$2:$F$121,3, FALSE) -> Le champ "Organisme d'origine" doit être alimenté si le type d'organisme d'origine est égal à 'Autre organisme', 'Fonction publique d'un état de l'Union Européenne' ou 'Fonction publique Européenne'. | BV16: POS_C_035 | BW16: =VLOOKUP(BV16,'Axe 2 Règles de gestion'!$D$2:$F$121,3, FALSE) -> Le champ "Code emploi statutaire FPT (NET)" est renseigné si le "Type d'organisme d'origine" est valorisé à FPT. | BX16: POS_C_036 | BY16: =VLOOKUP(BX16,'Axe 2 Règles de gestion'!$D$2:$F$121,3, FALSE) -> Le champ "Code emploi statutaire FPH (NEH)" est renseigné si le "Type d'organisme d'origine" est valorisé à FPH. | BZ16: POS_C_111 | CA16: =VLOOKUP(BZ16,'Axe 2 Règles de gestion'!$D$2:$F$121,3, FALSE) -> La date de fin ou la date de fin prévisionnelle doit être saisie.
A17: 20.00.00 | B17: A | C17: 44012.455 | D17: D0004 | E17: Position | F17: S0009 | G17: Détachement entrant/sortant | H17: E0136 | I17: Détachement entrant sur demande auprès d'une administration, d'un office ou d'un EP de l'Etat conduisant à pension | J17: Position administrative Saisie égale à 'Détachement entrant sur demande auprès d'une administration ou d'un EP de l'Etat conduisant à pension' ET Indicateur de maintien saisi = Non | K17: A_POS_POSIAD [Saisi] = 'DEE01' ET A_POS_SITPAR [Saisi] = Vide ET A_POS_INDMAI [Saisi] = '0' | L17: T0390 | M17: Détachement entrant sur demande auprès d'une administration, d'un office ou d'un EP de l'Etat conduisant à pension - Demande | N17: Création Modification | O17: Indicateur de renouvellement saisi = Non ET (Indicateur de renouvellement saisi différent d'Indicateur de renouvellement avant saisi OU Indicateur de maintien saisi différent de Indicateur de maintien avant saisi) | P17: A_POS_INDREN [Saisi] = '0' ET (A_POS_INDREN [Saisi] <> A_POS_INDREN [Valeur avant saisie] OU A_POS_INDMAI [Saisi] <> A_POS_INDMAI [Valeur avant saisie]) | Q17: Préfet ou sous-préfet | R17: P0016 | S17: Particulier | T17: Passant | U17: 43831 | W17: DEE_I_002 ET DEE_I_003 ET DEE_I_004 ET DEE_D_505 ET DEE_D_011 ET DEE_D_411 ET POS_C_004 ET POS_C_005 ET POS_C_007 ET POS_C_010 ET POS_C_012 ET POS_C_013 ET POS_C_022 ET POS_C_030 ET POS_C_031 ET POS_C_034 ET POS_C_035 ET POS_C_036 ET POS_C_111 | X17: DEE_I_002 | Y17: =VLOOKUP(X17,'Axe 2 Règles de gestion'!$D$2:$F$121,3, FALSE) -> L'agent doit détenir le titre ou le diplôme requis pour l'exercice des fonctions du corps d'accueil. | Z17: DEE_I_003 | AA17: =VLOOKUP(Z17,'Axe 2 Règles de gestion'!$D$2:$F$121,3, FALSE) -> L'agent doit formuler une demande. | AB17: DEE_I_004 | AC17: =VLOOKUP(AB17,'Axe 2 Règles de gestion'!$D$2:$F$121,3, FALSE) -> L'accord de l'administration d'origine est nécessaire. | AP17: DEE_D_505 | AQ17: =VLOOKUP(AP17,'Axe 2 Règles de gestion'!$D$2:$F$121,3, FALSE) -> Le détachement de courte durée est interdit. | AR17: DEE_D_011 | AS17: =VLOOKUP(AR17,'Axe 2 Règles de gestion'!$D$2:$F$121,3, FALSE) -> Un détachement de longue durée ne peut excéder 5 ans entre la date de début et la date de fin prévisionnelle. | AT17: DEE_D_411 | AU17: =VLOOKUP(AT17,'Axe 2 Règles de gestion'!$D$2:$F$121,3, FALSE) -> Un détachement de longue durée ne peut excéder 5 ans entre la date de début et la date de fin réelle. | BB17: POS_C_004 | BC17: =VLOOKUP(BB17,'Axe 2 Règles de gestion'!$D$2:$F$121,3, FALSE) -> La date de début de position doit être antérieure ou égale à la date de fin prévisionnelle de position. | BD17: POS_C_005 | BE17: =VLOOKUP(BD17,'Axe 2 Règles de gestion'!$D$2:$F$121,3, FALSE) -> La date de début de la position doit être postérieure ou égale à la date d'entrée dans la FPE ou dans la carrière militaire. | BF17: POS_C_007 | BG17: =VLOOKUP(BF17,'Axe 2 Règles de gestion'!$D$2:$F$121,3, FALSE) -> La date de fin réelle de la position doit être antérieure à la date limite de départ à la retraite. | BH17: POS_C_010 | BI17: =VLOOKUP(BH17,'Axe 2 Règles de gestion'!$D$2:$F$121,3, FALSE) -> La date de début de position doit être antérieure ou égale à la date de fin réelle de position. | BJ17: POS_C_012 | BK17: =VLOOKUP(BJ17,'Axe 2 Règles de gestion'!$D$2:$F$121,3, FALSE) -> La date de fin prévisionnelle de la position doit être antérieure à la date limite de départ à la retraite. | BL17: POS_C_013 | BM17: =VLOOKUP(BL17,'Axe 2 Règles de gestion'!$D$2:$F$121,3, FALSE) -> L'indicateur de carrière est sur la valeur "Accueil". | BN17: POS_C_022 | BO17: =VLOOKUP(BN17,'Axe 2 Règles de gestion'!$D$2:$F$121,3, FALSE) -> La date de début de position est à J+1 de la date de fin de position de l'occurrence précédente. | BP17: POS_C_030 | BQ17: =VLOOKUP(BP17,'Axe 2 Règles de gestion'!$D$2:$F$121,3, FALSE) -> Les champs "Type d'organisme d'origine", "Catégorie statutaire d'origine" et "Pays" de l'organisme d'origine doivent être renseignés. | BR17: POS_C_031 | BS17: =VLOOKUP(BR17,'Axe 2 Règles de gestion'!$D$2:$F$121,3, FALSE) -> Les champs "Ministère (ou institution de la République) d'origine", "Corps d'origine", "Grade d'origine", "Echelon d'origine" sont renseignés si le "Type d'organisme d'origine" est valorisé à FPE. | BT17: POS_C_034 | BU17: =VLOOKUP(BT17,'Axe 2 Règles de gestion'!$D$2:$F$121,3, FALSE) -> Le champ "Organisme d'origine" doit être alimenté si le type d'organisme d'origine est égal à 'Autre organisme', 'Fonction publique d'un état de l'Union Européenne' ou 'Fonction publique Européenne'. | BV17: POS_C_035 | BW17: =VLOOKUP(BV17,'Axe 2 Règles de gestion'!$D$2:$F$121,3, FALSE) -> Le champ "Code emploi statutaire FPT (NET)" est renseigné si le "Type d'organisme d'origine" est valorisé à FPT. | BX17: POS_C_036 | BY17: =VLOOKUP(BX17,'Axe 2 Règles de gestion'!$D$2:$F$121,3, FALSE) -> Le champ "Code emploi statutaire FPH (NEH)" est renseigné si le "Type d'organisme d'origine" est valorisé à FPH. | BZ17: POS_C_111 | CA17: =VLOOKUP(BZ17,'Axe 2 Règles de gestion'!$D$2:$F$121,3, FALSE) -> La date de fin ou la date de fin prévisionnelle doit être saisie.
