Workbook

Sheet Mode opératoire
B1: MODE OPERATOIRE
B2: La transaction s'effectue au niveau des sous rubrique "Position statutaire/situation administrative" et "Compteurs de périodes de positions/situations".

Sheet Axe 1 Enchainement des RG
A1: Version | B1: Type de mise à jour | C1: Date de mise à jour | D1: Identifiant Domaine | E1: Libellé du Domaine | F1: Identifiant Sous-domaine | G1: Libellé du Sous-domaine | H1: Identifiant Evénement | I1: Libellé de l'évènement | J1: Libellé condition déclenchement Evènement | K1: Condition déclenchement Evènement | L1: Identifiant type d'évènement | M1: Libellé type d'évènement | N1: Type de mise à jour | O1: Libellé condition déclenchement Type Evènement | P1: Condition déclenchement Type Evènement | Q1: Libellé Population | R1: Codification Population | S1: Général / Particulier | T1: Passant / Exclu | U1: Date de début | V1: Date de fin | W1: Règles mobilisées | X1: Identifiant Règle de contrôle intellectuel 1 | Y1: Libellé Règle de contrôle intellectuel 1 | Z1: Identifiant Règle de contrôle intellectuel 2 | AA1: Libellé Règle de contrôle intellectuel 2 | AB1: Identifiant Règle de contrôle intellectuel 3 | AC1: Libellé Règle de contrôle intellectuel 3 | AD1: Identifiant Règle de contrôle intellectuel 4 | AE1: Libellé Règle de contrôle intellectuel 4 | AF1: Identifiant Règle de contrôle intellectuel 5 | AG1: Libellé Règle de contrôle intellectuel 5 | AH1: Identifiant Règle de contrôle intellectuel 6 | AI1: Libellé Règle de contrôle intellectuel 6 | AJ1: Identifiant Règle de contrôle intellectuel 7 | AK1: Libellé Règle de contrôle intellectuel 7 | AL1: Identifiant Règle de contrôle intellectuel 8 | AM1: Libellé Règle de contrôle intellectuel 8 | AN1: Identifiant Règle de contrôle intellectuel 9 | AO1: Libellé Règle de contrôle intellectuel 9 | AP1: Identifiant Règle de condition 1 | AQ1: Libellé Règle de condition 1 | AR1: Identifiant Règle de condition 2 | AS1: Libellé Règle de condition 2 | AT1: Identifiant Règle de condition 3 | AU1: Libellé Règle de condition 3 | AV1: Identifiant Règle de condition 4 | AW1: Libellé Règle de condition 4 | AX1: Identifiant Règle de condition 5 | AY1: Libellé Règle de condition 5 | AZ1: Identifiant Règle de condition 6 | BA1: Libellé Règle de condition 6 | BB1: Identifiant Règle de condition 7 | BC1: Libellé Règle de condition 7 | BD1: Identifiant Règle de condition 8 | BE1: Libellé Règle de condition 8 | BF1: Identifiant Règle de condition 9 | BG1: Libellé Règle de condition 9 | BH1: Identifiant Règle de condition 10 | BI1: Libellé Règle de condition 10 | BJ1: Identifiant Règle de condition 11 | BK1: Libellé Règle de condition 11 | BL1: Identifiant Règle de condition 12 | BM1: Libellé Règle de condition 12 | BN1: Identifiant Règle de contrôle 1 | BO1: Libellé Règle de contrôle 1 | BP1: Identifiant Règle de contrôle 2 | BQ1: Libellé Règle de contrôle 2 | BR1: Identifiant Règle de contrôle 3 | BS1: Libellé Règle de contrôle 3 | BT1: Identifiant Règle de contrôle 4 | BU1: Libellé Règle de contrôle 4 | BV1: Identifiant Règle de contrôle 5 | BW1: Libellé Règle de contrôle 5 | BX1: Identifiant Règle de contrôle 6 | BY1: Libellé Règle de contrôle 6 | BZ1: Identifiant Règle de contrôle 7 | CA1: Libellé Règle de contrôle 7 | CB1: Identifiant Règle de contrôle 8 | CC1: Libellé Règle de contrôle 8 | CD1: Identifiant Règle de contrôle 9 | CE1: Libellé Règle de contrôle 9 | CF1: Identifiant Règle de contrôle 10 | CG1: Libellé Règle de contrôle 10 | CH1: Identifiant Règle de contrôle 11 | CI1: Libellé Règle de contrôle 11 | CJ1: Identifiant Règle de contrôle 12 | CK1: Libellé Règle de contrôle 12 | CL1: Identifiant Règle de contrôle 13 | CM1: Libellé Règle de contrôle 13 | CN1: Identifiant Règle de contrôle 14 | CO1: Libellé Règle de contrôle 14 | CP1: FIME | CQ1: Statut de travail
A2: 20.10.00 | B2: M | C2: 43699.601 | D2: D0004 | E2: Position | F2: S0012 | G2: Disponibilité | H2: E0161 | I2: Disponibilité sur demande pour donner des soins au conjoint ou au partenaire pacsé suite à accident/maladie grave | J2: Position saisie égale à 'Disponibilité sur demande pour donner des soins au conjoint ou au partenaire pacsé suite à accident/maladie grave' ET Indicateur de maintien saisi = Non | K2: A_POS_POSIAD [Saisi] = 'DSP36' ET A_POS_INDMAI [Saisi] = '0' | L2: T0471 | M2: Disponibilité sur demande pour donner des soins au conjoint ou au partenaire pacsé suite à accident/maladie grave - Demande | N2: Création Modification | O2: Indicateur de renouvellement saisi = Non ET (Indicateur de renouvellement saisi différent d'Indicateur de renouvellement avant saisi OU Indicateur de maintien saisi différent de Indicateur de maintien avant saisi) | P2: A_POS_INDREN [Saisi] = '0' ET (A_POS_INDREN [Saisi] <> A_POS_INDREN [Valeur avant saisie] OU A_POS_INDMAI [Saisi] <> A_POS_INDMAI [Valeur avant saisie]) | Q2: Titulaire ou magistrat | R2: P0001 | S2: Général | T2: Passant | U2: 40725 | V2: 43349 | W2: DIS_I_005 ET DIS_I_006 ET DIS_D_011 ET DIS_D_400 ET DIS_D_379 ET DIS_D_506 ET POS_C_004 ET POS_C_005 ET POS_C_007 ET POS_C_010 ET POS_C_012 ET POS_C_022 ET POS_C_111 | X2: DIS_I_005 | Y2: =VLOOKUP(X2,'Axe 2 Règles de gestion'!$D$2:$F$408,3, FALSE) -> L'agent doit effectuer une demande. | Z2: DIS_I_006 | AA2: =VLOOKUP(Z2,'Axe 2 Règles de gestion'!$D$2:$F$408,3, FALSE) -> La demande est accordée de droit. | AP2: DIS_D_011 | AQ2: =VLOOKUP(AP2,'Axe 2 Règles de gestion'!$D$2:$F$408,3, FALSE) -> La durée prévisionnelle de la disponibilité ne peut pas excéder 3 ans pour chaque période. | AR2: DIS_D_400 | AS2: =VLOOKUP(AR2,'Axe 2 Règles de gestion'!$D$2:$F$408,3, FALSE) -> La durée réelle de la disponibilité ne peut pas excéder 3 ans pour chaque période. | AT2: DIS_D_379 | AU2: =VLOOKUP(AT2,'Axe 2 Règles de gestion'!$D$2:$F$408,3, FALSE) -> L'agent doit être en activité. | AV2: DIS_D_506 | AW2: =VLOOKUP(AV2,'Axe 2 Règles de gestion'!$D$2:$F$408,3, FALSE) -> Le type de situation de famille de l'agent doit être "marié(e)" ou "pacsé(e)". | BN2: POS_C_004 | BO2: =VLOOKUP(BN2,'Axe 2 Règles de gestion'!$D$2:$F$408,3, FALSE) -> La date de début de position doit être antérieure ou égale à la date de fin prévisionnelle de position. | BP2: POS_C_005 | BQ2: =VLOOKUP(BP2,'Axe 2 Règles de gestion'!$D$2:$F$408,3, FALSE) -> La date de début de la position doit être postérieure ou égale à la date d'entrée dans la FPE ou dans la carrière militaire. | BR2: POS_C_007 | BS2: =VLOOKUP(BR2,'Axe 2 Règles de gestion'!$D$2:$F$408,3, FALSE) -> La date de fin réelle de la position doit être antérieure à la date limite de départ à la retraite. | BT2: POS_C_010 | BU2: =VLOOKUP(BT2,'Axe 2 Règles de gestion'!$D$2:$F$408,3, FALSE) -> La date de début de position doit être antérieure ou égale à la date de fin réelle de position. | BV2: POS_C_012 | BW2: =VLOOKUP(BV2,'Axe 2 Règles de gestion'!$D$2:$F$408,3, FALSE) -> La date de fin prévisionnelle de la position doit être antérieure à la date limite de départ à la retraite. | BX2: POS_C_022 | BY2: =VLOOKUP(BX2,'Axe 2 Règles de gestion'!$D$2:$F$408,3, FALSE) -> La date de début de position est à J+1 de la date de fin de position de l'occurrence précédente. | BZ2: POS_C_111 | CA2: =VLOOKUP(BZ2,'Axe 2 Règles de gestion'!$D$2:$F$408,3, FALSE) -> La date de fin ou la date de fin prévisionnelle doit être saisie.
A3: 25.00.00 | B3: M | C3: 45803.683 | D3: D0004 | E3: Position | F3: S0012 | G3: Disponibilité | H3: E0161 | I3: Disponibilité sur demande pour donner des soins au conjoint ou au partenaire pacsé suite à accident/maladie grave | J3: Position saisie égale à 'Disponibilité sur demande pour donner des soins au conjoint ou au partenaire pacsé suite à accident/maladie grave' ET Indicateur de maintien saisi = Non | K3: A_POS_POSIAD [Saisi] = 'DSP36' ET A_POS_INDMAI [Saisi] = '0' | L3: T0471 | M3: Disponibilité sur demande pour donner des soins au conjoint ou au partenaire pacsé suite à accident/maladie grave - Demande | N3: Création Modification | O3: Indicateur de renouvellement saisi = Non ET (Indicateur de renouvellement saisi différent d'Indicateur de renouvellement avant saisi OU Indicateur de maintien saisi différent de Indicateur de maintien avant saisi) | P3: A_POS_INDREN [Saisi] = '0' ET (A_POS_INDREN [Saisi] <> A_POS_INDREN [Valeur avant saisie] OU A_POS_INDMAI [Saisi] <> A_POS_INDMAI [Valeur avant saisie]) | Q3: Titulaire ou magistrat | R3: P0001 | S3: Général | T3: Passant | U3: 43350 | W3: DIS_I_005 ET DIS_I_006 ET DIS_I_178 ET DIS_D_011 ET DIS_D_400 ET DIS_D_506 ET DIS_D_613 ET DIS_D_616 ET POS_C_004 ET POS_C_005 ET POS_C_007 ET POS_C_010 ET POS_C_012 ET POS_C_022 ET POS_C_111 ET POS_C_120 ET POS_C_121 | X3: DIS_I_005 | Y3: =VLOOKUP(X3,'Axe 2 Règles de gestion'!$D$2:$F$408,3, FALSE) -> L'agent doit effectuer une demande. | Z3: DIS_I_006 | AA3: =VLOOKUP(Z3,'Axe 2 Règles de gestion'!$D$2:$F$408,3, FALSE) -> La demande est accordée de droit. | AB3: DIS_I_178 | AC3: =VLOOKUP(AB3,'Axe 2 Règles de gestion'!$D$2:$F$408,3, FALSE) -> L'administration fait procéder aux enquêtes nécessaires en vue de s'assurer que l'activité de l'agent mis en disponibilité correspond réellement aux motifs pour lesquels il a été placé en cette position. | AP3: DIS_D_011 | AQ3: =VLOOKUP(AP3,'Axe 2 Règles de gestion'!$D$2:$F$408,3, FALSE) -> La durée prévisionnelle de la disponibilité ne peut pas excéder 3 ans pour chaque période. | AR3: DIS_D_400 | AS3: =VLOOKUP(AR3,'Axe 2 Règles de gestion'!$D$2:$F$408,3, FALSE) -> La durée réelle de la disponibilité ne peut pas excéder 3 ans pour chaque période. | AT3: DIS_D_506 | AU3: =VLOOKUP(AT3,'Axe 2 Règles de gestion'!$D$2:$F$408,3, FALSE) -> Le type de situation de famille de l'agent doit être "marié(e)" ou "pacsé(e)". | AV3: DIS_D_613 | AW3: =VLOOKUP(AV3,'Axe 2 Règles de gestion'!$D$2:$F$408,3, FALSE) -> L'agent a épuisé ses droits à ancienneté relatifs à la disponibilité. En effet, l'agent en disponibilité pour études ou recherches, convenances personnelles, créer ou reprendre une entreprise, donner des soins, suivre son conjoint ou partenaire de PACS conserve ses droits à l'avancement (échelon et grade) dans la limite de 5 ans s'il exerce une activité professionnelle. | AX3: DIS_D_616 | AY3: =VLOOKUP(AX3,'Axe 2 Règles de gestion'!$D$2:$F$408,3, FALSE) -> Si le champ « Situation particulière » est saisi, alors seule la valeur « Période de disponibilité donnant droit à avancement » peut être sélectionnée. | BN3: POS_C_004 | BO3: =VLOOKUP(BN3,'Axe 2 Règles de gestion'!$D$2:$F$408,3, FALSE) -> La date de début de position doit être antérieure ou égale à la date de fin prévisionnelle de position. | BP3: POS_C_005 | BQ3: =VLOOKUP(BP3,'Axe 2 Règles de gestion'!$D$2:$F$408,3, FALSE) -> La date de début de la position doit être postérieure ou égale à la date d'entrée dans la FPE ou dans la carrière militaire. | BR3: POS_C_007 | BS3: =VLOOKUP(BR3,'Axe 2 Règles de gestion'!$D$2:$F$408,3, FALSE) -> La date de fin réelle de la position doit être antérieure à la date limite de départ à la retraite. | BT3: POS_C_010 | BU3: =VLOOKUP(BT3,'Axe 2 Règles de gestion'!$D$2:$F$408,3, FALSE) -> La date de début de position doit être antérieure ou égale à la date de fin réelle de position. | BV3: POS_C_012 | BW3: =VLOOKUP(BV3,'Axe 2 Règles de gestion'!$D$2:$F$408,3, FALSE) -> La date de fin prévisionnelle de la position doit être antérieure à la date limite de départ à la retraite. | BX3: POS_C_022 | BY3: =VLOOKUP(BX3,'Axe 2 Règles de gestion'!$D$2:$F$408,3, FALSE) -> La date de début de position est à J+1 de la date de fin de position de l'occurrence précédente. | BZ3: POS_C_111 | CA3: =VLOOKUP(BZ3,'Axe 2 Règles de gestion'!$D$2:$F$408,3, FALSE) -> La date de fin ou la date de fin prévisionnelle doit être saisie. | CB3: POS_C_120 | CC3: =VLOOKUP(CB3,'Axe 2 Règles de gestion'!$D$2:$F$408,3, FALSE) -> La saisie d'une occurrence de congés/absences est interdite (date de fin réelle) | CD3: POS_C_121 | CE3: =VLOOKUP(CD3,'Axe 2 Règles de gestion'!$D$2:$F$408,3, FALSE) -> La saisie d'une occurrence de congés/absences est interdite (date de fin prévisionnelle)
A4: 20.10.00 | B4: M | C4: 43699.602 | D4: D0004 | E4: Position | F4: S0012 | G4: Disponibilité | H4: E0161 | I4: Disponibilité sur demande pour donner des soins au conjoint ou au partenaire pacsé suite à accident/maladie grave | J4: Position saisie égale à 'Disponibilité sur demande pour donner des soins au conjoint ou au partenaire pacsé suite à accident/maladie grave' ET Indicateur de maintien saisi = Non | K4: A_POS_POSIAD [Saisi] = 'DSP36' ET A_POS_INDMAI [Saisi] = '0' | L4: T0472 | M4: Disponibilité sur demande pour donner des soins au conjoint ou au partenaire pacsé suite à accident/maladie grave - Renouvellement | N4: Création Modification | O4: Indicateur de renouvellement saisi = Oui ET (Indicateur de renouvellement saisi différent d'Indicateur de renouvellement avant saisi OU Indicateur de maintien saisi différent de Indicateur de maintien avant saisi) | P4: A_POS_INDREN [Saisi] = '1' ET (A_POS_INDREN [Saisi] <> A_POS_INDREN [Valeur avant saisie] OU A_POS_INDMAI [Saisi] <> A_POS_INDMAI [Valeur avant saisie]) | Q4: Titulaire ou magistrat | R4: P0001 | S4: Général | T4: Passant | U4: 40725 | V4: 43349 | W4: DIS_I_034 ET DIS_D_011 ET DIS_D_400 ET DIS_D_506 ET POS_C_004 ET POS_C_005 ET POS_C_007 ET POS_C_010 ET POS_C_012 ET POS_C_022 ET POS_C_111 | X4: DIS_I_034 | Y4: =VLOOKUP(X4,'Axe 2 Règles de gestion'!$D$2:$F$408,3, FALSE) -> L'agent doit informer son administration d'origine de sa décision de solliciter le renouvellement de sa disponibilité ou de réintégrer son corps d'origine 3 mois au moins avant l'expiration de la disponibilité. | AP4: DIS_D_011 | AQ4: =VLOOKUP(AP4,'Axe 2 Règles de gestion'!$D$2:$F$408,3, FALSE) -> La durée prévisionnelle de la disponibilité ne peut pas excéder 3 ans pour chaque période. | AR4: DIS_D_400 | AS4: =VLOOKUP(AR4,'Axe 2 Règles de gestion'!$D$2:$F$408,3, FALSE) -> La durée réelle de la disponibilité ne peut pas excéder 3 ans pour chaque période. | AT4: DIS_D_506 | AU4: =VLOOKUP(AT4,'Axe 2 Règles de gestion'!$D$2:$F$408,3, FALSE) -> Le type de situation de famille de l'agent doit être "marié(e)" ou "pacsé(e)". | BN4: POS_C_004 | BO4: =VLOOKUP(BN4,'Axe 2 Règles de gestion'!$D$2:$F$408,3, FALSE) -> La date de début de position doit être antérieure ou égale à la date de fin prévisionnelle de position. | BP4: POS_C_005 | BQ4: =VLOOKUP(BP4,'Axe 2 Règles de gestion'!$D$2:$F$408,3, FALSE) -> La date de début de la position doit être postérieure ou égale à la date d'entrée dans la FPE ou dans la carrière militaire. | BR4: POS_C_007 | BS4: =VLOOKUP(BR4,'Axe 2 Règles de gestion'!$D$2:$F$408,3, FALSE) -> La date de fin réelle de la position doit être antérieure à la date limite de départ à la retraite. | BT4: POS_C_010 | BU4: =VLOOKUP(BT4,'Axe 2 Règles de gestion'!$D$2:$F$408,3, FALSE) -> La date de début de position doit être antérieure ou égale à la date de fin réelle de position. | BV4: POS_C_012 | BW4: =VLOOKUP(BV4,'Axe 2 Règles de gestion'!$D$2:$F$408,3, FALSE) -> La date de fin prévisionnelle de la position doit être antérieure à la date limite de départ à la retraite. | BX4: POS_C_022 | BY4: =VLOOKUP(BX4,'Axe 2 Règles de gestion'!$D$2:$F$408,3, FALSE) -> La date de début de position est à J+1 de la date de fin de position de l'occurrence précédente. | BZ4: POS_C_111 | CA4: =VLOOKUP(BZ4,'Axe 2 Règles de gestion'!$D$2:$F$408,3, FALSE) -> La date de fin ou la date de fin prévisionnelle doit être saisie.
A5: 25.00.00 | B5: M | C5: 45803.683 | D5: D0004 | E5: Position | F5: S0012 | G5: Disponibilité | H5: E0161 | I5: Disponibilité sur demande pour donner des soins au conjoint ou au partenaire pacsé suite à accident/maladie grave | J5: Position saisie égale à 'Disponibilité sur demande pour donner des soins au conjoint ou au partenaire pacsé suite à accident/maladie grave' ET Indicateur de maintien saisi = Non | K5: A_POS_POSIAD [Saisi] = 'DSP36' ET A_POS_INDMAI [Saisi] = '0' | L5: T0472 | M5: Disponibilité sur demande pour donner des soins au conjoint ou au partenaire pacsé suite à accident/maladie grave - Renouvellement | N5: Création Modification | O5: Indicateur de renouvellement saisi = Oui ET (Indicateur de renouvellement saisi différent d'Indicateur de renouvellement avant saisi OU Indicateur de maintien saisi différent de Indicateur de maintien avant saisi) | P5: A_POS_INDREN [Saisi] = '1' ET (A_POS_INDREN [Saisi] <> A_POS_INDREN [Valeur avant saisie] OU A_POS_INDMAI [Saisi] <> A_POS_INDMAI [Valeur avant saisie]) | Q5: Titulaire ou magistrat | R5: P0001 | S5: Général | T5: Passant | U5: 43350 | W5: DIS_I_171 ET DIS_I_178 ET DIS_D_011 ET DIS_D_400 ET DIS_D_506 ET DIS_D_613 ET DIS_D_616 ET POS_C_004 ET POS_C_005 ET POS_C_007 ET POS_C_010 ET POS_C_012 ET POS_C_022 ET POS_C_111 ET POS_C_120 ET POS_C_121 | X5: DIS_I_171 | Y5: =VLOOKUP(X5,'Axe 2 Règles de gestion'!$D$2:$F$408,3, FALSE) -> L'agent doit informer son administration d'origine de sa décision de solliciter le renouvellement de sa disponibilité 3 mois au moins avant l'expiration de la disponibilité. | Z5: DIS_I_178 | AA5: =VLOOKUP(Z5,'Axe 2 Règles de gestion'!$D$2:$F$408,3, FALSE) -> L'administration fait procéder aux enquêtes nécessaires en vue de s'assurer que l'activité de l'agent mis en disponibilité correspond réellement aux motifs pour lesquels il a été placé en cette position. | AP5: DIS_D_011 | AQ5: =VLOOKUP(AP5,'Axe 2 Règles de gestion'!$D$2:$F$408,3, FALSE) -> La durée prévisionnelle de la disponibilité ne peut pas excéder 3 ans pour chaque période. | AR5: DIS_D_400 | AS5: =VLOOKUP(AR5,'Axe 2 Règles de gestion'!$D$2:$F$408,3, FALSE) -> La durée réelle de la disponibilité ne peut pas excéder 3 ans pour chaque période. | AT5: DIS_D_506 | AU5: =VLOOKUP(AT5,'Axe 2 Règles de gestion'!$D$2:$F$408,3, FALSE) -> Le type de situation de famille de l'agent doit être "marié(e)" ou "pacsé(e)". | AV5: DIS_D_613 | AW5: =VLOOKUP(AV5,'Axe 2 Règles de gestion'!$D$2:$F$408,3, FALSE) -> L'agent a épuisé ses droits à ancienneté relatifs à la disponibilité. En effet, l'agent en disponibilité pour études ou recherches, convenances personnelles, créer ou reprendre une entreprise, donner des soins, suivre son conjoint ou partenaire de PACS conserve ses droits à l'avancement (échelon et grade) dans la limite de 5 ans s'il exerce une activité professionnelle. | AX5: DIS_D_616 | AY5: =VLOOKUP(AX5,'Axe 2 Règles de gestion'!$D$2:$F$408,3, FALSE) -> Si le champ « Situation particulière » est saisi, alors seule la valeur « Période de disponibilité donnant droit à avancement » peut être sélectionnée. | BN5: POS_C_004 | BO5: =VLOOKUP(BN5,'Axe 2 Règles de gestion'!$D$2:$F$408,3, FALSE) -> La date de début de position doit être antérieure ou égale à la date de fin prévisionnelle de position. | BP5: POS_C_005 | BQ5: =VLOOKUP(BP5,'Axe 2 Règles de gestion'!$D$2:$F$408,3, FALSE) -> La date de début de la position doit être postérieure ou égale à la date d'entrée dans la FPE ou dans la carrière militaire. | BR5: POS_C_007 | BS5: =VLOOKUP(BR5,'Axe 2 Règles de gestion'!$D$2:$F$408,3, FALSE) -> La date de fin réelle de la position doit être antérieure à la date limite de départ à la retraite. | BT5: POS_C_010 | BU5: =VLOOKUP(BT5,'Axe 2 Règles de gestion'!$D$2:$F$408,3, FALSE) -> La date de début de position doit être antérieure ou égale à la date de fin réelle de position. | BV5: POS_C_012 | BW5: =VLOOKUP(BV5,'Axe 2 Règles de gestion'!$D$2:$F$408,3, FALSE) -> La date de fin prévisionnelle de la position doit être antérieure à la date limite de départ à la retraite. | BX5: POS_C_022 | BY5: =VLOOKUP(BX5,'Axe 2 Règles de gestion'!$D$2:$F$408,3, FALSE) -> La date de début de position est à J+1 de la date de fin de position de l'occurrence précédente. | BZ5: POS_C_111 | CA5: =VLOOKUP(BZ5,'Axe 2 Règles de gestion'!$D$2:$F$408,3, FALSE) -> La date de fin ou la date de fin prévisionnelle doit être saisie. | CB5: POS_C_120 | CC5: =VLOOKUP(CB5,'Axe 2 Règles de gestion'!$D$2:$F$408,3, FALSE) -> La saisie d'une occurrence de congés/absences est interdite (date de fin réelle) | CD5: POS_C_121 | CE5: =VLOOKUP(CD5,'Axe 2 Règles de gestion'!$D$2:$F$408,3, FALSE) -> La saisie d'une occurrence de congés/absences est interdite (date de fin prévisionnelle)
A6: 20.10.00 | B6: M | C6: 43152.5 | D6: D0004 | E6: Position | F6: S0012 | G6: Disponibilité | H6: E0161 | I6: Disponibilité sur demande pour donner des soins au conjoint ou au partenaire pacsé suite à accident/maladie grave | J6: Position saisie égale à 'Disponibilité sur demande pour donner des soins au conjoint ou au partenaire pacsé suite à accident/maladie grave' ET Indicateur de maintien saisi = Non | K6: A_POS_POSIAD [Saisi] = 'DSP36' ET A_POS_INDMAI [Saisi] = '0' | L6: T0473 | M6: Disponibilité sur demande pour donner des soins au conjoint ou au partenaire pacsé suite à accident/maladie grave - Réintégration | N6: Modification | O6: Indicateur de renouvellement saisi identique à Indicateur de renouvellement avant saisi ET Indicateur de maintien saisi identique à Indicateur de maintien avant saisi | P6: A_POS_INDREN [Saisi] = A_POS_INDREN [Valeur avant saisie] ET A_POS_INDMAI [Saisi] = A_POS_INDMAI [Valeur avant saisie] | Q6: Titulaire ou magistrat | R6: P0001 | S6: Général | T6: Passant | U6: 40725 | V6: 43349 | W6: DIS_I_034 ET DIS_I_036 ET DIS_I_037 ET DIS_D_011 ET DIS_D_400 ET DIS_D_506 ET POS_C_004 ET POS_C_007 ET POS_C_010 ET POS_C_012 ET POS_C_111 | X6: DIS_I_034 | Y6: =VLOOKUP(X6,'Axe 2 Règles de gestion'!$D$2:$F$408,3, FALSE) -> L'agent doit informer son administration d'origine de sa décision de solliciter le renouvellement de sa disponibilité ou de réintégrer son corps d'origine 3 mois au moins avant l'expiration de la disponibilité. | Z6: DIS_I_036 | AA6: =VLOOKUP(Z6,'Axe 2 Règles de gestion'!$D$2:$F$408,3, FALSE) -> La réintégration est subordonnée à la vérification par un médecin agréé et, éventuellement, par le comité médical compétent, de l'aptitude physique de l'agent à l'exercice des fonctions afférentes à son grade. | AB6: DIS_I_037 | AC6: =VLOOKUP(AB6,'Axe 2 Règles de gestion'!$D$2:$F$408,3, FALSE) -> L'agent qui ne peut être réintégré pour cause d'inaptitude physique est soit reclassé, soit mis en disponibilité d'office. En cas d'inaptitude définitive à l'exercice de ses fonctions, l'agent est admis à la retraite ou licencié. | AP6: DIS_D_011 | AQ6: =VLOOKUP(AP6,'Axe 2 Règles de gestion'!$D$2:$F$408,3, FALSE) -> La durée prévisionnelle de la disponibilité ne peut pas excéder 3 ans pour chaque période. | AR6: DIS_D_400 | AS6: =VLOOKUP(AR6,'Axe 2 Règles de gestion'!$D$2:$F$408,3, FALSE) -> La durée réelle de la disponibilité ne peut pas excéder 3 ans pour chaque période. | AT6: DIS_D_506 | AU6: =VLOOKUP(AT6,'Axe 2 Règles de gestion'!$D$2:$F$408,3, FALSE) -> Le type de situation de famille de l'agent doit être "marié(e)" ou "pacsé(e)". | BN6: POS_C_004 | BO6: =VLOOKUP(BN6,'Axe 2 Règles de gestion'!$D$2:$F$408,3, FALSE) -> La date de début de position doit être antérieure ou égale à la date de fin prévisionnelle de position. | BP6: POS_C_007 | BQ6: =VLOOKUP(BP6,'Axe 2 Règles de gestion'!$D$2:$F$408,3, FALSE) -> La date de fin réelle de la position doit être antérieure à la date limite de départ à la retraite. | BR6: POS_C_010 | BS6: =VLOOKUP(BR6,'Axe 2 Règles de gestion'!$D$2:$F$408,3, FALSE) -> La date de début de position doit être antérieure ou égale à la date de fin réelle de position. | BT6: POS_C_012 | BU6: =VLOOKUP(BT6,'Axe 2 Règles de gestion'!$D$2:$F$408,3, FALSE) -> La date de fin prévisionnelle de la position doit être antérieure à la date limite de départ à la retraite. | BV6: POS_C_111 | BW6: =VLOOKUP(BV6,'Axe 2 Règles de gestion'!$D$2:$F$408,3, FALSE) -> La date de fin ou la date de fin prévisionnelle doit être saisie.
A7: 22.00.00 | B7: M | C7: 44713.814 | D7: D0004 | E7: Position | F7: S0012 | G7: Disponibilité | H7: E0161 | I7: Disponibilité sur demande pour donner des soins au conjoint ou au partenaire pacsé suite à accident/maladie grave | J7: Position saisie égale à 'Disponibilité sur demande pour donner des soins au conjoint ou au partenaire pacsé suite à accident/maladie grave' ET Indicateur de maintien saisi = Non | K7: A_POS_POSIAD [Saisi] = 'DSP36' ET A_POS_INDMAI [Saisi] = '0' | L7: T0473 | M7: Disponibilité sur demande pour donner des soins au conjoint ou au partenaire pacsé suite à accident/maladie grave - Réintégration | N7: Modification | O7: Indicateur de renouvellement saisi identique à Indicateur de renouvellement avant saisi ET Indicateur de maintien saisi identique à Indicateur de maintien avant saisi | P7: A_POS_INDREN [Saisi] = A_POS_INDREN [Valeur avant saisie] ET A_POS_INDMAI [Saisi] = A_POS_INDMAI [Valeur avant saisie] | Q7: Titulaire ou magistrat | R7: P0001 | S7: Général | T7: Passant | U7: 43350 | V7: 44633 | W7: DIS_I_034 ET DIS_I_036 ET DIS_I_037 ET DIS_D_011 ET DIS_D_400 ET DIS_D_506 ET DIS_D_613 ET DIS_D_616 ET POS_C_004 ET POS_C_007 ET POS_C_010 ET POS_C_012 ET POS_C_111 ET POS_C_120 ET POS_C_121 | X7: DIS_I_034 | Y7: =VLOOKUP(X7,'Axe 2 Règles de gestion'!$D$2:$F$408,3, FALSE) -> L'agent doit informer son administration d'origine de sa décision de solliciter le renouvellement de sa disponibilité ou de réintégrer son corps d'origine 3 mois au moins avant l'expiration de la disponibilité. | Z7: DIS_I_036 | AA7: =VLOOKUP(Z7,'Axe 2 Règles de gestion'!$D$2:$F$408,3, FALSE) -> La réintégration est subordonnée à la vérification par un médecin agréé et, éventuellement, par le comité médical compétent, de l'aptitude physique de l'agent à l'exercice des fonctions afférentes à son grade. | AB7: DIS_I_037 | AC7: =VLOOKUP(AB7,'Axe 2 Règles de gestion'!$D$2:$F$408,3, FALSE) -> L'agent qui ne peut être réintégré pour cause d'inaptitude physique est soit reclassé, soit mis en disponibilité d'office. En cas d'inaptitude définitive à l'exercice de ses fonctions, l'agent est admis à la retraite ou licencié. | AP7: DIS_D_011 | AQ7: =VLOOKUP(AP7,'Axe 2 Règles de gestion'!$D$2:$F$408,3, FALSE) -> La durée prévisionnelle de la disponibilité ne peut pas excéder 3 ans pour chaque période. | AR7: DIS_D_400 | AS7: =VLOOKUP(AR7,'Axe 2 Règles de gestion'!$D$2:$F$408,3, FALSE) -> La durée réelle de la disponibilité ne peut pas excéder 3 ans pour chaque période. | AT7: DIS_D_506 | AU7: =VLOOKUP(AT7,'Axe 2 Règles de gestion'!$D$2:$F$408,3, FALSE) -> Le type de situation de famille de l'agent doit être "marié(e)" ou "pacsé(e)". | AV7: DIS_D_613 | AW7: =VLOOKUP(AV7,'Axe 2 Règles de gestion'!$D$2:$F$408,3, FALSE) -> L'agent a épuisé ses droits à ancienneté relatifs à la disponibilité. En effet, l'agent en disponibilité pour études ou recherches, convenances personnelles, créer ou reprendre une entreprise, donner des soins, suivre son conjoint ou partenaire de PACS conserve ses droits à l'avancement (échelon et grade) dans la limite de 5 ans s'il exerce une activité professionnelle. | AX7: DIS_D_616 | AY7: =VLOOKUP(AX7,'Axe 2 Règles de gestion'!$D$2:$F$408,3, FALSE) -> Si le champ « Situation particulière » est saisi, alors seule la valeur « Période de disponibilité donnant droit à avancement » peut être sélectionnée. | BN7: POS_C_004 | BO7: =VLOOKUP(BN7,'Axe 2 Règles de gestion'!$D$2:$F$408,3, FALSE) -> La date de début de position doit être antérieure ou égale à la date de fin prévisionnelle de position. | BP7: POS_C_007 | BQ7: =VLOOKUP(BP7,'Axe 2 Règles de gestion'!$D$2:$F$408,3, FALSE) -> La date de fin réelle de la position doit être antérieure à la date limite de départ à la retraite. | BR7: POS_C_010 | BS7: =VLOOKUP(BR7,'Axe 2 Règles de gestion'!$D$2:$F$408,3, FALSE) -> La date de début de position doit être antérieure ou égale à la date de fin réelle de position. | BT7: POS_C_012 | BU7: =VLOOKUP(BT7,'Axe 2 Règles de gestion'!$D$2:$F$408,3, FALSE) -> La date de fin prévisionnelle de la position doit être antérieure à la date limite de départ à la retraite. | BV7: POS_C_111 | BW7: =VLOOKUP(BV7,'Axe 2 Règles de gestion'!$D$2:$F$408,3, FALSE) -> La date de fin ou la date de fin prévisionnelle doit être saisie. | BX7: POS_C_120 | BY7: =VLOOKUP(BX7,'Axe 2 Règles de gestion'!$D$2:$F$408,3, FALSE) -> La saisie d'une occurrence de congés/absences est interdite (date de fin réelle) | BZ7: POS_C_121 | CA7: =VLOOKUP(BZ7,'Axe 2 Règles de gestion'!$D$2:$F$408,3, FALSE) -> La saisie d'une occurrence de congés/absences est interdite (date de fin prévisionnelle)
A8: 25.00.00 | B8: M | C8: 45803.684 | D8: D0004 | E8: Position | F8: S0012 | G8: Disponibilité | H8: E0161 | I8: Disponibilité sur demande pour donner des soins au conjoint ou au partenaire pacsé suite à accident/maladie grave | J8: Position saisie égale à 'Disponibilité sur demande pour donner des soins au conjoint ou au partenaire pacsé suite à accident/maladie grave' ET Indicateur de maintien saisi = Non | K8: A_POS_POSIAD [Saisi] = 'DSP36' ET A_POS_INDMAI [Saisi] = '0' | L8: T0473 | M8: Disponibilité sur demande pour donner des soins au conjoint ou au partenaire pacsé suite à accident/maladie grave - Réintégration | N8: Modification | O8: Indicateur de renouvellement saisi identique à Indicateur de renouvellement avant saisi ET Indicateur de maintien saisi identique à Indicateur de maintien avant saisi | P8: A_POS_INDREN [Saisi] = A_POS_INDREN [Valeur avant saisie] ET A_POS_INDMAI [Saisi] = A_POS_INDMAI [Valeur avant saisie] | Q8: Titulaire ou magistrat | R8: P0001 | S8: Général | T8: Passant | U8: 44634 | W8: DIS_I_172 ET DIS_I_149 ET DIS_I_037 ET DIS_I_173 ET DIS_I_176 ET DIS_I_177 ET DIS_D_011 ET DIS_D_400 ET DIS_D_506 ET DIS_D_613 ET DIS_D_616 ET POS_C_004 ET POS_C_007 ET POS_C_010 ET POS_C_012 ET POS_C_111 ET POS_C_120 ET POS_C_121 | X8: DIS_I_172 | Y8: =VLOOKUP(X8,'Axe 2 Règles de gestion'!$D$2:$F$408,3, FALSE) -> L'agent doit informer son administration d'origine de sa décision de réintégrer son corps d'origine 3 mois au moins avant l'expiration de la disponibilité. | Z8: DIS_I_149 | AA8: =VLOOKUP(Z8,'Axe 2 Règles de gestion'!$D$2:$F$408,3, FALSE) -> Lorsque les fonctions requièrent des conditions de santé particulières, la réintégration est subordonnée à la vérification du respect de ces conditions par un médecin agréé et, éventuellement, par le conseil médical compétent. | AB8: DIS_I_037 | AC8: =VLOOKUP(AB8,'Axe 2 Règles de gestion'!$D$2:$F$408,3, FALSE) -> L'agent qui ne peut être réintégré pour cause d'inaptitude physique est soit reclassé, soit mis en disponibilité d'office. En cas d'inaptitude définitive à l'exercice de ses fonctions, l'agent est admis à la retraite ou licencié. | AD8: DIS_I_173 | AE8: =VLOOKUP(AD8,'Axe 2 Règles de gestion'!$D$2:$F$408,3, FALSE) -> L'agent qui a formulé avant l'expiration de la période de mise en disponibilité une demande de réintégration est maintenu en disponibilité jusqu'à ce qu'un poste lui soit proposé. | AF8: DIS_I_176 | AG8: =VLOOKUP(AF8,'Axe 2 Règles de gestion'!$D$2:$F$408,3, FALSE) -> A l'issue de sa disponibilité ou avant cette date, s'il sollicite sa réintégration anticipée, l'agent est obligatoirement réintégré à la première vacance dans son corps d'origine et affecté à un emploi correspondant à son grade. | AH8: DIS_I_177 | AI8: =VLOOKUP(AH8,'Axe 2 Règles de gestion'!$D$2:$F$408,3, FALSE) -> S'il refuse le poste, il peut être licencié après avis de la commission administrative paritaire. | AP8: DIS_D_011 | AQ8: =VLOOKUP(AP8,'Axe 2 Règles de gestion'!$D$2:$F$408,3, FALSE) -> La durée prévisionnelle de la disponibilité ne peut pas excéder 3 ans pour chaque période. | AR8: DIS_D_400 | AS8: =VLOOKUP(AR8,'Axe 2 Règles de gestion'!$D$2:$F$408,3, FALSE) -> La durée réelle de la disponibilité ne peut pas excéder 3 ans pour chaque période. | AT8: DIS_D_506 | AU8: =VLOOKUP(AT8,'Axe 2 Règles de gestion'!$D$2:$F$408,3, FALSE) -> Le type de situation de famille de l'agent doit être "marié(e)" ou "pacsé(e)". | AV8: DIS_D_613 | AW8: =VLOOKUP(AV8,'Axe 2 Règles de gestion'!$D$2:$F$408,3, FALSE) -> L'agent a épuisé ses droits à ancienneté relatifs à la disponibilité. En effet, l'agent en disponibilité pour études ou recherches, convenances personnelles, créer ou reprendre une entreprise, donner des soins, suivre son conjoint ou partenaire de PACS conserve ses droits à l'avancement (échelon et grade) dans la limite de 5 ans s'il exerce une activité professionnelle. | AX8: DIS_D_616 | AY8: =VLOOKUP(AX8,'Axe 2 Règles de gestion'!$D$2:$F$408,3, FALSE) -> Si le champ « Situation particulière » est saisi, alors seule la valeur « Période de disponibilité donnant droit à avancement » peut être sélectionnée. | BN8: POS_C_004 | BO8: =VLOOKUP(BN8,'Axe 2 Règles de gestion'!$D$2:$F$408,3, FALSE) -> La date de début de position doit être antérieure ou égale à la date de fin prévisionnelle de position. | BP8: POS_C_007 | BQ8: =VLOOKUP(BP8,'Axe 2 Règles de gestion'!$D$2:$F$408,3, FALSE) -> La date de fin réelle de la position doit être antérieure à la date limite de départ à la retraite. | BR8: POS_C_010 | BS8: =VLOOKUP(BR8,'Axe 2 Règles de gestion'!$D$2:$F$408,3, FALSE) -> La date de début de position doit être antérieure ou égale à la date de fin réelle de position. | BT8: POS_C_012 | BU8: =VLOOKUP(BT8,'Axe 2 Règles de gestion'!$D$2:$F$408,3, FALSE) -> La date de fin prévisionnelle de la position doit être antérieure à la date limite de départ à la retraite. | BV8: POS_C_111 | BW8: =VLOOKUP(BV8,'Axe 2 Règles de gestion'!$D$2:$F$408,3, FALSE) -> La date de fin ou la date de fin prévisionnelle doit être saisie. | BX8: POS_C_120 | BY8: =VLOOKUP(BX8,'Axe 2 Règles de gestion'!$D$2:$F$408,3, FALSE) -> La saisie d'une occurrence de congés/absences est interdite (date de fin réelle) | BZ8: POS_C_121 | CA8: =VLOOKUP(BZ8,'Axe 2 Règles de gestion'!$D$2:$F$408,3, FALSE) -> La saisie d'une occurrence de congés/absences est interdite (date de fin prévisionnelle)
A9: 17.10.00 | B9: A | C9: 43152.5 | D9: D0004 | E9: Position | F9: S0012 | G9: Disponibilité | H9: E0161 | I9: Disponibilité sur demande pour donner des soins au conjoint ou au partenaire pacsé suite à accident/maladie grave | J9: Position saisie égale à 'Disponibilité sur demande pour donner des soins au conjoint ou au partenaire pacsé suite à accident/maladie grave' ET Indicateur de maintien saisi = Non | K9: A_POS_POSIAD [Saisi] = 'DSP36' ET A_POS_INDMAI [Saisi] = '0' | L9: T0471 | M9: Disponibilité sur demande pour donner des soins au conjoint ou au partenaire pacsé suite à accident/maladie grave - Demande | N9: Création Modification | O9: Indicateur de renouvellement saisi = Non ET (Indicateur de renouvellement saisi différent d'Indicateur de renouvellement avant saisi OU Indicateur de maintien saisi différent de Indicateur de maintien avant saisi) | P9: A_POS_INDREN [Saisi] = '0' ET (A_POS_INDREN [Saisi] <> A_POS_INDREN [Valeur avant saisie] OU A_POS_INDMAI [Saisi] <> A_POS_INDMAI [Valeur avant saisie]) | Q9: Militaire | R9: P0002 | S9: Général | T9: Exclu | U9: 40725
A10: 17.10.00 | B10: M | C10: 43152.5 | D10: D0004 | E10: Position | F10: S0012 | G10: Disponibilité | H10: E0161 | I10: Disponibilité sur demande pour donner des soins au conjoint ou au partenaire pacsé suite à accident/maladie grave | J10: Position saisie égale à 'Disponibilité sur demande pour donner des soins au conjoint ou au partenaire pacsé suite à accident/maladie grave' ET Indicateur de maintien saisi = Non | K10: A_POS_POSIAD [Saisi] = 'DSP36' ET A_POS_INDMAI [Saisi] = '0' | L10: T0472 | M10: Disponibilité sur demande pour donner des soins au conjoint ou au partenaire pacsé suite à accident/maladie grave - Renouvellement | N10: Création Modification | O10: Indicateur de renouvellement saisi = Oui ET (Indicateur de renouvellement saisi différent d'Indicateur de renouvellement avant saisi OU Indicateur de maintien saisi différent de Indicateur de maintien avant saisi) | P10: A_POS_INDREN [Saisi] = '1' ET (A_POS_INDREN [Saisi] <> A_POS_INDREN [Valeur avant saisie] OU A_POS_INDMAI [Saisi] <> A_POS_INDMAI [Valeur avant saisie]) | Q10: Militaire | R10: P0002 | S10: Général | T10: Exclu | U10: 40725
A11: 17.10.00 | B11: A | C11: 43152.5 | D11: D0004 | E11: Position | F11: S0012 | G11: Disponibilité | H11: E0161 | I11: Disponibilité sur demande pour donner des soins au conjoint ou au partenaire pacsé suite à accident/maladie grave | J11: Position saisie égale à 'Disponibilité sur demande pour donner des soins au conjoint ou au partenaire pacsé suite à accident/maladie grave' ET Indicateur de maintien saisi = Non | K11: A_POS_POSIAD [Saisi] = 'DSP36' ET A_POS_INDMAI [Saisi] = '0' | L11: T0473 | M11: Disponibilité sur demande pour donner des soins au conjoint ou au partenaire pacsé suite à accident/maladie grave - Réintégration | N11: Modification | O11: Indicateur de renouvellement saisi identique à Indicateur de renouvellement avant saisi ET Indicateur de maintien saisi identique à Indicateur de maintien avant saisi | P11: A_POS_INDREN [Saisi] = A_POS_INDREN [Valeur avant saisie] ET A_POS_INDMAI [Saisi] = A_POS_INDMAI [Valeur avant saisie] | Q11: Militaire | R11: P0002 | S11: Général | T11: Exclu | U11: 40725
A12: 17.10.00 | B12: A | C12: 43152.5 | D12: D0004 | E12: Position | F12: S0012 | G12: Disponibilité | H12: E0161 | I12: Disponibilité sur demande pour donner des soins au conjoint ou au partenaire pacsé suite à accident/maladie grave | J12: Position saisie égale à 'Disponibilité sur demande pour donner des soins au conjoint ou au partenaire pacsé suite à accident/maladie grave' ET Indicateur de maintien saisi = Non | K12: A_POS_POSIAD [Saisi] = 'DSP36' ET A_POS_INDMAI [Saisi] = '0' | L12: T0471 | M12: Disponibilité sur demande pour donner des soins au conjoint ou au partenaire pacsé suite à accident/maladie grave - Demande | N12: Création Modification | O12: Indicateur de renouvellement saisi = Non ET (Indicateur de renouvellement saisi différent d'Indicateur de renouvellement avant saisi OU Indicateur de maintien saisi différent de Indicateur de maintien avant saisi) | P12: A_POS_INDREN [Saisi] = '0' ET (A_POS_INDREN [Saisi] <> A_POS_INDREN [Valeur avant saisie] OU A_POS_INDMAI [Saisi] <> A_POS_INDMAI [Valeur avant saisie]) | Q12: Contractuel | R12: P0003 | S12: Général | T12: Exclu | U12: 40725
A13: 17.10.00 | B13: A | C13: 43152.5 | D13: D0004 | E13: Position | F13: S0012 | G13: Disponibilité | H13: E0161 | I13: Disponibilité sur demande pour donner des soins au conjoint ou au partenaire pacsé suite à accident/maladie grave | J13: Position saisie égale à 'Disponibilité sur demande pour donner des soins au conjoint ou au partenaire pacsé suite à accident/maladie grave' ET Indicateur de maintien saisi = Non | K13: A_POS_POSIAD [Saisi] = 'DSP36' ET A_POS_INDMAI [Saisi] = '0' | L13: T0472 | M13: Disponibilité sur demande pour donner des soins au conjoint ou au partenaire pacsé suite à accident/maladie grave - Renouvellement | N13: Création Modification | O13: Indicateur de renouvellement saisi = Oui ET (Indicateur de renouvellement saisi différent d'Indicateur de renouvellement avant saisi OU Indicateur de maintien saisi différent de Indicateur de maintien avant saisi) | P13: A_POS_INDREN [Saisi] = '1' ET (A_POS_INDREN [Saisi] <> A_POS_INDREN [Valeur avant saisie] OU A_POS_INDMAI [Saisi] <> A_POS_INDMAI [Valeur avant saisie]) | Q13: Contractuel | R13: P0003 | S13: Général | T13: Exclu | U13: 40725
A14: 17.10.00 | B14: A | C14: 43152.5 | D14: D0004 | E14: Position | F14: S0012 | G14: Disponibilité | H14: E0161 | I14: Disponibilité sur demande pour donner des soins au conjoint ou au partenaire pacsé suite à accident/maladie grave | J14: Position saisie égale à 'Disponibilité sur demande pour donner des soins au conjoint ou au partenaire pacsé suite à accident/maladie grave' ET Indicateur de maintien saisi = Non | K14: A_POS_POSIAD [Saisi] = 'DSP36' ET A_POS_INDMAI [Saisi] = '0' | L14: T0473 | M14: Disponibilité sur demande pour donner des soins au conjoint ou au partenaire pacsé suite à accident/maladie grave - Réintégration | N14: Modification | O14: Indicateur de renouvellement saisi identique à Indicateur de renouvellement avant saisi ET Indicateur de maintien saisi identique à Indicateur de maintien avant saisi | P14: A_POS_INDREN [Saisi] = A_POS_INDREN [Valeur avant saisie] ET A_POS_INDMAI [Saisi] = A_POS_INDMAI [Valeur avant saisie] | Q14: Contractuel | R14: P0003 | S14: Général | T14: Exclu | U14: 40725
A15: 17.10.00 | B15: A | C15: 43152.5 | D15: D0004 | E15: Position | F15: S0012 | G15: Disponibilité | H15: E0161 | I15: Disponibilité sur demande pour donner des soins au conjoint ou au partenaire pacsé suite à accident/maladie grave | J15: Position saisie égale à 'Disponibilité sur demande pour donner des soins au conjoint ou au partenaire pacsé suite à accident/maladie grave' ET Indicateur de maintien saisi = Non | K15: A_POS_POSIAD [Saisi] = 'DSP36' ET A_POS_INDMAI [Saisi] = '0' | L15: T0471 | M15: Disponibilité sur demande pour donner des soins au conjoint ou au partenaire pacsé suite à accident/maladie grave - Demande | N15: Création Modification | O15: Indicateur de renouvellement saisi = Non ET (Indicateur de renouvellement saisi différent d'Indicateur de renouvellement avant saisi OU Indicateur de maintien saisi différent de Indicateur de maintien avant saisi) | P15: A_POS_INDREN [Saisi] = '0' ET (A_POS_INDREN [Saisi] <> A_POS_INDREN [Valeur avant saisie] OU A_POS_INDMAI [Saisi] <> A_POS_INDMAI [Valeur avant saisie]) | Q15: Stagiaire ou auditeur ou élève | R15: P0004 | S15: Général | T15: Exclu | U15: 40725
A16: 17.10.00 | B16: A | C16: 43152.5 | D16: D0004 | E16: Position | F16: S0012 | G16: Disponibilité | H16: E0161 | I16: Disponibilité sur demande pour donner des soins au conjoint ou au partenaire pacsé suite à accident/maladie grave | J16: Position saisie égale à 'Disponibilité sur demande pour donner des soins au conjoint ou au partenaire pacsé suite à accident/maladie grave' ET Indicateur de maintien saisi = Non | K16: A_POS_POSIAD [Saisi] = 'DSP36' ET A_POS_INDMAI [Saisi] = '0' | L16: T0472 | M16: Disponibilité sur demande pour donner des soins au conjoint ou au partenaire pacsé suite à accident/maladie grave - Renouvellement | N16: Création Modification | O16: Indicateur de renouvellement saisi = Oui ET (Indicateur de renouvellement saisi différent d'Indicateur de renouvellement avant saisi OU Indicateur de maintien saisi différent de Indicateur de maintien avant saisi) | P16: A_POS_INDREN [Saisi] = '1' ET (A_POS_INDREN [Saisi] <> A_POS_INDREN [Valeur avant saisie] OU A_POS_INDMAI [Saisi] <> A_POS_INDMAI [Valeur avant saisie]) | Q16: Stagiaire ou auditeur ou élève | R16: P0004 | S16: Général | T16: Exclu | U16: 40725
A17: 17.10.00 | B17: A | C17: 43152.5 | D17: D0004 | E17: Position | F17: S0012 | G17: Disponibilité | H17: E0161 | I17: Disponibilité sur demande pour donner des soins au conjoint ou au partenaire pacsé suite à accident/maladie grave | J17: Position saisie égale à 'Disponibilité sur demande pour donner des soins au conjoint ou au partenaire pacsé suite à accident/maladie grave' ET Indicateur de maintien saisi = Non | K17: A_POS_POSIAD [Saisi] = 'DSP36' ET A_POS_INDMAI [Saisi] = '0' | L17: T0473 | M17: Disponibilité sur demande pour donner des soins au conjoint ou au partenaire pacsé suite à accident/maladie grave - Réintégration | N17: Modification | O17: Indicateur de renouvellement saisi identique à Indicateur de renouvellement avant saisi ET Indicateur de maintien saisi identique à Indicateur de maintien avant saisi | P17: A_POS_INDREN [Saisi] = A_POS_INDREN [Valeur avant saisie] ET A_POS_INDMAI [Saisi] = A_POS_INDMAI [Valeur avant saisie] | Q17: Stagiaire ou auditeur ou élève | R17: P0004 | S17: Général | T17: Exclu | U17: 40725
A18: 17.10.00 | B18: A | C18: 43152.5 | D18: D0004 | E18: Position | F18: S0012 | G18: Disponibilité | H18: E0161 | I18: Disponibilité sur demande pour donner des soins au conjoint ou au partenaire pacsé suite à accident/maladie grave | J18: Position saisie égale à 'Disponibilité sur demande pour donner des soins au conjoint ou au partenaire pacsé suite à accident/maladie grave' ET Indicateur de maintien saisi = Non | K18: A_POS_POSIAD [Saisi] = 'DSP36' ET A_POS_INDMAI [Saisi] = '0' | L18: T0471 | M18: Disponibilité sur demande pour donner des soins au conjoint ou au partenaire pacsé suite à accident/maladie grave - Demande | N18: Création Modification | O18: Indicateur de renouvellement saisi = Non ET (Indicateur de renouvellement saisi différent d'Indicateur de renouvellement avant saisi OU Indicateur de maintien saisi différent de Indicateur de maintien avant saisi) | P18: A_POS_INDREN [Saisi] = '0' ET (A_POS_INDREN [Saisi] <> A_POS_INDREN [Valeur avant saisie] OU A_POS_INDMAI [Saisi] <> A_POS_INDMAI [Valeur avant saisie]) | Q18: Ouvrier d'état | R18: P0005 | S18: Général | T18: Exclu | U18: 40725
A19: 17.10.00 | B19: A | C19: 43152.5 | D19: D0004 | E19: Position | F19: S0012 | G19: Disponibilité | H19: E0161 | I19: Disponibilité sur demande pour donner des soins au conjoint ou au partenaire pacsé suite à accident/maladie grave | J19: Position saisie égale à 'Disponibilité sur demande pour donner des soins au conjoint ou au partenaire pacsé suite à accident/maladie grave' ET Indicateur de maintien saisi = Non | K19: A_POS_POSIAD [Saisi] = 'DSP36' ET A_POS_INDMAI [Saisi] = '0' | L19: T0472 | M19: Disponibilité sur demande pour donner des soins au conjoint ou au partenaire pacsé suite à accident/maladie grave - Renouvellement | N19: Création Modification | O19: Indicateur de renouvellement saisi = Oui ET (Indicateur de renouvellement saisi différent d'Indicateur de renouvellement avant saisi OU Indicateur de maintien saisi différent de Indicateur de maintien avant saisi) | P19: A_POS_INDREN [Saisi] = '1' ET (A_POS_INDREN [Saisi] <> A_POS_INDREN [Valeur avant saisie] OU A_POS_INDMAI [Saisi] <> A_POS_INDMAI [Valeur avant saisie]) | Q19: Ouvrier d'état | R19: P0005 | S19: Général | T19: Exclu | U19: 40725
A20: 17.10.00 | B20: A | C20: 43152.5 | D20: D0004 | E20: Position | F20: S0012 | G20: Disponibilité | H20: E0161 | I20: Disponibilité sur demande pour donner des soins au conjoint ou au partenaire pacsé suite à accident/maladie grave | J20: Position saisie égale à 'Disponibilité sur demande pour donner des soins au conjoint ou au partenaire pacsé suite à accident/maladie grave' ET Indicateur de maintien saisi = Non | K20: A_POS_POSIAD [Saisi] = 'DSP36' ET A_POS_INDMAI [Saisi] = '0' | L20: T0473 | M20: Disponibilité sur demande pour donner des soins au conjoint ou au partenaire pacsé suite à accident/maladie grave - Réintégration | N20: Modification | O20: Indicateur de renouvellement saisi identique à Indicateur de renouvellement avant saisi ET Indicateur de maintien saisi identique à Indicateur de maintien avant saisi | P20: A_POS_INDREN [Saisi] = A_POS_INDREN [Valeur avant saisie] ET A_POS_INDMAI [Saisi] = A_POS_INDMAI [Valeur avant saisie] | Q20: Ouvrier d'état | R20: P0005 | S20: Général | T20: Exclu | U20: 40725
A21: 20.10.00 | B21: M | C21: 43152.5 | D21: D0004 | E21: Position | F21: S0012 | G21: Disponibilité | H21: E0161 | I21: Disponibilité sur demande pour donner des soins au conjoint ou au partenaire pacsé suite à accident/maladie grave | J21: Position saisie égale à 'Disponibilité sur demande pour donner des soins au conjoint ou au partenaire pacsé suite à accident/maladie grave' ET Indicateur de maintien saisi = Non | K21: A_POS_POSIAD [Saisi] = 'DSP36' ET A_POS_INDMAI [Saisi] = '0' | L21: T0471 | M21: Disponibilité sur demande pour donner des soins au conjoint ou au partenaire pacsé suite à accident/maladie grave - Demande | N21: Création Modification | O21: Indicateur de renouvellement saisi = Non ET (Indicateur de renouvellement saisi différent d'Indicateur de renouvellement avant saisi OU Indicateur de maintien saisi différent de Indicateur de maintien avant saisi) | P21: A_POS_INDREN [Saisi] = '0' ET (A_POS_INDREN [Saisi] <> A_POS_INDREN [Valeur avant saisie] OU A_POS_INDMAI [Saisi] <> A_POS_INDMAI [Valeur avant saisie]) | Q21: Magistrat de l'ordre judiciaire | R21: P0007 | S21: Particulier | T21: Passant | U21: 40725 | V21: 43349 | W21: DIS_I_044 ET DIS_I_080 ET DIS_D_301 ET DIS_D_429 ET DIS_D_380 ET DIS_D_496 ET POS_C_004 ET POS_C_005 ET POS_C_007 ET POS_C_010 ET POS_C_012 ET POS_C_022 ET POS_C_111 | X21: DIS_I_044 | Y21: =VLOOKUP(X21,'Axe 2 Règles de gestion'!$D$2:$F$408,3, FALSE) -> L'agent doit effectuer une demande. | Z21: DIS_I_080 | AA21: =VLOOKUP(Z21,'Axe 2 Règles de gestion'!$D$2:$F$408,3, FALSE) -> La disponibilité est prononcée après avis de la formation compétente du Conseil supérieur de la magistrature. | AP21: DIS_D_301 | AQ21: =VLOOKUP(AP21,'Axe 2 Règles de gestion'!$D$2:$F$408,3, FALSE) -> La durée prévisionnelle de la disponibilité ne peut pas excéder 3 ans pour chaque période. | AR21: DIS_D_429 | AS21: =VLOOKUP(AR21,'Axe 2 Règles de gestion'!$D$2:$F$408,3, FALSE) -> La durée réelle de la disponibilité ne peut pas excéder 3 ans pour chaque période. | AT21: DIS_D_380 | AU21: =VLOOKUP(AT21,'Axe 2 Règles de gestion'!$D$2:$F$408,3, FALSE) -> L'agent doit être en activité. | AV21: DIS_D_496 | AW21: =VLOOKUP(AV21,'Axe 2 Règles de gestion'!$D$2:$F$408,3, FALSE) -> Le type de situation de famille de l'agent doit être "marié(e)" ou "pacsé(e)". | BN21: POS_C_004 | BO21: =VLOOKUP(BN21,'Axe 2 Règles de gestion'!$D$2:$F$408,3, FALSE) -> La date de début de position doit être antérieure ou égale à la date de fin prévisionnelle de position. | BP21: POS_C_005 | BQ21: =VLOOKUP(BP21,'Axe 2 Règles de gestion'!$D$2:$F$408,3, FALSE) -> La date de début de la position doit être postérieure ou égale à la date d'entrée dans la FPE ou dans la carrière militaire. | BR21: POS_C_007 | BS21: =VLOOKUP(BR21,'Axe 2 Règles de gestion'!$D$2:$F$408,3, FALSE) -> La date de fin réelle de la position doit être antérieure à la date limite de départ à la retraite. | BT21: POS_C_010 | BU21: =VLOOKUP(BT21,'Axe 2 Règles de gestion'!$D$2:$F$408,3, FALSE) -> La date de début de position doit être antérieure ou égale à la date de fin réelle de position. | BV21: POS_C_012 | BW21: =VLOOKUP(BV21,'Axe 2 Règles de gestion'!$D$2:$F$408,3, FALSE) -> La date de fin prévisionnelle de la position doit être antérieure à la date limite de départ à la retraite. | BX21: POS_C_022 | BY21: =VLOOKUP(BX21,'Axe 2 Règles de gestion'!$D$2:$F$408,3, FALSE) -> La date de début de position est à J+1 de la date de fin de position de l'occurrence précédente. | BZ21: POS_C_111 | CA21: =VLOOKUP(BZ21,'Axe 2 Règles de gestion'!$D$2:$F$408,3, FALSE) -> La date de fin ou la date de fin prévisionnelle doit être saisie.
A22: 21.00.00 | B22: M | C22: 44368.708 | D22: D0004 | E22: Position | F22: S0012 | G22: Disponibilité | H22: E0161 | I22: Disponibilité sur demande pour donner des soins au conjoint ou au partenaire pacsé suite à accident/maladie grave | J22: Position saisie égale à 'Disponibilité sur demande pour donner des soins au conjoint ou au partenaire pacsé suite à accident/maladie grave' ET Indicateur de maintien saisi = Non | K22: A_POS_POSIAD [Saisi] = 'DSP36' ET A_POS_INDMAI [Saisi] = '0' | L22: T0471 | M22: Disponibilité sur demande pour donner des soins au conjoint ou au partenaire pacsé suite à accident/maladie grave - Demande | N22: Création Modification | O22: Indicateur de renouvellement saisi = Non ET (Indicateur de renouvellement saisi différent d'Indicateur de renouvellement avant saisi OU Indicateur de maintien saisi différent de Indicateur de maintien avant saisi) | P22: A_POS_INDREN [Saisi] = '0' ET (A_POS_INDREN [Saisi] <> A_POS_INDREN [Valeur avant saisie] OU A_POS_INDMAI [Saisi] <> A_POS_INDMAI [Valeur avant saisie]) | Q22: Magistrat de l'ordre judiciaire | R22: P0007 | S22: Particulier | T22: Passant | U22: 43350 | W22: DIS_I_044 ET DIS_I_080 ET DIS_D_301 ET DIS_D_429 ET DIS_D_380 ET DIS_D_496 ET DIS_D_614 ET DIS_D_617 ET POS_C_004 ET POS_C_005 ET POS_C_007 ET POS_C_010 ET POS_C_012 ET POS_C_022 ET POS_C_111 ET POS_C_120 ET POS_C_121 | X22: DIS_I_044 | Y22: =VLOOKUP(X22,'Axe 2 Règles de gestion'!$D$2:$F$408,3, FALSE) -> L'agent doit effectuer une demande. | Z22: DIS_I_080 | AA22: =VLOOKUP(Z22,'Axe 2 Règles de gestion'!$D$2:$F$408,3, FALSE) -> La disponibilité est prononcée après avis de la formation compétente du Conseil supérieur de la magistrature. | AP22: DIS_D_301 | AQ22: =VLOOKUP(AP22,'Axe 2 Règles de gestion'!$D$2:$F$408,3, FALSE) -> La durée prévisionnelle de la disponibilité ne peut pas excéder 3 ans pour chaque période. | AR22: DIS_D_429 | AS22: =VLOOKUP(AR22,'Axe 2 Règles de gestion'!$D$2:$F$408,3, FALSE) -> La durée réelle de la disponibilité ne peut pas excéder 3 ans pour chaque période. | AT22: DIS_D_380 | AU22: =VLOOKUP(AT22,'Axe 2 Règles de gestion'!$D$2:$F$408,3, FALSE) -> L'agent doit être en activité. | AV22: DIS_D_496 | AW22: =VLOOKUP(AV22,'Axe 2 Règles de gestion'!$D$2:$F$408,3, FALSE) -> Le type de situation de famille de l'agent doit être "marié(e)" ou "pacsé(e)". | AX22: DIS_D_614 | AY22: =VLOOKUP(AX22,'Axe 2 Règles de gestion'!$D$2:$F$408,3, FALSE) -> L'agent a épuisé ses droits à ancienneté relatifs à la disponibilité. En effet, l'agent qui exerce une activité professionnelle durant la période de disponibilité conserve ses droits à l'avancement d'échelon et de grade dans la limite de 5 ans sur l'ensemble de sa carrière. | AZ22: DIS_D_617 | BA22: =VLOOKUP(AZ22,'Axe 2 Règles de gestion'!$D$2:$F$408,3, FALSE) -> Si le champ « Situation particulière » est saisi, alors seule la valeur « Période de disponibilité donnant droit à avancement » peut être sélectionnée. | BN22: POS_C_004 | BO22: =VLOOKUP(BN22,'Axe 2 Règles de gestion'!$D$2:$F$408,3, FALSE) -> La date de début de position doit être antérieure ou égale à la date de fin prévisionnelle de position. | BP22: POS_C_005 | BQ22: =VLOOKUP(BP22,'Axe 2 Règles de gestion'!$D$2:$F$408,3, FALSE) -> La date de début de la position doit être postérieure ou égale à la date d'entrée dans la FPE ou dans la carrière militaire. | BR22: POS_C_007 | BS22: =VLOOKUP(BR22,'Axe 2 Règles de gestion'!$D$2:$F$408,3, FALSE) -> La date de fin réelle de la position doit être antérieure à la date limite de départ à la retraite. | BT22: POS_C_010 | BU22: =VLOOKUP(BT22,'Axe 2 Règles de gestion'!$D$2:$F$408,3, FALSE) -> La date de début de position doit être antérieure ou égale à la date de fin réelle de position. | BV22: POS_C_012 | BW22: =VLOOKUP(BV22,'Axe 2 Règles de gestion'!$D$2:$F$408,3, FALSE) -> La date de fin prévisionnelle de la position doit être antérieure à la date limite de départ à la retraite. | BX22: POS_C_022 | BY22: =VLOOKUP(BX22,'Axe 2 Règles de gestion'!$D$2:$F$408,3, FALSE) -> La date de début de position est à J+1 de la date de fin de position de l'occurrence précédente. | BZ22: POS_C_111 | CA22: =VLOOKUP(BZ22,'Axe 2 Règles de gestion'!$D$2:$F$408,3, FALSE) -> La date de fin ou la date de fin prévisionnelle doit être saisie. | CB22: POS_C_120 | CC22: =VLOOKUP(CB22,'Axe 2 Règles de gestion'!$D$2:$F$408,3, FALSE) -> La saisie d'une occurrence de congés/absences est interdite (date de fin réelle) | CD22: POS_C_121 | CE22: =VLOOKUP(CD22,'Axe 2 Règles de gestion'!$D$2:$F$408,3, FALSE) -> La saisie d'une occurrence de congés/absences est interdite (date de fin prévisionnelle)
A23: 20.10.00 | B23: M | C23: 43152.5 | D23: D0004 | E23: Position | F23: S0012 | G23: Disponibilité | H23: E0161 | I23: Disponibilité sur demande pour donner des soins au conjoint ou au partenaire pacsé suite à accident/maladie grave | J23: Position saisie égale à 'Disponibilité sur demande pour donner des soins au conjoint ou au partenaire pacsé suite à accident/maladie grave' ET Indicateur de maintien saisi = Non | K23: A_POS_POSIAD [Saisi] = 'DSP36' ET A_POS_INDMAI [Saisi] = '0' | L23: T0472 | M23: Disponibilité sur demande pour donner des soins au conjoint ou au partenaire pacsé suite à accident/maladie grave - Renouvellement | N23: Création Modification | O23: Indicateur de renouvellement saisi = Oui ET (Indicateur de renouvellement saisi différent d'Indicateur de renouvellement avant saisi OU Indicateur de maintien saisi différent de Indicateur de maintien avant saisi) | P23: A_POS_INDREN [Saisi] = '1' ET (A_POS_INDREN [Saisi] <> A_POS_INDREN [Valeur avant saisie] OU A_POS_INDMAI [Saisi] <> A_POS_INDMAI [Valeur avant saisie]) | Q23: Magistrat de l'ordre judiciaire | R23: P0007 | S23: Particulier | T23: Passant | U23: 40725 | V23: 43349 | W23: DIS_I_077 ET DIS_D_301 ET DIS_D_429 ET DIS_D_496 ET POS_C_004 ET POS_C_005 ET POS_C_007 ET POS_C_010 ET POS_C_012 ET POS_C_022 ET POS_C_111 | X23: DIS_I_077 | Y23: =VLOOKUP(X23,'Axe 2 Règles de gestion'!$D$2:$F$408,3, FALSE) -> L'agent doit informer son administration d'origine de sa décision de solliciter le renouvellement de sa disponibilité ou de réintégrer son corps d'origine 3 mois au moins avant l'expiration de la disponibilité. | AP23: DIS_D_301 | AQ23: =VLOOKUP(AP23,'Axe 2 Règles de gestion'!$D$2:$F$408,3, FALSE) -> La durée prévisionnelle de la disponibilité ne peut pas excéder 3 ans pour chaque période. | AR23: DIS_D_429 | AS23: =VLOOKUP(AR23,'Axe 2 Règles de gestion'!$D$2:$F$408,3, FALSE) -> La durée réelle de la disponibilité ne peut pas excéder 3 ans pour chaque période. | AT23: DIS_D_496 | AU23: =VLOOKUP(AT23,'Axe 2 Règles de gestion'!$D$2:$F$408,3, FALSE) -> Le type de situation de famille de l'agent doit être "marié(e)" ou "pacsé(e)". | BN23: POS_C_004 | BO23: =VLOOKUP(BN23,'Axe 2 Règles de gestion'!$D$2:$F$408,3, FALSE) -> La date de début de position doit être antérieure ou égale à la date de fin prévisionnelle de position. | BP23: POS_C_005 | BQ23: =VLOOKUP(BP23,'Axe 2 Règles de gestion'!$D$2:$F$408,3, FALSE) -> La date de début de la position doit être postérieure ou égale à la date d'entrée dans la FPE ou dans la carrière militaire. | BR23: POS_C_007 | BS23: =VLOOKUP(BR23,'Axe 2 Règles de gestion'!$D$2:$F$408,3, FALSE) -> La date de fin réelle de la position doit être antérieure à la date limite de départ à la retraite. | BT23: POS_C_010 | BU23: =VLOOKUP(BT23,'Axe 2 Règles de gestion'!$D$2:$F$408,3, FALSE) -> La date de début de position doit être antérieure ou égale à la date de fin réelle de position. | BV23: POS_C_012 | BW23: =VLOOKUP(BV23,'Axe 2 Règles de gestion'!$D$2:$F$408,3, FALSE) -> La date de fin prévisionnelle de la position doit être antérieure à la date limite de départ à la retraite. | BX23: POS_C_022 | BY23: =VLOOKUP(BX23,'Axe 2 Règles de gestion'!$D$2:$F$408,3, FALSE) -> La date de début de position est à J+1 de la date de fin de position de l'occurrence précédente. | BZ23: POS_C_111 | CA23: =VLOOKUP(BZ23,'Axe 2 Règles de gestion'!$D$2:$F$408,3, FALSE) -> La date de fin ou la date de fin prévisionnelle doit être saisie.
