Workbook
Name date_DIADC: 'Mode opératoire'!#REF!
Name notice_DIADC: 'Mode opératoire'!#REF!
Name notice_ENCHN: 'Mode opératoire'!$B$1:$B$4
Name notice_ICA: 'Mode opératoire'!#REF!

Sheet Mode opératoire
B1: MODE OPERATOIRE
B2: La transaction s'effectue au niveau des sous rubriques "Position statutaire/situation administrative" et "Compteurs de périodes de positions/situations".

Sheet Axe 1 Enchainement des RG
A1: Version | B1: Type de mise à jour | C1: Date de mise à jour | D1: Identifiant Domaine | E1: Libellé du Domaine | F1: Identifiant Sous-domaine | G1: Libellé du Sous-domaine | H1: Identifiant Evénement | I1: Libellé de l'évènement | J1: Libellé condition déclenchement Evènement | K1: Condition déclenchement Evènement | L1: Identifiant type d'évènement | M1: Libellé type d'évènement | N1: Type de mise à jour | O1: Libellé condition déclenchement Type Evènement | P1: Condition déclenchement Type Evènement | Q1: Libellé Population | R1: Codification Population | S1: Typologie de population | T1: Général / Particulier | U1: Passant / Exclu | V1: Date de début | W1: Date de fin | X1: Règles mobilisées | Y1: Identifiant Règle de contrôle intellectuel 1 | Z1: Libellé Règle de contrôle intellectuel 1 | AA1: Identifiant Règle de contrôle intellectuel 2 | AB1: Libellé Règle de contrôle intellectuel 2 | AC1: Identifiant Règle de contrôle intellectuel 3 | AD1: Libellé Règle de contrôle intellectuel 3 | AE1: Identifiant Règle de contrôle intellectuel 4 | AF1: Libellé Règle de contrôle intellectuel 4 | AG1: Identifiant Règle de contrôle intellectuel 5 | AH1: Libellé Règle de contrôle intellectuel 5 | AI1: Identifiant Règle de contrôle intellectuel 6 | AJ1: Libellé Règle de contrôle intellectuel 6 | AK1: Identifiant Règle de contrôle intellectuel 7 | AL1: Libellé Règle de contrôle intellectuel 7 | AM1: Identifiant Règle de contrôle intellectuel 8 | AN1: Libellé Règle de contrôle intellectuel 8 | AO1: Identifiant Règle de contrôle intellectuel 9 | AP1: Libellé Règle de contrôle intellectuel 9 | AQ1: Identifiant Règle de contrôle intellectuel 10 | AR1: Libellé Règle de contrôle intellectuel 10 | AS1: Identifiant Règle de contrôle intellectuel 11 | AT1: Libellé Règle de contrôle intellectuel 11 | AU1: Identifiant Règle de contrôle intellectuel 12 | AV1: Libellé Règle de contrôle intellectuel 12 | AW1: Identifiant Règle de condition 1 | AX1: Libellé Règle de condition 1 | AY1: Identifiant Règle de condition 2 | AZ1: Libellé Règle de condition 2 | BA1: Identifiant Règle de condition 3 | BB1: Libellé Règle de condition 3 | BC1: Identifiant Règle de condition 4 | BD1: Libellé Règle de condition 4 | BE1: Identifiant Règle de condition 5 | BF1: Libellé Règle de condition 5 | BG1: Identifiant Règle de condition 6 | BH1: Libellé Règle de condition 6 | BI1: Identifiant Règle de condition 7 | BJ1: Libellé Règle de condition 7 | BK1: Identifiant Règle de condition 8 | BL1: Libellé Règle de condition 8 | BM1: Identifiant Règle de contrôle 1 | BN1: Libellé Règle de contrôle 1 | BO1: Identifiant Règle de contrôle 2 | BP1: Libellé Règle de contrôle 2 | BQ1: Identifiant Règle de contrôle 3 | BR1: Libellé Règle de contrôle 3 | BS1: Identifiant Règle de contrôle 4 | BT1: Libellé Règle de contrôle 4 | BU1: Identifiant Règle de contrôle 5 | BV1: Libellé Règle de contrôle 5 | BW1: Identifiant Règle de contrôle 6 | BX1: Libellé Règle de contrôle 6 | BY1: Identifiant Règle de contrôle 7 | BZ1: Libellé Règle de contrôle 7 | CA1: Identifiant Règle de contrôle 8 | CB1: Libellé Règle de contrôle 8 | CC1: Identifiant Règle de contrôle 9 | CD1: Libellé Règle de contrôle 9 | CE1: Identifiant Règle de contrôle 10 | CF1: Libellé Règle de contrôle 10 | CG1: Identifiant Règle de contrôle 11 | CH1: Libellé Règle de contrôle 11 | CI1: Identifiant Règle de contrôle 12 | CJ1: Libellé Règle de contrôle 12 | CK1: Identifiant Règle de contrôle 13 | CL1: Libellé Règle de contrôle 13 | CM1: Identifiant Règle de contrôle 14 | CN1: Libellé Règle de contrôle 14 | CO1: Identifiant Règle de contrôle 15 | CP1: Libellé Règle de contrôle 15 | CQ1: Identifiant Règle de contrôle 16 | CR1: Libellé Règle de contrôle 16 | CS1: Identifiant Règle de contrôle 17 | CT1: Libellé Règle de contrôle 17 | CU1: Identifiant Règle de contrôle 18 | CV1: Libellé Règle de contrôle 18 | CW1: Identifiant Règle de contrôle 19 | CX1: Libellé Règle de contrôle 19 | CY1: Identifiant Règle de contrôle 20 | CZ1: Libellé Règle de contrôle 20 | DA1: Identifiant Règle de contrôle 21 | DB1: Libellé Règle de contrôle 21 | DC1: FIME | DD1: Statut de travail
A2: 17.10.00 | B2: A | C2: 43189.5 | D2: D0004 | E2: Position | F2: S0027 | G2: Congé sans salaire (ouvriers) | H2: E0286 | I2: Congé sans salaire pour donner des soins au conjoint ou partenaire pacsé suite à accident/maladie grave | J2: La position saisie est égale à 'Congé sans salaire pour donner des soins au conjoint ou partenaire pacsé suite à accident/maladie grave' ET l'indicateur de maintien saisi = Non | K2: A_POS_POSIAD [Saisi] = 'SS201' ET A_POS_INDMAI [Saisi] = '0' | L2: T0833 | M2: Congé sans salaire pour donner des soins au conjoint ou partenaire pacsé suite à accident/maladie grave - Demande | N2: Création Modification | O2: Indicateur de renouvellement saisi = Non ET (Indicateur de renouvellement saisi différent d'Indicateur de renouvellement avant saisi OU Indicateur de maintien saisi différent de Indicateur de maintien avant saisi) | P2: A_POS_INDREN [Saisi] = '0' ET (A_POS_INDREN [Saisi] <> A_POS_INDREN [Valeur avant saisie] OU A_POS_INDMAI [Saisi] <> A_POS_INDMAI [Valeur avant saisie]) | Q2: Titulaire ou magistrat | R2: P0001 | S2: T | T2: Général | U2: Exclu | V2: 40725
A3: 17.10.00 | B3: A | C3: 43189.5 | D3: D0004 | E3: Position | F3: S0027 | G3: Congé sans salaire (ouvriers) | H3: E0286 | I3: Congé sans salaire pour donner des soins au conjoint ou partenaire pacsé suite à accident/maladie grave | J3: La position saisie est égale à 'Congé sans salaire pour donner des soins au conjoint ou partenaire pacsé suite à accident/maladie grave' ET l'indicateur de maintien saisi = Non | K3: A_POS_POSIAD [Saisi] = 'SS201' ET A_POS_INDMAI [Saisi] = '0' | L3: T0834 | M3: Congé sans salaire pour donner des soins au conjoint ou partenaire pacsé suite à accident/maladie grave - Renouvellement | N3: Création Modification | O3: Indicateur de renouvellement saisi = Oui ET (Indicateur de renouvellement saisi différent d'Indicateur de renouvellement avant saisi OU Indicateur de maintien saisi différent de Indicateur de maintien avant saisi) | P3: A_POS_INDREN [Saisi] = '1' ET (A_POS_INDREN [Saisi] <> A_POS_INDREN [Valeur avant saisie] OU A_POS_INDMAI [Saisi] <> A_POS_INDMAI [Valeur avant saisie]) | Q3: Titulaire ou magistrat | R3: P0001 | S3: T | T3: Général | U3: Exclu | V3: 40725
A4: 17.10.00 | B4: A | C4: 43189.5 | D4: D0004 | E4: Position | F4: S0027 | G4: Congé sans salaire (ouvriers) | H4: E0286 | I4: Congé sans salaire pour donner des soins au conjoint ou partenaire pacsé suite à accident/maladie grave | J4: La position saisie est égale à 'Congé sans salaire pour donner des soins au conjoint ou partenaire pacsé suite à accident/maladie grave' ET l'indicateur de maintien saisi = Non | K4: A_POS_POSIAD [Saisi] = 'SS201' ET A_POS_INDMAI [Saisi] = '0' | L4: T0835 | M4: Congé sans salaire pour donner des soins au conjoint ou partenaire pacsé suite à accident/maladie grave - Réintégration | N4: Modification | O4: Indicateur de renouvellement saisi identique à Indicateur de renouvellement avant saisi ET Indicateur de maintien saisi identique à Indicateur de maintien avant saisi | P4: A_POS_INDREN [Saisi] = A_POS_INDREN [Valeur avant saisie] ET A_POS_INDMAI [Saisi] = A_POS_INDMAI [Valeur avant saisie] | Q4: Titulaire ou magistrat | R4: P0001 | S4: T | T4: Général | U4: Exclu | V4: 40725
A5: 17.10.00 | B5: A | C5: 43189.5 | D5: D0004 | E5: Position | F5: S0027 | G5: Congé sans salaire (ouvriers) | H5: E0286 | I5: Congé sans salaire pour donner des soins au conjoint ou partenaire pacsé suite à accident/maladie grave | J5: La position saisie est égale à 'Congé sans salaire pour donner des soins au conjoint ou partenaire pacsé suite à accident/maladie grave' ET l'indicateur de maintien saisi = Non | K5: A_POS_POSIAD [Saisi] = 'SS201' ET A_POS_INDMAI [Saisi] = '0' | L5: T0833 | M5: Congé sans salaire pour donner des soins au conjoint ou partenaire pacsé suite à accident/maladie grave - Demande | N5: Création Modification | O5: Indicateur de renouvellement saisi = Non ET (Indicateur de renouvellement saisi différent d'Indicateur de renouvellement avant saisi OU Indicateur de maintien saisi différent de Indicateur de maintien avant saisi) | P5: A_POS_INDREN [Saisi] = '0' ET (A_POS_INDREN [Saisi] <> A_POS_INDREN [Valeur avant saisie] OU A_POS_INDMAI [Saisi] <> A_POS_INDMAI [Valeur avant saisie]) | Q5: Militaire | R5: P0002 | S5: M | T5: Général | U5: Exclu | V5: 40725
A6: 17.10.00 | B6: A | C6: 43189.5 | D6: D0004 | E6: Position | F6: S0027 | G6: Congé sans salaire (ouvriers) | H6: E0286 | I6: Congé sans salaire pour donner des soins au conjoint ou partenaire pacsé suite à accident/maladie grave | J6: La position saisie est égale à 'Congé sans salaire pour donner des soins au conjoint ou partenaire pacsé suite à accident/maladie grave' ET l'indicateur de maintien saisi = Non | K6: A_POS_POSIAD [Saisi] = 'SS201' ET A_POS_INDMAI [Saisi] = '0' | L6: T0834 | M6: Congé sans salaire pour donner des soins au conjoint ou partenaire pacsé suite à accident/maladie grave - Renouvellement | N6: Création Modification | O6: Indicateur de renouvellement saisi = Oui ET (Indicateur de renouvellement saisi différent d'Indicateur de renouvellement avant saisi OU Indicateur de maintien saisi différent de Indicateur de maintien avant saisi) | P6: A_POS_INDREN [Saisi] = '1' ET (A_POS_INDREN [Saisi] <> A_POS_INDREN [Valeur avant saisie] OU A_POS_INDMAI [Saisi] <> A_POS_INDMAI [Valeur avant saisie]) | Q6: Militaire | R6: P0002 | S6: M | T6: Général | U6: Exclu | V6: 40725
A7: 17.10.00 | B7: A | C7: 43189.5 | D7: D0004 | E7: Position | F7: S0027 | G7: Congé sans salaire (ouvriers) | H7: E0286 | I7: Congé sans salaire pour donner des soins au conjoint ou partenaire pacsé suite à accident/maladie grave | J7: La position saisie est égale à 'Congé sans salaire pour donner des soins au conjoint ou partenaire pacsé suite à accident/maladie grave' ET l'indicateur de maintien saisi = Non | K7: A_POS_POSIAD [Saisi] = 'SS201' ET A_POS_INDMAI [Saisi] = '0' | L7: T0835 | M7: Congé sans salaire pour donner des soins au conjoint ou partenaire pacsé suite à accident/maladie grave - Réintégration | N7: Modification | O7: Indicateur de renouvellement saisi identique à Indicateur de renouvellement avant saisi ET Indicateur de maintien saisi identique à Indicateur de maintien avant saisi | P7: A_POS_INDREN [Saisi] = A_POS_INDREN [Valeur avant saisie] ET A_POS_INDMAI [Saisi] = A_POS_INDMAI [Valeur avant saisie] | Q7: Militaire | R7: P0002 | S7: M | T7: Général | U7: Exclu | V7: 40725
A8: 17.10.00 | B8: A | C8: 43189.5 | D8: D0004 | E8: Position | F8: S0027 | G8: Congé sans salaire (ouvriers) | H8: E0286 | I8: Congé sans salaire pour donner des soins au conjoint ou partenaire pacsé suite à accident/maladie grave | J8: La position saisie est égale à 'Congé sans salaire pour donner des soins au conjoint ou partenaire pacsé suite à accident/maladie grave' ET l'indicateur de maintien saisi = Non | K8: A_POS_POSIAD [Saisi] = 'SS201' ET A_POS_INDMAI [Saisi] = '0' | L8: T0833 | M8: Congé sans salaire pour donner des soins au conjoint ou partenaire pacsé suite à accident/maladie grave - Demande | N8: Création Modification | O8: Indicateur de renouvellement saisi = Non ET (Indicateur de renouvellement saisi différent d'Indicateur de renouvellement avant saisi OU Indicateur de maintien saisi différent de Indicateur de maintien avant saisi) | P8: A_POS_INDREN [Saisi] = '0' ET (A_POS_INDREN [Saisi] <> A_POS_INDREN [Valeur avant saisie] OU A_POS_INDMAI [Saisi] <> A_POS_INDMAI [Valeur avant saisie]) | Q8: Contractuel | R8: P0003 | S8: N | T8: Général | U8: Exclu | V8: 40725
A9: 17.10.00 | B9: A | C9: 43189.5 | D9: D0004 | E9: Position | F9: S0027 | G9: Congé sans salaire (ouvriers) | H9: E0286 | I9: Congé sans salaire pour donner des soins au conjoint ou partenaire pacsé suite à accident/maladie grave | J9: La position saisie est égale à 'Congé sans salaire pour donner des soins au conjoint ou partenaire pacsé suite à accident/maladie grave' ET l'indicateur de maintien saisi = Non | K9: A_POS_POSIAD [Saisi] = 'SS201' ET A_POS_INDMAI [Saisi] = '0' | L9: T0834 | M9: Congé sans salaire pour donner des soins au conjoint ou partenaire pacsé suite à accident/maladie grave - Renouvellement | N9: Création Modification | O9: Indicateur de renouvellement saisi = Oui ET (Indicateur de renouvellement saisi différent d'Indicateur de renouvellement avant saisi OU Indicateur de maintien saisi différent de Indicateur de maintien avant saisi) | P9: A_POS_INDREN [Saisi] = '1' ET (A_POS_INDREN [Saisi] <> A_POS_INDREN [Valeur avant saisie] OU A_POS_INDMAI [Saisi] <> A_POS_INDMAI [Valeur avant saisie]) | Q9: Contractuel | R9: P0003 | S9: N | T9: Général | U9: Exclu | V9: 40725
A10: 17.10.00 | B10: A | C10: 43189.5 | D10: D0004 | E10: Position | F10: S0027 | G10: Congé sans salaire (ouvriers) | H10: E0286 | I10: Congé sans salaire pour donner des soins au conjoint ou partenaire pacsé suite à accident/maladie grave | J10: La position saisie est égale à 'Congé sans salaire pour donner des soins au conjoint ou partenaire pacsé suite à accident/maladie grave' ET l'indicateur de maintien saisi = Non | K10: A_POS_POSIAD [Saisi] = 'SS201' ET A_POS_INDMAI [Saisi] = '0' | L10: T0835 | M10: Congé sans salaire pour donner des soins au conjoint ou partenaire pacsé suite à accident/maladie grave - Réintégration | N10: Modification | O10: Indicateur de renouvellement saisi identique à Indicateur de renouvellement avant saisi ET Indicateur de maintien saisi identique à Indicateur de maintien avant saisi | P10: A_POS_INDREN [Saisi] = A_POS_INDREN [Valeur avant saisie] ET A_POS_INDMAI [Saisi] = A_POS_INDMAI [Valeur avant saisie] | Q10: Contractuel | R10: P0003 | S10: N | T10: Général | U10: Exclu | V10: 40725
A11: 17.10.00 | B11: A | C11: 43189.5 | D11: D0004 | E11: Position | F11: S0027 | G11: Congé sans salaire (ouvriers) | H11: E0286 | I11: Congé sans salaire pour donner des soins au conjoint ou partenaire pacsé suite à accident/maladie grave | J11: La position saisie est égale à 'Congé sans salaire pour donner des soins au conjoint ou partenaire pacsé suite à accident/maladie grave' ET l'indicateur de maintien saisi = Non | K11: A_POS_POSIAD [Saisi] = 'SS201' ET A_POS_INDMAI [Saisi] = '0' | L11: T0833 | M11: Congé sans salaire pour donner des soins au conjoint ou partenaire pacsé suite à accident/maladie grave - Demande | N11: Création Modification | O11: Indicateur de renouvellement saisi = Non ET (Indicateur de renouvellement saisi différent d'Indicateur de renouvellement avant saisi OU Indicateur de maintien saisi différent de Indicateur de maintien avant saisi) | P11: A_POS_INDREN [Saisi] = '0' ET (A_POS_INDREN [Saisi] <> A_POS_INDREN [Valeur avant saisie] OU A_POS_INDMAI [Saisi] <> A_POS_INDMAI [Valeur avant saisie]) | Q11: Stagiaire ou auditeur ou élève | R11: P0004 | S11: S | T11: Général | U11: Exclu | V11: 40725
A12: 17.10.00 | B12: A | C12: 43189.5 | D12: D0004 | E12: Position | F12: S0027 | G12: Congé sans salaire (ouvriers) | H12: E0286 | I12: Congé sans salaire pour donner des soins au conjoint ou partenaire pacsé suite à accident/maladie grave | J12: La position saisie est égale à 'Congé sans salaire pour donner des soins au conjoint ou partenaire pacsé suite à accident/maladie grave' ET l'indicateur de maintien saisi = Non | K12: A_POS_POSIAD [Saisi] = 'SS201' ET A_POS_INDMAI [Saisi] = '0' | L12: T0834 | M12: Congé sans salaire pour donner des soins au conjoint ou partenaire pacsé suite à accident/maladie grave - Renouvellement | N12: Création Modification | O12: Indicateur de renouvellement saisi = Oui ET (Indicateur de renouvellement saisi différent d'Indicateur de renouvellement avant saisi OU Indicateur de maintien saisi différent de Indicateur de maintien avant saisi) | P12: A_POS_INDREN [Saisi] = '1' ET (A_POS_INDREN [Saisi] <> A_POS_INDREN [Valeur avant saisie] OU A_POS_INDMAI [Saisi] <> A_POS_INDMAI [Valeur avant saisie]) | Q12: Stagiaire ou auditeur ou élève | R12: P0004 | S12: S | T12: Général | U12: Exclu | V12: 40725
A13: 17.10.00 | B13: A | C13: 43189.5 | D13: D0004 | E13: Position | F13: S0027 | G13: Congé sans salaire (ouvriers) | H13: E0286 | I13: Congé sans salaire pour donner des soins au conjoint ou partenaire pacsé suite à accident/maladie grave | J13: La position saisie est égale à 'Congé sans salaire pour donner des soins au conjoint ou partenaire pacsé suite à accident/maladie grave' ET l'indicateur de maintien saisi = Non | K13: A_POS_POSIAD [Saisi] = 'SS201' ET A_POS_INDMAI [Saisi] = '0' | L13: T0835 | M13: Congé sans salaire pour donner des soins au conjoint ou partenaire pacsé suite à accident/maladie grave - Réintégration | N13: Modification | O13: Indicateur de renouvellement saisi identique à Indicateur de renouvellement avant saisi ET Indicateur de maintien saisi identique à Indicateur de maintien avant saisi | P13: A_POS_INDREN [Saisi] = A_POS_INDREN [Valeur avant saisie] ET A_POS_INDMAI [Saisi] = A_POS_INDMAI [Valeur avant saisie] | Q13: Stagiaire ou auditeur ou élève | R13: P0004 | S13: S | T13: Général | U13: Exclu | V13: 40725
A14: 21.00.00 | B14: M | C14: 44369.615 | D14: D0004 | E14: Position | F14: S0027 | G14: Congé sans salaire (ouvriers) | H14: E0286 | I14: Congé sans salaire pour donner des soins au conjoint ou partenaire pacsé suite à accident/maladie grave | J14: La position saisie est égale à 'Congé sans salaire pour donner des soins au conjoint ou partenaire pacsé suite à accident/maladie grave' ET l'indicateur de maintien saisi = Non | K14: A_POS_POSIAD [Saisi] = 'SS201' ET A_POS_INDMAI [Saisi] = '0' | L14: T0833 | M14: Congé sans salaire pour donner des soins au conjoint ou partenaire pacsé suite à accident/maladie grave - Demande | N14: Création Modification | O14: Indicateur de renouvellement saisi = Non ET (Indicateur de renouvellement saisi différent d'Indicateur de renouvellement avant saisi OU Indicateur de maintien saisi différent de Indicateur de maintien avant saisi) | P14: A_POS_INDREN [Saisi] = '0' ET (A_POS_INDREN [Saisi] <> A_POS_INDREN [Valeur avant saisie] OU A_POS_INDMAI [Saisi] <> A_POS_INDMAI [Valeur avant saisie]) | Q14: Ouvrier d'état | R14: P0005 | S14: O | T14: Général | U14: Passant | V14: 40725 | X14: CSS_C_001 ET CSS_C_003 ET CSS_C_004 ET POS_C_004 ET POS_C_009 ET POS_C_007 ET POS_C_010 ET POS_C_012 ET POS_C_022 ET POS_C_111 ET POS_C_006 ET POS_C_106 ET POS_C_100 ET POS_C_120 ET POS_C_121 | BM14: CSS_C_001 | BN14: =VLOOKUP(BM14,'Axe 2 Règles de gestion'!$D$2:$F$292,3, FALSE) -> Le type de situation de famille de l'agent doit être "marié(e) ou "pacsé(e)". | BO14: CSS_C_003 | BP14: =VLOOKUP(BO14,'Axe 2 Règles de gestion'!$D$2:$F$292,3, FALSE) -> Chaque période est d'une durée réelle maximale de 2 ans. | BQ14: CSS_C_004 | BR14: =VLOOKUP(BQ14,'Axe 2 Règles de gestion'!$D$2:$F$292,3, FALSE) -> Chaque période est d'une durée prévisionnelle maximale de 2 ans. | BS14: POS_C_004 | BT14: =VLOOKUP(BS14,'Axe 2 Règles de gestion'!$D$2:$F$292,3, FALSE) -> La date de début de position doit être antérieure ou égale à la date de fin prévisionnelle de position. | BU14: POS_C_009 | BV14: =VLOOKUP(BU14,'Axe 2 Règles de gestion'!$D$2:$F$292,3, FALSE) -> La date de début de la position doit être postérieure ou égale à la date de début du lien juridique. | BW14: POS_C_007 | BX14: =VLOOKUP(BW14,'Axe 2 Règles de gestion'!$D$2:$F$292,3, FALSE) -> La date de fin réelle de la position doit être antérieure à la date limite de départ à la retraite. | BY14: POS_C_010 | BZ14: =VLOOKUP(BY14,'Axe 2 Règles de gestion'!$D$2:$F$292,3, FALSE) -> La date de début de position doit être antérieure ou égale à la date de fin réelle de position. | CA14: POS_C_012 | CB14: =VLOOKUP(CA14,'Axe 2 Règles de gestion'!$D$2:$F$292,3, FALSE) -> La date de fin prévisionnelle de la position doit être antérieure à la date limite de départ à la retraite. | CC14: POS_C_022 | CD14: =VLOOKUP(CC14,'Axe 2 Règles de gestion'!$D$2:$F$292,3, FALSE) -> La date de début de position est à J+1 de la date de fin de position de l'occurrence précédente. | CE14: POS_C_111 | CF14: =VLOOKUP(CE14,'Axe 2 Règles de gestion'!$D$2:$F$292,3, FALSE) -> La date de fin ou la date de fin prévisionnelle doit être saisie. | CG14: POS_C_006 | CH14: =VLOOKUP(CG14,'Axe 2 Règles de gestion'!$D$2:$F$292,3, FALSE) -> La date de fin réelle de la position doit être antérieure ou égale à la date de fin réelle ou prévisionnelle du lien juridique. | CI14: POS_C_106 | CJ14: =VLOOKUP(CI14,'Axe 2 Règles de gestion'!$D$2:$F$292,3, FALSE) -> La date de fin prévisionnelle de la position doit être antérieure ou égale à la date de fin réelle ou prévisionnelle du lien juridique. | CK14: POS_C_100 | CL14: =VLOOKUP(CK14,'Axe 2 Règles de gestion'!$D$2:$F$292,3, FALSE) -> Lors de la demande initiale, l'agent doit être en activité. | CM14: POS_C_120 | CN14: =VLOOKUP(CM14,'Axe 2 Règles de gestion'!$D$2:$F$292,3, FALSE) -> La saisie d'une occurrence de congés/absences est interdite (date de fin réelle) | CO14: POS_C_121 | CP14: =VLOOKUP(CO14,'Axe 2 Règles de gestion'!$D$2:$F$292,3, FALSE) -> La saisie d'une occurrence de congés/absences est interdite (date de fin prévisionnelle)
A15: 21.00.00 | B15: M | C15: 44369.615 | D15: D0004 | E15: Position | F15: S0027 | G15: Congé sans salaire (ouvriers) | H15: E0286 | I15: Congé sans salaire pour donner des soins au conjoint ou partenaire pacsé suite à accident/maladie grave | J15: La position saisie est égale à 'Congé sans salaire pour donner des soins au conjoint ou partenaire pacsé suite à accident/maladie grave' ET l'indicateur de maintien saisi = Non | K15: A_POS_POSIAD [Saisi] = 'SS201' ET A_POS_INDMAI [Saisi] = '0' | L15: T0834 | M15: Congé sans salaire pour donner des soins au conjoint ou partenaire pacsé suite à accident/maladie grave - Renouvellement | N15: Création Modification | O15: Indicateur de renouvellement saisi = Oui ET (Indicateur de renouvellement saisi différent d'Indicateur de renouvellement avant saisi OU Indicateur de maintien saisi différent de Indicateur de maintien avant saisi) | P15: A_POS_INDREN [Saisi] = '1' ET (A_POS_INDREN [Saisi] <> A_POS_INDREN [Valeur avant saisie] OU A_POS_INDMAI [Saisi] <> A_POS_INDMAI [Valeur avant saisie]) | Q15: Ouvrier d'état | R15: P0005 | S15: O | T15: Général | U15: Passant | V15: 40725 | X15: CSS_C_001 ET CSS_C_003 ET CSS_C_004 ET CSS_C_005 ET CSS_C_006 ET POS_C_004 ET POS_C_007 ET POS_C_010 ET POS_C_012 ET POS_C_022 ET POS_C_111 ET POS_C_006 ET POS_C_106 ET POS_C_120 ET POS_C_121 | BM15: CSS_C_001 | BN15: =VLOOKUP(BM15,'Axe 2 Règles de gestion'!$D$2:$F$292,3, FALSE) -> Le type de situation de famille de l'agent doit être "marié(e) ou "pacsé(e)". | BO15: CSS_C_003 | BP15: =VLOOKUP(BO15,'Axe 2 Règles de gestion'!$D$2:$F$292,3, FALSE) -> Chaque période est d'une durée réelle maximale de 2 ans. | BQ15: CSS_C_004 | BR15: =VLOOKUP(BQ15,'Axe 2 Règles de gestion'!$D$2:$F$292,3, FALSE) -> Chaque période est d'une durée prévisionnelle maximale de 2 ans. | BS15: CSS_C_005 | BT15: =VLOOKUP(BS15,'Axe 2 Règles de gestion'!$D$2:$F$292,3, FALSE) -> La durée cumulée dans cette position ne doit pas excéder 8 ans (date de fin réelle du congé sans salaire). | BU15: CSS_C_006 | BV15: =VLOOKUP(BU15,'Axe 2 Règles de gestion'!$D$2:$F$292,3, FALSE) -> La durée cumulée dans cette position ne doit pas excéder 8 ans (date de fin prévisionnelle du congé sans salaire). | BW15: POS_C_004 | BX15: =VLOOKUP(BW15,'Axe 2 Règles de gestion'!$D$2:$F$292,3, FALSE) -> La date de début de position doit être antérieure ou égale à la date de fin prévisionnelle de position. | BY15: POS_C_007 | BZ15: =VLOOKUP(BY15,'Axe 2 Règles de gestion'!$D$2:$F$292,3, FALSE) -> La date de fin réelle de la position doit être antérieure à la date limite de départ à la retraite. | CA15: POS_C_010 | CB15: =VLOOKUP(CA15,'Axe 2 Règles de gestion'!$D$2:$F$292,3, FALSE) -> La date de début de position doit être antérieure ou égale à la date de fin réelle de position. | CC15: POS_C_012 | CD15: =VLOOKUP(CC15,'Axe 2 Règles de gestion'!$D$2:$F$292,3, FALSE) -> La date de fin prévisionnelle de la position doit être antérieure à la date limite de départ à la retraite. | CE15: POS_C_022 | CF15: =VLOOKUP(CE15,'Axe 2 Règles de gestion'!$D$2:$F$292,3, FALSE) -> La date de début de position est à J+1 de la date de fin de position de l'occurrence précédente. | CG15: POS_C_111 | CH15: =VLOOKUP(CG15,'Axe 2 Règles de gestion'!$D$2:$F$292,3, FALSE) -> La date de fin ou la date de fin prévisionnelle doit être saisie. | CI15: POS_C_006 | CJ15: =VLOOKUP(CI15,'Axe 2 Règles de gestion'!$D$2:$F$292,3, FALSE) -> La date de fin réelle de la position doit être antérieure ou égale à la date de fin réelle ou prévisionnelle du lien juridique. | CK15: POS_C_106 | CL15: =VLOOKUP(CK15,'Axe 2 Règles de gestion'!$D$2:$F$292,3, FALSE) -> La date de fin prévisionnelle de la position doit être antérieure ou égale à la date de fin réelle ou prévisionnelle du lien juridique. | CM15: POS_C_120 | CN15: =VLOOKUP(CM15,'Axe 2 Règles de gestion'!$D$2:$F$292,3, FALSE) -> La saisie d'une occurrence de congés/absences est interdite (date de fin réelle) | CO15: POS_C_121 | CP15: =VLOOKUP(CO15,'Axe 2 Règles de gestion'!$D$2:$F$292,3, FALSE) -> La saisie d'une occurrence de congés/absences est interdite (date de fin prévisionnelle)
A16: 21.00.00 | B16: M | C16: 44368.708 | D16: D0004 | E16: Position | F16: S0027 | G16: Congé sans salaire (ouvriers) | H16: E0286 | I16: Congé sans salaire pour donner des soins au conjoint ou partenaire pacsé suite à accident/maladie grave | J16: La position saisie est égale à 'Congé sans salaire pour donner des soins au conjoint ou partenaire pacsé suite à accident/maladie grave' ET l'indicateur de maintien saisi = Non | K16: A_POS_POSIAD [Saisi] = 'SS201' ET A_POS_INDMAI [Saisi] = '0' | L16: T0835 | M16: Congé sans salaire pour donner des soins au conjoint ou partenaire pacsé suite à accident/maladie grave - Réintégration | N16: Modification | O16: Indicateur de renouvellement saisi identique à Indicateur de renouvellement avant saisi ET Indicateur de maintien saisi identique à Indicateur de maintien avant saisi | P16: A_POS_INDREN [Saisi] = A_POS_INDREN [Valeur avant saisie] ET A_POS_INDMAI [Saisi] = A_POS_INDMAI [Valeur avant saisie] | Q16: Ouvrier d'état | R16: P0005 | S16: O | T16: Général | U16: Passant | V16: 40725 | X16: CSS_C_001 ET CSS_C_003 ET CSS_C_004 ET CSS_C_005 ET CSS_C_006 ET POS_C_004 ET POS_C_007 ET POS_C_010 ET POS_C_012 ET POS_C_111 ET POS_C_006 ET POS_C_106 ET POS_C_120 ET POS_C_121 | BM16: CSS_C_001 | BN16: =VLOOKUP(BM16,'Axe 2 Règles de gestion'!$D$2:$F$292,3, FALSE) -> Le type de situation de famille de l'agent doit être "marié(e) ou "pacsé(e)". | BO16: CSS_C_003 | BP16: =VLOOKUP(BO16,'Axe 2 Règles de gestion'!$D$2:$F$292,3, FALSE) -> Chaque période est d'une durée réelle maximale de 2 ans. | BQ16: CSS_C_004 | BR16: =VLOOKUP(BQ16,'Axe 2 Règles de gestion'!$D$2:$F$292,3, FALSE) -> Chaque période est d'une durée prévisionnelle maximale de 2 ans. | BS16: CSS_C_005 | BT16: =VLOOKUP(BS16,'Axe 2 Règles de gestion'!$D$2:$F$292,3, FALSE) -> La durée cumulée dans cette position ne doit pas excéder 8 ans (date de fin réelle du congé sans salaire). | BU16: CSS_C_006 | BV16: =VLOOKUP(BU16,'Axe 2 Règles de gestion'!$D$2:$F$292,3, FALSE) -> La durée cumulée dans cette position ne doit pas excéder 8 ans (date de fin prévisionnelle du congé sans salaire). | BW16: POS_C_004 | BX16: =VLOOKUP(BW16,'Axe 2 Règles de gestion'!$D$2:$F$292,3, FALSE) -> La date de début de position doit être antérieure ou égale à la date de fin prévisionnelle de position. | BY16: POS_C_007 | BZ16: =VLOOKUP(BY16,'Axe 2 Règles de gestion'!$D$2:$F$292,3, FALSE) -> La date de fin réelle de la position doit être antérieure à la date limite de départ à la retraite. | CA16: POS_C_010 | CB16: =VLOOKUP(CA16,'Axe 2 Règles de gestion'!$D$2:$F$292,3, FALSE) -> La date de début de position doit être antérieure ou égale à la date de fin réelle de position. | CC16: POS_C_012 | CD16: =VLOOKUP(CC16,'Axe 2 Règles de gestion'!$D$2:$F$292,3, FALSE) -> La date de fin prévisionnelle de la position doit être antérieure à la date limite de départ à la retraite. | CE16: POS_C_111 | CF16: =VLOOKUP(CE16,'Axe 2 Règles de gestion'!$D$2:$F$292,3, FALSE) -> La date de fin ou la date de fin prévisionnelle doit être saisie. | CG16: POS_C_006 | CH16: =VLOOKUP(CG16,'Axe 2 Règles de gestion'!$D$2:$F$292,3, FALSE) -> La date de fin réelle de la position doit être antérieure ou égale à la date de fin réelle ou prévisionnelle du lien juridique. | CI16: POS_C_106 | CJ16: =VLOOKUP(CI16,'Axe 2 Règles de gestion'!$D$2:$F$292,3, FALSE) -> La date de fin prévisionnelle de la position doit être antérieure ou égale à la date de fin réelle ou prévisionnelle du lien juridique. | CK16: POS_C_120 | CL16: =VLOOKUP(CK16,'Axe 2 Règles de gestion'!$D$2:$F$292,3, FALSE) -> La saisie d'une occurrence de congés/absences est interdite (date de fin réelle) | CM16: POS_C_121 | CN16: =VLOOKUP(CM16,'Axe 2 Règles de gestion'!$D$2:$F$292,3, FALSE) -> La saisie d'une occurrence de congés/absences est interdite (date de fin prévisionnelle)
A17: 25.10.00 | B17: M | C17: 45994.424 | D17: D0004 | E17: Position | F17: S0027 | G17: Congé sans salaire (ouvriers) | H17: E0286 | I17: Congé sans salaire pour donner des soins au conjoint ou partenaire pacsé suite à accident/maladie grave | J17: La position saisie est égale à 'Congé sans salaire pour donner des soins au conjoint ou partenaire pacsé suite à accident/maladie grave' ET l'indicateur de maintien saisi = Non | K17: A_POS_POSIAD [Saisi] = 'SS201' ET A_POS_INDMAI [Saisi] = '0' | L17: T0833 | M17: Congé sans salaire pour donner des soins au conjoint ou partenaire pacsé suite à accident/maladie grave - Demande | N17: Création Modification | O17: Indicateur de renouvellement saisi = Non ET (Indicateur de renouvellement saisi différent d'Indicateur de renouvellement avant saisi OU Indicateur de maintien saisi différent de Indicateur de maintien avant saisi) | P17: A_POS_INDREN [Saisi] = '0' ET (A_POS_INDREN [Saisi] <> A_POS_INDREN [Valeur avant saisie] OU A_POS_INDMAI [Saisi] <> A_POS_INDMAI [Valeur avant saisie]) | Q17: Ouvrier des parcs et ateliers confirmé ou stagiaire | R17: P0143 | S17: O | T17: Particulier | U17: Exclu | V17: 40725 | W17: 45900
A18: 25.10.00 | B18: A | C18: 45995.41 | D18: D0004 | E18: Position | F18: S0027 | G18: Congé sans salaire (ouvriers) | H18: E0286 | I18: Congé sans salaire pour donner des soins au conjoint ou partenaire pacsé suite à accident/maladie grave | J18: La position saisie est égale à 'Congé sans salaire pour donner des soins au conjoint ou partenaire pacsé suite à accident/maladie grave' ET l'indicateur de maintien saisi = Non | K18: A_POS_POSIAD [Saisi] = 'SS201' ET A_POS_INDMAI [Saisi] = '0' | L18: T0833 | M18: Congé sans salaire pour donner des soins au conjoint ou partenaire pacsé suite à accident/maladie grave - Demande | N18: Création Modification | O18: Indicateur de renouvellement saisi = Non ET (Indicateur de renouvellement saisi différent d'Indicateur de renouvellement avant saisi OU Indicateur de maintien saisi différent de Indicateur de maintien avant saisi) | P18: A_POS_INDREN [Saisi] = '0' ET (A_POS_INDREN [Saisi] <> A_POS_INDREN [Valeur avant saisie] OU A_POS_INDMAI [Saisi] <> A_POS_INDMAI [Valeur avant saisie]) | Q18: Ouvrier des parcs et ateliers confirmé ou stagiaire | R18: P0143 | S18: O | T18: Particulier | U18: Passant | V18: 45901 | X18: CSS_I_108 ET CSS_I_102 ET CSS_I_050 ET CSS_I_103 ET CSS_I_104 ET CSS_I_132 ET CSS_I_121 ET CSS_D_030 ET CSS_D_031 ET CSS_D_032 ET CSS_D_038 ET CSS_D_040 ET POS_C_004 ET POS_C_009 ET POS_C_007 ET POS_C_010 ET POS_C_012 ET POS_C_022 ET POS_C_111 ET POS_C_006 ET POS_C_106 ET POS_C_100 ET POS_C_120 ET POS_C_121 | Y18: CSS_I_108 | Z18: =VLOOKUP(Y18,'Axe 2 Règles de gestion'!$D$2:$F$292,3, FALSE) -> L'agent doit donner des soins à son conjoint ou son partenaire pacsé à la suite d'un accident ou d'une maladie grave nécessitant la présence d'une tierce personne. | AA18: CSS_I_102 | AB18: =VLOOKUP(AA18,'Axe 2 Règles de gestion'!$D$2:$F$292,3, FALSE) -> L'agent doit effectuer une demande. | AC18: CSS_I_050 | AD18: =VLOOKUP(AC18,'Axe 2 Règles de gestion'!$D$2:$F$292,3, FALSE) -> La demande de l'agent est accordée de droit par l'administration. | AE18: CSS_I_103 | AF18: =VLOOKUP(AE18,'Axe 2 Règles de gestion'!$D$2:$F$292,3, FALSE) -> Le congé est accordé dans un délai maximal de 2 mois à compter de la réception de la demande de l'agent. | AG18: CSS_I_104 | AH18: =VLOOKUP(AG18,'Axe 2 Règles de gestion'!$D$2:$F$292,3, FALSE) -> En cas d'urgence liée à l'état de santé, le congé débute à la date de réception de la demande de l'agent. | AI18: CSS_I_132 | AJ18: =VLOOKUP(AI18,'Axe 2 Règles de gestion'!$D$2:$F$292,3, FALSE) -> L'administration peut faire procéder aux enquêtes nécessaires en vue de s'assurer que l'activité de l'agent bénéficiaire du congé correspond réellement aux motifs pour lesquels ce congé a été déposé. | AK18: CSS_I_121 | AL18: =VLOOKUP(AK18,'Axe 2 Règles de gestion'!$D$2:$F$292,3, FALSE) -> Si le contrôle révèle que le congé n'est pas utilisé conformément au motif invoqué, l'administration peut mettre fin au congé après que l'agent a été invité à présenter ses observations. | AW18: CSS_D_030 | AX18: =VLOOKUP(AW18,'Axe 2 Règles de gestion'!$D$2:$F$292,3, FALSE) -> L'agent doit être employé depuis plus d'1 an. | AY18: CSS_D_031 | AZ18: =VLOOKUP(AY18,'Axe 2 Règles de gestion'!$D$2:$F$292,3, FALSE) -> La durée réelle du congé ne peut pas excéder 3 années. | BA18: CSS_D_032 | BB18: =VLOOKUP(BA18,'Axe 2 Règles de gestion'!$D$2:$F$292,3, FALSE) -> La durée prévisionnelle du congé ne peut pas excéder 3 années. | BC18: CSS_D_038 | BD18: =VLOOKUP(BC18,'Axe 2 Règles de gestion'!$D$2:$F$292,3, FALSE) -> Le type de situation de famille de l'agent doit être "marié(e)" ou "pacsé(e)". | BE18: CSS_D_040 | BF18: =VLOOKUP(BE18,'Axe 2 Règles de gestion'!$D$2:$F$292,3, FALSE) -> Si le champ « Situation particulière » est saisi, alors seule la valeur « Période de congé sans salaire donnant droit à avancement » peut être sélectionnée. | BM18: POS_C_004 | BN18: =VLOOKUP(BM18,'Axe 2 Règles de gestion'!$D$2:$F$292,3, FALSE) -> La date de début de position doit être antérieure ou égale à la date de fin prévisionnelle de position. | BO18: POS_C_009 | BP18: =VLOOKUP(BO18,'Axe 2 Règles de gestion'!$D$2:$F$292,3, FALSE) -> La date de début de la position doit être postérieure ou égale à la date de début du lien juridique. | BQ18: POS_C_007 | BR18: =VLOOKUP(BQ18,'Axe 2 Règles de gestion'!$D$2:$F$292,3, FALSE) -> La date de fin réelle de la position doit être antérieure à la date limite de départ à la retraite. | BS18: POS_C_010 | BT18: =VLOOKUP(BS18,'Axe 2 Règles de gestion'!$D$2:$F$292,3, FALSE) -> La date de début de position doit être antérieure ou égale à la date de fin réelle de position. | BU18: POS_C_012 | BV18: =VLOOKUP(BU18,'Axe 2 Règles de gestion'!$D$2:$F$292,3, FALSE) -> La date de fin prévisionnelle de la position doit être antérieure à la date limite de départ à la retraite. | BW18: POS_C_022 | BX18: =VLOOKUP(BW18,'Axe 2 Règles de gestion'!$D$2:$F$292,3, FALSE) -> La date de début de position est à J+1 de la date de fin de position de l'occurrence précédente. | BY18: POS_C_111 | BZ18: =VLOOKUP(BY18,'Axe 2 Règles de gestion'!$D$2:$F$292,3, FALSE) -> La date de fin ou la date de fin prévisionnelle doit être saisie. | CA18: POS_C_006 | CB18: =VLOOKUP(CA18,'Axe 2 Règles de gestion'!$D$2:$F$292,3, FALSE) -> La date de fin réelle de la position doit être antérieure ou égale à la date de fin réelle ou prévisionnelle du lien juridique. | CC18: POS_C_106 | CD18: =VLOOKUP(CC18,'Axe 2 Règles de gestion'!$D$2:$F$292,3, FALSE) -> La date de fin prévisionnelle de la position doit être antérieure ou égale à la date de fin réelle ou prévisionnelle du lien juridique. | CE18: POS_C_100 | CF18: =VLOOKUP(CE18,'Axe 2 Règles de gestion'!$D$2:$F$292,3, FALSE) -> Lors de la demande initiale, l'agent doit être en activité. | CG18: POS_C_120 | CH18: =VLOOKUP(CG18,'Axe 2 Règles de gestion'!$D$2:$F$292,3, FALSE) -> La saisie d'une occurrence de congés/absences est interdite (date de fin réelle) | CI18: POS_C_121 | CJ18: =VLOOKUP(CI18,'Axe 2 Règles de gestion'!$D$2:$F$292,3, FALSE) -> La saisie d'une occurrence de congés/absences est interdite (date de fin prévisionnelle)
A19: 25.10.00 | B19: M | C19: 45994.421 | D19: D0004 | E19: Position | F19: S0027 | G19: Congé sans salaire (ouvriers) | H19: E0286 | I19: Congé sans salaire pour donner des soins au conjoint ou partenaire pacsé suite à accident/maladie grave | J19: La position saisie est égale à 'Congé sans salaire pour donner des soins au conjoint ou partenaire pacsé suite à accident/maladie grave' ET l'indicateur de maintien saisi = Non | K19: A_POS_POSIAD [Saisi] = 'SS201' ET A_POS_INDMAI [Saisi] = '0' | L19: T0834 | M19: Congé sans salaire pour donner des soins au conjoint ou partenaire pacsé suite à accident/maladie grave - Renouvellement | N19: Création Modification | O19: Indicateur de renouvellement saisi = Oui ET (Indicateur de renouvellement saisi différent d'Indicateur de renouvellement avant saisi OU Indicateur de maintien saisi différent de Indicateur de maintien avant saisi) | P19: A_POS_INDREN [Saisi] = '1' ET (A_POS_INDREN [Saisi] <> A_POS_INDREN [Valeur avant saisie] OU A_POS_INDMAI [Saisi] <> A_POS_INDMAI [Valeur avant saisie]) | Q19: Ouvrier des parcs et ateliers confirmé ou stagiaire | R19: P0143 | S19: O | T19: Particulier | U19: Exclu | V19: 40725 | W19: 45900
A20: 25.10.00 | B20: A | C20: 45995.411 | D20: D0004 | E20: Position | F20: S0027 | G20: Congé sans salaire (ouvriers) | H20: E0286 | I20: Congé sans salaire pour donner des soins au conjoint ou partenaire pacsé suite à accident/maladie grave | J20: La position saisie est égale à 'Congé sans salaire pour donner des soins au conjoint ou partenaire pacsé suite à accident/maladie grave' ET l'indicateur de maintien saisi = Non | K20: A_POS_POSIAD [Saisi] = 'SS201' ET A_POS_INDMAI [Saisi] = '0' | L20: T0834 | M20: Congé sans salaire pour donner des soins au conjoint ou partenaire pacsé suite à accident/maladie grave - Renouvellement | N20: Création Modification | O20: Indicateur de renouvellement saisi = Oui ET (Indicateur de renouvellement saisi différent d'Indicateur de renouvellement avant saisi OU Indicateur de maintien saisi différent de Indicateur de maintien avant saisi) | P20: A_POS_INDREN [Saisi] = '1' ET (A_POS_INDREN [Saisi] <> A_POS_INDREN [Valeur avant saisie] OU A_POS_INDMAI [Saisi] <> A_POS_INDMAI [Valeur avant saisie]) | Q20: Ouvrier des parcs et ateliers confirmé ou stagiaire | R20: P0143 | S20: O | T20: Particulier | U20: Passant | V20: 45901 | X20: CSS_I_119 ET CSS_I_132 ET CSS_I_121 ET CSS_D_031 ET CSS_D_032 ET CSS_D_038 ET CSS_D_040 ET POS_C_004 ET POS_C_007 ET POS_C_010 ET POS_C_012 ET POS_C_022 ET POS_C_111 ET POS_C_006 ET POS_C_106 ET POS_C_120 ET POS_C_121 | Y20: CSS_I_119 | Z20: =VLOOKUP(Y20,'Axe 2 Règles de gestion'!$D$2:$F$292,3, FALSE) -> L'agent doit solliciter au moins 3 mois avant le terme du congé le renouvellement de son congé par lettre recommandée avec demande d'avis de réception. | AA20: CSS_I_132 | AB20: =VLOOKUP(AA20,'Axe 2 Règles de gestion'!$D$2:$F$292,3, FALSE) -> L'administration peut faire procéder aux enquêtes nécessaires en vue de s'assurer que l'activité de l'agent bénéficiaire du congé correspond réellement aux motifs pour lesquels ce congé a été déposé. | AC20: CSS_I_121 | AD20: =VLOOKUP(AC20,'Axe 2 Règles de gestion'!$D$2:$F$292,3, FALSE) -> Si le contrôle révèle que le congé n'est pas utilisé conformément au motif invoqué, l'administration peut mettre fin au congé après que l'agent a été invité à présenter ses observations. | AW20: CSS_D_031 | AX20: =VLOOKUP(AW20,'Axe 2 Règles de gestion'!$D$2:$F$292,3, FALSE) -> La durée réelle du congé ne peut pas excéder 3 années. | AY20: CSS_D_032 | AZ20: =VLOOKUP(AY20,'Axe 2 Règles de gestion'!$D$2:$F$292,3, FALSE) -> La durée prévisionnelle du congé ne peut pas excéder 3 années. | BA20: CSS_D_038 | BB20: =VLOOKUP(BA20,'Axe 2 Règles de gestion'!$D$2:$F$292,3, FALSE) -> Le type de situation de famille de l'agent doit être "marié(e)" ou "pacsé(e)". | BC20: CSS_D_040 | BD20: =VLOOKUP(BC20,'Axe 2 Règles de gestion'!$D$2:$F$292,3, FALSE) -> Si le champ « Situation particulière » est saisi, alors seule la valeur « Période de congé sans salaire donnant droit à avancement » peut être sélectionnée. | BM20: POS_C_004 | BN20: =VLOOKUP(BM20,'Axe 2 Règles de gestion'!$D$2:$F$292,3, FALSE) -> La date de début de position doit être antérieure ou égale à la date de fin prévisionnelle de position. | BO20: POS_C_007 | BP20: =VLOOKUP(BO20,'Axe 2 Règles de gestion'!$D$2:$F$292,3, FALSE) -> La date de fin réelle de la position doit être antérieure à la date limite de départ à la retraite. | BQ20: POS_C_010 | BR20: =VLOOKUP(BQ20,'Axe 2 Règles de gestion'!$D$2:$F$292,3, FALSE) -> La date de début de position doit être antérieure ou égale à la date de fin réelle de position. | BS20: POS_C_012 | BT20: =VLOOKUP(BS20,'Axe 2 Règles de gestion'!$D$2:$F$292,3, FALSE) -> La date de fin prévisionnelle de la position doit être antérieure à la date limite de départ à la retraite. | BU20: POS_C_022 | BV20: =VLOOKUP(BU20,'Axe 2 Règles de gestion'!$D$2:$F$292,3, FALSE) -> La date de début de position est à J+1 de la date de fin de position de l'occurrence précédente. | BW20: POS_C_111 | BX20: =VLOOKUP(BW20,'Axe 2 Règles de gestion'!$D$2:$F$292,3, FALSE) -> La date de fin ou la date de fin prévisionnelle doit être saisie. | BY20: POS_C_006 | BZ20: =VLOOKUP(BY20,'Axe 2 Règles de gestion'!$D$2:$F$292,3, FALSE) -> La date de fin réelle de la position doit être antérieure ou égale à la date de fin réelle ou prévisionnelle du lien juridique. | CA20: POS_C_106 | CB20: =VLOOKUP(CA20,'Axe 2 Règles de gestion'!$D$2:$F$292,3, FALSE) -> La date de fin prévisionnelle de la position doit être antérieure ou égale à la date de fin réelle ou prévisionnelle du lien juridique. | CC20: POS_C_120 | CD20: =VLOOKUP(CC20,'Axe 2 Règles de gestion'!$D$2:$F$292,3, FALSE) -> La saisie d'une occurrence de congés/absences est interdite (date de fin réelle) | CE20: POS_C_121 | CF20: =VLOOKUP(CE20,'Axe 2 Règles de gestion'!$D$2:$F$292,3, FALSE) -> La saisie d'une occurrence de congés/absences est interdite (date de fin prévisionnelle)
A21: 25.10.00 | B21: M | C21: 45994.42 | D21: D0004 | E21: Position | F21: S0027 | G21: Congé sans salaire (ouvriers) | H21: E0286 | I21: Congé sans salaire pour donner des soins au conjoint ou partenaire pacsé suite à accident/maladie grave | J21: La position saisie est égale à 'Congé sans salaire pour donner des soins au conjoint ou partenaire pacsé suite à accident/maladie grave' ET l'indicateur de maintien saisi = Non | K21: A_POS_POSIAD [Saisi] = 'SS201' ET A_POS_INDMAI [Saisi] = '0' | L21: T0835 | M21: Congé sans salaire pour donner des soins au conjoint ou partenaire pacsé suite à accident/maladie grave - Réintégration | N21: Modification | O21: Indicateur de renouvellement saisi identique à Indicateur de renouvellement avant saisi ET Indicateur de maintien saisi identique à Indicateur de maintien avant saisi | P21: A_POS_INDREN [Saisi] = A_POS_INDREN [Valeur avant saisie] ET A_POS_INDMAI [Saisi] = A_POS_INDMAI [Valeur avant saisie] | Q21: Ouvrier des parcs et ateliers confirmé ou stagiaire | R21: P0143 | S21: O | T21: Particulier | U21: Exclu | V21: 40725 | W21: 45900
A22: 25.10.00 | B22: A | C22: 45994.42 | D22: D0004 | E22: Position | F22: S0027 | G22: Congé sans salaire (ouvriers) | H22: E0286 | I22: Congé sans salaire pour donner des soins au conjoint ou partenaire pacsé suite à accident/maladie grave | J22: La position saisie est égale à 'Congé sans salaire pour donner des soins au conjoint ou partenaire pacsé suite à accident/maladie grave' ET l'indicateur de maintien saisi = Non | K22: A_POS_POSIAD [Saisi] = 'SS201' ET A_POS_INDMAI [Saisi] = '0' | L22: T0835 | M22: Congé sans salaire pour donner des soins au conjoint ou partenaire pacsé suite à accident/maladie grave - Réintégration | N22: Modification | O22: Indicateur de renouvellement saisi identique à Indicateur de renouvellement avant saisi ET Indicateur de maintien saisi identique à Indicateur de maintien avant saisi | P22: A_POS_INDREN [Saisi] = A_POS_INDREN [Valeur avant saisie] ET A_POS_INDMAI [Saisi] = A_POS_INDMAI [Valeur avant saisie] | Q22: Ouvrier des parcs et ateliers confirmé ou stagiaire | R22: P0143 | S22: O | T22: Particulier | U22: Passant | V22: 45901 | X22: CSS_I_120 ET CSS_I_126 ET CSS_I_127 ET CSS_I_128 ET CSS_I_129 ET CSS_I_130 ET CSS_I_131 ET CSS_I_122 ET CSS_I_123 ET CSS_I_124 ET CSS_I_125 ET CSS_D_031 ET CSS_D_032 ET CSS_D_038 ET CSS_D_040 ET POS_C_004 ET POS_C_007 ET POS_C_010 ET POS_C_012 ET POS_C_111 ET POS_C_006 ET POS_C_106 ET POS_C_120 ET POS_C_121 | Y22: CSS_I_120 | Z22: =VLOOKUP(Y22,'Axe 2 Règles de gestion'!$D$2:$F$292,3, FALSE) -> L'agent doit solliciter au moins 3 mois avant le terme du congé sa demande de réemploi par lettre recommandée avec demande d'avis de réception. | AA22: CSS_I_126 | AB22: =VLOOKUP(AA22,'Axe 2 Règles de gestion'!$D$2:$F$292,3, FALSE) -> Si l'agent n'a pas fait connaître sa décision dans ce délai, il est présumé renoncer à son emploi. | AC22: CSS_I_127 | AD22: =VLOOKUP(AC22,'Axe 2 Règles de gestion'!$D$2:$F$292,3, FALSE) -> L'administration informe sans délai par écrit l'agent des conséquences de son silence. | AE22: CSS_I_128 | AF22: =VLOOKUP(AE22,'Axe 2 Règles de gestion'!$D$2:$F$292,3, FALSE) -> En l'absence de réponse de l'agent dans un délai de 15 jours à compter de la réception de ce courrier, l'agent peut être licencié sans indemnité. | AG22: CSS_I_129 | AH22: =VLOOKUP(AG22,'Axe 2 Règles de gestion'!$D$2:$F$292,3, FALSE) -> L'agent peut demander, par lettre recommandée avec demande d'avis de réception, qu'il soit mis fin au congé avant le terme initialement fixé. | AI22: CSS_I_130 | AJ22: =VLOOKUP(AI22,'Axe 2 Règles de gestion'!$D$2:$F$292,3, FALSE) -> Cette demande de fin anticipée est adressée au chef de service ou au directeur de l'établissement en respectant un préavis de 3 mois au terme duquel l'agent est réemployé. | AK22: CSS_I_131 | AL22: =VLOOKUP(AK22,'Axe 2 Règles de gestion'!$D$2:$F$292,3, FALSE) -> Toutefois, en cas de motif grave, notamment en cas de diminution des revenus du ménage, l'agent est réemployé dès réception par l'administration de la lettre recommandée. | AM22: CSS_I_122 | AN22: =VLOOKUP(AM22,'Axe 2 Règles de gestion'!$D$2:$F$292,3, FALSE) -> L'agent est réemployé sur son emploi précédent dans la mesure permise par le service. Dans le cas contraire, il dispose d'une priorité pour être réemployé sur un emploi ou une occupation similaire assorti d'une rémunération équivalente. | AO22: CSS_I_123 | AP22: =VLOOKUP(AO22,'Axe 2 Règles de gestion'!$D$2:$F$292,3, FALSE) -> En cas d'impossibilité de réemploi au sein de son service ou établissement d'origine, l'agent se voit proposer un poste relevant de la même classification dans 3 autres services ou directions territoriales de l'établissement susceptibles de l'accueillir. | AQ22: CSS_I_124 | AR22: =VLOOKUP(AQ22,'Axe 2 Règles de gestion'!$D$2:$F$292,3, FALSE) -> L'agent qui a formulé, avant l'expiration de la période de mise en congé, une demande de réemploi, est maintenu dans la situation où il a été placé dans l'attente de son réemploi dans l'un des 3 postes qui lui seront proposés. | AS22: CSS_I_125 | AT22: =VLOOKUP(AS22,'Axe 2 Règles de gestion'!$D$2:$F$292,3, FALSE) -> Si l'agent refuse successivement chacun de ces 3 postes qui lui sont proposés, il peut être licencié après avis de la commission consultative. | AW22: CSS_D_031 | AX22: =VLOOKUP(AW22,'Axe 2 Règles de gestion'!$D$2:$F$292,3, FALSE) -> La durée réelle du congé ne peut pas excéder 3 années. | AY22: CSS_D_032 | AZ22: =VLOOKUP(AY22,'Axe 2 Règles de gestion'!$D$2:$F$292,3, FALSE) -> La durée prévisionnelle du congé ne peut pas excéder 3 années. | BA22: CSS_D_038 | BB22: =VLOOKUP(BA22,'Axe 2 Règles de gestion'!$D$2:$F$292,3, FALSE) -> Le type de situation de famille de l'agent doit être "marié(e)" ou "pacsé(e)". | BC22: CSS_D_040 | BD22: =VLOOKUP(BC22,'Axe 2 Règles de gestion'!$D$2:$F$292,3, FALSE) -> Si le champ « Situation particulière » est saisi, alors seule la valeur « Période de congé sans salaire donnant droit à avancement » peut être sélectionnée. | BM22: POS_C_004 | BN22: =VLOOKUP(BM22,'Axe 2 Règles de gestion'!$D$2:$F$292,3, FALSE) -> La date de début de position doit être antérieure ou égale à la date de fin prévisionnelle de position. | BO22: POS_C_007 | BP22: =VLOOKUP(BO22,'Axe 2 Règles de gestion'!$D$2:$F$292,3, FALSE) -> La date de fin réelle de la position doit être antérieure à la date limite de départ à la retraite. | BQ22: POS_C_010 | BR22: =VLOOKUP(BQ22,'Axe 2 Règles de gestion'!$D$2:$F$292,3, FALSE) -> La date de début de position doit être antérieure ou égale à la date de fin réelle de position. | BS22: POS_C_012 | BT22: =VLOOKUP(BS22,'Axe 2 Règles de gestion'!$D$2:$F$292,3, FALSE) -> La date de fin prévisionnelle de la position doit être antérieure à la date limite de départ à la retraite. | BU22: POS_C_111 | BV22: =VLOOKUP(BU22,'Axe 2 Règles de gestion'!$D$2:$F$292,3, FALSE) -> La date de fin ou la date de fin prévisionnelle doit être saisie. | BW22: POS_C_006 | BX22: =VLOOKUP(BW22,'Axe 2 Règles de gestion'!$D$2:$F$292,3, FALSE) -> La date de fin réelle de la position doit être antérieure ou égale à la date de fin réelle ou prévisionnelle du lien juridique. | BY22: POS_C_106 | BZ22: =VLOOKUP(BY22,'Axe 2 Règles de gestion'!$D$2:$F$292,3, FALSE) -> La date de fin prévisionnelle de la position doit être antérieure ou égale à la date de fin réelle ou prévisionnelle du lien juridique. | CA22: POS_C_120 | CB22: =VLOOKUP(CA22,'Axe 2 Règles de gestion'!$D$2:$F$292,3, FALSE) -> La saisie d'une occurrence de congés/absences est interdite (date de fin réelle) | CC22: POS_C_121 | CD22: =VLOOKUP(CC22,'Axe 2 Règles de gestion'!$D$2:$F$292,3, FALSE) -> La saisie d'une occurrence de congés/absences est interdite (date de fin prévisionnelle)
A23: 21.00.00 | B23: M | C23: 44368.708 | D23: D0004 | E23: Position | F23: S0027 | G23: Congé sans salaire (ouvriers) | H23: E0286 | I23: Congé sans salaire pour donner des soins au conjoint ou partenaire pacsé suite à accident/maladie grave | J23: La position saisie est égale à 'Congé sans salaire pour donner des soins au conjoint ou partenaire pacsé suite à accident/maladie grave' ET l'indicateur de maintien saisi = Non | K23: A_POS_POSIAD [Saisi] = 'SS201' ET A_POS_INDMAI [Saisi] = '0' | L23: T0833 | M23: Congé sans salaire pour donner des soins au conjoint ou partenaire pacsé suite à accident/maladie grave - Demande | N23: Création Modification | O23: Indicateur de renouvellement saisi = Non ET (Indicateur de renouvellement saisi différent d'Indicateur de renouvellement avant saisi OU Indicateur de maintien saisi différent de Indicateur de maintien avant saisi) | P23: A_POS_INDREN [Saisi] = '0' ET (A_POS_INDREN [Saisi] <> A_POS_INDREN [Valeur avant saisie] OU A_POS_INDMAI [Saisi] <> A_POS_INDMAI [Valeur avant saisie]) | Q23: Ouvrier de la défense ou assimilé | R23: P0197 | S23: O | T23: Particulier | U23: Passant | V23: 40725 | X23: CSS_I_001 ET CSS_I_002 ET CSS_D_011 ET CSS_D_260 ET CSS_D_005 ET POS_C_004 ET POS_C_009 ET POS_C_007 ET POS_C_010 ET POS_C_012 ET POS_C_022 ET POS_C_111 ET POS_C_006 ET POS_C_106 ET POS_C_100 ET POS_C_120 ET POS_C_121 | Y23: CSS_I_001 | Z23: =VLOOKUP(Y23,'Axe 2 Règles de gestion'!$D$2:$F$292,3, FALSE) -> L'agent adresse sa demande à son service gestionnaire dans un délai minimum laissé à l'appréciation du chef d'établissement avant la date de départ souhaitée. Elle doit préciser la durée du congé, et comporter, le cas échéant, les pièces justificatives. | AA23: CSS_I_002 | AB23: =VLOOKUP(AA23,'Axe 2 Règles de gestion'!$D$2:$F$292,3, FALSE) -> La demande de l'agent est accordée de droit par l'administration. | AW23: CSS_D_011 | AX23: =VLOOKUP(AW23,'Axe 2 Règles de gestion'!$D$2:$F$292,3, FALSE) -> Chaque période est d'une durée réelle maximale de 2 ans. | AY23: CSS_D_260 | AZ23: =VLOOKUP(AY23,'Axe 2 Règles de gestion'!$D$2:$F$292,3, FALSE) -> Chaque période est d'une durée prévisionnelle maximale de 2 ans. | BA23: CSS_D_005 | BB23: =VLOOKUP(BA23,'Axe 2 Règles de gestion'!$D$2:$F$292,3, FALSE) -> Le type de situation de famille de l'agent doit être "marié(e)", "pacsé(e)", ou "en concubinage". | BM23: POS_C_004 | BN23: =VLOOKUP(BM23,'Axe 2 Règles de gestion'!$D$2:$F$292,3, FALSE) -> La date de début de position doit être antérieure ou égale à la date de fin prévisionnelle de position. | BO23: POS_C_009 | BP23: =VLOOKUP(BO23,'Axe 2 Règles de gestion'!$D$2:$F$292,3, FALSE) -> La date de début de la position doit être postérieure ou égale à la date de début du lien juridique. | BQ23: POS_C_007 | BR23: =VLOOKUP(BQ23,'Axe 2 Règles de gestion'!$D$2:$F$292,3, FALSE) -> La date de fin réelle de la position doit être antérieure à la date limite de départ à la retraite. | BS23: POS_C_010 | BT23: =VLOOKUP(BS23,'Axe 2 Règles de gestion'!$D$2:$F$292,3, FALSE) -> La date de début de position doit être antérieure ou égale à la date de fin réelle de position. | BU23: POS_C_012 | BV23: =VLOOKUP(BU23,'Axe 2 Règles de gestion'!$D$2:$F$292,3, FALSE) -> La date de fin prévisionnelle de la position doit être antérieure à la date limite de départ à la retraite. | BW23: POS_C_022 | BX23: =VLOOKUP(BW23,'Axe 2 Règles de gestion'!$D$2:$F$292,3, FALSE) -> La date de début de position est à J+1 de la date de fin de position de l'occurrence précédente. | BY23: POS_C_111 | BZ23: =VLOOKUP(BY23,'Axe 2 Règles de gestion'!$D$2:$F$292,3, FALSE) -> La date de fin ou la date de fin prévisionnelle doit être saisie. | CA23: POS_C_006 | CB23: =VLOOKUP(CA23,'Axe 2 Règles de gestion'!$D$2:$F$292,3, FALSE) -> La date de fin réelle de la position doit être antérieure ou égale à la date de fin réelle ou prévisionnelle du lien juridique. | CC23: POS_C_106 | CD23: =VLOOKUP(CC23,'Axe 2 Règles de gestion'!$D$2:$F$292,3, FALSE) -> La date de fin prévisionnelle de la position doit être antérieure ou égale à la date de fin réelle ou prévisionnelle du lien juridique. | CE23: POS_C_100 | CF23: =VLOOKUP(CE23,'Axe 2 Règles de gestion'!$D$2:$F$292,3, FALSE) -> Lors de la demande initiale, l'agent doit être en activité. | CG23: POS_C_120 | CH23: =VLOOKUP(CG23,'Axe 2 Règles de gestion'!$D$2:$F$292,3, FALSE) -> La saisie d'une occurrence de congés/absences est interdite (date de fin réelle) | CI23: POS_C_121 | CJ23: =VLOOKUP(CI23,'Axe 2 Règles de gestion'!$D$2:$F$292,3, FALSE) -> La saisie d'une occurrence de congés/absences est interdite (date de fin prévisionnelle)
A24: 21.00.00 | B24: M | C24: 44368.708 | D24: D0004 | E24: Position | F24: S0027 | G24: Congé sans salaire (ouvriers) | H24: E0286 | I24: Congé sans salaire pour donner des soins au conjoint ou partenaire pacsé suite à accident/maladie grave | J24: La position saisie est égale à 'Congé sans salaire pour donner des soins au conjoint ou partenaire pacsé suite à accident/maladie grave' ET l'indicateur de maintien saisi = Non | K24: A_POS_POSIAD [Saisi] = 'SS201' ET A_POS_INDMAI [Saisi] = '0' | L24: T0834 | M24: Congé sans salaire pour donner des soins au conjoint ou partenaire pacsé suite à accident/maladie grave - Renouvellement | N24: Création Modification | O24: Indicateur de renouvellement saisi = Oui ET (Indicateur de renouvellement saisi différent d'Indicateur de renouvellement avant saisi OU Indicateur de maintien saisi différent de Indicateur de maintien avant saisi) | P24: A_POS_INDREN [Saisi] = '1' ET (A_POS_INDREN [Saisi] <> A_POS_INDREN [Valeur avant saisie] OU A_POS_INDMAI [Saisi] <> A_POS_INDMAI [Valeur avant saisie]) | Q24: Ouvrier de la défense ou assimilé | R24: P0197 | S24: O | T24: Particulier | U24: Passant | V24: 40725 | X24: CSS_I_003 ET CSS_I_004 ET CSS_D_011 ET CSS_D_260 ET CSS_D_012 ET CSS_D_261 ET CSS_D_005 ET POS_C_004 ET POS_C_007 ET POS_C_010 ET POS_C_012 ET POS_C_022 ET POS_C_111 ET POS_C_006 ET POS_C_106 ET POS_C_120 ET POS_C_121 | Y24: CSS_I_003 | Z24: =VLOOKUP(Y24,'Axe 2 Règles de gestion'!$D$2:$F$292,3, FALSE) -> Le service gestionnaire informe l'agent 2 mois avant la fin du congé de ses droits et obligations. | AA24: CSS_I_004 | AB24: =VLOOKUP(AA24,'Axe 2 Règles de gestion'!$D$2:$F$292,3, FALSE) -> L'agent devra solliciter, dans les 2 mois avant l'expiration du congé soit le renouvellement de son congé, soit sa radiation des contrôles, soit sa réintégration. | AW24: CSS_D_011 | AX24: =VLOOKUP(AW24,'Axe 2 Règles de gestion'!$D$2:$F$292,3, FALSE) -> Chaque période est d'une durée réelle maximale de 2 ans. | AY24: CSS_D_260 | AZ24: =VLOOKUP(AY24,'Axe 2 Règles de gestion'!$D$2:$F$292,3, FALSE) -> Chaque période est d'une durée prévisionnelle maximale de 2 ans. | BA24: CSS_D_012 | BB24: =VLOOKUP(BA24,'Axe 2 Règles de gestion'!$D$2:$F$292,3, FALSE) -> La durée cumulée dans cette position ne doit pas excéder 8 ans (date de fin réelle du congé sans salaire). | BC24: CSS_D_261 | BD24: =VLOOKUP(BC24,'Axe 2 Règles de gestion'!$D$2:$F$292,3, FALSE) -> La durée cumulée dans cette position ne doit pas excéder 8 ans (date de fin prévisionnelle du congé sans salaire). | BE24: CSS_D_005 | BF24: =VLOOKUP(BE24,'Axe 2 Règles de gestion'!$D$2:$F$292,3, FALSE) -> Le type de situation de famille de l'agent doit être "marié(e)", "pacsé(e)", ou "en concubinage". | BM24: POS_C_004 | BN24: =VLOOKUP(BM24,'Axe 2 Règles de gestion'!$D$2:$F$292,3, FALSE) -> La date de début de position doit être antérieure ou égale à la date de fin prévisionnelle de position. | BO24: POS_C_007 | BP24: =VLOOKUP(BO24,'Axe 2 Règles de gestion'!$D$2:$F$292,3, FALSE) -> La date de fin réelle de la position doit être antérieure à la date limite de départ à la retraite. | BQ24: POS_C_010 | BR24: =VLOOKUP(BQ24,'Axe 2 Règles de gestion'!$D$2:$F$292,3, FALSE) -> La date de début de position doit être antérieure ou égale à la date de fin réelle de position. | BS24: POS_C_012 | BT24: =VLOOKUP(BS24,'Axe 2 Règles de gestion'!$D$2:$F$292,3, FALSE) -> La date de fin prévisionnelle de la position doit être antérieure à la date limite de départ à la retraite. | BU24: POS_C_022 | BV24: =VLOOKUP(BU24,'Axe 2 Règles de gestion'!$D$2:$F$292,3, FALSE) -> La date de début de position est à J+1 de la date de fin de position de l'occurrence précédente. | BW24: POS_C_111 | BX24: =VLOOKUP(BW24,'Axe 2 Règles de gestion'!$D$2:$F$292,3, FALSE) -> La date de fin ou la date de fin prévisionnelle doit être saisie. | BY24: POS_C_006 | BZ24: =VLOOKUP(BY24,'Axe 2 Règles de gestion'!$D$2:$F$292,3, FALSE) -> La date de fin réelle de la position doit être antérieure ou égale à la date de fin réelle ou prévisionnelle du lien juridique. | CA24: POS_C_106 | CB24: =VLOOKUP(CA24,'Axe 2 Règles de gestion'!$D$2:$F$292,3, FALSE) -> La date de fin prévisionnelle de la position doit être antérieure ou égale à la date de fin réelle ou prévisionnelle du lien juridique. | CC24: POS_C_120 | CD24: =VLOOKUP(CC24,'Axe 2 Règles de gestion'!$D$2:$F$292,3, FALSE) -> La saisie d'une occurrence de congés/absences est interdite (date de fin réelle) | CE24: POS_C_121 | CF24: =VLOOKUP(CE24,'Axe 2 Règles de gestion'!$D$2:$F$292,3, FALSE) -> La saisie d'une occurrence de congés/absences est interdite (date de fin prévisionnelle)
