Workbook
Name date_DIADC: 'Mode opératoire'!#REF!
Name notice_DIADC: 'Mode opératoire'!#REF!
Name notice_ENCHN: 'Mode opératoire'!$B$1:$B$4
Name notice_ICA: 'Mode opératoire'!#REF!

Sheet Mode opératoire
B1: MODE OPERATOIRE
B2: La transaction s'effectue au niveau de la sous rubrique "Position statutaire/situation administrative" Parmi les non titulaires ne sont pas traités pour le moment : - Les enseignants contractuels ou agréés d'établissement privé sous contrat d'association ou sous contrat simple à titre définitif - MEN - Les enseignants contractuels ou agréés d'établissement privé sous contrat d'association ou sous contrat simple à titre provisoire - MEN - Les maitres délégués établissement privé sous contrat d'association - MEN

Sheet Axe 1 Enchainement des RG
A1: Version | B1: Type de mise à jour | C1: Date de mise à jour | D1: Identifiant Domaine | E1: Libellé du Domaine | F1: Identifiant Sous-domaine | G1: Libellé du Sous-domaine | H1: Identifiant Evénement | I1: Libellé de l'évènement | J1: Libellé condition déclenchement Evènement | K1: Condition déclenchement Evènement | L1: Identifiant type d'évènement | M1: Libellé type d'évènement | N1: Type de mise à jour | O1: Libellé condition déclenchement Type Evènement | P1: Condition déclenchement Type Evènement | Q1: Libellé Population | R1: Codification Population | S1: Typologie de population | T1: Général / Particulier | U1: Passant / Exclu | V1: Date de début | W1: Date de fin | X1: Règles mobilisées | Y1: Identifiant Règle de contrôle intellectuel 1 | Z1: Libellé Règle de contrôle intellectuel 1 | AA1: Identifiant Règle de contrôle intellectuel 2 | AB1: Libellé Règle de contrôle intellectuel 2 | AC1: Identifiant Règle de contrôle intellectuel 3 | AD1: Libellé Règle de contrôle intellectuel 3 | AE1: Identifiant Règle de contrôle intellectuel 4 | AF1: Libellé Règle de contrôle intellectuel 4 | AG1: Identifiant Règle de contrôle intellectuel 5 | AH1: Libellé Règle de contrôle intellectuel 5 | AI1: Identifiant Règle de contrôle intellectuel 6 | AJ1: Libellé Règle de contrôle intellectuel 6 | AK1: Identifiant Règle de contrôle intellectuel 7 | AL1: Libellé Règle de contrôle intellectuel 7 | AM1: Identifiant Règle de contrôle intellectuel 8 | AN1: Libellé Règle de contrôle intellectuel 8 | AO1: Identifiant Règle de contrôle intellectuel 9 | AP1: Libellé Règle de contrôle intellectuel 9 | AQ1: Identifiant Règle de contrôle intellectuel 10 | AR1: Libellé Règle de contrôle intellectuel 10 | AS1: Identifiant Règle de contrôle intellectuel 11 | AT1: Libellé Règle de contrôle intellectuel 11 | AU1: Identifiant Règle de contrôle intellectuel 12 | AV1: Libellé Règle de contrôle intellectuel 12 | AW1: Identifiant Règle de contrôle intellectuel 13 | AX1: Libellé Règle de contrôle intellectuel 13 | AY1: Identifiant Règle de condition 1 | AZ1: Libellé Règle de condition 1 | BA1: Identifiant Règle de condition 2 | BB1: Libellé Règle de condition 2 | BC1: Identifiant Règle de condition 3 | BD1: Libellé Règle de condition 3 | BE1: Identifiant Règle de condition 4 | BF1: Libellé Règle de condition 4 | BG1: Identifiant Règle de condition 5 | BH1: Libellé Règle de condition 5 | BI1: Identifiant Règle de condition 6 | BJ1: Libellé Règle de condition 6 | BK1: Identifiant Règle de condition 7 | BL1: Libellé Règle de condition 7 | BM1: Identifiant Règle de condition 8 | BN1: Libellé Règle de condition 8 | BO1: Identifiant Règle de condition 9 | BP1: Libellé Règle de condition 9 | BQ1: Identifiant Règle de condition 10 | BR1: Libellé Règle de condition 10 | BS1: Identifiant Règle de condition 11 | BT1: Libellé Règle de condition 11 | BU1: Identifiant Règle de condition 12 | BV1: Libellé Règle de condition 12 | BW1: Identifiant Règle de condition 13 | BX1: Libellé Règle de condition 13 | BY1: Identifiant Règle de contrôle 1 | BZ1: Libellé Règle de contrôle 1 | CA1: Identifiant Règle de contrôle 2 | CB1: Libellé Règle de contrôle 2 | CC1: Identifiant Règle de contrôle 3 | CD1: Libellé Règle de contrôle 3 | CE1: Identifiant Règle de contrôle 4 | CF1: Libellé Règle de contrôle 4 | CG1: Identifiant Règle de contrôle 5 | CH1: Libellé Règle de contrôle 5 | CI1: Identifiant Règle de contrôle 6 | CJ1: Libellé Règle de contrôle 6 | CK1: Identifiant Règle de contrôle 7 | CL1: Libellé Règle de contrôle 7 | CM1: Identifiant Règle de contrôle 8 | CN1: Libellé Règle de contrôle 8 | CO1: Identifiant Règle de contrôle 9 | CP1: Libellé Règle de contrôle 9 | CQ1: Identifiant Règle de contrôle 10 | CR1: Libellé Règle de contrôle 10 | CS1: Identifiant Règle de contrôle 11 | CT1: Libellé Règle de contrôle 11 | CU1: Identifiant Règle de contrôle 12 | CV1: Libellé Règle de contrôle 12 | CW1: Identifiant Règle de contrôle 13 | CX1: Libellé Règle de contrôle 13 | CY1: Identifiant Règle de contrôle 14 | CZ1: Libellé Règle de contrôle 14 | DA1: Identifiant Règle de contrôle 15 | DB1: Libellé Règle de contrôle 15 | DC1: Identifiant Règle de contrôle 16 | DD1: Libellé Règle de contrôle 16 | DE1: Identifiant Règle de contrôle 17 | DF1: Libellé Règle de contrôle 17 | DG1: Identifiant Règle de contrôle 18 | DH1: Libellé Règle de contrôle 18 | DI1: FIME | DJ1: Statut de travail
A2: 17.10.00 | B2: A | C2: 43152.5 | D2: D0004 | E2: Position | F2: S0031 | G2: Congé parental | H2: E0333 | I2: Congé parental après congé de maternité | J2: Position saisie égale à 'Congé parental après congé de maternité' | K2: A_POS_POSIAD [Saisi] = 'CGP01' | L2: T0964 | M2: Congé parental après congé de maternité - Demande | N2: Création Modification | O2: Indicateur de renouvellement saisi = Non ET (Indicateur de renouvellement saisi différent d'Indicateur de renouvellement avant saisi OU Lien vers enfant saisi différent du Lien vers enfant avant saisi) ET Position saisie de l'occurrence précédente est différente d'une position de 'Congé parental' | P2: A_POS_INDREN [Saisi] = '0' ET (A_POS_INDREN [Saisi] <> A_POS_INDREN [Valeur avant saisie] OU A_POS_LVEPAC [Saisi] <> A_POS_LVEPAC [Valeur avant saisie]) ET (A_POS_POSIAD [Occurrence précédente] = POSITION_SITUATION.R_FOR_IDEN05 ET POSITION_SITUATION.R_REL_PSSAG2 <> 'CGP') | Q2: Titulaire ou magistrat | R2: P0001 | S2: T | T2: Général | U2: Passant | V2: 40725 | W2: 41182 | X2: CPR_D_007 ET CPR_D_702 ET CPR_D_002 ET CPR_D_003 ET CPR_D_025 ET CPR_D_700 ET POS_C_100 ET POS_C_004 ET POS_C_005 ET POS_C_007 ET POS_C_010 ET POS_C_012 ET POS_C_022 ET POS_C_050 ET POS_C_051 ET POS_C_055 ET POS_C_056 ET POS_C_057 ET POS_C_111 | AY2: CPR_D_007 | AZ2: =VLOOKUP(AY2,'Axe 2 Règles de gestion'!$D$2:$F$506,3, FALSE) -> Le congé parental est accordé par périodes de 6 mois maximum renouvelables (date de fin prévisionnelle du congé parental). | BA2: CPR_D_702 | BB2: =VLOOKUP(BA2,'Axe 2 Règles de gestion'!$D$2:$F$506,3, FALSE) -> Le congé parental est accordé par périodes de 6 mois maximum renouvelables (date de fin réelle du congé parental). | BC2: CPR_D_002 | BD2: =VLOOKUP(BC2,'Axe 2 Règles de gestion'!$D$2:$F$506,3, FALSE) -> L'agent doit avoir la qualité de mère ou de père. | BE2: CPR_D_003 | BF2: =VLOOKUP(BE2,'Axe 2 Règles de gestion'!$D$2:$F$506,3, FALSE) -> L'enfant né au foyer doit être âgé de 3 ans au plus (date de fin prévisionnelle du congé parental). | BG2: CPR_D_025 | BH2: =VLOOKUP(BG2,'Axe 2 Règles de gestion'!$D$2:$F$506,3, FALSE) -> Le congé parental est accordé de droit à la mère après un congé maternité. | BI2: CPR_D_700 | BJ2: =VLOOKUP(BI2,'Axe 2 Règles de gestion'!$D$2:$F$506,3, FALSE) -> L'enfant né au foyer doit être âgé de 3 ans au plus (date de fin réelle du congé parental). | BY2: POS_C_100 | BZ2: =VLOOKUP(BY2,'Axe 2 Règles de gestion'!$D$2:$F$506,3, FALSE) -> Lors de la demande initiale, l'agent doit être en activité. | CA2: POS_C_004 | CB2: =VLOOKUP(CA2,'Axe 2 Règles de gestion'!$D$2:$F$506,3, FALSE) -> La date de début de position doit être antérieure ou égale à la date de fin prévisionnelle de position. | CC2: POS_C_005 | CD2: =VLOOKUP(CC2,'Axe 2 Règles de gestion'!$D$2:$F$506,3, FALSE) -> La date de début de la position doit être postérieure ou égale à la date d'entrée dans la FPE ou dans la carrière militaire. | CE2: POS_C_007 | CF2: =VLOOKUP(CE2,'Axe 2 Règles de gestion'!$D$2:$F$506,3, FALSE) -> La date de fin réelle de la position doit être antérieure à la date limite de départ à la retraite. | CG2: POS_C_010 | CH2: =VLOOKUP(CG2,'Axe 2 Règles de gestion'!$D$2:$F$506,3, FALSE) -> La date de début de position doit être antérieure ou égale à la date de fin réelle de position. | CI2: POS_C_012 | CJ2: =VLOOKUP(CI2,'Axe 2 Règles de gestion'!$D$2:$F$506,3, FALSE) -> La date de fin prévisionnelle de la position doit être antérieure à la date limite de départ à la retraite. | CK2: POS_C_022 | CL2: =VLOOKUP(CK2,'Axe 2 Règles de gestion'!$D$2:$F$506,3, FALSE) -> La date de début de position est à J+1 de la date de fin de position de l'occurrence précédente. | CM2: POS_C_050 | CN2: =VLOOKUP(CM2,'Axe 2 Règles de gestion'!$D$2:$F$506,3, FALSE) -> Le lien vers l'enfant doit être renseigné. | CO2: POS_C_051 | CP2: =VLOOKUP(CO2,'Axe 2 Règles de gestion'!$D$2:$F$506,3, FALSE) -> La date de naissance de l'enfant doit être renseignée. | CQ2: POS_C_055 | CR2: =VLOOKUP(CQ2,'Axe 2 Règles de gestion'!$D$2:$F$506,3, FALSE) -> La date de fin réelle de la position doit être antérieure ou égale à la date de décès de l'enfant. | CS2: POS_C_056 | CT2: =VLOOKUP(CS2,'Axe 2 Règles de gestion'!$D$2:$F$506,3, FALSE) -> La date de fin prévisionnelle de la position doit être antérieure ou égale à la date de décès de l'enfant. | CU2: POS_C_057 | CV2: =VLOOKUP(CU2,'Axe 2 Règles de gestion'!$D$2:$F$506,3, FALSE) -> L'agent ne doit pas être en position de détachement entrant sur l'occurrence précédente. | CW2: POS_C_111 | CX2: =VLOOKUP(CW2,'Axe 2 Règles de gestion'!$D$2:$F$506,3, FALSE) -> La date de fin ou la date de fin prévisionnelle doit être saisie.
A3: 25.10.00 | B3: M | C3: 45989.673 | D3: D0004 | E3: Position | F3: S0031 | G3: Congé parental | H3: E0333 | I3: Congé parental après congé de maternité | J3: Position saisie égale à 'Congé parental après congé de maternité' | K3: A_POS_POSIAD [Saisi] = 'CGP01' | L3: T0964 | M3: Congé parental après congé de maternité - Demande | N3: Création Modification | O3: Indicateur de renouvellement saisi = Non ET (Indicateur de renouvellement saisi différent d'Indicateur de renouvellement avant saisi OU Lien vers enfant saisi différent du Lien vers enfant avant saisi) ET Position saisie de l'occurrence précédente est différente d'une position de 'Congé parental' | P3: A_POS_INDREN [Saisi] = '0' ET (A_POS_INDREN [Saisi] <> A_POS_INDREN [Valeur avant saisie] OU A_POS_LVEPAC [Saisi] <> A_POS_LVEPAC [Valeur avant saisie]) ET (A_POS_POSIAD [Occurrence précédente] = POSITION_SITUATION.R_FOR_IDEN05 ET POSITION_SITUATION.R_REL_PSSAG2 <> 'CGP') | Q3: Titulaire ou magistrat | R3: P0001 | S3: T | T3: Général | U3: Exclu | V3: 41183 | W3: 46110
A4: 17.10.00 | B4: A | C4: 43152.5 | D4: D0004 | E4: Position | F4: S0031 | G4: Congé parental | H4: E0333 | I4: Congé parental après congé de maternité | J4: Position saisie égale à 'Congé parental après congé de maternité' | K4: A_POS_POSIAD [Saisi] = 'CGP01' | L4: T0965 | M4: Congé parental après congé de maternité - Renouvellement | N4: Création Modification | O4: Indicateur de renouvellement saisi = Oui ET (Indicateur de renouvellement saisi différent d'Indicateur de renouvellement avant saisi OU Lien vers enfant saisi différent du Lien vers enfant avant saisi) | P4: A_POS_INDREN [Saisi] = '1' ET (A_POS_INDREN [Saisi] <> A_POS_INDREN [Valeur avant saisie] OU A_POS_LVEPAC [Saisi] <> A_POS_LVEPAC [Valeur avant saisie]) | Q4: Titulaire ou magistrat | R4: P0001 | S4: T | T4: Général | U4: Passant | V4: 40725 | W4: 41362 | X4: CPR_D_007 ET CPR_D_702 ET CPR_D_002 ET CPR_D_003 ET CPR_D_700 ET POS_C_004 ET POS_C_005 ET POS_C_007 ET POS_C_010 ET POS_C_012 ET POS_C_022 ET POS_C_050 ET POS_C_051 ET POS_C_055 ET POS_C_056 ET POS_C_111 | AY4: CPR_D_007 | AZ4: =VLOOKUP(AY4,'Axe 2 Règles de gestion'!$D$2:$F$506,3, FALSE) -> Le congé parental est accordé par périodes de 6 mois maximum renouvelables (date de fin prévisionnelle du congé parental). | BA4: CPR_D_702 | BB4: =VLOOKUP(BA4,'Axe 2 Règles de gestion'!$D$2:$F$506,3, FALSE) -> Le congé parental est accordé par périodes de 6 mois maximum renouvelables (date de fin réelle du congé parental). | BC4: CPR_D_002 | BD4: =VLOOKUP(BC4,'Axe 2 Règles de gestion'!$D$2:$F$506,3, FALSE) -> L'agent doit avoir la qualité de mère ou de père. | BE4: CPR_D_003 | BF4: =VLOOKUP(BE4,'Axe 2 Règles de gestion'!$D$2:$F$506,3, FALSE) -> L'enfant né au foyer doit être âgé de 3 ans au plus (date de fin prévisionnelle du congé parental). | BG4: CPR_D_700 | BH4: =VLOOKUP(BG4,'Axe 2 Règles de gestion'!$D$2:$F$506,3, FALSE) -> L'enfant né au foyer doit être âgé de 3 ans au plus (date de fin réelle du congé parental). | BY4: POS_C_004 | BZ4: =VLOOKUP(BY4,'Axe 2 Règles de gestion'!$D$2:$F$506,3, FALSE) -> La date de début de position doit être antérieure ou égale à la date de fin prévisionnelle de position. | CA4: POS_C_005 | CB4: =VLOOKUP(CA4,'Axe 2 Règles de gestion'!$D$2:$F$506,3, FALSE) -> La date de début de la position doit être postérieure ou égale à la date d'entrée dans la FPE ou dans la carrière militaire. | CC4: POS_C_007 | CD4: =VLOOKUP(CC4,'Axe 2 Règles de gestion'!$D$2:$F$506,3, FALSE) -> La date de fin réelle de la position doit être antérieure à la date limite de départ à la retraite. | CE4: POS_C_010 | CF4: =VLOOKUP(CE4,'Axe 2 Règles de gestion'!$D$2:$F$506,3, FALSE) -> La date de début de position doit être antérieure ou égale à la date de fin réelle de position. | CG4: POS_C_012 | CH4: =VLOOKUP(CG4,'Axe 2 Règles de gestion'!$D$2:$F$506,3, FALSE) -> La date de fin prévisionnelle de la position doit être antérieure à la date limite de départ à la retraite. | CI4: POS_C_022 | CJ4: =VLOOKUP(CI4,'Axe 2 Règles de gestion'!$D$2:$F$506,3, FALSE) -> La date de début de position est à J+1 de la date de fin de position de l'occurrence précédente. | CK4: POS_C_050 | CL4: =VLOOKUP(CK4,'Axe 2 Règles de gestion'!$D$2:$F$506,3, FALSE) -> Le lien vers l'enfant doit être renseigné. | CM4: POS_C_051 | CN4: =VLOOKUP(CM4,'Axe 2 Règles de gestion'!$D$2:$F$506,3, FALSE) -> La date de naissance de l'enfant doit être renseignée. | CO4: POS_C_055 | CP4: =VLOOKUP(CO4,'Axe 2 Règles de gestion'!$D$2:$F$506,3, FALSE) -> La date de fin réelle de la position doit être antérieure ou égale à la date de décès de l'enfant. | CQ4: POS_C_056 | CR4: =VLOOKUP(CQ4,'Axe 2 Règles de gestion'!$D$2:$F$506,3, FALSE) -> La date de fin prévisionnelle de la position doit être antérieure ou égale à la date de décès de l'enfant. | CS4: POS_C_111 | CT4: =VLOOKUP(CS4,'Axe 2 Règles de gestion'!$D$2:$F$506,3, FALSE) -> La date de fin ou la date de fin prévisionnelle doit être saisie.
A5: 25.10.00 | B5: M | C5: 45989.676 | D5: D0004 | E5: Position | F5: S0031 | G5: Congé parental | H5: E0333 | I5: Congé parental après congé de maternité | J5: Position saisie égale à 'Congé parental après congé de maternité' | K5: A_POS_POSIAD [Saisi] = 'CGP01' | L5: T0965 | M5: Congé parental après congé de maternité - Renouvellement | N5: Création Modification | O5: Indicateur de renouvellement saisi = Oui ET (Indicateur de renouvellement saisi différent d'Indicateur de renouvellement avant saisi OU Lien vers enfant saisi différent du Lien vers enfant avant saisi) | P5: A_POS_INDREN [Saisi] = '1' ET (A_POS_INDREN [Saisi] <> A_POS_INDREN [Valeur avant saisie] OU A_POS_LVEPAC [Saisi] <> A_POS_LVEPAC [Valeur avant saisie]) | Q5: Titulaire ou magistrat | R5: P0001 | S5: T | T5: Général | U5: Exclu | V5: 41363 | W5: 46110
A6: 17.10.00 | B6: A | C6: 43152.5 | D6: D0004 | E6: Position | F6: S0031 | G6: Congé parental | H6: E0333 | I6: Congé parental après congé de maternité | J6: Position saisie égale à 'Congé parental après congé de maternité' | K6: A_POS_POSIAD [Saisi] = 'CGP01' | L6: T0967 | M6: Congé parental après congé de maternité - Réintégration | N6: Modification | O6: Indicateur de renouvellement saisi identique à Indicateur de renouvellement avant saisi ET Lien vers enfant saisi identique au Lien vers enfant avant saisi | P6: A_POS_INDREN [Saisi] = A_POS_INDREN [Valeur avant saisie] ET A_POS_LVEPAC [Saisi] = A_POS_LVEPAC [Valeur avant saisie]) | Q6: Titulaire ou magistrat | R6: P0001 | S6: T | T6: Général | U6: Passant | V6: 40725 | W6: 41362 | X6: CPR_D_007 ET CPR_D_702 ET CPR_D_003 ET CPR_D_700 ET POS_C_004 ET POS_C_007 ET POS_C_010 ET POS_C_012 ET POS_C_050 ET POS_C_051 ET POS_C_055 ET POS_C_056 ET POS_C_111 | AY6: CPR_D_007 | AZ6: =VLOOKUP(AY6,'Axe 2 Règles de gestion'!$D$2:$F$506,3, FALSE) -> Le congé parental est accordé par périodes de 6 mois maximum renouvelables (date de fin prévisionnelle du congé parental). | BA6: CPR_D_702 | BB6: =VLOOKUP(BA6,'Axe 2 Règles de gestion'!$D$2:$F$506,3, FALSE) -> Le congé parental est accordé par périodes de 6 mois maximum renouvelables (date de fin réelle du congé parental). | BC6: CPR_D_003 | BD6: =VLOOKUP(BC6,'Axe 2 Règles de gestion'!$D$2:$F$506,3, FALSE) -> L'enfant né au foyer doit être âgé de 3 ans au plus (date de fin prévisionnelle du congé parental). | BE6: CPR_D_700 | BF6: =VLOOKUP(BE6,'Axe 2 Règles de gestion'!$D$2:$F$506,3, FALSE) -> L'enfant né au foyer doit être âgé de 3 ans au plus (date de fin réelle du congé parental). | BY6: POS_C_004 | BZ6: =VLOOKUP(BY6,'Axe 2 Règles de gestion'!$D$2:$F$506,3, FALSE) -> La date de début de position doit être antérieure ou égale à la date de fin prévisionnelle de position. | CA6: POS_C_007 | CB6: =VLOOKUP(CA6,'Axe 2 Règles de gestion'!$D$2:$F$506,3, FALSE) -> La date de fin réelle de la position doit être antérieure à la date limite de départ à la retraite. | CC6: POS_C_010 | CD6: =VLOOKUP(CC6,'Axe 2 Règles de gestion'!$D$2:$F$506,3, FALSE) -> La date de début de position doit être antérieure ou égale à la date de fin réelle de position. | CE6: POS_C_012 | CF6: =VLOOKUP(CE6,'Axe 2 Règles de gestion'!$D$2:$F$506,3, FALSE) -> La date de fin prévisionnelle de la position doit être antérieure à la date limite de départ à la retraite. | CG6: POS_C_050 | CH6: =VLOOKUP(CG6,'Axe 2 Règles de gestion'!$D$2:$F$506,3, FALSE) -> Le lien vers l'enfant doit être renseigné. | CI6: POS_C_051 | CJ6: =VLOOKUP(CI6,'Axe 2 Règles de gestion'!$D$2:$F$506,3, FALSE) -> La date de naissance de l'enfant doit être renseignée. | CK6: POS_C_055 | CL6: =VLOOKUP(CK6,'Axe 2 Règles de gestion'!$D$2:$F$506,3, FALSE) -> La date de fin réelle de la position doit être antérieure ou égale à la date de décès de l'enfant. | CM6: POS_C_056 | CN6: =VLOOKUP(CM6,'Axe 2 Règles de gestion'!$D$2:$F$506,3, FALSE) -> La date de fin prévisionnelle de la position doit être antérieure ou égale à la date de décès de l'enfant. | CO6: POS_C_111 | CP6: =VLOOKUP(CO6,'Axe 2 Règles de gestion'!$D$2:$F$506,3, FALSE) -> La date de fin ou la date de fin prévisionnelle doit être saisie.
A7: 25.10.00 | B7: M | C7: 45989.707 | D7: D0004 | E7: Position | F7: S0031 | G7: Congé parental | H7: E0333 | I7: Congé parental après congé de maternité | J7: Position saisie égale à 'Congé parental après congé de maternité' | K7: A_POS_POSIAD [Saisi] = 'CGP01' | L7: T0967 | M7: Congé parental après congé de maternité - Réintégration | N7: Modification | O7: Indicateur de renouvellement saisi identique à Indicateur de renouvellement avant saisi ET Lien vers enfant saisi identique au Lien vers enfant avant saisi | P7: A_POS_INDREN [Saisi] = A_POS_INDREN [Valeur avant saisie] ET A_POS_LVEPAC [Saisi] = A_POS_LVEPAC [Valeur avant saisie]) | Q7: Titulaire ou magistrat | R7: P0001 | S7: T | T7: Général | U7: Exclu | V7: 41363 | W7: 46110
A8: 17.10.00 | B8: A | C8: 43152.5 | D8: D0004 | E8: Position | F8: S0031 | G8: Congé parental | H8: E0333 | I8: Congé parental après congé de maternité | J8: Position saisie égale à 'Congé parental après congé de maternité' | K8: A_POS_POSIAD [Saisi] = 'CGP01' | L8: T1578 | M8: Congé parental après Congé de maternité - Demande pendant un Congé parental | N8: Création Modification | O8: Indicateur de renouvellement saisi = Non ET (Indicateur de renouvellement saisi différent d'Indicateur de renouvellement avant saisi OU Lien vers enfant saisi différent du Lien vers enfant avant saisi) ET Position saisie de l'occurrence précédente est une position de 'Congé parental' | P8: A_POS_INDREN [Saisi] = '0' ET (A_POS_INDREN [Saisi] <> A_POS_INDREN [Valeur avant saisie] OU A_POS_LVEPAC [Saisi] <> A_POS_LVEPAC [Valeur avant saisie]) ET (A_POS_POSIAD [Occurrence précédente] = POSITION_SITUATION.R_FOR_IDEN05 ET POSITION_SITUATION.R_REL_PSSAG2 = 'CGP') | Q8: Titulaire ou magistrat | R8: P0001 | S8: T | T8: Général | U8: Passant | V8: 40725 | W8: 41182 | X8: CPR_D_007 ET CPR_D_702 ET CPR_D_657 ET CPR_D_002 ET CPR_D_025 ET CPR_D_066 ET CPR_D_714 ET POS_C_004 ET POS_C_005 ET POS_C_007 ET POS_C_010 ET POS_C_012 ET POS_C_022 ET POS_C_050 ET POS_C_051 ET POS_C_055 ET POS_C_056 ET POS_C_111 | AY8: CPR_D_007 | AZ8: =VLOOKUP(AY8,'Axe 2 Règles de gestion'!$D$2:$F$506,3, FALSE) -> Le congé parental est accordé par périodes de 6 mois maximum renouvelables (date de fin prévisionnelle du congé parental). | BA8: CPR_D_702 | BB8: =VLOOKUP(BA8,'Axe 2 Règles de gestion'!$D$2:$F$506,3, FALSE) -> Le congé parental est accordé par périodes de 6 mois maximum renouvelables (date de fin réelle du congé parental). | BC8: CPR_D_657 | BD8: =VLOOKUP(BC8,'Axe 2 Règles de gestion'!$D$2:$F$506,3, FALSE) -> Si une nouvelle naissance ou adoption intervient alors que l'agent est déjà en position de congé parental, celui-ci a droit, du chef de son nouvel enfant, à un nouveau congé parental. | BE8: CPR_D_002 | BF8: =VLOOKUP(BE8,'Axe 2 Règles de gestion'!$D$2:$F$506,3, FALSE) -> L'agent doit avoir la qualité de mère ou de père. | BG8: CPR_D_025 | BH8: =VLOOKUP(BG8,'Axe 2 Règles de gestion'!$D$2:$F$506,3, FALSE) -> Le congé parental est accordé de droit à la mère après un congé maternité. | BI8: CPR_D_066 | BJ8: =VLOOKUP(BI8,'Axe 2 Règles de gestion'!$D$2:$F$506,3, FALSE) -> L'enfant né au foyer doit être âgé de 3 ans au plus (date de fin prévisionnelle du congé parental). | BK8: CPR_D_714 | BL8: =VLOOKUP(BK8,'Axe 2 Règles de gestion'!$D$2:$F$506,3, FALSE) -> L'enfant né au foyer doit être âgé de 3 ans au plus (date de fin réelle du congé parental). | BY8: POS_C_004 | BZ8: =VLOOKUP(BY8,'Axe 2 Règles de gestion'!$D$2:$F$506,3, FALSE) -> La date de début de position doit être antérieure ou égale à la date de fin prévisionnelle de position. | CA8: POS_C_005 | CB8: =VLOOKUP(CA8,'Axe 2 Règles de gestion'!$D$2:$F$506,3, FALSE) -> La date de début de la position doit être postérieure ou égale à la date d'entrée dans la FPE ou dans la carrière militaire. | CC8: POS_C_007 | CD8: =VLOOKUP(CC8,'Axe 2 Règles de gestion'!$D$2:$F$506,3, FALSE) -> La date de fin réelle de la position doit être antérieure à la date limite de départ à la retraite. | CE8: POS_C_010 | CF8: =VLOOKUP(CE8,'Axe 2 Règles de gestion'!$D$2:$F$506,3, FALSE) -> La date de début de position doit être antérieure ou égale à la date de fin réelle de position. | CG8: POS_C_012 | CH8: =VLOOKUP(CG8,'Axe 2 Règles de gestion'!$D$2:$F$506,3, FALSE) -> La date de fin prévisionnelle de la position doit être antérieure à la date limite de départ à la retraite. | CI8: POS_C_022 | CJ8: =VLOOKUP(CI8,'Axe 2 Règles de gestion'!$D$2:$F$506,3, FALSE) -> La date de début de position est à J+1 de la date de fin de position de l'occurrence précédente. | CK8: POS_C_050 | CL8: =VLOOKUP(CK8,'Axe 2 Règles de gestion'!$D$2:$F$506,3, FALSE) -> Le lien vers l'enfant doit être renseigné. | CM8: POS_C_051 | CN8: =VLOOKUP(CM8,'Axe 2 Règles de gestion'!$D$2:$F$506,3, FALSE) -> La date de naissance de l'enfant doit être renseignée. | CO8: POS_C_055 | CP8: =VLOOKUP(CO8,'Axe 2 Règles de gestion'!$D$2:$F$506,3, FALSE) -> La date de fin réelle de la position doit être antérieure ou égale à la date de décès de l'enfant. | CQ8: POS_C_056 | CR8: =VLOOKUP(CQ8,'Axe 2 Règles de gestion'!$D$2:$F$506,3, FALSE) -> La date de fin prévisionnelle de la position doit être antérieure ou égale à la date de décès de l'enfant. | CS8: POS_C_111 | CT8: =VLOOKUP(CS8,'Axe 2 Règles de gestion'!$D$2:$F$506,3, FALSE) -> La date de fin ou la date de fin prévisionnelle doit être saisie.
A9: 25.10.00 | B9: M | C9: 45992.61 | D9: D0004 | E9: Position | F9: S0031 | G9: Congé parental | H9: E0333 | I9: Congé parental après congé de maternité | J9: Position saisie égale à 'Congé parental après congé de maternité' | K9: A_POS_POSIAD [Saisi] = 'CGP01' | L9: T1578 | M9: Congé parental après Congé de maternité - Demande pendant un Congé parental | N9: Création Modification | O9: Indicateur de renouvellement saisi = Non ET (Indicateur de renouvellement saisi différent d'Indicateur de renouvellement avant saisi OU Lien vers enfant saisi différent du Lien vers enfant avant saisi) ET Position saisie de l'occurrence précédente est une position de 'Congé parental' | P9: A_POS_INDREN [Saisi] = '0' ET (A_POS_INDREN [Saisi] <> A_POS_INDREN [Valeur avant saisie] OU A_POS_LVEPAC [Saisi] <> A_POS_LVEPAC [Valeur avant saisie]) ET (A_POS_POSIAD [Occurrence précédente] = POSITION_SITUATION.R_FOR_IDEN05 ET POSITION_SITUATION.R_REL_PSSAG2 = 'CGP') | Q9: Titulaire ou magistrat | R9: P0001 | S9: T | T9: Général | U9: Exclu | V9: 41183 | W9: 46110
A10: 25.10.00 | B10: M | C10: 45989.674 | D10: D0004 | E10: Position | F10: S0031 | G10: Congé parental | H10: E0333 | I10: Congé parental après congé de maternité | J10: Position saisie égale à 'Congé parental après congé de maternité' | K10: A_POS_POSIAD [Saisi] = 'CGP01' | L10: T0964 | M10: Congé parental après congé de maternité - Demande | N10: Création Modification | O10: Indicateur de renouvellement saisi = Non ET (Indicateur de renouvellement saisi différent d'Indicateur de renouvellement avant saisi OU Lien vers enfant saisi différent du Lien vers enfant avant saisi) ET Position saisie de l'occurrence précédente est différente d'une position de 'Congé parental' | P10: A_POS_INDREN [Saisi] = '0' ET (A_POS_INDREN [Saisi] <> A_POS_INDREN [Valeur avant saisie] OU A_POS_LVEPAC [Saisi] <> A_POS_LVEPAC [Valeur avant saisie]) ET (A_POS_POSIAD [Occurrence précédente] = POSITION_SITUATION.R_FOR_IDEN05 ET POSITION_SITUATION.R_REL_PSSAG2 <> 'CGP') | Q10: Militaire | R10: P0002 | S10: M | T10: Général | U10: Exclu | V10: 40725 | W10: 46110
A11: 25.10.00 | B11: M | C11: 45989.675 | D11: D0004 | E11: Position | F11: S0031 | G11: Congé parental | H11: E0333 | I11: Congé parental après congé de maternité | J11: Position saisie égale à 'Congé parental après congé de maternité' | K11: A_POS_POSIAD [Saisi] = 'CGP01' | L11: T0965 | M11: Congé parental après congé de maternité - Renouvellement | N11: Création Modification | O11: Indicateur de renouvellement saisi = Oui ET (Indicateur de renouvellement saisi différent d'Indicateur de renouvellement avant saisi OU Lien vers enfant saisi différent du Lien vers enfant avant saisi) | P11: A_POS_INDREN [Saisi] = '1' ET (A_POS_INDREN [Saisi] <> A_POS_INDREN [Valeur avant saisie] OU A_POS_LVEPAC [Saisi] <> A_POS_LVEPAC [Valeur avant saisie]) | Q11: Militaire | R11: P0002 | S11: M | T11: Général | U11: Exclu | V11: 40725 | W11: 46110
A12: 25.10.00 | B12: M | C12: 45989.677 | D12: D0004 | E12: Position | F12: S0031 | G12: Congé parental | H12: E0333 | I12: Congé parental après congé de maternité | J12: Position saisie égale à 'Congé parental après congé de maternité' | K12: A_POS_POSIAD [Saisi] = 'CGP01' | L12: T0967 | M12: Congé parental après congé de maternité - Réintégration | N12: Modification | O12: Indicateur de renouvellement saisi identique à Indicateur de renouvellement avant saisi ET Lien vers enfant saisi identique au Lien vers enfant avant saisi | P12: A_POS_INDREN [Saisi] = A_POS_INDREN [Valeur avant saisie] ET A_POS_LVEPAC [Saisi] = A_POS_LVEPAC [Valeur avant saisie]) | Q12: Militaire | R12: P0002 | S12: M | T12: Général | U12: Exclu | V12: 40725 | W12: 46110
A13: 25.10.00 | B13: M | C13: 45992.61 | D13: D0004 | E13: Position | F13: S0031 | G13: Congé parental | H13: E0333 | I13: Congé parental après congé de maternité | J13: Position saisie égale à 'Congé parental après congé de maternité' | K13: A_POS_POSIAD [Saisi] = 'CGP01' | L13: T1578 | M13: Congé parental après Congé de maternité - Demande pendant un Congé parental | N13: Création Modification | O13: Indicateur de renouvellement saisi = Non ET (Indicateur de renouvellement saisi différent d'Indicateur de renouvellement avant saisi OU Lien vers enfant saisi différent du Lien vers enfant avant saisi) ET Position saisie de l'occurrence précédente est une position de 'Congé parental' | P13: A_POS_INDREN [Saisi] = '0' ET (A_POS_INDREN [Saisi] <> A_POS_INDREN [Valeur avant saisie] OU A_POS_LVEPAC [Saisi] <> A_POS_LVEPAC [Valeur avant saisie]) ET (A_POS_POSIAD [Occurrence précédente] = POSITION_SITUATION.R_FOR_IDEN05 ET POSITION_SITUATION.R_REL_PSSAG2 = 'CGP') | Q13: Militaire | R13: P0002 | S13: M | T13: Général | U13: Exclu | V13: 40725 | W13: 46110
A14: 17.10.00 | B14: A | C14: 43152.5 | D14: D0004 | E14: Position | F14: S0031 | G14: Congé parental | H14: E0333 | I14: Congé parental après congé de maternité | J14: Position saisie égale à 'Congé parental après congé de maternité' | K14: A_POS_POSIAD [Saisi] = 'CGP01' | L14: T0964 | M14: Congé parental après congé de maternité - Demande | N14: Création Modification | O14: Indicateur de renouvellement saisi = Non ET (Indicateur de renouvellement saisi différent d'Indicateur de renouvellement avant saisi OU Lien vers enfant saisi différent du Lien vers enfant avant saisi) ET Position saisie de l'occurrence précédente est différente d'une position de 'Congé parental' | P14: A_POS_INDREN [Saisi] = '0' ET (A_POS_INDREN [Saisi] <> A_POS_INDREN [Valeur avant saisie] OU A_POS_LVEPAC [Saisi] <> A_POS_LVEPAC [Valeur avant saisie]) ET (A_POS_POSIAD [Occurrence précédente] = POSITION_SITUATION.R_FOR_IDEN05 ET POSITION_SITUATION.R_REL_PSSAG2 <> 'CGP') | Q14: Contractuel | R14: P0003 | S14: N | T14: Général | U14: Passant | V14: 40725 | W14: 41182 | X14: CPR_D_024 ET CPR_D_744 ET CPR_D_020 ET CPR_D_743 ET CPR_D_018 ET CPR_D_017 ET CPR_D_043 ET POS_C_100 ET POS_C_004 ET POS_C_006 ET POS_C_007 ET POS_C_009 ET POS_C_010 ET POS_C_012 ET POS_C_022 ET POS_C_050 ET POS_C_051 ET POS_C_055 ET POS_C_056 ET POS_C_057 ET POS_C_106 ET POS_C_111 | AY14: CPR_D_024 | AZ14: =VLOOKUP(AY14,'Axe 2 Règles de gestion'!$D$2:$F$506,3, FALSE) -> Le congé parental est accordé par périodes de 6 mois maximum renouvelables (date de fin prévisionnelle du congé parental). | BA14: CPR_D_744 | BB14: =VLOOKUP(BA14,'Axe 2 Règles de gestion'!$D$2:$F$506,3, FALSE) -> Le congé parental est accordé par périodes de 6 mois maximum renouvelables (date de fin réelle du congé parental). | BC14: CPR_D_020 | BD14: =VLOOKUP(BC14,'Axe 2 Règles de gestion'!$D$2:$F$506,3, FALSE) -> L'enfant né au foyer doit être âgé de 3 ans au plus (date de fin prévisionnelle du congé parental). | BE14: CPR_D_743 | BF14: =VLOOKUP(BE14,'Axe 2 Règles de gestion'!$D$2:$F$506,3, FALSE) -> L'enfant né au foyer doit être âgé de 3 ans au plus (date de fin réelle du congé parental). | BG14: CPR_D_018 | BH14: =VLOOKUP(BG14,'Axe 2 Règles de gestion'!$D$2:$F$506,3, FALSE) -> L'agent doit justifier d'une ancienneté minimale d'un an à la date de la naissance. | BI14: CPR_D_017 | BJ14: =VLOOKUP(BI14,'Axe 2 Règles de gestion'!$D$2:$F$506,3, FALSE) -> L'agent doit avoir la qualité de mère ou de père. | BK14: CPR_D_043 | BL14: =VLOOKUP(BK14,'Axe 2 Règles de gestion'!$D$2:$F$506,3, FALSE) -> Le congé parental est accordé de droit à la mère après un congé maternité. | BY14: POS_C_100 | BZ14: =VLOOKUP(BY14,'Axe 2 Règles de gestion'!$D$2:$F$506,3, FALSE) -> Lors de la demande initiale, l'agent doit être en activité. | CA14: POS_C_004 | CB14: =VLOOKUP(CA14,'Axe 2 Règles de gestion'!$D$2:$F$506,3, FALSE) -> La date de début de position doit être antérieure ou égale à la date de fin prévisionnelle de position. | CC14: POS_C_006 | CD14: =VLOOKUP(CC14,'Axe 2 Règles de gestion'!$D$2:$F$506,3, FALSE) -> La date de fin réelle de la position doit être antérieure ou égale à la date de fin réelle ou prévisionnelle du lien juridique. | CE14: POS_C_007 | CF14: =VLOOKUP(CE14,'Axe 2 Règles de gestion'!$D$2:$F$506,3, FALSE) -> La date de fin réelle de la position doit être antérieure à la date limite de départ à la retraite. | CG14: POS_C_009 | CH14: =VLOOKUP(CG14,'Axe 2 Règles de gestion'!$D$2:$F$506,3, FALSE) -> La date de début de la position doit être postérieure ou égale à la date de début du lien juridique. | CI14: POS_C_010 | CJ14: =VLOOKUP(CI14,'Axe 2 Règles de gestion'!$D$2:$F$506,3, FALSE) -> La date de début de position doit être antérieure ou égale à la date de fin réelle de position. | CK14: POS_C_012 | CL14: =VLOOKUP(CK14,'Axe 2 Règles de gestion'!$D$2:$F$506,3, FALSE) -> La date de fin prévisionnelle de la position doit être antérieure à la date limite de départ à la retraite. | CM14: POS_C_022 | CN14: =VLOOKUP(CM14,'Axe 2 Règles de gestion'!$D$2:$F$506,3, FALSE) -> La date de début de position est à J+1 de la date de fin de position de l'occurrence précédente. | CO14: POS_C_050 | CP14: =VLOOKUP(CO14,'Axe 2 Règles de gestion'!$D$2:$F$506,3, FALSE) -> Le lien vers l'enfant doit être renseigné. | CQ14: POS_C_051 | CR14: =VLOOKUP(CQ14,'Axe 2 Règles de gestion'!$D$2:$F$506,3, FALSE) -> La date de naissance de l'enfant doit être renseignée. | CS14: POS_C_055 | CT14: =VLOOKUP(CS14,'Axe 2 Règles de gestion'!$D$2:$F$506,3, FALSE) -> La date de fin réelle de la position doit être antérieure ou égale à la date de décès de l'enfant. | CU14: POS_C_056 | CV14: =VLOOKUP(CU14,'Axe 2 Règles de gestion'!$D$2:$F$506,3, FALSE) -> La date de fin prévisionnelle de la position doit être antérieure ou égale à la date de décès de l'enfant. | CW14: POS_C_057 | CX14: =VLOOKUP(CW14,'Axe 2 Règles de gestion'!$D$2:$F$506,3, FALSE) -> L'agent ne doit pas être en position de détachement entrant sur l'occurrence précédente. | CY14: POS_C_106 | CZ14: =VLOOKUP(CY14,'Axe 2 Règles de gestion'!$D$2:$F$506,3, FALSE) -> La date de fin prévisionnelle de la position doit être antérieure ou égale à la date de fin réelle ou prévisionnelle du lien juridique. | DA14: POS_C_111 | DB14: =VLOOKUP(DA14,'Axe 2 Règles de gestion'!$D$2:$F$506,3, FALSE) -> La date de fin ou la date de fin prévisionnelle doit être saisie.
A15: 25.10.00 | B15: M | C15: 45989.669 | D15: D0004 | E15: Position | F15: S0031 | G15: Congé parental | H15: E0333 | I15: Congé parental après congé de maternité | J15: Position saisie égale à 'Congé parental après congé de maternité' | K15: A_POS_POSIAD [Saisi] = 'CGP01' | L15: T0964 | M15: Congé parental après congé de maternité - Demande | N15: Création Modification | O15: Indicateur de renouvellement saisi = Non ET (Indicateur de renouvellement saisi différent d'Indicateur de renouvellement avant saisi OU Lien vers enfant saisi différent du Lien vers enfant avant saisi) ET Position saisie de l'occurrence précédente est différente d'une position de 'Congé parental' | P15: A_POS_INDREN [Saisi] = '0' ET (A_POS_INDREN [Saisi] <> A_POS_INDREN [Valeur avant saisie] OU A_POS_LVEPAC [Saisi] <> A_POS_LVEPAC [Valeur avant saisie]) ET (A_POS_POSIAD [Occurrence précédente] = POSITION_SITUATION.R_FOR_IDEN05 ET POSITION_SITUATION.R_REL_PSSAG2 <> 'CGP') | Q15: Contractuel | R15: P0003 | S15: N | T15: Général | U15: Exclu | V15: 41183 | W15: 46110
A16: 17.10.00 | B16: A | C16: 43152.5 | D16: D0004 | E16: Position | F16: S0031 | G16: Congé parental | H16: E0333 | I16: Congé parental après congé de maternité | J16: Position saisie égale à 'Congé parental après congé de maternité' | K16: A_POS_POSIAD [Saisi] = 'CGP01' | L16: T0965 | M16: Congé parental après congé de maternité - Renouvellement | N16: Création Modification | O16: Indicateur de renouvellement saisi = Oui ET (Indicateur de renouvellement saisi différent d'Indicateur de renouvellement avant saisi OU Lien vers enfant saisi différent du Lien vers enfant avant saisi) | P16: A_POS_INDREN [Saisi] = '1' ET (A_POS_INDREN [Saisi] <> A_POS_INDREN [Valeur avant saisie] OU A_POS_LVEPAC [Saisi] <> A_POS_LVEPAC [Valeur avant saisie]) | Q16: Contractuel | R16: P0003 | S16: N | T16: Général | U16: Passant | V16: 40725 | W16: 41362 | X16: CPR_D_024 ET CPR_D_744 ET CPR_D_020 ET CPR_D_743 ET CPR_D_018 ET CPR_D_017 ET POS_C_004 ET POS_C_006 ET POS_C_007 ET POS_C_009 ET POS_C_010 ET POS_C_012 ET POS_C_022 ET POS_C_050 ET POS_C_051 ET POS_C_055 ET POS_C_056 ET POS_C_106 ET POS_C_111 | AY16: CPR_D_024 | AZ16: =VLOOKUP(AY16,'Axe 2 Règles de gestion'!$D$2:$F$506,3, FALSE) -> Le congé parental est accordé par périodes de 6 mois maximum renouvelables (date de fin prévisionnelle du congé parental). | BA16: CPR_D_744 | BB16: =VLOOKUP(BA16,'Axe 2 Règles de gestion'!$D$2:$F$506,3, FALSE) -> Le congé parental est accordé par périodes de 6 mois maximum renouvelables (date de fin réelle du congé parental). | BC16: CPR_D_020 | BD16: =VLOOKUP(BC16,'Axe 2 Règles de gestion'!$D$2:$F$506,3, FALSE) -> L'enfant né au foyer doit être âgé de 3 ans au plus (date de fin prévisionnelle du congé parental). | BE16: CPR_D_743 | BF16: =VLOOKUP(BE16,'Axe 2 Règles de gestion'!$D$2:$F$506,3, FALSE) -> L'enfant né au foyer doit être âgé de 3 ans au plus (date de fin réelle du congé parental). | BG16: CPR_D_018 | BH16: =VLOOKUP(BG16,'Axe 2 Règles de gestion'!$D$2:$F$506,3, FALSE) -> L'agent doit justifier d'une ancienneté minimale d'un an à la date de la naissance. | BI16: CPR_D_017 | BJ16: =VLOOKUP(BI16,'Axe 2 Règles de gestion'!$D$2:$F$506,3, FALSE) -> L'agent doit avoir la qualité de mère ou de père. | BY16: POS_C_004 | BZ16: =VLOOKUP(BY16,'Axe 2 Règles de gestion'!$D$2:$F$506,3, FALSE) -> La date de début de position doit être antérieure ou égale à la date de fin prévisionnelle de position. | CA16: POS_C_006 | CB16: =VLOOKUP(CA16,'Axe 2 Règles de gestion'!$D$2:$F$506,3, FALSE) -> La date de fin réelle de la position doit être antérieure ou égale à la date de fin réelle ou prévisionnelle du lien juridique. | CC16: POS_C_007 | CD16: =VLOOKUP(CC16,'Axe 2 Règles de gestion'!$D$2:$F$506,3, FALSE) -> La date de fin réelle de la position doit être antérieure à la date limite de départ à la retraite. | CE16: POS_C_009 | CF16: =VLOOKUP(CE16,'Axe 2 Règles de gestion'!$D$2:$F$506,3, FALSE) -> La date de début de la position doit être postérieure ou égale à la date de début du lien juridique. | CG16: POS_C_010 | CH16: =VLOOKUP(CG16,'Axe 2 Règles de gestion'!$D$2:$F$506,3, FALSE) -> La date de début de position doit être antérieure ou égale à la date de fin réelle de position. | CI16: POS_C_012 | CJ16: =VLOOKUP(CI16,'Axe 2 Règles de gestion'!$D$2:$F$506,3, FALSE) -> La date de fin prévisionnelle de la position doit être antérieure à la date limite de départ à la retraite. | CK16: POS_C_022 | CL16: =VLOOKUP(CK16,'Axe 2 Règles de gestion'!$D$2:$F$506,3, FALSE) -> La date de début de position est à J+1 de la date de fin de position de l'occurrence précédente. | CM16: POS_C_050 | CN16: =VLOOKUP(CM16,'Axe 2 Règles de gestion'!$D$2:$F$506,3, FALSE) -> Le lien vers l'enfant doit être renseigné. | CO16: POS_C_051 | CP16: =VLOOKUP(CO16,'Axe 2 Règles de gestion'!$D$2:$F$506,3, FALSE) -> La date de naissance de l'enfant doit être renseignée. | CQ16: POS_C_055 | CR16: =VLOOKUP(CQ16,'Axe 2 Règles de gestion'!$D$2:$F$506,3, FALSE) -> La date de fin réelle de la position doit être antérieure ou égale à la date de décès de l'enfant. | CS16: POS_C_056 | CT16: =VLOOKUP(CS16,'Axe 2 Règles de gestion'!$D$2:$F$506,3, FALSE) -> La date de fin prévisionnelle de la position doit être antérieure ou égale à la date de décès de l'enfant. | CU16: POS_C_106 | CV16: =VLOOKUP(CU16,'Axe 2 Règles de gestion'!$D$2:$F$506,3, FALSE) -> La date de fin prévisionnelle de la position doit être antérieure ou égale à la date de fin réelle ou prévisionnelle du lien juridique. | CW16: POS_C_111 | CX16: =VLOOKUP(CW16,'Axe 2 Règles de gestion'!$D$2:$F$506,3, FALSE) -> La date de fin ou la date de fin prévisionnelle doit être saisie.
A17: 25.10.00 | B17: M | C17: 45989.675 | D17: D0004 | E17: Position | F17: S0031 | G17: Congé parental | H17: E0333 | I17: Congé parental après congé de maternité | J17: Position saisie égale à 'Congé parental après congé de maternité' | K17: A_POS_POSIAD [Saisi] = 'CGP01' | L17: T0965 | M17: Congé parental après congé de maternité - Renouvellement | N17: Création Modification | O17: Indicateur de renouvellement saisi = Oui ET (Indicateur de renouvellement saisi différent d'Indicateur de renouvellement avant saisi OU Lien vers enfant saisi différent du Lien vers enfant avant saisi) | P17: A_POS_INDREN [Saisi] = '1' ET (A_POS_INDREN [Saisi] <> A_POS_INDREN [Valeur avant saisie] OU A_POS_LVEPAC [Saisi] <> A_POS_LVEPAC [Valeur avant saisie]) | Q17: Contractuel | R17: P0003 | S17: N | T17: Général | U17: Exclu | V17: 41363 | W17: 46110
A18: 17.10.00 | B18: A | C18: 43152.5 | D18: D0004 | E18: Position | F18: S0031 | G18: Congé parental | H18: E0333 | I18: Congé parental après congé de maternité | J18: Position saisie égale à 'Congé parental après congé de maternité' | K18: A_POS_POSIAD [Saisi] = 'CGP01' | L18: T0967 | M18: Congé parental après congé de maternité - Réintégration | N18: Modification | O18: Indicateur de renouvellement saisi identique à Indicateur de renouvellement avant saisi ET Lien vers enfant saisi identique au Lien vers enfant avant saisi | P18: A_POS_INDREN [Saisi] = A_POS_INDREN [Valeur avant saisie] ET A_POS_LVEPAC [Saisi] = A_POS_LVEPAC [Valeur avant saisie]) | Q18: Contractuel | R18: P0003 | S18: N | T18: Général | U18: Passant | V18: 40725 | W18: 41362 | X18: CPR_D_024 ET CPR_D_744 ET CPR_D_020 ET CPR_D_743 ET CPR_D_018 ET POS_C_004 ET POS_C_006 ET POS_C_007 ET POS_C_010 ET POS_C_012 ET POS_C_050 ET POS_C_051 ET POS_C_055 ET POS_C_056 ET POS_C_106 ET POS_C_111 | AY18: CPR_D_024 | AZ18: =VLOOKUP(AY18,'Axe 2 Règles de gestion'!$D$2:$F$506,3, FALSE) -> Le congé parental est accordé par périodes de 6 mois maximum renouvelables (date de fin prévisionnelle du congé parental). | BA18: CPR_D_744 | BB18: =VLOOKUP(BA18,'Axe 2 Règles de gestion'!$D$2:$F$506,3, FALSE) -> Le congé parental est accordé par périodes de 6 mois maximum renouvelables (date de fin réelle du congé parental). | BC18: CPR_D_020 | BD18: =VLOOKUP(BC18,'Axe 2 Règles de gestion'!$D$2:$F$506,3, FALSE) -> L'enfant né au foyer doit être âgé de 3 ans au plus (date de fin prévisionnelle du congé parental). | BE18: CPR_D_743 | BF18: =VLOOKUP(BE18,'Axe 2 Règles de gestion'!$D$2:$F$506,3, FALSE) -> L'enfant né au foyer doit être âgé de 3 ans au plus (date de fin réelle du congé parental). | BG18: CPR_D_018 | BH18: =VLOOKUP(BG18,'Axe 2 Règles de gestion'!$D$2:$F$506,3, FALSE) -> L'agent doit justifier d'une ancienneté minimale d'un an à la date de la naissance. | BY18: POS_C_004 | BZ18: =VLOOKUP(BY18,'Axe 2 Règles de gestion'!$D$2:$F$506,3, FALSE) -> La date de début de position doit être antérieure ou égale à la date de fin prévisionnelle de position. | CA18: POS_C_006 | CB18: =VLOOKUP(CA18,'Axe 2 Règles de gestion'!$D$2:$F$506,3, FALSE) -> La date de fin réelle de la position doit être antérieure ou égale à la date de fin réelle ou prévisionnelle du lien juridique. | CC18: POS_C_007 | CD18: =VLOOKUP(CC18,'Axe 2 Règles de gestion'!$D$2:$F$506,3, FALSE) -> La date de fin réelle de la position doit être antérieure à la date limite de départ à la retraite. | CE18: POS_C_010 | CF18: =VLOOKUP(CE18,'Axe 2 Règles de gestion'!$D$2:$F$506,3, FALSE) -> La date de début de position doit être antérieure ou égale à la date de fin réelle de position. | CG18: POS_C_012 | CH18: =VLOOKUP(CG18,'Axe 2 Règles de gestion'!$D$2:$F$506,3, FALSE) -> La date de fin prévisionnelle de la position doit être antérieure à la date limite de départ à la retraite. | CI18: POS_C_050 | CJ18: =VLOOKUP(CI18,'Axe 2 Règles de gestion'!$D$2:$F$506,3, FALSE) -> Le lien vers l'enfant doit être renseigné. | CK18: POS_C_051 | CL18: =VLOOKUP(CK18,'Axe 2 Règles de gestion'!$D$2:$F$506,3, FALSE) -> La date de naissance de l'enfant doit être renseignée. | CM18: POS_C_055 | CN18: =VLOOKUP(CM18,'Axe 2 Règles de gestion'!$D$2:$F$506,3, FALSE) -> La date de fin réelle de la position doit être antérieure ou égale à la date de décès de l'enfant. | CO18: POS_C_056 | CP18: =VLOOKUP(CO18,'Axe 2 Règles de gestion'!$D$2:$F$506,3, FALSE) -> La date de fin prévisionnelle de la position doit être antérieure ou égale à la date de décès de l'enfant. | CQ18: POS_C_106 | CR18: =VLOOKUP(CQ18,'Axe 2 Règles de gestion'!$D$2:$F$506,3, FALSE) -> La date de fin prévisionnelle de la position doit être antérieure ou égale à la date de fin réelle ou prévisionnelle du lien juridique. | CS18: POS_C_111 | CT18: =VLOOKUP(CS18,'Axe 2 Règles de gestion'!$D$2:$F$506,3, FALSE) -> La date de fin ou la date de fin prévisionnelle doit être saisie.
A19: 25.10.00 | B19: M | C19: 45989.706 | D19: D0004 | E19: Position | F19: S0031 | G19: Congé parental | H19: E0333 | I19: Congé parental après congé de maternité | J19: Position saisie égale à 'Congé parental après congé de maternité' | K19: A_POS_POSIAD [Saisi] = 'CGP01' | L19: T0967 | M19: Congé parental après congé de maternité - Réintégration | N19: Modification | O19: Indicateur de renouvellement saisi identique à Indicateur de renouvellement avant saisi ET Lien vers enfant saisi identique au Lien vers enfant avant saisi | P19: A_POS_INDREN [Saisi] = A_POS_INDREN [Valeur avant saisie] ET A_POS_LVEPAC [Saisi] = A_POS_LVEPAC [Valeur avant saisie]) | Q19: Contractuel | R19: P0003 | S19: N | T19: Général | U19: Exclu | V19: 41363 | W19: 46110
A20: 17.10.00 | B20: A | C20: 43152.5 | D20: D0004 | E20: Position | F20: S0031 | G20: Congé parental | H20: E0333 | I20: Congé parental après congé de maternité | J20: Position saisie égale à 'Congé parental après congé de maternité' | K20: A_POS_POSIAD [Saisi] = 'CGP01' | L20: T1578 | M20: Congé parental après Congé de maternité - Demande pendant un Congé parental | N20: Création Modification | O20: Indicateur de renouvellement saisi = Non ET (Indicateur de renouvellement saisi différent d'Indicateur de renouvellement avant saisi OU Lien vers enfant saisi différent du Lien vers enfant avant saisi) ET Position saisie de l'occurrence précédente est une position de 'Congé parental' | P20: A_POS_INDREN [Saisi] = '0' ET (A_POS_INDREN [Saisi] <> A_POS_INDREN [Valeur avant saisie] OU A_POS_LVEPAC [Saisi] <> A_POS_LVEPAC [Valeur avant saisie]) ET (A_POS_POSIAD [Occurrence précédente] = POSITION_SITUATION.R_FOR_IDEN05 ET POSITION_SITUATION.R_REL_PSSAG2 = 'CGP') | Q20: Contractuel | R20: P0003 | S20: N | T20: Général | U20: Passant | V20: 40725 | W20: 41182 | X20: CPR_D_024 ET CPR_D_744 ET CPR_D_658 ET CPR_D_074 ET CPR_D_747 ET CPR_D_018 ET CPR_D_017 ET CPR_D_043 ET POS_C_004 ET POS_C_006 ET POS_C_007 ET POS_C_009 ET POS_C_010 ET POS_C_012 ET POS_C_022 ET POS_C_050 ET POS_C_051 ET POS_C_055 ET POS_C_056 ET POS_C_106 ET POS_C_111 | AY20: CPR_D_024 | AZ20: =VLOOKUP(AY20,'Axe 2 Règles de gestion'!$D$2:$F$506,3, FALSE) -> Le congé parental est accordé par périodes de 6 mois maximum renouvelables (date de fin prévisionnelle du congé parental). | BA20: CPR_D_744 | BB20: =VLOOKUP(BA20,'Axe 2 Règles de gestion'!$D$2:$F$506,3, FALSE) -> Le congé parental est accordé par périodes de 6 mois maximum renouvelables (date de fin réelle du congé parental). | BC20: CPR_D_658 | BD20: =VLOOKUP(BC20,'Axe 2 Règles de gestion'!$D$2:$F$506,3, FALSE) -> Si une nouvelle naissance ou adoption intervient alors que l'agent est déjà en position de congé parental, celui-ci a droit, du chef de son nouvel enfant, à un nouveau congé parental. | BE20: CPR_D_074 | BF20: =VLOOKUP(BE20,'Axe 2 Règles de gestion'!$D$2:$F$506,3, FALSE) -> L'enfant né au foyer doit être âgé de 3 ans au plus (date de fin prévisionnelle du congé parental). | BG20: CPR_D_747 | BH20: =VLOOKUP(BG20,'Axe 2 Règles de gestion'!$D$2:$F$506,3, FALSE) -> L'enfant né au foyer doit être âgé de 3 ans au plus (date de fin réelle du congé parental). | BI20: CPR_D_018 | BJ20: =VLOOKUP(BI20,'Axe 2 Règles de gestion'!$D$2:$F$506,3, FALSE) -> L'agent doit justifier d'une ancienneté minimale d'un an à la date de la naissance. | BK20: CPR_D_017 | BL20: =VLOOKUP(BK20,'Axe 2 Règles de gestion'!$D$2:$F$506,3, FALSE) -> L'agent doit avoir la qualité de mère ou de père. | BM20: CPR_D_043 | BN20: =VLOOKUP(BM20,'Axe 2 Règles de gestion'!$D$2:$F$506,3, FALSE) -> Le congé parental est accordé de droit à la mère après un congé maternité. | BY20: POS_C_004 | BZ20: =VLOOKUP(BY20,'Axe 2 Règles de gestion'!$D$2:$F$506,3, FALSE) -> La date de début de position doit être antérieure ou égale à la date de fin prévisionnelle de position. | CA20: POS_C_006 | CB20: =VLOOKUP(CA20,'Axe 2 Règles de gestion'!$D$2:$F$506,3, FALSE) -> La date de fin réelle de la position doit être antérieure ou égale à la date de fin réelle ou prévisionnelle du lien juridique. | CC20: POS_C_007 | CD20: =VLOOKUP(CC20,'Axe 2 Règles de gestion'!$D$2:$F$506,3, FALSE) -> La date de fin réelle de la position doit être antérieure à la date limite de départ à la retraite. | CE20: POS_C_009 | CF20: =VLOOKUP(CE20,'Axe 2 Règles de gestion'!$D$2:$F$506,3, FALSE) -> La date de début de la position doit être postérieure ou égale à la date de début du lien juridique. | CG20: POS_C_010 | CH20: =VLOOKUP(CG20,'Axe 2 Règles de gestion'!$D$2:$F$506,3, FALSE) -> La date de début de position doit être antérieure ou égale à la date de fin réelle de position. | CI20: POS_C_012 | CJ20: =VLOOKUP(CI20,'Axe 2 Règles de gestion'!$D$2:$F$506,3, FALSE) -> La date de fin prévisionnelle de la position doit être antérieure à la date limite de départ à la retraite. | CK20: POS_C_022 | CL20: =VLOOKUP(CK20,'Axe 2 Règles de gestion'!$D$2:$F$506,3, FALSE) -> La date de début de position est à J+1 de la date de fin de position de l'occurrence précédente. | CM20: POS_C_050 | CN20: =VLOOKUP(CM20,'Axe 2 Règles de gestion'!$D$2:$F$506,3, FALSE) -> Le lien vers l'enfant doit être renseigné. | CO20: POS_C_051 | CP20: =VLOOKUP(CO20,'Axe 2 Règles de gestion'!$D$2:$F$506,3, FALSE) -> La date de naissance de l'enfant doit être renseignée. | CQ20: POS_C_055 | CR20: =VLOOKUP(CQ20,'Axe 2 Règles de gestion'!$D$2:$F$506,3, FALSE) -> La date de fin réelle de la position doit être antérieure ou égale à la date de décès de l'enfant. | CS20: POS_C_056 | CT20: =VLOOKUP(CS20,'Axe 2 Règles de gestion'!$D$2:$F$506,3, FALSE) -> La date de fin prévisionnelle de la position doit être antérieure ou égale à la date de décès de l'enfant. | CU20: POS_C_106 | CV20: =VLOOKUP(CU20,'Axe 2 Règles de gestion'!$D$2:$F$506,3, FALSE) -> La date de fin prévisionnelle de la position doit être antérieure ou égale à la date de fin réelle ou prévisionnelle du lien juridique. | CW20: POS_C_111 | CX20: =VLOOKUP(CW20,'Axe 2 Règles de gestion'!$D$2:$F$506,3, FALSE) -> La date de fin ou la date de fin prévisionnelle doit être saisie.
A21: 25.10.00 | B21: M | C21: 45992.61 | D21: D0004 | E21: Position | F21: S0031 | G21: Congé parental | H21: E0333 | I21: Congé parental après congé de maternité | J21: Position saisie égale à 'Congé parental après congé de maternité' | K21: A_POS_POSIAD [Saisi] = 'CGP01' | L21: T1578 | M21: Congé parental après Congé de maternité - Demande pendant un Congé parental | N21: Création Modification | O21: Indicateur de renouvellement saisi = Non ET (Indicateur de renouvellement saisi différent d'Indicateur de renouvellement avant saisi OU Lien vers enfant saisi différent du Lien vers enfant avant saisi) ET Position saisie de l'occurrence précédente est une position de 'Congé parental' | P21: A_POS_INDREN [Saisi] = '0' ET (A_POS_INDREN [Saisi] <> A_POS_INDREN [Valeur avant saisie] OU A_POS_LVEPAC [Saisi] <> A_POS_LVEPAC [Valeur avant saisie]) ET (A_POS_POSIAD [Occurrence précédente] = POSITION_SITUATION.R_FOR_IDEN05 ET POSITION_SITUATION.R_REL_PSSAG2 = 'CGP') | Q21: Contractuel | R21: P0003 | S21: N | T21: Général | U21: Exclu | V21: 41183 | W21: 46110
A22: 17.10.00 | B22: A | C22: 43152.5 | D22: D0004 | E22: Position | F22: S0031 | G22: Congé parental | H22: E0333 | I22: Congé parental après congé de maternité | J22: Position saisie égale à 'Congé parental après congé de maternité' | K22: A_POS_POSIAD [Saisi] = 'CGP01' | L22: T0964 | M22: Congé parental après congé de maternité - Demande | N22: Création Modification | O22: Indicateur de renouvellement saisi = Non ET (Indicateur de renouvellement saisi différent d'Indicateur de renouvellement avant saisi OU Lien vers enfant saisi différent du Lien vers enfant avant saisi) ET Position saisie de l'occurrence précédente est différente d'une position de 'Congé parental' | P22: A_POS_INDREN [Saisi] = '0' ET (A_POS_INDREN [Saisi] <> A_POS_INDREN [Valeur avant saisie] OU A_POS_LVEPAC [Saisi] <> A_POS_LVEPAC [Valeur avant saisie]) ET (A_POS_POSIAD [Occurrence précédente] = POSITION_SITUATION.R_FOR_IDEN05 ET POSITION_SITUATION.R_REL_PSSAG2 <> 'CGP') | Q22: Stagiaire ou auditeur ou élève | R22: P0004 | S22: S | T22: Général | U22: Passant | V22: 40725 | W22: 41182 | X22: CPR_D_014 ET CPR_D_705 ET CPR_D_009 ET CPR_D_010 ET CPR_D_034 ET CPR_D_703 ET POS_C_100 ET POS_C_004 ET POS_C_005 ET POS_C_007 ET POS_C_010 ET POS_C_012 ET POS_C_022 ET POS_C_050 ET POS_C_051 ET POS_C_055 ET POS_C_056 ET POS_C_057 ET POS_C_111 | AY22: CPR_D_014 | AZ22: =VLOOKUP(AY22,'Axe 2 Règles de gestion'!$D$2:$F$506,3, FALSE) -> Le congé parental est accordé par périodes de 6 mois maximum renouvelables (date de fin prévisionnelle du congé parental). | BA22: CPR_D_705 | BB22: =VLOOKUP(BA22,'Axe 2 Règles de gestion'!$D$2:$F$506,3, FALSE) -> Le congé parental est accordé par périodes de 6 mois maximum renouvelables (date de fin réelle du congé parental). | BC22: CPR_D_009 | BD22: =VLOOKUP(BC22,'Axe 2 Règles de gestion'!$D$2:$F$506,3, FALSE) -> L'agent doit avoir la qualité de mère ou de père. | BE22: CPR_D_010 | BF22: =VLOOKUP(BE22,'Axe 2 Règles de gestion'!$D$2:$F$506,3, FALSE) -> L'enfant né au foyer doit être âgé de 3 ans au plus (date de fin prévisionnelle du congé parental). | BG22: CPR_D_034 | BH22: =VLOOKUP(BG22,'Axe 2 Règles de gestion'!$D$2:$F$506,3, FALSE) -> Le congé parental est accordé de droit à la mère après un congé maternité. | BI22: CPR_D_703 | BJ22: =VLOOKUP(BI22,'Axe 2 Règles de gestion'!$D$2:$F$506,3, FALSE) -> L'enfant né au foyer doit être âgé de 3 ans au plus (date de fin réelle du congé parental). | BY22: POS_C_100 | BZ22: =VLOOKUP(BY22,'Axe 2 Règles de gestion'!$D$2:$F$506,3, FALSE) -> Lors de la demande initiale, l'agent doit être en activité. | CA22: POS_C_004 | CB22: =VLOOKUP(CA22,'Axe 2 Règles de gestion'!$D$2:$F$506,3, FALSE) -> La date de début de position doit être antérieure ou égale à la date de fin prévisionnelle de position. | CC22: POS_C_005 | CD22: =VLOOKUP(CC22,'Axe 2 Règles de gestion'!$D$2:$F$506,3, FALSE) -> La date de début de la position doit être postérieure ou égale à la date d'entrée dans la FPE ou dans la carrière militaire. | CE22: POS_C_007 | CF22: =VLOOKUP(CE22,'Axe 2 Règles de gestion'!$D$2:$F$506,3, FALSE) -> La date de fin réelle de la position doit être antérieure à la date limite de départ à la retraite. | CG22: POS_C_010 | CH22: =VLOOKUP(CG22,'Axe 2 Règles de gestion'!$D$2:$F$506,3, FALSE) -> La date de début de position doit être antérieure ou égale à la date de fin réelle de position. | CI22: POS_C_012 | CJ22: =VLOOKUP(CI22,'Axe 2 Règles de gestion'!$D$2:$F$506,3, FALSE) -> La date de fin prévisionnelle de la position doit être antérieure à la date limite de départ à la retraite. | CK22: POS_C_022 | CL22: =VLOOKUP(CK22,'Axe 2 Règles de gestion'!$D$2:$F$506,3, FALSE) -> La date de début de position est à J+1 de la date de fin de position de l'occurrence précédente. | CM22: POS_C_050 | CN22: =VLOOKUP(CM22,'Axe 2 Règles de gestion'!$D$2:$F$506,3, FALSE) -> Le lien vers l'enfant doit être renseigné. | CO22: POS_C_051 | CP22: =VLOOKUP(CO22,'Axe 2 Règles de gestion'!$D$2:$F$506,3, FALSE) -> La date de naissance de l'enfant doit être renseignée. | CQ22: POS_C_055 | CR22: =VLOOKUP(CQ22,'Axe 2 Règles de gestion'!$D$2:$F$506,3, FALSE) -> La date de fin réelle de la position doit être antérieure ou égale à la date de décès de l'enfant. | CS22: POS_C_056 | CT22: =VLOOKUP(CS22,'Axe 2 Règles de gestion'!$D$2:$F$506,3, FALSE) -> La date de fin prévisionnelle de la position doit être antérieure ou égale à la date de décès de l'enfant. | CU22: POS_C_057 | CV22: =VLOOKUP(CU22,'Axe 2 Règles de gestion'!$D$2:$F$506,3, FALSE) -> L'agent ne doit pas être en position de détachement entrant sur l'occurrence précédente. | CW22: POS_C_111 | CX22: =VLOOKUP(CW22,'Axe 2 Règles de gestion'!$D$2:$F$506,3, FALSE) -> La date de fin ou la date de fin prévisionnelle doit être saisie.
A23: 25.10.00 | B23: M | C23: 45989.672 | D23: D0004 | E23: Position | F23: S0031 | G23: Congé parental | H23: E0333 | I23: Congé parental après congé de maternité | J23: Position saisie égale à 'Congé parental après congé de maternité' | K23: A_POS_POSIAD [Saisi] = 'CGP01' | L23: T0964 | M23: Congé parental après congé de maternité - Demande | N23: Création Modification | O23: Indicateur de renouvellement saisi = Non ET (Indicateur de renouvellement saisi différent d'Indicateur de renouvellement avant saisi OU Lien vers enfant saisi différent du Lien vers enfant avant saisi) ET Position saisie de l'occurrence précédente est différente d'une position de 'Congé parental' | P23: A_POS_INDREN [Saisi] = '0' ET (A_POS_INDREN [Saisi] <> A_POS_INDREN [Valeur avant saisie] OU A_POS_LVEPAC [Saisi] <> A_POS_LVEPAC [Valeur avant saisie]) ET (A_POS_POSIAD [Occurrence précédente] = POSITION_SITUATION.R_FOR_IDEN05 ET POSITION_SITUATION.R_REL_PSSAG2 <> 'CGP') | Q23: Stagiaire ou auditeur ou élève | R23: P0004 | S23: S | T23: Général | U23: Exclu | V23: 41183 | W23: 46110
