Workbook

Sheet Mode opératoire
B1: MODE OPERATOIRE
B2: La transaction s'effectue au niveau de la rubrique : Statut de l'agent. Remarque : le sous domaine "S0188 - Report de la nomination en qualité de stagiaire" n'existe que pour les besoins des connaissances de Rebecca. En effet, l'agent n'est pas encore stagiaire.

Sheet Axe 1 Enchainement des RG
A1: Version | B1: Type de mise à jour | C1: Date de mise à jour | D1: Identifiant Domaine | E1: Libellé du Domaine | F1: Identifiant Sous-domaine | G1: Libellé du Sous-domaine | H1: Identifiant Evénement | I1: Libellé de l'évènement | J1: Libellé condition déclenchement Evènement | K1: Condition déclenchement Evènement | L1: Identifiant type d'évènement | M1: Libellé type d'évènement | N1: Type de mise à jour | O1: Libellé condition déclenchement Type Evènement | P1: Condition déclenchement Type Evènement | Q1: Libellé Population | R1: Codification Population | S1: Général / Particulier | T1: Passant / Exclu | U1: Date de début | V1: Date de fin | W1: Règles mobilisées | X1: Identifiant Règle de contrôle intellectuel 1 | Y1: Libellé Règle de contrôle intellectuel 1 | Z1: Identifiant Règle de contrôle intellectuel 2 | AA1: Libellé Règle de contrôle intellectuel 2 | AB1: Identifiant Règle de contrôle intellectuel 3 | AC1: Libellé Règle de contrôle intellectuel 3 | AD1: Identifiant Règle de contrôle intellectuel 4 | AE1: Libellé Règle de contrôle intellectuel 4 | AF1: Identifiant Règle de contrôle intellectuel 5 | AG1: Libellé Règle de contrôle intellectuel 5 | AH1: Identifiant Règle de contrôle intellectuel 6 | AI1: Libellé Règle de contrôle intellectuel 6 | AJ1: Identifiant Règle de condition 1 | AK1: Libellé Règle de condition 1 | AL1: Identifiant Règle de condition 2 | AM1: Libellé Règle de condition 2 | AN1: Identifiant Règle de condition 3 | AO1: Libellé Règle de condition 3 | AP1: Identifiant Règle de contrôle 1 | AQ1: Libellé Règle de contrôle 1 | AR1: Identifiant Règle de contrôle 2 | AS1: Libellé Règle de contrôle 2 | AT1: Identifiant Règle de contrôle 3 | AU1: Libellé Règle de contrôle 3 | AV1: Identifiant Règle de contrôle 4 | AW1: Libellé Règle de contrôle 4 | AX1: FIME | AY1: Statut de travail
A2: 25.10.00 | B2: A | C2: 45982.411 | D2: D0005 | E2: Carrière | F2: S0187 | G2: Stage préalable à la titularisation ou à la confirmation | H2: E1030 | I2: Prolongation stage suite à résultats insuffisants | J2: Prolongation suite à résultats insuffisants | K2: A_CAR_MOREST [Saisi] = 'TS01' | L2: T2478 | M2: Prolongation stage suite à résultats insuffisants | N2: Création Modification | Q2: Titulaire ou magistrat | R2: P0001 | S2: Général | T2: Exclu | U2: 45931 | AX2: 2025-69
A3: 25.10.00 | B3: A | C3: 45982.411 | D3: D0005 | E3: Carrière | F3: S0187 | G3: Stage préalable à la titularisation ou à la confirmation | H3: E1030 | I3: Prolongation stage suite à résultats insuffisants | J3: Prolongation suite à résultats insuffisants | K3: A_CAR_MOREST [Saisi] = 'TS01' | L3: T2478 | M3: Prolongation stage suite à résultats insuffisants | N3: Création Modification | Q3: Militaire | R3: P0002 | S3: Général | T3: Exclu | U3: 45931 | AX3: 2025-69
A4: 25.10.00 | B4: A | C4: 45982.411 | D4: D0005 | E4: Carrière | F4: S0187 | G4: Stage préalable à la titularisation ou à la confirmation | H4: E1030 | I4: Prolongation stage suite à résultats insuffisants | J4: Prolongation suite à résultats insuffisants | K4: A_CAR_MOREST [Saisi] = 'TS01' | L4: T2478 | M4: Prolongation stage suite à résultats insuffisants | N4: Création Modification | Q4: Contractuel | R4: P0003 | S4: Général | T4: Exclu | U4: 45931 | AX4: 2025-69
A5: 25.10.00 | B5: A | C5: 45982.601 | D5: D0005 | E5: Carrière | F5: S0187 | G5: Stage préalable à la titularisation ou à la confirmation | H5: E1030 | I5: Prolongation stage suite à résultats insuffisants | J5: Prolongation suite à résultats insuffisants | K5: A_CAR_MOREST [Saisi] = 'TS01' | L5: T2478 | M5: Prolongation stage suite à résultats insuffisants | N5: Création Modification | Q5: Stagiaire ou auditeur ou élève | R5: P0004 | S5: Général | T5: Passant | U5: 45931 | W5: STA_I_088 ET STA_I_074 ET STA_I_037 ET STA_I_092 ET CAR_C_054 ET CAR_C_055 | X5: STA_I_088 | Y5: =VLOOKUP(X5,'Axe 2 Règles de gestion'!$D$2:$F$97,3, FALSE) -> La durée normale de stage peut être prolongée si les aptitudes professionnelles du stagiaire ne sont pas jugées suffisantes pour permettre sa titularisation à l'expiration de la durée normale du stage. | Z5: STA_I_074 | AA5: =VLOOKUP(Z5,'Axe 2 Règles de gestion'!$D$2:$F$97,3, FALSE) -> A l'issue de la formation dispensée dans un établissement de formation, si l'administration ne peut apprécier l'aptitude suite aux absences aux épreuves ou évaluations, l'agent est autorisé à suivre ultérieurement tout ou partie de la formation. | AB5: STA_I_037 | AC5: =VLOOKUP(AB5,'Axe 2 Règles de gestion'!$D$2:$F$97,3, FALSE) -> En cas d'interruption du stage pendant moins de 3 ans, l'agent doit avoir accompli la période complémentaire de stage qui est nécessaire pour atteindre la durée normale du stage pour être titularisé. | AD5: STA_I_092 | AE5: =VLOOKUP(AD5,'Axe 2 Règles de gestion'!$D$2:$F$97,3, FALSE) -> Pour les agents dont le stage se déroule dans un établissement de formation, l'autorité peut mettre fin au stage si les absences de l'agent dépassent une durée fixée réglementairement. | AP5: CAR_C_054 | AQ5: =VLOOKUP(AP5,'Axe 2 Règles de gestion'!$D$2:$F$97,3, FALSE) -> La date de fin réelle du stage doit être antérieure à la date limite de départ à la retraite. | AR5: CAR_C_055 | AS5: =VLOOKUP(AR5,'Axe 2 Règles de gestion'!$D$2:$F$97,3, FALSE) -> La date de fin prévisionnelle de stage doit être antérieure à la date limite de départ à la retraite. | AX5: 2025-69
A6: 25.10.00 | B6: A | C6: 45982.411 | D6: D0005 | E6: Carrière | F6: S0187 | G6: Stage préalable à la titularisation ou à la confirmation | H6: E1030 | I6: Prolongation stage suite à résultats insuffisants | J6: Prolongation suite à résultats insuffisants | K6: A_CAR_MOREST [Saisi] = 'TS01' | L6: T2478 | M6: Prolongation stage suite à résultats insuffisants | N6: Création Modification | Q6: Ouvrier d'état | R6: P0005 | S6: Général | T6: Exclu | U6: 45931 | AX6: 2025-69
A7: 25.10.00 | B7: A | C7: 45982.642 | D7: D0005 | E7: Carrière | F7: S0187 | G7: Stage préalable à la titularisation ou à la confirmation | H7: E1030 | I7: Prolongation stage suite à résultats insuffisants | J7: Prolongation suite à résultats insuffisants | K7: A_CAR_MOREST [Saisi] = 'TS01' | L7: T2478 | M7: Prolongation stage suite à résultats insuffisants | N7: Création Modification | Q7: Ouvrier de la défense auxiliaire non affilié ou temporaire non mensualisé | R7: P0182 | S7: Particulier | T7: Passant | U7: 45931 | W7: STA_D_102 ET STA_D_103 ET CAR_C_054 ET CAR_C_055 | AJ7: STA_D_102 | AK7: =VLOOKUP(AJ7,'Axe 2 Règles de gestion'!$D$2:$F$97,3, FALSE) -> La durée totale du stage (prolongation incluse) ne peut excéder 2 ans entre la date de début et la date de fin prévisionnelle. | AL7: STA_D_103 | AM7: =VLOOKUP(AL7,'Axe 2 Règles de gestion'!$D$2:$F$97,3, FALSE) -> La durée totale du stage (prolongation incluse) ne peut excéder 2 ans entre la date de début et la date de fin réelle. | AP7: CAR_C_054 | AQ7: =VLOOKUP(AP7,'Axe 2 Règles de gestion'!$D$2:$F$97,3, FALSE) -> La date de fin réelle du stage doit être antérieure à la date limite de départ à la retraite. | AR7: CAR_C_055 | AS7: =VLOOKUP(AR7,'Axe 2 Règles de gestion'!$D$2:$F$97,3, FALSE) -> La date de fin prévisionnelle de stage doit être antérieure à la date limite de départ à la retraite. | AX7: 2025-69
A8: 25.10.00 | B8: A | C8: 45982.653 | D8: D0005 | E8: Carrière | F8: S0187 | G8: Stage préalable à la titularisation ou à la confirmation | H8: E1030 | I8: Prolongation stage suite à résultats insuffisants | J8: Prolongation suite à résultats insuffisants | K8: A_CAR_MOREST [Saisi] = 'TS01' | L8: T2478 | M8: Prolongation stage suite à résultats insuffisants | N8: Création Modification | Q8: Ouvrier des parcs et ateliers stagiaire | R8: P0226 | S8: Particulier | T8: Passant | U8: 45931 | W8: STA_D_111 ET STA_D_115 ET CAR_C_054 ET CAR_C_055 | AJ8: STA_D_111 | AK8: =VLOOKUP(AJ8,'Axe 2 Règles de gestion'!$D$2:$F$97,3, FALSE) -> La durée totale du stage (prolongation incluse) ne peut excéder 2 ans entre la date de début et la date de fin prévisionnelle. | AL8: STA_D_115 | AM8: =VLOOKUP(AL8,'Axe 2 Règles de gestion'!$D$2:$F$97,3, FALSE) -> La durée totale du stage (prolongation incluse) ne peut excéder 2 ans entre la date de début et la date de fin réelle. | AP8: CAR_C_054 | AQ8: =VLOOKUP(AP8,'Axe 2 Règles de gestion'!$D$2:$F$97,3, FALSE) -> La date de fin réelle du stage doit être antérieure à la date limite de départ à la retraite. | AR8: CAR_C_055 | AS8: =VLOOKUP(AR8,'Axe 2 Règles de gestion'!$D$2:$F$97,3, FALSE) -> La date de fin prévisionnelle de stage doit être antérieure à la date limite de départ à la retraite. | AX8: 2025-69
A9: 25.10.00 | B9: A | C9: 45982.66 | D9: D0005 | E9: Carrière | F9: S0187 | G9: Stage préalable à la titularisation ou à la confirmation | H9: E1030 | I9: Prolongation stage suite à résultats insuffisants | J9: Prolongation suite à résultats insuffisants | K9: A_CAR_MOREST [Saisi] = 'TS01' | L9: T2478 | M9: Prolongation stage suite à résultats insuffisants | N9: Création Modification | Q9: Ouvrier de l'Institut Géographique National stagiaire | R9: P0294 | S9: Particulier | T9: Passant | U9: 45931 | W9: STA_D_116 ET STA_D_117 ET CAR_C_054 ET CAR_C_055 | AJ9: STA_D_116 | AK9: =VLOOKUP(AJ9,'Axe 2 Règles de gestion'!$D$2:$F$97,3, FALSE) -> La durée totale du stage (prolongation incluse) ne peut excéder 2 ans entre la date de début et la date de fin prévisionnelle. | AL9: STA_D_117 | AM9: =VLOOKUP(AL9,'Axe 2 Règles de gestion'!$D$2:$F$97,3, FALSE) -> La durée totale du stage (prolongation incluse) ne peut excéder 2 ans entre la date de début et la date de fin réelle. | AP9: CAR_C_054 | AQ9: =VLOOKUP(AP9,'Axe 2 Règles de gestion'!$D$2:$F$97,3, FALSE) -> La date de fin réelle du stage doit être antérieure à la date limite de départ à la retraite. | AR9: CAR_C_055 | AS9: =VLOOKUP(AR9,'Axe 2 Règles de gestion'!$D$2:$F$97,3, FALSE) -> La date de fin prévisionnelle de stage doit être antérieure à la date limite de départ à la retraite. | AX9: 2025-69
A10: 25.10.00 | B10: A | C10: 45982.412 | D10: D0005 | E10: Carrière | F10: S0187 | G10: Stage préalable à la titularisation ou à la confirmation | H10: E1031 | I10: Prolongation stage suite à temps partiel | J10: Le type de situation de stage est égal à 'Prolongation suite à temps partiel' | K10: A_CAR_MOREST [Saisi] = 'TS02' | L10: T2479 | M10: Prolongation stage suite à temps partiel | N10: Création Modification | Q10: Titulaire ou magistrat | R10: P0001 | S10: Général | T10: Exclu | U10: 45931 | AX10: 2025-69
A11: 25.10.00 | B11: A | C11: 45982.413 | D11: D0005 | E11: Carrière | F11: S0187 | G11: Stage préalable à la titularisation ou à la confirmation | H11: E1031 | I11: Prolongation stage suite à temps partiel | J11: Le type de situation de stage est égal à 'Prolongation suite à temps partiel' | K11: A_CAR_MOREST [Saisi] = 'TS02' | L11: T2479 | M11: Prolongation stage suite à temps partiel | N11: Création Modification | Q11: Militaire | R11: P0002 | S11: Général | T11: Exclu | U11: 45931 | AX11: 2025-69
A12: 25.10.00 | B12: A | C12: 45982.413 | D12: D0005 | E12: Carrière | F12: S0187 | G12: Stage préalable à la titularisation ou à la confirmation | H12: E1031 | I12: Prolongation stage suite à temps partiel | J12: Le type de situation de stage est égal à 'Prolongation suite à temps partiel' | K12: A_CAR_MOREST [Saisi] = 'TS02' | L12: T2479 | M12: Prolongation stage suite à temps partiel | N12: Création Modification | Q12: Contractuel | R12: P0003 | S12: Général | T12: Exclu | U12: 45931 | AX12: 2025-69
A13: 25.10.00 | B13: A | C13: 45982.602 | D13: D0005 | E13: Carrière | F13: S0187 | G13: Stage préalable à la titularisation ou à la confirmation | H13: E1031 | I13: Prolongation stage suite à temps partiel | J13: Le type de situation de stage est égal à 'Prolongation suite à temps partiel' | K13: A_CAR_MOREST [Saisi] = 'TS02' | L13: T2479 | M13: Prolongation stage suite à temps partiel | N13: Création Modification | Q13: Stagiaire ou auditeur ou élève | R13: P0004 | S13: Général | T13: Passant | U13: 45931 | W13: STA_I_046 ET STA_D_001 ET CAR_C_054 ET CAR_C_055 ET CAR_C_101 ET CAR_C_102 | X13: STA_I_046 | Y13: =VLOOKUP(X13,'Axe 2 Règles de gestion'!$D$2:$F$97,3, FALSE) -> La durée du stage est augmentée en proportion pour être équivalente à celle d'un agent travaillant à temps plein. | AJ13: STA_D_001 | AK13: =VLOOKUP(AJ13,'Axe 2 Règles de gestion'!$D$2:$F$97,3, FALSE) -> L'agent a été en temps partiel de droit ou sur autorisation pendant sa période de stage | AP13: CAR_C_054 | AQ13: =VLOOKUP(AP13,'Axe 2 Règles de gestion'!$D$2:$F$97,3, FALSE) -> La date de fin réelle du stage doit être antérieure à la date limite de départ à la retraite. | AR13: CAR_C_055 | AS13: =VLOOKUP(AR13,'Axe 2 Règles de gestion'!$D$2:$F$97,3, FALSE) -> La date de fin prévisionnelle de stage doit être antérieure à la date limite de départ à la retraite. | AT13: CAR_C_101 | AU13: =VLOOKUP(AT13,'Axe 2 Règles de gestion'!$D$2:$F$97,3, FALSE) -> La date de fin prévisionnelle du stage doit être postérieure à la date de fin réelle de la modalité de service liée à la prolongation | AV13: CAR_C_102 | AW13: =VLOOKUP(AV13,'Axe 2 Règles de gestion'!$D$2:$F$97,3, FALSE) -> La date de fin réelle du stage doit être postérieure à la date de fin réelle de la modalité de service liée à la prolongation | AX13: 2025-69
A14: 25.10.00 | B14: A | C14: 45982.413 | D14: D0005 | E14: Carrière | F14: S0187 | G14: Stage préalable à la titularisation ou à la confirmation | H14: E1031 | I14: Prolongation stage suite à temps partiel | J14: Le type de situation de stage est égal à 'Prolongation suite à temps partiel' | K14: A_CAR_MOREST [Saisi] = 'TS02' | L14: T2479 | M14: Prolongation stage suite à temps partiel | N14: Création Modification | Q14: Ouvrier d'état | R14: P0005 | S14: Général | T14: Exclu | U14: 45931 | AX14: 2025-69
A15: 25.10.00 | B15: M | C15: 46020.573 | D15: D0005 | E15: Carrière | F15: S0187 | G15: Stage préalable à la titularisation ou à la confirmation | H15: E1031 | I15: Prolongation stage suite à temps partiel | J15: Le type de situation de stage est égal à 'Prolongation suite à temps partiel' | K15: A_CAR_MOREST [Saisi] = 'TS02' | L15: T2479 | M15: Prolongation stage suite à temps partiel | N15: Création Modification | Q15: Ouvrier de l'Etat stagiaire | R15: P0293 | S15: Particulier | T15: Passant | U15: 45931 | W15: STA_I_101 ET STA_D_045 ET CAR_C_054 ET CAR_C_055 ET CAR_C_101 ET CAR_C_102 | X15: STA_I_101 | Y15: =VLOOKUP(X15,'Axe 2 Règles de gestion'!$D$2:$F$97,3, FALSE) -> La durée du stage pour un agent bénéficiant d'un temps partiel est augmentée en proportion pour être équivalente à celle d'un agent travaillant à temps plein. | AJ15: STA_D_045 | AK15: =VLOOKUP(AJ15,'Axe 2 Règles de gestion'!$D$2:$F$97,3, FALSE) -> L'agent a été en temps partiel de droit ou sur autorisation pendant sa période de stage. | AP15: CAR_C_054 | AQ15: =VLOOKUP(AP15,'Axe 2 Règles de gestion'!$D$2:$F$97,3, FALSE) -> La date de fin réelle du stage doit être antérieure à la date limite de départ à la retraite. | AR15: CAR_C_055 | AS15: =VLOOKUP(AR15,'Axe 2 Règles de gestion'!$D$2:$F$97,3, FALSE) -> La date de fin prévisionnelle de stage doit être antérieure à la date limite de départ à la retraite. | AT15: CAR_C_101 | AU15: =VLOOKUP(AT15,'Axe 2 Règles de gestion'!$D$2:$F$97,3, FALSE) -> La date de fin prévisionnelle du stage doit être postérieure à la date de fin réelle de la modalité de service liée à la prolongation | AV15: CAR_C_102 | AW15: =VLOOKUP(AV15,'Axe 2 Règles de gestion'!$D$2:$F$97,3, FALSE) -> La date de fin réelle du stage doit être postérieure à la date de fin réelle de la modalité de service liée à la prolongation | AX15: 2025-69
A16: 25.10.00 | B16: A | C16: 45982.446 | D16: D0005 | E16: Carrière | F16: S0187 | G16: Stage préalable à la titularisation ou à la confirmation | H16: E1032 | I16: Prolongation stage suite à congé de maternité, paternité, adoption | J16: Le type de situation de stage est égal à 'Prolongation suite à congé de maternité, paternité, adoption' | K16: A_CAR_MOREST [Saisi] = 'TS04' | L16: T2480 | M16: Prolongation stage suite à congé de maternité, paternité, adoption | N16: Création Modification | Q16: Titulaire ou magistrat | R16: P0001 | S16: Général | T16: Exclu | U16: 45931 | AX16: 2025-69
A17: 25.10.00 | B17: A | C17: 45982.447 | D17: D0005 | E17: Carrière | F17: S0187 | G17: Stage préalable à la titularisation ou à la confirmation | H17: E1032 | I17: Prolongation stage suite à congé de maternité, paternité, adoption | J17: Le type de situation de stage est égal à 'Prolongation suite à congé de maternité, paternité, adoption' | K17: A_CAR_MOREST [Saisi] = 'TS04' | L17: T2480 | M17: Prolongation stage suite à congé de maternité, paternité, adoption | N17: Création Modification | Q17: Militaire | R17: P0002 | S17: Général | T17: Exclu | U17: 45931 | AX17: 2025-69
A18: 25.10.00 | B18: A | C18: 45982.446 | D18: D0005 | E18: Carrière | F18: S0187 | G18: Stage préalable à la titularisation ou à la confirmation | H18: E1032 | I18: Prolongation stage suite à congé de maternité, paternité, adoption | J18: Le type de situation de stage est égal à 'Prolongation suite à congé de maternité, paternité, adoption' | K18: A_CAR_MOREST [Saisi] = 'TS04' | L18: T2480 | M18: Prolongation stage suite à congé de maternité, paternité, adoption | N18: Création Modification | Q18: Contractuel | R18: P0003 | S18: Général | T18: Exclu | U18: 45931 | AX18: 2025-69
A19: 25.10.00 | B19: M | C19: 46020.452 | D19: D0005 | E19: Carrière | F19: S0187 | G19: Stage préalable à la titularisation ou à la confirmation | H19: E1032 | I19: Prolongation stage suite à congé de maternité, paternité, adoption | J19: Le type de situation de stage est égal à 'Prolongation suite à congé de maternité, paternité, adoption' | K19: A_CAR_MOREST [Saisi] = 'TS04' | L19: T2480 | M19: Prolongation stage suite à congé de maternité, paternité, adoption | N19: Création Modification | Q19: Stagiaire ou auditeur ou élève | R19: P0004 | S19: Général | T19: Passant | U19: 45931 | W19: STA_I_048 ET STA_I_037 ET STA_I_092 ET STA_D_003 ET CAR_C_054 ET CAR_C_055 ET CAR_C_097 ET CAR_C_098 | X19: STA_I_048 | Y19: =VLOOKUP(X19,'Axe 2 Règles de gestion'!$D$2:$F$97,3, FALSE) -> La période de prolongation est égale à la durée totale de ces congés qui excède 1/10ème de la durée statutaire du stage. | Z19: STA_I_037 | AA19: =VLOOKUP(Z19,'Axe 2 Règles de gestion'!$D$2:$F$97,3, FALSE) -> En cas d'interruption du stage pendant moins de 3 ans, l'agent doit avoir accompli la période complémentaire de stage qui est nécessaire pour atteindre la durée normale du stage pour être titularisé. | AB19: STA_I_092 | AC19: =VLOOKUP(AB19,'Axe 2 Règles de gestion'!$D$2:$F$97,3, FALSE) -> Pour les agents dont le stage se déroule dans un établissement de formation, l'autorité peut mettre fin au stage si les absences de l'agent dépassent une durée fixée réglementairement. | AJ19: STA_D_003 | AK19: =VLOOKUP(AJ19,'Axe 2 Règles de gestion'!$D$2:$F$97,3, FALSE) -> L'agent a été en congés annuels, maternité, paternité ou adoption pendant sa période de stage. | AP19: CAR_C_054 | AQ19: =VLOOKUP(AP19,'Axe 2 Règles de gestion'!$D$2:$F$97,3, FALSE) -> La date de fin réelle du stage doit être antérieure à la date limite de départ à la retraite. | AR19: CAR_C_055 | AS19: =VLOOKUP(AR19,'Axe 2 Règles de gestion'!$D$2:$F$97,3, FALSE) -> La date de fin prévisionnelle de stage doit être antérieure à la date limite de départ à la retraite. | AT19: CAR_C_097 | AU19: =VLOOKUP(AT19,'Axe 2 Règles de gestion'!$D$2:$F$97,3, FALSE) -> La date de fin réelle du stage doit être postérieure à la date de fin réelle du congé liée à la prolongation | AV19: CAR_C_098 | AW19: =VLOOKUP(AV19,'Axe 2 Règles de gestion'!$D$2:$F$97,3, FALSE) -> La date de fin prévisionnelle du stage doit être postérieure à la date de fin réelle du congé liée à la prolongation | AX19: 2025-69
A20: 25.10.00 | B20: A | C20: 45982.447 | D20: D0005 | E20: Carrière | F20: S0187 | G20: Stage préalable à la titularisation ou à la confirmation | H20: E1032 | I20: Prolongation stage suite à congé de maternité, paternité, adoption | J20: Le type de situation de stage est égal à 'Prolongation suite à congé de maternité, paternité, adoption' | K20: A_CAR_MOREST [Saisi] = 'TS04' | L20: T2480 | M20: Prolongation stage suite à congé de maternité, paternité, adoption | N20: Création Modification | Q20: Ouvrier d'état | R20: P0005 | S20: Général | T20: Exclu | U20: 45931 | AX20: 2025-69
A21: 25.10.00 | B21: A | C21: 45982.644 | D21: D0005 | E21: Carrière | F21: S0187 | G21: Stage préalable à la titularisation ou à la confirmation | H21: E1032 | I21: Prolongation stage suite à congé de maternité, paternité, adoption | J21: Le type de situation de stage est égal à 'Prolongation suite à congé de maternité, paternité, adoption' | K21: A_CAR_MOREST [Saisi] = 'TS04' | L21: T2480 | M21: Prolongation stage suite à congé de maternité, paternité, adoption | N21: Création Modification | Q21: Ouvrier de la défense auxiliaire non affilié ou temporaire non mensualisé | R21: P0182 | S21: Particulier | T21: Passant | U21: 45931 | W21: STA_D_102 ET STA_D_103 ET CAR_C_054 ET CAR_C_055 ET CAR_C_097 ET CAR_C_098 | AJ21: STA_D_102 | AK21: =VLOOKUP(AJ21,'Axe 2 Règles de gestion'!$D$2:$F$97,3, FALSE) -> La durée totale du stage (prolongation incluse) ne peut excéder 2 ans entre la date de début et la date de fin prévisionnelle. | AL21: STA_D_103 | AM21: =VLOOKUP(AL21,'Axe 2 Règles de gestion'!$D$2:$F$97,3, FALSE) -> La durée totale du stage (prolongation incluse) ne peut excéder 2 ans entre la date de début et la date de fin réelle. | AP21: CAR_C_054 | AQ21: =VLOOKUP(AP21,'Axe 2 Règles de gestion'!$D$2:$F$97,3, FALSE) -> La date de fin réelle du stage doit être antérieure à la date limite de départ à la retraite. | AR21: CAR_C_055 | AS21: =VLOOKUP(AR21,'Axe 2 Règles de gestion'!$D$2:$F$97,3, FALSE) -> La date de fin prévisionnelle de stage doit être antérieure à la date limite de départ à la retraite. | AT21: CAR_C_097 | AU21: =VLOOKUP(AT21,'Axe 2 Règles de gestion'!$D$2:$F$97,3, FALSE) -> La date de fin réelle du stage doit être postérieure à la date de fin réelle du congé liée à la prolongation | AV21: CAR_C_098 | AW21: =VLOOKUP(AV21,'Axe 2 Règles de gestion'!$D$2:$F$97,3, FALSE) -> La date de fin prévisionnelle du stage doit être postérieure à la date de fin réelle du congé liée à la prolongation | AX21: 2025-69
A22: 25.10.00 | B22: M | C22: 46020.454 | D22: D0005 | E22: Carrière | F22: S0187 | G22: Stage préalable à la titularisation ou à la confirmation | H22: E1032 | I22: Prolongation stage suite à congé de maternité, paternité, adoption | J22: Le type de situation de stage est égal à 'Prolongation suite à congé de maternité, paternité, adoption' | K22: A_CAR_MOREST [Saisi] = 'TS04' | L22: T2480 | M22: Prolongation stage suite à congé de maternité, paternité, adoption | N22: Création Modification | Q22: Ouvrier de l'Etat stagiaire | R22: P0293 | S22: Particulier | T22: Passant | U22: 45931 | W22: STA_D_114 ET CAR_C_054 ET CAR_C_055 ET CAR_C_097 ET CAR_C_098 | AJ22: STA_D_114 | AK22: =VLOOKUP(AJ22,'Axe 2 Règles de gestion'!$D$2:$F$97,3, FALSE) -> L'agent a été en congés maternité, paternité ou adoption pendant sa période de stage. | AP22: CAR_C_054 | AQ22: =VLOOKUP(AP22,'Axe 2 Règles de gestion'!$D$2:$F$97,3, FALSE) -> La date de fin réelle du stage doit être antérieure à la date limite de départ à la retraite. | AR22: CAR_C_055 | AS22: =VLOOKUP(AR22,'Axe 2 Règles de gestion'!$D$2:$F$97,3, FALSE) -> La date de fin prévisionnelle de stage doit être antérieure à la date limite de départ à la retraite. | AT22: CAR_C_097 | AU22: =VLOOKUP(AT22,'Axe 2 Règles de gestion'!$D$2:$F$97,3, FALSE) -> La date de fin réelle du stage doit être postérieure à la date de fin réelle du congé liée à la prolongation | AV22: CAR_C_098 | AW22: =VLOOKUP(AV22,'Axe 2 Règles de gestion'!$D$2:$F$97,3, FALSE) -> La date de fin prévisionnelle du stage doit être postérieure à la date de fin réelle du congé liée à la prolongation | AX22: 2025-69
A23: 25.10.00 | B23: A | C23: 45982.448 | D23: D0005 | E23: Carrière | F23: S0187 | G23: Stage préalable à la titularisation ou à la confirmation | H23: E1033 | I23: Prolongation stage suite à congés rémunérés de toute nature hors congés annuel, maternité, paternité, adoption | J23: Le type de situation de stage est égal à 'Prolongation suite à congés rémunérés de toute nature hors congés annuel, maternité, paternité, adoption' | K23: A_CAR_MOREST [Saisi] = 'TS05' | L23: T2481 | M23: Prolongation stage suite à congés rémunérés de toute nature hors congés annuel, maternité, paternité, adoption | N23: Création Modification | Q23: Titulaire ou magistrat | R23: P0001 | S23: Général | T23: Exclu | U23: 45931 | AX23: 2025-69
A24: 25.10.00 | B24: A | C24: 45982.449 | D24: D0005 | E24: Carrière | F24: S0187 | G24: Stage préalable à la titularisation ou à la confirmation | H24: E1033 | I24: Prolongation stage suite à congés rémunérés de toute nature hors congés annuel, maternité, paternité, adoption | J24: Le type de situation de stage est égal à 'Prolongation suite à congés rémunérés de toute nature hors congés annuel, maternité, paternité, adoption' | K24: A_CAR_MOREST [Saisi] = 'TS05' | L24: T2481 | M24: Prolongation stage suite à congés rémunérés de toute nature hors congés annuel, maternité, paternité, adoption | N24: Création Modification | Q24: Militaire | R24: P0002 | S24: Général | T24: Exclu | U24: 45931 | AX24: 2025-69
A25: 25.10.00 | B25: A | C25: 45982.448 | D25: D0005 | E25: Carrière | F25: S0187 | G25: Stage préalable à la titularisation ou à la confirmation | H25: E1033 | I25: Prolongation stage suite à congés rémunérés de toute nature hors congés annuel, maternité, paternité, adoption | J25: Le type de situation de stage est égal à 'Prolongation suite à congés rémunérés de toute nature hors congés annuel, maternité, paternité, adoption' | K25: A_CAR_MOREST [Saisi] = 'TS05' | L25: T2481 | M25: Prolongation stage suite à congés rémunérés de toute nature hors congés annuel, maternité, paternité, adoption | N25: Création Modification | Q25: Contractuel | R25: P0003 | S25: Général | T25: Exclu | U25: 45931 | AX25: 2025-69
A26: 25.10.00 | B26: M | C26: 45982.624 | D26: D0005 | E26: Carrière | F26: S0187 | G26: Stage préalable à la titularisation ou à la confirmation | H26: E1033 | I26: Prolongation stage suite à congés rémunérés de toute nature hors congés annuel, maternité, paternité, adoption | J26: Le type de situation de stage est égal à 'Prolongation suite à congés rémunérés de toute nature hors congés annuel, maternité, paternité, adoption' | K26: A_CAR_MOREST [Saisi] = 'TS05' | L26: T2481 | M26: Prolongation stage suite à congés rémunérés de toute nature hors congés annuel, maternité, paternité, adoption | N26: Création Modification | Q26: Stagiaire ou auditeur ou élève | R26: P0004 | S26: Général | T26: Passant | U26: 45931 | W26: STA_I_048 ET STA_I_037 ET STA_I_092 ET STA_D_004 ET CAR_C_054 ET CAR_C_055 ET CAR_C_097 ET CAR_C_098 | X26: STA_I_048 | Y26: =VLOOKUP(X26,'Axe 2 Règles de gestion'!$D$2:$F$97,3, FALSE) -> La période de prolongation est égale à la durée totale de ces congés qui excède 1/10ème de la durée statutaire du stage. | Z26: STA_I_037 | AA26: =VLOOKUP(Z26,'Axe 2 Règles de gestion'!$D$2:$F$97,3, FALSE) -> En cas d'interruption du stage pendant moins de 3 ans, l'agent doit avoir accompli la période complémentaire de stage qui est nécessaire pour atteindre la durée normale du stage pour être titularisé. | AB26: STA_I_092 | AC26: =VLOOKUP(AB26,'Axe 2 Règles de gestion'!$D$2:$F$97,3, FALSE) -> Pour les agents dont le stage se déroule dans un établissement de formation, l'autorité peut mettre fin au stage si les absences de l'agent dépassent une durée fixée réglementairement. | AJ26: STA_D_004 | AK26: =VLOOKUP(AJ26,'Axe 2 Règles de gestion'!$D$2:$F$97,3, FALSE) -> L'agent a été en congés rémunérés hors congés annuels, maternité, paternité ou adoption pendant sa période de stage | AP26: CAR_C_054 | AQ26: =VLOOKUP(AP26,'Axe 2 Règles de gestion'!$D$2:$F$97,3, FALSE) -> La date de fin réelle du stage doit être antérieure à la date limite de départ à la retraite. | AR26: CAR_C_055 | AS26: =VLOOKUP(AR26,'Axe 2 Règles de gestion'!$D$2:$F$97,3, FALSE) -> La date de fin prévisionnelle de stage doit être antérieure à la date limite de départ à la retraite. | AT26: CAR_C_097 | AU26: =VLOOKUP(AT26,'Axe 2 Règles de gestion'!$D$2:$F$97,3, FALSE) -> La date de fin réelle du stage doit être postérieure à la date de fin réelle du congé liée à la prolongation | AV26: CAR_C_098 | AW26: =VLOOKUP(AV26,'Axe 2 Règles de gestion'!$D$2:$F$97,3, FALSE) -> La date de fin prévisionnelle du stage doit être postérieure à la date de fin réelle du congé liée à la prolongation | AX26: 2025-69
A27: 25.10.00 | B27: A | C27: 45982.449 | D27: D0005 | E27: Carrière | F27: S0187 | G27: Stage préalable à la titularisation ou à la confirmation | H27: E1033 | I27: Prolongation stage suite à congés rémunérés de toute nature hors congés annuel, maternité, paternité, adoption | J27: Le type de situation de stage est égal à 'Prolongation suite à congés rémunérés de toute nature hors congés annuel, maternité, paternité, adoption' | K27: A_CAR_MOREST [Saisi] = 'TS05' | L27: T2481 | M27: Prolongation stage suite à congés rémunérés de toute nature hors congés annuel, maternité, paternité, adoption | N27: Création Modification | Q27: Ouvrier d'état | R27: P0005 | S27: Général | T27: Exclu | U27: 45931 | AX27: 2025-69
A28: 25.10.00 | B28: A | C28: 45982.645 | D28: D0005 | E28: Carrière | F28: S0187 | G28: Stage préalable à la titularisation ou à la confirmation | H28: E1033 | I28: Prolongation stage suite à congés rémunérés de toute nature hors congés annuel, maternité, paternité, adoption | J28: Le type de situation de stage est égal à 'Prolongation suite à congés rémunérés de toute nature hors congés annuel, maternité, paternité, adoption' | K28: A_CAR_MOREST [Saisi] = 'TS05' | L28: T2481 | M28: Prolongation stage suite à congés rémunérés de toute nature hors congés annuel, maternité, paternité, adoption | N28: Création Modification | Q28: Ouvrier de la défense auxiliaire non affilié ou temporaire non mensualisé | R28: P0182 | S28: Particulier | T28: Passant | U28: 45931 | W28: STA_D_102 ET STA_D_103 ET CAR_C_054 ET CAR_C_055 ET CAR_C_097 ET CAR_C_098 | AJ28: STA_D_102 | AK28: =VLOOKUP(AJ28,'Axe 2 Règles de gestion'!$D$2:$F$97,3, FALSE) -> La durée totale du stage (prolongation incluse) ne peut excéder 2 ans entre la date de début et la date de fin prévisionnelle. | AL28: STA_D_103 | AM28: =VLOOKUP(AL28,'Axe 2 Règles de gestion'!$D$2:$F$97,3, FALSE) -> La durée totale du stage (prolongation incluse) ne peut excéder 2 ans entre la date de début et la date de fin réelle. | AP28: CAR_C_054 | AQ28: =VLOOKUP(AP28,'Axe 2 Règles de gestion'!$D$2:$F$97,3, FALSE) -> La date de fin réelle du stage doit être antérieure à la date limite de départ à la retraite. | AR28: CAR_C_055 | AS28: =VLOOKUP(AR28,'Axe 2 Règles de gestion'!$D$2:$F$97,3, FALSE) -> La date de fin prévisionnelle de stage doit être antérieure à la date limite de départ à la retraite. | AT28: CAR_C_097 | AU28: =VLOOKUP(AT28,'Axe 2 Règles de gestion'!$D$2:$F$97,3, FALSE) -> La date de fin réelle du stage doit être postérieure à la date de fin réelle du congé liée à la prolongation | AV28: CAR_C_098 | AW28: =VLOOKUP(AV28,'Axe 2 Règles de gestion'!$D$2:$F$97,3, FALSE) -> La date de fin prévisionnelle du stage doit être postérieure à la date de fin réelle du congé liée à la prolongation | AX28: 2025-69
A29: 25.10.00 | B29: M | C29: 46020.578 | D29: D0005 | E29: Carrière | F29: S0187 | G29: Stage préalable à la titularisation ou à la confirmation | H29: E1033 | I29: Prolongation stage suite à congés rémunérés de toute nature hors congés annuel, maternité, paternité, adoption | J29: Le type de situation de stage est égal à 'Prolongation suite à congés rémunérés de toute nature hors congés annuel, maternité, paternité, adoption' | K29: A_CAR_MOREST [Saisi] = 'TS05' | L29: T2481 | M29: Prolongation stage suite à congés rémunérés de toute nature hors congés annuel, maternité, paternité, adoption | N29: Création Modification | Q29: Ouvrier de l'Etat stagiaire | R29: P0293 | S29: Particulier | T29: Passant | U29: 45931 | W29: STA_I_103 ET STA_D_105 ET CAR_C_054 ET CAR_C_055 ET CAR_C_097 ET CAR_C_098 | X29: STA_I_103 | Y29: =VLOOKUP(X29,'Axe 2 Règles de gestion'!$D$2:$F$97,3, FALSE) -> L'agent bénéficie d'une prise en compte de la durée passée dans un congé de maladie, de longue maladie, de longue durée, d'accident du travail, de maladie professionnelle ou d'un congé sans salaire à concurrence du 1/10 de la durée du contrat. | AJ29: STA_D_105 | AK29: =VLOOKUP(AJ29,'Axe 2 Règles de gestion'!$D$2:$F$97,3, FALSE) -> L'agent a été en congés rémunérés hors congés annuels, maternité, paternité ou adoption pendant sa période de stage. | AP29: CAR_C_054 | AQ29: =VLOOKUP(AP29,'Axe 2 Règles de gestion'!$D$2:$F$97,3, FALSE) -> La date de fin réelle du stage doit être antérieure à la date limite de départ à la retraite. | AR29: CAR_C_055 | AS29: =VLOOKUP(AR29,'Axe 2 Règles de gestion'!$D$2:$F$97,3, FALSE) -> La date de fin prévisionnelle de stage doit être antérieure à la date limite de départ à la retraite. | AT29: CAR_C_097 | AU29: =VLOOKUP(AT29,'Axe 2 Règles de gestion'!$D$2:$F$97,3, FALSE) -> La date de fin réelle du stage doit être postérieure à la date de fin réelle du congé liée à la prolongation | AV29: CAR_C_098 | AW29: =VLOOKUP(AV29,'Axe 2 Règles de gestion'!$D$2:$F$97,3, FALSE) -> La date de fin prévisionnelle du stage doit être postérieure à la date de fin réelle du congé liée à la prolongation | AX29: 2025-69
A30: 25.10.00 | B30: A | C30: 45982.465 | D30: D0005 | E30: Carrière | F30: S0187 | G30: Stage préalable à la titularisation ou à la confirmation | H30: E1034 | I30: Prolongation stage suite à période d'instruction militaire obligatoire ou congé sans traitement pour service national | J30: Le type de situation de stage est égal à 'Prolongation suite à période d'instruction militaire obligatoire ou congé sans traitement pour service national' | K30: A_CAR_MOREST [Saisi] = 'TS06' | L30: T2482 | M30: Prolongation stage suite à période d'instruction militaire obligatoire ou congé sans traitement pour service national | N30: Création Modification | Q30: Titulaire ou magistrat | R30: P0001 | S30: Général | T30: Exclu | U30: 45931 | AX30: 2025-69
A31: 25.10.00 | B31: A | C31: 45982.465 | D31: D0005 | E31: Carrière | F31: S0187 | G31: Stage préalable à la titularisation ou à la confirmation | H31: E1034 | I31: Prolongation stage suite à période d'instruction militaire obligatoire ou congé sans traitement pour service national | J31: Le type de situation de stage est égal à 'Prolongation suite à période d'instruction militaire obligatoire ou congé sans traitement pour service national' | K31: A_CAR_MOREST [Saisi] = 'TS06' | L31: T2482 | M31: Prolongation stage suite à période d'instruction militaire obligatoire ou congé sans traitement pour service national | N31: Création Modification | Q31: Militaire | R31: P0002 | S31: Général | T31: Exclu | U31: 45931 | AX31: 2025-69
A32: 25.10.00 | B32: A | C32: 45982.465 | D32: D0005 | E32: Carrière | F32: S0187 | G32: Stage préalable à la titularisation ou à la confirmation | H32: E1034 | I32: Prolongation stage suite à période d'instruction militaire obligatoire ou congé sans traitement pour service national | J32: Le type de situation de stage est égal à 'Prolongation suite à période d'instruction militaire obligatoire ou congé sans traitement pour service national' | K32: A_CAR_MOREST [Saisi] = 'TS06' | L32: T2482 | M32: Prolongation stage suite à période d'instruction militaire obligatoire ou congé sans traitement pour service national | N32: Création Modification | Q32: Contractuel | R32: P0003 | S32: Général | T32: Exclu | U32: 45931 | AX32: 2025-69
A33: 25.10.00 | B33: A | C33: 45982.626 | D33: D0005 | E33: Carrière | F33: S0187 | G33: Stage préalable à la titularisation ou à la confirmation | H33: E1034 | I33: Prolongation stage suite à période d'instruction militaire obligatoire ou congé sans traitement pour service national | J33: Le type de situation de stage est égal à 'Prolongation suite à période d'instruction militaire obligatoire ou congé sans traitement pour service national' | K33: A_CAR_MOREST [Saisi] = 'TS06' | L33: T2482 | M33: Prolongation stage suite à période d'instruction militaire obligatoire ou congé sans traitement pour service national | N33: Création Modification | Q33: Stagiaire ou auditeur ou élève | R33: P0004 | S33: Général | T33: Passant | U33: 45931 | W33: STA_I_048 ET STA_I_037 ET STA_I_092 ET STA_D_104 ET CAR_C_054 ET CAR_C_055 ET CAR_C_099 ET CAR_C_100 | X33: STA_I_048 | Y33: =VLOOKUP(X33,'Axe 2 Règles de gestion'!$D$2:$F$97,3, FALSE) -> La période de prolongation est égale à la durée totale de ces congés qui excède 1/10ème de la durée statutaire du stage. | Z33: STA_I_037 | AA33: =VLOOKUP(Z33,'Axe 2 Règles de gestion'!$D$2:$F$97,3, FALSE) -> En cas d'interruption du stage pendant moins de 3 ans, l'agent doit avoir accompli la période complémentaire de stage qui est nécessaire pour atteindre la durée normale du stage pour être titularisé. | AB33: STA_I_092 | AC33: =VLOOKUP(AB33,'Axe 2 Règles de gestion'!$D$2:$F$97,3, FALSE) -> Pour les agents dont le stage se déroule dans un établissement de formation, l'autorité peut mettre fin au stage si les absences de l'agent dépassent une durée fixée réglementairement. | AJ33: STA_D_104 | AK33: =VLOOKUP(AJ33,'Axe 2 Règles de gestion'!$D$2:$F$97,3, FALSE) -> L'agent a été en période d'instruction militaire obligatoire ou en congé sans traitement pour service national pendant sa période de stage. | AP33: CAR_C_054 | AQ33: =VLOOKUP(AP33,'Axe 2 Règles de gestion'!$D$2:$F$97,3, FALSE) -> La date de fin réelle du stage doit être antérieure à la date limite de départ à la retraite. | AR33: CAR_C_055 | AS33: =VLOOKUP(AR33,'Axe 2 Règles de gestion'!$D$2:$F$97,3, FALSE) -> La date de fin prévisionnelle de stage doit être antérieure à la date limite de départ à la retraite. | AT33: CAR_C_099 | AU33: =VLOOKUP(AT33,'Axe 2 Règles de gestion'!$D$2:$F$97,3, FALSE) -> La date de fin réelle du stage doit être postérieure à la date de fin réelle de la position liée à la prolongation | AV33: CAR_C_100 | AW33: =VLOOKUP(AV33,'Axe 2 Règles de gestion'!$D$2:$F$97,3, FALSE) -> La date de fin prévisionnelle du stage doit être postérieure à la date de fin réelle de la position liée à la prolongation | AX33: 2025-69
A34: 25.10.00 | B34: A | C34: 45982.465 | D34: D0005 | E34: Carrière | F34: S0187 | G34: Stage préalable à la titularisation ou à la confirmation | H34: E1034 | I34: Prolongation stage suite à période d'instruction militaire obligatoire ou congé sans traitement pour service national | J34: Le type de situation de stage est égal à 'Prolongation suite à période d'instruction militaire obligatoire ou congé sans traitement pour service national' | K34: A_CAR_MOREST [Saisi] = 'TS06' | L34: T2482 | M34: Prolongation stage suite à période d'instruction militaire obligatoire ou congé sans traitement pour service national | N34: Création Modification | Q34: Ouvrier d'état | R34: P0005 | S34: Général | T34: Exclu | U34: 45931 | AX34: 2025-69
A35: 25.10.00 | B35: A | C35: 45982.466 | D35: D0005 | E35: Carrière | F35: S0187 | G35: Stage préalable à la titularisation ou à la confirmation | H35: E1035 | I35: Prolongation stage suite à congé de solidarité familiale ou à congé de proche aidant | J35: Le type de situation de stage est égal à 'Prolongation suite à congé de solidarité familiale ou à congé de proche aidant' | K35: A_CAR_MOREST [Saisi] = 'TS07' | L35: T2483 | M35: Prolongation stage suite à congé de solidarité familiale ou à congé de proche aidant | N35: Création Modification | Q35: Titulaire ou magistrat | R35: P0001 | S35: Général | T35: Exclu | U35: 45931 | AX35: 2025-69
A36: 25.10.00 | B36: A | C36: 45982.466 | D36: D0005 | E36: Carrière | F36: S0187 | G36: Stage préalable à la titularisation ou à la confirmation | H36: E1035 | I36: Prolongation stage suite à congé de solidarité familiale ou à congé de proche aidant | J36: Le type de situation de stage est égal à 'Prolongation suite à congé de solidarité familiale ou à congé de proche aidant' | K36: A_CAR_MOREST [Saisi] = 'TS07' | L36: T2483 | M36: Prolongation stage suite à congé de solidarité familiale ou à congé de proche aidant | N36: Création Modification | Q36: Militaire | R36: P0002 | S36: Général | T36: Exclu | U36: 45931 | AX36: 2025-69
A37: 25.10.00 | B37: A | C37: 45982.466 | D37: D0005 | E37: Carrière | F37: S0187 | G37: Stage préalable à la titularisation ou à la confirmation | H37: E1035 | I37: Prolongation stage suite à congé de solidarité familiale ou à congé de proche aidant | J37: Le type de situation de stage est égal à 'Prolongation suite à congé de solidarité familiale ou à congé de proche aidant' | K37: A_CAR_MOREST [Saisi] = 'TS07' | L37: T2483 | M37: Prolongation stage suite à congé de solidarité familiale ou à congé de proche aidant | N37: Création Modification | Q37: Contractuel | R37: P0003 | S37: Général | T37: Exclu | U37: 45931 | AX37: 2025-69
A38: 25.10.00 | B38: A | C38: 45982.628 | D38: D0005 | E38: Carrière | F38: S0187 | G38: Stage préalable à la titularisation ou à la confirmation | H38: E1035 | I38: Prolongation stage suite à congé de solidarité familiale ou à congé de proche aidant | J38: Le type de situation de stage est égal à 'Prolongation suite à congé de solidarité familiale ou à congé de proche aidant' | K38: A_CAR_MOREST [Saisi] = 'TS07' | L38: T2483 | M38: Prolongation stage suite à congé de solidarité familiale ou à congé de proche aidant | N38: Création Modification | Q38: Stagiaire ou auditeur ou élève | R38: P0004 | S38: Général | T38: Passant | U38: 45931 | W38: STA_I_047 ET STA_I_037 ET STA_I_092 ET STA_D_006 ET CAR_C_054 ET CAR_C_055 ET CAR_C_097 ET CAR_C_098 | X38: STA_I_047 | Y38: =VLOOKUP(X38,'Axe 2 Règles de gestion'!$D$2:$F$97,3, FALSE) -> La date de fin de stage est reportée pour le temps passé dans ces congés. | Z38: STA_I_037 | AA38: =VLOOKUP(Z38,'Axe 2 Règles de gestion'!$D$2:$F$97,3, FALSE) -> En cas d'interruption du stage pendant moins de 3 ans, l'agent doit avoir accompli la période complémentaire de stage qui est nécessaire pour atteindre la durée normale du stage pour être titularisé. | AB38: STA_I_092 | AC38: =VLOOKUP(AB38,'Axe 2 Règles de gestion'!$D$2:$F$97,3, FALSE) -> Pour les agents dont le stage se déroule dans un établissement de formation, l'autorité peut mettre fin au stage si les absences de l'agent dépassent une durée fixée réglementairement. | AJ38: STA_D_006 | AK38: =VLOOKUP(AJ38,'Axe 2 Règles de gestion'!$D$2:$F$97,3, FALSE) -> L'agent a été en congé de solidarité familiale ou en congé de proche aidant pendant sa période de stage. | AP38: CAR_C_054 | AQ38: =VLOOKUP(AP38,'Axe 2 Règles de gestion'!$D$2:$F$97,3, FALSE) -> La date de fin réelle du stage doit être antérieure à la date limite de départ à la retraite. | AR38: CAR_C_055 | AS38: =VLOOKUP(AR38,'Axe 2 Règles de gestion'!$D$2:$F$97,3, FALSE) -> La date de fin prévisionnelle de stage doit être antérieure à la date limite de départ à la retraite. | AT38: CAR_C_097 | AU38: =VLOOKUP(AT38,'Axe 2 Règles de gestion'!$D$2:$F$97,3, FALSE) -> La date de fin réelle du stage doit être postérieure à la date de fin réelle du congé liée à la prolongation | AV38: CAR_C_098 | AW38: =VLOOKUP(AV38,'Axe 2 Règles de gestion'!$D$2:$F$97,3, FALSE) -> La date de fin prévisionnelle du stage doit être postérieure à la date de fin réelle du congé liée à la prolongation | AX38: 2025-69
A39: 25.10.00 | B39: A | C39: 45982.467 | D39: D0005 | E39: Carrière | F39: S0187 | G39: Stage préalable à la titularisation ou à la confirmation | H39: E1035 | I39: Prolongation stage suite à congé de solidarité familiale ou à congé de proche aidant | J39: Le type de situation de stage est égal à 'Prolongation suite à congé de solidarité familiale ou à congé de proche aidant' | K39: A_CAR_MOREST [Saisi] = 'TS07' | L39: T2483 | M39: Prolongation stage suite à congé de solidarité familiale ou à congé de proche aidant | N39: Création Modification | Q39: Ouvrier d'état | R39: P0005 | S39: Général | T39: Exclu | U39: 45931 | AX39: 2025-69
A40: 25.10.00 | B40: A | C40: 45982.646 | D40: D0005 | E40: Carrière | F40: S0187 | G40: Stage préalable à la titularisation ou à la confirmation | H40: E1035 | I40: Prolongation stage suite à congé de solidarité familiale ou à congé de proche aidant | J40: Le type de situation de stage est égal à 'Prolongation suite à congé de solidarité familiale ou à congé de proche aidant' | K40: A_CAR_MOREST [Saisi] = 'TS07' | L40: T2483 | M40: Prolongation stage suite à congé de solidarité familiale ou à congé de proche aidant | N40: Création Modification | Q40: Ouvrier de la défense auxiliaire non affilié ou temporaire non mensualisé | R40: P0182 | S40: Particulier | T40: Passant | U40: 45931 | W40: STA_D_102 ET STA_D_103 ET CAR_C_054 ET CAR_C_055 ET CAR_C_097 ET CAR_C_098 | AJ40: STA_D_102 | AK40: =VLOOKUP(AJ40,'Axe 2 Règles de gestion'!$D$2:$F$97,3, FALSE) -> La durée totale du stage (prolongation incluse) ne peut excéder 2 ans entre la date de début et la date de fin prévisionnelle. | AL40: STA_D_103 | AM40: =VLOOKUP(AL40,'Axe 2 Règles de gestion'!$D$2:$F$97,3, FALSE) -> La durée totale du stage (prolongation incluse) ne peut excéder 2 ans entre la date de début et la date de fin réelle. | AP40: CAR_C_054 | AQ40: =VLOOKUP(AP40,'Axe 2 Règles de gestion'!$D$2:$F$97,3, FALSE) -> La date de fin réelle du stage doit être antérieure à la date limite de départ à la retraite. | AR40: CAR_C_055 | AS40: =VLOOKUP(AR40,'Axe 2 Règles de gestion'!$D$2:$F$97,3, FALSE) -> La date de fin prévisionnelle de stage doit être antérieure à la date limite de départ à la retraite. | AT40: CAR_C_097 | AU40: =VLOOKUP(AT40,'Axe 2 Règles de gestion'!$D$2:$F$97,3, FALSE) -> La date de fin réelle du stage doit être postérieure à la date de fin réelle du congé liée à la prolongation | AV40: CAR_C_098 | AW40: =VLOOKUP(AV40,'Axe 2 Règles de gestion'!$D$2:$F$97,3, FALSE) -> La date de fin prévisionnelle du stage doit être postérieure à la date de fin réelle du congé liée à la prolongation | AX40: 2025-69
...

Sheet Axe 1 Enchaînement RG Impact
A1: Version | B1: Type de mise à jour | C1: Date de mise à jour | D1: Identifiant Domaine | E1: Libellé du Domaine | F1: Identifiant Sous-domaine | G1: Libellé du Sous-domaine | H1: Identifiant Evénement | I1: Libellé de l'évènement | J1: Libellé condition déclenchement Evènement | K1: Condition déclenchement Evènement | L1: Identifiant type d'évènement | M1: Libellé type d'évènement | N1: Type de mise à jour | O1: Libellé condition déclenchement Type Evènement | P1: Condition déclenchement Type Evènement | Q1: Libellé Population | R1: Codification Population | S1: Général / Particulier | T1: Passant / Exclu | U1: Date de début | V1: Date de fin | W1: Impacts | X1: Identifiant Impacts 1 | Y1: Libellé Impacts 1 | Z1: FIME | AA1: Statut de travail
A2: 25.10.00 | B2: A | C2: 45982.411 | D2: D0005 | E2: Carrière | F2: S0187 | G2: Stage préalable à la titularisation ou à la confirmation | H2: E1030 | I2: Prolongation stage suite à résultats insuffisants | J2: Prolongation suite à résultats insuffisants | K2: A_CAR_MOREST [Saisi] = 'TS01' | L2: T2478 | M2: Prolongation stage suite à résultats insuffisants | N2: Création Modification | Q2: Titulaire ou magistrat | R2: P0001 | S2: Général | T2: Exclu | U2: 45931 | Z2: 2025-69
A3: 25.10.00 | B3: A | C3: 45982.411 | D3: D0005 | E3: Carrière | F3: S0187 | G3: Stage préalable à la titularisation ou à la confirmation | H3: E1030 | I3: Prolongation stage suite à résultats insuffisants | J3: Prolongation suite à résultats insuffisants | K3: A_CAR_MOREST [Saisi] = 'TS01' | L3: T2478 | M3: Prolongation stage suite à résultats insuffisants | N3: Création Modification | Q3: Militaire | R3: P0002 | S3: Général | T3: Exclu | U3: 45931 | Z3: 2025-69
A4: 25.10.00 | B4: A | C4: 45982.411 | D4: D0005 | E4: Carrière | F4: S0187 | G4: Stage préalable à la titularisation ou à la confirmation | H4: E1030 | I4: Prolongation stage suite à résultats insuffisants | J4: Prolongation suite à résultats insuffisants | K4: A_CAR_MOREST [Saisi] = 'TS01' | L4: T2478 | M4: Prolongation stage suite à résultats insuffisants | N4: Création Modification | Q4: Contractuel | R4: P0003 | S4: Général | T4: Exclu | U4: 45931 | Z4: 2025-69
A5: 25.10.00 | B5: A | C5: 45982.601 | D5: D0005 | E5: Carrière | F5: S0187 | G5: Stage préalable à la titularisation ou à la confirmation | H5: E1030 | I5: Prolongation stage suite à résultats insuffisants | J5: Prolongation suite à résultats insuffisants | K5: A_CAR_MOREST [Saisi] = 'TS01' | L5: T2478 | M5: Prolongation stage suite à résultats insuffisants | N5: Création Modification | Q5: Stagiaire ou auditeur ou élève | R5: P0004 | S5: Général | T5: Passant | U5: 45931 | Z5: 2025-69
A6: 25.10.00 | B6: A | C6: 45982.411 | D6: D0005 | E6: Carrière | F6: S0187 | G6: Stage préalable à la titularisation ou à la confirmation | H6: E1030 | I6: Prolongation stage suite à résultats insuffisants | J6: Prolongation suite à résultats insuffisants | K6: A_CAR_MOREST [Saisi] = 'TS01' | L6: T2478 | M6: Prolongation stage suite à résultats insuffisants | N6: Création Modification | Q6: Ouvrier d'état | R6: P0005 | S6: Général | T6: Exclu | U6: 45931 | Z6: 2025-69
A7: 25.10.00 | B7: A | C7: 45982.642 | D7: D0005 | E7: Carrière | F7: S0187 | G7: Stage préalable à la titularisation ou à la confirmation | H7: E1030 | I7: Prolongation stage suite à résultats insuffisants | J7: Prolongation suite à résultats insuffisants | K7: A_CAR_MOREST [Saisi] = 'TS01' | L7: T2478 | M7: Prolongation stage suite à résultats insuffisants | N7: Création Modification | Q7: Ouvrier de la défense auxiliaire non affilié ou temporaire non mensualisé | R7: P0182 | S7: Particulier | T7: Passant | U7: 45931 | Z7: 2025-69
A8: 25.10.00 | B8: A | C8: 45982.653 | D8: D0005 | E8: Carrière | F8: S0187 | G8: Stage préalable à la titularisation ou à la confirmation | H8: E1030 | I8: Prolongation stage suite à résultats insuffisants | J8: Prolongation suite à résultats insuffisants | K8: A_CAR_MOREST [Saisi] = 'TS01' | L8: T2478 | M8: Prolongation stage suite à résultats insuffisants | N8: Création Modification | Q8: Ouvrier des parcs et ateliers stagiaire | R8: P0226 | S8: Particulier | T8: Passant | U8: 45931 | Z8: 2025-69
A9: 25.10.00 | B9: A | C9: 45982.66 | D9: D0005 | E9: Carrière | F9: S0187 | G9: Stage préalable à la titularisation ou à la confirmation | H9: E1030 | I9: Prolongation stage suite à résultats insuffisants | J9: Prolongation suite à résultats insuffisants | K9: A_CAR_MOREST [Saisi] = 'TS01' | L9: T2478 | M9: Prolongation stage suite à résultats insuffisants | N9: Création Modification | Q9: Ouvrier de l'Institut Géographique National stagiaire | R9: P0294 | S9: Particulier | T9: Passant | U9: 45931 | Z9: 2025-69
A10: 25.10.00 | B10: A | C10: 45982.412 | D10: D0005 | E10: Carrière | F10: S0187 | G10: Stage préalable à la titularisation ou à la confirmation | H10: E1031 | I10: Prolongation stage suite à temps partiel | J10: Le type de situation de stage est égal à 'Prolongation suite à temps partiel' | K10: A_CAR_MOREST [Saisi] = 'TS02' | L10: T2479 | M10: Prolongation stage suite à temps partiel | N10: Création Modification | Q10: Titulaire ou magistrat | R10: P0001 | S10: Général | T10: Exclu | U10: 45931 | Z10: 2025-69
A11: 25.10.00 | B11: A | C11: 45982.413 | D11: D0005 | E11: Carrière | F11: S0187 | G11: Stage préalable à la titularisation ou à la confirmation | H11: E1031 | I11: Prolongation stage suite à temps partiel | J11: Le type de situation de stage est égal à 'Prolongation suite à temps partiel' | K11: A_CAR_MOREST [Saisi] = 'TS02' | L11: T2479 | M11: Prolongation stage suite à temps partiel | N11: Création Modification | Q11: Militaire | R11: P0002 | S11: Général | T11: Exclu | U11: 45931 | Z11: 2025-69
A12: 25.10.00 | B12: A | C12: 45982.413 | D12: D0005 | E12: Carrière | F12: S0187 | G12: Stage préalable à la titularisation ou à la confirmation | H12: E1031 | I12: Prolongation stage suite à temps partiel | J12: Le type de situation de stage est égal à 'Prolongation suite à temps partiel' | K12: A_CAR_MOREST [Saisi] = 'TS02' | L12: T2479 | M12: Prolongation stage suite à temps partiel | N12: Création Modification | Q12: Contractuel | R12: P0003 | S12: Général | T12: Exclu | U12: 45931 | Z12: 2025-69
A13: 25.10.00 | B13: A | C13: 45982.602 | D13: D0005 | E13: Carrière | F13: S0187 | G13: Stage préalable à la titularisation ou à la confirmation | H13: E1031 | I13: Prolongation stage suite à temps partiel | J13: Le type de situation de stage est égal à 'Prolongation suite à temps partiel' | K13: A_CAR_MOREST [Saisi] = 'TS02' | L13: T2479 | M13: Prolongation stage suite à temps partiel | N13: Création Modification | Q13: Stagiaire ou auditeur ou élève | R13: P0004 | S13: Général | T13: Passant | U13: 45931 | Z13: 2025-69
... A18: 25.10.00 | B18: A | C18: 45982.446 | D18: D0005 | E18: Carrière | F18: S0187 | G18: Stage préalable à la titularisation ou à la confirmation | H18: E1032 | I18: Prolongation stage suite à congé de maternité, paternité, adoption | J18: Le type de situation de stage est égal à 'Prolongation suite à congé de maternité, paternité, adoption' | K18: A_CAR_MOREST [Saisi] = 'TS04' | L18: T2480 | M18: Prolongation stage suite à congé de maternité, paternité, adoption | N18: Création Modification | Q18: Contractuel | R18: P0003 | S18: Général | T18: Exclu | U18: 45931 | Z18: 2025-69
A19: 25.10.00 | B19: M | C19: 46020.452 | D19: D0005 | E19: Carrière | F19: S0187 | G19: Stage préalable à la titularisation ou à la confirmation | H19: E1032 | I19: Prolongation stage suite à congé de maternité, paternité, adoption | J19: Le type de situation de stage est égal à 'Prolongation suite à congé de maternité, paternité, adoption' | K19: A_CAR_MOREST [Saisi] = 'TS04' | L19: T2480 | M19: Prolongation stage suite à congé de maternité, paternité, adoption | N19: Création Modification | Q19: Stagiaire ou auditeur ou élève | R19: P0004 | S19: Général | T19: Passant | U19: 45931 | W19: STA_P_035 | X19: STA_P_035 | Y19: =VLOOKUP(X19,'Axe 2 Règles de gestion'!$D$2:$F$97,3, FALSE) -> Titularisation : Elle prend effet à la date de la fin de la durée statutaire du stage compte non tenu de la prolongation du stage imputable à ce congé. | Z19: 2025-69
A20: 25.10.00 | B20: A | C20: 45982.447 | D20: D0005 | E20: Carrière | F20: S0187 | G20: Stage préalable à la titularisation ou à la confirmation | H20: E1032 | I20: Prolongation stage suite à congé de maternité, paternité, adoption | J20: Le type de situation de stage est égal à 'Prolongation suite à congé de maternité, paternité, adoption' | K20: A_CAR_MOREST [Saisi] = 'TS04' | L20: T2480 | M20: Prolongation stage suite à congé de maternité, paternité, adoption | N20: Création Modification | Q20: Ouvrier d'état | R20: P0005 | S20: Général | T20: Exclu | U20: 45931 | Z20: 2025-69
A21: 25.10.00 | B21: A | C21: 45982.644 | D21: D0005 | E21: Carrière | F21: S0187 | G21: Stage préalable à la titularisation ou à la confirmation | H21: E1032 | I21: Prolongation stage suite à congé de maternité, paternité, adoption | J21: Le type de situation de stage est égal à 'Prolongation suite à congé de maternité, paternité, adoption' | K21: A_CAR_MOREST [Saisi] = 'TS04' | L21: T2480 | M21: Prolongation stage suite à congé de maternité, paternité, adoption | N21: Création Modification | Q21: Ouvrier de la défense auxiliaire non affilié ou temporaire non mensualisé | R21: P0182 | S21: Particulier | T21: Passant | U21: 45931 | Z21: 2025-69
A22: 25.10.00 | B22: M | C22: 46020.454 | D22: D0005 | E22: Carrière | F22: S0187 | G22: Stage préalable à la titularisation ou à la confirmation | H22: E1032 | I22: Prolongation stage suite à congé de maternité, paternité, adoption | J22: Le type de situation de stage est égal à 'Prolongation suite à congé de maternité, paternité, adoption' | K22: A_CAR_MOREST [Saisi] = 'TS04' | L22: T2480 | M22: Prolongation stage suite à congé de maternité, paternité, adoption | N22: Création Modification | Q22: Ouvrier de l'Etat stagiaire | R22: P0293 | S22: Particulier | T22: Passant | U22: 45931 | W22: STA_P_036 | X22: STA_P_036 | Y22: =VLOOKUP(X22,'Axe 2 Règles de gestion'!$D$2:$F$97,3, FALSE) -> Affiliation : Elle prend effet à la date de la fin de la durée statutaire du stage compte non tenu de la prolongation du stage imputable à ce congé. | Z22: 2025-69
A23: 25.10.00 | B23: A | C23: 45982.448 | D23: D0005 | E23: Carrière | F23: S0187 | G23: Stage préalable à la titularisation ou à la confirmation | H23: E1033 | I23: Prolongation stage suite à congés rémunérés de toute nature hors congés annuel, maternité, paternité, adoption | J23: Le type de situation de stage est égal à 'Prolongation suite à congés rémunérés de toute nature hors congés annuel, maternité, paternité, adoption' | K23: A_CAR_MOREST [Saisi] = 'TS05' | L23: T2481 | M23: Prolongation stage suite à congés rémunérés de toute nature hors congés annuel, maternité, paternité, adoption | N23: Création Modification | Q23: Titulaire ou magistrat | R23: P0001 | S23: Général | T23: Exclu | U23: 45931 | Z23: 2025-69
A24: 25.10.00 | B24: A | C24: 45982.449 | D24: D0005 | E24: Carrière | F24: S0187 | G24: Stage préalable à la titularisation ou à la confirmation | H24: E1033 | I24: Prolongation stage suite à congés rémunérés de toute nature hors congés annuel, maternité, paternité, adoption | J24: Le type de situation de stage est égal à 'Prolongation suite à congés rémunérés de toute nature hors congés annuel, maternité, paternité, adoption' | K24: A_CAR_MOREST [Saisi] = 'TS05' | L24: T2481 | M24: Prolongation stage suite à congés rémunérés de toute nature hors congés annuel, maternité, paternité, adoption | N24: Création Modification | Q24: Militaire | R24: P0002 | S24: Général | T24: Exclu | U24: 45931 | Z24: 2025-69
A25: 25.10.00 | B25: A | C25: 45982.448 | D25: D0005 | E25: Carrière | F25: S0187 | G25: Stage préalable à la titularisation ou à la confirmation | H25: E1033 | I25: Prolongation stage suite à congés rémunérés de toute nature hors congés annuel, maternité, paternité, adoption | J25: Le type de situation de stage est égal à 'Prolongation suite à congés rémunérés de toute nature hors congés annuel, maternité, paternité, adoption' | K25: A_CAR_MOREST [Saisi] = 'TS05' | L25: T2481 | M25: Prolongation stage suite à congés rémunérés de toute nature hors congés annuel, maternité, paternité, adoption | N25: Création Modification | Q25: Contractuel | R25: P0003 | S25: Général | T25: Exclu | U25: 45931 | Z25: 2025-69
