Workbook
Name date_DIADC: 'Mode opératoire'!#REF!
Name notice_DIADC: 'Mode opératoire'!#REF!
Name notice_ENCHN: 'Mode opératoire'!$B$1:$B$4
Name notice_ICA: 'Mode opératoire'!#REF!

Sheet Mode opératoire
B1: MODE OPERATOIRE
B2: La transaction s'effectue au niveau de la rubrique "Action de formation" et inclut la sous-rubrique "Formation demandée/suivie".

Sheet Axe 1 Enchainement des RG
A1: Version | B1: Type de mise à jour | C1: Date de mise à jour | D1: Identifiant Domaine | E1: Libellé du Domaine | F1: Identifiant Sous-domaine | G1: Libellé du Sous-domaine | H1: Identifiant Evénement | I1: Libellé de l'évènement | J1: Libellé condition déclenchement Evènement | K1: Condition déclenchement Evènement | L1: Identifiant type d'évènement | M1: Libellé type d'évènement | N1: Type de mise à jour | O1: Libellé condition déclenchement Type Evènement | P1: Condition déclenchement Type Evènement | Q1: Libellé Population | R1: Codification Population | S1: Typologie de population | T1: Général / Particulier | U1: Passant / Exclu | V1: Date de début | W1: Date de fin | X1: Règles mobilisées | Y1: Identifiant Règle de contrôle intellectuel 1 | Z1: Libellé Règle de contrôle intellectuel 1 | AA1: Identifiant Règle de contrôle intellectuel 2 | AB1: Libellé Règle de contrôle intellectuel 2 | AC1: Identifiant Règle de contrôle intellectuel 3 | AD1: Libellé Règle de contrôle intellectuel 3 | AE1: Identifiant Règle de contrôle intellectuel 4 | AF1: Libellé Règle de contrôle intellectuel 4 | AG1: Identifiant Règle de contrôle intellectuel 5 | AH1: Libellé Règle de contrôle intellectuel 5 | AI1: Identifiant Règle de contrôle intellectuel 6 | AJ1: Libellé Règle de contrôle intellectuel 6 | AK1: Identifiant Règle de contrôle intellectuel 7 | AL1: Libellé Règle de contrôle intellectuel 7 | AM1: Identifiant Règle de contrôle intellectuel 8 | AN1: Libellé Règle de contrôle intellectuel 8 | AO1: Identifiant Règle de contrôle intellectuel 9 | AP1: Libellé Règle de contrôle intellectuel 9 | AQ1: Identifiant Règle de contrôle intellectuel 10 | AR1: Libellé Règle de contrôle intellectuel 10 | AS1: Identifiant Règle de contrôle intellectuel 11 | AT1: Libellé Règle de contrôle intellectuel 11 | AU1: Identifiant Règle de contrôle intellectuel 12 | AV1: Libellé Règle de contrôle intellectuel 12 | AW1: Identifiant Règle de condition 1 | AX1: Libellé Règle de condition 1 | AY1: Identifiant Règle de contrôle 1 | AZ1: Libellé Règle de contrôle 1 | BA1: Identifiant Règle de contrôle 2 | BB1: Libellé Règle de contrôle 2 | BC1: Identifiant Règle de contrôle 3 | BD1: Libellé Règle de contrôle 3 | BE1: Identifiant Règle de contrôle 4 | BF1: Libellé Règle de contrôle 4 | BG1: FIME | BH1: Statut de travail
A2: 20.00.00 | B2: A | C2: 43895.661 | D2: D0009 | E2: Formation | F2: S0143 | G2: Préparation aux concours ou examens | H2: E0809 | I2: Préparation aux concours ou examens | J2: Type de la formation demandée saisi égal 'Préparation aux concours ou examens' | K2: P_ACF_TYDFOR [Saisi] = 'F16' | L2: T2003 | M2: Préparation aux concours ou examens - Demande | N2: Création | Q2: Titulaire ou magistrat | R2: P0001 | S2: T | T2: Général | U2: Passant | V2: 40725 | W2: 42865 | X2: DCE_I_001 ET DCE_I_007 ET DCE_I_010 ET DCE_I_012 ET DCE_I_014 ET DCE_I_016 ET DCE_D_001 ET FOR_C_001 ET FOR_C_003 ET FOR_C_004 | Y2: DCE_I_001 | Z2: =VLOOKUP(Y2,'Axe 2 Règles de gestion'!$D$2:$F$40,3, FALSE) -> L'agent doit formuler une demande. | AA2: DCE_I_007 | AB2: =VLOOKUP(AA2,'Axe 2 Règles de gestion'!$D$2:$F$40,3, FALSE) -> L'accord de l'administration est de droit pour l'agent en congé parental n'ayant bénéficié d'aucune action de formation de préparation d'examen ou concours au cours des 3 années antérieures, dans la limite des crédits disponibles. | AC2: DCE_I_010 | AD2: =VLOOKUP(AC2,'Axe 2 Règles de gestion'!$D$2:$F$40,3, FALSE) -> L'agent peut demander à bénéficier d'un congé de formation professionnelle. | AE2: DCE_I_012 | AF2: =VLOOKUP(AE2,'Axe 2 Règles de gestion'!$D$2:$F$40,3, FALSE) -> L'agent peut demander une décharge de service si la formation se déroule pendant son temps de service. | AG2: DCE_I_014 | AH2: =VLOOKUP(AG2,'Axe 2 Règles de gestion'!$D$2:$F$40,3, FALSE) -> Toute demande de décharge inférieure ou égale à 5 journées de service à temps complet pour une année donnée est accordée de droit. | AI2: DCE_I_016 | AJ2: =VLOOKUP(AI2,'Axe 2 Règles de gestion'!$D$2:$F$40,3, FALSE) -> L'administration peut reporter la demande de décharge au maximum 2 fois dans l'intérêt du fonctionnement du service. | AW2: DCE_D_001 | AX2: =VLOOKUP(AW2,'Axe 2 Règles de gestion'!$D$2:$F$40,3, FALSE) -> L'agent doit être en position d'activité ou de congé parental. | AY2: FOR_C_001 | AZ2: =VLOOKUP(AY2,'Axe 2 Règles de gestion'!$D$2:$F$40,3, FALSE) -> La date de début de la formation doit être postérieure ou égale à la date de recrutement dans la FPE ou dans la carrière militaire. | BA2: FOR_C_003 | BB2: =VLOOKUP(BA2,'Axe 2 Règles de gestion'!$D$2:$F$40,3, FALSE) -> La date de début de la formation doit être antérieure ou égale à la date de fin de la formation. | BC2: FOR_C_004 | BD2: =VLOOKUP(BC2,'Axe 2 Règles de gestion'!$D$2:$F$40,3, FALSE) -> La date de fin de formation doit être antérieure ou égale à la date limite de départ à la retraite.
A3: 22.10.00 | B3: M | C3: 44963.671 | D3: D0009 | E3: Formation | F3: S0143 | G3: Préparation aux concours ou examens | H3: E0809 | I3: Préparation aux concours ou examens | J3: Type de la formation demandée saisi égal 'Préparation aux concours ou examens' | K3: P_ACF_TYDFOR [Saisi] = 'F16' | L3: T2003 | M3: Préparation aux concours ou examens - Demande | N3: Création | Q3: Titulaire ou magistrat | R3: P0001 | S3: T | T3: Général | U3: Passant | V3: 42866 | W3: 44766 | X3: DCE_I_001 ET DCE_I_007 ET DCE_I_008 ET DCE_I_010 ET DCE_I_012 ET DCE_I_014 ET DCE_I_016 ET DCE_D_001 ET FOR_C_001 ET FOR_C_003 ET FOR_C_004 | Y3: DCE_I_001 | Z3: =VLOOKUP(Y3,'Axe 2 Règles de gestion'!$D$2:$F$40,3, FALSE) -> L'agent doit formuler une demande. | AA3: DCE_I_007 | AB3: =VLOOKUP(AA3,'Axe 2 Règles de gestion'!$D$2:$F$40,3, FALSE) -> L'accord de l'administration est de droit pour l'agent en congé parental n'ayant bénéficié d'aucune action de formation de préparation d'examen ou concours au cours des 3 années antérieures, dans la limite des crédits disponibles. | AC3: DCE_I_008 | AD3: =VLOOKUP(AC3,'Axe 2 Règles de gestion'!$D$2:$F$40,3, FALSE) -> L'agent peut utiliser son compte personnel de formation. | AE3: DCE_I_010 | AF3: =VLOOKUP(AE3,'Axe 2 Règles de gestion'!$D$2:$F$40,3, FALSE) -> L'agent peut demander à bénéficier d'un congé de formation professionnelle. | AG3: DCE_I_012 | AH3: =VLOOKUP(AG3,'Axe 2 Règles de gestion'!$D$2:$F$40,3, FALSE) -> L'agent peut demander une décharge de service si la formation se déroule pendant son temps de service. | AI3: DCE_I_014 | AJ3: =VLOOKUP(AI3,'Axe 2 Règles de gestion'!$D$2:$F$40,3, FALSE) -> Toute demande de décharge inférieure ou égale à 5 journées de service à temps complet pour une année donnée est accordée de droit. | AK3: DCE_I_016 | AL3: =VLOOKUP(AK3,'Axe 2 Règles de gestion'!$D$2:$F$40,3, FALSE) -> L'administration peut reporter la demande de décharge au maximum 2 fois dans l'intérêt du fonctionnement du service. | AW3: DCE_D_001 | AX3: =VLOOKUP(AW3,'Axe 2 Règles de gestion'!$D$2:$F$40,3, FALSE) -> L'agent doit être en position d'activité ou de congé parental. | AY3: FOR_C_001 | AZ3: =VLOOKUP(AY3,'Axe 2 Règles de gestion'!$D$2:$F$40,3, FALSE) -> La date de début de la formation doit être postérieure ou égale à la date de recrutement dans la FPE ou dans la carrière militaire. | BA3: FOR_C_003 | BB3: =VLOOKUP(BA3,'Axe 2 Règles de gestion'!$D$2:$F$40,3, FALSE) -> La date de début de la formation doit être antérieure ou égale à la date de fin de la formation. | BC3: FOR_C_004 | BD3: =VLOOKUP(BC3,'Axe 2 Règles de gestion'!$D$2:$F$40,3, FALSE) -> La date de fin de formation doit être antérieure ou égale à la date limite de départ à la retraite.
A4: 22.10.00 | B4: A | C4: 44963.674 | D4: D0009 | E4: Formation | F4: S0143 | G4: Préparation aux concours ou examens | H4: E0809 | I4: Préparation aux concours ou examens | J4: Type de la formation demandée saisi égal 'Préparation aux concours ou examens' | K4: P_ACF_TYDFOR [Saisi] = 'F16' | L4: T2003 | M4: Préparation aux concours ou examens - Demande | N4: Création | Q4: Titulaire ou magistrat | R4: P0001 | S4: T | T4: Général | U4: Passant | V4: 44767 | X4: DCE_I_001 ET DCE_I_007 ET DCE_I_008 ET DCE_I_010 ET DCE_I_012 ET DCE_I_014 ET DCE_I_016 ET DCE_I_021 ET DCE_D_001 ET FOR_C_001 ET FOR_C_003 ET FOR_C_004 | Y4: DCE_I_001 | Z4: =VLOOKUP(Y4,'Axe 2 Règles de gestion'!$D$2:$F$40,3, FALSE) -> L'agent doit formuler une demande. | AA4: DCE_I_007 | AB4: =VLOOKUP(AA4,'Axe 2 Règles de gestion'!$D$2:$F$40,3, FALSE) -> L'accord de l'administration est de droit pour l'agent en congé parental n'ayant bénéficié d'aucune action de formation de préparation d'examen ou concours au cours des 3 années antérieures, dans la limite des crédits disponibles. | AC4: DCE_I_008 | AD4: =VLOOKUP(AC4,'Axe 2 Règles de gestion'!$D$2:$F$40,3, FALSE) -> L'agent peut utiliser son compte personnel de formation. | AE4: DCE_I_010 | AF4: =VLOOKUP(AE4,'Axe 2 Règles de gestion'!$D$2:$F$40,3, FALSE) -> L'agent peut demander à bénéficier d'un congé de formation professionnelle. | AG4: DCE_I_012 | AH4: =VLOOKUP(AG4,'Axe 2 Règles de gestion'!$D$2:$F$40,3, FALSE) -> L'agent peut demander une décharge de service si la formation se déroule pendant son temps de service. | AI4: DCE_I_014 | AJ4: =VLOOKUP(AI4,'Axe 2 Règles de gestion'!$D$2:$F$40,3, FALSE) -> Toute demande de décharge inférieure ou égale à 5 journées de service à temps complet pour une année donnée est accordée de droit. | AK4: DCE_I_016 | AL4: =VLOOKUP(AK4,'Axe 2 Règles de gestion'!$D$2:$F$40,3, FALSE) -> L'administration peut reporter la demande de décharge au maximum 2 fois dans l'intérêt du fonctionnement du service. | AM4: DCE_I_021 | AN4: =VLOOKUP(AM4,'Axe 2 Règles de gestion'!$D$2:$F$40,3, FALSE) -> L'agent bénéficiant d'un accès prioritaire à la formation de préparation d'examen ou concours dans des conditions définies règlementairement doit transmettre à l'administration les attestations d'assiduité établies par l'organisme de formation. | AW4: DCE_D_001 | AX4: =VLOOKUP(AW4,'Axe 2 Règles de gestion'!$D$2:$F$40,3, FALSE) -> L'agent doit être en position d'activité ou de congé parental. | AY4: FOR_C_001 | AZ4: =VLOOKUP(AY4,'Axe 2 Règles de gestion'!$D$2:$F$40,3, FALSE) -> La date de début de la formation doit être postérieure ou égale à la date de recrutement dans la FPE ou dans la carrière militaire. | BA4: FOR_C_003 | BB4: =VLOOKUP(BA4,'Axe 2 Règles de gestion'!$D$2:$F$40,3, FALSE) -> La date de début de la formation doit être antérieure ou égale à la date de fin de la formation. | BC4: FOR_C_004 | BD4: =VLOOKUP(BC4,'Axe 2 Règles de gestion'!$D$2:$F$40,3, FALSE) -> La date de fin de formation doit être antérieure ou égale à la date limite de départ à la retraite.
A5: 22.10.00 | B5: M | C5: 44963.675 | D5: D0009 | E5: Formation | F5: S0143 | G5: Préparation aux concours ou examens | H5: E0809 | I5: Préparation aux concours ou examens | J5: Type de la formation demandée saisi égal 'Préparation aux concours ou examens' | K5: P_ACF_TYDFOR [Saisi] = 'F16' | L5: T2004 | M5: Préparation aux concours ou examens - Fin | N5: Modification | Q5: Titulaire ou magistrat | R5: P0001 | S5: T | T5: Général | U5: Passant | V5: 40725 | W5: 44766 | X5: FOR_C_003 ET FOR_C_004 | AY5: FOR_C_003 | AZ5: =VLOOKUP(AY5,'Axe 2 Règles de gestion'!$D$2:$F$40,3, FALSE) -> La date de début de la formation doit être antérieure ou égale à la date de fin de la formation. | BA5: FOR_C_004 | BB5: =VLOOKUP(BA5,'Axe 2 Règles de gestion'!$D$2:$F$40,3, FALSE) -> La date de fin de formation doit être antérieure ou égale à la date limite de départ à la retraite.
A6: 22.10.00 | B6: A | C6: 44963.675 | D6: D0009 | E6: Formation | F6: S0143 | G6: Préparation aux concours ou examens | H6: E0809 | I6: Préparation aux concours ou examens | J6: Type de la formation demandée saisi égal 'Préparation aux concours ou examens' | K6: P_ACF_TYDFOR [Saisi] = 'F16' | L6: T2004 | M6: Préparation aux concours ou examens - Fin | N6: Modification | Q6: Titulaire ou magistrat | R6: P0001 | S6: T | T6: Général | U6: Passant | V6: 44767 | X6: DCE_I_022 ET FOR_C_003 ET FOR_C_004 | Y6: DCE_I_022 | Z6: =VLOOKUP(Y6,'Axe 2 Règles de gestion'!$D$2:$F$40,3, FALSE) -> L'agent bénéficiant d'un accès prioritaire à la formation en perd le bénéfice s'il arrête, sans motif légitime, de la suivre. | AY6: FOR_C_003 | AZ6: =VLOOKUP(AY6,'Axe 2 Règles de gestion'!$D$2:$F$40,3, FALSE) -> La date de début de la formation doit être antérieure ou égale à la date de fin de la formation. | BA6: FOR_C_004 | BB6: =VLOOKUP(BA6,'Axe 2 Règles de gestion'!$D$2:$F$40,3, FALSE) -> La date de fin de formation doit être antérieure ou égale à la date limite de départ à la retraite.
A7: 20.00.00 | B7: A | C7: 43895.667 | D7: D0009 | E7: Formation | F7: S0143 | G7: Préparation aux concours ou examens | H7: E0809 | I7: Préparation aux concours ou examens | J7: Type de la formation demandée saisi égal 'Préparation aux concours ou examens' | K7: P_ACF_TYDFOR [Saisi] = 'F16' | L7: T2003 | M7: Préparation aux concours ou examens - Demande | N7: Création | Q7: Contractuel | R7: P0003 | S7: N | T7: Général | U7: Passant | V7: 40725 | W7: 42865 | X7: DCE_I_018 ET DCE_I_002 ET DCE_I_013 ET DCE_I_015 ET DCE_I_017 ET DCE_I_011 ET DCE_I_019 ET DCE_D_002 ET FOR_C_002 ET FOR_C_003 ET FOR_C_004 ET FOR_C_005 | Y7: DCE_I_018 | Z7: =VLOOKUP(Y7,'Axe 2 Règles de gestion'!$D$2:$F$40,3, FALSE) -> L'agent détaché auprès d'une administration de l'Etat ou dans un établissement public de l'Etat dans un emploi ne conduisant pas à pension est soumis aux règles applicables aux titulaires. | AA7: DCE_I_002 | AB7: =VLOOKUP(AA7,'Axe 2 Règles de gestion'!$D$2:$F$40,3, FALSE) -> L'agent doit remplir ou être susceptible de remplir les conditions requises pour se présenter à ces examens, concours ou sélections à la fin du cycle de formation. | AC7: DCE_I_013 | AD7: =VLOOKUP(AC7,'Axe 2 Règles de gestion'!$D$2:$F$40,3, FALSE) -> L'agent peut demander une décharge de service si la formation se déroule pendant son temps de service. | AE7: DCE_I_015 | AF7: =VLOOKUP(AE7,'Axe 2 Règles de gestion'!$D$2:$F$40,3, FALSE) -> Toute demande de décharge inférieure ou égale à 5 journées de service à temps complet pour une année donnée est accordée de droit. | AG7: DCE_I_017 | AH7: =VLOOKUP(AG7,'Axe 2 Règles de gestion'!$D$2:$F$40,3, FALSE) -> L'administration peut reporter la demande de décharge au maximum 2 fois dans l'intérêt du fonctionnement du service. | AI7: DCE_I_011 | AJ7: =VLOOKUP(AI7,'Axe 2 Règles de gestion'!$D$2:$F$40,3, FALSE) -> L'agent peut demander à bénéficier d'un congé de formation professionnelle. | AK7: DCE_I_019 | AL7: =VLOOKUP(AK7,'Axe 2 Règles de gestion'!$D$2:$F$40,3, FALSE) -> Les agents ayant bénéficié de décharges de service ne peuvent prétendre au congé de formation dans les 12 mois suivant la fin de la période au cours de laquelle les décharges leur ont été consenties. | AW7: DCE_D_002 | AX7: =VLOOKUP(AW7,'Axe 2 Règles de gestion'!$D$2:$F$40,3, FALSE) -> L'agent doit être en position d'activité ou de congé parental. | AY7: FOR_C_002 | AZ7: =VLOOKUP(AY7,'Axe 2 Règles de gestion'!$D$2:$F$40,3, FALSE) -> La date de début de la formation doit être postérieure ou égale à la date de début du lien juridique. | BA7: FOR_C_003 | BB7: =VLOOKUP(BA7,'Axe 2 Règles de gestion'!$D$2:$F$40,3, FALSE) -> La date de début de la formation doit être antérieure ou égale à la date de fin de la formation. | BC7: FOR_C_004 | BD7: =VLOOKUP(BC7,'Axe 2 Règles de gestion'!$D$2:$F$40,3, FALSE) -> La date de fin de formation doit être antérieure ou égale à la date limite de départ à la retraite. | BE7: FOR_C_005 | BF7: =VLOOKUP(BE7,'Axe 2 Règles de gestion'!$D$2:$F$40,3, FALSE) -> La date de fin de la formation doit être antérieure ou égale à la date limite de fin réelle ou prévisionnelle du lien juridique.
A8: 22.10.00 | B8: M | C8: 44963.672 | D8: D0009 | E8: Formation | F8: S0143 | G8: Préparation aux concours ou examens | H8: E0809 | I8: Préparation aux concours ou examens | J8: Type de la formation demandée saisi égal 'Préparation aux concours ou examens' | K8: P_ACF_TYDFOR [Saisi] = 'F16' | L8: T2003 | M8: Préparation aux concours ou examens - Demande | N8: Création | Q8: Contractuel | R8: P0003 | S8: N | T8: Général | U8: Passant | V8: 42866 | W8: 44677 | X8: DCE_I_018 ET DCE_I_002 ET DCE_I_009 ET DCE_I_013 ET DCE_I_015 ET DCE_I_017 ET DCE_I_011 ET DCE_I_019 ET DCE_D_002 ET FOR_C_002 ET FOR_C_003 ET FOR_C_004 ET FOR_C_005 | Y8: DCE_I_018 | Z8: =VLOOKUP(Y8,'Axe 2 Règles de gestion'!$D$2:$F$40,3, FALSE) -> L'agent détaché auprès d'une administration de l'Etat ou dans un établissement public de l'Etat dans un emploi ne conduisant pas à pension est soumis aux règles applicables aux titulaires. | AA8: DCE_I_002 | AB8: =VLOOKUP(AA8,'Axe 2 Règles de gestion'!$D$2:$F$40,3, FALSE) -> L'agent doit remplir ou être susceptible de remplir les conditions requises pour se présenter à ces examens, concours ou sélections à la fin du cycle de formation. | AC8: DCE_I_009 | AD8: =VLOOKUP(AC8,'Axe 2 Règles de gestion'!$D$2:$F$40,3, FALSE) -> L'agent peut utiliser son compte personnel de formation. | AE8: DCE_I_013 | AF8: =VLOOKUP(AE8,'Axe 2 Règles de gestion'!$D$2:$F$40,3, FALSE) -> L'agent peut demander une décharge de service si la formation se déroule pendant son temps de service. | AG8: DCE_I_015 | AH8: =VLOOKUP(AG8,'Axe 2 Règles de gestion'!$D$2:$F$40,3, FALSE) -> Toute demande de décharge inférieure ou égale à 5 journées de service à temps complet pour une année donnée est accordée de droit. | AI8: DCE_I_017 | AJ8: =VLOOKUP(AI8,'Axe 2 Règles de gestion'!$D$2:$F$40,3, FALSE) -> L'administration peut reporter la demande de décharge au maximum 2 fois dans l'intérêt du fonctionnement du service. | AK8: DCE_I_011 | AL8: =VLOOKUP(AK8,'Axe 2 Règles de gestion'!$D$2:$F$40,3, FALSE) -> L'agent peut demander à bénéficier d'un congé de formation professionnelle. | AM8: DCE_I_019 | AN8: =VLOOKUP(AM8,'Axe 2 Règles de gestion'!$D$2:$F$40,3, FALSE) -> Les agents ayant bénéficié de décharges de service ne peuvent prétendre au congé de formation dans les 12 mois suivant la fin de la période au cours de laquelle les décharges leur ont été consenties. | AW8: DCE_D_002 | AX8: =VLOOKUP(AW8,'Axe 2 Règles de gestion'!$D$2:$F$40,3, FALSE) -> L'agent doit être en position d'activité ou de congé parental. | AY8: FOR_C_002 | AZ8: =VLOOKUP(AY8,'Axe 2 Règles de gestion'!$D$2:$F$40,3, FALSE) -> La date de début de la formation doit être postérieure ou égale à la date de début du lien juridique. | BA8: FOR_C_003 | BB8: =VLOOKUP(BA8,'Axe 2 Règles de gestion'!$D$2:$F$40,3, FALSE) -> La date de début de la formation doit être antérieure ou égale à la date de fin de la formation. | BC8: FOR_C_004 | BD8: =VLOOKUP(BC8,'Axe 2 Règles de gestion'!$D$2:$F$40,3, FALSE) -> La date de fin de formation doit être antérieure ou égale à la date limite de départ à la retraite. | BE8: FOR_C_005 | BF8: =VLOOKUP(BE8,'Axe 2 Règles de gestion'!$D$2:$F$40,3, FALSE) -> La date de fin de la formation doit être antérieure ou égale à la date limite de fin réelle ou prévisionnelle du lien juridique.
A9: 22.10.00 | B9: M | C9: 44963.672 | D9: D0009 | E9: Formation | F9: S0143 | G9: Préparation aux concours ou examens | H9: E0809 | I9: Préparation aux concours ou examens | J9: Type de la formation demandée saisi égal 'Préparation aux concours ou examens' | K9: P_ACF_TYDFOR [Saisi] = 'F16' | L9: T2003 | M9: Préparation aux concours ou examens - Demande | N9: Création | Q9: Contractuel | R9: P0003 | S9: N | T9: Général | U9: Passant | V9: 44678 | W9: 44766 | X9: DCE_I_018 ET DCE_I_002 ET DCE_I_009 ET DCE_I_020 ET DCE_I_013 ET DCE_I_015 ET DCE_I_017 ET DCE_I_011 ET DCE_I_019 ET DCE_D_002 ET FOR_C_002 ET FOR_C_003 ET FOR_C_004 ET FOR_C_005 | Y9: DCE_I_018 | Z9: =VLOOKUP(Y9,'Axe 2 Règles de gestion'!$D$2:$F$40,3, FALSE) -> L'agent détaché auprès d'une administration de l'Etat ou dans un établissement public de l'Etat dans un emploi ne conduisant pas à pension est soumis aux règles applicables aux titulaires. | AA9: DCE_I_002 | AB9: =VLOOKUP(AA9,'Axe 2 Règles de gestion'!$D$2:$F$40,3, FALSE) -> L'agent doit remplir ou être susceptible de remplir les conditions requises pour se présenter à ces examens, concours ou sélections à la fin du cycle de formation. | AC9: DCE_I_009 | AD9: =VLOOKUP(AC9,'Axe 2 Règles de gestion'!$D$2:$F$40,3, FALSE) -> L'agent peut utiliser son compte personnel de formation. | AE9: DCE_I_020 | AF9: =VLOOKUP(AE9,'Axe 2 Règles de gestion'!$D$2:$F$40,3, FALSE) -> La décision de refus d'une autorisation d'absence pour suivre une action de préparation à un concours administratif est soumise à la consultation de la commission consultative paritaire. | AG9: DCE_I_013 | AH9: =VLOOKUP(AG9,'Axe 2 Règles de gestion'!$D$2:$F$40,3, FALSE) -> L'agent peut demander une décharge de service si la formation se déroule pendant son temps de service. | AI9: DCE_I_015 | AJ9: =VLOOKUP(AI9,'Axe 2 Règles de gestion'!$D$2:$F$40,3, FALSE) -> Toute demande de décharge inférieure ou égale à 5 journées de service à temps complet pour une année donnée est accordée de droit. | AK9: DCE_I_017 | AL9: =VLOOKUP(AK9,'Axe 2 Règles de gestion'!$D$2:$F$40,3, FALSE) -> L'administration peut reporter la demande de décharge au maximum 2 fois dans l'intérêt du fonctionnement du service. | AM9: DCE_I_011 | AN9: =VLOOKUP(AM9,'Axe 2 Règles de gestion'!$D$2:$F$40,3, FALSE) -> L'agent peut demander à bénéficier d'un congé de formation professionnelle. | AO9: DCE_I_019 | AP9: =VLOOKUP(AO9,'Axe 2 Règles de gestion'!$D$2:$F$40,3, FALSE) -> Les agents ayant bénéficié de décharges de service ne peuvent prétendre au congé de formation dans les 12 mois suivant la fin de la période au cours de laquelle les décharges leur ont été consenties. | AW9: DCE_D_002 | AX9: =VLOOKUP(AW9,'Axe 2 Règles de gestion'!$D$2:$F$40,3, FALSE) -> L'agent doit être en position d'activité ou de congé parental. | AY9: FOR_C_002 | AZ9: =VLOOKUP(AY9,'Axe 2 Règles de gestion'!$D$2:$F$40,3, FALSE) -> La date de début de la formation doit être postérieure ou égale à la date de début du lien juridique. | BA9: FOR_C_003 | BB9: =VLOOKUP(BA9,'Axe 2 Règles de gestion'!$D$2:$F$40,3, FALSE) -> La date de début de la formation doit être antérieure ou égale à la date de fin de la formation. | BC9: FOR_C_004 | BD9: =VLOOKUP(BC9,'Axe 2 Règles de gestion'!$D$2:$F$40,3, FALSE) -> La date de fin de formation doit être antérieure ou égale à la date limite de départ à la retraite. | BE9: FOR_C_005 | BF9: =VLOOKUP(BE9,'Axe 2 Règles de gestion'!$D$2:$F$40,3, FALSE) -> La date de fin de la formation doit être antérieure ou égale à la date limite de fin réelle ou prévisionnelle du lien juridique.
A10: 25.10.00 | B10: M | C10: 45995.649 | D10: D0009 | E10: Formation | F10: S0143 | G10: Préparation aux concours ou examens | H10: E0809 | I10: Préparation aux concours ou examens | J10: Type de la formation demandée saisi égal 'Préparation aux concours ou examens' | K10: P_ACF_TYDFOR [Saisi] = 'F16' | L10: T2003 | M10: Préparation aux concours ou examens - Demande | N10: Création | Q10: Contractuel | R10: P0003 | S10: N | T10: Général | U10: Passant | V10: 44767 | X10: DCE_I_018 ET DCE_I_002 ET DCE_I_009 ET DCE_I_020 ET DCE_I_013 ET DCE_I_015 ET DCE_I_017 ET DCE_I_011 ET DCE_I_019 ET DCE_I_025 ET DCE_I_003 ET DCE_I_004 ET DCE_D_002 ET FOR_C_002 ET FOR_C_003 ET FOR_C_004 ET FOR_C_005 | Y10: DCE_I_018 | Z10: =VLOOKUP(Y10,'Axe 2 Règles de gestion'!$D$2:$F$40,3, FALSE) -> L'agent détaché auprès d'une administration de l'Etat ou dans un établissement public de l'Etat dans un emploi ne conduisant pas à pension est soumis aux règles applicables aux titulaires. | AA10: DCE_I_002 | AB10: =VLOOKUP(AA10,'Axe 2 Règles de gestion'!$D$2:$F$40,3, FALSE) -> L'agent doit remplir ou être susceptible de remplir les conditions requises pour se présenter à ces examens, concours ou sélections à la fin du cycle de formation. | AC10: DCE_I_009 | AD10: =VLOOKUP(AC10,'Axe 2 Règles de gestion'!$D$2:$F$40,3, FALSE) -> L'agent peut utiliser son compte personnel de formation. | AE10: DCE_I_020 | AF10: =VLOOKUP(AE10,'Axe 2 Règles de gestion'!$D$2:$F$40,3, FALSE) -> La décision de refus d'une autorisation d'absence pour suivre une action de préparation à un concours administratif est soumise à la consultation de la commission consultative paritaire. | AG10: DCE_I_013 | AH10: =VLOOKUP(AG10,'Axe 2 Règles de gestion'!$D$2:$F$40,3, FALSE) -> L'agent peut demander une décharge de service si la formation se déroule pendant son temps de service. | AI10: DCE_I_015 | AJ10: =VLOOKUP(AI10,'Axe 2 Règles de gestion'!$D$2:$F$40,3, FALSE) -> Toute demande de décharge inférieure ou égale à 5 journées de service à temps complet pour une année donnée est accordée de droit. | AK10: DCE_I_017 | AL10: =VLOOKUP(AK10,'Axe 2 Règles de gestion'!$D$2:$F$40,3, FALSE) -> L'administration peut reporter la demande de décharge au maximum 2 fois dans l'intérêt du fonctionnement du service. | AM10: DCE_I_011 | AN10: =VLOOKUP(AM10,'Axe 2 Règles de gestion'!$D$2:$F$40,3, FALSE) -> L'agent peut demander à bénéficier d'un congé de formation professionnelle. | AO10: DCE_I_019 | AP10: =VLOOKUP(AO10,'Axe 2 Règles de gestion'!$D$2:$F$40,3, FALSE) -> Les agents ayant bénéficié de décharges de service ne peuvent prétendre au congé de formation dans les 12 mois suivant la fin de la période au cours de laquelle les décharges leur ont été consenties. | AQ10: DCE_I_025 | AR10: =VLOOKUP(AQ10,'Axe 2 Règles de gestion'!$D$2:$F$40,3, FALSE) -> L'agent bénéficiant d'un accès prioritaire à la formation de préparation d'examen ou concours dans des conditions définies règlementairement doit transmettre à l'administration les attestations d'assiduité établies par l'organisme de formation. | AS10: DCE_I_003 | AT10: =VLOOKUP(AS10,'Axe 2 Règles de gestion'!$D$2:$F$40,3, FALSE) -> L'agent qui n'a pas été admis, après avoir participé aux épreuves d'un examen ou concours auquel destinait l'action de préparation qu'il a suivie, peut bénéficier une seconde fois d'autorisations d'absence pour suivre la même action. | AU10: DCE_I_004 | AV10: =VLOOKUP(AU10,'Axe 2 Règles de gestion'!$D$2:$F$40,3, FALSE) -> L'agent ne peut bénéficier d'aucune autorisation d'absence pour suivre une nouvelle formation de même nature dans les 2 ans suivant la fin de cette seconde action de préparation. | AW10: DCE_D_002 | AX10: =VLOOKUP(AW10,'Axe 2 Règles de gestion'!$D$2:$F$40,3, FALSE) -> L'agent doit être en position d'activité ou de congé parental. | AY10: FOR_C_002 | AZ10: =VLOOKUP(AY10,'Axe 2 Règles de gestion'!$D$2:$F$40,3, FALSE) -> La date de début de la formation doit être postérieure ou égale à la date de début du lien juridique. | BA10: FOR_C_003 | BB10: =VLOOKUP(BA10,'Axe 2 Règles de gestion'!$D$2:$F$40,3, FALSE) -> La date de début de la formation doit être antérieure ou égale à la date de fin de la formation. | BC10: FOR_C_004 | BD10: =VLOOKUP(BC10,'Axe 2 Règles de gestion'!$D$2:$F$40,3, FALSE) -> La date de fin de formation doit être antérieure ou égale à la date limite de départ à la retraite. | BE10: FOR_C_005 | BF10: =VLOOKUP(BE10,'Axe 2 Règles de gestion'!$D$2:$F$40,3, FALSE) -> La date de fin de la formation doit être antérieure ou égale à la date limite de fin réelle ou prévisionnelle du lien juridique.
A11: 22.10.00 | B11: M | C11: 44963.675 | D11: D0009 | E11: Formation | F11: S0143 | G11: Préparation aux concours ou examens | H11: E0809 | I11: Préparation aux concours ou examens | J11: Type de la formation demandée saisi égal 'Préparation aux concours ou examens' | K11: P_ACF_TYDFOR [Saisi] = 'F16' | L11: T2004 | M11: Préparation aux concours ou examens - Fin | N11: Modification | Q11: Contractuel | R11: P0003 | S11: N | T11: Général | U11: Passant | V11: 40725 | W11: 44766 | X11: FOR_C_003 ET FOR_C_004 ET FOR_C_005 | AY11: FOR_C_003 | AZ11: =VLOOKUP(AY11,'Axe 2 Règles de gestion'!$D$2:$F$40,3, FALSE) -> La date de début de la formation doit être antérieure ou égale à la date de fin de la formation. | BA11: FOR_C_004 | BB11: =VLOOKUP(BA11,'Axe 2 Règles de gestion'!$D$2:$F$40,3, FALSE) -> La date de fin de formation doit être antérieure ou égale à la date limite de départ à la retraite. | BC11: FOR_C_005 | BD11: =VLOOKUP(BC11,'Axe 2 Règles de gestion'!$D$2:$F$40,3, FALSE) -> La date de fin de la formation doit être antérieure ou égale à la date limite de fin réelle ou prévisionnelle du lien juridique.
A12: 22.10.00 | B12: A | C12: 44963.675 | D12: D0009 | E12: Formation | F12: S0143 | G12: Préparation aux concours ou examens | H12: E0809 | I12: Préparation aux concours ou examens | J12: Type de la formation demandée saisi égal 'Préparation aux concours ou examens' | K12: P_ACF_TYDFOR [Saisi] = 'F16' | L12: T2004 | M12: Préparation aux concours ou examens - Fin | N12: Modification | Q12: Contractuel | R12: P0003 | S12: N | T12: Général | U12: Passant | V12: 44767 | X12: DCE_I_026 ET FOR_C_003 ET FOR_C_004 ET FOR_C_005 | Y12: DCE_I_026 | Z12: =VLOOKUP(Y12,'Axe 2 Règles de gestion'!$D$2:$F$40,3, FALSE) -> L'agent bénéficiant d'un accès prioritaire à la formation en perd le bénéfice s'il arrête, sans motif légitime, de la suivre. | AY12: FOR_C_003 | AZ12: =VLOOKUP(AY12,'Axe 2 Règles de gestion'!$D$2:$F$40,3, FALSE) -> La date de début de la formation doit être antérieure ou égale à la date de fin de la formation. | BA12: FOR_C_004 | BB12: =VLOOKUP(BA12,'Axe 2 Règles de gestion'!$D$2:$F$40,3, FALSE) -> La date de fin de formation doit être antérieure ou égale à la date limite de départ à la retraite. | BC12: FOR_C_005 | BD12: =VLOOKUP(BC12,'Axe 2 Règles de gestion'!$D$2:$F$40,3, FALSE) -> La date de fin de la formation doit être antérieure ou égale à la date limite de fin réelle ou prévisionnelle du lien juridique.
A13: 20.00.00 | B13: A | C13: 43895.663 | D13: D0009 | E13: Formation | F13: S0143 | G13: Préparation aux concours ou examens | H13: E0809 | I13: Préparation aux concours ou examens | J13: Type de la formation demandée saisi égal 'Préparation aux concours ou examens' | K13: P_ACF_TYDFOR [Saisi] = 'F16' | L13: T2003 | M13: Préparation aux concours ou examens - Demande | N13: Création | Q13: Stagiaire ou auditeur ou élève | R13: P0004 | S13: S | T13: Général | U13: Passant | V13: 40725 | W13: 42865 | X13: DCE_I_001 ET DCE_I_007 ET DCE_I_010 ET DCE_I_012 ET DCE_I_014 ET DCE_I_016 ET DCE_D_001 ET FOR_C_001 ET FOR_C_003 ET FOR_C_004 | Y13: DCE_I_001 | Z13: =VLOOKUP(Y13,'Axe 2 Règles de gestion'!$D$2:$F$40,3, FALSE) -> L'agent doit formuler une demande. | AA13: DCE_I_007 | AB13: =VLOOKUP(AA13,'Axe 2 Règles de gestion'!$D$2:$F$40,3, FALSE) -> L'accord de l'administration est de droit pour l'agent en congé parental n'ayant bénéficié d'aucune action de formation de préparation d'examen ou concours au cours des 3 années antérieures, dans la limite des crédits disponibles. | AC13: DCE_I_010 | AD13: =VLOOKUP(AC13,'Axe 2 Règles de gestion'!$D$2:$F$40,3, FALSE) -> L'agent peut demander à bénéficier d'un congé de formation professionnelle. | AE13: DCE_I_012 | AF13: =VLOOKUP(AE13,'Axe 2 Règles de gestion'!$D$2:$F$40,3, FALSE) -> L'agent peut demander une décharge de service si la formation se déroule pendant son temps de service. | AG13: DCE_I_014 | AH13: =VLOOKUP(AG13,'Axe 2 Règles de gestion'!$D$2:$F$40,3, FALSE) -> Toute demande de décharge inférieure ou égale à 5 journées de service à temps complet pour une année donnée est accordée de droit. | AI13: DCE_I_016 | AJ13: =VLOOKUP(AI13,'Axe 2 Règles de gestion'!$D$2:$F$40,3, FALSE) -> L'administration peut reporter la demande de décharge au maximum 2 fois dans l'intérêt du fonctionnement du service. | AW13: DCE_D_001 | AX13: =VLOOKUP(AW13,'Axe 2 Règles de gestion'!$D$2:$F$40,3, FALSE) -> L'agent doit être en position d'activité ou de congé parental. | AY13: FOR_C_001 | AZ13: =VLOOKUP(AY13,'Axe 2 Règles de gestion'!$D$2:$F$40,3, FALSE) -> La date de début de la formation doit être postérieure ou égale à la date de recrutement dans la FPE ou dans la carrière militaire. | BA13: FOR_C_003 | BB13: =VLOOKUP(BA13,'Axe 2 Règles de gestion'!$D$2:$F$40,3, FALSE) -> La date de début de la formation doit être antérieure ou égale à la date de fin de la formation. | BC13: FOR_C_004 | BD13: =VLOOKUP(BC13,'Axe 2 Règles de gestion'!$D$2:$F$40,3, FALSE) -> La date de fin de formation doit être antérieure ou égale à la date limite de départ à la retraite.
A14: 22.10.00 | B14: M | C14: 44963.672 | D14: D0009 | E14: Formation | F14: S0143 | G14: Préparation aux concours ou examens | H14: E0809 | I14: Préparation aux concours ou examens | J14: Type de la formation demandée saisi égal 'Préparation aux concours ou examens' | K14: P_ACF_TYDFOR [Saisi] = 'F16' | L14: T2003 | M14: Préparation aux concours ou examens - Demande | N14: Création | Q14: Stagiaire ou auditeur ou élève | R14: P0004 | S14: S | T14: Général | U14: Passant | V14: 42866 | W14: 44766 | X14: DCE_I_001 ET DCE_I_007 ET DCE_I_008 ET DCE_I_010 ET DCE_I_012 ET DCE_I_014 ET DCE_I_016 ET DCE_D_001 ET FOR_C_001 ET FOR_C_003 ET FOR_C_004 | Y14: DCE_I_001 | Z14: =VLOOKUP(Y14,'Axe 2 Règles de gestion'!$D$2:$F$40,3, FALSE) -> L'agent doit formuler une demande. | AA14: DCE_I_007 | AB14: =VLOOKUP(AA14,'Axe 2 Règles de gestion'!$D$2:$F$40,3, FALSE) -> L'accord de l'administration est de droit pour l'agent en congé parental n'ayant bénéficié d'aucune action de formation de préparation d'examen ou concours au cours des 3 années antérieures, dans la limite des crédits disponibles. | AC14: DCE_I_008 | AD14: =VLOOKUP(AC14,'Axe 2 Règles de gestion'!$D$2:$F$40,3, FALSE) -> L'agent peut utiliser son compte personnel de formation. | AE14: DCE_I_010 | AF14: =VLOOKUP(AE14,'Axe 2 Règles de gestion'!$D$2:$F$40,3, FALSE) -> L'agent peut demander à bénéficier d'un congé de formation professionnelle. | AG14: DCE_I_012 | AH14: =VLOOKUP(AG14,'Axe 2 Règles de gestion'!$D$2:$F$40,3, FALSE) -> L'agent peut demander une décharge de service si la formation se déroule pendant son temps de service. | AI14: DCE_I_014 | AJ14: =VLOOKUP(AI14,'Axe 2 Règles de gestion'!$D$2:$F$40,3, FALSE) -> Toute demande de décharge inférieure ou égale à 5 journées de service à temps complet pour une année donnée est accordée de droit. | AK14: DCE_I_016 | AL14: =VLOOKUP(AK14,'Axe 2 Règles de gestion'!$D$2:$F$40,3, FALSE) -> L'administration peut reporter la demande de décharge au maximum 2 fois dans l'intérêt du fonctionnement du service. | AW14: DCE_D_001 | AX14: =VLOOKUP(AW14,'Axe 2 Règles de gestion'!$D$2:$F$40,3, FALSE) -> L'agent doit être en position d'activité ou de congé parental. | AY14: FOR_C_001 | AZ14: =VLOOKUP(AY14,'Axe 2 Règles de gestion'!$D$2:$F$40,3, FALSE) -> La date de début de la formation doit être postérieure ou égale à la date de recrutement dans la FPE ou dans la carrière militaire. | BA14: FOR_C_003 | BB14: =VLOOKUP(BA14,'Axe 2 Règles de gestion'!$D$2:$F$40,3, FALSE) -> La date de début de la formation doit être antérieure ou égale à la date de fin de la formation. | BC14: FOR_C_004 | BD14: =VLOOKUP(BC14,'Axe 2 Règles de gestion'!$D$2:$F$40,3, FALSE) -> La date de fin de formation doit être antérieure ou égale à la date limite de départ à la retraite.
A15: 22.10.00 | B15: A | C15: 44963.674 | D15: D0009 | E15: Formation | F15: S0143 | G15: Préparation aux concours ou examens | H15: E0809 | I15: Préparation aux concours ou examens | J15: Type de la formation demandée saisi égal 'Préparation aux concours ou examens' | K15: P_ACF_TYDFOR [Saisi] = 'F16' | L15: T2003 | M15: Préparation aux concours ou examens - Demande | N15: Création | Q15: Stagiaire ou auditeur ou élève | R15: P0004 | S15: S | T15: Général | U15: Passant | V15: 44767 | X15: DCE_I_001 ET DCE_I_007 ET DCE_I_008 ET DCE_I_010 ET DCE_I_012 ET DCE_I_014 ET DCE_I_016 ET DCE_I_023 ET DCE_D_001 ET FOR_C_001 ET FOR_C_003 ET FOR_C_004 | Y15: DCE_I_001 | Z15: =VLOOKUP(Y15,'Axe 2 Règles de gestion'!$D$2:$F$40,3, FALSE) -> L'agent doit formuler une demande. | AA15: DCE_I_007 | AB15: =VLOOKUP(AA15,'Axe 2 Règles de gestion'!$D$2:$F$40,3, FALSE) -> L'accord de l'administration est de droit pour l'agent en congé parental n'ayant bénéficié d'aucune action de formation de préparation d'examen ou concours au cours des 3 années antérieures, dans la limite des crédits disponibles. | AC15: DCE_I_008 | AD15: =VLOOKUP(AC15,'Axe 2 Règles de gestion'!$D$2:$F$40,3, FALSE) -> L'agent peut utiliser son compte personnel de formation. | AE15: DCE_I_010 | AF15: =VLOOKUP(AE15,'Axe 2 Règles de gestion'!$D$2:$F$40,3, FALSE) -> L'agent peut demander à bénéficier d'un congé de formation professionnelle. | AG15: DCE_I_012 | AH15: =VLOOKUP(AG15,'Axe 2 Règles de gestion'!$D$2:$F$40,3, FALSE) -> L'agent peut demander une décharge de service si la formation se déroule pendant son temps de service. | AI15: DCE_I_014 | AJ15: =VLOOKUP(AI15,'Axe 2 Règles de gestion'!$D$2:$F$40,3, FALSE) -> Toute demande de décharge inférieure ou égale à 5 journées de service à temps complet pour une année donnée est accordée de droit. | AK15: DCE_I_016 | AL15: =VLOOKUP(AK15,'Axe 2 Règles de gestion'!$D$2:$F$40,3, FALSE) -> L'administration peut reporter la demande de décharge au maximum 2 fois dans l'intérêt du fonctionnement du service. | AM15: DCE_I_023 | AN15: =VLOOKUP(AM15,'Axe 2 Règles de gestion'!$D$2:$F$40,3, FALSE) -> L'agent bénéficiant d'un accès prioritaire à la formation de préparation d'examen ou concours dans des conditions définies règlementairement doit transmettre à l'administration les attestations d'assiduité établies par l'organisme de formation. | AW15: DCE_D_001 | AX15: =VLOOKUP(AW15,'Axe 2 Règles de gestion'!$D$2:$F$40,3, FALSE) -> L'agent doit être en position d'activité ou de congé parental. | AY15: FOR_C_001 | AZ15: =VLOOKUP(AY15,'Axe 2 Règles de gestion'!$D$2:$F$40,3, FALSE) -> La date de début de la formation doit être postérieure ou égale à la date de recrutement dans la FPE ou dans la carrière militaire. | BA15: FOR_C_003 | BB15: =VLOOKUP(BA15,'Axe 2 Règles de gestion'!$D$2:$F$40,3, FALSE) -> La date de début de la formation doit être antérieure ou égale à la date de fin de la formation. | BC15: FOR_C_004 | BD15: =VLOOKUP(BC15,'Axe 2 Règles de gestion'!$D$2:$F$40,3, FALSE) -> La date de fin de formation doit être antérieure ou égale à la date limite de départ à la retraite.
A16: 22.10.00 | B16: M | C16: 44963.676 | D16: D0009 | E16: Formation | F16: S0143 | G16: Préparation aux concours ou examens | H16: E0809 | I16: Préparation aux concours ou examens | J16: Type de la formation demandée saisi égal 'Préparation aux concours ou examens' | K16: P_ACF_TYDFOR [Saisi] = 'F16' | L16: T2004 | M16: Préparation aux concours ou examens - Fin | N16: Modification | Q16: Stagiaire ou auditeur ou élève | R16: P0004 | S16: S | T16: Général | U16: Passant | V16: 40725 | W16: 44766 | X16: FOR_C_003 ET FOR_C_004 | AY16: FOR_C_003 | AZ16: =VLOOKUP(AY16,'Axe 2 Règles de gestion'!$D$2:$F$40,3, FALSE) -> La date de début de la formation doit être antérieure ou égale à la date de fin de la formation. | BA16: FOR_C_004 | BB16: =VLOOKUP(BA16,'Axe 2 Règles de gestion'!$D$2:$F$40,3, FALSE) -> La date de fin de formation doit être antérieure ou égale à la date limite de départ à la retraite.
A17: 22.10.00 | B17: A | C17: 44963.676 | D17: D0009 | E17: Formation | F17: S0143 | G17: Préparation aux concours ou examens | H17: E0809 | I17: Préparation aux concours ou examens | J17: Type de la formation demandée saisi égal 'Préparation aux concours ou examens' | K17: P_ACF_TYDFOR [Saisi] = 'F16' | L17: T2004 | M17: Préparation aux concours ou examens - Fin | N17: Modification | Q17: Stagiaire ou auditeur ou élève | R17: P0004 | S17: S | T17: Général | U17: Passant | V17: 44767 | X17: DCE_I_024 ET FOR_C_003 ET FOR_C_004 | Y17: DCE_I_024 | Z17: =VLOOKUP(Y17,'Axe 2 Règles de gestion'!$D$2:$F$40,3, FALSE) -> L'agent bénéficiant d'un accès prioritaire à la formation en perd le bénéfice s'il arrête, sans motif légitime, de la suivre. | AY17: FOR_C_003 | AZ17: =VLOOKUP(AY17,'Axe 2 Règles de gestion'!$D$2:$F$40,3, FALSE) -> La date de début de la formation doit être antérieure ou égale à la date de fin de la formation. | BA17: FOR_C_004 | BB17: =VLOOKUP(BA17,'Axe 2 Règles de gestion'!$D$2:$F$40,3, FALSE) -> La date de fin de formation doit être antérieure ou égale à la date limite de départ à la retraite.
A18: 20.00.00 | B18: A | C18: 43895.669 | D18: D0009 | E18: Formation | F18: S0143 | G18: Préparation aux concours ou examens | H18: E0809 | I18: Préparation aux concours ou examens | J18: Type de la formation demandée saisi égal 'Préparation aux concours ou examens' | K18: P_ACF_TYDFOR [Saisi] = 'F16' | L18: T2003 | M18: Préparation aux concours ou examens - Demande | N18: Création | Q18: Ouvrier d'état | R18: P0005 | S18: O | T18: Général | U18: Passant | V18: 40725 | W18: 42865 | X18: DCE_I_002 ET DCE_I_013 ET DCE_I_015 ET DCE_I_017 ET DCE_I_011 ET DCE_I_019 ET DCE_D_002 ET FOR_C_002 ET FOR_C_003 ET FOR_C_004 ET FOR_C_005 | Y18: DCE_I_002 | Z18: =VLOOKUP(Y18,'Axe 2 Règles de gestion'!$D$2:$F$40,3, FALSE) -> L'agent doit remplir ou être susceptible de remplir les conditions requises pour se présenter à ces examens, concours ou sélections à la fin du cycle de formation. | AA18: DCE_I_013 | AB18: =VLOOKUP(AA18,'Axe 2 Règles de gestion'!$D$2:$F$40,3, FALSE) -> L'agent peut demander une décharge de service si la formation se déroule pendant son temps de service. | AC18: DCE_I_015 | AD18: =VLOOKUP(AC18,'Axe 2 Règles de gestion'!$D$2:$F$40,3, FALSE) -> Toute demande de décharge inférieure ou égale à 5 journées de service à temps complet pour une année donnée est accordée de droit. | AE18: DCE_I_017 | AF18: =VLOOKUP(AE18,'Axe 2 Règles de gestion'!$D$2:$F$40,3, FALSE) -> L'administration peut reporter la demande de décharge au maximum 2 fois dans l'intérêt du fonctionnement du service. | AG18: DCE_I_011 | AH18: =VLOOKUP(AG18,'Axe 2 Règles de gestion'!$D$2:$F$40,3, FALSE) -> L'agent peut demander à bénéficier d'un congé de formation professionnelle. | AI18: DCE_I_019 | AJ18: =VLOOKUP(AI18,'Axe 2 Règles de gestion'!$D$2:$F$40,3, FALSE) -> Les agents ayant bénéficié de décharges de service ne peuvent prétendre au congé de formation dans les 12 mois suivant la fin de la période au cours de laquelle les décharges leur ont été consenties. | AW18: DCE_D_002 | AX18: =VLOOKUP(AW18,'Axe 2 Règles de gestion'!$D$2:$F$40,3, FALSE) -> L'agent doit être en position d'activité ou de congé parental. | AY18: FOR_C_002 | AZ18: =VLOOKUP(AY18,'Axe 2 Règles de gestion'!$D$2:$F$40,3, FALSE) -> La date de début de la formation doit être postérieure ou égale à la date de début du lien juridique. | BA18: FOR_C_003 | BB18: =VLOOKUP(BA18,'Axe 2 Règles de gestion'!$D$2:$F$40,3, FALSE) -> La date de début de la formation doit être antérieure ou égale à la date de fin de la formation. | BC18: FOR_C_004 | BD18: =VLOOKUP(BC18,'Axe 2 Règles de gestion'!$D$2:$F$40,3, FALSE) -> La date de fin de formation doit être antérieure ou égale à la date limite de départ à la retraite. | BE18: FOR_C_005 | BF18: =VLOOKUP(BE18,'Axe 2 Règles de gestion'!$D$2:$F$40,3, FALSE) -> La date de fin de la formation doit être antérieure ou égale à la date limite de fin réelle ou prévisionnelle du lien juridique.
A19: 22.10.00 | B19: M | C19: 44963.672 | D19: D0009 | E19: Formation | F19: S0143 | G19: Préparation aux concours ou examens | H19: E0809 | I19: Préparation aux concours ou examens | J19: Type de la formation demandée saisi égal 'Préparation aux concours ou examens' | K19: P_ACF_TYDFOR [Saisi] = 'F16' | L19: T2003 | M19: Préparation aux concours ou examens - Demande | N19: Création | Q19: Ouvrier d'état | R19: P0005 | S19: O | T19: Général | U19: Passant | V19: 42866 | W19: 44766 | X19: DCE_I_002 ET DCE_I_009 ET DCE_I_013 ET DCE_I_015 ET DCE_I_017 ET DCE_I_011 ET DCE_I_019 ET DCE_D_002 ET FOR_C_002 ET FOR_C_003 ET FOR_C_004 ET FOR_C_005 | Y19: DCE_I_002 | Z19: =VLOOKUP(Y19,'Axe 2 Règles de gestion'!$D$2:$F$40,3, FALSE) -> L'agent doit remplir ou être susceptible de remplir les conditions requises pour se présenter à ces examens, concours ou sélections à la fin du cycle de formation. | AA19: DCE_I_009 | AB19: =VLOOKUP(AA19,'Axe 2 Règles de gestion'!$D$2:$F$40,3, FALSE) -> L'agent peut utiliser son compte personnel de formation. | AC19: DCE_I_013 | AD19: =VLOOKUP(AC19,'Axe 2 Règles de gestion'!$D$2:$F$40,3, FALSE) -> L'agent peut demander une décharge de service si la formation se déroule pendant son temps de service. | AE19: DCE_I_015 | AF19: =VLOOKUP(AE19,'Axe 2 Règles de gestion'!$D$2:$F$40,3, FALSE) -> Toute demande de décharge inférieure ou égale à 5 journées de service à temps complet pour une année donnée est accordée de droit. | AG19: DCE_I_017 | AH19: =VLOOKUP(AG19,'Axe 2 Règles de gestion'!$D$2:$F$40,3, FALSE) -> L'administration peut reporter la demande de décharge au maximum 2 fois dans l'intérêt du fonctionnement du service. | AI19: DCE_I_011 | AJ19: =VLOOKUP(AI19,'Axe 2 Règles de gestion'!$D$2:$F$40,3, FALSE) -> L'agent peut demander à bénéficier d'un congé de formation professionnelle. | AK19: DCE_I_019 | AL19: =VLOOKUP(AK19,'Axe 2 Règles de gestion'!$D$2:$F$40,3, FALSE) -> Les agents ayant bénéficié de décharges de service ne peuvent prétendre au congé de formation dans les 12 mois suivant la fin de la période au cours de laquelle les décharges leur ont été consenties. | AW19: DCE_D_002 | AX19: =VLOOKUP(AW19,'Axe 2 Règles de gestion'!$D$2:$F$40,3, FALSE) -> L'agent doit être en position d'activité ou de congé parental. | AY19: FOR_C_002 | AZ19: =VLOOKUP(AY19,'Axe 2 Règles de gestion'!$D$2:$F$40,3, FALSE) -> La date de début de la formation doit être postérieure ou égale à la date de début du lien juridique. | BA19: FOR_C_003 | BB19: =VLOOKUP(BA19,'Axe 2 Règles de gestion'!$D$2:$F$40,3, FALSE) -> La date de début de la formation doit être antérieure ou égale à la date de fin de la formation. | BC19: FOR_C_004 | BD19: =VLOOKUP(BC19,'Axe 2 Règles de gestion'!$D$2:$F$40,3, FALSE) -> La date de fin de formation doit être antérieure ou égale à la date limite de départ à la retraite. | BE19: FOR_C_005 | BF19: =VLOOKUP(BE19,'Axe 2 Règles de gestion'!$D$2:$F$40,3, FALSE) -> La date de fin de la formation doit être antérieure ou égale à la date limite de fin réelle ou prévisionnelle du lien juridique.
A20: 25.10.00 | B20: M | C20: 45995.649 | D20: D0009 | E20: Formation | F20: S0143 | G20: Préparation aux concours ou examens | H20: E0809 | I20: Préparation aux concours ou examens | J20: Type de la formation demandée saisi égal 'Préparation aux concours ou examens' | K20: P_ACF_TYDFOR [Saisi] = 'F16' | L20: T2003 | M20: Préparation aux concours ou examens - Demande | N20: Création | Q20: Ouvrier d'état | R20: P0005 | S20: O | T20: Général | U20: Passant | V20: 44767 | X20: DCE_I_002 ET DCE_I_009 ET DCE_I_013 ET DCE_I_015 ET DCE_I_017 ET DCE_I_011 ET DCE_I_019 ET DCE_I_025 ET DCE_I_003 ET DCE_I_004 ET DCE_D_002 ET FOR_C_002 ET FOR_C_003 ET FOR_C_004 ET FOR_C_005 | Y20: DCE_I_002 | Z20: =VLOOKUP(Y20,'Axe 2 Règles de gestion'!$D$2:$F$40,3, FALSE) -> L'agent doit remplir ou être susceptible de remplir les conditions requises pour se présenter à ces examens, concours ou sélections à la fin du cycle de formation. | AA20: DCE_I_009 | AB20: =VLOOKUP(AA20,'Axe 2 Règles de gestion'!$D$2:$F$40,3, FALSE) -> L'agent peut utiliser son compte personnel de formation. | AC20: DCE_I_013 | AD20: =VLOOKUP(AC20,'Axe 2 Règles de gestion'!$D$2:$F$40,3, FALSE) -> L'agent peut demander une décharge de service si la formation se déroule pendant son temps de service. | AE20: DCE_I_015 | AF20: =VLOOKUP(AE20,'Axe 2 Règles de gestion'!$D$2:$F$40,3, FALSE) -> Toute demande de décharge inférieure ou égale à 5 journées de service à temps complet pour une année donnée est accordée de droit. | AG20: DCE_I_017 | AH20: =VLOOKUP(AG20,'Axe 2 Règles de gestion'!$D$2:$F$40,3, FALSE) -> L'administration peut reporter la demande de décharge au maximum 2 fois dans l'intérêt du fonctionnement du service. | AI20: DCE_I_011 | AJ20: =VLOOKUP(AI20,'Axe 2 Règles de gestion'!$D$2:$F$40,3, FALSE) -> L'agent peut demander à bénéficier d'un congé de formation professionnelle. | AK20: DCE_I_019 | AL20: =VLOOKUP(AK20,'Axe 2 Règles de gestion'!$D$2:$F$40,3, FALSE) -> Les agents ayant bénéficié de décharges de service ne peuvent prétendre au congé de formation dans les 12 mois suivant la fin de la période au cours de laquelle les décharges leur ont été consenties. | AM20: DCE_I_025 | AN20: =VLOOKUP(AM20,'Axe 2 Règles de gestion'!$D$2:$F$40,3, FALSE) -> L'agent bénéficiant d'un accès prioritaire à la formation de préparation d'examen ou concours dans des conditions définies règlementairement doit transmettre à l'administration les attestations d'assiduité établies par l'organisme de formation. | AO20: DCE_I_003 | AP20: =VLOOKUP(AO20,'Axe 2 Règles de gestion'!$D$2:$F$40,3, FALSE) -> L'agent qui n'a pas été admis, après avoir participé aux épreuves d'un examen ou concours auquel destinait l'action de préparation qu'il a suivie, peut bénéficier une seconde fois d'autorisations d'absence pour suivre la même action. | AQ20: DCE_I_004 | AR20: =VLOOKUP(AQ20,'Axe 2 Règles de gestion'!$D$2:$F$40,3, FALSE) -> L'agent ne peut bénéficier d'aucune autorisation d'absence pour suivre une nouvelle formation de même nature dans les 2 ans suivant la fin de cette seconde action de préparation. | AW20: DCE_D_002 | AX20: =VLOOKUP(AW20,'Axe 2 Règles de gestion'!$D$2:$F$40,3, FALSE) -> L'agent doit être en position d'activité ou de congé parental. | AY20: FOR_C_002 | AZ20: =VLOOKUP(AY20,'Axe 2 Règles de gestion'!$D$2:$F$40,3, FALSE) -> La date de début de la formation doit être postérieure ou égale à la date de début du lien juridique. | BA20: FOR_C_003 | BB20: =VLOOKUP(BA20,'Axe 2 Règles de gestion'!$D$2:$F$40,3, FALSE) -> La date de début de la formation doit être antérieure ou égale à la date de fin de la formation. | BC20: FOR_C_004 | BD20: =VLOOKUP(BC20,'Axe 2 Règles de gestion'!$D$2:$F$40,3, FALSE) -> La date de fin de formation doit être antérieure ou égale à la date limite de départ à la retraite. | BE20: FOR_C_005 | BF20: =VLOOKUP(BE20,'Axe 2 Règles de gestion'!$D$2:$F$40,3, FALSE) -> La date de fin de la formation doit être antérieure ou égale à la date limite de fin réelle ou prévisionnelle du lien juridique.
A21: 22.10.00 | B21: M | C21: 44963.676 | D21: D0009 | E21: Formation | F21: S0143 | G21: Préparation aux concours ou examens | H21: E0809 | I21: Préparation aux concours ou examens | J21: Type de la formation demandée saisi égal 'Préparation aux concours ou examens' | K21: P_ACF_TYDFOR [Saisi] = 'F16' | L21: T2004 | M21: Préparation aux concours ou examens - Fin | N21: Modification | Q21: Ouvrier d'état | R21: P0005 | S21: O | T21: Général | U21: Passant | V21: 40725 | W21: 44766 | X21: FOR_C_003 ET FOR_C_004 ET FOR_C_005 | AY21: FOR_C_003 | AZ21: =VLOOKUP(AY21,'Axe 2 Règles de gestion'!$D$2:$F$40,3, FALSE) -> La date de début de la formation doit être antérieure ou égale à la date de fin de la formation. | BA21: FOR_C_004 | BB21: =VLOOKUP(BA21,'Axe 2 Règles de gestion'!$D$2:$F$40,3, FALSE) -> La date de fin de formation doit être antérieure ou égale à la date limite de départ à la retraite. | BC21: FOR_C_005 | BD21: =VLOOKUP(BC21,'Axe 2 Règles de gestion'!$D$2:$F$40,3, FALSE) -> La date de fin de la formation doit être antérieure ou égale à la date limite de fin réelle ou prévisionnelle du lien juridique.
A22: 22.10.00 | B22: A | C22: 44963.676 | D22: D0009 | E22: Formation | F22: S0143 | G22: Préparation aux concours ou examens | H22: E0809 | I22: Préparation aux concours ou examens | J22: Type de la formation demandée saisi égal 'Préparation aux concours ou examens' | K22: P_ACF_TYDFOR [Saisi] = 'F16' | L22: T2004 | M22: Préparation aux concours ou examens - Fin | N22: Modification | Q22: Ouvrier d'état | R22: P0005 | S22: O | T22: Général | U22: Passant | V22: 44767 | X22: DCE_I_026 ET FOR_C_003 ET FOR_C_004 ET FOR_C_005 | Y22: DCE_I_026 | Z22: =VLOOKUP(Y22,'Axe 2 Règles de gestion'!$D$2:$F$40,3, FALSE) -> L'agent bénéficiant d'un accès prioritaire à la formation en perd le bénéfice s'il arrête, sans motif légitime, de la suivre. | AY22: FOR_C_003 | AZ22: =VLOOKUP(AY22,'Axe 2 Règles de gestion'!$D$2:$F$40,3, FALSE) -> La date de début de la formation doit être antérieure ou égale à la date de fin de la formation. | BA22: FOR_C_004 | BB22: =VLOOKUP(BA22,'Axe 2 Règles de gestion'!$D$2:$F$40,3, FALSE) -> La date de fin de formation doit être antérieure ou égale à la date limite de départ à la retraite. | BC22: FOR_C_005 | BD22: =VLOOKUP(BC22,'Axe 2 Règles de gestion'!$D$2:$F$40,3, FALSE) -> La date de fin de la formation doit être antérieure ou égale à la date limite de fin réelle ou prévisionnelle du lien juridique.
A23: 20.00.00 | B23: A | C23: 43896.395 | D23: D0009 | E23: Formation | F23: S0143 | G23: Préparation aux concours ou examens | H23: E0809 | I23: Préparation aux concours ou examens | J23: Type de la formation demandée saisi égal 'Préparation aux concours ou examens' | K23: P_ACF_TYDFOR [Saisi] = 'F16' | L23: T2003 | M23: Préparation aux concours ou examens - Demande | N23: Création | Q23: Magistrat de l'ordre judiciaire | R23: P0007 | S23: T | T23: Particulier | U23: Exclu | V23: 40725
A24: 20.00.00 | B24: A | C24: 43896.426 | D24: D0009 | E24: Formation | F24: S0143 | G24: Préparation aux concours ou examens | H24: E0809 | I24: Préparation aux concours ou examens | J24: Type de la formation demandée saisi égal 'Préparation aux concours ou examens' | K24: P_ACF_TYDFOR [Saisi] = 'F16' | L24: T2004 | M24: Préparation aux concours ou examens - Fin | N24: Modification | Q24: Magistrat de l'ordre judiciaire | R24: P0007 | S24: T | T24: Particulier | U24: Exclu | V24: 40725
A25: 20.00.00 | B25: A | C25: 43896.395 | D25: D0009 | E25: Formation | F25: S0143 | G25: Préparation aux concours ou examens | H25: E0809 | I25: Préparation aux concours ou examens | J25: Type de la formation demandée saisi égal 'Préparation aux concours ou examens' | K25: P_ACF_TYDFOR [Saisi] = 'F16' | L25: T2003 | M25: Préparation aux concours ou examens - Demande | N25: Création | Q25: Auditeur de justice | R25: P0009 | S25: S | T25: Particulier | U25: Exclu | V25: 40725
A26: 20.00.00 | B26: A | C26: 43896.426 | D26: D0009 | E26: Formation | F26: S0143 | G26: Préparation aux concours ou examens | H26: E0809 | I26: Préparation aux concours ou examens | J26: Type de la formation demandée saisi égal 'Préparation aux concours ou examens' | K26: P_ACF_TYDFOR [Saisi] = 'F16' | L26: T2004 | M26: Préparation aux concours ou examens - Fin | N26: Modification | Q26: Auditeur de justice | R26: P0009 | S26: S | T26: Particulier | U26: Exclu | V26: 40725
A27: 20.00.00 | B27: A | C27: 43896.395 | D27: D0009 | E27: Formation | F27: S0143 | G27: Préparation aux concours ou examens | H27: E0809 | I27: Préparation aux concours ou examens | J27: Type de la formation demandée saisi égal 'Préparation aux concours ou examens' | K27: P_ACF_TYDFOR [Saisi] = 'F16' | L27: T2003 | M27: Préparation aux concours ou examens - Demande | N27: Création | Q27: Conseiller ou avocat général à la Cour de cassation en service extraordinaire | R27: P0046 | S27: N | T27: Particulier | U27: Exclu | V27: 40725
A28: 20.00.00 | B28: A | C28: 43896.426 | D28: D0009 | E28: Formation | F28: S0143 | G28: Préparation aux concours ou examens | H28: E0809 | I28: Préparation aux concours ou examens | J28: Type de la formation demandée saisi égal 'Préparation aux concours ou examens' | K28: P_ACF_TYDFOR [Saisi] = 'F16' | L28: T2004 | M28: Préparation aux concours ou examens - Fin | N28: Modification | Q28: Conseiller ou avocat général à la Cour de cassation en service extraordinaire | R28: P0046 | S28: N | T28: Particulier | U28: Exclu | V28: 40725
A29: 20.00.00 | B29: A | C29: 43896.395 | D29: D0009 | E29: Formation | F29: S0143 | G29: Préparation aux concours ou examens | H29: E0809 | I29: Préparation aux concours ou examens | J29: Type de la formation demandée saisi égal 'Préparation aux concours ou examens' | K29: P_ACF_TYDFOR [Saisi] = 'F16' | L29: T2003 | M29: Préparation aux concours ou examens - Demande | N29: Création | Q29: Personnel civil payé à l'acte ou à la tâche | R29: P0054 | S29: N | T29: Particulier | U29: Exclu | V29: 40725
A30: 20.00.00 | B30: A | C30: 43896.426 | D30: D0009 | E30: Formation | F30: S0143 | G30: Préparation aux concours ou examens | H30: E0809 | I30: Préparation aux concours ou examens | J30: Type de la formation demandée saisi égal 'Préparation aux concours ou examens' | K30: P_ACF_TYDFOR [Saisi] = 'F16' | L30: T2004 | M30: Préparation aux concours ou examens - Fin | N30: Modification | Q30: Personnel civil payé à l'acte ou à la tâche | R30: P0054 | S30: N | T30: Particulier | U30: Exclu | V30: 40725
A31: 20.00.00 | B31: A | C31: 43896.393 | D31: D0009 | E31: Formation | F31: S0143 | G31: Préparation aux concours ou examens | H31: E0809 | I31: Préparation aux concours ou examens | J31: Type de la formation demandée saisi égal 'Préparation aux concours ou examens' | K31: P_ACF_TYDFOR [Saisi] = 'F16' | L31: T2003 | M31: Préparation aux concours ou examens - Demande | N31: Création | Q31: Ouvrier de la défense auxiliaire non affilié ou temporaire non mensualisé | R31: P0182 | S31: O | T31: Particulier | U31: Exclu | V31: 40725
A32: 20.00.00 | B32: A | C32: 43896.425 | D32: D0009 | E32: Formation | F32: S0143 | G32: Préparation aux concours ou examens | H32: E0809 | I32: Préparation aux concours ou examens | J32: Type de la formation demandée saisi égal 'Préparation aux concours ou examens' | K32: P_ACF_TYDFOR [Saisi] = 'F16' | L32: T2004 | M32: Préparation aux concours ou examens - Fin | N32: Modification | Q32: Ouvrier de la défense auxiliaire non affilié ou temporaire non mensualisé | R32: P0182 | S32: O | T32: Particulier | U32: Exclu | V32: 40725
A33: 25.10.00 | B33: M | C33: 45995.654 | D33: D0009 | E33: Formation | F33: S0143 | G33: Préparation aux concours ou examens | H33: E0809 | I33: Préparation aux concours ou examens | J33: Type de la formation demandée saisi égal 'Préparation aux concours ou examens' | K33: P_ACF_TYDFOR [Saisi] = 'F16' | L33: T2003 | M33: Préparation aux concours ou examens - Demande | N33: Création | Q33: Ouvrier des parcs et ateliers confirmé non affilié ou stagiaire | R33: P0185 | S33: O | T33: Particulier | U33: Exclu | V33: 40725 | W33: 45900
