Workbook
Name date_DIADC: 'Mode opératoire'!#REF!
Name notice_DIADC: 'Mode opératoire'!#REF!
Name notice_ENCHN: 'Mode opératoire'!$B$1:$B$4
Name notice_ICA: 'Mode opératoire'!#REF!

Sheet Mode opératoire
B1: MODE OPERATOIRE

Sheet Axe 1 Enchainement des RG
A1: Version | B1: Type de mise à jour | C1: Date de mise à jour | D1: Identifiant Domaine | E1: Libellé du Domaine | F1: Identifiant Sous-domaine | G1: Libellé du Sous-domaine | H1: Identifiant Evénement | I1: Libellé de l'évènement | J1: Libellé condition déclenchement Evènement | K1: Condition déclenchement Evènement | L1: Identifiant type d'évènement | M1: Libellé type d'évènement | N1: Type de mise à jour | O1: Libellé condition déclenchement Type Evènement | P1: Condition déclenchement Type Evènement | Q1: Libellé Population | R1: Codification Population | S1: Typologie de population | T1: Général / Particulier | U1: Passant / Exclu | V1: Date de début | W1: Date de fin | X1: Règles mobilisées | Y1: Identifiant Règle de contrôle intellectuel 1 | Z1: Libellé Règle de contrôle intellectuel 1 | AA1: Identifiant Règle de contrôle intellectuel 2 | AB1: Libellé Règle de contrôle intellectuel 2 | AC1: Identifiant Règle de contrôle intellectuel 3 | AD1: Libellé Règle de contrôle intellectuel 3 | AE1: Identifiant Règle de contrôle intellectuel 4 | AF1: Libellé Règle de contrôle intellectuel 4 | AG1: Identifiant Règle de contrôle intellectuel 5 | AH1: Libellé Règle de contrôle intellectuel 5 | AI1: Identifiant Règle de contrôle intellectuel 6 | AJ1: Libellé Règle de contrôle intellectuel 6 | AK1: Identifiant Règle de contrôle intellectuel 7 | AL1: Libellé Règle de contrôle intellectuel 7 | AM1: Identifiant Règle de contrôle intellectuel 8 | AN1: Libellé Règle de contrôle intellectuel 8 | AO1: Identifiant Règle de contrôle intellectuel 9 | AP1: Libellé Règle de contrôle intellectuel 9 | AQ1: Identifiant Règle de contrôle intellectuel 10 | AR1: Libellé Règle de contrôle intellectuel 10 | AS1: Identifiant Règle de contrôle intellectuel 11 | AT1: Libellé Règle de contrôle intellectuel 11 | AU1: Identifiant Règle de contrôle intellectuel 12 | AV1: Libellé Règle de contrôle intellectuel 12 | AW1: Identifiant Règle de contrôle intellectuel 13 | AX1: Libellé Règle de contrôle intellectuel 13 | AY1: Identifiant Règle de contrôle intellectuel 14 | AZ1: Libellé Règle de contrôle intellectuel 14 | BA1: Identifiant Règle de contrôle intellectuel 15 | BB1: Libellé Règle de contrôle intellectuel 15 | BC1: Identifiant Règle de contrôle intellectuel 16 | BD1: Libellé Règle de contrôle intellectuel 16 | BE1: Identifiant Règle de contrôle intellectuel 17 | BF1: Libellé Règle de contrôle intellectuel 17 | BG1: Identifiant Règle de contrôle intellectuel 18 | BH1: Libellé Règle de contrôle intellectuel 18 | BI1: Identifiant Règle de contrôle intellectuel 19 | BJ1: Libellé Règle de contrôle intellectuel 19 | BK1: Identifiant Règle de contrôle intellectuel 20 | BL1: Libellé Règle de contrôle intellectuel 20 | BM1: Identifiant Règle de contrôle intellectuel 21 | BN1: Libellé Règle de contrôle intellectuel 21 | BO1: Identifiant Règle de contrôle intellectuel 22 | BP1: Libellé Règle de contrôle intellectuel 22 | BQ1: Identifiant Règle de contrôle intellectuel 23 | BR1: Libellé Règle de contrôle intellectuel 23 | BS1: Identifiant Règle de contrôle intellectuel 24 | BT1: Libellé Règle de contrôle intellectuel 24 | BU1: Identifiant Règle de contrôle intellectuel 25 | BV1: Libellé Règle de contrôle intellectuel 25 | BW1: Identifiant Règle de contrôle intellectuel 26 | BX1: Libellé Règle de contrôle intellectuel 26 | BY1: Identifiant Règle de contrôle intellectuel 27 | BZ1: Libellé Règle de contrôle intellectuel 27 | CA1: Identifiant Règle de contrôle intellectuel 28 | CB1: Libellé Règle de contrôle intellectuel 28 | CC1: Identifiant Règle de contrôle intellectuel 29 | CD1: Libellé Règle de contrôle intellectuel 29 | CE1: Identifiant Règle de contrôle intellectuel 30 | CF1: Libellé Règle de contrôle intellectuel 30 | CG1: FIME | CH1: Statut de travail
A2: 20.00.00 | B2: A | C2: 43924.52 | D2: D0009 | E2: Formation | F2: S0147 | G2: Compte personnel d'activité | H2: E0816 | I2: Compte personnel de formation | L2: T2013 | M2: Compte personnel de formation - Demande | N2: Création Modification | Q2: Titulaire ou magistrat | R2: P0001 | S2: T | T2: Général | U2: Passant | V2: 42736 | X2: CPF_I_001 ET CPF_I_002 ET CPF_I_042 ET CPF_I_043 ET CPF_I_005 ET CPF_I_059 ET CPF_I_003 ET CPF_I_045 ET CPF_I_047 ET CPF_I_004 ET CPF_I_063 ET CPF_I_046 ET CPF_I_048 ET CPF_I_049 ET CPF_I_006 ET CPF_I_007 ET CPF_I_008 ET CPF_I_009 ET CPF_I_010 ET CPF_I_050 ET CPF_I_051 ET CPF_I_052 ET CPF_I_018 ET CPF_I_019 ET CPF_I_020 ET CPF_I_044 ET CPF_I_060 ET CPF_I_061 ET CPF_I_026 ET CPF_I_064 | Y2: CPF_I_001 | Z2: =VLOOKUP(Y2,'Axe 2 Règles de gestion'!$D$2:$F$75,3, FALSE) -> L'agent ne peut utiliser son compte personnel de formation que pour accéder à une qualification ou développer ses compétences dans le cadre d'un projet d'évolution professionnelle. | AA2: CPF_I_002 | AB2: =VLOOKUP(AA2,'Axe 2 Règles de gestion'!$D$2:$F$75,3, FALSE) -> L'agent utilise les heures acquises sur son compte pour suivre des actions de formation. | AC2: CPF_I_042 | AD2: =VLOOKUP(AC2,'Axe 2 Règles de gestion'!$D$2:$F$75,3, FALSE) -> La formation ne doit pas avoir pour objet l'adaptation aux fonctions exercées. | AE2: CPF_I_043 | AF2: =VLOOKUP(AE2,'Axe 2 Règles de gestion'!$D$2:$F$75,3, FALSE) -> La formation doit avoir pour objet l'acquisition d'un diplôme, d'un titre, d'un certificat de qualification professionnelle ou le développement des compétences nécessaires à la mise en œuvre du projet d'évolution professionnelle. | AG2: CPF_I_005 | AH2: =VLOOKUP(AG2,'Axe 2 Règles de gestion'!$D$2:$F$75,3, FALSE) -> L'agent doit suivre la formation, en priorité, pendant son temps de travail. | AI2: CPF_I_059 | AJ2: =VLOOKUP(AI2,'Axe 2 Règles de gestion'!$D$2:$F$75,3, FALSE) -> L'agent peut utiliser son compte pour réaliser des heures de formation d'adaptation à l'évolution prévisible des métiers ou de développement des qualifications ou d'acquisition de nouvelles qualifications hors temps de service. | AK2: CPF_I_003 | AL2: =VLOOKUP(AK2,'Axe 2 Règles de gestion'!$D$2:$F$75,3, FALSE) -> L'agent doit faire une demande. | AM2: CPF_I_045 | AN2: =VLOOKUP(AM2,'Axe 2 Règles de gestion'!$D$2:$F$75,3, FALSE) -> L'agent sollicite l'accord écrit de l'administration sur la nature, le calendrier et le financement de la formation souhaitée, en précisant le projet d'évolution professionnelle qui fonde sa demande. | AO2: CPF_I_047 | AP2: =VLOOKUP(AO2,'Axe 2 Règles de gestion'!$D$2:$F$75,3, FALSE) -> L'agent peut bénéficier, préalablement à sa demande, d'un accompagnement afin d'élaborer son projet professionnel et d'identifier les différentes actions nécessaires à sa mise en œuvre. | AQ2: CPF_I_004 | AR2: =VLOOKUP(AQ2,'Axe 2 Règles de gestion'!$D$2:$F$75,3, FALSE) -> L'administration doit donner son accord. | AS2: CPF_I_063 | AT2: =VLOOKUP(AS2,'Axe 2 Règles de gestion'!$D$2:$F$75,3, FALSE) -> L'administration dispose d'un délai de 2 mois pour notifier sa décision. | AU2: CPF_I_046 | AV2: =VLOOKUP(AU2,'Axe 2 Règles de gestion'!$D$2:$F$75,3, FALSE) -> Si plusieurs formations permettent de satisfaire la demande de l'agent, une priorité est accordée à celles assurées par l'administration de l'agent. | AW2: CPF_I_048 | AX2: =VLOOKUP(AW2,'Axe 2 Règles de gestion'!$D$2:$F$75,3, FALSE) -> L'administration examine les demandes en donnant une priorité à certaine action de formation ou à certain accompagnement. | AY2: CPF_I_049 | AZ2: =VLOOKUP(AY2,'Axe 2 Règles de gestion'!$D$2:$F$75,3, FALSE) -> L'ordre de priorisation est : 1) action dont le bilan de compétences permettant de prévenir une situation d'inaptitude à l'exercice des fonctions; 2) action de validation des acquis de l'expérience; 3) action de préparation aux concours et examens. | BA2: CPF_I_006 | BB2: =VLOOKUP(BA2,'Axe 2 Règles de gestion'!$D$2:$F$75,3, FALSE) -> L'administration doit motiver son refus à une demande. | BC2: CPF_I_007 | BD2: =VLOOKUP(BC2,'Axe 2 Règles de gestion'!$D$2:$F$75,3, FALSE) -> L'agent peut contester le refus devant l'instance paritaire compétente. | BE2: CPF_I_008 | BF2: =VLOOKUP(BE2,'Axe 2 Règles de gestion'!$D$2:$F$75,3, FALSE) -> L'administration ne peut refuser une demande relevant du socle de connaissances et compétences que toute personne doit maîtriser afin de favoriser son accès à la formation professionnelle et son insertion professionnelle. | BG2: CPF_I_009 | BH2: =VLOOKUP(BG2,'Axe 2 Règles de gestion'!$D$2:$F$75,3, FALSE) -> Cependant l'administration peut différer le suivi d'une formation relevant du socle de connaissances et compétences dans l'année qui suit la demande. | BI2: CPF_I_010 | BJ2: =VLOOKUP(BI2,'Axe 2 Règles de gestion'!$D$2:$F$75,3, FALSE) -> Si une demande a été refusée pendant 2 années consécutives, l'administration ne peut refuser une 3ème demande portant sur une action de formation de même nature qu'après avis de l'instance paritaire compétente. | BK2: CPF_I_050 | BL2: =VLOOKUP(BK2,'Axe 2 Règles de gestion'!$D$2:$F$75,3, FALSE) -> L'administration prend en charge les frais pédagogiques qui se rattachent à la formation suivie et peut prendre en charge les frais de déplacements. | BM2: CPF_I_051 | BN2: =VLOOKUP(BM2,'Axe 2 Règles de gestion'!$D$2:$F$75,3, FALSE) -> La prise en charge des frais peut faire l'objet de plafonds déterminés par arrêtés ministériels. | BO2: CPF_I_052 | BP2: =VLOOKUP(BO2,'Axe 2 Règles de gestion'!$D$2:$F$75,3, FALSE) -> L'agent qui ne suit pas tout ou partie de la formation sans motif valable doit rembourser les frais pédagogiques et de déplacements. | BQ2: CPF_I_018 | BR2: =VLOOKUP(BQ2,'Axe 2 Règles de gestion'!$D$2:$F$75,3, FALSE) -> Il peut être utilisé en combinaison avec le congé de formation professionnelle. | BS2: CPF_I_019 | BT2: =VLOOKUP(BS2,'Axe 2 Règles de gestion'!$D$2:$F$75,3, FALSE) -> L'agent peut utilisé compte personnel de formation pour compléter la préparation ou la réalisation de sa validation des acquis de l'expérience. | BU2: CPF_I_020 | BV2: =VLOOKUP(BU2,'Axe 2 Règles de gestion'!$D$2:$F$75,3, FALSE) -> L'agent peut utilisé son compte personnel de formation pour compléter la préparation ou la réalisation de son bilan de compétences. | BW2: CPF_I_044 | BX2: =VLOOKUP(BW2,'Axe 2 Règles de gestion'!$D$2:$F$75,3, FALSE) -> L'agent peut utiliser son compte personnel de formation pour compléter une décharge accordée pour suivre une action de préparation aux concours et examens. | BY2: CPF_I_060 | BZ2: =VLOOKUP(BY2,'Axe 2 Règles de gestion'!$D$2:$F$75,3, FALSE) -> L'agent peut utiliser son compte personnel de formation, après son accord écrit, pour suivre des actions de formation incluses dans la période de professionnalisation. | CA2: CPF_I_061 | CB2: =VLOOKUP(CA2,'Axe 2 Règles de gestion'!$D$2:$F$75,3, FALSE) -> L'agent peut utiliser son compte personnel de formation pour participer aux actions de préparation aux examens et concours administratifs et aux autres procédures de sélection. | CC2: CPF_I_026 | CD2: =VLOOKUP(CC2,'Axe 2 Règles de gestion'!$D$2:$F$75,3, FALSE) -> Lorsque l'agent est en position de détachement, l'alimentation, l'instruction et le financement des droits du compte personnel de formation relèvent de l'organisme d'accueil. | CE2: CPF_I_064 | CF2: =VLOOKUP(CE2,'Axe 2 Règles de gestion'!$D$2:$F$75,3, FALSE) -> Sauf disposition contraire prévue par la convention, si l'agent est mis à disposition ou affecté auprès d'un autre organisme, l'alimentation, l'instruction et le financement des droits du compte personnel de formation relèvent de l'organisme d'origine.
A3: 20.00.00 | B3: A | C3: 43923.679 | D3: D0009 | E3: Formation | F3: S0147 | G3: Compte personnel d'activité | H3: E0816 | I3: Compte personnel de formation | L3: T2014 | M3: Compte personnel de formation - Alimentation | N3: Création Modification | Q3: Titulaire ou magistrat | R3: P0001 | S3: T | T3: Général | U3: Passant | V3: 42736 | W3: 43830 | X3: CPF_I_011 ET CPF_I_053 ET CPF_I_012 ET CPF_I_013 ET CPF_I_014 ET CPF_I_058 ET CPF_I_026 ET CPF_I_064 | Y3: CPF_I_011 | Z3: =VLOOKUP(Y3,'Axe 2 Règles de gestion'!$D$2:$F$75,3, FALSE) -> L'alimentation du compte s'effectue à la fin de chaque année. | AA3: CPF_I_053 | AB3: =VLOOKUP(AA3,'Axe 2 Règles de gestion'!$D$2:$F$75,3, FALSE) -> Le compte personnel de formation est alimenté en heures de formation au 31 décembre de chaque année. | AC3: CPF_I_012 | AD3: =VLOOKUP(AC3,'Axe 2 Règles de gestion'!$D$2:$F$75,3, FALSE) -> L'alimentation du compte s'effectue à hauteur de 24 heures maximum par année de travail jusqu'à l'acquisition d'un crédit de 120 heures, puis de 12 heures maximum par année de travail, dans la limite d'un plafond total de 150 heures. | AE3: CPF_I_013 | AF3: =VLOOKUP(AE3,'Axe 2 Règles de gestion'!$D$2:$F$75,3, FALSE) -> L'agent de catégorie C qui n'a pas atteint un niveau de formation sanctionné par un diplôme de niveau V (Certificat d'aptitude professionnelle, Brevet d'études professionnelles) acquiert 48 heures maximum par an avec un plafond de 400 heures. | AG3: CPF_I_014 | AH3: =VLOOKUP(AG3,'Axe 2 Règles de gestion'!$D$2:$F$75,3, FALSE) -> Lorsque le projet d'évolution professionnelle vise à prévenir une situation d'inaptitude à l'exercice de ses fonctions, l'agent peut bénéficier d'un crédit d'heures supplémentaires, dans la limite de 150 heures avec les mêmes plafonds. | AI3: CPF_I_058 | AJ3: =VLOOKUP(AI3,'Axe 2 Règles de gestion'!$D$2:$F$75,3, FALSE) -> Pour justifier de ce crédit supplémentaire, l'agent présente un avis du médecin de prévention ou du travail attestant que son état de santé l'expose, compte tenu de ses conditions de travail, à un risque d'inaptitude à l'exercice de ses fonctions. | AK3: CPF_I_026 | AL3: =VLOOKUP(AK3,'Axe 2 Règles de gestion'!$D$2:$F$75,3, FALSE) -> Lorsque l'agent est en position de détachement, l'alimentation, l'instruction et le financement des droits du compte personnel de formation relèvent de l'organisme d'accueil. | AM3: CPF_I_064 | AN3: =VLOOKUP(AM3,'Axe 2 Règles de gestion'!$D$2:$F$75,3, FALSE) -> Sauf disposition contraire prévue par la convention, si l'agent est mis à disposition ou affecté auprès d'un autre organisme, l'alimentation, l'instruction et le financement des droits du compte personnel de formation relèvent de l'organisme d'origine.
A4: 20.00.00 | B4: A | C4: 43923.68 | D4: D0009 | E4: Formation | F4: S0147 | G4: Compte personnel d'activité | H4: E0816 | I4: Compte personnel de formation | L4: T2014 | M4: Compte personnel de formation - Alimentation | N4: Création Modification | Q4: Titulaire ou magistrat | R4: P0001 | S4: T | T4: Général | U4: Passant | V4: 43831 | X4: CPF_I_011 ET CPF_I_054 ET CPF_I_055 ET CPF_I_057 ET CPF_I_058 ET CPF_I_026 ET CPF_I_064 | Y4: CPF_I_011 | Z4: =VLOOKUP(Y4,'Axe 2 Règles de gestion'!$D$2:$F$75,3, FALSE) -> L'alimentation du compte s'effectue à la fin de chaque année. | AA4: CPF_I_054 | AB4: =VLOOKUP(AA4,'Axe 2 Règles de gestion'!$D$2:$F$75,3, FALSE) -> L'alimentation du compte personnel de formation s'effectue à hauteur de 25 heures maximum au titre de chaque année civile, dans la limite d'un plafond de 150 heures. | AC4: CPF_I_055 | AD4: =VLOOKUP(AC4,'Axe 2 Règles de gestion'!$D$2:$F$75,3, FALSE) -> L'agent de catégorie C qui n'a pas atteint un niveau de formation sanctionné par un diplôme de niveau 3 (certificat d'aptitude professionnelle, brevet d'études professionnelles) acquiert 50 heures maximum par année civile avec un plafond de 400 heures. | AE4: CPF_I_057 | AF4: =VLOOKUP(AE4,'Axe 2 Règles de gestion'!$D$2:$F$75,3, FALSE) -> Lorsque le projet d'évolution professionnelle vise à prévenir une situation d'inaptitude à l'exercice des fonctions, le crédit d'heures supplémentaires est limité à 150 heures. Il peut compléter, à la demande de l'agent, les droits acquis. | AG4: CPF_I_058 | AH4: =VLOOKUP(AG4,'Axe 2 Règles de gestion'!$D$2:$F$75,3, FALSE) -> Pour justifier de ce crédit supplémentaire, l'agent présente un avis du médecin de prévention ou du travail attestant que son état de santé l'expose, compte tenu de ses conditions de travail, à un risque d'inaptitude à l'exercice de ses fonctions. | AI4: CPF_I_026 | AJ4: =VLOOKUP(AI4,'Axe 2 Règles de gestion'!$D$2:$F$75,3, FALSE) -> Lorsque l'agent est en position de détachement, l'alimentation, l'instruction et le financement des droits du compte personnel de formation relèvent de l'organisme d'accueil. | AK4: CPF_I_064 | AL4: =VLOOKUP(AK4,'Axe 2 Règles de gestion'!$D$2:$F$75,3, FALSE) -> Sauf disposition contraire prévue par la convention, si l'agent est mis à disposition ou affecté auprès d'un autre organisme, l'alimentation, l'instruction et le financement des droits du compte personnel de formation relèvent de l'organisme d'origine.
A5: 20.00.00 | B5: A | C5: 43923.686 | D5: D0009 | E5: Formation | F5: S0147 | G5: Compte personnel d'activité | H5: E0816 | I5: Compte personnel de formation | L5: T2015 | M5: Compte personnel de formation - Anticipation | N5: Création Modification | Q5: Titulaire ou magistrat | R5: P0001 | S5: T | T5: Général | U5: Passant | V5: 42736 | X5: CPF_I_056 ET CPF_I_026 ET CPF_I_064 | Y5: CPF_I_056 | Z5: =VLOOKUP(Y5,'Axe 2 Règles de gestion'!$D$2:$F$75,3, FALSE) -> Si la durée de la formation est supérieure aux droits acquis, l'agent peut avec l'accord de l'administration utiliser par anticipation des droits non encore acquis dans la limite de ceux qu'il pourrait acquérir au cours des 2 années civiles suivantes. | AA5: CPF_I_026 | AB5: =VLOOKUP(AA5,'Axe 2 Règles de gestion'!$D$2:$F$75,3, FALSE) -> Lorsque l'agent est en position de détachement, l'alimentation, l'instruction et le financement des droits du compte personnel de formation relèvent de l'organisme d'accueil. | AC5: CPF_I_064 | AD5: =VLOOKUP(AC5,'Axe 2 Règles de gestion'!$D$2:$F$75,3, FALSE) -> Sauf disposition contraire prévue par la convention, si l'agent est mis à disposition ou affecté auprès d'un autre organisme, l'alimentation, l'instruction et le financement des droits du compte personnel de formation relèvent de l'organisme d'origine.
A6: 20.00.00 | B6: A | C6: 43923.671 | D6: D0009 | E6: Formation | F6: S0147 | G6: Compte personnel d'activité | H6: E0816 | I6: Compte personnel de formation | L6: T2013 | M6: Compte personnel de formation - Demande | N6: Création Modification | Q6: Militaire | R6: P0002 | S6: M | T6: Général | U6: Exclu | V6: 42736
A7: 20.00.00 | B7: A | C7: 43923.672 | D7: D0009 | E7: Formation | F7: S0147 | G7: Compte personnel d'activité | H7: E0816 | I7: Compte personnel de formation | L7: T2014 | M7: Compte personnel de formation - Alimentation | N7: Création Modification | Q7: Militaire | R7: P0002 | S7: M | T7: Général | U7: Exclu | V7: 42736
A8: 20.00.00 | B8: A | C8: 43923.672 | D8: D0009 | E8: Formation | F8: S0147 | G8: Compte personnel d'activité | H8: E0816 | I8: Compte personnel de formation | L8: T2015 | M8: Compte personnel de formation - Anticipation | N8: Création Modification | Q8: Militaire | R8: P0002 | S8: M | T8: Général | U8: Exclu | V8: 42736
A9: 22.10.00 | B9: M | C9: 44832.708 | D9: D0009 | E9: Formation | F9: S0147 | G9: Compte personnel d'activité | H9: E0816 | I9: Compte personnel de formation | L9: T2013 | M9: Compte personnel de formation - Demande | N9: Création Modification | Q9: Contractuel | R9: P0003 | S9: N | T9: Général | U9: Passant | V9: 42736 | W9: 44677 | X9: CPF_I_021 ET CPF_I_022 ET CPF_I_042 ET CPF_I_043 ET CPF_I_025 ET CPF_I_023 ET CPF_I_045 ET CPF_I_047 ET CPF_I_024 ET CPF_I_063 ET CPF_I_046 ET CPF_I_048 ET CPF_I_049 ET CPF_I_027 ET CPF_I_028 ET CPF_I_029 ET CPF_I_030 ET CPF_I_031 ET CPF_I_050 ET CPF_I_051 ET CPF_I_052 ET CPF_I_039 ET CPF_I_040 ET CPF_I_041 ET CPF_I_044 ET CPF_I_062 ET CPF_I_026 ET CPF_I_064 | Y9: CPF_I_021 | Z9: =VLOOKUP(Y9,'Axe 2 Règles de gestion'!$D$2:$F$75,3, FALSE) -> L'agent ne peut utiliser son compte personnel de formation que dans le cadre d'un projet d'évolution professionnel. | AA9: CPF_I_022 | AB9: =VLOOKUP(AA9,'Axe 2 Règles de gestion'!$D$2:$F$75,3, FALSE) -> L'agent utilise les heures acquises sur son compte pour suivre des actions de formation. | AC9: CPF_I_042 | AD9: =VLOOKUP(AC9,'Axe 2 Règles de gestion'!$D$2:$F$75,3, FALSE) -> La formation ne doit pas avoir pour objet l'adaptation aux fonctions exercées. | AE9: CPF_I_043 | AF9: =VLOOKUP(AE9,'Axe 2 Règles de gestion'!$D$2:$F$75,3, FALSE) -> La formation doit avoir pour objet l'acquisition d'un diplôme, d'un titre, d'un certificat de qualification professionnelle ou le développement des compétences nécessaires à la mise en œuvre du projet d'évolution professionnelle. | AG9: CPF_I_025 | AH9: =VLOOKUP(AG9,'Axe 2 Règles de gestion'!$D$2:$F$75,3, FALSE) -> L'agent doit suivre la formation, en priorité, pendant son temps de travail. | AI9: CPF_I_023 | AJ9: =VLOOKUP(AI9,'Axe 2 Règles de gestion'!$D$2:$F$75,3, FALSE) -> L'agent doit faire une demande. | AK9: CPF_I_045 | AL9: =VLOOKUP(AK9,'Axe 2 Règles de gestion'!$D$2:$F$75,3, FALSE) -> L'agent sollicite l'accord écrit de l'administration sur la nature, le calendrier et le financement de la formation souhaitée, en précisant le projet d'évolution professionnelle qui fonde sa demande. | AM9: CPF_I_047 | AN9: =VLOOKUP(AM9,'Axe 2 Règles de gestion'!$D$2:$F$75,3, FALSE) -> L'agent peut bénéficier, préalablement à sa demande, d'un accompagnement afin d'élaborer son projet professionnel et d'identifier les différentes actions nécessaires à sa mise en œuvre. | AO9: CPF_I_024 | AP9: =VLOOKUP(AO9,'Axe 2 Règles de gestion'!$D$2:$F$75,3, FALSE) -> L'administration doit donner son accord. | AQ9: CPF_I_063 | AR9: =VLOOKUP(AQ9,'Axe 2 Règles de gestion'!$D$2:$F$75,3, FALSE) -> L'administration dispose d'un délai de 2 mois pour notifier sa décision. | AS9: CPF_I_046 | AT9: =VLOOKUP(AS9,'Axe 2 Règles de gestion'!$D$2:$F$75,3, FALSE) -> Si plusieurs formations permettent de satisfaire la demande de l'agent, une priorité est accordée à celles assurées par l'administration de l'agent. | AU9: CPF_I_048 | AV9: =VLOOKUP(AU9,'Axe 2 Règles de gestion'!$D$2:$F$75,3, FALSE) -> L'administration examine les demandes en donnant une priorité à certaine action de formation ou à certain accompagnement. | AW9: CPF_I_049 | AX9: =VLOOKUP(AW9,'Axe 2 Règles de gestion'!$D$2:$F$75,3, FALSE) -> L'ordre de priorisation est : 1) action dont le bilan de compétences permettant de prévenir une situation d'inaptitude à l'exercice des fonctions; 2) action de validation des acquis de l'expérience; 3) action de préparation aux concours et examens. | AY9: CPF_I_027 | AZ9: =VLOOKUP(AY9,'Axe 2 Règles de gestion'!$D$2:$F$75,3, FALSE) -> L'administration doit motiver son refus à une demande. | BA9: CPF_I_028 | BB9: =VLOOKUP(BA9,'Axe 2 Règles de gestion'!$D$2:$F$75,3, FALSE) -> L'agent peut contester le refus devant l'instance paritaire compétente. | BC9: CPF_I_029 | BD9: =VLOOKUP(BC9,'Axe 2 Règles de gestion'!$D$2:$F$75,3, FALSE) -> L'administration ne peut refuser une demande relevant du socle de connaissances et compétences que toute personne doit maîtriser afin de favoriser son accès à la formation professionnelle et son insertion professionnelle. | BE9: CPF_I_030 | BF9: =VLOOKUP(BE9,'Axe 2 Règles de gestion'!$D$2:$F$75,3, FALSE) -> Cependant l'administration peut differer le suivi d'une formation relevant du socle de connaissances et compétences dans l'année qui suit la demande. | BG9: CPF_I_031 | BH9: =VLOOKUP(BG9,'Axe 2 Règles de gestion'!$D$2:$F$75,3, FALSE) -> Si une demande a été refusée pendant 2 années consécutives, l'administration ne peut refuser une 3ème demande portant sur une action de formation de même nature qu'après avis de l'instance paritaire compétente. | BI9: CPF_I_050 | BJ9: =VLOOKUP(BI9,'Axe 2 Règles de gestion'!$D$2:$F$75,3, FALSE) -> L'administration prend en charge les frais pédagogiques qui se rattachent à la formation suivie et peut prendre en charge les frais de déplacements. | BK9: CPF_I_051 | BL9: =VLOOKUP(BK9,'Axe 2 Règles de gestion'!$D$2:$F$75,3, FALSE) -> La prise en charge des frais peut faire l'objet de plafonds déterminés par arrêtés ministériels. | BM9: CPF_I_052 | BN9: =VLOOKUP(BM9,'Axe 2 Règles de gestion'!$D$2:$F$75,3, FALSE) -> L'agent qui ne suit pas tout ou partie de la formation sans motif valable doit rembourser les frais pédagogiques et de déplacements. | BO9: CPF_I_039 | BP9: =VLOOKUP(BO9,'Axe 2 Règles de gestion'!$D$2:$F$75,3, FALSE) -> Il peut être utilisé en combinaison avec le congé de formation professionnelle. | BQ9: CPF_I_040 | BR9: =VLOOKUP(BQ9,'Axe 2 Règles de gestion'!$D$2:$F$75,3, FALSE) -> L'agent peut utilisé compte personnel de formation pour compléter la préparation ou la réalisation de sa validation des acquis de l'expérience. | BS9: CPF_I_041 | BT9: =VLOOKUP(BS9,'Axe 2 Règles de gestion'!$D$2:$F$75,3, FALSE) -> L'agent peut utilisé son compte personnel de formation pour compléter la préparation ou la réalisation de son bilan de compétences. | BU9: CPF_I_044 | BV9: =VLOOKUP(BU9,'Axe 2 Règles de gestion'!$D$2:$F$75,3, FALSE) -> L'agent peut utiliser son compte personnel de formation pour compléter une décharge accordée pour suivre une action de préparation aux concours et examens. | BW9: CPF_I_062 | BX9: =VLOOKUP(BW9,'Axe 2 Règles de gestion'!$D$2:$F$75,3, FALSE) -> L'agent peut utiliser son compte personnel de formation pour participer aux actions de préparation aux examens et concours administratifs et aux autres procédures de sélection. | BY9: CPF_I_026 | BZ9: =VLOOKUP(BY9,'Axe 2 Règles de gestion'!$D$2:$F$75,3, FALSE) -> Lorsque l'agent est en position de détachement, l'alimentation, l'instruction et le financement des droits du compte personnel de formation relèvent de l'organisme d'accueil. | CA9: CPF_I_064 | CB9: =VLOOKUP(CA9,'Axe 2 Règles de gestion'!$D$2:$F$75,3, FALSE) -> Sauf disposition contraire prévue par la convention, si l'agent est mis à disposition ou affecté auprès d'un autre organisme, l'alimentation, l'instruction et le financement des droits du compte personnel de formation relèvent de l'organisme d'origine.
A10: 22.10.00 | B10: A | C10: 44832.708 | D10: D0009 | E10: Formation | F10: S0147 | G10: Compte personnel d'activité | H10: E0816 | I10: Compte personnel de formation | L10: T2013 | M10: Compte personnel de formation - Demande | N10: Création Modification | Q10: Contractuel | R10: P0003 | S10: N | T10: Général | U10: Passant | V10: 44678 | X10: CPF_I_021 ET CPF_I_022 ET CPF_I_042 ET CPF_I_043 ET CPF_I_025 ET CPF_I_023 ET CPF_I_045 ET CPF_I_047 ET CPF_I_024 ET CPF_I_063 ET CPF_I_046 ET CPF_I_048 ET CPF_I_049 ET CPF_I_070 ET CPF_I_027 ET CPF_I_028 ET CPF_I_029 ET CPF_I_030 ET CPF_I_031 ET CPF_I_050 ET CPF_I_051 ET CPF_I_052 ET CPF_I_039 ET CPF_I_040 ET CPF_I_041 ET CPF_I_044 ET CPF_I_062 ET CPF_I_026 ET CPF_I_064 | Y10: CPF_I_021 | Z10: =VLOOKUP(Y10,'Axe 2 Règles de gestion'!$D$2:$F$75,3, FALSE) -> L'agent ne peut utiliser son compte personnel de formation que dans le cadre d'un projet d'évolution professionnel. | AA10: CPF_I_022 | AB10: =VLOOKUP(AA10,'Axe 2 Règles de gestion'!$D$2:$F$75,3, FALSE) -> L'agent utilise les heures acquises sur son compte pour suivre des actions de formation. | AC10: CPF_I_042 | AD10: =VLOOKUP(AC10,'Axe 2 Règles de gestion'!$D$2:$F$75,3, FALSE) -> La formation ne doit pas avoir pour objet l'adaptation aux fonctions exercées. | AE10: CPF_I_043 | AF10: =VLOOKUP(AE10,'Axe 2 Règles de gestion'!$D$2:$F$75,3, FALSE) -> La formation doit avoir pour objet l'acquisition d'un diplôme, d'un titre, d'un certificat de qualification professionnelle ou le développement des compétences nécessaires à la mise en œuvre du projet d'évolution professionnelle. | AG10: CPF_I_025 | AH10: =VLOOKUP(AG10,'Axe 2 Règles de gestion'!$D$2:$F$75,3, FALSE) -> L'agent doit suivre la formation, en priorité, pendant son temps de travail. | AI10: CPF_I_023 | AJ10: =VLOOKUP(AI10,'Axe 2 Règles de gestion'!$D$2:$F$75,3, FALSE) -> L'agent doit faire une demande. | AK10: CPF_I_045 | AL10: =VLOOKUP(AK10,'Axe 2 Règles de gestion'!$D$2:$F$75,3, FALSE) -> L'agent sollicite l'accord écrit de l'administration sur la nature, le calendrier et le financement de la formation souhaitée, en précisant le projet d'évolution professionnelle qui fonde sa demande. | AM10: CPF_I_047 | AN10: =VLOOKUP(AM10,'Axe 2 Règles de gestion'!$D$2:$F$75,3, FALSE) -> L'agent peut bénéficier, préalablement à sa demande, d'un accompagnement afin d'élaborer son projet professionnel et d'identifier les différentes actions nécessaires à sa mise en œuvre. | AO10: CPF_I_024 | AP10: =VLOOKUP(AO10,'Axe 2 Règles de gestion'!$D$2:$F$75,3, FALSE) -> L'administration doit donner son accord. | AQ10: CPF_I_063 | AR10: =VLOOKUP(AQ10,'Axe 2 Règles de gestion'!$D$2:$F$75,3, FALSE) -> L'administration dispose d'un délai de 2 mois pour notifier sa décision. | AS10: CPF_I_046 | AT10: =VLOOKUP(AS10,'Axe 2 Règles de gestion'!$D$2:$F$75,3, FALSE) -> Si plusieurs formations permettent de satisfaire la demande de l'agent, une priorité est accordée à celles assurées par l'administration de l'agent. | AU10: CPF_I_048 | AV10: =VLOOKUP(AU10,'Axe 2 Règles de gestion'!$D$2:$F$75,3, FALSE) -> L'administration examine les demandes en donnant une priorité à certaine action de formation ou à certain accompagnement. | AW10: CPF_I_049 | AX10: =VLOOKUP(AW10,'Axe 2 Règles de gestion'!$D$2:$F$75,3, FALSE) -> L'ordre de priorisation est : 1) action dont le bilan de compétences permettant de prévenir une situation d'inaptitude à l'exercice des fonctions; 2) action de validation des acquis de l'expérience; 3) action de préparation aux concours et examens. | AY10: CPF_I_070 | AZ10: =VLOOKUP(AY10,'Axe 2 Règles de gestion'!$D$2:$F$75,3, FALSE) -> La décision de refus d'une demande de mobilisation du compte personnel de formation par l'agent fait l'objet d'une consultation de la commission consultative paritaire. | BA10: CPF_I_027 | BB10: =VLOOKUP(BA10,'Axe 2 Règles de gestion'!$D$2:$F$75,3, FALSE) -> L'administration doit motiver son refus à une demande. | BC10: CPF_I_028 | BD10: =VLOOKUP(BC10,'Axe 2 Règles de gestion'!$D$2:$F$75,3, FALSE) -> L'agent peut contester le refus devant l'instance paritaire compétente. | BE10: CPF_I_029 | BF10: =VLOOKUP(BE10,'Axe 2 Règles de gestion'!$D$2:$F$75,3, FALSE) -> L'administration ne peut refuser une demande relevant du socle de connaissances et compétences que toute personne doit maîtriser afin de favoriser son accès à la formation professionnelle et son insertion professionnelle. | BG10: CPF_I_030 | BH10: =VLOOKUP(BG10,'Axe 2 Règles de gestion'!$D$2:$F$75,3, FALSE) -> Cependant l'administration peut differer le suivi d'une formation relevant du socle de connaissances et compétences dans l'année qui suit la demande. | BI10: CPF_I_031 | BJ10: =VLOOKUP(BI10,'Axe 2 Règles de gestion'!$D$2:$F$75,3, FALSE) -> Si une demande a été refusée pendant 2 années consécutives, l'administration ne peut refuser une 3ème demande portant sur une action de formation de même nature qu'après avis de l'instance paritaire compétente. | BK10: CPF_I_050 | BL10: =VLOOKUP(BK10,'Axe 2 Règles de gestion'!$D$2:$F$75,3, FALSE) -> L'administration prend en charge les frais pédagogiques qui se rattachent à la formation suivie et peut prendre en charge les frais de déplacements. | BM10: CPF_I_051 | BN10: =VLOOKUP(BM10,'Axe 2 Règles de gestion'!$D$2:$F$75,3, FALSE) -> La prise en charge des frais peut faire l'objet de plafonds déterminés par arrêtés ministériels. | BO10: CPF_I_052 | BP10: =VLOOKUP(BO10,'Axe 2 Règles de gestion'!$D$2:$F$75,3, FALSE) -> L'agent qui ne suit pas tout ou partie de la formation sans motif valable doit rembourser les frais pédagogiques et de déplacements. | BQ10: CPF_I_039 | BR10: =VLOOKUP(BQ10,'Axe 2 Règles de gestion'!$D$2:$F$75,3, FALSE) -> Il peut être utilisé en combinaison avec le congé de formation professionnelle. | BS10: CPF_I_040 | BT10: =VLOOKUP(BS10,'Axe 2 Règles de gestion'!$D$2:$F$75,3, FALSE) -> L'agent peut utilisé compte personnel de formation pour compléter la préparation ou la réalisation de sa validation des acquis de l'expérience. | BU10: CPF_I_041 | BV10: =VLOOKUP(BU10,'Axe 2 Règles de gestion'!$D$2:$F$75,3, FALSE) -> L'agent peut utilisé son compte personnel de formation pour compléter la préparation ou la réalisation de son bilan de compétences. | BW10: CPF_I_044 | BX10: =VLOOKUP(BW10,'Axe 2 Règles de gestion'!$D$2:$F$75,3, FALSE) -> L'agent peut utiliser son compte personnel de formation pour compléter une décharge accordée pour suivre une action de préparation aux concours et examens. | BY10: CPF_I_062 | BZ10: =VLOOKUP(BY10,'Axe 2 Règles de gestion'!$D$2:$F$75,3, FALSE) -> L'agent peut utiliser son compte personnel de formation pour participer aux actions de préparation aux examens et concours administratifs et aux autres procédures de sélection. | CA10: CPF_I_026 | CB10: =VLOOKUP(CA10,'Axe 2 Règles de gestion'!$D$2:$F$75,3, FALSE) -> Lorsque l'agent est en position de détachement, l'alimentation, l'instruction et le financement des droits du compte personnel de formation relèvent de l'organisme d'accueil. | CC10: CPF_I_064 | CD10: =VLOOKUP(CC10,'Axe 2 Règles de gestion'!$D$2:$F$75,3, FALSE) -> Sauf disposition contraire prévue par la convention, si l'agent est mis à disposition ou affecté auprès d'un autre organisme, l'alimentation, l'instruction et le financement des droits du compte personnel de formation relèvent de l'organisme d'origine.
A11: 20.00.00 | B11: A | C11: 43928.397 | D11: D0009 | E11: Formation | F11: S0147 | G11: Compte personnel d'activité | H11: E0816 | I11: Compte personnel de formation | L11: T2014 | M11: Compte personnel de formation - Alimentation | N11: Création Modification | Q11: Contractuel | R11: P0003 | S11: N | T11: Général | U11: Passant | V11: 42736 | W11: 43830 | X11: CPF_I_032 ET CPF_I_053 ET CPF_I_033 ET CPF_I_034 ET CPF_I_035 ET CPF_I_058 ET CPF_I_026 ET CPF_I_064 | Y11: CPF_I_032 | Z11: =VLOOKUP(Y11,'Axe 2 Règles de gestion'!$D$2:$F$75,3, FALSE) -> L'alimentation du compte s'effectue à la fin de chaque année. | AA11: CPF_I_053 | AB11: =VLOOKUP(AA11,'Axe 2 Règles de gestion'!$D$2:$F$75,3, FALSE) -> Le compte personnel de formation est alimenté en heures de formation au 31 décembre de chaque année. | AC11: CPF_I_033 | AD11: =VLOOKUP(AC11,'Axe 2 Règles de gestion'!$D$2:$F$75,3, FALSE) -> L'alimentation du compte s'effectue à hauteur de 24 heures maximum par année de travail jusqu'à l'acquisition d'un crédit de 120 heures, puis de 12 heures maximum par année de travail, dans la limite d'un plafond total de 150 heures. | AE11: CPF_I_034 | AF11: =VLOOKUP(AE11,'Axe 2 Règles de gestion'!$D$2:$F$75,3, FALSE) -> L'agent de catégorie C qui n'a pas atteint un niveau de formation sanctionné par un diplôme de niveau V (Certificat d'aptitude professionnelle, Brevet d'études professionnelles) acquiert 48 heures maximum par an avec un plafond de 400 heures. | AG11: CPF_I_035 | AH11: =VLOOKUP(AG11,'Axe 2 Règles de gestion'!$D$2:$F$75,3, FALSE) -> Lorsque le projet d'évolution professionnelle vise à prévenir une situation d'inaptitude à l'exercice de ses fonctions, l'agent peut bénéficier d'un crédit d'heures supplémentaires, dans la limite de 150 heures avec les mêmes plafonds. | AI11: CPF_I_058 | AJ11: =VLOOKUP(AI11,'Axe 2 Règles de gestion'!$D$2:$F$75,3, FALSE) -> Pour justifier de ce crédit supplémentaire, l'agent présente un avis du médecin de prévention ou du travail attestant que son état de santé l'expose, compte tenu de ses conditions de travail, à un risque d'inaptitude à l'exercice de ses fonctions. | AK11: CPF_I_026 | AL11: =VLOOKUP(AK11,'Axe 2 Règles de gestion'!$D$2:$F$75,3, FALSE) -> Lorsque l'agent est en position de détachement, l'alimentation, l'instruction et le financement des droits du compte personnel de formation relèvent de l'organisme d'accueil. | AM11: CPF_I_064 | AN11: =VLOOKUP(AM11,'Axe 2 Règles de gestion'!$D$2:$F$75,3, FALSE) -> Sauf disposition contraire prévue par la convention, si l'agent est mis à disposition ou affecté auprès d'un autre organisme, l'alimentation, l'instruction et le financement des droits du compte personnel de formation relèvent de l'organisme d'origine.
A12: 20.00.00 | B12: A | C12: 43928.371 | D12: D0009 | E12: Formation | F12: S0147 | G12: Compte personnel d'activité | H12: E0816 | I12: Compte personnel de formation | L12: T2014 | M12: Compte personnel de formation - Alimentation | N12: Création Modification | Q12: Contractuel | R12: P0003 | S12: N | T12: Général | U12: Passant | V12: 43831 | X12: CPF_I_032 ET CPF_I_054 ET CPF_I_055 ET CPF_I_057 ET CPF_I_058 ET CPF_I_026 ET CPF_I_064 | Y12: CPF_I_032 | Z12: =VLOOKUP(Y12,'Axe 2 Règles de gestion'!$D$2:$F$75,3, FALSE) -> L'alimentation du compte s'effectue à la fin de chaque année. | AA12: CPF_I_054 | AB12: =VLOOKUP(AA12,'Axe 2 Règles de gestion'!$D$2:$F$75,3, FALSE) -> L'alimentation du compte personnel de formation s'effectue à hauteur de 25 heures maximum au titre de chaque année civile, dans la limite d'un plafond de 150 heures. | AC12: CPF_I_055 | AD12: =VLOOKUP(AC12,'Axe 2 Règles de gestion'!$D$2:$F$75,3, FALSE) -> L'agent de catégorie C qui n'a pas atteint un niveau de formation sanctionné par un diplôme de niveau 3 (certificat d'aptitude professionnelle, brevet d'études professionnelles) acquiert 50 heures maximum par année civile avec un plafond de 400 heures. | AE12: CPF_I_057 | AF12: =VLOOKUP(AE12,'Axe 2 Règles de gestion'!$D$2:$F$75,3, FALSE) -> Lorsque le projet d'évolution professionnelle vise à prévenir une situation d'inaptitude à l'exercice des fonctions, le crédit d'heures supplémentaires est limité à 150 heures. Il peut compléter, à la demande de l'agent, les droits acquis. | AG12: CPF_I_058 | AH12: =VLOOKUP(AG12,'Axe 2 Règles de gestion'!$D$2:$F$75,3, FALSE) -> Pour justifier de ce crédit supplémentaire, l'agent présente un avis du médecin de prévention ou du travail attestant que son état de santé l'expose, compte tenu de ses conditions de travail, à un risque d'inaptitude à l'exercice de ses fonctions. | AI12: CPF_I_026 | AJ12: =VLOOKUP(AI12,'Axe 2 Règles de gestion'!$D$2:$F$75,3, FALSE) -> Lorsque l'agent est en position de détachement, l'alimentation, l'instruction et le financement des droits du compte personnel de formation relèvent de l'organisme d'accueil. | AK12: CPF_I_064 | AL12: =VLOOKUP(AK12,'Axe 2 Règles de gestion'!$D$2:$F$75,3, FALSE) -> Sauf disposition contraire prévue par la convention, si l'agent est mis à disposition ou affecté auprès d'un autre organisme, l'alimentation, l'instruction et le financement des droits du compte personnel de formation relèvent de l'organisme d'origine.
A13: 20.00.00 | B13: A | C13: 43923.687 | D13: D0009 | E13: Formation | F13: S0147 | G13: Compte personnel d'activité | H13: E0816 | I13: Compte personnel de formation | L13: T2015 | M13: Compte personnel de formation - Anticipation | N13: Création Modification | Q13: Contractuel | R13: P0003 | S13: N | T13: Général | U13: Passant | V13: 42736 | X13: CPF_I_056 ET CPF_I_026 ET CPF_I_064 | Y13: CPF_I_056 | Z13: =VLOOKUP(Y13,'Axe 2 Règles de gestion'!$D$2:$F$75,3, FALSE) -> Si la durée de la formation est supérieure aux droits acquis, l'agent peut avec l'accord de l'administration utiliser par anticipation des droits non encore acquis dans la limite de ceux qu'il pourrait acquérir au cours des 2 années civiles suivantes. | AA13: CPF_I_026 | AB13: =VLOOKUP(AA13,'Axe 2 Règles de gestion'!$D$2:$F$75,3, FALSE) -> Lorsque l'agent est en position de détachement, l'alimentation, l'instruction et le financement des droits du compte personnel de formation relèvent de l'organisme d'accueil. | AC13: CPF_I_064 | AD13: =VLOOKUP(AC13,'Axe 2 Règles de gestion'!$D$2:$F$75,3, FALSE) -> Sauf disposition contraire prévue par la convention, si l'agent est mis à disposition ou affecté auprès d'un autre organisme, l'alimentation, l'instruction et le financement des droits du compte personnel de formation relèvent de l'organisme d'origine.
A14: 20.00.00 | B14: A | C14: 43924.521 | D14: D0009 | E14: Formation | F14: S0147 | G14: Compte personnel d'activité | H14: E0816 | I14: Compte personnel de formation | L14: T2013 | M14: Compte personnel de formation - Demande | N14: Création Modification | Q14: Stagiaire ou auditeur ou élève | R14: P0004 | S14: S | T14: Général | U14: Passant | V14: 42736 | X14: CPF_I_001 ET CPF_I_002 ET CPF_I_042 ET CPF_I_043 ET CPF_I_005 ET CPF_I_059 ET CPF_I_003 ET CPF_I_045 ET CPF_I_047 ET CPF_I_004 ET CPF_I_063 ET CPF_I_046 ET CPF_I_048 ET CPF_I_049 ET CPF_I_006 ET CPF_I_007 ET CPF_I_008 ET CPF_I_009 ET CPF_I_010 ET CPF_I_050 ET CPF_I_051 ET CPF_I_052 ET CPF_I_018 ET CPF_I_019 ET CPF_I_020 ET CPF_I_044 ET CPF_I_060 ET CPF_I_061 ET CPF_I_026 ET CPF_I_064 | Y14: CPF_I_001 | Z14: =VLOOKUP(Y14,'Axe 2 Règles de gestion'!$D$2:$F$75,3, FALSE) -> L'agent ne peut utiliser son compte personnel de formation que pour accéder à une qualification ou développer ses compétences dans le cadre d'un projet d'évolution professionnelle. | AA14: CPF_I_002 | AB14: =VLOOKUP(AA14,'Axe 2 Règles de gestion'!$D$2:$F$75,3, FALSE) -> L'agent utilise les heures acquises sur son compte pour suivre des actions de formation. | AC14: CPF_I_042 | AD14: =VLOOKUP(AC14,'Axe 2 Règles de gestion'!$D$2:$F$75,3, FALSE) -> La formation ne doit pas avoir pour objet l'adaptation aux fonctions exercées. | AE14: CPF_I_043 | AF14: =VLOOKUP(AE14,'Axe 2 Règles de gestion'!$D$2:$F$75,3, FALSE) -> La formation doit avoir pour objet l'acquisition d'un diplôme, d'un titre, d'un certificat de qualification professionnelle ou le développement des compétences nécessaires à la mise en œuvre du projet d'évolution professionnelle. | AG14: CPF_I_005 | AH14: =VLOOKUP(AG14,'Axe 2 Règles de gestion'!$D$2:$F$75,3, FALSE) -> L'agent doit suivre la formation, en priorité, pendant son temps de travail. | AI14: CPF_I_059 | AJ14: =VLOOKUP(AI14,'Axe 2 Règles de gestion'!$D$2:$F$75,3, FALSE) -> L'agent peut utiliser son compte pour réaliser des heures de formation d'adaptation à l'évolution prévisible des métiers ou de développement des qualifications ou d'acquisition de nouvelles qualifications hors temps de service. | AK14: CPF_I_003 | AL14: =VLOOKUP(AK14,'Axe 2 Règles de gestion'!$D$2:$F$75,3, FALSE) -> L'agent doit faire une demande. | AM14: CPF_I_045 | AN14: =VLOOKUP(AM14,'Axe 2 Règles de gestion'!$D$2:$F$75,3, FALSE) -> L'agent sollicite l'accord écrit de l'administration sur la nature, le calendrier et le financement de la formation souhaitée, en précisant le projet d'évolution professionnelle qui fonde sa demande. | AO14: CPF_I_047 | AP14: =VLOOKUP(AO14,'Axe 2 Règles de gestion'!$D$2:$F$75,3, FALSE) -> L'agent peut bénéficier, préalablement à sa demande, d'un accompagnement afin d'élaborer son projet professionnel et d'identifier les différentes actions nécessaires à sa mise en œuvre. | AQ14: CPF_I_004 | AR14: =VLOOKUP(AQ14,'Axe 2 Règles de gestion'!$D$2:$F$75,3, FALSE) -> L'administration doit donner son accord. | AS14: CPF_I_063 | AT14: =VLOOKUP(AS14,'Axe 2 Règles de gestion'!$D$2:$F$75,3, FALSE) -> L'administration dispose d'un délai de 2 mois pour notifier sa décision. | AU14: CPF_I_046 | AV14: =VLOOKUP(AU14,'Axe 2 Règles de gestion'!$D$2:$F$75,3, FALSE) -> Si plusieurs formations permettent de satisfaire la demande de l'agent, une priorité est accordée à celles assurées par l'administration de l'agent. | AW14: CPF_I_048 | AX14: =VLOOKUP(AW14,'Axe 2 Règles de gestion'!$D$2:$F$75,3, FALSE) -> L'administration examine les demandes en donnant une priorité à certaine action de formation ou à certain accompagnement. | AY14: CPF_I_049 | AZ14: =VLOOKUP(AY14,'Axe 2 Règles de gestion'!$D$2:$F$75,3, FALSE) -> L'ordre de priorisation est : 1) action dont le bilan de compétences permettant de prévenir une situation d'inaptitude à l'exercice des fonctions; 2) action de validation des acquis de l'expérience; 3) action de préparation aux concours et examens. | BA14: CPF_I_006 | BB14: =VLOOKUP(BA14,'Axe 2 Règles de gestion'!$D$2:$F$75,3, FALSE) -> L'administration doit motiver son refus à une demande. | BC14: CPF_I_007 | BD14: =VLOOKUP(BC14,'Axe 2 Règles de gestion'!$D$2:$F$75,3, FALSE) -> L'agent peut contester le refus devant l'instance paritaire compétente. | BE14: CPF_I_008 | BF14: =VLOOKUP(BE14,'Axe 2 Règles de gestion'!$D$2:$F$75,3, FALSE) -> L'administration ne peut refuser une demande relevant du socle de connaissances et compétences que toute personne doit maîtriser afin de favoriser son accès à la formation professionnelle et son insertion professionnelle. | BG14: CPF_I_009 | BH14: =VLOOKUP(BG14,'Axe 2 Règles de gestion'!$D$2:$F$75,3, FALSE) -> Cependant l'administration peut différer le suivi d'une formation relevant du socle de connaissances et compétences dans l'année qui suit la demande. | BI14: CPF_I_010 | BJ14: =VLOOKUP(BI14,'Axe 2 Règles de gestion'!$D$2:$F$75,3, FALSE) -> Si une demande a été refusée pendant 2 années consécutives, l'administration ne peut refuser une 3ème demande portant sur une action de formation de même nature qu'après avis de l'instance paritaire compétente. | BK14: CPF_I_050 | BL14: =VLOOKUP(BK14,'Axe 2 Règles de gestion'!$D$2:$F$75,3, FALSE) -> L'administration prend en charge les frais pédagogiques qui se rattachent à la formation suivie et peut prendre en charge les frais de déplacements. | BM14: CPF_I_051 | BN14: =VLOOKUP(BM14,'Axe 2 Règles de gestion'!$D$2:$F$75,3, FALSE) -> La prise en charge des frais peut faire l'objet de plafonds déterminés par arrêtés ministériels. | BO14: CPF_I_052 | BP14: =VLOOKUP(BO14,'Axe 2 Règles de gestion'!$D$2:$F$75,3, FALSE) -> L'agent qui ne suit pas tout ou partie de la formation sans motif valable doit rembourser les frais pédagogiques et de déplacements. | BQ14: CPF_I_018 | BR14: =VLOOKUP(BQ14,'Axe 2 Règles de gestion'!$D$2:$F$75,3, FALSE) -> Il peut être utilisé en combinaison avec le congé de formation professionnelle. | BS14: CPF_I_019 | BT14: =VLOOKUP(BS14,'Axe 2 Règles de gestion'!$D$2:$F$75,3, FALSE) -> L'agent peut utilisé compte personnel de formation pour compléter la préparation ou la réalisation de sa validation des acquis de l'expérience. | BU14: CPF_I_020 | BV14: =VLOOKUP(BU14,'Axe 2 Règles de gestion'!$D$2:$F$75,3, FALSE) -> L'agent peut utilisé son compte personnel de formation pour compléter la préparation ou la réalisation de son bilan de compétences. | BW14: CPF_I_044 | BX14: =VLOOKUP(BW14,'Axe 2 Règles de gestion'!$D$2:$F$75,3, FALSE) -> L'agent peut utiliser son compte personnel de formation pour compléter une décharge accordée pour suivre une action de préparation aux concours et examens. | BY14: CPF_I_060 | BZ14: =VLOOKUP(BY14,'Axe 2 Règles de gestion'!$D$2:$F$75,3, FALSE) -> L'agent peut utiliser son compte personnel de formation, après son accord écrit, pour suivre des actions de formation incluses dans la période de professionnalisation. | CA14: CPF_I_061 | CB14: =VLOOKUP(CA14,'Axe 2 Règles de gestion'!$D$2:$F$75,3, FALSE) -> L'agent peut utiliser son compte personnel de formation pour participer aux actions de préparation aux examens et concours administratifs et aux autres procédures de sélection. | CC14: CPF_I_026 | CD14: =VLOOKUP(CC14,'Axe 2 Règles de gestion'!$D$2:$F$75,3, FALSE) -> Lorsque l'agent est en position de détachement, l'alimentation, l'instruction et le financement des droits du compte personnel de formation relèvent de l'organisme d'accueil. | CE14: CPF_I_064 | CF14: =VLOOKUP(CE14,'Axe 2 Règles de gestion'!$D$2:$F$75,3, FALSE) -> Sauf disposition contraire prévue par la convention, si l'agent est mis à disposition ou affecté auprès d'un autre organisme, l'alimentation, l'instruction et le financement des droits du compte personnel de formation relèvent de l'organisme d'origine.
A15: 20.00.00 | B15: A | C15: 43923.683 | D15: D0009 | E15: Formation | F15: S0147 | G15: Compte personnel d'activité | H15: E0816 | I15: Compte personnel de formation | L15: T2014 | M15: Compte personnel de formation - Alimentation | N15: Création Modification | Q15: Stagiaire ou auditeur ou élève | R15: P0004 | S15: S | T15: Général | U15: Passant | V15: 42736 | W15: 43830 | X15: CPF_I_011 ET CPF_I_053 ET CPF_I_012 ET CPF_I_013 ET CPF_I_014 ET CPF_I_058 ET CPF_I_026 ET CPF_I_064 | Y15: CPF_I_011 | Z15: =VLOOKUP(Y15,'Axe 2 Règles de gestion'!$D$2:$F$75,3, FALSE) -> L'alimentation du compte s'effectue à la fin de chaque année. | AA15: CPF_I_053 | AB15: =VLOOKUP(AA15,'Axe 2 Règles de gestion'!$D$2:$F$75,3, FALSE) -> Le compte personnel de formation est alimenté en heures de formation au 31 décembre de chaque année. | AC15: CPF_I_012 | AD15: =VLOOKUP(AC15,'Axe 2 Règles de gestion'!$D$2:$F$75,3, FALSE) -> L'alimentation du compte s'effectue à hauteur de 24 heures maximum par année de travail jusqu'à l'acquisition d'un crédit de 120 heures, puis de 12 heures maximum par année de travail, dans la limite d'un plafond total de 150 heures. | AE15: CPF_I_013 | AF15: =VLOOKUP(AE15,'Axe 2 Règles de gestion'!$D$2:$F$75,3, FALSE) -> L'agent de catégorie C qui n'a pas atteint un niveau de formation sanctionné par un diplôme de niveau V (Certificat d'aptitude professionnelle, Brevet d'études professionnelles) acquiert 48 heures maximum par an avec un plafond de 400 heures. | AG15: CPF_I_014 | AH15: =VLOOKUP(AG15,'Axe 2 Règles de gestion'!$D$2:$F$75,3, FALSE) -> Lorsque le projet d'évolution professionnelle vise à prévenir une situation d'inaptitude à l'exercice de ses fonctions, l'agent peut bénéficier d'un crédit d'heures supplémentaires, dans la limite de 150 heures avec les mêmes plafonds. | AI15: CPF_I_058 | AJ15: =VLOOKUP(AI15,'Axe 2 Règles de gestion'!$D$2:$F$75,3, FALSE) -> Pour justifier de ce crédit supplémentaire, l'agent présente un avis du médecin de prévention ou du travail attestant que son état de santé l'expose, compte tenu de ses conditions de travail, à un risque d'inaptitude à l'exercice de ses fonctions. | AK15: CPF_I_026 | AL15: =VLOOKUP(AK15,'Axe 2 Règles de gestion'!$D$2:$F$75,3, FALSE) -> Lorsque l'agent est en position de détachement, l'alimentation, l'instruction et le financement des droits du compte personnel de formation relèvent de l'organisme d'accueil. | AM15: CPF_I_064 | AN15: =VLOOKUP(AM15,'Axe 2 Règles de gestion'!$D$2:$F$75,3, FALSE) -> Sauf disposition contraire prévue par la convention, si l'agent est mis à disposition ou affecté auprès d'un autre organisme, l'alimentation, l'instruction et le financement des droits du compte personnel de formation relèvent de l'organisme d'origine.
A16: 20.00.00 | B16: A | C16: 43923.683 | D16: D0009 | E16: Formation | F16: S0147 | G16: Compte personnel d'activité | H16: E0816 | I16: Compte personnel de formation | L16: T2014 | M16: Compte personnel de formation - Alimentation | N16: Création Modification | Q16: Stagiaire ou auditeur ou élève | R16: P0004 | S16: S | T16: Général | U16: Passant | V16: 43831 | X16: CPF_I_011 ET CPF_I_054 ET CPF_I_055 ET CPF_I_057 ET CPF_I_058 ET CPF_I_026 ET CPF_I_064 | Y16: CPF_I_011 | Z16: =VLOOKUP(Y16,'Axe 2 Règles de gestion'!$D$2:$F$75,3, FALSE) -> L'alimentation du compte s'effectue à la fin de chaque année. | AA16: CPF_I_054 | AB16: =VLOOKUP(AA16,'Axe 2 Règles de gestion'!$D$2:$F$75,3, FALSE) -> L'alimentation du compte personnel de formation s'effectue à hauteur de 25 heures maximum au titre de chaque année civile, dans la limite d'un plafond de 150 heures. | AC16: CPF_I_055 | AD16: =VLOOKUP(AC16,'Axe 2 Règles de gestion'!$D$2:$F$75,3, FALSE) -> L'agent de catégorie C qui n'a pas atteint un niveau de formation sanctionné par un diplôme de niveau 3 (certificat d'aptitude professionnelle, brevet d'études professionnelles) acquiert 50 heures maximum par année civile avec un plafond de 400 heures. | AE16: CPF_I_057 | AF16: =VLOOKUP(AE16,'Axe 2 Règles de gestion'!$D$2:$F$75,3, FALSE) -> Lorsque le projet d'évolution professionnelle vise à prévenir une situation d'inaptitude à l'exercice des fonctions, le crédit d'heures supplémentaires est limité à 150 heures. Il peut compléter, à la demande de l'agent, les droits acquis. | AG16: CPF_I_058 | AH16: =VLOOKUP(AG16,'Axe 2 Règles de gestion'!$D$2:$F$75,3, FALSE) -> Pour justifier de ce crédit supplémentaire, l'agent présente un avis du médecin de prévention ou du travail attestant que son état de santé l'expose, compte tenu de ses conditions de travail, à un risque d'inaptitude à l'exercice de ses fonctions. | AI16: CPF_I_026 | AJ16: =VLOOKUP(AI16,'Axe 2 Règles de gestion'!$D$2:$F$75,3, FALSE) -> Lorsque l'agent est en position de détachement, l'alimentation, l'instruction et le financement des droits du compte personnel de formation relèvent de l'organisme d'accueil. | AK16: CPF_I_064 | AL16: =VLOOKUP(AK16,'Axe 2 Règles de gestion'!$D$2:$F$75,3, FALSE) -> Sauf disposition contraire prévue par la convention, si l'agent est mis à disposition ou affecté auprès d'un autre organisme, l'alimentation, l'instruction et le financement des droits du compte personnel de formation relèvent de l'organisme d'origine.
A17: 20.00.00 | B17: A | C17: 43923.689 | D17: D0009 | E17: Formation | F17: S0147 | G17: Compte personnel d'activité | H17: E0816 | I17: Compte personnel de formation | L17: T2015 | M17: Compte personnel de formation - Anticipation | N17: Création Modification | Q17: Stagiaire ou auditeur ou élève | R17: P0004 | S17: S | T17: Général | U17: Passant | V17: 42736 | X17: CPF_I_056 ET CPF_I_026 ET CPF_I_064 | Y17: CPF_I_056 | Z17: =VLOOKUP(Y17,'Axe 2 Règles de gestion'!$D$2:$F$75,3, FALSE) -> Si la durée de la formation est supérieure aux droits acquis, l'agent peut avec l'accord de l'administration utiliser par anticipation des droits non encore acquis dans la limite de ceux qu'il pourrait acquérir au cours des 2 années civiles suivantes. | AA17: CPF_I_026 | AB17: =VLOOKUP(AA17,'Axe 2 Règles de gestion'!$D$2:$F$75,3, FALSE) -> Lorsque l'agent est en position de détachement, l'alimentation, l'instruction et le financement des droits du compte personnel de formation relèvent de l'organisme d'accueil. | AC17: CPF_I_064 | AD17: =VLOOKUP(AC17,'Axe 2 Règles de gestion'!$D$2:$F$75,3, FALSE) -> Sauf disposition contraire prévue par la convention, si l'agent est mis à disposition ou affecté auprès d'un autre organisme, l'alimentation, l'instruction et le financement des droits du compte personnel de formation relèvent de l'organisme d'origine.
