Workbook

Sheet Mode opératoire
B1: MODE OPERATOIRE
B2: La transaction s'effectue au niveau de la rubrique "Notation/Evaluation" et de la sous-rubrique "Entretien professionnel".

Sheet Axe 1 Enchainement des RG
A1: Version | B1: Type de mise à jour | C1: Date de mise à jour | D1: Identifiant Domaine | E1: Libellé du Domaine | F1: Identifiant Sous-domaine | G1: Libellé du Sous-domaine | H1: Identifiant Evénement | I1: Libellé de l'évènement | J1: Libellé condition déclenchement Evènement | K1: Condition déclenchement Evènement | L1: Identifiant type d'évènement | M1: Libellé type d'évènement | N1: Type de mise à jour | O1: Libellé condition déclenchement Type Evènement | P1: Condition déclenchement Type Evènement | Q1: Libellé Population | R1: Codification Population | S1: Général / Particulier | T1: Passant / Exclu | U1: Date de début | V1: Date de fin | W1: Règles mobilisées | X1: Identifiant Règle de contrôle intellectuel 1 | Y1: Libellé Règle de contrôle intellectuel 1 | Z1: Identifiant Règle de contrôle intellectuel 2 | AA1: Libellé Règle de contrôle intellectuel 2 | AB1: Identifiant Règle de contrôle intellectuel 3 | AC1: Libellé Règle de contrôle intellectuel 3 | AD1: Identifiant Règle de contrôle intellectuel 4 | AE1: Libellé Règle de contrôle intellectuel 4 | AF1: Identifiant Règle de contrôle intellectuel 5 | AG1: Libellé Règle de contrôle intellectuel 5 | AH1: Identifiant Règle de contrôle intellectuel 6 | AI1: Libellé Règle de contrôle intellectuel 6 | AJ1: Identifiant Règle de contrôle intellectuel 7 | AK1: Libellé Règle de contrôle intellectuel 7 | AL1: Identifiant Règle de contrôle intellectuel 8 | AM1: Libellé Règle de contrôle intellectuel 8 | AN1: Identifiant Règle de contrôle intellectuel 9 | AO1: Libellé Règle de contrôle intellectuel 9 | AP1: Identifiant Règle de contrôle intellectuel 10 | AQ1: Libellé Règle de contrôle intellectuel 10 | AR1: Identifiant Règle de contrôle intellectuel 11 | AS1: Libellé Règle de contrôle intellectuel 11 | AT1: Identifiant Règle de contrôle intellectuel 12 | AU1: Libellé Règle de contrôle intellectuel 12 | AV1: Identifiant Règle de contrôle intellectuel 13 | AW1: Libellé Règle de contrôle intellectuel 13 | AX1: Identifiant Règle de contrôle intellectuel 14 | AY1: Libellé Règle de contrôle intellectuel 14 | AZ1: Identifiant Règle de contrôle intellectuel 15 | BA1: Libellé Règle de contrôle intellectuel 15 | BB1: Identifiant Règle de contrôle intellectuel 16 | BC1: Libellé Règle de contrôle intellectuel 16 | BD1: Identifiant Règle de condition 1 | BE1: Libellé Règle de condition 1 | BF1: Identifiant Règle de condition 2 | BG1: Libellé Règle de condition 2 | BH1: Identifiant Règle de contrôle 1 | BI1: Libellé Règle de contrôle 1 | BJ1: FIME | BK1: Statut de travail
A2: 20.10.00 | B2: A | C2: 44225.399 | D2: D0014 | E2: Entretien professionnel/Notation | F2: S0151 | G2: Entretien professionnel | H2: E0852 | I2: Entretien professionnel | J2: Date de l'entretien professionnel saisie différent de vide | K2: A_NEV_DAENPR [Saisi] <> vide | L2: T2108 | M2: Entretien professionnel | N2: Création Modification | Q2: Titulaire ou magistrat | R2: P0001 | S2: Général | T2: Passant | U2: 44197 | W2: NEV_I_007 ET NEV_I_002 ET NEV_I_003 ET NEV_I_004 ET NEV_I_005 ET NEV_I_006 ET NEV_I_010 ET NEV_I_011 ET NEV_I_012 ET NEV_I_013 ET NEV_I_014 ET NEV_I_015 ET NEV_I_016 ET NEV_I_017 ET NEV_I_018 ET NEV_I_019 ET NEV_C_001 | X2: NEV_I_007 | Y2: =VLOOKUP(X2,'Axe 2 Règles de gestion'!$D$2:$F$79,3, FALSE) -> L'entretien professionnel a pour objet l'appréciation de la valeur professionnelle de l'agent. Cependant les statuts particuliers peuvent prévoir des modalités différentes d'appréciation de la valeur professionnelle. | Z2: NEV_I_002 | AA2: =VLOOKUP(Z2,'Axe 2 Règles de gestion'!$D$2:$F$79,3, FALSE) -> L'entretien professionnel est annuel. | AB2: NEV_I_003 | AC2: =VLOOKUP(AB2,'Axe 2 Règles de gestion'!$D$2:$F$79,3, FALSE) -> L'entretien professionnel est conduit par le supérieur hiérarchique direct. | AD2: NEV_I_004 | AE2: =VLOOKUP(AD2,'Axe 2 Règles de gestion'!$D$2:$F$79,3, FALSE) -> Le supérieur hiérarchique direct fixe la date de l'entretien professionnel et la communique à l'agent au moins 8 jours à l'avance. | AF2: NEV_I_005 | AG2: =VLOOKUP(AF2,'Axe 2 Règles de gestion'!$D$2:$F$79,3, FALSE) -> L'entretien professionnel donne lieu à un compte rendu. | AH2: NEV_I_006 | AI2: =VLOOKUP(AH2,'Axe 2 Règles de gestion'!$D$2:$F$79,3, FALSE) -> Le compte rendu de l'entretien professionnel est établi et signé par le supérieur hiérarchique direct de l'agent. | AJ2: NEV_I_010 | AK2: =VLOOKUP(AJ2,'Axe 2 Règles de gestion'!$D$2:$F$79,3, FALSE) -> Le compte rendu est communiqué à l'agent qui le complète, si besoin, de ses observations. | AL2: NEV_I_011 | AM2: =VLOOKUP(AL2,'Axe 2 Règles de gestion'!$D$2:$F$79,3, FALSE) -> Le compte rendu est visé par l'autorité hiérarchique qui peut formuler ses propres observations. | AN2: NEV_I_012 | AO2: =VLOOKUP(AN2,'Axe 2 Règles de gestion'!$D$2:$F$79,3, FALSE) -> Le compte rendu est notifié à l'agent. | AP2: NEV_I_013 | AQ2: =VLOOKUP(AP2,'Axe 2 Règles de gestion'!$D$2:$F$79,3, FALSE) -> L'agent doit signer le compte rendu pour attester qu'il en a pris connaissance. | AR2: NEV_I_014 | AS2: =VLOOKUP(AR2,'Axe 2 Règles de gestion'!$D$2:$F$79,3, FALSE) -> L'agent doit retourner le compte rendu à l'autorité hiérarchique qui le verse à son dossier. | AT2: NEV_I_015 | AU2: =VLOOKUP(AT2,'Axe 2 Règles de gestion'!$D$2:$F$79,3, FALSE) -> L'agent peut demander à son autorité hiérarchique une révision du compte rendu dans un délai de 15 jours francs à compter de la date de notification à l'agent de ce compte rendu. | AV2: NEV_I_016 | AW2: =VLOOKUP(AV2,'Axe 2 Règles de gestion'!$D$2:$F$79,3, FALSE) -> L'autorité hiérarchique notifie sa réponse dans un délai de 15 jours francs à compter de la date de réception de la demande de révision du compte rendu. | AX2: NEV_I_017 | AY2: =VLOOKUP(AX2,'Axe 2 Règles de gestion'!$D$2:$F$79,3, FALSE) -> La commission administrative paritaire peut, à la requête de l'agent qui a exercé ce recours, demander à l'autorité hiérarchique la révision du compte rendu. | AZ2: NEV_I_018 | BA2: =VLOOKUP(AZ2,'Axe 2 Règles de gestion'!$D$2:$F$79,3, FALSE) -> La commission administrative paritaire doit être saisie dans un délai d'1 mois à compter de la date de notification de la réponse de l'autorité hiérarchique dans le cadre du recours. | BB2: NEV_I_019 | BC2: =VLOOKUP(BB2,'Axe 2 Règles de gestion'!$D$2:$F$79,3, FALSE) -> L'autorité hiérarchique communique à l'agent, qui en accuse réception, le compte rendu définitif de l'entretien professionnel. | BH2: NEV_C_001 | BI2: =VLOOKUP(BH2,'Axe 2 Règles de gestion'!$D$2:$F$79,3, FALSE) -> La date de l'entretien professionnel doit être postérieure ou égale à la date d'entrée dans la FPE ou dans la carrière militaire.
A3: 20.10.00 | B3: A | C3: 44225.4 | D3: D0014 | E3: Entretien professionnel/Notation | F3: S0151 | G3: Entretien professionnel | H3: E0852 | I3: Entretien professionnel | J3: Date de l'entretien professionnel saisie différent de vide | K3: A_NEV_DAENPR [Saisi] <> vide | L3: T2108 | M3: Entretien professionnel | N3: Création Modification | Q3: Contractuel | R3: P0003 | S3: Général | T3: Exclu | U3: 44197
A4: 20.10.00 | B4: A | C4: 44225.4 | D4: D0014 | E4: Entretien professionnel/Notation | F4: S0151 | G4: Entretien professionnel | H4: E0852 | I4: Entretien professionnel | J4: Date de l'entretien professionnel saisie différent de vide | K4: A_NEV_DAENPR [Saisi] <> vide | L4: T2108 | M4: Entretien professionnel | N4: Création Modification | Q4: Stagiaire ou auditeur ou élève | R4: P0004 | S4: Général | T4: Exclu | U4: 44197
A5: 20.10.00 | B5: A | C5: 44225.401 | D5: D0014 | E5: Entretien professionnel/Notation | F5: S0151 | G5: Entretien professionnel | H5: E0852 | I5: Entretien professionnel | J5: Date de l'entretien professionnel saisie différent de vide | K5: A_NEV_DAENPR [Saisi] <> vide | L5: T2108 | M5: Entretien professionnel | N5: Création Modification | Q5: Ouvrier d'état | R5: P0005 | S5: Général | T5: Exclu | U5: 44197
A6: 22.10.00 | B6: M | C6: 44832.702 | D6: D0014 | E6: Entretien professionnel/Notation | F6: S0151 | G6: Entretien professionnel | H6: E0852 | I6: Entretien professionnel | J6: Date de l'entretien professionnel saisie différent de vide | K6: A_NEV_DAENPR [Saisi] <> vide | L6: T2108 | M6: Entretien professionnel | N6: Création Modification | Q6: Contractuel recruté pour répondre à un besoin permanent | R6: P0104 | S6: Particulier | T6: Passant | U6: 44197 | V6: 44677 | W6: NEV_I_020 ET NEV_I_022 ET NEV_I_023 ET NEV_I_021 ET NEV_I_024 ET NEV_I_026 ET NEV_I_027 ET NEV_I_028 ET NEV_I_029 ET NEV_I_030 ET NEV_I_031 ET NEV_I_032 ET NEV_I_033 ET NEV_I_034 ET NEV_I_035 ET NEV_D_001 ET NEV_D_002 ET NEV_C_002 | X6: NEV_I_020 | Y6: =VLOOKUP(X6,'Axe 2 Règles de gestion'!$D$2:$F$79,3, FALSE) -> L'entretien professionnel est annuel. | Z6: NEV_I_022 | AA6: =VLOOKUP(Z6,'Axe 2 Règles de gestion'!$D$2:$F$79,3, FALSE) -> L'entretien professionnel est conduit par le supérieur hiérarchique direct. | AB6: NEV_I_023 | AC6: =VLOOKUP(AB6,'Axe 2 Règles de gestion'!$D$2:$F$79,3, FALSE) -> Le supérieur hiérarchique direct fixe la date de cet entretien et la communique à l'agent au moins 8 jours à l'avance. | AD6: NEV_I_021 | AE6: =VLOOKUP(AD6,'Axe 2 Règles de gestion'!$D$2:$F$79,3, FALSE) -> L'entretien professionnel donne lieu à un compte rendu. | AF6: NEV_I_024 | AG6: =VLOOKUP(AF6,'Axe 2 Règles de gestion'!$D$2:$F$79,3, FALSE) -> Le compte rendu est établi et signé par le supérieur hiérarchique direct de l'agent. | AH6: NEV_I_026 | AI6: =VLOOKUP(AH6,'Axe 2 Règles de gestion'!$D$2:$F$79,3, FALSE) -> Le compte rendu est communiqué à l'agent qui le complète, si besoin, de ses observations. | AJ6: NEV_I_027 | AK6: =VLOOKUP(AJ6,'Axe 2 Règles de gestion'!$D$2:$F$79,3, FALSE) -> Le compte rendu est visé par l'autorité hiérarchique qui peut formuler ses propres observations. | AL6: NEV_I_028 | AM6: =VLOOKUP(AL6,'Axe 2 Règles de gestion'!$D$2:$F$79,3, FALSE) -> Le compte rendu est notifié à l'agent. | AN6: NEV_I_029 | AO6: =VLOOKUP(AN6,'Axe 2 Règles de gestion'!$D$2:$F$79,3, FALSE) -> L'agent doit signer le compte rendu pour attester qu'il en a pris connaissance. | AP6: NEV_I_030 | AQ6: =VLOOKUP(AP6,'Axe 2 Règles de gestion'!$D$2:$F$79,3, FALSE) -> L'agent doit retourner le compte rendu à l'autorité hiérarchique qui le verse à son dossier. | AR6: NEV_I_031 | AS6: =VLOOKUP(AR6,'Axe 2 Règles de gestion'!$D$2:$F$79,3, FALSE) -> L'agent peut demander à son autorité hiérarchique une révision du compte rendu dans un délai de 15 jours francs à compter de la date de notification à l'agent de ce compte rendu. | AT6: NEV_I_032 | AU6: =VLOOKUP(AT6,'Axe 2 Règles de gestion'!$D$2:$F$79,3, FALSE) -> L'autorité hiérarchique notifie sa réponse dans un délai de 15 jours francs à compter de la date de réception de la demande de révision du compte rendu. | AV6: NEV_I_033 | AW6: =VLOOKUP(AV6,'Axe 2 Règles de gestion'!$D$2:$F$79,3, FALSE) -> La commission consultative paritaire peut, à la requête de l'agent qui a exercé ce recours, demander à l'autorité hiérarchique la révision du compte rendu de l'entretien professionnel. | AX6: NEV_I_034 | AY6: =VLOOKUP(AX6,'Axe 2 Règles de gestion'!$D$2:$F$79,3, FALSE) -> La commission consultative paritaire doit être saisie dans un délai d'1 mois à compter de la date de notification de la réponse de l'autorité hiérarchique dans le cadre du recours. | AZ6: NEV_I_035 | BA6: =VLOOKUP(AZ6,'Axe 2 Règles de gestion'!$D$2:$F$79,3, FALSE) -> L'autorité hiérarchique communique à l'agent, qui en accuse réception, le compte rendu définitif de l'entretien professionnel. | BD6: NEV_D_001 | BE6: =VLOOKUP(BD6,'Axe 2 Règles de gestion'!$D$2:$F$79,3, FALSE) -> L'agent est recruté en contrat à durée indéterminée ou à durée déterminée. | BF6: NEV_D_002 | BG6: =VLOOKUP(BF6,'Axe 2 Règles de gestion'!$D$2:$F$79,3, FALSE) -> Dans le cas d'un contrat à durée déterminée, il doit être d'une durée supérieure à 1 an. | BH6: NEV_C_002 | BI6: =VLOOKUP(BH6,'Axe 2 Règles de gestion'!$D$2:$F$79,3, FALSE) -> La date de l'entretien professionnel doit être postérieure ou égale à la date de début du lien juridique du contrat.
A7: 22.10.00 | B7: A | C7: 44832.703 | D7: D0014 | E7: Entretien professionnel/Notation | F7: S0151 | G7: Entretien professionnel | H7: E0852 | I7: Entretien professionnel | J7: Date de l'entretien professionnel saisie différent de vide | K7: A_NEV_DAENPR [Saisi] <> vide | L7: T2108 | M7: Entretien professionnel | N7: Création Modification | Q7: Contractuel recruté pour répondre à un besoin permanent | R7: P0104 | S7: Particulier | T7: Passant | U7: 44678 | W7: NEV_I_020 ET NEV_I_022 ET NEV_I_023 ET NEV_I_021 ET NEV_I_024 ET NEV_I_026 ET NEV_I_027 ET NEV_I_028 ET NEV_I_029 ET NEV_I_030 ET NEV_I_031 ET NEV_I_032 ET NEV_I_033 ET NEV_I_034 ET NEV_I_035 ET NEV_I_060 ET NEV_D_001 ET NEV_D_002 ET NEV_C_002 | X7: NEV_I_020 | Y7: =VLOOKUP(X7,'Axe 2 Règles de gestion'!$D$2:$F$79,3, FALSE) -> L'entretien professionnel est annuel. | Z7: NEV_I_022 | AA7: =VLOOKUP(Z7,'Axe 2 Règles de gestion'!$D$2:$F$79,3, FALSE) -> L'entretien professionnel est conduit par le supérieur hiérarchique direct. | AB7: NEV_I_023 | AC7: =VLOOKUP(AB7,'Axe 2 Règles de gestion'!$D$2:$F$79,3, FALSE) -> Le supérieur hiérarchique direct fixe la date de cet entretien et la communique à l'agent au moins 8 jours à l'avance. | AD7: NEV_I_021 | AE7: =VLOOKUP(AD7,'Axe 2 Règles de gestion'!$D$2:$F$79,3, FALSE) -> L'entretien professionnel donne lieu à un compte rendu. | AF7: NEV_I_024 | AG7: =VLOOKUP(AF7,'Axe 2 Règles de gestion'!$D$2:$F$79,3, FALSE) -> Le compte rendu est établi et signé par le supérieur hiérarchique direct de l'agent. | AH7: NEV_I_026 | AI7: =VLOOKUP(AH7,'Axe 2 Règles de gestion'!$D$2:$F$79,3, FALSE) -> Le compte rendu est communiqué à l'agent qui le complète, si besoin, de ses observations. | AJ7: NEV_I_027 | AK7: =VLOOKUP(AJ7,'Axe 2 Règles de gestion'!$D$2:$F$79,3, FALSE) -> Le compte rendu est visé par l'autorité hiérarchique qui peut formuler ses propres observations. | AL7: NEV_I_028 | AM7: =VLOOKUP(AL7,'Axe 2 Règles de gestion'!$D$2:$F$79,3, FALSE) -> Le compte rendu est notifié à l'agent. | AN7: NEV_I_029 | AO7: =VLOOKUP(AN7,'Axe 2 Règles de gestion'!$D$2:$F$79,3, FALSE) -> L'agent doit signer le compte rendu pour attester qu'il en a pris connaissance. | AP7: NEV_I_030 | AQ7: =VLOOKUP(AP7,'Axe 2 Règles de gestion'!$D$2:$F$79,3, FALSE) -> L'agent doit retourner le compte rendu à l'autorité hiérarchique qui le verse à son dossier. | AR7: NEV_I_031 | AS7: =VLOOKUP(AR7,'Axe 2 Règles de gestion'!$D$2:$F$79,3, FALSE) -> L'agent peut demander à son autorité hiérarchique une révision du compte rendu dans un délai de 15 jours francs à compter de la date de notification à l'agent de ce compte rendu. | AT7: NEV_I_032 | AU7: =VLOOKUP(AT7,'Axe 2 Règles de gestion'!$D$2:$F$79,3, FALSE) -> L'autorité hiérarchique notifie sa réponse dans un délai de 15 jours francs à compter de la date de réception de la demande de révision du compte rendu. | AV7: NEV_I_033 | AW7: =VLOOKUP(AV7,'Axe 2 Règles de gestion'!$D$2:$F$79,3, FALSE) -> La commission consultative paritaire peut, à la requête de l'agent qui a exercé ce recours, demander à l'autorité hiérarchique la révision du compte rendu de l'entretien professionnel. | AX7: NEV_I_034 | AY7: =VLOOKUP(AX7,'Axe 2 Règles de gestion'!$D$2:$F$79,3, FALSE) -> La commission consultative paritaire doit être saisie dans un délai d'1 mois à compter de la date de notification de la réponse de l'autorité hiérarchique dans le cadre du recours. | AZ7: NEV_I_035 | BA7: =VLOOKUP(AZ7,'Axe 2 Règles de gestion'!$D$2:$F$79,3, FALSE) -> L'autorité hiérarchique communique à l'agent, qui en accuse réception, le compte rendu définitif de l'entretien professionnel. | BB7: NEV_I_060 | BC7: =VLOOKUP(BB7,'Axe 2 Règles de gestion'!$D$2:$F$79,3, FALSE) -> La décision relative à la révision du compte rendu de l'entretien professionnel fait l'objet d'une consultation de la commission consultative paritaire. | BD7: NEV_D_001 | BE7: =VLOOKUP(BD7,'Axe 2 Règles de gestion'!$D$2:$F$79,3, FALSE) -> L'agent est recruté en contrat à durée indéterminée ou à durée déterminée. | BF7: NEV_D_002 | BG7: =VLOOKUP(BF7,'Axe 2 Règles de gestion'!$D$2:$F$79,3, FALSE) -> Dans le cas d'un contrat à durée déterminée, il doit être d'une durée supérieure à 1 an. | BH7: NEV_C_002 | BI7: =VLOOKUP(BH7,'Axe 2 Règles de gestion'!$D$2:$F$79,3, FALSE) -> La date de l'entretien professionnel doit être postérieure ou égale à la date de début du lien juridique du contrat.
A8: 25.10.00 | B8: A | C8: 46002.497 | D8: D0014 | E8: Entretien professionnel/Notation | F8: S0151 | G8: Entretien professionnel | H8: E0852 | I8: Entretien professionnel | J8: Date de l'entretien professionnel saisie différent de vide | K8: A_NEV_DAENPR [Saisi] <> vide | L8: T2108 | M8: Entretien professionnel | N8: Création Modification | Q8: Ouvrier des parcs et ateliers confirmé ou stagiaire | R8: P0143 | S8: Particulier | T8: Passant | U8: 45901 | W8: NEV_I_051 ET NEV_I_020 ET NEV_I_022 ET NEV_I_023 ET NEV_I_021 ET NEV_I_024 ET NEV_I_026 ET NEV_I_027 ET NEV_I_028 ET NEV_I_029 ET NEV_I_030 ET NEV_I_031 ET NEV_I_032 ET NEV_I_052 ET NEV_I_035 ET NEV_D_001 ET NEV_D_002 ET NEV_C_002 | X8: NEV_I_051 | Y8: =VLOOKUP(X8,'Axe 2 Règles de gestion'!$D$2:$F$79,3, FALSE) -> L'agent bénéficie, sauf dispositions particulières, des dispositions applicables aux agents contractuels recrutés pour répondre à un besoin permanent pour l'entretien professionnel. | Z8: NEV_I_020 | AA8: =VLOOKUP(Z8,'Axe 2 Règles de gestion'!$D$2:$F$79,3, FALSE) -> L'entretien professionnel est annuel. | AB8: NEV_I_022 | AC8: =VLOOKUP(AB8,'Axe 2 Règles de gestion'!$D$2:$F$79,3, FALSE) -> L'entretien professionnel est conduit par le supérieur hiérarchique direct. | AD8: NEV_I_023 | AE8: =VLOOKUP(AD8,'Axe 2 Règles de gestion'!$D$2:$F$79,3, FALSE) -> Le supérieur hiérarchique direct fixe la date de cet entretien et la communique à l'agent au moins 8 jours à l'avance. | AF8: NEV_I_021 | AG8: =VLOOKUP(AF8,'Axe 2 Règles de gestion'!$D$2:$F$79,3, FALSE) -> L'entretien professionnel donne lieu à un compte rendu. | AH8: NEV_I_024 | AI8: =VLOOKUP(AH8,'Axe 2 Règles de gestion'!$D$2:$F$79,3, FALSE) -> Le compte rendu est établi et signé par le supérieur hiérarchique direct de l'agent. | AJ8: NEV_I_026 | AK8: =VLOOKUP(AJ8,'Axe 2 Règles de gestion'!$D$2:$F$79,3, FALSE) -> Le compte rendu est communiqué à l'agent qui le complète, si besoin, de ses observations. | AL8: NEV_I_027 | AM8: =VLOOKUP(AL8,'Axe 2 Règles de gestion'!$D$2:$F$79,3, FALSE) -> Le compte rendu est visé par l'autorité hiérarchique qui peut formuler ses propres observations. | AN8: NEV_I_028 | AO8: =VLOOKUP(AN8,'Axe 2 Règles de gestion'!$D$2:$F$79,3, FALSE) -> Le compte rendu est notifié à l'agent. | AP8: NEV_I_029 | AQ8: =VLOOKUP(AP8,'Axe 2 Règles de gestion'!$D$2:$F$79,3, FALSE) -> L'agent doit signer le compte rendu pour attester qu'il en a pris connaissance. | AR8: NEV_I_030 | AS8: =VLOOKUP(AR8,'Axe 2 Règles de gestion'!$D$2:$F$79,3, FALSE) -> L'agent doit retourner le compte rendu à l'autorité hiérarchique qui le verse à son dossier. | AT8: NEV_I_031 | AU8: =VLOOKUP(AT8,'Axe 2 Règles de gestion'!$D$2:$F$79,3, FALSE) -> L'agent peut demander à son autorité hiérarchique une révision du compte rendu dans un délai de 15 jours francs à compter de la date de notification à l'agent de ce compte rendu. | AV8: NEV_I_032 | AW8: =VLOOKUP(AV8,'Axe 2 Règles de gestion'!$D$2:$F$79,3, FALSE) -> L'autorité hiérarchique notifie sa réponse dans un délai de 15 jours francs à compter de la date de réception de la demande de révision du compte rendu. | AX8: NEV_I_052 | AY8: =VLOOKUP(AX8,'Axe 2 Règles de gestion'!$D$2:$F$79,3, FALSE) -> La commission consultative est consultée pour la révision du compte-rendu de l'entretien professionnel. | AZ8: NEV_I_035 | BA8: =VLOOKUP(AZ8,'Axe 2 Règles de gestion'!$D$2:$F$79,3, FALSE) -> L'autorité hiérarchique communique à l'agent, qui en accuse réception, le compte rendu définitif de l'entretien professionnel. | BD8: NEV_D_001 | BE8: =VLOOKUP(BD8,'Axe 2 Règles de gestion'!$D$2:$F$79,3, FALSE) -> L'agent est recruté en contrat à durée indéterminée ou à durée déterminée. | BF8: NEV_D_002 | BG8: =VLOOKUP(BF8,'Axe 2 Règles de gestion'!$D$2:$F$79,3, FALSE) -> Dans le cas d'un contrat à durée déterminée, il doit être d'une durée supérieure à 1 an. | BH8: NEV_C_002 | BI8: =VLOOKUP(BH8,'Axe 2 Règles de gestion'!$D$2:$F$79,3, FALSE) -> La date de l'entretien professionnel doit être postérieure ou égale à la date de début du lien juridique du contrat. | BJ8: 2025-121
A9: 20.10.00 | B9: A | C9: 44225.403 | D9: D0014 | E9: Entretien professionnel/Notation | F9: S0151 | G9: Entretien professionnel | H9: E0852 | I9: Entretien professionnel | J9: Date de l'entretien professionnel saisie différent de vide | K9: A_NEV_DAENPR [Saisi] <> vide | L9: T2108 | M9: Entretien professionnel | N9: Création Modification | Q9: Contractuel sous contrat PACTE | R9: P0166 | S9: Particulier | T9: Exclu | U9: 44197
A10: 22.10.00 | B10: M | C10: 44832.703 | D10: D0014 | E10: Entretien professionnel/Notation | F10: S0151 | G10: Entretien professionnel | H10: E0852 | I10: Entretien professionnel | J10: Date de l'entretien professionnel saisie différent de vide | K10: A_NEV_DAENPR [Saisi] <> vide | L10: T2108 | M10: Entretien professionnel | N10: Création Modification | Q10: Contractuel recruté sur contrat de projet | R10: P0241 | S10: Particulier | T10: Passant | U10: 44197 | V10: 44677 | W10: NEV_I_036 ET NEV_I_038 ET NEV_I_039 ET NEV_I_037 ET NEV_I_040 ET NEV_I_041 ET NEV_I_042 ET NEV_I_043 ET NEV_I_044 ET NEV_I_045 ET NEV_I_046 ET NEV_I_047 ET NEV_I_048 ET NEV_I_049 ET NEV_I_050 ET NEV_C_002 | X10: NEV_I_036 | Y10: =VLOOKUP(X10,'Axe 2 Règles de gestion'!$D$2:$F$79,3, FALSE) -> L'entretien professionnel est annuel. | Z10: NEV_I_038 | AA10: =VLOOKUP(Z10,'Axe 2 Règles de gestion'!$D$2:$F$79,3, FALSE) -> L'entretien professionnel est conduit par le supérieur hiérarchique direct. | AB10: NEV_I_039 | AC10: =VLOOKUP(AB10,'Axe 2 Règles de gestion'!$D$2:$F$79,3, FALSE) -> Le supérieur hiérarchique direct fixe la date de cet entretien et la communique à l'agent au moins 8 jours à l'avance. | AD10: NEV_I_037 | AE10: =VLOOKUP(AD10,'Axe 2 Règles de gestion'!$D$2:$F$79,3, FALSE) -> L'entretien professionnel donne lieu à un compte rendu. | AF10: NEV_I_040 | AG10: =VLOOKUP(AF10,'Axe 2 Règles de gestion'!$D$2:$F$79,3, FALSE) -> Le compte rendu est établi et signé par le supérieur hiérarchique direct de l'agent. | AH10: NEV_I_041 | AI10: =VLOOKUP(AH10,'Axe 2 Règles de gestion'!$D$2:$F$79,3, FALSE) -> Le compte rendu est communiqué à l'agent qui le complète, si besoin, de ses observations. | AJ10: NEV_I_042 | AK10: =VLOOKUP(AJ10,'Axe 2 Règles de gestion'!$D$2:$F$79,3, FALSE) -> Le compte rendu est visé par l'autorité hiérarchique qui peut formuler ses propres observations. | AL10: NEV_I_043 | AM10: =VLOOKUP(AL10,'Axe 2 Règles de gestion'!$D$2:$F$79,3, FALSE) -> Le compte rendu est notifié à l'agent. | AN10: NEV_I_044 | AO10: =VLOOKUP(AN10,'Axe 2 Règles de gestion'!$D$2:$F$79,3, FALSE) -> L'agent doit signer le compte rendu pour attester qu'il en a pris connaissance. | AP10: NEV_I_045 | AQ10: =VLOOKUP(AP10,'Axe 2 Règles de gestion'!$D$2:$F$79,3, FALSE) -> L'agent doit retourner le compte rendu à l'autorité hiérarchique qui le verse à son dossier. | AR10: NEV_I_046 | AS10: =VLOOKUP(AR10,'Axe 2 Règles de gestion'!$D$2:$F$79,3, FALSE) -> L'agent peut demander à son autorité hiérarchique une révision du compte rendu dans un délai de 15 jours francs à compter de la date de notification à l'agent de ce compte rendu. | AT10: NEV_I_047 | AU10: =VLOOKUP(AT10,'Axe 2 Règles de gestion'!$D$2:$F$79,3, FALSE) -> L'autorité hiérarchique notifie sa réponse dans un délai de 15 jours francs à compter de la date de réception de la demande de révision du compte rendu. | AV10: NEV_I_048 | AW10: =VLOOKUP(AV10,'Axe 2 Règles de gestion'!$D$2:$F$79,3, FALSE) -> La commission consultative paritaire peut, à la requête de l'agent qui a exercé ce recours, demander à l'autorité hiérarchique la révision du compte rendu de l'entretien professionnel. | AX10: NEV_I_049 | AY10: =VLOOKUP(AX10,'Axe 2 Règles de gestion'!$D$2:$F$79,3, FALSE) -> La commission consultative paritaire doit être saisie dans un délai d'1 mois à compter de la date de notification de la réponse de l'autorité hiérarchique dans le cadre du recours. | AZ10: NEV_I_050 | BA10: =VLOOKUP(AZ10,'Axe 2 Règles de gestion'!$D$2:$F$79,3, FALSE) -> L'autorité hiérarchique communique à l'agent, qui en accuse réception, le compte rendu définitif de l'entretien professionnel. | BH10: NEV_C_002 | BI10: =VLOOKUP(BH10,'Axe 2 Règles de gestion'!$D$2:$F$79,3, FALSE) -> La date de l'entretien professionnel doit être postérieure ou égale à la date de début du lien juridique du contrat.
A11: 22.10.00 | B11: A | C11: 44832.706 | D11: D0014 | E11: Entretien professionnel/Notation | F11: S0151 | G11: Entretien professionnel | H11: E0852 | I11: Entretien professionnel | J11: Date de l'entretien professionnel saisie différent de vide | K11: A_NEV_DAENPR [Saisi] <> vide | L11: T2108 | M11: Entretien professionnel | N11: Création Modification | Q11: Contractuel recruté sur contrat de projet | R11: P0241 | S11: Particulier | T11: Passant | U11: 44678 | W11: NEV_I_036 ET NEV_I_038 ET NEV_I_039 ET NEV_I_037 ET NEV_I_040 ET NEV_I_041 ET NEV_I_042 ET NEV_I_043 ET NEV_I_044 ET NEV_I_045 ET NEV_I_046 ET NEV_I_047 ET NEV_I_061 ET NEV_I_048 ET NEV_I_049 ET NEV_I_050 ET NEV_C_002 | X11: NEV_I_036 | Y11: =VLOOKUP(X11,'Axe 2 Règles de gestion'!$D$2:$F$79,3, FALSE) -> L'entretien professionnel est annuel. | Z11: NEV_I_038 | AA11: =VLOOKUP(Z11,'Axe 2 Règles de gestion'!$D$2:$F$79,3, FALSE) -> L'entretien professionnel est conduit par le supérieur hiérarchique direct. | AB11: NEV_I_039 | AC11: =VLOOKUP(AB11,'Axe 2 Règles de gestion'!$D$2:$F$79,3, FALSE) -> Le supérieur hiérarchique direct fixe la date de cet entretien et la communique à l'agent au moins 8 jours à l'avance. | AD11: NEV_I_037 | AE11: =VLOOKUP(AD11,'Axe 2 Règles de gestion'!$D$2:$F$79,3, FALSE) -> L'entretien professionnel donne lieu à un compte rendu. | AF11: NEV_I_040 | AG11: =VLOOKUP(AF11,'Axe 2 Règles de gestion'!$D$2:$F$79,3, FALSE) -> Le compte rendu est établi et signé par le supérieur hiérarchique direct de l'agent. | AH11: NEV_I_041 | AI11: =VLOOKUP(AH11,'Axe 2 Règles de gestion'!$D$2:$F$79,3, FALSE) -> Le compte rendu est communiqué à l'agent qui le complète, si besoin, de ses observations. | AJ11: NEV_I_042 | AK11: =VLOOKUP(AJ11,'Axe 2 Règles de gestion'!$D$2:$F$79,3, FALSE) -> Le compte rendu est visé par l'autorité hiérarchique qui peut formuler ses propres observations. | AL11: NEV_I_043 | AM11: =VLOOKUP(AL11,'Axe 2 Règles de gestion'!$D$2:$F$79,3, FALSE) -> Le compte rendu est notifié à l'agent. | AN11: NEV_I_044 | AO11: =VLOOKUP(AN11,'Axe 2 Règles de gestion'!$D$2:$F$79,3, FALSE) -> L'agent doit signer le compte rendu pour attester qu'il en a pris connaissance. | AP11: NEV_I_045 | AQ11: =VLOOKUP(AP11,'Axe 2 Règles de gestion'!$D$2:$F$79,3, FALSE) -> L'agent doit retourner le compte rendu à l'autorité hiérarchique qui le verse à son dossier. | AR11: NEV_I_046 | AS11: =VLOOKUP(AR11,'Axe 2 Règles de gestion'!$D$2:$F$79,3, FALSE) -> L'agent peut demander à son autorité hiérarchique une révision du compte rendu dans un délai de 15 jours francs à compter de la date de notification à l'agent de ce compte rendu. | AT11: NEV_I_047 | AU11: =VLOOKUP(AT11,'Axe 2 Règles de gestion'!$D$2:$F$79,3, FALSE) -> L'autorité hiérarchique notifie sa réponse dans un délai de 15 jours francs à compter de la date de réception de la demande de révision du compte rendu. | AV11: NEV_I_061 | AW11: =VLOOKUP(AV11,'Axe 2 Règles de gestion'!$D$2:$F$79,3, FALSE) -> La décision relative à la révision du compte rendu de l'entretien professionnel fait l'objet d'une consultation de la commission consultative paritaire. | AX11: NEV_I_048 | AY11: =VLOOKUP(AX11,'Axe 2 Règles de gestion'!$D$2:$F$79,3, FALSE) -> La commission consultative paritaire peut, à la requête de l'agent qui a exercé ce recours, demander à l'autorité hiérarchique la révision du compte rendu de l'entretien professionnel. | AZ11: NEV_I_049 | BA11: =VLOOKUP(AZ11,'Axe 2 Règles de gestion'!$D$2:$F$79,3, FALSE) -> La commission consultative paritaire doit être saisie dans un délai d'1 mois à compter de la date de notification de la réponse de l'autorité hiérarchique dans le cadre du recours. | BB11: NEV_I_050 | BC11: =VLOOKUP(BB11,'Axe 2 Règles de gestion'!$D$2:$F$79,3, FALSE) -> L'autorité hiérarchique communique à l'agent, qui en accuse réception, le compte rendu définitif de l'entretien professionnel. | BH11: NEV_C_002 | BI11: =VLOOKUP(BH11,'Axe 2 Règles de gestion'!$D$2:$F$79,3, FALSE) -> La date de l'entretien professionnel doit être postérieure ou égale à la date de début du lien juridique du contrat.
A12: 25.10.00 | B12: A | C12: 45917.712 | D12: D0014 | E12: Entretien professionnel/Notation | F12: S0151 | G12: Entretien professionnel | H12: E1021 | I12: Entretien annuel d'accompagnement | L12: T2464 | M12: Entretien d'accompagnement | N12: Création Modification | Q12: Titulaire ou magistrat | R12: P0001 | S12: Général | T12: Passant | U12: 45689 | W12: NEV_I_062 ET NEV_I_063 ET NEV_I_064 ET NEV_I_065 ET NEV_I_066 ET NEV_I_067 ET NEV_I_068 ET NEV_I_069 ET NEV_I_070 ET NEV_I_071 ET NEV_I_072 ET NEV_I_073 ET NEV_I_074 ET NEV_I_075 ET NEV_I_076 | X12: NEV_I_062 | Y12: =VLOOKUP(X12,'Axe 2 Règles de gestion'!$D$2:$F$79,3, FALSE) -> L'agent est en décharge d'activité de services à titre syndical. | Z12: NEV_I_063 | AA12: =VLOOKUP(Z12,'Axe 2 Règles de gestion'!$D$2:$F$79,3, FALSE) -> L'agent peut bénéficier, sur demande, d'un entretien annuel d'accompagnement. | AB12: NEV_I_064 | AC12: =VLOOKUP(AB12,'Axe 2 Règles de gestion'!$D$2:$F$79,3, FALSE) -> L'agent consacrant l'intégralité de son service à une activité syndicale bénéficie, de droit, d'un entretien annuel d'accompagnement intervenant avant le terme de sa décharge d'activité de service. | AD12: NEV_I_065 | AE12: =VLOOKUP(AD12,'Axe 2 Règles de gestion'!$D$2:$F$79,3, FALSE) -> L'entretien annuel est conduit par le responsable des ressources humaines du service ou de l'établissement de l'agent. | AF12: NEV_I_066 | AG12: =VLOOKUP(AF12,'Axe 2 Règles de gestion'!$D$2:$F$79,3, FALSE) -> Le responsable des ressources humaines fixe la date de l'entretien d'accompagnement et la communique à l'agent par tout moyen conférant date certaine. | AH12: NEV_I_067 | AI12: =VLOOKUP(AH12,'Axe 2 Règles de gestion'!$D$2:$F$79,3, FALSE) -> L'entretien d'accompagnement ne peut avoir lieu moins de 8 jours ouvrables après la réception de la convocation. | AJ12: NEV_I_068 | AK12: =VLOOKUP(AJ12,'Axe 2 Règles de gestion'!$D$2:$F$79,3, FALSE) -> L'entretien d'accompagnement porte sur les acquis de l'expérience professionnelle dont ceux résultant d'activités syndicales, les besoins de formation professionnelle et les perspectives d'évolution professionnelle en termes de carrière et de mobilité. | AL12: NEV_I_069 | AM12: =VLOOKUP(AL12,'Axe 2 Règles de gestion'!$D$2:$F$79,3, FALSE) -> Le compte rendu est établi, signé et adressé par le responsable des ressources humaines à l'agent dans un délai maximal d'1 mois. | AN12: NEV_I_070 | AO12: =VLOOKUP(AN12,'Axe 2 Règles de gestion'!$D$2:$F$79,3, FALSE) -> Le compte rendu ne peut comporter aucune appréciation de la valeur professionnelle de l'agent. | AP12: NEV_I_071 | AQ12: =VLOOKUP(AP12,'Axe 2 Règles de gestion'!$D$2:$F$79,3, FALSE) -> Le compte rendu de l'entretien d'accompagnement se substitue au compte rendu de l'entretien professionnel si l'agent ne bénéficie pas d'un entretien de suivi. | AR12: NEV_I_072 | AS12: =VLOOKUP(AR12,'Axe 2 Règles de gestion'!$D$2:$F$79,3, FALSE) -> Le compte rendu est communiqué à l'agent qui le complète, si besoin, de ses observations. | AT12: NEV_I_073 | AU12: =VLOOKUP(AT12,'Axe 2 Règles de gestion'!$D$2:$F$79,3, FALSE) -> Le compte rendu est signé par le responsable des ressources humaines qui peut formuler, si besoin, ses propres observations. | AV12: NEV_I_074 | AW12: =VLOOKUP(AV12,'Axe 2 Règles de gestion'!$D$2:$F$79,3, FALSE) -> Le compte rendu est notifié à l'agent. | AX12: NEV_I_075 | AY12: =VLOOKUP(AX12,'Axe 2 Règles de gestion'!$D$2:$F$79,3, FALSE) -> L'agent doit signer le compte rendu pour attester qu'il en a pris connaissance. | AZ12: NEV_I_076 | BA12: =VLOOKUP(AZ12,'Axe 2 Règles de gestion'!$D$2:$F$79,3, FALSE) -> L'agent doit retourner le compte rendu au responsable des ressources humaines qui le verse à son dossier. | BJ12: 2025-77
A13: 25.10.00 | B13: A | C13: 45917.715 | D13: D0014 | E13: Entretien professionnel/Notation | F13: S0151 | G13: Entretien professionnel | H13: E1021 | I13: Entretien annuel d'accompagnement | L13: T2464 | M13: Entretien d'accompagnement | N13: Création Modification | Q13: Contractuel | R13: P0003 | S13: Général | T13: Passant | U13: 45689 | W13: NEV_I_062 ET NEV_I_063 ET NEV_I_064 ET NEV_I_065 ET NEV_I_066 ET NEV_I_067 ET NEV_I_068 ET NEV_I_069 ET NEV_I_070 ET NEV_I_071 ET NEV_I_072 ET NEV_I_073 ET NEV_I_074 ET NEV_I_075 ET NEV_I_076 | X13: NEV_I_062 | Y13: =VLOOKUP(X13,'Axe 2 Règles de gestion'!$D$2:$F$79,3, FALSE) -> L'agent est en décharge d'activité de services à titre syndical. | Z13: NEV_I_063 | AA13: =VLOOKUP(Z13,'Axe 2 Règles de gestion'!$D$2:$F$79,3, FALSE) -> L'agent peut bénéficier, sur demande, d'un entretien annuel d'accompagnement. | AB13: NEV_I_064 | AC13: =VLOOKUP(AB13,'Axe 2 Règles de gestion'!$D$2:$F$79,3, FALSE) -> L'agent consacrant l'intégralité de son service à une activité syndicale bénéficie, de droit, d'un entretien annuel d'accompagnement intervenant avant le terme de sa décharge d'activité de service. | AD13: NEV_I_065 | AE13: =VLOOKUP(AD13,'Axe 2 Règles de gestion'!$D$2:$F$79,3, FALSE) -> L'entretien annuel est conduit par le responsable des ressources humaines du service ou de l'établissement de l'agent. | AF13: NEV_I_066 | AG13: =VLOOKUP(AF13,'Axe 2 Règles de gestion'!$D$2:$F$79,3, FALSE) -> Le responsable des ressources humaines fixe la date de l'entretien d'accompagnement et la communique à l'agent par tout moyen conférant date certaine. | AH13: NEV_I_067 | AI13: =VLOOKUP(AH13,'Axe 2 Règles de gestion'!$D$2:$F$79,3, FALSE) -> L'entretien d'accompagnement ne peut avoir lieu moins de 8 jours ouvrables après la réception de la convocation. | AJ13: NEV_I_068 | AK13: =VLOOKUP(AJ13,'Axe 2 Règles de gestion'!$D$2:$F$79,3, FALSE) -> L'entretien d'accompagnement porte sur les acquis de l'expérience professionnelle dont ceux résultant d'activités syndicales, les besoins de formation professionnelle et les perspectives d'évolution professionnelle en termes de carrière et de mobilité. | AL13: NEV_I_069 | AM13: =VLOOKUP(AL13,'Axe 2 Règles de gestion'!$D$2:$F$79,3, FALSE) -> Le compte rendu est établi, signé et adressé par le responsable des ressources humaines à l'agent dans un délai maximal d'1 mois. | AN13: NEV_I_070 | AO13: =VLOOKUP(AN13,'Axe 2 Règles de gestion'!$D$2:$F$79,3, FALSE) -> Le compte rendu ne peut comporter aucune appréciation de la valeur professionnelle de l'agent. | AP13: NEV_I_071 | AQ13: =VLOOKUP(AP13,'Axe 2 Règles de gestion'!$D$2:$F$79,3, FALSE) -> Le compte rendu de l'entretien d'accompagnement se substitue au compte rendu de l'entretien professionnel si l'agent ne bénéficie pas d'un entretien de suivi. | AR13: NEV_I_072 | AS13: =VLOOKUP(AR13,'Axe 2 Règles de gestion'!$D$2:$F$79,3, FALSE) -> Le compte rendu est communiqué à l'agent qui le complète, si besoin, de ses observations. | AT13: NEV_I_073 | AU13: =VLOOKUP(AT13,'Axe 2 Règles de gestion'!$D$2:$F$79,3, FALSE) -> Le compte rendu est signé par le responsable des ressources humaines qui peut formuler, si besoin, ses propres observations. | AV13: NEV_I_074 | AW13: =VLOOKUP(AV13,'Axe 2 Règles de gestion'!$D$2:$F$79,3, FALSE) -> Le compte rendu est notifié à l'agent. | AX13: NEV_I_075 | AY13: =VLOOKUP(AX13,'Axe 2 Règles de gestion'!$D$2:$F$79,3, FALSE) -> L'agent doit signer le compte rendu pour attester qu'il en a pris connaissance. | AZ13: NEV_I_076 | BA13: =VLOOKUP(AZ13,'Axe 2 Règles de gestion'!$D$2:$F$79,3, FALSE) -> L'agent doit retourner le compte rendu au responsable des ressources humaines qui le verse à son dossier. | BJ13: 2025-77
A14: 25.10.00 | B14: A | C14: 45917.719 | D14: D0014 | E14: Entretien professionnel/Notation | F14: S0151 | G14: Entretien professionnel | H14: E1021 | I14: Entretien annuel d'accompagnement | L14: T2464 | M14: Entretien d'accompagnement | N14: Création Modification | Q14: Stagiaire ou auditeur ou élève | R14: P0004 | S14: Général | T14: Exclu | U14: 45689 | BJ14: 2025-77
A15: 25.10.00 | B15: A | C15: 45917.715 | D15: D0014 | E15: Entretien professionnel/Notation | F15: S0151 | G15: Entretien professionnel | H15: E1021 | I15: Entretien annuel d'accompagnement | L15: T2464 | M15: Entretien d'accompagnement | N15: Création Modification | Q15: Ouvrier d'état | R15: P0005 | S15: Général | T15: Exclu | U15: 45689 | BJ15: 2025-77
A16: 25.10.00 | B16: A | C16: 45917.716 | D16: D0014 | E16: Entretien professionnel/Notation | F16: S0151 | G16: Entretien professionnel | H16: E1021 | I16: Entretien annuel d'accompagnement | L16: T2464 | M16: Entretien d'accompagnement | N16: Création Modification | Q16: Contractuel à temps incomplet | R16: P0067 | S16: Particulier | T16: Exclu | U16: 45689 | BJ16: 2025-77
A17: 25.10.00 | B17: A | C17: 45917.716 | D17: D0014 | E17: Entretien professionnel/Notation | F17: S0151 | G17: Entretien professionnel | H17: E1022 | I17: Entretien annuel de suivi | L17: T2465 | M17: Entretien de suivi | N17: Création Modification | Q17: Titulaire ou magistrat | R17: P0001 | S17: Général | T17: Passant | U17: 45689 | W17: NEV_I_062 ET NEV_I_077 ET NEV_I_078 ET NEV_I_079 ET NEV_I_080 ET NEV_I_081 ET NEV_I_082 ET NEV_I_083 ET NEV_I_084 ET NEV_I_085 | X17: NEV_I_062 | Y17: =VLOOKUP(X17,'Axe 2 Règles de gestion'!$D$2:$F$79,3, FALSE) -> L'agent est en décharge d'activité de services à titre syndical. | Z17: NEV_I_077 | AA17: =VLOOKUP(Z17,'Axe 2 Règles de gestion'!$D$2:$F$79,3, FALSE) -> L'agent consacre une quotité de temps de travail au moins égale à 70% et inférieure à 100% d'un service à temps plein à une activité syndicale. | AB17: NEV_I_078 | AC17: =VLOOKUP(AB17,'Axe 2 Règles de gestion'!$D$2:$F$79,3, FALSE) -> L'agent bénéficie d'un entretien annuel de suivi conduit par son supérieur hiérarchique direct, sans être soumis à une appréciation de sa valeur professionnelle. | AD17: NEV_I_079 | AE17: =VLOOKUP(AD17,'Axe 2 Règles de gestion'!$D$2:$F$79,3, FALSE) -> L'entretien de suivi n'a pas lieu lorsque les dispositions du statut particulier du corps d'origine prévoient le maintien d'un système de notation. | AF17: NEV_I_080 | AG17: =VLOOKUP(AF17,'Axe 2 Règles de gestion'!$D$2:$F$79,3, FALSE) -> L'entretien de suivi porte sur les acquis de l'expérience professionnelle dont ceux résultant d'activités syndicales, les besoins de formation professionnelle et les perspectives d'évolution professionnelle en termes de carrière et de mobilité. | AH17: NEV_I_081 | AI17: =VLOOKUP(AH17,'Axe 2 Règles de gestion'!$D$2:$F$79,3, FALSE) -> Le supérieur hiérarchique direct communique à l'agent la date de l'entretien au moins 8 jours à l'avance et le convoque par tout moyen conférant date certaine. | AJ17: NEV_I_082 | AK17: =VLOOKUP(AJ17,'Axe 2 Règles de gestion'!$D$2:$F$79,3, FALSE) -> Le compte rendu est établi, signé et adressé par le supérieur hiérarchique à l'agent qui le complète, si besoin, de ses observations. | AL17: NEV_I_083 | AM17: =VLOOKUP(AL17,'Axe 2 Règles de gestion'!$D$2:$F$79,3, FALSE) -> L'agent doit signer le compte rendu, éventuellement complété des observations de son supérieur, pour attester en avoir pris connaissance. | AN17: NEV_I_084 | AO17: =VLOOKUP(AN17,'Axe 2 Règles de gestion'!$D$2:$F$79,3, FALSE) -> L'agent doit retourner le compte rendu à son supérieur hiérarchique qui le verse à son dossier. | AP17: NEV_I_085 | AQ17: =VLOOKUP(AP17,'Axe 2 Règles de gestion'!$D$2:$F$79,3, FALSE) -> L'entretien ne concerne pas l'agent appartenant aux corps d'inspection pédagogique, de direction d'établissement d'enseignement, d'enseignants, d'éducation, de psychologues de l'éducation nationale, de chercheurs, d'enseignants-chercheurs ou assimilés. | BJ17: 2025-77
A18: 25.10.00 | B18: A | C18: 45917.717 | D18: D0014 | E18: Entretien professionnel/Notation | F18: S0151 | G18: Entretien professionnel | H18: E1022 | I18: Entretien annuel de suivi | L18: T2465 | M18: Entretien de suivi | N18: Création Modification | Q18: Contractuel | R18: P0003 | S18: Général | T18: Passant | U18: 45689 | W18: NEV_I_062 ET NEV_I_077 ET NEV_I_078 ET NEV_I_079 ET NEV_I_080 ET NEV_I_081 ET NEV_I_082 ET NEV_I_083 ET NEV_I_084 ET NEV_I_085 | X18: NEV_I_062 | Y18: =VLOOKUP(X18,'Axe 2 Règles de gestion'!$D$2:$F$79,3, FALSE) -> L'agent est en décharge d'activité de services à titre syndical. | Z18: NEV_I_077 | AA18: =VLOOKUP(Z18,'Axe 2 Règles de gestion'!$D$2:$F$79,3, FALSE) -> L'agent consacre une quotité de temps de travail au moins égale à 70% et inférieure à 100% d'un service à temps plein à une activité syndicale. | AB18: NEV_I_078 | AC18: =VLOOKUP(AB18,'Axe 2 Règles de gestion'!$D$2:$F$79,3, FALSE) -> L'agent bénéficie d'un entretien annuel de suivi conduit par son supérieur hiérarchique direct, sans être soumis à une appréciation de sa valeur professionnelle. | AD18: NEV_I_079 | AE18: =VLOOKUP(AD18,'Axe 2 Règles de gestion'!$D$2:$F$79,3, FALSE) -> L'entretien de suivi n'a pas lieu lorsque les dispositions du statut particulier du corps d'origine prévoient le maintien d'un système de notation. | AF18: NEV_I_080 | AG18: =VLOOKUP(AF18,'Axe 2 Règles de gestion'!$D$2:$F$79,3, FALSE) -> L'entretien de suivi porte sur les acquis de l'expérience professionnelle dont ceux résultant d'activités syndicales, les besoins de formation professionnelle et les perspectives d'évolution professionnelle en termes de carrière et de mobilité. | AH18: NEV_I_081 | AI18: =VLOOKUP(AH18,'Axe 2 Règles de gestion'!$D$2:$F$79,3, FALSE) -> Le supérieur hiérarchique direct communique à l'agent la date de l'entretien au moins 8 jours à l'avance et le convoque par tout moyen conférant date certaine. | AJ18: NEV_I_082 | AK18: =VLOOKUP(AJ18,'Axe 2 Règles de gestion'!$D$2:$F$79,3, FALSE) -> Le compte rendu est établi, signé et adressé par le supérieur hiérarchique à l'agent qui le complète, si besoin, de ses observations. | AL18: NEV_I_083 | AM18: =VLOOKUP(AL18,'Axe 2 Règles de gestion'!$D$2:$F$79,3, FALSE) -> L'agent doit signer le compte rendu, éventuellement complété des observations de son supérieur, pour attester en avoir pris connaissance. | AN18: NEV_I_084 | AO18: =VLOOKUP(AN18,'Axe 2 Règles de gestion'!$D$2:$F$79,3, FALSE) -> L'agent doit retourner le compte rendu à son supérieur hiérarchique qui le verse à son dossier. | AP18: NEV_I_085 | AQ18: =VLOOKUP(AP18,'Axe 2 Règles de gestion'!$D$2:$F$79,3, FALSE) -> L'entretien ne concerne pas l'agent appartenant aux corps d'inspection pédagogique, de direction d'établissement d'enseignement, d'enseignants, d'éducation, de psychologues de l'éducation nationale, de chercheurs, d'enseignants-chercheurs ou assimilés. | BJ18: 2025-77
A19: 25.10.00 | B19: A | C19: 45917.717 | D19: D0014 | E19: Entretien professionnel/Notation | F19: S0151 | G19: Entretien professionnel | H19: E1022 | I19: Entretien annuel de suivi | L19: T2465 | M19: Entretien de suivi | N19: Création Modification | Q19: Stagiaire ou auditeur ou élève | R19: P0004 | S19: Général | T19: Exclu | U19: 45689 | BJ19: 2025-77
A20: 25.10.00 | B20: A | C20: 45917.717 | D20: D0014 | E20: Entretien professionnel/Notation | F20: S0151 | G20: Entretien professionnel | H20: E1022 | I20: Entretien annuel de suivi | L20: T2465 | M20: Entretien de suivi | N20: Création Modification | Q20: Ouvrier d'état | R20: P0005 | S20: Général | T20: Exclu | U20: 45689 | BJ20: 2025-77
A21: 25.10.00 | B21: A | C21: 45917.718 | D21: D0014 | E21: Entretien professionnel/Notation | F21: S0151 | G21: Entretien professionnel | H21: E1022 | I21: Entretien annuel de suivi | L21: T2465 | M21: Entretien de suivi | N21: Création Modification | Q21: Contractuel à temps incomplet | R21: P0067 | S21: Particulier | T21: Exclu | U21: 45689 | BJ21: 2025-77

Sheet Axe 1 Enchaînement RG Impact
A1: Version | B1: Type de mise à jour | C1: Date de mise à jour | D1: Identifiant Domaine | E1: Libellé du Domaine | F1: Identifiant Sous-domaine | G1: Libellé du Sous-domaine | H1: Identifiant Evénement | I1: Libellé de l'évènement | J1: Libellé condition déclenchement Evènement | K1: Condition déclenchement Evènement | L1: Identifiant type d'évènement | M1: Libellé type d'évènement | N1: Type de mise à jour | O1: Libellé condition déclenchement Type Evènement | P1: Condition déclenchement Type Evènement | Q1: Libellé Population | R1: Codification Population | S1: Général / Particulier | T1: Passant / Exclu | U1: Date de début | V1: Date de fin | W1: Impacts | X1: FIME | Y1: Statut de travail
A2: 20.10.00 | B2: A | C2: 44225.399 | D2: D0014 | E2: Entretien professionnel/Notation | F2: S0151 | G2: Entretien professionnel | H2: E0852 | I2: Entretien professionnel | J2: Date de l'entretien professionnel saisie différent de vide | K2: A_NEV_DAENPR [Saisi] <> vide | L2: T2108 | M2: Entretien professionnel | N2: Création Modification | Q2: Titulaire ou magistrat | R2: P0001 | S2: Général | T2: Passant | U2: 44197
A3: 20.10.00 | B3: A | C3: 44225.4 | D3: D0014 | E3: Entretien professionnel/Notation | F3: S0151 | G3: Entretien professionnel | H3: E0852 | I3: Entretien professionnel | J3: Date de l'entretien professionnel saisie différent de vide | K3: A_NEV_DAENPR [Saisi] <> vide | L3: T2108 | M3: Entretien professionnel | N3: Création Modification | Q3: Contractuel | R3: P0003 | S3: Général | T3: Exclu | U3: 44197
A4: 20.10.00 | B4: A | C4: 44225.4 | D4: D0014 | E4: Entretien professionnel/Notation | F4: S0151 | G4: Entretien professionnel | H4: E0852 | I4: Entretien professionnel | J4: Date de l'entretien professionnel saisie différent de vide | K4: A_NEV_DAENPR [Saisi] <> vide | L4: T2108 | M4: Entretien professionnel | N4: Création Modification | Q4: Stagiaire ou auditeur ou élève | R4: P0004 | S4: Général | T4: Exclu | U4: 44197
A5: 20.10.00 | B5: A | C5: 44225.401 | D5: D0014 | E5: Entretien professionnel/Notation | F5: S0151 | G5: Entretien professionnel | H5: E0852 | I5: Entretien professionnel | J5: Date de l'entretien professionnel saisie différent de vide | K5: A_NEV_DAENPR [Saisi] <> vide | L5: T2108 | M5: Entretien professionnel | N5: Création Modification | Q5: Ouvrier d'état | R5: P0005 | S5: Général | T5: Exclu | U5: 44197
A6: 22.10.00 | B6: M | C6: 44832.702 | D6: D0014 | E6: Entretien professionnel/Notation | F6: S0151 | G6: Entretien professionnel | H6: E0852 | I6: Entretien professionnel | J6: Date de l'entretien professionnel saisie différent de vide | K6: A_NEV_DAENPR [Saisi] <> vide | L6: T2108 | M6: Entretien professionnel | N6: Création Modification | Q6: Contractuel recruté pour répondre à un besoin permanent | R6: P0104 | S6: Particulier | T6: Passant | U6: 44197 | V6: 44677
A7: 22.10.00 | B7: A | C7: 44832.703 | D7: D0014 | E7: Entretien professionnel/Notation | F7: S0151 | G7: Entretien professionnel | H7: E0852 | I7: Entretien professionnel | J7: Date de l'entretien professionnel saisie différent de vide | K7: A_NEV_DAENPR [Saisi] <> vide | L7: T2108 | M7: Entretien professionnel | N7: Création Modification | Q7: Contractuel recruté pour répondre à un besoin permanent | R7: P0104 | S7: Particulier | T7: Passant | U7: 44678
A8: 25.10.00 | B8: A | C8: 46002.497 | D8: D0014 | E8: Entretien professionnel/Notation | F8: S0151 | G8: Entretien professionnel | H8: E0852 | I8: Entretien professionnel | J8: Date de l'entretien professionnel saisie différent de vide | K8: A_NEV_DAENPR [Saisi] <> vide | L8: T2108 | M8: Entretien professionnel | N8: Création Modification | Q8: Ouvrier des parcs et ateliers confirmé ou stagiaire | R8: P0143 | S8: Particulier | T8: Passant | U8: 45901 | X8: 2025-121
A9: 20.10.00 | B9: A | C9: 44225.403 | D9: D0014 | E9: Entretien professionnel/Notation | F9: S0151 | G9: Entretien professionnel | H9: E0852 | I9: Entretien professionnel | J9: Date de l'entretien professionnel saisie différent de vide | K9: A_NEV_DAENPR [Saisi] <> vide | L9: T2108 | M9: Entretien professionnel | N9: Création Modification | Q9: Contractuel sous contrat PACTE | R9: P0166 | S9: Particulier | T9: Exclu | U9: 44197
A10: 22.10.00 | B10: M | C10: 44832.703 | D10: D0014 | E10: Entretien professionnel/Notation | F10: S0151 | G10: Entretien professionnel | H10: E0852 | I10: Entretien professionnel | J10: Date de l'entretien professionnel saisie différent de vide | K10: A_NEV_DAENPR [Saisi] <> vide | L10: T2108 | M10: Entretien professionnel | N10: Création Modification | Q10: Contractuel recruté sur contrat de projet | R10: P0241 | S10: Particulier | T10: Passant | U10: 44197 | V10: 44677
A11: 22.10.00 | B11: A | C11: 44832.706 | D11: D0014 | E11: Entretien professionnel/Notation | F11: S0151 | G11: Entretien professionnel | H11: E0852 | I11: Entretien professionnel | J11: Date de l'entretien professionnel saisie différent de vide | K11: A_NEV_DAENPR [Saisi] <> vide | L11: T2108 | M11: Entretien professionnel | N11: Création Modification | Q11: Contractuel recruté sur contrat de projet | R11: P0241 | S11: Particulier | T11: Passant | U11: 44678
A12: 25.10.00 | B12: A | C12: 45917.712 | D12: D0014 | E12: Entretien professionnel/Notation | F12: S0151 | G12: Entretien professionnel | H12: E1021 | I12: Entretien annuel d'accompagnement | L12: T2464 | M12: Entretien d'accompagnement | N12: Création Modification | Q12: Titulaire ou magistrat | R12: P0001 | S12: Général | T12: Passant | U12: 45689 | X12: 2025-77
A13: 25.10.00 | B13: A | C13: 45917.715 | D13: D0014 | E13: Entretien professionnel/Notation | F13: S0151 | G13: Entretien professionnel | H13: E1021 | I13: Entretien annuel d'accompagnement | L13: T2464 | M13: Entretien d'accompagnement | N13: Création Modification | Q13: Contractuel | R13: P0003 | S13: Général | T13: Passant | U13: 45689 | X13: 2025-77
A14: 25.10.00 | B14: A | C14: 45917.719 | D14: D0014 | E14: Entretien professionnel/Notation | F14: S0151 | G14: Entretien professionnel | H14: E1021 | I14: Entretien annuel d'accompagnement | L14: T2464 | M14: Entretien d'accompagnement | N14: Création Modification | Q14: Stagiaire ou auditeur ou élève | R14: P0004 | S14: Général | T14: Exclu | U14: 45689 | X14: 2025-77
A15: 25.10.00 | B15: A | C15: 45917.715 | D15: D0014 | E15: Entretien professionnel/Notation | F15: S0151 | G15: Entretien professionnel | H15: E1021 | I15: Entretien annuel d'accompagnement | L15: T2464 | M15: Entretien d'accompagnement | N15: Création Modification | Q15: Ouvrier d'état | R15: P0005 | S15: Général | T15: Exclu | U15: 45689 | X15: 2025-77
A16: 25.10.00 | B16: A | C16: 45917.716 | D16: D0014 | E16: Entretien professionnel/Notation | F16: S0151 | G16: Entretien professionnel | H16: E1021 | I16: Entretien annuel d'accompagnement | L16: T2464 | M16: Entretien d'accompagnement | N16: Création Modification | Q16: Contractuel à temps incomplet | R16: P0067 | S16: Particulier | T16: Exclu | U16: 45689 | X16: 2025-77
A17: 25.10.00 | B17: A | C17: 45917.716 | D17: D0014 | E17: Entretien professionnel/Notation | F17: S0151 | G17: Entretien professionnel | H17: E1022 | I17: Entretien annuel de suivi | L17: T2465 | M17: Entretien de suivi | N17: Création Modification | Q17: Titulaire ou magistrat | R17: P0001 | S17: Général | T17: Passant | U17: 45689 | X17: 2025-77
A18: 25.10.00 | B18: A | C18: 45917.717 | D18: D0014 | E18: Entretien professionnel/Notation | F18: S0151 | G18: Entretien professionnel | H18: E1022 | I18: Entretien annuel de suivi | L18: T2465 | M18: Entretien de suivi | N18: Création Modification | Q18: Contractuel | R18: P0003 | S18: Général | T18: Passant | U18: 45689 | X18: 2025-77
A19: 25.10.00 | B19: A | C19: 45917.717 | D19: D0014 | E19: Entretien professionnel/Notation | F19: S0151 | G19: Entretien professionnel | H19: E1022 | I19: Entretien annuel de suivi | L19: T2465 | M19: Entretien de suivi | N19: Création Modification | Q19: Stagiaire ou auditeur ou élève | R19: P0004 | S19: Général | T19: Exclu | U19: 45689 | X19: 2025-77
A20: 25.10.00 | B20: A | C20: 45917.717 | D20: D0014 | E20: Entretien professionnel/Notation | F20: S0151 | G20: Entretien professionnel | H20: E1022 | I20: Entretien annuel de suivi | L20: T2465 | M20: Entretien de suivi | N20: Création Modification | Q20: Ouvrier d'état | R20: P0005 | S20: Général | T20: Exclu | U20: 45689 | X20: 2025-77
A21: 25.10.00 | B21: A | C21: 45917.718 | D21: D0014 | E21: Entretien professionnel/Notation | F21: S0151 | G21: Entretien professionnel | H21: E1022 | I21: Entretien annuel de suivi | L21: T2465 | M21: Entretien de suivi | N21: Création Modification | Q21: Contractuel à temps incomplet | R21: P0067 | S21: Particulier | T21: Exclu | U21: 45689 | X21: 2025-77

Sheet Axe 1 Rattachement des actes
A1: Version | B1: Type de mise à jour | C1: Date de mise à jour | D1: Identifiant Domaine | E1: Libellé du Domaine | F1: Identifiant Sous-domaine | G1: Libellé du Sous-domaine | H1: Identifiant Evénement | I1: Libellé de l'évènement | J1: Libellé condition déclenchement Evènement | K1: Condition déclenchement Evènement | L1: Identifiant type d'évènement | M1: Libellé type d'évènement | N1: Type de mise à jour | O1: Libellé condition déclenchement Type Evènement | P1: Condition déclenchement Type Evènement | Q1: Libellé Population | R1: Codification Population | S1: Général / Particulier | T1: Passant / Exclu | U1: Date de début | V1: Date de fin | W1: Libellé condition de déclenchement 1 | X1: Condition de déclenchement 1 | Y1: Code nature 1 | Z1: Libellé nature 1 | AA1: Libellé condition de déclenchement 2 | AB1: Condition de déclenchement 2 | AC1: Code nature 2 | AD1: Libellé nature 2 | AE1: Libellé condition de déclenchement 3 | AF1: Condition de déclenchement 3 | AG1: Code nature 3 | AH1: Libellé nature 3 | AI1: Libellé condition de déclenchement 4 | AJ1: Condition de déclenchement 4 | AK1: Code nature 4 | AL1: Libellé nature 4 | AM1: Commentaire | AN1: FIME | AO1: Statut de travail
A2: 20.10.00 | B2: A | C2: 44225.399 | D2: D0014 | E2: Entretien professionnel/Notation | F2: S0151 | G2: Entretien professionnel | H2: E0852 | I2: Entretien professionnel | J2: Date de l'entretien professionnel saisie différent de vide | K2: A_NEV_DAENPR [Saisi] <> vide | L2: T2108 | M2: Entretien professionnel | N2: Création Modification | Q2: Titulaire ou magistrat | R2: P0001 | S2: Général | T2: Passant | U2: 44197
A3: 20.10.00 | B3: A | C3: 44225.4 | D3: D0014 | E3: Entretien professionnel/Notation | F3: S0151 | G3: Entretien professionnel | H3: E0852 | I3: Entretien professionnel | J3: Date de l'entretien professionnel saisie différent de vide | K3: A_NEV_DAENPR [Saisi] <> vide | L3: T2108 | M3: Entretien professionnel | N3: Création Modification | Q3: Contractuel | R3: P0003 | S3: Général | T3: Exclu | U3: 44197
A4: 20.10.00 | B4: A | C4: 44225.4 | D4: D0014 | E4: Entretien professionnel/Notation | F4: S0151 | G4: Entretien professionnel | H4: E0852 | I4: Entretien professionnel | J4: Date de l'entretien professionnel saisie différent de vide | K4: A_NEV_DAENPR [Saisi] <> vide | L4: T2108 | M4: Entretien professionnel | N4: Création Modification | Q4: Stagiaire ou auditeur ou élève | R4: P0004 | S4: Général | T4: Exclu | U4: 44197
A5: 20.10.00 | B5: A | C5: 44225.401 | D5: D0014 | E5: Entretien professionnel/Notation | F5: S0151 | G5: Entretien professionnel | H5: E0852 | I5: Entretien professionnel | J5: Date de l'entretien professionnel saisie différent de vide | K5: A_NEV_DAENPR [Saisi] <> vide | L5: T2108 | M5: Entretien professionnel | N5: Création Modification | Q5: Ouvrier d'état | R5: P0005 | S5: Général | T5: Exclu | U5: 44197
A6: 22.10.00 | B6: M | C6: 44832.702 | D6: D0014 | E6: Entretien professionnel/Notation | F6: S0151 | G6: Entretien professionnel | H6: E0852 | I6: Entretien professionnel | J6: Date de l'entretien professionnel saisie différent de vide | K6: A_NEV_DAENPR [Saisi] <> vide | L6: T2108 | M6: Entretien professionnel | N6: Création Modification | Q6: Contractuel recruté pour répondre à un besoin permanent | R6: P0104 | S6: Particulier | T6: Passant | U6: 44197 | V6: 44677
A7: 22.10.00 | B7: A | C7: 44832.703 | D7: D0014 | E7: Entretien professionnel/Notation | F7: S0151 | G7: Entretien professionnel | H7: E0852 | I7: Entretien professionnel | J7: Date de l'entretien professionnel saisie différent de vide | K7: A_NEV_DAENPR [Saisi] <> vide | L7: T2108 | M7: Entretien professionnel | N7: Création Modification | Q7: Contractuel recruté pour répondre à un besoin permanent | R7: P0104 | S7: Particulier | T7: Passant | U7: 44678
A8: 25.10.00 | B8: A | C8: 46002.497 | D8: D0014 | E8: Entretien professionnel/Notation | F8: S0151 | G8: Entretien professionnel | H8: E0852 | I8: Entretien professionnel | J8: Date de l'entretien professionnel saisie différent de vide | K8: A_NEV_DAENPR [Saisi] <> vide | L8: T2108 | M8: Entretien professionnel | N8: Création Modification | Q8: Ouvrier des parcs et ateliers confirmé ou stagiaire | R8: P0143 | S8: Particulier | T8: Passant | U8: 45901
A9: 20.10.00 | B9: A | C9: 44225.403 | D9: D0014 | E9: Entretien professionnel/Notation | F9: S0151 | G9: Entretien professionnel | H9: E0852 | I9: Entretien professionnel | J9: Date de l'entretien professionnel saisie différent de vide | K9: A_NEV_DAENPR [Saisi] <> vide | L9: T2108 | M9: Entretien professionnel | N9: Création Modification | Q9: Contractuel sous contrat PACTE | R9: P0166 | S9: Particulier | T9: Exclu | U9: 44197
A10: 22.10.00 | B10: M | C10: 44832.703 | D10: D0014 | E10: Entretien professionnel/Notation | F10: S0151 | G10: Entretien professionnel | H10: E0852 | I10: Entretien professionnel | J10: Date de l'entretien professionnel saisie différent de vide | K10: A_NEV_DAENPR [Saisi] <> vide | L10: T2108 | M10: Entretien professionnel | N10: Création Modification | Q10: Contractuel recruté sur contrat de projet | R10: P0241 | S10: Particulier | T10: Passant | U10: 44197 | V10: 44677
A11: 22.10.00 | B11: A | C11: 44832.706 | D11: D0014 | E11: Entretien professionnel/Notation | F11: S0151 | G11: Entretien professionnel | H11: E0852 | I11: Entretien professionnel | J11: Date de l'entretien professionnel saisie différent de vide | K11: A_NEV_DAENPR [Saisi] <> vide | L11: T2108 | M11: Entretien professionnel | N11: Création Modification | Q11: Contractuel recruté sur contrat de projet | R11: P0241 | S11: Particulier | T11: Passant | U11: 44678
A12: 25.10.00 | B12: A | C12: 45917.712 | D12: D0014 | E12: Entretien professionnel/Notation | F12: S0151 | G12: Entretien professionnel | H12: E1021 | I12: Entretien annuel d'accompagnement | L12: T2464 | M12: Entretien d'accompagnement | N12: Création Modification | Q12: Titulaire ou magistrat | R12: P0001 | S12: Général | T12: Passant | U12: 45689
A13: 25.10.00 | B13: A | C13: 45917.715 | D13: D0014 | E13: Entretien professionnel/Notation | F13: S0151 | G13: Entretien professionnel | H13: E1021 | I13: Entretien annuel d'accompagnement | L13: T2464 | M13: Entretien d'accompagnement | N13: Création Modification | Q13: Contractuel | R13: P0003 | S13: Général | T13: Passant | U13: 45689
