Workbook

Sheet Mode opératoire
B1: MODE OPERATOIRE
B2: La transaction s'effectue au niveau de la rubrique "Congés/absences", elle inclut l'ensemble des sous-rubriques listées ci-dessous : - Congés/absences - Complément pour congé / absence : impact rémunération - Compteurs de périodes de congés.

Sheet Axe 1 Enchainement des RG
A1: Version | B1: Type de mise à jour | C1: Date de mise à jour | D1: Identifiant Domaine | E1: Libellé du Domaine | F1: Identifiant Sous-domaine | G1: Libellé du Sous-domaine | H1: Identifiant Evénement | I1: Libellé de l'évènement | J1: Libellé condition déclenchement Evènement | K1: Condition déclenchement Evènement | L1: Identifiant type d'évènement | M1: Libellé type d'évènement | N1: Type de mise à jour | O1: Libellé condition déclenchement Type Evènement | P1: Condition déclenchement Type Evènement | Q1: Libellé Population | R1: Codification Population | S1: Général / Particulier | T1: Passant / Exclu | U1: Date de début | V1: Date de fin | W1: Règles mobilisées | X1: Identifiant Règle de contrôle intellectuel 1 | Y1: Libellé Règle de contrôle intellectuel 1 | Z1: Identifiant Règle de contrôle intellectuel 2 | AA1: Libellé Règle de contrôle intellectuel 2 | AB1: Identifiant Règle de contrôle intellectuel 3 | AC1: Libellé Règle de contrôle intellectuel 3 | AD1: Identifiant Règle de contrôle intellectuel 4 | AE1: Libellé Règle de contrôle intellectuel 4 | AF1: Identifiant Règle de contrôle intellectuel 5 | AG1: Libellé Règle de contrôle intellectuel 5 | AH1: Identifiant Règle de contrôle intellectuel 6 | AI1: Libellé Règle de contrôle intellectuel 6 | AJ1: Identifiant Règle de contrôle intellectuel 7 | AK1: Libellé Règle de contrôle intellectuel 7 | AL1: Identifiant Règle de contrôle intellectuel 8 | AM1: Libellé Règle de contrôle intellectuel 8 | AN1: Identifiant Règle de contrôle intellectuel 9 | AO1: Libellé Règle de contrôle intellectuel 9 | AP1: Identifiant Règle de condition 1 | AQ1: Libellé Règle de condition 1 | AR1: Identifiant Règle de condition 2 | AS1: Libellé Règle de condition 2 | AT1: Identifiant Règle de condition 3 | AU1: Libellé Règle de condition 3 | AV1: Identifiant Règle de condition 4 | AW1: Libellé Règle de condition 4 | AX1: Identifiant Règle de condition 5 | AY1: Libellé Règle de condition 5 | AZ1: Identifiant Règle de condition 6 | BA1: Libellé Règle de condition 6 | BB1: Identifiant Règle de contrôle 1 | BC1: Libellé Règle de contrôle 1 | BD1: Identifiant Règle de contrôle 2 | BE1: Libellé Règle de contrôle 2 | BF1: Identifiant Règle de contrôle 3 | BG1: Libellé Règle de contrôle 3 | BH1: Identifiant Règle de contrôle 4 | BI1: Libellé Règle de contrôle 4 | BJ1: Identifiant Règle de contrôle 5 | BK1: Libellé Règle de contrôle 5 | BL1: Identifiant Règle de contrôle 6 | BM1: Libellé Règle de contrôle 6 | BN1: Identifiant Règle de contrôle 7 | BO1: Libellé Règle de contrôle 7 | BP1: Identifiant Règle de contrôle 8 | BQ1: Libellé Règle de contrôle 8 | BR1: Identifiant Règle de contrôle 9 | BS1: Libellé Règle de contrôle 9 | BT1: Identifiant Règle de contrôle 10 | BU1: Libellé Règle de contrôle 10 | BV1: FIME | BW1: Statut de travail
A2: 24.00.00 | B2: A | C2: 45414.664 | D2: D0007 | E2: Congés/Absence | F2: S0171 | G2: Permission liée à des évènements familiaux | H2: E0863 | I2: Permission pour évènements familiaux (mariage, PACS, naissance, adoption, décès d'un parent) | J2: Le Type de congé/absence est 'Permission pour évènements familiaux (mariage, PACS, naissance, adoption, décès d'un parent)' | K2: A_COA_TYCOAB [Saisi] = 'CP007' | L2: T2304 | M2: Permission pour évènements familiaux (mariage, PACS, naissance, adoption, décès d'un parent) - Demande | N2: Création | Q2: Titulaire ou magistrat | R2: P0001 | S2: Général | T2: Exclu | U2: 44927
A3: 24.00.00 | B3: A | C3: 45414.665 | D3: D0007 | E3: Congés/Absence | F3: S0171 | G3: Permission liée à des évènements familiaux | H3: E0863 | I3: Permission pour évènements familiaux (mariage, PACS, naissance, adoption, décès d'un parent) | J3: Le Type de congé/absence est 'Permission pour évènements familiaux (mariage, PACS, naissance, adoption, décès d'un parent)' | K3: A_COA_TYCOAB [Saisi] = 'CP007' | L3: T2305 | M3: Permission pour évènements familiaux (mariage, PACS, naissance, adoption, décès d'un parent) - Fin | N3: Modification | Q3: Titulaire ou magistrat | R3: P0001 | S3: Général | T3: Exclu | U3: 44927
A4: 24.00.00 | B4: A | C4: 45414.665 | D4: D0007 | E4: Congés/Absence | F4: S0171 | G4: Permission liée à des évènements familiaux | H4: E0863 | I4: Permission pour évènements familiaux (mariage, PACS, naissance, adoption, décès d'un parent) | J4: Le Type de congé/absence est 'Permission pour évènements familiaux (mariage, PACS, naissance, adoption, décès d'un parent)' | K4: A_COA_TYCOAB [Saisi] = 'CP007' | L4: T2304 | M4: Permission pour évènements familiaux (mariage, PACS, naissance, adoption, décès d'un parent) - Demande | N4: Création | Q4: Militaire | R4: P0002 | S4: Général | T4: Exclu | U4: 44927
A5: 24.00.00 | B5: A | C5: 45414.665 | D5: D0007 | E5: Congés/Absence | F5: S0171 | G5: Permission liée à des évènements familiaux | H5: E0863 | I5: Permission pour évènements familiaux (mariage, PACS, naissance, adoption, décès d'un parent) | J5: Le Type de congé/absence est 'Permission pour évènements familiaux (mariage, PACS, naissance, adoption, décès d'un parent)' | K5: A_COA_TYCOAB [Saisi] = 'CP007' | L5: T2305 | M5: Permission pour évènements familiaux (mariage, PACS, naissance, adoption, décès d'un parent) - Fin | N5: Modification | Q5: Militaire | R5: P0002 | S5: Général | T5: Exclu | U5: 44927
A6: 24.00.00 | B6: A | C6: 45414.664 | D6: D0007 | E6: Congés/Absence | F6: S0171 | G6: Permission liée à des évènements familiaux | H6: E0863 | I6: Permission pour évènements familiaux (mariage, PACS, naissance, adoption, décès d'un parent) | J6: Le Type de congé/absence est 'Permission pour évènements familiaux (mariage, PACS, naissance, adoption, décès d'un parent)' | K6: A_COA_TYCOAB [Saisi] = 'CP007' | L6: T2304 | M6: Permission pour évènements familiaux (mariage, PACS, naissance, adoption, décès d'un parent) - Demande | N6: Création | Q6: Contractuel | R6: P0003 | S6: Général | T6: Exclu | U6: 44927
A7: 24.00.00 | B7: A | C7: 45414.665 | D7: D0007 | E7: Congés/Absence | F7: S0171 | G7: Permission liée à des évènements familiaux | H7: E0863 | I7: Permission pour évènements familiaux (mariage, PACS, naissance, adoption, décès d'un parent) | J7: Le Type de congé/absence est 'Permission pour évènements familiaux (mariage, PACS, naissance, adoption, décès d'un parent)' | K7: A_COA_TYCOAB [Saisi] = 'CP007' | L7: T2305 | M7: Permission pour évènements familiaux (mariage, PACS, naissance, adoption, décès d'un parent) - Fin | N7: Modification | Q7: Contractuel | R7: P0003 | S7: Général | T7: Exclu | U7: 44927
A8: 24.00.00 | B8: A | C8: 45414.664 | D8: D0007 | E8: Congés/Absence | F8: S0171 | G8: Permission liée à des évènements familiaux | H8: E0863 | I8: Permission pour évènements familiaux (mariage, PACS, naissance, adoption, décès d'un parent) | J8: Le Type de congé/absence est 'Permission pour évènements familiaux (mariage, PACS, naissance, adoption, décès d'un parent)' | K8: A_COA_TYCOAB [Saisi] = 'CP007' | L8: T2304 | M8: Permission pour évènements familiaux (mariage, PACS, naissance, adoption, décès d'un parent) - Demande | N8: Création | Q8: Stagiaire ou auditeur ou élève | R8: P0004 | S8: Général | T8: Exclu | U8: 44927
A9: 24.00.00 | B9: A | C9: 45414.665 | D9: D0007 | E9: Congés/Absence | F9: S0171 | G9: Permission liée à des évènements familiaux | H9: E0863 | I9: Permission pour évènements familiaux (mariage, PACS, naissance, adoption, décès d'un parent) | J9: Le Type de congé/absence est 'Permission pour évènements familiaux (mariage, PACS, naissance, adoption, décès d'un parent)' | K9: A_COA_TYCOAB [Saisi] = 'CP007' | L9: T2305 | M9: Permission pour évènements familiaux (mariage, PACS, naissance, adoption, décès d'un parent) - Fin | N9: Modification | Q9: Stagiaire ou auditeur ou élève | R9: P0004 | S9: Général | T9: Exclu | U9: 44927
A10: 24.00.00 | B10: A | C10: 45414.664 | D10: D0007 | E10: Congés/Absence | F10: S0171 | G10: Permission liée à des évènements familiaux | H10: E0863 | I10: Permission pour évènements familiaux (mariage, PACS, naissance, adoption, décès d'un parent) | J10: Le Type de congé/absence est 'Permission pour évènements familiaux (mariage, PACS, naissance, adoption, décès d'un parent)' | K10: A_COA_TYCOAB [Saisi] = 'CP007' | L10: T2304 | M10: Permission pour évènements familiaux (mariage, PACS, naissance, adoption, décès d'un parent) - Demande | N10: Création | Q10: Ouvrier d'état | R10: P0005 | S10: Général | T10: Exclu | U10: 44927
A11: 24.00.00 | B11: A | C11: 45414.665 | D11: D0007 | E11: Congés/Absence | F11: S0171 | G11: Permission liée à des évènements familiaux | H11: E0863 | I11: Permission pour évènements familiaux (mariage, PACS, naissance, adoption, décès d'un parent) | J11: Le Type de congé/absence est 'Permission pour évènements familiaux (mariage, PACS, naissance, adoption, décès d'un parent)' | K11: A_COA_TYCOAB [Saisi] = 'CP007' | L11: T2305 | M11: Permission pour évènements familiaux (mariage, PACS, naissance, adoption, décès d'un parent) - Fin | N11: Modification | Q11: Ouvrier d'état | R11: P0005 | S11: Général | T11: Exclu | U11: 44927
A12: 24.00.00 | B12: A | C12: 45414.666 | D12: D0007 | E12: Congés/Absence | F12: S0171 | G12: Permission liée à des évènements familiaux | H12: E0863 | I12: Permission pour évènements familiaux (mariage, PACS, naissance, adoption, décès d'un parent) | J12: Le Type de congé/absence est 'Permission pour évènements familiaux (mariage, PACS, naissance, adoption, décès d'un parent)' | K12: A_COA_TYCOAB [Saisi] = 'CP007' | L12: T2304 | M12: Permission pour évènements familiaux (mariage, PACS, naissance, adoption, décès d'un parent) - Demande | N12: Création | Q12: Militaire sous contrat | R12: P0145 | S12: Particulier | T12: Passant | U12: 44927 | W12: PEF_I_020 ET PEF_I_001 ET PEF_I_011 ET PEF_I_004 ET PEF_I_005 ET PEF_I_003 ET PEF_I_002 ET PEF_I_013 ET PEF_D_003 ET PEF_D_004 ET PEF_D_012 ET PEF_D_011 ET PEF_D_001 ET ABS_C_001 ET ABS_C_045 ET ABS_C_003 ET ABS_C_004 ET ABS_C_007 ET ABS_C_008 ET ABS_C_009 ET ABS_C_019 ET ABS_C_020 ET ABS_C_026 | X12: PEF_I_020 | Y12: =VLOOKUP(X12,'Axe 2 Règles de gestion'!$D$2:$F$40,3, FALSE) -> En cas de participation à des opérations militaires, la permission est accordée par le commandant de la formation administrative ou l'autorité équivalente, dans les conditions fixées par le ministre de la défense. | Z12: PEF_I_001 | AA12: =VLOOKUP(Z12,'Axe 2 Règles de gestion'!$D$2:$F$40,3, FALSE) -> La permission est accordée à l'occasion du mariage du militaire ou de la conclusion d'un pacte civil de solidarité par ce dernier. | AB12: PEF_I_011 | AC12: =VLOOKUP(AB12,'Axe 2 Règles de gestion'!$D$2:$F$40,3, FALSE) -> La permission est accordée à l'occasion de la naissance d'un enfant du militaire ou de l'accueil d'un enfant par le militaire. | AD12: PEF_I_004 | AE12: =VLOOKUP(AD12,'Axe 2 Règles de gestion'!$D$2:$F$40,3, FALSE) -> La permission est accordée à l'occasion du mariage d'un enfant du militaire. | AF12: PEF_I_005 | AG12: =VLOOKUP(AF12,'Axe 2 Règles de gestion'!$D$2:$F$40,3, FALSE) -> La permission est accordée à l'occasion du décès d'un parent du militaire, lorsqu'il s'agit des grands-parents, parents, beaux-parents, frère ou sœur. | AH12: PEF_I_003 | AI12: =VLOOKUP(AH12,'Axe 2 Règles de gestion'!$D$2:$F$40,3, FALSE) -> La permission est accordée à l'occasion de l'arrivée dans le foyer du militaire d'un enfant placé en vue de son adoption. | AJ12: PEF_I_002 | AK12: =VLOOKUP(AJ12,'Axe 2 Règles de gestion'!$D$2:$F$40,3, FALSE) -> Lorsque la permission est prise à l'occasion de de l'arrivée d'un enfant placé en vue de son adoption, les jours sont pris de manière continue ou fractionnée. | AL12: PEF_I_013 | AM12: =VLOOKUP(AL12,'Axe 2 Règles de gestion'!$D$2:$F$40,3, FALSE) -> La permission peut être prise, au choix du militaire, à compter du jour de l'arrivée de l'enfant adopté au sein du foyer ou au cours de la période de 7 jours consécutifs précédant son arrivée. | AP12: PEF_D_003 | AQ12: =VLOOKUP(AP12,'Axe 2 Règles de gestion'!$D$2:$F$40,3, FALSE) -> La durée prévisionnelle de la permission est de 3 jours ouvrés. | AR12: PEF_D_004 | AS12: =VLOOKUP(AR12,'Axe 2 Règles de gestion'!$D$2:$F$40,3, FALSE) -> La durée réelle de la permission est de 3 jours ouvrés. | AT12: PEF_D_012 | AU12: =VLOOKUP(AT12,'Axe 2 Règles de gestion'!$D$2:$F$40,3, FALSE) -> La date de fin prévisionnelle de la permission doit être antérieure ou égale à la date limite de fin réelle ou prévisionnelle du lien juridique. Le militaire ne voit pas son contrat prorogé jusqu'à la date de fin de la permission. | AV12: PEF_D_011 | AW12: =VLOOKUP(AV12,'Axe 2 Règles de gestion'!$D$2:$F$40,3, FALSE) -> La date de fin réelle de la permission doit être antérieure ou égale à la date limite de fin réelle ou prévisionnelle du lien juridique. Le militaire ne voit pas son contrat prorogé jusqu'à la date de fin de la permission. | AX12: PEF_D_001 | AY12: =VLOOKUP(AX12,'Axe 2 Règles de gestion'!$D$2:$F$40,3, FALSE) -> Le militaire est en activité. | BB12: ABS_C_001 | BC12: =VLOOKUP(BB12,'Axe 2 Règles de gestion'!$D$2:$F$40,3, FALSE) -> La date de début du congé/absence doit être postérieure ou égale à la date de recrutement dans la FPE ou dans la carrière militaire. | BD12: ABS_C_045 | BE12: =VLOOKUP(BD12,'Axe 2 Règles de gestion'!$D$2:$F$40,3, FALSE) -> Pour les militaires sous contrat à durée déterminée, la date de début du congé/absence doit être postérieure ou égale à la date de début du lien juridique. | BF12: ABS_C_003 | BG12: =VLOOKUP(BF12,'Axe 2 Règles de gestion'!$D$2:$F$40,3, FALSE) -> La date de début du congé/absence doit être antérieure ou égale à la date de fin réelle du congé/absence. | BH12: ABS_C_004 | BI12: =VLOOKUP(BH12,'Axe 2 Règles de gestion'!$D$2:$F$40,3, FALSE) -> La date de début du congé/absence doit être antérieure ou égale à la date de fin prévisionnelle du congé/absence. | BJ12: ABS_C_007 | BK12: =VLOOKUP(BJ12,'Axe 2 Règles de gestion'!$D$2:$F$40,3, FALSE) -> La date de fin réelle du congé/absence doit être antérieure à la date limite de départ à la retraite. | BL12: ABS_C_008 | BM12: =VLOOKUP(BL12,'Axe 2 Règles de gestion'!$D$2:$F$40,3, FALSE) -> La date de fin prévisionnelle du congé/absence doit être antérieure à la date limite de départ à la retraite. | BN12: ABS_C_009 | BO12: =VLOOKUP(BN12,'Axe 2 Règles de gestion'!$D$2:$F$40,3, FALSE) -> La date de fin réelle ou la date de fin prévisionnelle du congé/absence doit être saisie. | BP12: ABS_C_019 | BQ12: =VLOOKUP(BP12,'Axe 2 Règles de gestion'!$D$2:$F$40,3, FALSE) -> Si l'absence ne commence pas par une demi-journée et si l'absence précédente ne finit pas par une demi journée, la date de début de l'absence saisie est postérieure à la date de fin réelle de l'absence précédente. | BR12: ABS_C_020 | BS12: =VLOOKUP(BR12,'Axe 2 Règles de gestion'!$D$2:$F$40,3, FALSE) -> Si l'absence ne commence pas par une demi-journée et si l'absence précédente ne finit pas par une demi journée, la date de début de l'absence saisie est postérieure à la date de fin prévisionnelle de l'absence précédente. | BT12: ABS_C_026 | BU12: =VLOOKUP(BT12,'Axe 2 Règles de gestion'!$D$2:$F$40,3, FALSE) -> Dans le cas d'un congé autre que CLM, CLD, CGM et CITIS, l'indicateur de requalification doit être à non et les impacts spécifiques à la requalification ne doivent pas être mobilisés ou l'impact rémunération est vide.
A13: 24.00.00 | B13: A | C13: 45414.667 | D13: D0007 | E13: Congés/Absence | F13: S0171 | G13: Permission liée à des évènements familiaux | H13: E0863 | I13: Permission pour évènements familiaux (mariage, PACS, naissance, adoption, décès d'un parent) | J13: Le Type de congé/absence est 'Permission pour évènements familiaux (mariage, PACS, naissance, adoption, décès d'un parent)' | K13: A_COA_TYCOAB [Saisi] = 'CP007' | L13: T2305 | M13: Permission pour évènements familiaux (mariage, PACS, naissance, adoption, décès d'un parent) - Fin | N13: Modification | Q13: Militaire sous contrat | R13: P0145 | S13: Particulier | T13: Passant | U13: 44927 | W13: PEF_I_022 ET PEF_D_003 ET PEF_D_004 ET PEF_D_012 ET PEF_D_011 ET PEF_D_001 ET ABS_C_003 ET ABS_C_004 ET ABS_C_007 ET ABS_C_008 ET ABS_C_009 ET ABS_C_026 | X13: PEF_I_022 | Y13: =VLOOKUP(X13,'Axe 2 Règles de gestion'!$D$2:$F$40,3, FALSE) -> Le militaire en permission peut être rappelé immédiatement lorsque les circonstances l'exigent. | AP13: PEF_D_003 | AQ13: =VLOOKUP(AP13,'Axe 2 Règles de gestion'!$D$2:$F$40,3, FALSE) -> La durée prévisionnelle de la permission est de 3 jours ouvrés. | AR13: PEF_D_004 | AS13: =VLOOKUP(AR13,'Axe 2 Règles de gestion'!$D$2:$F$40,3, FALSE) -> La durée réelle de la permission est de 3 jours ouvrés. | AT13: PEF_D_012 | AU13: =VLOOKUP(AT13,'Axe 2 Règles de gestion'!$D$2:$F$40,3, FALSE) -> La date de fin prévisionnelle de la permission doit être antérieure ou égale à la date limite de fin réelle ou prévisionnelle du lien juridique. Le militaire ne voit pas son contrat prorogé jusqu'à la date de fin de la permission. | AV13: PEF_D_011 | AW13: =VLOOKUP(AV13,'Axe 2 Règles de gestion'!$D$2:$F$40,3, FALSE) -> La date de fin réelle de la permission doit être antérieure ou égale à la date limite de fin réelle ou prévisionnelle du lien juridique. Le militaire ne voit pas son contrat prorogé jusqu'à la date de fin de la permission. | AX13: PEF_D_001 | AY13: =VLOOKUP(AX13,'Axe 2 Règles de gestion'!$D$2:$F$40,3, FALSE) -> Le militaire est en activité. | BB13: ABS_C_003 | BC13: =VLOOKUP(BB13,'Axe 2 Règles de gestion'!$D$2:$F$40,3, FALSE) -> La date de début du congé/absence doit être antérieure ou égale à la date de fin réelle du congé/absence. | BD13: ABS_C_004 | BE13: =VLOOKUP(BD13,'Axe 2 Règles de gestion'!$D$2:$F$40,3, FALSE) -> La date de début du congé/absence doit être antérieure ou égale à la date de fin prévisionnelle du congé/absence. | BF13: ABS_C_007 | BG13: =VLOOKUP(BF13,'Axe 2 Règles de gestion'!$D$2:$F$40,3, FALSE) -> La date de fin réelle du congé/absence doit être antérieure à la date limite de départ à la retraite. | BH13: ABS_C_008 | BI13: =VLOOKUP(BH13,'Axe 2 Règles de gestion'!$D$2:$F$40,3, FALSE) -> La date de fin prévisionnelle du congé/absence doit être antérieure à la date limite de départ à la retraite. | BJ13: ABS_C_009 | BK13: =VLOOKUP(BJ13,'Axe 2 Règles de gestion'!$D$2:$F$40,3, FALSE) -> La date de fin réelle ou la date de fin prévisionnelle du congé/absence doit être saisie. | BL13: ABS_C_026 | BM13: =VLOOKUP(BL13,'Axe 2 Règles de gestion'!$D$2:$F$40,3, FALSE) -> Dans le cas d'un congé autre que CLM, CLD, CGM et CITIS, l'indicateur de requalification doit être à non et les impacts spécifiques à la requalification ne doivent pas être mobilisés ou l'impact rémunération est vide.
A14: 24.00.00 | B14: A | C14: 45414.667 | D14: D0007 | E14: Congés/Absence | F14: S0171 | G14: Permission liée à des évènements familiaux | H14: E0863 | I14: Permission pour évènements familiaux (mariage, PACS, naissance, adoption, décès d'un parent) | J14: Le Type de congé/absence est 'Permission pour évènements familiaux (mariage, PACS, naissance, adoption, décès d'un parent)' | K14: A_COA_TYCOAB [Saisi] = 'CP007' | L14: T2304 | M14: Permission pour évènements familiaux (mariage, PACS, naissance, adoption, décès d'un parent) - Demande | N14: Création | Q14: Militaire de réserve | R14: P0146 | S14: Particulier | T14: Passant | U14: 44927 | W14: PEF_I_015 ET PEF_I_020 ET PEF_I_001 ET PEF_I_011 ET PEF_I_004 ET PEF_I_005 ET PEF_I_003 ET PEF_I_002 ET PEF_I_013 ET PEF_D_003 ET PEF_D_004 ET PEF_D_012 ET PEF_D_011 ET PEF_D_001 ET ABS_C_001 ET ABS_C_045 ET ABS_C_003 ET ABS_C_004 ET ABS_C_007 ET ABS_C_008 ET ABS_C_009 ET ABS_C_019 ET ABS_C_020 ET ABS_C_026 | X14: PEF_I_015 | Y14: =VLOOKUP(X14,'Axe 2 Règles de gestion'!$D$2:$F$40,3, FALSE) -> Le militaire doit exercer une activité au titre d'un engagement à servir dans la réserve opérationnelle ou au titre de la disponibilité. | Z14: PEF_I_020 | AA14: =VLOOKUP(Z14,'Axe 2 Règles de gestion'!$D$2:$F$40,3, FALSE) -> En cas de participation à des opérations militaires, la permission est accordée par le commandant de la formation administrative ou l'autorité équivalente, dans les conditions fixées par le ministre de la défense. | AB14: PEF_I_001 | AC14: =VLOOKUP(AB14,'Axe 2 Règles de gestion'!$D$2:$F$40,3, FALSE) -> La permission est accordée à l'occasion du mariage du militaire ou de la conclusion d'un pacte civil de solidarité par ce dernier. | AD14: PEF_I_011 | AE14: =VLOOKUP(AD14,'Axe 2 Règles de gestion'!$D$2:$F$40,3, FALSE) -> La permission est accordée à l'occasion de la naissance d'un enfant du militaire ou de l'accueil d'un enfant par le militaire. | AF14: PEF_I_004 | AG14: =VLOOKUP(AF14,'Axe 2 Règles de gestion'!$D$2:$F$40,3, FALSE) -> La permission est accordée à l'occasion du mariage d'un enfant du militaire. | AH14: PEF_I_005 | AI14: =VLOOKUP(AH14,'Axe 2 Règles de gestion'!$D$2:$F$40,3, FALSE) -> La permission est accordée à l'occasion du décès d'un parent du militaire, lorsqu'il s'agit des grands-parents, parents, beaux-parents, frère ou sœur. | AJ14: PEF_I_003 | AK14: =VLOOKUP(AJ14,'Axe 2 Règles de gestion'!$D$2:$F$40,3, FALSE) -> La permission est accordée à l'occasion de l'arrivée dans le foyer du militaire d'un enfant placé en vue de son adoption. | AL14: PEF_I_002 | AM14: =VLOOKUP(AL14,'Axe 2 Règles de gestion'!$D$2:$F$40,3, FALSE) -> Lorsque la permission est prise à l'occasion de de l'arrivée d'un enfant placé en vue de son adoption, les jours sont pris de manière continue ou fractionnée. | AN14: PEF_I_013 | AO14: =VLOOKUP(AN14,'Axe 2 Règles de gestion'!$D$2:$F$40,3, FALSE) -> La permission peut être prise, au choix du militaire, à compter du jour de l'arrivée de l'enfant adopté au sein du foyer ou au cours de la période de 7 jours consécutifs précédant son arrivée. | AP14: PEF_D_003 | AQ14: =VLOOKUP(AP14,'Axe 2 Règles de gestion'!$D$2:$F$40,3, FALSE) -> La durée prévisionnelle de la permission est de 3 jours ouvrés. | AR14: PEF_D_004 | AS14: =VLOOKUP(AR14,'Axe 2 Règles de gestion'!$D$2:$F$40,3, FALSE) -> La durée réelle de la permission est de 3 jours ouvrés. | AT14: PEF_D_012 | AU14: =VLOOKUP(AT14,'Axe 2 Règles de gestion'!$D$2:$F$40,3, FALSE) -> La date de fin prévisionnelle de la permission doit être antérieure ou égale à la date limite de fin réelle ou prévisionnelle du lien juridique. Le militaire ne voit pas son contrat prorogé jusqu'à la date de fin de la permission. | AV14: PEF_D_011 | AW14: =VLOOKUP(AV14,'Axe 2 Règles de gestion'!$D$2:$F$40,3, FALSE) -> La date de fin réelle de la permission doit être antérieure ou égale à la date limite de fin réelle ou prévisionnelle du lien juridique. Le militaire ne voit pas son contrat prorogé jusqu'à la date de fin de la permission. | AX14: PEF_D_001 | AY14: =VLOOKUP(AX14,'Axe 2 Règles de gestion'!$D$2:$F$40,3, FALSE) -> Le militaire est en activité. | BB14: ABS_C_001 | BC14: =VLOOKUP(BB14,'Axe 2 Règles de gestion'!$D$2:$F$40,3, FALSE) -> La date de début du congé/absence doit être postérieure ou égale à la date de recrutement dans la FPE ou dans la carrière militaire. | BD14: ABS_C_045 | BE14: =VLOOKUP(BD14,'Axe 2 Règles de gestion'!$D$2:$F$40,3, FALSE) -> Pour les militaires sous contrat à durée déterminée, la date de début du congé/absence doit être postérieure ou égale à la date de début du lien juridique. | BF14: ABS_C_003 | BG14: =VLOOKUP(BF14,'Axe 2 Règles de gestion'!$D$2:$F$40,3, FALSE) -> La date de début du congé/absence doit être antérieure ou égale à la date de fin réelle du congé/absence. | BH14: ABS_C_004 | BI14: =VLOOKUP(BH14,'Axe 2 Règles de gestion'!$D$2:$F$40,3, FALSE) -> La date de début du congé/absence doit être antérieure ou égale à la date de fin prévisionnelle du congé/absence. | BJ14: ABS_C_007 | BK14: =VLOOKUP(BJ14,'Axe 2 Règles de gestion'!$D$2:$F$40,3, FALSE) -> La date de fin réelle du congé/absence doit être antérieure à la date limite de départ à la retraite. | BL14: ABS_C_008 | BM14: =VLOOKUP(BL14,'Axe 2 Règles de gestion'!$D$2:$F$40,3, FALSE) -> La date de fin prévisionnelle du congé/absence doit être antérieure à la date limite de départ à la retraite. | BN14: ABS_C_009 | BO14: =VLOOKUP(BN14,'Axe 2 Règles de gestion'!$D$2:$F$40,3, FALSE) -> La date de fin réelle ou la date de fin prévisionnelle du congé/absence doit être saisie. | BP14: ABS_C_019 | BQ14: =VLOOKUP(BP14,'Axe 2 Règles de gestion'!$D$2:$F$40,3, FALSE) -> Si l'absence ne commence pas par une demi-journée et si l'absence précédente ne finit pas par une demi journée, la date de début de l'absence saisie est postérieure à la date de fin réelle de l'absence précédente. | BR14: ABS_C_020 | BS14: =VLOOKUP(BR14,'Axe 2 Règles de gestion'!$D$2:$F$40,3, FALSE) -> Si l'absence ne commence pas par une demi-journée et si l'absence précédente ne finit pas par une demi journée, la date de début de l'absence saisie est postérieure à la date de fin prévisionnelle de l'absence précédente. | BT14: ABS_C_026 | BU14: =VLOOKUP(BT14,'Axe 2 Règles de gestion'!$D$2:$F$40,3, FALSE) -> Dans le cas d'un congé autre que CLM, CLD, CGM et CITIS, l'indicateur de requalification doit être à non et les impacts spécifiques à la requalification ne doivent pas être mobilisés ou l'impact rémunération est vide.
A15: 24.00.00 | B15: A | C15: 45414.667 | D15: D0007 | E15: Congés/Absence | F15: S0171 | G15: Permission liée à des évènements familiaux | H15: E0863 | I15: Permission pour évènements familiaux (mariage, PACS, naissance, adoption, décès d'un parent) | J15: Le Type de congé/absence est 'Permission pour évènements familiaux (mariage, PACS, naissance, adoption, décès d'un parent)' | K15: A_COA_TYCOAB [Saisi] = 'CP007' | L15: T2305 | M15: Permission pour évènements familiaux (mariage, PACS, naissance, adoption, décès d'un parent) - Fin | N15: Modification | Q15: Militaire de réserve | R15: P0146 | S15: Particulier | T15: Passant | U15: 44927 | W15: PEF_I_022 ET PEF_D_003 ET PEF_D_004 ET PEF_D_012 ET PEF_D_011 ET PEF_D_001 ET ABS_C_003 ET ABS_C_004 ET ABS_C_007 ET ABS_C_008 ET ABS_C_009 ET ABS_C_026 | X15: PEF_I_022 | Y15: =VLOOKUP(X15,'Axe 2 Règles de gestion'!$D$2:$F$40,3, FALSE) -> Le militaire en permission peut être rappelé immédiatement lorsque les circonstances l'exigent. | AP15: PEF_D_003 | AQ15: =VLOOKUP(AP15,'Axe 2 Règles de gestion'!$D$2:$F$40,3, FALSE) -> La durée prévisionnelle de la permission est de 3 jours ouvrés. | AR15: PEF_D_004 | AS15: =VLOOKUP(AR15,'Axe 2 Règles de gestion'!$D$2:$F$40,3, FALSE) -> La durée réelle de la permission est de 3 jours ouvrés. | AT15: PEF_D_012 | AU15: =VLOOKUP(AT15,'Axe 2 Règles de gestion'!$D$2:$F$40,3, FALSE) -> La date de fin prévisionnelle de la permission doit être antérieure ou égale à la date limite de fin réelle ou prévisionnelle du lien juridique. Le militaire ne voit pas son contrat prorogé jusqu'à la date de fin de la permission. | AV15: PEF_D_011 | AW15: =VLOOKUP(AV15,'Axe 2 Règles de gestion'!$D$2:$F$40,3, FALSE) -> La date de fin réelle de la permission doit être antérieure ou égale à la date limite de fin réelle ou prévisionnelle du lien juridique. Le militaire ne voit pas son contrat prorogé jusqu'à la date de fin de la permission. | AX15: PEF_D_001 | AY15: =VLOOKUP(AX15,'Axe 2 Règles de gestion'!$D$2:$F$40,3, FALSE) -> Le militaire est en activité. | BB15: ABS_C_003 | BC15: =VLOOKUP(BB15,'Axe 2 Règles de gestion'!$D$2:$F$40,3, FALSE) -> La date de début du congé/absence doit être antérieure ou égale à la date de fin réelle du congé/absence. | BD15: ABS_C_004 | BE15: =VLOOKUP(BD15,'Axe 2 Règles de gestion'!$D$2:$F$40,3, FALSE) -> La date de début du congé/absence doit être antérieure ou égale à la date de fin prévisionnelle du congé/absence. | BF15: ABS_C_007 | BG15: =VLOOKUP(BF15,'Axe 2 Règles de gestion'!$D$2:$F$40,3, FALSE) -> La date de fin réelle du congé/absence doit être antérieure à la date limite de départ à la retraite. | BH15: ABS_C_008 | BI15: =VLOOKUP(BH15,'Axe 2 Règles de gestion'!$D$2:$F$40,3, FALSE) -> La date de fin prévisionnelle du congé/absence doit être antérieure à la date limite de départ à la retraite. | BJ15: ABS_C_009 | BK15: =VLOOKUP(BJ15,'Axe 2 Règles de gestion'!$D$2:$F$40,3, FALSE) -> La date de fin réelle ou la date de fin prévisionnelle du congé/absence doit être saisie. | BL15: ABS_C_026 | BM15: =VLOOKUP(BL15,'Axe 2 Règles de gestion'!$D$2:$F$40,3, FALSE) -> Dans le cas d'un congé autre que CLM, CLD, CGM et CITIS, l'indicateur de requalification doit être à non et les impacts spécifiques à la requalification ne doivent pas être mobilisés ou l'impact rémunération est vide.
A16: 24.00.00 | B16: A | C16: 45414.667 | D16: D0007 | E16: Congés/Absence | F16: S0171 | G16: Permission liée à des évènements familiaux | H16: E0863 | I16: Permission pour évènements familiaux (mariage, PACS, naissance, adoption, décès d'un parent) | J16: Le Type de congé/absence est 'Permission pour évènements familiaux (mariage, PACS, naissance, adoption, décès d'un parent)' | K16: A_COA_TYCOAB [Saisi] = 'CP007' | L16: T2304 | M16: Permission pour évènements familiaux (mariage, PACS, naissance, adoption, décès d'un parent) - Demande | N16: Création | Q16: Militaire de carrière | R16: P0189 | S16: Particulier | T16: Passant | U16: 44927 | W16: PEF_I_020 ET PEF_I_001 ET PEF_I_011 ET PEF_I_004 ET PEF_I_005 ET PEF_I_003 ET PEF_I_002 ET PEF_I_013 ET PEF_D_003 ET PEF_D_004 ET PEF_D_001 ET ABS_C_001 ET ABS_C_003 ET ABS_C_004 ET ABS_C_007 ET ABS_C_008 ET ABS_C_009 ET ABS_C_019 ET ABS_C_020 ET ABS_C_026 | X16: PEF_I_020 | Y16: =VLOOKUP(X16,'Axe 2 Règles de gestion'!$D$2:$F$40,3, FALSE) -> En cas de participation à des opérations militaires, la permission est accordée par le commandant de la formation administrative ou l'autorité équivalente, dans les conditions fixées par le ministre de la défense. | Z16: PEF_I_001 | AA16: =VLOOKUP(Z16,'Axe 2 Règles de gestion'!$D$2:$F$40,3, FALSE) -> La permission est accordée à l'occasion du mariage du militaire ou de la conclusion d'un pacte civil de solidarité par ce dernier. | AB16: PEF_I_011 | AC16: =VLOOKUP(AB16,'Axe 2 Règles de gestion'!$D$2:$F$40,3, FALSE) -> La permission est accordée à l'occasion de la naissance d'un enfant du militaire ou de l'accueil d'un enfant par le militaire. | AD16: PEF_I_004 | AE16: =VLOOKUP(AD16,'Axe 2 Règles de gestion'!$D$2:$F$40,3, FALSE) -> La permission est accordée à l'occasion du mariage d'un enfant du militaire. | AF16: PEF_I_005 | AG16: =VLOOKUP(AF16,'Axe 2 Règles de gestion'!$D$2:$F$40,3, FALSE) -> La permission est accordée à l'occasion du décès d'un parent du militaire, lorsqu'il s'agit des grands-parents, parents, beaux-parents, frère ou sœur. | AH16: PEF_I_003 | AI16: =VLOOKUP(AH16,'Axe 2 Règles de gestion'!$D$2:$F$40,3, FALSE) -> La permission est accordée à l'occasion de l'arrivée dans le foyer du militaire d'un enfant placé en vue de son adoption. | AJ16: PEF_I_002 | AK16: =VLOOKUP(AJ16,'Axe 2 Règles de gestion'!$D$2:$F$40,3, FALSE) -> Lorsque la permission est prise à l'occasion de de l'arrivée d'un enfant placé en vue de son adoption, les jours sont pris de manière continue ou fractionnée. | AL16: PEF_I_013 | AM16: =VLOOKUP(AL16,'Axe 2 Règles de gestion'!$D$2:$F$40,3, FALSE) -> La permission peut être prise, au choix du militaire, à compter du jour de l'arrivée de l'enfant adopté au sein du foyer ou au cours de la période de 7 jours consécutifs précédant son arrivée. | AP16: PEF_D_003 | AQ16: =VLOOKUP(AP16,'Axe 2 Règles de gestion'!$D$2:$F$40,3, FALSE) -> La durée prévisionnelle de la permission est de 3 jours ouvrés. | AR16: PEF_D_004 | AS16: =VLOOKUP(AR16,'Axe 2 Règles de gestion'!$D$2:$F$40,3, FALSE) -> La durée réelle de la permission est de 3 jours ouvrés. | AT16: PEF_D_001 | AU16: =VLOOKUP(AT16,'Axe 2 Règles de gestion'!$D$2:$F$40,3, FALSE) -> Le militaire est en activité. | BB16: ABS_C_001 | BC16: =VLOOKUP(BB16,'Axe 2 Règles de gestion'!$D$2:$F$40,3, FALSE) -> La date de début du congé/absence doit être postérieure ou égale à la date de recrutement dans la FPE ou dans la carrière militaire. | BD16: ABS_C_003 | BE16: =VLOOKUP(BD16,'Axe 2 Règles de gestion'!$D$2:$F$40,3, FALSE) -> La date de début du congé/absence doit être antérieure ou égale à la date de fin réelle du congé/absence. | BF16: ABS_C_004 | BG16: =VLOOKUP(BF16,'Axe 2 Règles de gestion'!$D$2:$F$40,3, FALSE) -> La date de début du congé/absence doit être antérieure ou égale à la date de fin prévisionnelle du congé/absence. | BH16: ABS_C_007 | BI16: =VLOOKUP(BH16,'Axe 2 Règles de gestion'!$D$2:$F$40,3, FALSE) -> La date de fin réelle du congé/absence doit être antérieure à la date limite de départ à la retraite. | BJ16: ABS_C_008 | BK16: =VLOOKUP(BJ16,'Axe 2 Règles de gestion'!$D$2:$F$40,3, FALSE) -> La date de fin prévisionnelle du congé/absence doit être antérieure à la date limite de départ à la retraite. | BL16: ABS_C_009 | BM16: =VLOOKUP(BL16,'Axe 2 Règles de gestion'!$D$2:$F$40,3, FALSE) -> La date de fin réelle ou la date de fin prévisionnelle du congé/absence doit être saisie. | BN16: ABS_C_019 | BO16: =VLOOKUP(BN16,'Axe 2 Règles de gestion'!$D$2:$F$40,3, FALSE) -> Si l'absence ne commence pas par une demi-journée et si l'absence précédente ne finit pas par une demi journée, la date de début de l'absence saisie est postérieure à la date de fin réelle de l'absence précédente. | BP16: ABS_C_020 | BQ16: =VLOOKUP(BP16,'Axe 2 Règles de gestion'!$D$2:$F$40,3, FALSE) -> Si l'absence ne commence pas par une demi-journée et si l'absence précédente ne finit pas par une demi journée, la date de début de l'absence saisie est postérieure à la date de fin prévisionnelle de l'absence précédente. | BR16: ABS_C_026 | BS16: =VLOOKUP(BR16,'Axe 2 Règles de gestion'!$D$2:$F$40,3, FALSE) -> Dans le cas d'un congé autre que CLM, CLD, CGM et CITIS, l'indicateur de requalification doit être à non et les impacts spécifiques à la requalification ne doivent pas être mobilisés ou l'impact rémunération est vide.
A17: 24.00.00 | B17: A | C17: 45414.667 | D17: D0007 | E17: Congés/Absence | F17: S0171 | G17: Permission liée à des évènements familiaux | H17: E0863 | I17: Permission pour évènements familiaux (mariage, PACS, naissance, adoption, décès d'un parent) | J17: Le Type de congé/absence est 'Permission pour évènements familiaux (mariage, PACS, naissance, adoption, décès d'un parent)' | K17: A_COA_TYCOAB [Saisi] = 'CP007' | L17: T2305 | M17: Permission pour évènements familiaux (mariage, PACS, naissance, adoption, décès d'un parent) - Fin | N17: Modification | Q17: Militaire de carrière | R17: P0189 | S17: Particulier | T17: Passant | U17: 44927 | W17: PEF_I_022 ET PEF_D_003 ET PEF_D_004 ET PEF_D_001 ET ABS_C_003 ET ABS_C_004 ET ABS_C_007 ET ABS_C_008 ET ABS_C_009 ET ABS_C_026 | X17: PEF_I_022 | Y17: =VLOOKUP(X17,'Axe 2 Règles de gestion'!$D$2:$F$40,3, FALSE) -> Le militaire en permission peut être rappelé immédiatement lorsque les circonstances l'exigent. | AP17: PEF_D_003 | AQ17: =VLOOKUP(AP17,'Axe 2 Règles de gestion'!$D$2:$F$40,3, FALSE) -> La durée prévisionnelle de la permission est de 3 jours ouvrés. | AR17: PEF_D_004 | AS17: =VLOOKUP(AR17,'Axe 2 Règles de gestion'!$D$2:$F$40,3, FALSE) -> La durée réelle de la permission est de 3 jours ouvrés. | AT17: PEF_D_001 | AU17: =VLOOKUP(AT17,'Axe 2 Règles de gestion'!$D$2:$F$40,3, FALSE) -> Le militaire est en activité. | BB17: ABS_C_003 | BC17: =VLOOKUP(BB17,'Axe 2 Règles de gestion'!$D$2:$F$40,3, FALSE) -> La date de début du congé/absence doit être antérieure ou égale à la date de fin réelle du congé/absence. | BD17: ABS_C_004 | BE17: =VLOOKUP(BD17,'Axe 2 Règles de gestion'!$D$2:$F$40,3, FALSE) -> La date de début du congé/absence doit être antérieure ou égale à la date de fin prévisionnelle du congé/absence. | BF17: ABS_C_007 | BG17: =VLOOKUP(BF17,'Axe 2 Règles de gestion'!$D$2:$F$40,3, FALSE) -> La date de fin réelle du congé/absence doit être antérieure à la date limite de départ à la retraite. | BH17: ABS_C_008 | BI17: =VLOOKUP(BH17,'Axe 2 Règles de gestion'!$D$2:$F$40,3, FALSE) -> La date de fin prévisionnelle du congé/absence doit être antérieure à la date limite de départ à la retraite. | BJ17: ABS_C_009 | BK17: =VLOOKUP(BJ17,'Axe 2 Règles de gestion'!$D$2:$F$40,3, FALSE) -> La date de fin réelle ou la date de fin prévisionnelle du congé/absence doit être saisie. | BL17: ABS_C_026 | BM17: =VLOOKUP(BL17,'Axe 2 Règles de gestion'!$D$2:$F$40,3, FALSE) -> Dans le cas d'un congé autre que CLM, CLD, CGM et CITIS, l'indicateur de requalification doit être à non et les impacts spécifiques à la requalification ne doivent pas être mobilisés ou l'impact rémunération est vide.
A18: 24.00.00 | B18: A | C18: 45414.668 | D18: D0007 | E18: Congés/Absence | F18: S0171 | G18: Permission liée à des évènements familiaux | H18: E0955 | I18: Permission pour le décès du conjoint du militaire, du partenaire pacsé ou de l'enfant | J18: Le Type de congé/absence est 'Permission pour le décès du conjoint du militaire, du partenaire pacsé ou de l'enfant' | K18: A_COA_TYCOAB [Saisi] = 'CP008' | L18: T2306 | M18: Permission pour le décès du conjoint du militaire, du partenaire pacsé ou de l'enfant - Demande | N18: Création | Q18: Titulaire ou magistrat | R18: P0001 | S18: Général | T18: Exclu | U18: 44927
A19: 24.00.00 | B19: A | C19: 45414.669 | D19: D0007 | E19: Congés/Absence | F19: S0171 | G19: Permission liée à des évènements familiaux | H19: E0955 | I19: Permission pour le décès du conjoint du militaire, du partenaire pacsé ou de l'enfant | J19: Le Type de congé/absence est 'Permission pour le décès du conjoint du militaire, du partenaire pacsé ou de l'enfant' | K19: A_COA_TYCOAB [Saisi] = 'CP008' | L19: T2307 | M19: Permission pour le décès du conjoint du militaire, du partenaire pacsé ou de l'enfant - Fin | N19: Modification | Q19: Titulaire ou magistrat | R19: P0001 | S19: Général | T19: Exclu | U19: 44927
A20: 24.00.00 | B20: A | C20: 45414.669 | D20: D0007 | E20: Congés/Absence | F20: S0171 | G20: Permission liée à des évènements familiaux | H20: E0955 | I20: Permission pour le décès du conjoint du militaire, du partenaire pacsé ou de l'enfant | J20: Le Type de congé/absence est 'Permission pour le décès du conjoint du militaire, du partenaire pacsé ou de l'enfant' | K20: A_COA_TYCOAB [Saisi] = 'CP008' | L20: T2306 | M20: Permission pour le décès du conjoint du militaire, du partenaire pacsé ou de l'enfant - Demande | N20: Création | Q20: Militaire | R20: P0002 | S20: Général | T20: Exclu | U20: 44927
A21: 24.00.00 | B21: A | C21: 45414.67 | D21: D0007 | E21: Congés/Absence | F21: S0171 | G21: Permission liée à des évènements familiaux | H21: E0955 | I21: Permission pour le décès du conjoint du militaire, du partenaire pacsé ou de l'enfant | J21: Le Type de congé/absence est 'Permission pour le décès du conjoint du militaire, du partenaire pacsé ou de l'enfant' | K21: A_COA_TYCOAB [Saisi] = 'CP008' | L21: T2307 | M21: Permission pour le décès du conjoint du militaire, du partenaire pacsé ou de l'enfant - Fin | N21: Modification | Q21: Militaire | R21: P0002 | S21: Général | T21: Exclu | U21: 44927
A22: 24.00.00 | B22: A | C22: 45414.669 | D22: D0007 | E22: Congés/Absence | F22: S0171 | G22: Permission liée à des évènements familiaux | H22: E0955 | I22: Permission pour le décès du conjoint du militaire, du partenaire pacsé ou de l'enfant | J22: Le Type de congé/absence est 'Permission pour le décès du conjoint du militaire, du partenaire pacsé ou de l'enfant' | K22: A_COA_TYCOAB [Saisi] = 'CP008' | L22: T2306 | M22: Permission pour le décès du conjoint du militaire, du partenaire pacsé ou de l'enfant - Demande | N22: Création | Q22: Contractuel | R22: P0003 | S22: Général | T22: Exclu | U22: 44927
A23: 24.00.00 | B23: A | C23: 45414.669 | D23: D0007 | E23: Congés/Absence | F23: S0171 | G23: Permission liée à des évènements familiaux | H23: E0955 | I23: Permission pour le décès du conjoint du militaire, du partenaire pacsé ou de l'enfant | J23: Le Type de congé/absence est 'Permission pour le décès du conjoint du militaire, du partenaire pacsé ou de l'enfant' | K23: A_COA_TYCOAB [Saisi] = 'CP008' | L23: T2307 | M23: Permission pour le décès du conjoint du militaire, du partenaire pacsé ou de l'enfant - Fin | N23: Modification | Q23: Contractuel | R23: P0003 | S23: Général | T23: Exclu | U23: 44927
A24: 24.00.00 | B24: A | C24: 45414.669 | D24: D0007 | E24: Congés/Absence | F24: S0171 | G24: Permission liée à des évènements familiaux | H24: E0955 | I24: Permission pour le décès du conjoint du militaire, du partenaire pacsé ou de l'enfant | J24: Le Type de congé/absence est 'Permission pour le décès du conjoint du militaire, du partenaire pacsé ou de l'enfant' | K24: A_COA_TYCOAB [Saisi] = 'CP008' | L24: T2306 | M24: Permission pour le décès du conjoint du militaire, du partenaire pacsé ou de l'enfant - Demande | N24: Création | Q24: Stagiaire ou auditeur ou élève | R24: P0004 | S24: Général | T24: Exclu | U24: 44927
A25: 24.00.00 | B25: A | C25: 45414.669 | D25: D0007 | E25: Congés/Absence | F25: S0171 | G25: Permission liée à des évènements familiaux | H25: E0955 | I25: Permission pour le décès du conjoint du militaire, du partenaire pacsé ou de l'enfant | J25: Le Type de congé/absence est 'Permission pour le décès du conjoint du militaire, du partenaire pacsé ou de l'enfant' | K25: A_COA_TYCOAB [Saisi] = 'CP008' | L25: T2307 | M25: Permission pour le décès du conjoint du militaire, du partenaire pacsé ou de l'enfant - Fin | N25: Modification | Q25: Stagiaire ou auditeur ou élève | R25: P0004 | S25: Général | T25: Exclu | U25: 44927
A26: 24.00.00 | B26: A | C26: 45414.669 | D26: D0007 | E26: Congés/Absence | F26: S0171 | G26: Permission liée à des évènements familiaux | H26: E0955 | I26: Permission pour le décès du conjoint du militaire, du partenaire pacsé ou de l'enfant | J26: Le Type de congé/absence est 'Permission pour le décès du conjoint du militaire, du partenaire pacsé ou de l'enfant' | K26: A_COA_TYCOAB [Saisi] = 'CP008' | L26: T2306 | M26: Permission pour le décès du conjoint du militaire, du partenaire pacsé ou de l'enfant - Demande | N26: Création | Q26: Ouvrier d'état | R26: P0005 | S26: Général | T26: Exclu | U26: 44927
A27: 24.00.00 | B27: A | C27: 45414.669 | D27: D0007 | E27: Congés/Absence | F27: S0171 | G27: Permission liée à des évènements familiaux | H27: E0955 | I27: Permission pour le décès du conjoint du militaire, du partenaire pacsé ou de l'enfant | J27: Le Type de congé/absence est 'Permission pour le décès du conjoint du militaire, du partenaire pacsé ou de l'enfant' | K27: A_COA_TYCOAB [Saisi] = 'CP008' | L27: T2307 | M27: Permission pour le décès du conjoint du militaire, du partenaire pacsé ou de l'enfant - Fin | N27: Modification | Q27: Ouvrier d'état | R27: P0005 | S27: Général | T27: Exclu | U27: 44927
A28: 24.00.00 | B28: A | C28: 45414.671 | D28: D0007 | E28: Congés/Absence | F28: S0171 | G28: Permission liée à des évènements familiaux | H28: E0955 | I28: Permission pour le décès du conjoint du militaire, du partenaire pacsé ou de l'enfant | J28: Le Type de congé/absence est 'Permission pour le décès du conjoint du militaire, du partenaire pacsé ou de l'enfant' | K28: A_COA_TYCOAB [Saisi] = 'CP008' | L28: T2306 | M28: Permission pour le décès du conjoint du militaire, du partenaire pacsé ou de l'enfant - Demande | N28: Création | Q28: Militaire sous contrat | R28: P0145 | S28: Particulier | T28: Passant | U28: 44927 | W28: PEF_I_020 ET PEF_I_017 ET PEF_I_019 ET PEF_I_028 ET PEF_I_024 ET PEF_D_007 ET PEF_D_008 ET PEF_D_016 ET PEF_D_012 ET PEF_D_011 ET PEF_D_001 ET ABS_C_001 ET ABS_C_045 ET ABS_C_003 ET ABS_C_004 ET ABS_C_007 ET ABS_C_008 ET ABS_C_009 ET ABS_C_019 ET ABS_C_020 ET ABS_C_026 | X28: PEF_I_020 | Y28: =VLOOKUP(X28,'Axe 2 Règles de gestion'!$D$2:$F$40,3, FALSE) -> En cas de participation à des opérations militaires, la permission est accordée par le commandant de la formation administrative ou l'autorité équivalente, dans les conditions fixées par le ministre de la défense. | Z28: PEF_I_017 | AA28: =VLOOKUP(Z28,'Axe 2 Règles de gestion'!$D$2:$F$40,3, FALSE) -> Une permission de 5 jours est accordée pour le décès du conjoint du militaire, du partenaire auquel celui-ci est lié par un PACS ou du concubin. | AB28: PEF_I_019 | AC28: =VLOOKUP(AB28,'Axe 2 Règles de gestion'!$D$2:$F$40,3, FALSE) -> Une permission de 5 jours est accordée pour le décès de l'enfant du militaire. | AD28: PEF_I_028 | AE28: =VLOOKUP(AD28,'Axe 2 Règles de gestion'!$D$2:$F$40,3, FALSE) -> La durée de la permission est portée à 7 jours lorsque l'enfant qui décède est âgé de moins de 25 ans ou en cas de décès d'une personne âgée de moins de 25 ans dont le militaire a la charge effective et permanente. | AF28: PEF_I_024 | AG28: =VLOOKUP(AF28,'Axe 2 Règles de gestion'!$D$2:$F$40,3, FALSE) -> Le militaire bénéficie dans les mêmes conditions d'une seconde permission de 8 jours. Elle peut être fractionnée en 2 périodes. Chaque période est d'une durée au moins égale à 1 journée. Elle est prise dans un délai d'1 an à compter du décès. | AP28: PEF_D_007 | AQ28: =VLOOKUP(AP28,'Axe 2 Règles de gestion'!$D$2:$F$40,3, FALSE) -> La durée prévisionnelle de la permission est de 5 jours ouvrés. | AR28: PEF_D_008 | AS28: =VLOOKUP(AR28,'Axe 2 Règles de gestion'!$D$2:$F$40,3, FALSE) -> La durée réelle de la permission est de 5 jours ouvrés. | AT28: PEF_D_016 | AU28: =VLOOKUP(AT28,'Axe 2 Règles de gestion'!$D$2:$F$40,3, FALSE) -> La durée cumulée des deux périodes de permission ne peut pas dépasser les 15 jours ouvrés. | AV28: PEF_D_012 | AW28: =VLOOKUP(AV28,'Axe 2 Règles de gestion'!$D$2:$F$40,3, FALSE) -> La date de fin prévisionnelle de la permission doit être antérieure ou égale à la date limite de fin réelle ou prévisionnelle du lien juridique. Le militaire ne voit pas son contrat prorogé jusqu'à la date de fin de la permission. | AX28: PEF_D_011 | AY28: =VLOOKUP(AX28,'Axe 2 Règles de gestion'!$D$2:$F$40,3, FALSE) -> La date de fin réelle de la permission doit être antérieure ou égale à la date limite de fin réelle ou prévisionnelle du lien juridique. Le militaire ne voit pas son contrat prorogé jusqu'à la date de fin de la permission. | AZ28: PEF_D_001 | BA28: =VLOOKUP(AZ28,'Axe 2 Règles de gestion'!$D$2:$F$40,3, FALSE) -> Le militaire est en activité. | BB28: ABS_C_001 | BC28: =VLOOKUP(BB28,'Axe 2 Règles de gestion'!$D$2:$F$40,3, FALSE) -> La date de début du congé/absence doit être postérieure ou égale à la date de recrutement dans la FPE ou dans la carrière militaire. | BD28: ABS_C_045 | BE28: =VLOOKUP(BD28,'Axe 2 Règles de gestion'!$D$2:$F$40,3, FALSE) -> Pour les militaires sous contrat à durée déterminée, la date de début du congé/absence doit être postérieure ou égale à la date de début du lien juridique. | BF28: ABS_C_003 | BG28: =VLOOKUP(BF28,'Axe 2 Règles de gestion'!$D$2:$F$40,3, FALSE) -> La date de début du congé/absence doit être antérieure ou égale à la date de fin réelle du congé/absence. | BH28: ABS_C_004 | BI28: =VLOOKUP(BH28,'Axe 2 Règles de gestion'!$D$2:$F$40,3, FALSE) -> La date de début du congé/absence doit être antérieure ou égale à la date de fin prévisionnelle du congé/absence. | BJ28: ABS_C_007 | BK28: =VLOOKUP(BJ28,'Axe 2 Règles de gestion'!$D$2:$F$40,3, FALSE) -> La date de fin réelle du congé/absence doit être antérieure à la date limite de départ à la retraite. | BL28: ABS_C_008 | BM28: =VLOOKUP(BL28,'Axe 2 Règles de gestion'!$D$2:$F$40,3, FALSE) -> La date de fin prévisionnelle du congé/absence doit être antérieure à la date limite de départ à la retraite. | BN28: ABS_C_009 | BO28: =VLOOKUP(BN28,'Axe 2 Règles de gestion'!$D$2:$F$40,3, FALSE) -> La date de fin réelle ou la date de fin prévisionnelle du congé/absence doit être saisie. | BP28: ABS_C_019 | BQ28: =VLOOKUP(BP28,'Axe 2 Règles de gestion'!$D$2:$F$40,3, FALSE) -> Si l'absence ne commence pas par une demi-journée et si l'absence précédente ne finit pas par une demi journée, la date de début de l'absence saisie est postérieure à la date de fin réelle de l'absence précédente. | BR28: ABS_C_020 | BS28: =VLOOKUP(BR28,'Axe 2 Règles de gestion'!$D$2:$F$40,3, FALSE) -> Si l'absence ne commence pas par une demi-journée et si l'absence précédente ne finit pas par une demi journée, la date de début de l'absence saisie est postérieure à la date de fin prévisionnelle de l'absence précédente. | BT28: ABS_C_026 | BU28: =VLOOKUP(BT28,'Axe 2 Règles de gestion'!$D$2:$F$40,3, FALSE) -> Dans le cas d'un congé autre que CLM, CLD, CGM et CITIS, l'indicateur de requalification doit être à non et les impacts spécifiques à la requalification ne doivent pas être mobilisés ou l'impact rémunération est vide.
A29: 24.00.00 | B29: A | C29: 45414.672 | D29: D0007 | E29: Congés/Absence | F29: S0171 | G29: Permission liée à des évènements familiaux | H29: E0955 | I29: Permission pour le décès du conjoint du militaire, du partenaire pacsé ou de l'enfant | J29: Le Type de congé/absence est 'Permission pour le décès du conjoint du militaire, du partenaire pacsé ou de l'enfant' | K29: A_COA_TYCOAB [Saisi] = 'CP008' | L29: T2307 | M29: Permission pour le décès du conjoint du militaire, du partenaire pacsé ou de l'enfant - Fin | N29: Modification | Q29: Militaire sous contrat | R29: P0145 | S29: Particulier | T29: Passant | U29: 44927 | W29: PEF_I_022 ET PEF_D_007 ET PEF_D_008 ET PEF_D_016 ET PEF_D_012 ET PEF_D_011 ET PEF_D_001 ET ABS_C_003 ET ABS_C_004 ET ABS_C_007 ET ABS_C_008 ET ABS_C_009 ET ABS_C_026 | X29: PEF_I_022 | Y29: =VLOOKUP(X29,'Axe 2 Règles de gestion'!$D$2:$F$40,3, FALSE) -> Le militaire en permission peut être rappelé immédiatement lorsque les circonstances l'exigent. | AP29: PEF_D_007 | AQ29: =VLOOKUP(AP29,'Axe 2 Règles de gestion'!$D$2:$F$40,3, FALSE) -> La durée prévisionnelle de la permission est de 5 jours ouvrés. | AR29: PEF_D_008 | AS29: =VLOOKUP(AR29,'Axe 2 Règles de gestion'!$D$2:$F$40,3, FALSE) -> La durée réelle de la permission est de 5 jours ouvrés. | AT29: PEF_D_016 | AU29: =VLOOKUP(AT29,'Axe 2 Règles de gestion'!$D$2:$F$40,3, FALSE) -> La durée cumulée des deux périodes de permission ne peut pas dépasser les 15 jours ouvrés. | AV29: PEF_D_012 | AW29: =VLOOKUP(AV29,'Axe 2 Règles de gestion'!$D$2:$F$40,3, FALSE) -> La date de fin prévisionnelle de la permission doit être antérieure ou égale à la date limite de fin réelle ou prévisionnelle du lien juridique. Le militaire ne voit pas son contrat prorogé jusqu'à la date de fin de la permission. | AX29: PEF_D_011 | AY29: =VLOOKUP(AX29,'Axe 2 Règles de gestion'!$D$2:$F$40,3, FALSE) -> La date de fin réelle de la permission doit être antérieure ou égale à la date limite de fin réelle ou prévisionnelle du lien juridique. Le militaire ne voit pas son contrat prorogé jusqu'à la date de fin de la permission. | AZ29: PEF_D_001 | BA29: =VLOOKUP(AZ29,'Axe 2 Règles de gestion'!$D$2:$F$40,3, FALSE) -> Le militaire est en activité. | BB29: ABS_C_003 | BC29: =VLOOKUP(BB29,'Axe 2 Règles de gestion'!$D$2:$F$40,3, FALSE) -> La date de début du congé/absence doit être antérieure ou égale à la date de fin réelle du congé/absence. | BD29: ABS_C_004 | BE29: =VLOOKUP(BD29,'Axe 2 Règles de gestion'!$D$2:$F$40,3, FALSE) -> La date de début du congé/absence doit être antérieure ou égale à la date de fin prévisionnelle du congé/absence. | BF29: ABS_C_007 | BG29: =VLOOKUP(BF29,'Axe 2 Règles de gestion'!$D$2:$F$40,3, FALSE) -> La date de fin réelle du congé/absence doit être antérieure à la date limite de départ à la retraite. | BH29: ABS_C_008 | BI29: =VLOOKUP(BH29,'Axe 2 Règles de gestion'!$D$2:$F$40,3, FALSE) -> La date de fin prévisionnelle du congé/absence doit être antérieure à la date limite de départ à la retraite. | BJ29: ABS_C_009 | BK29: =VLOOKUP(BJ29,'Axe 2 Règles de gestion'!$D$2:$F$40,3, FALSE) -> La date de fin réelle ou la date de fin prévisionnelle du congé/absence doit être saisie. | BL29: ABS_C_026 | BM29: =VLOOKUP(BL29,'Axe 2 Règles de gestion'!$D$2:$F$40,3, FALSE) -> Dans le cas d'un congé autre que CLM, CLD, CGM et CITIS, l'indicateur de requalification doit être à non et les impacts spécifiques à la requalification ne doivent pas être mobilisés ou l'impact rémunération est vide.
A30: 24.00.00 | B30: A | C30: 45414.671 | D30: D0007 | E30: Congés/Absence | F30: S0171 | G30: Permission liée à des évènements familiaux | H30: E0955 | I30: Permission pour le décès du conjoint du militaire, du partenaire pacsé ou de l'enfant | J30: Le Type de congé/absence est 'Permission pour le décès du conjoint du militaire, du partenaire pacsé ou de l'enfant' | K30: A_COA_TYCOAB [Saisi] = 'CP008' | L30: T2306 | M30: Permission pour le décès du conjoint du militaire, du partenaire pacsé ou de l'enfant - Demande | N30: Création | Q30: Militaire de réserve | R30: P0146 | S30: Particulier | T30: Passant | U30: 44927 | W30: PEF_I_015 ET PEF_I_020 ET PEF_I_017 ET PEF_I_019 ET PEF_I_028 ET PEF_I_024 ET PEF_D_007 ET PEF_D_008 ET PEF_D_016 ET PEF_D_012 ET PEF_D_011 ET PEF_D_001 ET ABS_C_001 ET ABS_C_045 ET ABS_C_003 ET ABS_C_004 ET ABS_C_007 ET ABS_C_008 ET ABS_C_009 ET ABS_C_019 ET ABS_C_020 ET ABS_C_026 | X30: PEF_I_015 | Y30: =VLOOKUP(X30,'Axe 2 Règles de gestion'!$D$2:$F$40,3, FALSE) -> Le militaire doit exercer une activité au titre d'un engagement à servir dans la réserve opérationnelle ou au titre de la disponibilité. | Z30: PEF_I_020 | AA30: =VLOOKUP(Z30,'Axe 2 Règles de gestion'!$D$2:$F$40,3, FALSE) -> En cas de participation à des opérations militaires, la permission est accordée par le commandant de la formation administrative ou l'autorité équivalente, dans les conditions fixées par le ministre de la défense. | AB30: PEF_I_017 | AC30: =VLOOKUP(AB30,'Axe 2 Règles de gestion'!$D$2:$F$40,3, FALSE) -> Une permission de 5 jours est accordée pour le décès du conjoint du militaire, du partenaire auquel celui-ci est lié par un PACS ou du concubin. | AD30: PEF_I_019 | AE30: =VLOOKUP(AD30,'Axe 2 Règles de gestion'!$D$2:$F$40,3, FALSE) -> Une permission de 5 jours est accordée pour le décès de l'enfant du militaire. | AF30: PEF_I_028 | AG30: =VLOOKUP(AF30,'Axe 2 Règles de gestion'!$D$2:$F$40,3, FALSE) -> La durée de la permission est portée à 7 jours lorsque l'enfant qui décède est âgé de moins de 25 ans ou en cas de décès d'une personne âgée de moins de 25 ans dont le militaire a la charge effective et permanente. | AH30: PEF_I_024 | AI30: =VLOOKUP(AH30,'Axe 2 Règles de gestion'!$D$2:$F$40,3, FALSE) -> Le militaire bénéficie dans les mêmes conditions d'une seconde permission de 8 jours. Elle peut être fractionnée en 2 périodes. Chaque période est d'une durée au moins égale à 1 journée. Elle est prise dans un délai d'1 an à compter du décès. | AP30: PEF_D_007 | AQ30: =VLOOKUP(AP30,'Axe 2 Règles de gestion'!$D$2:$F$40,3, FALSE) -> La durée prévisionnelle de la permission est de 5 jours ouvrés. | AR30: PEF_D_008 | AS30: =VLOOKUP(AR30,'Axe 2 Règles de gestion'!$D$2:$F$40,3, FALSE) -> La durée réelle de la permission est de 5 jours ouvrés. | AT30: PEF_D_016 | AU30: =VLOOKUP(AT30,'Axe 2 Règles de gestion'!$D$2:$F$40,3, FALSE) -> La durée cumulée des deux périodes de permission ne peut pas dépasser les 15 jours ouvrés. | AV30: PEF_D_012 | AW30: =VLOOKUP(AV30,'Axe 2 Règles de gestion'!$D$2:$F$40,3, FALSE) -> La date de fin prévisionnelle de la permission doit être antérieure ou égale à la date limite de fin réelle ou prévisionnelle du lien juridique. Le militaire ne voit pas son contrat prorogé jusqu'à la date de fin de la permission. | AX30: PEF_D_011 | AY30: =VLOOKUP(AX30,'Axe 2 Règles de gestion'!$D$2:$F$40,3, FALSE) -> La date de fin réelle de la permission doit être antérieure ou égale à la date limite de fin réelle ou prévisionnelle du lien juridique. Le militaire ne voit pas son contrat prorogé jusqu'à la date de fin de la permission. | AZ30: PEF_D_001 | BA30: =VLOOKUP(AZ30,'Axe 2 Règles de gestion'!$D$2:$F$40,3, FALSE) -> Le militaire est en activité. | BB30: ABS_C_001 | BC30: =VLOOKUP(BB30,'Axe 2 Règles de gestion'!$D$2:$F$40,3, FALSE) -> La date de début du congé/absence doit être postérieure ou égale à la date de recrutement dans la FPE ou dans la carrière militaire. | BD30: ABS_C_045 | BE30: =VLOOKUP(BD30,'Axe 2 Règles de gestion'!$D$2:$F$40,3, FALSE) -> Pour les militaires sous contrat à durée déterminée, la date de début du congé/absence doit être postérieure ou égale à la date de début du lien juridique. | BF30: ABS_C_003 | BG30: =VLOOKUP(BF30,'Axe 2 Règles de gestion'!$D$2:$F$40,3, FALSE) -> La date de début du congé/absence doit être antérieure ou égale à la date de fin réelle du congé/absence. | BH30: ABS_C_004 | BI30: =VLOOKUP(BH30,'Axe 2 Règles de gestion'!$D$2:$F$40,3, FALSE) -> La date de début du congé/absence doit être antérieure ou égale à la date de fin prévisionnelle du congé/absence. | BJ30: ABS_C_007 | BK30: =VLOOKUP(BJ30,'Axe 2 Règles de gestion'!$D$2:$F$40,3, FALSE) -> La date de fin réelle du congé/absence doit être antérieure à la date limite de départ à la retraite. | BL30: ABS_C_008 | BM30: =VLOOKUP(BL30,'Axe 2 Règles de gestion'!$D$2:$F$40,3, FALSE) -> La date de fin prévisionnelle du congé/absence doit être antérieure à la date limite de départ à la retraite. | BN30: ABS_C_009 | BO30: =VLOOKUP(BN30,'Axe 2 Règles de gestion'!$D$2:$F$40,3, FALSE) -> La date de fin réelle ou la date de fin prévisionnelle du congé/absence doit être saisie. | BP30: ABS_C_019 | BQ30: =VLOOKUP(BP30,'Axe 2 Règles de gestion'!$D$2:$F$40,3, FALSE) -> Si l'absence ne commence pas par une demi-journée et si l'absence précédente ne finit pas par une demi journée, la date de début de l'absence saisie est postérieure à la date de fin réelle de l'absence précédente. | BR30: ABS_C_020 | BS30: =VLOOKUP(BR30,'Axe 2 Règles de gestion'!$D$2:$F$40,3, FALSE) -> Si l'absence ne commence pas par une demi-journée et si l'absence précédente ne finit pas par une demi journée, la date de début de l'absence saisie est postérieure à la date de fin prévisionnelle de l'absence précédente. | BT30: ABS_C_026 | BU30: =VLOOKUP(BT30,'Axe 2 Règles de gestion'!$D$2:$F$40,3, FALSE) -> Dans le cas d'un congé autre que CLM, CLD, CGM et CITIS, l'indicateur de requalification doit être à non et les impacts spécifiques à la requalification ne doivent pas être mobilisés ou l'impact rémunération est vide.
