Workbook
Name date_DIADC: 'Mode opératoire'!#REF!
Name notice_DIADC: 'Mode opératoire'!#REF!
Name notice_ENCHN: 'Mode opératoire'!$B$1:$B$4
Name notice_ICA: 'Mode opératoire'!#REF!

Sheet Mode opératoire
B1: MODE OPERATOIRE
B2: La transaction s'effectue au niveau de la rubrique "Congés/absences", elle inclut l'ensemble des sous-rubriques listées ci-dessous : - Congés/absences - Complément pour congé / absence : impact rémunération - Compteurs de périodes de congés

Sheet Axe 1 Enchainement des RG
A1: Version | B1: Type de mise à jour | C1: Date de mise à jour | D1: Identifiant Domaine | E1: Libellé du Domaine | F1: Identifiant Sous-domaine | G1: Libellé du Sous-domaine | H1: Identifiant Evénement | I1: Libellé de l'évènement | J1: Libellé condition déclenchement Evènement | K1: Condition déclenchement Evènement | L1: Identifiant type d'évènement | M1: Libellé type d'évènement | N1: Type de mise à jour | O1: Libellé condition déclenchement Type Evènement | P1: Condition déclenchement Type Evènement | Q1: Libellé Population | R1: Codification Population | S1: Typologie de population | T1: Général / Particulier | U1: Passant / Exclu | V1: Date de début | W1: Date de fin | X1: Règles mobilisées | Y1: Identifiant Règle de contrôle intellectuel 1 | Z1: Libellé Règle de contrôle intellectuel 1 | AA1: Identifiant Règle de contrôle intellectuel 2 | AB1: Libellé Règle de contrôle intellectuel 2 | AC1: Identifiant Règle de contrôle intellectuel 3 | AD1: Libellé Règle de contrôle intellectuel 3 | AE1: Identifiant Règle de contrôle intellectuel 4 | AF1: Libellé Règle de contrôle intellectuel 4 | AG1: Identifiant Règle de contrôle intellectuel 5 | AH1: Libellé Règle de contrôle intellectuel 5 | AI1: Identifiant Règle de contrôle intellectuel 6 | AJ1: Libellé Règle de contrôle intellectuel 6 | AK1: Identifiant Règle de contrôle intellectuel 7 | AL1: Libellé Règle de contrôle intellectuel 7 | AM1: Identifiant Règle de contrôle intellectuel 8 | AN1: Libellé Règle de contrôle intellectuel 8 | AO1: Identifiant Règle de contrôle intellectuel 9 | AP1: Libellé Règle de contrôle intellectuel 9 | AQ1: Identifiant Règle de contrôle intellectuel 10 | AR1: Libellé Règle de contrôle intellectuel 10 | AS1: Identifiant Règle de contrôle intellectuel 11 | AT1: Libellé Règle de contrôle intellectuel 11 | AU1: Identifiant Règle de contrôle intellectuel 12 | AV1: Libellé Règle de contrôle intellectuel 12 | AW1: Identifiant Règle de contrôle intellectuel 13 | AX1: Libellé Règle de contrôle intellectuel 13 | AY1: Identifiant Règle de contrôle intellectuel 14 | AZ1: Libellé Règle de contrôle intellectuel 14 | BA1: Identifiant Règle de contrôle intellectuel 15 | BB1: Libellé Règle de contrôle intellectuel 15 | BC1: Identifiant Règle de contrôle intellectuel 16 | BD1: Libellé Règle de contrôle intellectuel 16 | BE1: Identifiant Règle de condition 1 | BF1: Libellé Règle de condition 1 | BG1: Identifiant Règle de condition 2 | BH1: Libellé Règle de condition 2 | BI1: Identifiant Règle de condition 3 | BJ1: Libellé Règle de condition 3 | BK1: Identifiant Règle de condition 4 | BL1: Libellé Règle de condition 4 | BM1: Identifiant Règle de contrôle 1 | BN1: Libellé Règle de contrôle 1 | BO1: Identifiant Règle de contrôle 2 | BP1: Libellé Règle de contrôle 2 | BQ1: Identifiant Règle de contrôle 3 | BR1: Libellé Règle de contrôle 3 | BS1: Identifiant Règle de contrôle 4 | BT1: Libellé Règle de contrôle 4 | BU1: Identifiant Règle de contrôle 5 | BV1: Libellé Règle de contrôle 5 | BW1: Identifiant Règle de contrôle 6 | BX1: Libellé Règle de contrôle 6 | BY1: Identifiant Règle de contrôle 7 | BZ1: Libellé Règle de contrôle 7 | CA1: FIME | CB1: Statut de travail
A2: 20.00.00 | B2: A | C2: 43899.684 | D2: D0007 | E2: Congés/Absence | F2: S0146 | G2: Congé de transition professionnelle | H2: E0813 | I2: Congé de transition professionnelle | J2: Type de congé/absence saisi = 'Congé de transition professionnelle' | K2: A_COA_TYCOAB [Saisi] = 'CF016' | L2: T2009 | M2: Congé de transition professionnelle - Demande | N2: Création | Q2: Titulaire ou magistrat | R2: P0001 | S2: T | T2: Général | U2: Passant | V2: 43826 | X2: CTP_I_001 ET CTP_I_003 ET CTP_I_004 ET CTP_I_005 ET CTP_I_006 ET CTP_I_007 ET CTP_I_008 ET CTP_I_009 ET CTP_I_010 ET CTP_I_011 ET CTP_I_002 ET CTP_I_014 ET CTP_D_001 ET CTP_D_002 ET CTP_D_003 ET ABS_C_001 ET ABS_C_002 ET ABS_C_003 ET ABS_C_004 ET ABS_C_019 ET ABS_C_020 ET ABS_C_026 | Y2: CTP_I_001 | Z2: =VLOOKUP(Y2,'Axe 2 Règles de gestion'!$D$2:$F$65,3, FALSE) -> L'agent peut bénéficier du congé si l'administration envisage de supprimer son emploi en cas de restructuration de son service, dont le périmètre et la durée sont définis par arrêté. | AA2: CTP_I_003 | AB2: =VLOOKUP(AA2,'Axe 2 Règles de gestion'!$D$2:$F$65,3, FALSE) -> Le comité social d'administration compétent est consulté sur la mise en place du congé. | AC2: CTP_I_004 | AD2: =VLOOKUP(AC2,'Axe 2 Règles de gestion'!$D$2:$F$65,3, FALSE) -> Le congé peut être fractionné en mois, semaines ou journées. | AE2: CTP_I_005 | AF2: =VLOOKUP(AE2,'Axe 2 Règles de gestion'!$D$2:$F$65,3, FALSE) -> Le congé permet à l'agent de suivre une formation d'une durée égale ou supérieure à 120 heures sanctionnée par une certification professionnelle ou à 70 heures pour accompagner ou conseiller les créateurs ou repreneurs d'entreprises. | AG2: CTP_I_006 | AH2: =VLOOKUP(AG2,'Axe 2 Règles de gestion'!$D$2:$F$65,3, FALSE) -> L'agent doit effectuer une demande. | AI2: CTP_I_007 | AJ2: =VLOOKUP(AI2,'Axe 2 Règles de gestion'!$D$2:$F$65,3, FALSE) -> La demande de congé précise la nature de la formation, sa durée, le nom de l'organisme qui la dispense et l'objectif professionnel visé. | AK2: CTP_I_008 | AL2: =VLOOKUP(AK2,'Axe 2 Règles de gestion'!$D$2:$F$65,3, FALSE) -> L'administration informe l'agent de sa réponse par écrit dans le délai de 30 jours suivant la réception de la demande. | AM2: CTP_I_009 | AN2: =VLOOKUP(AM2,'Axe 2 Règles de gestion'!$D$2:$F$65,3, FALSE) -> La décision de rejet du congé doit être motivée. | AO2: CTP_I_010 | AP2: =VLOOKUP(AO2,'Axe 2 Règles de gestion'!$D$2:$F$65,3, FALSE) -> Le bénéfice du congé peut être différé dans l'intérêt du service. | AQ2: CTP_I_011 | AR2: =VLOOKUP(AQ2,'Axe 2 Règles de gestion'!$D$2:$F$65,3, FALSE) -> L'agent transmet les attestations établies par l'organisme de formation, justifiant son assiduité à l'action de formation, sinon il perd le bénéfice de ce congé. | AS2: CTP_I_002 | AT2: =VLOOKUP(AS2,'Axe 2 Règles de gestion'!$D$2:$F$65,3, FALSE) -> Si le projet professionnel nécessite des actions de formation dont la durée totale est supérieure à 12 mois, alors le congé est prolongé en un congé de formation professionnelle pour une durée cumulée ne pouvant excéder 3 ans. | AU2: CTP_I_014 | AV2: =VLOOKUP(AU2,'Axe 2 Règles de gestion'!$D$2:$F$65,3, FALSE) -> Le silence gardé par l'administration à l'issue de ce délai vaut rejet de la demande. | BE2: CTP_D_001 | BF2: =VLOOKUP(BE2,'Axe 2 Règles de gestion'!$D$2:$F$65,3, FALSE) -> L'agent doit être en activité. | BG2: CTP_D_002 | BH2: =VLOOKUP(BG2,'Axe 2 Règles de gestion'!$D$2:$F$65,3, FALSE) -> Le congé est accordé pour une durée maximale de 12 mois. | BI2: CTP_D_003 | BJ2: =VLOOKUP(BI2,'Axe 2 Règles de gestion'!$D$2:$F$65,3, FALSE) -> La demande de congé doit être formulée au moins 60 jours avant la date de début de la formation liée au congé. | BM2: ABS_C_001 | BN2: =VLOOKUP(BM2,'Axe 2 Règles de gestion'!$D$2:$F$65,3, FALSE) -> La date de début du congé/absence doit être postérieure ou égale à la date de recrutement dans la FPE ou dans la carrière militaire. | BO2: ABS_C_002 | BP2: =VLOOKUP(BO2,'Axe 2 Règles de gestion'!$D$2:$F$65,3, FALSE) -> La date de début du congé/absence doit être postérieure ou égale à la date de début du lien juridique. | BQ2: ABS_C_003 | BR2: =VLOOKUP(BQ2,'Axe 2 Règles de gestion'!$D$2:$F$65,3, FALSE) -> La date de début du congé/absence doit être antérieure ou égale à la date de fin réelle du congé/absence. | BS2: ABS_C_004 | BT2: =VLOOKUP(BS2,'Axe 2 Règles de gestion'!$D$2:$F$65,3, FALSE) -> La date de début du congé/absence doit être antérieure ou égale à la date de fin prévisionnelle du congé/absence. | BU2: ABS_C_019 | BV2: =VLOOKUP(BU2,'Axe 2 Règles de gestion'!$D$2:$F$65,3, FALSE) -> Si l'absence ne commence pas par une demi-journée et si l'absence précédente ne finit pas par une demi journée, la date de début de l'absence saisie est postérieure à la date de fin réelle de l'absence précédente. | BW2: ABS_C_020 | BX2: =VLOOKUP(BW2,'Axe 2 Règles de gestion'!$D$2:$F$65,3, FALSE) -> Si l'absence ne commence pas par une demi-journée et si l'absence précédente ne finit pas par une demi journée, la date de début de l'absence saisie est postérieure à la date de fin prévisionnelle de l'absence précédente. | BY2: ABS_C_026 | BZ2: =VLOOKUP(BY2,'Axe 2 Règles de gestion'!$D$2:$F$65,3, FALSE) -> Dans le cas d'un congé autre que CLM, CLD, CGM et CITIS, l'indicateur de requalification doit être à non et les impacts spécifiques à la requalification ne doivent pas être mobilisés ou l'impact rémunération est vide.
A3: 22.00.00 | B3: M | C3: 44725.416 | D3: D0007 | E3: Congés/Absence | F3: S0146 | G3: Congé de transition professionnelle | H3: E0813 | I3: Congé de transition professionnelle | J3: Type de congé/absence saisi = 'Congé de transition professionnelle' | K3: A_COA_TYCOAB [Saisi] = 'CF016' | L3: T2010 | M3: Congé de transition professionnelle - Fin | N3: Modification | Q3: Titulaire ou magistrat | R3: P0001 | S3: T | T3: Général | U3: Passant | V3: 43826 | X3: CTP_I_012 ET CTP_D_002 ET ABS_C_005 ET ABS_C_006 ET ABS_C_007 ET ABS_C_008 ET ABS_C_009 | Y3: CTP_I_012 | Z3: =VLOOKUP(Y3,'Axe 2 Règles de gestion'!$D$2:$F$65,3, FALSE) -> Le congé s'achève avant le terme de la période de restructuration sauf si l'agent a débuté sa formation moins de 12 mois avant ce terme du fait d'une décision de report dans l'intérêt du service. | BE3: CTP_D_002 | BF3: =VLOOKUP(BE3,'Axe 2 Règles de gestion'!$D$2:$F$65,3, FALSE) -> Le congé est accordé pour une durée maximale de 12 mois. | BM3: ABS_C_005 | BN3: =VLOOKUP(BM3,'Axe 2 Règles de gestion'!$D$2:$F$65,3, FALSE) -> La date de fin réelle du congé/absence doit être antérieure ou égale à la date limite de fin réelle ou prévisionnelle du lien juridique. | BO3: ABS_C_006 | BP3: =VLOOKUP(BO3,'Axe 2 Règles de gestion'!$D$2:$F$65,3, FALSE) -> La date de fin prévisionnelle du congé/absence doit être antérieure ou égale à la date limite de fin réelle ou prévisionnelle du lien juridique. | BQ3: ABS_C_007 | BR3: =VLOOKUP(BQ3,'Axe 2 Règles de gestion'!$D$2:$F$65,3, FALSE) -> La date de fin réelle du congé/absence doit être antérieure à la date limite de départ à la retraite. | BS3: ABS_C_008 | BT3: =VLOOKUP(BS3,'Axe 2 Règles de gestion'!$D$2:$F$65,3, FALSE) -> La date de fin prévisionnelle du congé/absence doit être antérieure à la date limite de départ à la retraite. | BU3: ABS_C_009 | BV3: =VLOOKUP(BU3,'Axe 2 Règles de gestion'!$D$2:$F$65,3, FALSE) -> La date de fin réelle ou la date de fin prévisionnelle du congé/absence doit être saisie.
A4: 22.10.00 | B4: A | C4: 44886.485 | D4: D0007 | E4: Congés/Absence | F4: S0146 | G4: Congé de transition professionnelle | H4: E0813 | I4: Congé de transition professionnelle | J4: Type de congé/absence saisi = 'Congé de transition professionnelle' | K4: A_COA_TYCOAB [Saisi] = 'CF016' | L4: T2009 | M4: Congé de transition professionnelle - Demande | N4: Création | Q4: Militaire | R4: P0002 | S4: M | T4: Général | U4: Exclu | V4: 43831
A5: 22.10.00 | B5: A | C5: 44886.485 | D5: D0007 | E5: Congés/Absence | F5: S0146 | G5: Congé de transition professionnelle | H5: E0813 | I5: Congé de transition professionnelle | J5: Type de congé/absence saisi = 'Congé de transition professionnelle' | K5: A_COA_TYCOAB [Saisi] = 'CF016' | L5: T2010 | M5: Congé de transition professionnelle - Fin | N5: Modification | Q5: Militaire | R5: P0002 | S5: M | T5: Général | U5: Exclu | V5: 43831
A6: 22.10.00 | B6: M | C6: 44837.723 | D6: D0007 | E6: Congés/Absence | F6: S0146 | G6: Congé de transition professionnelle | H6: E0813 | I6: Congé de transition professionnelle | J6: Type de congé/absence saisi = 'Congé de transition professionnelle' | K6: A_COA_TYCOAB [Saisi] = 'CF016' | L6: T2009 | M6: Congé de transition professionnelle - Demande | N6: Création | Q6: Contractuel | R6: P0003 | S6: N | T6: Général | U6: Passant | V6: 43826 | W6: 44677 | X6: CTP_I_001 ET CTP_I_003 ET CTP_I_004 ET CTP_I_005 ET CTP_I_006 ET CTP_I_007 ET CTP_I_008 ET CTP_I_009 ET CTP_I_010 ET CTP_I_011 ET CTP_I_002 ET CTP_I_014 ET CTP_D_001 ET CTP_D_004 ET CTP_D_003 ET CTP_D_005 ET ABS_C_001 ET ABS_C_002 ET ABS_C_003 ET ABS_C_004 ET ABS_C_019 ET ABS_C_020 ET ABS_C_026 | Y6: CTP_I_001 | Z6: =VLOOKUP(Y6,'Axe 2 Règles de gestion'!$D$2:$F$65,3, FALSE) -> L'agent peut bénéficier du congé si l'administration envisage de supprimer son emploi en cas de restructuration de son service, dont le périmètre et la durée sont définis par arrêté. | AA6: CTP_I_003 | AB6: =VLOOKUP(AA6,'Axe 2 Règles de gestion'!$D$2:$F$65,3, FALSE) -> Le comité social d'administration compétent est consulté sur la mise en place du congé. | AC6: CTP_I_004 | AD6: =VLOOKUP(AC6,'Axe 2 Règles de gestion'!$D$2:$F$65,3, FALSE) -> Le congé peut être fractionné en mois, semaines ou journées. | AE6: CTP_I_005 | AF6: =VLOOKUP(AE6,'Axe 2 Règles de gestion'!$D$2:$F$65,3, FALSE) -> Le congé permet à l'agent de suivre une formation d'une durée égale ou supérieure à 120 heures sanctionnée par une certification professionnelle ou à 70 heures pour accompagner ou conseiller les créateurs ou repreneurs d'entreprises. | AG6: CTP_I_006 | AH6: =VLOOKUP(AG6,'Axe 2 Règles de gestion'!$D$2:$F$65,3, FALSE) -> L'agent doit effectuer une demande. | AI6: CTP_I_007 | AJ6: =VLOOKUP(AI6,'Axe 2 Règles de gestion'!$D$2:$F$65,3, FALSE) -> La demande de congé précise la nature de la formation, sa durée, le nom de l'organisme qui la dispense et l'objectif professionnel visé. | AK6: CTP_I_008 | AL6: =VLOOKUP(AK6,'Axe 2 Règles de gestion'!$D$2:$F$65,3, FALSE) -> L'administration informe l'agent de sa réponse par écrit dans le délai de 30 jours suivant la réception de la demande. | AM6: CTP_I_009 | AN6: =VLOOKUP(AM6,'Axe 2 Règles de gestion'!$D$2:$F$65,3, FALSE) -> La décision de rejet du congé doit être motivée. | AO6: CTP_I_010 | AP6: =VLOOKUP(AO6,'Axe 2 Règles de gestion'!$D$2:$F$65,3, FALSE) -> Le bénéfice du congé peut être différé dans l'intérêt du service. | AQ6: CTP_I_011 | AR6: =VLOOKUP(AQ6,'Axe 2 Règles de gestion'!$D$2:$F$65,3, FALSE) -> L'agent transmet les attestations établies par l'organisme de formation, justifiant son assiduité à l'action de formation, sinon il perd le bénéfice de ce congé. | AS6: CTP_I_002 | AT6: =VLOOKUP(AS6,'Axe 2 Règles de gestion'!$D$2:$F$65,3, FALSE) -> Si le projet professionnel nécessite des actions de formation dont la durée totale est supérieure à 12 mois, alors le congé est prolongé en un congé de formation professionnelle pour une durée cumulée ne pouvant excéder 3 ans. | AU6: CTP_I_014 | AV6: =VLOOKUP(AU6,'Axe 2 Règles de gestion'!$D$2:$F$65,3, FALSE) -> Le silence gardé par l'administration à l'issue de ce délai vaut rejet de la demande. | BE6: CTP_D_001 | BF6: =VLOOKUP(BE6,'Axe 2 Règles de gestion'!$D$2:$F$65,3, FALSE) -> L'agent doit être en activité. | BG6: CTP_D_004 | BH6: =VLOOKUP(BG6,'Axe 2 Règles de gestion'!$D$2:$F$65,3, FALSE) -> Le congé est accordé pour une durée maximale de 12 mois. | BI6: CTP_D_003 | BJ6: =VLOOKUP(BI6,'Axe 2 Règles de gestion'!$D$2:$F$65,3, FALSE) -> La demande de congé doit être formulée au moins 60 jours avant la date de début de la formation liée au congé. | BK6: CTP_D_005 | BL6: =VLOOKUP(BK6,'Axe 2 Règles de gestion'!$D$2:$F$65,3, FALSE) -> Les agents contractuels recrutés pour une durée indéterminée bénéficient du congé. | BM6: ABS_C_001 | BN6: =VLOOKUP(BM6,'Axe 2 Règles de gestion'!$D$2:$F$65,3, FALSE) -> La date de début du congé/absence doit être postérieure ou égale à la date de recrutement dans la FPE ou dans la carrière militaire. | BO6: ABS_C_002 | BP6: =VLOOKUP(BO6,'Axe 2 Règles de gestion'!$D$2:$F$65,3, FALSE) -> La date de début du congé/absence doit être postérieure ou égale à la date de début du lien juridique. | BQ6: ABS_C_003 | BR6: =VLOOKUP(BQ6,'Axe 2 Règles de gestion'!$D$2:$F$65,3, FALSE) -> La date de début du congé/absence doit être antérieure ou égale à la date de fin réelle du congé/absence. | BS6: ABS_C_004 | BT6: =VLOOKUP(BS6,'Axe 2 Règles de gestion'!$D$2:$F$65,3, FALSE) -> La date de début du congé/absence doit être antérieure ou égale à la date de fin prévisionnelle du congé/absence. | BU6: ABS_C_019 | BV6: =VLOOKUP(BU6,'Axe 2 Règles de gestion'!$D$2:$F$65,3, FALSE) -> Si l'absence ne commence pas par une demi-journée et si l'absence précédente ne finit pas par une demi journée, la date de début de l'absence saisie est postérieure à la date de fin réelle de l'absence précédente. | BW6: ABS_C_020 | BX6: =VLOOKUP(BW6,'Axe 2 Règles de gestion'!$D$2:$F$65,3, FALSE) -> Si l'absence ne commence pas par une demi-journée et si l'absence précédente ne finit pas par une demi journée, la date de début de l'absence saisie est postérieure à la date de fin prévisionnelle de l'absence précédente. | BY6: ABS_C_026 | BZ6: =VLOOKUP(BY6,'Axe 2 Règles de gestion'!$D$2:$F$65,3, FALSE) -> Dans le cas d'un congé autre que CLM, CLD, CGM et CITIS, l'indicateur de requalification doit être à non et les impacts spécifiques à la requalification ne doivent pas être mobilisés ou l'impact rémunération est vide.
A7: 22.10.00 | B7: A | C7: 44959.574 | D7: D0007 | E7: Congés/Absence | F7: S0146 | G7: Congé de transition professionnelle | H7: E0813 | I7: Congé de transition professionnelle | J7: Type de congé/absence saisi = 'Congé de transition professionnelle' | K7: A_COA_TYCOAB [Saisi] = 'CF016' | L7: T2009 | M7: Congé de transition professionnelle - Demande | N7: Création | Q7: Contractuel | R7: P0003 | S7: N | T7: Général | U7: Passant | V7: 44678 | X7: CTP_I_001 ET CTP_I_003 ET CTP_I_004 ET CTP_I_005 ET CTP_I_006 ET CTP_I_007 ET CTP_I_008 ET CTP_I_009 ET CTP_I_010 ET CTP_I_011 ET CTP_I_002 ET CTP_I_014 ET CTP_D_001 ET CTP_D_004 ET CTP_D_003 ET CTP_D_006 ET ABS_C_001 ET ABS_C_002 ET ABS_C_003 ET ABS_C_004 ET ABS_C_019 ET ABS_C_020 ET ABS_C_026 | Y7: CTP_I_001 | Z7: =VLOOKUP(Y7,'Axe 2 Règles de gestion'!$D$2:$F$65,3, FALSE) -> L'agent peut bénéficier du congé si l'administration envisage de supprimer son emploi en cas de restructuration de son service, dont le périmètre et la durée sont définis par arrêté. | AA7: CTP_I_003 | AB7: =VLOOKUP(AA7,'Axe 2 Règles de gestion'!$D$2:$F$65,3, FALSE) -> Le comité social d'administration compétent est consulté sur la mise en place du congé. | AC7: CTP_I_004 | AD7: =VLOOKUP(AC7,'Axe 2 Règles de gestion'!$D$2:$F$65,3, FALSE) -> Le congé peut être fractionné en mois, semaines ou journées. | AE7: CTP_I_005 | AF7: =VLOOKUP(AE7,'Axe 2 Règles de gestion'!$D$2:$F$65,3, FALSE) -> Le congé permet à l'agent de suivre une formation d'une durée égale ou supérieure à 120 heures sanctionnée par une certification professionnelle ou à 70 heures pour accompagner ou conseiller les créateurs ou repreneurs d'entreprises. | AG7: CTP_I_006 | AH7: =VLOOKUP(AG7,'Axe 2 Règles de gestion'!$D$2:$F$65,3, FALSE) -> L'agent doit effectuer une demande. | AI7: CTP_I_007 | AJ7: =VLOOKUP(AI7,'Axe 2 Règles de gestion'!$D$2:$F$65,3, FALSE) -> La demande de congé précise la nature de la formation, sa durée, le nom de l'organisme qui la dispense et l'objectif professionnel visé. | AK7: CTP_I_008 | AL7: =VLOOKUP(AK7,'Axe 2 Règles de gestion'!$D$2:$F$65,3, FALSE) -> L'administration informe l'agent de sa réponse par écrit dans le délai de 30 jours suivant la réception de la demande. | AM7: CTP_I_009 | AN7: =VLOOKUP(AM7,'Axe 2 Règles de gestion'!$D$2:$F$65,3, FALSE) -> La décision de rejet du congé doit être motivée. | AO7: CTP_I_010 | AP7: =VLOOKUP(AO7,'Axe 2 Règles de gestion'!$D$2:$F$65,3, FALSE) -> Le bénéfice du congé peut être différé dans l'intérêt du service. | AQ7: CTP_I_011 | AR7: =VLOOKUP(AQ7,'Axe 2 Règles de gestion'!$D$2:$F$65,3, FALSE) -> L'agent transmet les attestations établies par l'organisme de formation, justifiant son assiduité à l'action de formation, sinon il perd le bénéfice de ce congé. | AS7: CTP_I_002 | AT7: =VLOOKUP(AS7,'Axe 2 Règles de gestion'!$D$2:$F$65,3, FALSE) -> Si le projet professionnel nécessite des actions de formation dont la durée totale est supérieure à 12 mois, alors le congé est prolongé en un congé de formation professionnelle pour une durée cumulée ne pouvant excéder 3 ans. | AU7: CTP_I_014 | AV7: =VLOOKUP(AU7,'Axe 2 Règles de gestion'!$D$2:$F$65,3, FALSE) -> Le silence gardé par l'administration à l'issue de ce délai vaut rejet de la demande. | BE7: CTP_D_001 | BF7: =VLOOKUP(BE7,'Axe 2 Règles de gestion'!$D$2:$F$65,3, FALSE) -> L'agent doit être en activité. | BG7: CTP_D_004 | BH7: =VLOOKUP(BG7,'Axe 2 Règles de gestion'!$D$2:$F$65,3, FALSE) -> Le congé est accordé pour une durée maximale de 12 mois. | BI7: CTP_D_003 | BJ7: =VLOOKUP(BI7,'Axe 2 Règles de gestion'!$D$2:$F$65,3, FALSE) -> La demande de congé doit être formulée au moins 60 jours avant la date de début de la formation liée au congé. | BK7: CTP_D_006 | BL7: =VLOOKUP(BK7,'Axe 2 Règles de gestion'!$D$2:$F$65,3, FALSE) -> Les agents contractuels recrutés pour une durée indéterminée bénéficient du congé. | BM7: ABS_C_001 | BN7: =VLOOKUP(BM7,'Axe 2 Règles de gestion'!$D$2:$F$65,3, FALSE) -> La date de début du congé/absence doit être postérieure ou égale à la date de recrutement dans la FPE ou dans la carrière militaire. | BO7: ABS_C_002 | BP7: =VLOOKUP(BO7,'Axe 2 Règles de gestion'!$D$2:$F$65,3, FALSE) -> La date de début du congé/absence doit être postérieure ou égale à la date de début du lien juridique. | BQ7: ABS_C_003 | BR7: =VLOOKUP(BQ7,'Axe 2 Règles de gestion'!$D$2:$F$65,3, FALSE) -> La date de début du congé/absence doit être antérieure ou égale à la date de fin réelle du congé/absence. | BS7: ABS_C_004 | BT7: =VLOOKUP(BS7,'Axe 2 Règles de gestion'!$D$2:$F$65,3, FALSE) -> La date de début du congé/absence doit être antérieure ou égale à la date de fin prévisionnelle du congé/absence. | BU7: ABS_C_019 | BV7: =VLOOKUP(BU7,'Axe 2 Règles de gestion'!$D$2:$F$65,3, FALSE) -> Si l'absence ne commence pas par une demi-journée et si l'absence précédente ne finit pas par une demi journée, la date de début de l'absence saisie est postérieure à la date de fin réelle de l'absence précédente. | BW7: ABS_C_020 | BX7: =VLOOKUP(BW7,'Axe 2 Règles de gestion'!$D$2:$F$65,3, FALSE) -> Si l'absence ne commence pas par une demi-journée et si l'absence précédente ne finit pas par une demi journée, la date de début de l'absence saisie est postérieure à la date de fin prévisionnelle de l'absence précédente. | BY7: ABS_C_026 | BZ7: =VLOOKUP(BY7,'Axe 2 Règles de gestion'!$D$2:$F$65,3, FALSE) -> Dans le cas d'un congé autre que CLM, CLD, CGM et CITIS, l'indicateur de requalification doit être à non et les impacts spécifiques à la requalification ne doivent pas être mobilisés ou l'impact rémunération est vide.
A8: 22.00.00 | B8: M | C8: 44725.417 | D8: D0007 | E8: Congés/Absence | F8: S0146 | G8: Congé de transition professionnelle | H8: E0813 | I8: Congé de transition professionnelle | J8: Type de congé/absence saisi = 'Congé de transition professionnelle' | K8: A_COA_TYCOAB [Saisi] = 'CF016' | L8: T2010 | M8: Congé de transition professionnelle - Fin | N8: Modification | Q8: Contractuel | R8: P0003 | S8: N | T8: Général | U8: Passant | V8: 43826 | X8: CTP_I_012 ET CTP_D_004 ET ABS_C_005 ET ABS_C_006 ET ABS_C_007 ET ABS_C_008 ET ABS_C_009 | Y8: CTP_I_012 | Z8: =VLOOKUP(Y8,'Axe 2 Règles de gestion'!$D$2:$F$65,3, FALSE) -> Le congé s'achève avant le terme de la période de restructuration sauf si l'agent a débuté sa formation moins de 12 mois avant ce terme du fait d'une décision de report dans l'intérêt du service. | BE8: CTP_D_004 | BF8: =VLOOKUP(BE8,'Axe 2 Règles de gestion'!$D$2:$F$65,3, FALSE) -> Le congé est accordé pour une durée maximale de 12 mois. | BM8: ABS_C_005 | BN8: =VLOOKUP(BM8,'Axe 2 Règles de gestion'!$D$2:$F$65,3, FALSE) -> La date de fin réelle du congé/absence doit être antérieure ou égale à la date limite de fin réelle ou prévisionnelle du lien juridique. | BO8: ABS_C_006 | BP8: =VLOOKUP(BO8,'Axe 2 Règles de gestion'!$D$2:$F$65,3, FALSE) -> La date de fin prévisionnelle du congé/absence doit être antérieure ou égale à la date limite de fin réelle ou prévisionnelle du lien juridique. | BQ8: ABS_C_007 | BR8: =VLOOKUP(BQ8,'Axe 2 Règles de gestion'!$D$2:$F$65,3, FALSE) -> La date de fin réelle du congé/absence doit être antérieure à la date limite de départ à la retraite. | BS8: ABS_C_008 | BT8: =VLOOKUP(BS8,'Axe 2 Règles de gestion'!$D$2:$F$65,3, FALSE) -> La date de fin prévisionnelle du congé/absence doit être antérieure à la date limite de départ à la retraite. | BU8: ABS_C_009 | BV8: =VLOOKUP(BU8,'Axe 2 Règles de gestion'!$D$2:$F$65,3, FALSE) -> La date de fin réelle ou la date de fin prévisionnelle du congé/absence doit être saisie.
A9: 22.00.00 | B9: M | C9: 44725.465 | D9: D0007 | E9: Congés/Absence | F9: S0146 | G9: Congé de transition professionnelle | H9: E0813 | I9: Congé de transition professionnelle | J9: Type de congé/absence saisi = 'Congé de transition professionnelle' | K9: A_COA_TYCOAB [Saisi] = 'CF016' | L9: T2009 | M9: Congé de transition professionnelle - Demande | N9: Création | Q9: Stagiaire ou auditeur ou élève | R9: P0004 | S9: S | T9: Général | U9: Passant | V9: 43826 | X9: CTP_I_001 ET CTP_I_003 ET CTP_I_004 ET CTP_I_005 ET CTP_I_006 ET CTP_I_007 ET CTP_I_008 ET CTP_I_009 ET CTP_I_010 ET CTP_I_011 ET CTP_I_013 ET CTP_I_014 ET CTP_D_001 ET CTP_D_004 ET CTP_D_003 ET ABS_C_001 ET ABS_C_002 ET ABS_C_003 ET ABS_C_004 ET ABS_C_019 ET ABS_C_020 ET ABS_C_026 | Y9: CTP_I_001 | Z9: =VLOOKUP(Y9,'Axe 2 Règles de gestion'!$D$2:$F$65,3, FALSE) -> L'agent peut bénéficier du congé si l'administration envisage de supprimer son emploi en cas de restructuration de son service, dont le périmètre et la durée sont définis par arrêté. | AA9: CTP_I_003 | AB9: =VLOOKUP(AA9,'Axe 2 Règles de gestion'!$D$2:$F$65,3, FALSE) -> Le comité social d'administration compétent est consulté sur la mise en place du congé. | AC9: CTP_I_004 | AD9: =VLOOKUP(AC9,'Axe 2 Règles de gestion'!$D$2:$F$65,3, FALSE) -> Le congé peut être fractionné en mois, semaines ou journées. | AE9: CTP_I_005 | AF9: =VLOOKUP(AE9,'Axe 2 Règles de gestion'!$D$2:$F$65,3, FALSE) -> Le congé permet à l'agent de suivre une formation d'une durée égale ou supérieure à 120 heures sanctionnée par une certification professionnelle ou à 70 heures pour accompagner ou conseiller les créateurs ou repreneurs d'entreprises. | AG9: CTP_I_006 | AH9: =VLOOKUP(AG9,'Axe 2 Règles de gestion'!$D$2:$F$65,3, FALSE) -> L'agent doit effectuer une demande. | AI9: CTP_I_007 | AJ9: =VLOOKUP(AI9,'Axe 2 Règles de gestion'!$D$2:$F$65,3, FALSE) -> La demande de congé précise la nature de la formation, sa durée, le nom de l'organisme qui la dispense et l'objectif professionnel visé. | AK9: CTP_I_008 | AL9: =VLOOKUP(AK9,'Axe 2 Règles de gestion'!$D$2:$F$65,3, FALSE) -> L'administration informe l'agent de sa réponse par écrit dans le délai de 30 jours suivant la réception de la demande. | AM9: CTP_I_009 | AN9: =VLOOKUP(AM9,'Axe 2 Règles de gestion'!$D$2:$F$65,3, FALSE) -> La décision de rejet du congé doit être motivée. | AO9: CTP_I_010 | AP9: =VLOOKUP(AO9,'Axe 2 Règles de gestion'!$D$2:$F$65,3, FALSE) -> Le bénéfice du congé peut être différé dans l'intérêt du service. | AQ9: CTP_I_011 | AR9: =VLOOKUP(AQ9,'Axe 2 Règles de gestion'!$D$2:$F$65,3, FALSE) -> L'agent transmet les attestations établies par l'organisme de formation, justifiant son assiduité à l'action de formation, sinon il perd le bénéfice de ce congé. | AS9: CTP_I_013 | AT9: =VLOOKUP(AS9,'Axe 2 Règles de gestion'!$D$2:$F$65,3, FALSE) -> L'agent ne bénéficiant pas du congé de formation professionnelle, ne peut pas voir son congé de transition professionnelle prolongé au-delà des 12 mois. | AU9: CTP_I_014 | AV9: =VLOOKUP(AU9,'Axe 2 Règles de gestion'!$D$2:$F$65,3, FALSE) -> Le silence gardé par l'administration à l'issue de ce délai vaut rejet de la demande. | BE9: CTP_D_001 | BF9: =VLOOKUP(BE9,'Axe 2 Règles de gestion'!$D$2:$F$65,3, FALSE) -> L'agent doit être en activité. | BG9: CTP_D_004 | BH9: =VLOOKUP(BG9,'Axe 2 Règles de gestion'!$D$2:$F$65,3, FALSE) -> Le congé est accordé pour une durée maximale de 12 mois. | BI9: CTP_D_003 | BJ9: =VLOOKUP(BI9,'Axe 2 Règles de gestion'!$D$2:$F$65,3, FALSE) -> La demande de congé doit être formulée au moins 60 jours avant la date de début de la formation liée au congé. | BM9: ABS_C_001 | BN9: =VLOOKUP(BM9,'Axe 2 Règles de gestion'!$D$2:$F$65,3, FALSE) -> La date de début du congé/absence doit être postérieure ou égale à la date de recrutement dans la FPE ou dans la carrière militaire. | BO9: ABS_C_002 | BP9: =VLOOKUP(BO9,'Axe 2 Règles de gestion'!$D$2:$F$65,3, FALSE) -> La date de début du congé/absence doit être postérieure ou égale à la date de début du lien juridique. | BQ9: ABS_C_003 | BR9: =VLOOKUP(BQ9,'Axe 2 Règles de gestion'!$D$2:$F$65,3, FALSE) -> La date de début du congé/absence doit être antérieure ou égale à la date de fin réelle du congé/absence. | BS9: ABS_C_004 | BT9: =VLOOKUP(BS9,'Axe 2 Règles de gestion'!$D$2:$F$65,3, FALSE) -> La date de début du congé/absence doit être antérieure ou égale à la date de fin prévisionnelle du congé/absence. | BU9: ABS_C_019 | BV9: =VLOOKUP(BU9,'Axe 2 Règles de gestion'!$D$2:$F$65,3, FALSE) -> Si l'absence ne commence pas par une demi-journée et si l'absence précédente ne finit pas par une demi journée, la date de début de l'absence saisie est postérieure à la date de fin réelle de l'absence précédente. | BW9: ABS_C_020 | BX9: =VLOOKUP(BW9,'Axe 2 Règles de gestion'!$D$2:$F$65,3, FALSE) -> Si l'absence ne commence pas par une demi-journée et si l'absence précédente ne finit pas par une demi journée, la date de début de l'absence saisie est postérieure à la date de fin prévisionnelle de l'absence précédente. | BY9: ABS_C_026 | BZ9: =VLOOKUP(BY9,'Axe 2 Règles de gestion'!$D$2:$F$65,3, FALSE) -> Dans le cas d'un congé autre que CLM, CLD, CGM et CITIS, l'indicateur de requalification doit être à non et les impacts spécifiques à la requalification ne doivent pas être mobilisés ou l'impact rémunération est vide.
A10: 22.00.00 | B10: M | C10: 44725.461 | D10: D0007 | E10: Congés/Absence | F10: S0146 | G10: Congé de transition professionnelle | H10: E0813 | I10: Congé de transition professionnelle | J10: Type de congé/absence saisi = 'Congé de transition professionnelle' | K10: A_COA_TYCOAB [Saisi] = 'CF016' | L10: T2010 | M10: Congé de transition professionnelle - Fin | N10: Modification | Q10: Stagiaire ou auditeur ou élève | R10: P0004 | S10: S | T10: Général | U10: Passant | V10: 43826 | X10: CTP_I_012 ET CTP_D_004 ET ABS_C_005 ET ABS_C_006 ET ABS_C_007 ET ABS_C_008 ET ABS_C_009 | Y10: CTP_I_012 | Z10: =VLOOKUP(Y10,'Axe 2 Règles de gestion'!$D$2:$F$65,3, FALSE) -> Le congé s'achève avant le terme de la période de restructuration sauf si l'agent a débuté sa formation moins de 12 mois avant ce terme du fait d'une décision de report dans l'intérêt du service. | BE10: CTP_D_004 | BF10: =VLOOKUP(BE10,'Axe 2 Règles de gestion'!$D$2:$F$65,3, FALSE) -> Le congé est accordé pour une durée maximale de 12 mois. | BM10: ABS_C_005 | BN10: =VLOOKUP(BM10,'Axe 2 Règles de gestion'!$D$2:$F$65,3, FALSE) -> La date de fin réelle du congé/absence doit être antérieure ou égale à la date limite de fin réelle ou prévisionnelle du lien juridique. | BO10: ABS_C_006 | BP10: =VLOOKUP(BO10,'Axe 2 Règles de gestion'!$D$2:$F$65,3, FALSE) -> La date de fin prévisionnelle du congé/absence doit être antérieure ou égale à la date limite de fin réelle ou prévisionnelle du lien juridique. | BQ10: ABS_C_007 | BR10: =VLOOKUP(BQ10,'Axe 2 Règles de gestion'!$D$2:$F$65,3, FALSE) -> La date de fin réelle du congé/absence doit être antérieure à la date limite de départ à la retraite. | BS10: ABS_C_008 | BT10: =VLOOKUP(BS10,'Axe 2 Règles de gestion'!$D$2:$F$65,3, FALSE) -> La date de fin prévisionnelle du congé/absence doit être antérieure à la date limite de départ à la retraite. | BU10: ABS_C_009 | BV10: =VLOOKUP(BU10,'Axe 2 Règles de gestion'!$D$2:$F$65,3, FALSE) -> La date de fin réelle ou la date de fin prévisionnelle du congé/absence doit être saisie.
A11: 20.00.00 | B11: A | C11: 43899.688 | D11: D0007 | E11: Congés/Absence | F11: S0146 | G11: Congé de transition professionnelle | H11: E0813 | I11: Congé de transition professionnelle | J11: Type de congé/absence saisi = 'Congé de transition professionnelle' | K11: A_COA_TYCOAB [Saisi] = 'CF016' | L11: T2009 | M11: Congé de transition professionnelle - Demande | N11: Création | Q11: Ouvrier d'état | R11: P0005 | S11: O | T11: Général | U11: Passant | V11: 43826 | X11: CTP_I_001 ET CTP_I_003 ET CTP_I_004 ET CTP_I_005 ET CTP_I_006 ET CTP_I_007 ET CTP_I_008 ET CTP_I_009 ET CTP_I_010 ET CTP_I_011 ET CTP_I_002 ET CTP_I_014 ET CTP_D_001 ET CTP_D_004 ET CTP_D_003 ET ABS_C_001 ET ABS_C_002 ET ABS_C_003 ET ABS_C_004 ET ABS_C_019 ET ABS_C_020 ET ABS_C_026 | Y11: CTP_I_001 | Z11: =VLOOKUP(Y11,'Axe 2 Règles de gestion'!$D$2:$F$65,3, FALSE) -> L'agent peut bénéficier du congé si l'administration envisage de supprimer son emploi en cas de restructuration de son service, dont le périmètre et la durée sont définis par arrêté. | AA11: CTP_I_003 | AB11: =VLOOKUP(AA11,'Axe 2 Règles de gestion'!$D$2:$F$65,3, FALSE) -> Le comité social d'administration compétent est consulté sur la mise en place du congé. | AC11: CTP_I_004 | AD11: =VLOOKUP(AC11,'Axe 2 Règles de gestion'!$D$2:$F$65,3, FALSE) -> Le congé peut être fractionné en mois, semaines ou journées. | AE11: CTP_I_005 | AF11: =VLOOKUP(AE11,'Axe 2 Règles de gestion'!$D$2:$F$65,3, FALSE) -> Le congé permet à l'agent de suivre une formation d'une durée égale ou supérieure à 120 heures sanctionnée par une certification professionnelle ou à 70 heures pour accompagner ou conseiller les créateurs ou repreneurs d'entreprises. | AG11: CTP_I_006 | AH11: =VLOOKUP(AG11,'Axe 2 Règles de gestion'!$D$2:$F$65,3, FALSE) -> L'agent doit effectuer une demande. | AI11: CTP_I_007 | AJ11: =VLOOKUP(AI11,'Axe 2 Règles de gestion'!$D$2:$F$65,3, FALSE) -> La demande de congé précise la nature de la formation, sa durée, le nom de l'organisme qui la dispense et l'objectif professionnel visé. | AK11: CTP_I_008 | AL11: =VLOOKUP(AK11,'Axe 2 Règles de gestion'!$D$2:$F$65,3, FALSE) -> L'administration informe l'agent de sa réponse par écrit dans le délai de 30 jours suivant la réception de la demande. | AM11: CTP_I_009 | AN11: =VLOOKUP(AM11,'Axe 2 Règles de gestion'!$D$2:$F$65,3, FALSE) -> La décision de rejet du congé doit être motivée. | AO11: CTP_I_010 | AP11: =VLOOKUP(AO11,'Axe 2 Règles de gestion'!$D$2:$F$65,3, FALSE) -> Le bénéfice du congé peut être différé dans l'intérêt du service. | AQ11: CTP_I_011 | AR11: =VLOOKUP(AQ11,'Axe 2 Règles de gestion'!$D$2:$F$65,3, FALSE) -> L'agent transmet les attestations établies par l'organisme de formation, justifiant son assiduité à l'action de formation, sinon il perd le bénéfice de ce congé. | AS11: CTP_I_002 | AT11: =VLOOKUP(AS11,'Axe 2 Règles de gestion'!$D$2:$F$65,3, FALSE) -> Si le projet professionnel nécessite des actions de formation dont la durée totale est supérieure à 12 mois, alors le congé est prolongé en un congé de formation professionnelle pour une durée cumulée ne pouvant excéder 3 ans. | AU11: CTP_I_014 | AV11: =VLOOKUP(AU11,'Axe 2 Règles de gestion'!$D$2:$F$65,3, FALSE) -> Le silence gardé par l'administration à l'issue de ce délai vaut rejet de la demande. | BE11: CTP_D_001 | BF11: =VLOOKUP(BE11,'Axe 2 Règles de gestion'!$D$2:$F$65,3, FALSE) -> L'agent doit être en activité. | BG11: CTP_D_004 | BH11: =VLOOKUP(BG11,'Axe 2 Règles de gestion'!$D$2:$F$65,3, FALSE) -> Le congé est accordé pour une durée maximale de 12 mois. | BI11: CTP_D_003 | BJ11: =VLOOKUP(BI11,'Axe 2 Règles de gestion'!$D$2:$F$65,3, FALSE) -> La demande de congé doit être formulée au moins 60 jours avant la date de début de la formation liée au congé. | BM11: ABS_C_001 | BN11: =VLOOKUP(BM11,'Axe 2 Règles de gestion'!$D$2:$F$65,3, FALSE) -> La date de début du congé/absence doit être postérieure ou égale à la date de recrutement dans la FPE ou dans la carrière militaire. | BO11: ABS_C_002 | BP11: =VLOOKUP(BO11,'Axe 2 Règles de gestion'!$D$2:$F$65,3, FALSE) -> La date de début du congé/absence doit être postérieure ou égale à la date de début du lien juridique. | BQ11: ABS_C_003 | BR11: =VLOOKUP(BQ11,'Axe 2 Règles de gestion'!$D$2:$F$65,3, FALSE) -> La date de début du congé/absence doit être antérieure ou égale à la date de fin réelle du congé/absence. | BS11: ABS_C_004 | BT11: =VLOOKUP(BS11,'Axe 2 Règles de gestion'!$D$2:$F$65,3, FALSE) -> La date de début du congé/absence doit être antérieure ou égale à la date de fin prévisionnelle du congé/absence. | BU11: ABS_C_019 | BV11: =VLOOKUP(BU11,'Axe 2 Règles de gestion'!$D$2:$F$65,3, FALSE) -> Si l'absence ne commence pas par une demi-journée et si l'absence précédente ne finit pas par une demi journée, la date de début de l'absence saisie est postérieure à la date de fin réelle de l'absence précédente. | BW11: ABS_C_020 | BX11: =VLOOKUP(BW11,'Axe 2 Règles de gestion'!$D$2:$F$65,3, FALSE) -> Si l'absence ne commence pas par une demi-journée et si l'absence précédente ne finit pas par une demi journée, la date de début de l'absence saisie est postérieure à la date de fin prévisionnelle de l'absence précédente. | BY11: ABS_C_026 | BZ11: =VLOOKUP(BY11,'Axe 2 Règles de gestion'!$D$2:$F$65,3, FALSE) -> Dans le cas d'un congé autre que CLM, CLD, CGM et CITIS, l'indicateur de requalification doit être à non et les impacts spécifiques à la requalification ne doivent pas être mobilisés ou l'impact rémunération est vide.
A12: 22.00.00 | B12: M | C12: 44725.417 | D12: D0007 | E12: Congés/Absence | F12: S0146 | G12: Congé de transition professionnelle | H12: E0813 | I12: Congé de transition professionnelle | J12: Type de congé/absence saisi = 'Congé de transition professionnelle' | K12: A_COA_TYCOAB [Saisi] = 'CF016' | L12: T2010 | M12: Congé de transition professionnelle - Fin | N12: Modification | Q12: Ouvrier d'état | R12: P0005 | S12: O | T12: Général | U12: Passant | V12: 43826 | X12: CTP_I_012 ET CTP_D_004 ET ABS_C_005 ET ABS_C_006 ET ABS_C_007 ET ABS_C_008 ET ABS_C_009 | Y12: CTP_I_012 | Z12: =VLOOKUP(Y12,'Axe 2 Règles de gestion'!$D$2:$F$65,3, FALSE) -> Le congé s'achève avant le terme de la période de restructuration sauf si l'agent a débuté sa formation moins de 12 mois avant ce terme du fait d'une décision de report dans l'intérêt du service. | BE12: CTP_D_004 | BF12: =VLOOKUP(BE12,'Axe 2 Règles de gestion'!$D$2:$F$65,3, FALSE) -> Le congé est accordé pour une durée maximale de 12 mois. | BM12: ABS_C_005 | BN12: =VLOOKUP(BM12,'Axe 2 Règles de gestion'!$D$2:$F$65,3, FALSE) -> La date de fin réelle du congé/absence doit être antérieure ou égale à la date limite de fin réelle ou prévisionnelle du lien juridique. | BO12: ABS_C_006 | BP12: =VLOOKUP(BO12,'Axe 2 Règles de gestion'!$D$2:$F$65,3, FALSE) -> La date de fin prévisionnelle du congé/absence doit être antérieure ou égale à la date limite de fin réelle ou prévisionnelle du lien juridique. | BQ12: ABS_C_007 | BR12: =VLOOKUP(BQ12,'Axe 2 Règles de gestion'!$D$2:$F$65,3, FALSE) -> La date de fin réelle du congé/absence doit être antérieure à la date limite de départ à la retraite. | BS12: ABS_C_008 | BT12: =VLOOKUP(BS12,'Axe 2 Règles de gestion'!$D$2:$F$65,3, FALSE) -> La date de fin prévisionnelle du congé/absence doit être antérieure à la date limite de départ à la retraite. | BU12: ABS_C_009 | BV12: =VLOOKUP(BU12,'Axe 2 Règles de gestion'!$D$2:$F$65,3, FALSE) -> La date de fin réelle ou la date de fin prévisionnelle du congé/absence doit être saisie.
A13: 20.00.00 | B13: A | C13: 43894.619 | D13: D0007 | E13: Congés/Absence | F13: S0146 | G13: Congé de transition professionnelle | H13: E0813 | I13: Congé de transition professionnelle | J13: Type de congé/absence saisi = 'Congé de transition professionnelle' | K13: A_COA_TYCOAB [Saisi] = 'CF016' | L13: T2009 | M13: Congé de transition professionnelle - Demande | N13: Création | Q13: Magistrat de l'ordre judiciaire | R13: P0007 | S13: T | T13: Particulier | U13: Exclu | V13: 43826
A14: 20.00.00 | B14: A | C14: 43894.611 | D14: D0007 | E14: Congés/Absence | F14: S0146 | G14: Congé de transition professionnelle | H14: E0813 | I14: Congé de transition professionnelle | J14: Type de congé/absence saisi = 'Congé de transition professionnelle' | K14: A_COA_TYCOAB [Saisi] = 'CF016' | L14: T2010 | M14: Congé de transition professionnelle - Fin | N14: Modification | Q14: Magistrat de l'ordre judiciaire | R14: P0007 | S14: T | T14: Particulier | U14: Exclu | V14: 43826
A15: 20.00.00 | B15: A | C15: 43894.62 | D15: D0007 | E15: Congés/Absence | F15: S0146 | G15: Congé de transition professionnelle | H15: E0813 | I15: Congé de transition professionnelle | J15: Type de congé/absence saisi = 'Congé de transition professionnelle' | K15: A_COA_TYCOAB [Saisi] = 'CF016' | L15: T2009 | M15: Congé de transition professionnelle - Demande | N15: Création | Q15: Auditeur de justice | R15: P0009 | S15: S | T15: Particulier | U15: Exclu | V15: 43826
A16: 20.00.00 | B16: A | C16: 43894.611 | D16: D0007 | E16: Congés/Absence | F16: S0146 | G16: Congé de transition professionnelle | H16: E0813 | I16: Congé de transition professionnelle | J16: Type de congé/absence saisi = 'Congé de transition professionnelle' | K16: A_COA_TYCOAB [Saisi] = 'CF016' | L16: T2010 | M16: Congé de transition professionnelle - Fin | N16: Modification | Q16: Auditeur de justice | R16: P0009 | S16: S | T16: Particulier | U16: Exclu | V16: 43826
A17: 20.00.00 | B17: A | C17: 43894.62 | D17: D0007 | E17: Congés/Absence | F17: S0146 | G17: Congé de transition professionnelle | H17: E0813 | I17: Congé de transition professionnelle | J17: Type de congé/absence saisi = 'Congé de transition professionnelle' | K17: A_COA_TYCOAB [Saisi] = 'CF016' | L17: T2009 | M17: Congé de transition professionnelle - Demande | N17: Création | Q17: Conseiller ou avocat général à la Cour de cassation en service extraordinaire | R17: P0046 | S17: N | T17: Particulier | U17: Exclu | V17: 43826
A18: 20.00.00 | B18: A | C18: 43894.612 | D18: D0007 | E18: Congés/Absence | F18: S0146 | G18: Congé de transition professionnelle | H18: E0813 | I18: Congé de transition professionnelle | J18: Type de congé/absence saisi = 'Congé de transition professionnelle' | K18: A_COA_TYCOAB [Saisi] = 'CF016' | L18: T2010 | M18: Congé de transition professionnelle - Fin | N18: Modification | Q18: Conseiller ou avocat général à la Cour de cassation en service extraordinaire | R18: P0046 | S18: N | T18: Particulier | U18: Exclu | V18: 43826
A19: 20.00.00 | B19: A | C19: 43894.621 | D19: D0007 | E19: Congés/Absence | F19: S0146 | G19: Congé de transition professionnelle | H19: E0813 | I19: Congé de transition professionnelle | J19: Type de congé/absence saisi = 'Congé de transition professionnelle' | K19: A_COA_TYCOAB [Saisi] = 'CF016' | L19: T2009 | M19: Congé de transition professionnelle - Demande | N19: Création | Q19: Personnel civil payé à l'acte ou à la tâche | R19: P0054 | S19: N | T19: Particulier | U19: Exclu | V19: 43826
A20: 20.00.00 | B20: A | C20: 43894.613 | D20: D0007 | E20: Congés/Absence | F20: S0146 | G20: Congé de transition professionnelle | H20: E0813 | I20: Congé de transition professionnelle | J20: Type de congé/absence saisi = 'Congé de transition professionnelle' | K20: A_COA_TYCOAB [Saisi] = 'CF016' | L20: T2010 | M20: Congé de transition professionnelle - Fin | N20: Modification | Q20: Personnel civil payé à l'acte ou à la tâche | R20: P0054 | S20: N | T20: Particulier | U20: Exclu | V20: 43826
A21: 20.00.00 | B21: A | C21: 43894.625 | D21: D0007 | E21: Congés/Absence | F21: S0146 | G21: Congé de transition professionnelle | H21: E0813 | I21: Congé de transition professionnelle | J21: Type de congé/absence saisi = 'Congé de transition professionnelle' | K21: A_COA_TYCOAB [Saisi] = 'CF016' | L21: T2009 | M21: Congé de transition professionnelle - Demande | N21: Création | Q21: Contractuel de droit privé | R21: P0072 | S21: N | T21: Particulier | U21: Exclu | V21: 43826
A22: 20.00.00 | B22: A | C22: 43894.613 | D22: D0007 | E22: Congés/Absence | F22: S0146 | G22: Congé de transition professionnelle | H22: E0813 | I22: Congé de transition professionnelle | J22: Type de congé/absence saisi = 'Congé de transition professionnelle' | K22: A_COA_TYCOAB [Saisi] = 'CF016' | L22: T2010 | M22: Congé de transition professionnelle - Fin | N22: Modification | Q22: Contractuel de droit privé | R22: P0072 | S22: N | T22: Particulier | U22: Exclu | V22: 43826
A23: 20.00.00 | B23: A | C23: 43894.626 | D23: D0007 | E23: Congés/Absence | F23: S0146 | G23: Congé de transition professionnelle | H23: E0813 | I23: Congé de transition professionnelle | J23: Type de congé/absence saisi = 'Congé de transition professionnelle' | K23: A_COA_TYCOAB [Saisi] = 'CF016' | L23: T2009 | M23: Congé de transition professionnelle - Demande | N23: Création | Q23: Ouvrier de la défense auxiliaire non affilié ou temporaire non mensualisé | R23: P0182 | S23: O | T23: Particulier | U23: Exclu | V23: 43826
A24: 20.00.00 | B24: A | C24: 43894.614 | D24: D0007 | E24: Congés/Absence | F24: S0146 | G24: Congé de transition professionnelle | H24: E0813 | I24: Congé de transition professionnelle | J24: Type de congé/absence saisi = 'Congé de transition professionnelle' | K24: A_COA_TYCOAB [Saisi] = 'CF016' | L24: T2010 | M24: Congé de transition professionnelle - Fin | N24: Modification | Q24: Ouvrier de la défense auxiliaire non affilié ou temporaire non mensualisé | R24: P0182 | S24: O | T24: Particulier | U24: Exclu | V24: 43826
A25: 25.10.00 | B25: M | C25: 45995.637 | D25: D0007 | E25: Congés/Absence | F25: S0146 | G25: Congé de transition professionnelle | H25: E0813 | I25: Congé de transition professionnelle | J25: Type de congé/absence saisi = 'Congé de transition professionnelle' | K25: A_COA_TYCOAB [Saisi] = 'CF016' | L25: T2009 | M25: Congé de transition professionnelle - Demande | N25: Création | Q25: Ouvrier des parcs et ateliers confirmé non affilié ou stagiaire | R25: P0185 | S25: O | T25: Particulier | U25: Exclu | V25: 43826 | W25: 45900
A26: 25.10.00 | B26: A | C26: 45995.637 | D26: D0007 | E26: Congés/Absence | F26: S0146 | G26: Congé de transition professionnelle | H26: E0813 | I26: Congé de transition professionnelle | J26: Type de congé/absence saisi = 'Congé de transition professionnelle' | K26: A_COA_TYCOAB [Saisi] = 'CF016' | L26: T2009 | M26: Congé de transition professionnelle - Demande | N26: Création | Q26: Ouvrier des parcs et ateliers confirmé non affilié ou stagiaire | R26: P0185 | S26: O | T26: Particulier | U26: Passant | V26: 45901 | X26: CTP_I_034 ET CTP_I_001 ET CTP_I_003 ET CTP_I_004 ET CTP_I_005 ET CTP_I_006 ET CTP_I_007 ET CTP_I_008 ET CTP_I_009 ET CTP_I_010 ET CTP_I_011 ET CTP_I_002 ET CTP_I_014 ET CTP_D_001 ET CTP_D_004 ET CTP_D_003 ET ABS_C_001 ET ABS_C_002 ET ABS_C_003 ET ABS_C_004 ET ABS_C_019 ET ABS_C_020 ET ABS_C_026 | Y26: CTP_I_034 | Z26: =VLOOKUP(Y26,'Axe 2 Règles de gestion'!$D$2:$F$65,3, FALSE) -> L'agent bénéficie des dispositions applicables aux agents ouvriers affiliés pour le congé de transition professionnelle. | AA26: CTP_I_001 | AB26: =VLOOKUP(AA26,'Axe 2 Règles de gestion'!$D$2:$F$65,3, FALSE) -> L'agent peut bénéficier du congé si l'administration envisage de supprimer son emploi en cas de restructuration de son service, dont le périmètre et la durée sont définis par arrêté. | AC26: CTP_I_003 | AD26: =VLOOKUP(AC26,'Axe 2 Règles de gestion'!$D$2:$F$65,3, FALSE) -> Le comité social d'administration compétent est consulté sur la mise en place du congé. | AE26: CTP_I_004 | AF26: =VLOOKUP(AE26,'Axe 2 Règles de gestion'!$D$2:$F$65,3, FALSE) -> Le congé peut être fractionné en mois, semaines ou journées. | AG26: CTP_I_005 | AH26: =VLOOKUP(AG26,'Axe 2 Règles de gestion'!$D$2:$F$65,3, FALSE) -> Le congé permet à l'agent de suivre une formation d'une durée égale ou supérieure à 120 heures sanctionnée par une certification professionnelle ou à 70 heures pour accompagner ou conseiller les créateurs ou repreneurs d'entreprises. | AI26: CTP_I_006 | AJ26: =VLOOKUP(AI26,'Axe 2 Règles de gestion'!$D$2:$F$65,3, FALSE) -> L'agent doit effectuer une demande. | AK26: CTP_I_007 | AL26: =VLOOKUP(AK26,'Axe 2 Règles de gestion'!$D$2:$F$65,3, FALSE) -> La demande de congé précise la nature de la formation, sa durée, le nom de l'organisme qui la dispense et l'objectif professionnel visé. | AM26: CTP_I_008 | AN26: =VLOOKUP(AM26,'Axe 2 Règles de gestion'!$D$2:$F$65,3, FALSE) -> L'administration informe l'agent de sa réponse par écrit dans le délai de 30 jours suivant la réception de la demande. | AO26: CTP_I_009 | AP26: =VLOOKUP(AO26,'Axe 2 Règles de gestion'!$D$2:$F$65,3, FALSE) -> La décision de rejet du congé doit être motivée. | AQ26: CTP_I_010 | AR26: =VLOOKUP(AQ26,'Axe 2 Règles de gestion'!$D$2:$F$65,3, FALSE) -> Le bénéfice du congé peut être différé dans l'intérêt du service. | AS26: CTP_I_011 | AT26: =VLOOKUP(AS26,'Axe 2 Règles de gestion'!$D$2:$F$65,3, FALSE) -> L'agent transmet les attestations établies par l'organisme de formation, justifiant son assiduité à l'action de formation, sinon il perd le bénéfice de ce congé. | AU26: CTP_I_002 | AV26: =VLOOKUP(AU26,'Axe 2 Règles de gestion'!$D$2:$F$65,3, FALSE) -> Si le projet professionnel nécessite des actions de formation dont la durée totale est supérieure à 12 mois, alors le congé est prolongé en un congé de formation professionnelle pour une durée cumulée ne pouvant excéder 3 ans. | AW26: CTP_I_014 | AX26: =VLOOKUP(AW26,'Axe 2 Règles de gestion'!$D$2:$F$65,3, FALSE) -> Le silence gardé par l'administration à l'issue de ce délai vaut rejet de la demande. | BE26: CTP_D_001 | BF26: =VLOOKUP(BE26,'Axe 2 Règles de gestion'!$D$2:$F$65,3, FALSE) -> L'agent doit être en activité. | BG26: CTP_D_004 | BH26: =VLOOKUP(BG26,'Axe 2 Règles de gestion'!$D$2:$F$65,3, FALSE) -> Le congé est accordé pour une durée maximale de 12 mois. | BI26: CTP_D_003 | BJ26: =VLOOKUP(BI26,'Axe 2 Règles de gestion'!$D$2:$F$65,3, FALSE) -> La demande de congé doit être formulée au moins 60 jours avant la date de début de la formation liée au congé. | BM26: ABS_C_001 | BN26: =VLOOKUP(BM26,'Axe 2 Règles de gestion'!$D$2:$F$65,3, FALSE) -> La date de début du congé/absence doit être postérieure ou égale à la date de recrutement dans la FPE ou dans la carrière militaire. | BO26: ABS_C_002 | BP26: =VLOOKUP(BO26,'Axe 2 Règles de gestion'!$D$2:$F$65,3, FALSE) -> La date de début du congé/absence doit être postérieure ou égale à la date de début du lien juridique. | BQ26: ABS_C_003 | BR26: =VLOOKUP(BQ26,'Axe 2 Règles de gestion'!$D$2:$F$65,3, FALSE) -> La date de début du congé/absence doit être antérieure ou égale à la date de fin réelle du congé/absence. | BS26: ABS_C_004 | BT26: =VLOOKUP(BS26,'Axe 2 Règles de gestion'!$D$2:$F$65,3, FALSE) -> La date de début du congé/absence doit être antérieure ou égale à la date de fin prévisionnelle du congé/absence. | BU26: ABS_C_019 | BV26: =VLOOKUP(BU26,'Axe 2 Règles de gestion'!$D$2:$F$65,3, FALSE) -> Si l'absence ne commence pas par une demi-journée et si l'absence précédente ne finit pas par une demi journée, la date de début de l'absence saisie est postérieure à la date de fin réelle de l'absence précédente. | BW26: ABS_C_020 | BX26: =VLOOKUP(BW26,'Axe 2 Règles de gestion'!$D$2:$F$65,3, FALSE) -> Si l'absence ne commence pas par une demi-journée et si l'absence précédente ne finit pas par une demi journée, la date de début de l'absence saisie est postérieure à la date de fin prévisionnelle de l'absence précédente. | BY26: ABS_C_026 | BZ26: =VLOOKUP(BY26,'Axe 2 Règles de gestion'!$D$2:$F$65,3, FALSE) -> Dans le cas d'un congé autre que CLM, CLD, CGM et CITIS, l'indicateur de requalification doit être à non et les impacts spécifiques à la requalification ne doivent pas être mobilisés ou l'impact rémunération est vide.
A27: 25.10.00 | B27: M | C27: 45995.639 | D27: D0007 | E27: Congés/Absence | F27: S0146 | G27: Congé de transition professionnelle | H27: E0813 | I27: Congé de transition professionnelle | J27: Type de congé/absence saisi = 'Congé de transition professionnelle' | K27: A_COA_TYCOAB [Saisi] = 'CF016' | L27: T2010 | M27: Congé de transition professionnelle - Fin | N27: Modification | Q27: Ouvrier des parcs et ateliers confirmé non affilié ou stagiaire | R27: P0185 | S27: O | T27: Particulier | U27: Exclu | V27: 43826 | W27: 45900
A28: 25.10.00 | B28: A | C28: 45995.639 | D28: D0007 | E28: Congés/Absence | F28: S0146 | G28: Congé de transition professionnelle | H28: E0813 | I28: Congé de transition professionnelle | J28: Type de congé/absence saisi = 'Congé de transition professionnelle' | K28: A_COA_TYCOAB [Saisi] = 'CF016' | L28: T2010 | M28: Congé de transition professionnelle - Fin | N28: Modification | Q28: Ouvrier des parcs et ateliers confirmé non affilié ou stagiaire | R28: P0185 | S28: O | T28: Particulier | U28: Passant | V28: 45901 | X28: CTP_I_034 ET CTP_I_012 ET CTP_D_004 ET ABS_C_005 ET ABS_C_006 ET ABS_C_007 ET ABS_C_008 ET ABS_C_009 | Y28: CTP_I_034 | Z28: =VLOOKUP(Y28,'Axe 2 Règles de gestion'!$D$2:$F$65,3, FALSE) -> L'agent bénéficie des dispositions applicables aux agents ouvriers affiliés pour le congé de transition professionnelle. | AA28: CTP_I_012 | AB28: =VLOOKUP(AA28,'Axe 2 Règles de gestion'!$D$2:$F$65,3, FALSE) -> Le congé s'achève avant le terme de la période de restructuration sauf si l'agent a débuté sa formation moins de 12 mois avant ce terme du fait d'une décision de report dans l'intérêt du service. | BE28: CTP_D_004 | BF28: =VLOOKUP(BE28,'Axe 2 Règles de gestion'!$D$2:$F$65,3, FALSE) -> Le congé est accordé pour une durée maximale de 12 mois. | BM28: ABS_C_005 | BN28: =VLOOKUP(BM28,'Axe 2 Règles de gestion'!$D$2:$F$65,3, FALSE) -> La date de fin réelle du congé/absence doit être antérieure ou égale à la date limite de fin réelle ou prévisionnelle du lien juridique. | BO28: ABS_C_006 | BP28: =VLOOKUP(BO28,'Axe 2 Règles de gestion'!$D$2:$F$65,3, FALSE) -> La date de fin prévisionnelle du congé/absence doit être antérieure ou égale à la date limite de fin réelle ou prévisionnelle du lien juridique. | BQ28: ABS_C_007 | BR28: =VLOOKUP(BQ28,'Axe 2 Règles de gestion'!$D$2:$F$65,3, FALSE) -> La date de fin réelle du congé/absence doit être antérieure à la date limite de départ à la retraite. | BS28: ABS_C_008 | BT28: =VLOOKUP(BS28,'Axe 2 Règles de gestion'!$D$2:$F$65,3, FALSE) -> La date de fin prévisionnelle du congé/absence doit être antérieure à la date limite de départ à la retraite. | BU28: ABS_C_009 | BV28: =VLOOKUP(BU28,'Axe 2 Règles de gestion'!$D$2:$F$65,3, FALSE) -> La date de fin réelle ou la date de fin prévisionnelle du congé/absence doit être saisie.
A29: 20.00.00 | B29: A | C29: 43894.628 | D29: D0007 | E29: Congés/Absence | F29: S0146 | G29: Congé de transition professionnelle | H29: E0813 | I29: Congé de transition professionnelle | J29: Type de congé/absence saisi = 'Congé de transition professionnelle' | K29: A_COA_TYCOAB [Saisi] = 'CF016' | L29: T2009 | M29: Congé de transition professionnelle - Demande | N29: Création | Q29: Ouvrier du service des alcools confirmé non affilié | R29: P0221 | S29: O | T29: Particulier | U29: Exclu | V29: 43826
A30: 20.00.00 | B30: A | C30: 43894.615 | D30: D0007 | E30: Congés/Absence | F30: S0146 | G30: Congé de transition professionnelle | H30: E0813 | I30: Congé de transition professionnelle | J30: Type de congé/absence saisi = 'Congé de transition professionnelle' | K30: A_COA_TYCOAB [Saisi] = 'CF016' | L30: T2010 | M30: Congé de transition professionnelle - Fin | N30: Modification | Q30: Ouvrier du service des alcools confirmé non affilié | R30: P0221 | S30: O | T30: Particulier | U30: Exclu | V30: 43826
