Workbook
Name date_DIADC: 'Mode opératoire'!#REF!
Name notice_DIADC: 'Mode opératoire'!#REF!
Name notice_ENCHN: 'Mode opératoire'!$B$1:$B$4
Name notice_ICA: 'Mode opératoire'!#REF!

Sheet Mode opératoire
B1: MODE OPERATOIRE
B2: La transaction s'effectue au niveau de la rubrique "Congés/absences", elle inclut l'ensemble des sous-rubriques listées ci-dessous : - Congés/absences - Complément pour congé / absence : impact rémunération - Compteurs des droits à congés - Compteurs de périodes de congés On notera que : La sous-rubrique "Complément pour congé / absence : impact rémunération" est réputée, suite au découpage des absences en tranche de rémunération, avoir des dates de début et de fin alignées sur les dates dedébut et de fin de la sous-rubrique "Congés/absences" (contrôle bloquant)

Sheet Axe 1 Enchainement des RG
A1: Version | B1: Type de mise à jour | C1: Date de mise à jour | D1: Identifiant Domaine | E1: Libellé du Domaine | F1: Identifiant Sous-domaine | G1: Libellé du Sous-domaine | H1: Identifiant Evénement | I1: Libellé de l'évènement | J1: Libellé condition déclenchement Evènement | K1: Condition déclenchement Evènement | L1: Identifiant type d'évènement | M1: Libellé type d'évènement | N1: Type de mise à jour | O1: Libellé condition déclenchement Type Evènement | P1: Condition déclenchement Type Evènement | Q1: Libellé Population | R1: Codification Population | S1: Typologie de population | T1: Général / Particulier | U1: Passant / Exclu | V1: Date de début | W1: Date de fin | X1: Règles mobilisées | Y1: Identifiant Règle de contrôle intellectuel 1 | Z1: Libellé Règle de contrôle intellectuel 1 | AA1: Identifiant Règle de contrôle intellectuel 2 | AB1: Libellé Règle de contrôle intellectuel 2 | AC1: Identifiant Règle de contrôle intellectuel 3 | AD1: Libellé Règle de contrôle intellectuel 3 | AE1: Identifiant Règle de contrôle intellectuel 4 | AF1: Libellé Règle de contrôle intellectuel 4 | AG1: Identifiant Règle de contrôle intellectuel 5 | AH1: Libellé Règle de contrôle intellectuel 5 | AI1: Identifiant Règle de contrôle intellectuel 6 | AJ1: Libellé Règle de contrôle intellectuel 6 | AK1: Identifiant Règle de contrôle intellectuel 7 | AL1: Libellé Règle de contrôle intellectuel 7 | AM1: Identifiant Règle de contrôle intellectuel 8 | AN1: Libellé Règle de contrôle intellectuel 8 | AO1: Identifiant Règle de contrôle intellectuel 9 | AP1: Libellé Règle de contrôle intellectuel 9 | AQ1: Identifiant Règle de condition 1 | AR1: Libellé Règle de condition 1 | AS1: Identifiant Règle de condition 2 | AT1: Libellé Règle de condition 2 | AU1: Identifiant Règle de condition 3 | AV1: Libellé Règle de condition 3 | AW1: Identifiant Règle de condition 4 | AX1: Libellé Règle de condition 4 | AY1: Identifiant Règle de condition 5 | AZ1: Libellé Règle de condition 5 | BA1: Identifiant Règle de condition 6 | BB1: Libellé Règle de condition 6 | BC1: Identifiant Règle de condition 7 | BD1: Libellé Règle de condition 7 | BE1: Identifiant Règle de condition 8 | BF1: Libellé Règle de condition 8 | BG1: Identifiant Règle de contrôle 1 | BH1: Libellé Règle de contrôle 1 | BI1: Identifiant Règle de contrôle 2 | BJ1: Libellé Règle de contrôle 2 | BK1: Identifiant Règle de contrôle 3 | BL1: Libellé Règle de contrôle 3 | BM1: Identifiant Règle de contrôle 4 | BN1: Libellé Règle de contrôle 4 | BO1: Identifiant Règle de contrôle 5 | BP1: Libellé Règle de contrôle 5 | BQ1: Identifiant Règle de contrôle 6 | BR1: Libellé Règle de contrôle 6 | BS1: Identifiant Règle de contrôle 7 | BT1: Libellé Règle de contrôle 7 | BU1: Identifiant Règle de contrôle 8 | BV1: Libellé Règle de contrôle 8 | BW1: Identifiant Règle de contrôle 9 | BX1: Libellé Règle de contrôle 9 | BY1: Identifiant Règle de contrôle 10 | BZ1: Libellé Règle de contrôle 10 | CA1: Identifiant Règle de contrôle 11 | CB1: Libellé Règle de contrôle 11 | CC1: Identifiant Règle de contrôle 12 | CD1: Libellé Règle de contrôle 12 | CE1: Identifiant Règle de contrôle 13 | CF1: Libellé Règle de contrôle 13 | CG1: Identifiant Règle de contrôle 14 | CH1: Libellé Règle de contrôle 14 | CI1: Identifiant Règle de contrôle 15 | CJ1: Libellé Règle de contrôle 15 | CK1: FIME | CL1: Statut de travail
A2: 17.10.00 | B2: A | C2: 43152.5 | D2: D0007 | E2: Congés/Absence | F2: S0046 | G2: Autorisations d'absence | H2: E0427 | I2: Autorisation d'absence pour formation professionnelle | J2: Type de congé/absence saisi égal 'Autorisation d'absence pour formation professionnelle' | K2: A_COA_TYCOAB [Saisi] = 'CA001' | L2: T1088 | M2: Autorisation d'absence pour formation professionnelle | N2: Création Modification | Q2: Titulaire ou magistrat | R2: P0001 | S2: T | T2: Général | U2: Passant | V2: 40725 | X2: ABS_C_010 ET ABS_C_001 ET ABS_C_003 ET ABS_C_004 ET ABS_C_007 ET ABS_C_008 ET ABS_C_009 ET ABS_C_019 ET ABS_C_020 ET ABS_C_026 | BG2: ABS_C_010 | BH2: =VLOOKUP(BG2,'Axe 2 Règles de gestion'!$D$2:$F$354,3, FALSE) -> L'agent doit être en activité. | BI2: ABS_C_001 | BJ2: =VLOOKUP(BI2,'Axe 2 Règles de gestion'!$D$2:$F$354,3, FALSE) -> La date de début du congé/absence doit être postérieure ou égale à la date de recrutement dans la FPE ou dans la carrière militaire. | BK2: ABS_C_003 | BL2: =VLOOKUP(BK2,'Axe 2 Règles de gestion'!$D$2:$F$354,3, FALSE) -> La date de début du congé/absence doit être antérieure ou égale à la date de fin réelle du congé/absence. | BM2: ABS_C_004 | BN2: =VLOOKUP(BM2,'Axe 2 Règles de gestion'!$D$2:$F$354,3, FALSE) -> La date de début du congé/absence doit être antérieure ou égale à la date de fin prévisionnelle du congé/absence. | BO2: ABS_C_007 | BP2: =VLOOKUP(BO2,'Axe 2 Règles de gestion'!$D$2:$F$354,3, FALSE) -> La date de fin réelle du congé/absence doit être antérieure à la date limite de départ à la retraite. | BQ2: ABS_C_008 | BR2: =VLOOKUP(BQ2,'Axe 2 Règles de gestion'!$D$2:$F$354,3, FALSE) -> La date de fin prévisionnelle du congé/absence doit être antérieure à la date limite de départ à la retraite. | BS2: ABS_C_009 | BT2: =VLOOKUP(BS2,'Axe 2 Règles de gestion'!$D$2:$F$354,3, FALSE) -> La date de fin réelle ou la date de fin prévisionnelle du congé/absence doit être saisie. | BU2: ABS_C_019 | BV2: =VLOOKUP(BU2,'Axe 2 Règles de gestion'!$D$2:$F$354,3, FALSE) -> Si l'absence ne commence pas par une demi-journée et si l'absence précédente ne finit pas par une demi journée, la date de début de l'absence saisie est postérieure à la date de fin réelle de l'absence précédente. | BW2: ABS_C_020 | BX2: =VLOOKUP(BW2,'Axe 2 Règles de gestion'!$D$2:$F$354,3, FALSE) -> Si l'absence ne commence pas par une demi-journée et si l'absence précédente ne finit pas par une demi journée, la date de début de l'absence saisie est postérieure à la date de fin prévisionnelle de l'absence précédente. | BY2: ABS_C_026 | BZ2: =VLOOKUP(BY2,'Axe 2 Règles de gestion'!$D$2:$F$354,3, FALSE) -> Dans le cas d'un congé autre que CLM, CLD, CGM et CITIS, l'indicateur de requalification doit être à non et les impacts spécifiques à la requalification ne doivent pas être mobilisés ou l'impact rémunération est vide.
A3: 17.10.00 | B3: A | C3: 43152.5 | D3: D0007 | E3: Congés/Absence | F3: S0046 | G3: Autorisations d'absence | H3: E0427 | I3: Autorisation d'absence pour formation professionnelle | J3: Type de congé/absence saisi égal 'Autorisation d'absence pour formation professionnelle' | K3: A_COA_TYCOAB [Saisi] = 'CA001' | L3: T1088 | M3: Autorisation d'absence pour formation professionnelle | N3: Création Modification | Q3: Contractuel | R3: P0003 | S3: N | T3: Général | U3: Passant | V3: 40725 | X3: ABS_C_010 ET ABS_C_003 ET ABS_C_004 ET ABS_C_009 ET ABS_C_019 ET ABS_C_020 ET ABS_C_026 ET ABS_C_002 ET ABS_C_005 ET ABS_C_006 ET ABS_C_007 ET ABS_C_008 | BG3: ABS_C_010 | BH3: =VLOOKUP(BG3,'Axe 2 Règles de gestion'!$D$2:$F$354,3, FALSE) -> L'agent doit être en activité. | BI3: ABS_C_003 | BJ3: =VLOOKUP(BI3,'Axe 2 Règles de gestion'!$D$2:$F$354,3, FALSE) -> La date de début du congé/absence doit être antérieure ou égale à la date de fin réelle du congé/absence. | BK3: ABS_C_004 | BL3: =VLOOKUP(BK3,'Axe 2 Règles de gestion'!$D$2:$F$354,3, FALSE) -> La date de début du congé/absence doit être antérieure ou égale à la date de fin prévisionnelle du congé/absence. | BM3: ABS_C_009 | BN3: =VLOOKUP(BM3,'Axe 2 Règles de gestion'!$D$2:$F$354,3, FALSE) -> La date de fin réelle ou la date de fin prévisionnelle du congé/absence doit être saisie. | BO3: ABS_C_019 | BP3: =VLOOKUP(BO3,'Axe 2 Règles de gestion'!$D$2:$F$354,3, FALSE) -> Si l'absence ne commence pas par une demi-journée et si l'absence précédente ne finit pas par une demi journée, la date de début de l'absence saisie est postérieure à la date de fin réelle de l'absence précédente. | BQ3: ABS_C_020 | BR3: =VLOOKUP(BQ3,'Axe 2 Règles de gestion'!$D$2:$F$354,3, FALSE) -> Si l'absence ne commence pas par une demi-journée et si l'absence précédente ne finit pas par une demi journée, la date de début de l'absence saisie est postérieure à la date de fin prévisionnelle de l'absence précédente. | BS3: ABS_C_026 | BT3: =VLOOKUP(BS3,'Axe 2 Règles de gestion'!$D$2:$F$354,3, FALSE) -> Dans le cas d'un congé autre que CLM, CLD, CGM et CITIS, l'indicateur de requalification doit être à non et les impacts spécifiques à la requalification ne doivent pas être mobilisés ou l'impact rémunération est vide. | BU3: ABS_C_002 | BV3: =VLOOKUP(BU3,'Axe 2 Règles de gestion'!$D$2:$F$354,3, FALSE) -> La date de début du congé/absence doit être postérieure ou égale à la date de début du lien juridique. | BW3: ABS_C_005 | BX3: =VLOOKUP(BW3,'Axe 2 Règles de gestion'!$D$2:$F$354,3, FALSE) -> La date de fin réelle du congé/absence doit être antérieure ou égale à la date limite de fin réelle ou prévisionnelle du lien juridique. | BY3: ABS_C_006 | BZ3: =VLOOKUP(BY3,'Axe 2 Règles de gestion'!$D$2:$F$354,3, FALSE) -> La date de fin prévisionnelle du congé/absence doit être antérieure ou égale à la date limite de fin réelle ou prévisionnelle du lien juridique. | CA3: ABS_C_007 | CB3: =VLOOKUP(CA3,'Axe 2 Règles de gestion'!$D$2:$F$354,3, FALSE) -> La date de fin réelle du congé/absence doit être antérieure à la date limite de départ à la retraite. | CC3: ABS_C_008 | CD3: =VLOOKUP(CC3,'Axe 2 Règles de gestion'!$D$2:$F$354,3, FALSE) -> La date de fin prévisionnelle du congé/absence doit être antérieure à la date limite de départ à la retraite.
A4: 17.10.00 | B4: A | C4: 43152.5 | D4: D0007 | E4: Congés/Absence | F4: S0046 | G4: Autorisations d'absence | H4: E0427 | I4: Autorisation d'absence pour formation professionnelle | J4: Type de congé/absence saisi égal 'Autorisation d'absence pour formation professionnelle' | K4: A_COA_TYCOAB [Saisi] = 'CA001' | L4: T1088 | M4: Autorisation d'absence pour formation professionnelle | N4: Création Modification | Q4: Stagiaire ou auditeur ou élève | R4: P0004 | S4: S | T4: Général | U4: Passant | V4: 40725 | X4: ABS_C_010 ET ABS_C_001 ET ABS_C_003 ET ABS_C_004 ET ABS_C_007 ET ABS_C_008 ET ABS_C_009 ET ABS_C_019 ET ABS_C_020 ET ABS_C_026 | BG4: ABS_C_010 | BH4: =VLOOKUP(BG4,'Axe 2 Règles de gestion'!$D$2:$F$354,3, FALSE) -> L'agent doit être en activité. | BI4: ABS_C_001 | BJ4: =VLOOKUP(BI4,'Axe 2 Règles de gestion'!$D$2:$F$354,3, FALSE) -> La date de début du congé/absence doit être postérieure ou égale à la date de recrutement dans la FPE ou dans la carrière militaire. | BK4: ABS_C_003 | BL4: =VLOOKUP(BK4,'Axe 2 Règles de gestion'!$D$2:$F$354,3, FALSE) -> La date de début du congé/absence doit être antérieure ou égale à la date de fin réelle du congé/absence. | BM4: ABS_C_004 | BN4: =VLOOKUP(BM4,'Axe 2 Règles de gestion'!$D$2:$F$354,3, FALSE) -> La date de début du congé/absence doit être antérieure ou égale à la date de fin prévisionnelle du congé/absence. | BO4: ABS_C_007 | BP4: =VLOOKUP(BO4,'Axe 2 Règles de gestion'!$D$2:$F$354,3, FALSE) -> La date de fin réelle du congé/absence doit être antérieure à la date limite de départ à la retraite. | BQ4: ABS_C_008 | BR4: =VLOOKUP(BQ4,'Axe 2 Règles de gestion'!$D$2:$F$354,3, FALSE) -> La date de fin prévisionnelle du congé/absence doit être antérieure à la date limite de départ à la retraite. | BS4: ABS_C_009 | BT4: =VLOOKUP(BS4,'Axe 2 Règles de gestion'!$D$2:$F$354,3, FALSE) -> La date de fin réelle ou la date de fin prévisionnelle du congé/absence doit être saisie. | BU4: ABS_C_019 | BV4: =VLOOKUP(BU4,'Axe 2 Règles de gestion'!$D$2:$F$354,3, FALSE) -> Si l'absence ne commence pas par une demi-journée et si l'absence précédente ne finit pas par une demi journée, la date de début de l'absence saisie est postérieure à la date de fin réelle de l'absence précédente. | BW4: ABS_C_020 | BX4: =VLOOKUP(BW4,'Axe 2 Règles de gestion'!$D$2:$F$354,3, FALSE) -> Si l'absence ne commence pas par une demi-journée et si l'absence précédente ne finit pas par une demi journée, la date de début de l'absence saisie est postérieure à la date de fin prévisionnelle de l'absence précédente. | BY4: ABS_C_026 | BZ4: =VLOOKUP(BY4,'Axe 2 Règles de gestion'!$D$2:$F$354,3, FALSE) -> Dans le cas d'un congé autre que CLM, CLD, CGM et CITIS, l'indicateur de requalification doit être à non et les impacts spécifiques à la requalification ne doivent pas être mobilisés ou l'impact rémunération est vide.
A5: 17.10.00 | B5: A | C5: 43189.5 | D5: D0007 | E5: Congés/Absence | F5: S0046 | G5: Autorisations d'absence | H5: E0427 | I5: Autorisation d'absence pour formation professionnelle | J5: Type de congé/absence saisi égal 'Autorisation d'absence pour formation professionnelle' | K5: A_COA_TYCOAB [Saisi] = 'CA001' | L5: T1088 | M5: Autorisation d'absence pour formation professionnelle | N5: Création Modification | Q5: Ouvrier d'état | R5: P0005 | S5: O | T5: Général | U5: Passant | V5: 40725 | X5: ABS_C_010 ET ABS_C_003 ET ABS_C_004 ET ABS_C_009 ET ABS_C_019 ET ABS_C_020 ET ABS_C_026 ET ABS_C_002 ET ABS_C_005 ET ABS_C_006 ET ABS_C_007 ET ABS_C_008 | BG5: ABS_C_010 | BH5: =VLOOKUP(BG5,'Axe 2 Règles de gestion'!$D$2:$F$354,3, FALSE) -> L'agent doit être en activité. | BI5: ABS_C_003 | BJ5: =VLOOKUP(BI5,'Axe 2 Règles de gestion'!$D$2:$F$354,3, FALSE) -> La date de début du congé/absence doit être antérieure ou égale à la date de fin réelle du congé/absence. | BK5: ABS_C_004 | BL5: =VLOOKUP(BK5,'Axe 2 Règles de gestion'!$D$2:$F$354,3, FALSE) -> La date de début du congé/absence doit être antérieure ou égale à la date de fin prévisionnelle du congé/absence. | BM5: ABS_C_009 | BN5: =VLOOKUP(BM5,'Axe 2 Règles de gestion'!$D$2:$F$354,3, FALSE) -> La date de fin réelle ou la date de fin prévisionnelle du congé/absence doit être saisie. | BO5: ABS_C_019 | BP5: =VLOOKUP(BO5,'Axe 2 Règles de gestion'!$D$2:$F$354,3, FALSE) -> Si l'absence ne commence pas par une demi-journée et si l'absence précédente ne finit pas par une demi journée, la date de début de l'absence saisie est postérieure à la date de fin réelle de l'absence précédente. | BQ5: ABS_C_020 | BR5: =VLOOKUP(BQ5,'Axe 2 Règles de gestion'!$D$2:$F$354,3, FALSE) -> Si l'absence ne commence pas par une demi-journée et si l'absence précédente ne finit pas par une demi journée, la date de début de l'absence saisie est postérieure à la date de fin prévisionnelle de l'absence précédente. | BS5: ABS_C_026 | BT5: =VLOOKUP(BS5,'Axe 2 Règles de gestion'!$D$2:$F$354,3, FALSE) -> Dans le cas d'un congé autre que CLM, CLD, CGM et CITIS, l'indicateur de requalification doit être à non et les impacts spécifiques à la requalification ne doivent pas être mobilisés ou l'impact rémunération est vide. | BU5: ABS_C_002 | BV5: =VLOOKUP(BU5,'Axe 2 Règles de gestion'!$D$2:$F$354,3, FALSE) -> La date de début du congé/absence doit être postérieure ou égale à la date de début du lien juridique. | BW5: ABS_C_005 | BX5: =VLOOKUP(BW5,'Axe 2 Règles de gestion'!$D$2:$F$354,3, FALSE) -> La date de fin réelle du congé/absence doit être antérieure ou égale à la date limite de fin réelle ou prévisionnelle du lien juridique. | BY5: ABS_C_006 | BZ5: =VLOOKUP(BY5,'Axe 2 Règles de gestion'!$D$2:$F$354,3, FALSE) -> La date de fin prévisionnelle du congé/absence doit être antérieure ou égale à la date limite de fin réelle ou prévisionnelle du lien juridique. | CA5: ABS_C_007 | CB5: =VLOOKUP(CA5,'Axe 2 Règles de gestion'!$D$2:$F$354,3, FALSE) -> La date de fin réelle du congé/absence doit être antérieure à la date limite de départ à la retraite. | CC5: ABS_C_008 | CD5: =VLOOKUP(CC5,'Axe 2 Règles de gestion'!$D$2:$F$354,3, FALSE) -> La date de fin prévisionnelle du congé/absence doit être antérieure à la date limite de départ à la retraite.
A6: 17.10.00 | B6: A | C6: 43152.5 | D6: D0007 | E6: Congés/Absence | F6: S0046 | G6: Autorisations d'absence | H6: E0427 | I6: Autorisation d'absence pour formation professionnelle | J6: Type de congé/absence saisi égal 'Autorisation d'absence pour formation professionnelle' | K6: A_COA_TYCOAB [Saisi] = 'CA001' | L6: T1088 | M6: Autorisation d'absence pour formation professionnelle | N6: Création Modification | Q6: Personnel civil payé à l'acte ou à la tâche | R6: P0054 | S6: N | T6: Particulier | U6: Exclu | V6: 40725
A7: 17.10.00 | B7: A | C7: 43152.5 | D7: D0007 | E7: Congés/Absence | F7: S0046 | G7: Autorisations d'absence | H7: E0427 | I7: Autorisation d'absence pour formation professionnelle | J7: Type de congé/absence saisi égal 'Autorisation d'absence pour formation professionnelle' | K7: A_COA_TYCOAB [Saisi] = 'CA001' | L7: T1088 | M7: Autorisation d'absence pour formation professionnelle | N7: Création Modification | Q7: Volontaire de service civique outre-mer | R7: P0179 | S7: N | T7: Particulier | U7: Exclu | V7: 40725
A8: 22.00.00 | B8: A | C8: 44714.667 | D8: D0007 | E8: Congés/Absence | F8: S0046 | G8: Autorisations d'absence | H8: E0427 | I8: Autorisation d'absence pour formation professionnelle | J8: Type de congé/absence saisi égal 'Autorisation d'absence pour formation professionnelle' | K8: A_COA_TYCOAB [Saisi] = 'CA001' | L8: T1088 | M8: Autorisation d'absence pour formation professionnelle | N8: Création Modification | Q8: Contractuel recruté sur contrat de mission scientifique | R8: P0266 | S8: N | T8: Particulier | U8: Passant | V8: 44507 | X8: ADI_I_202 ET ADI_I_200 ET ABS_C_010 ET ABS_C_003 ET ABS_C_004 ET ABS_C_009 ET ABS_C_019 ET ABS_C_020 ET ABS_C_026 ET ABS_C_002 ET ABS_C_005 ET ABS_C_006 ET ABS_C_007 ET ABS_C_008 | Y8: ADI_I_202 | Z8: =VLOOKUP(Y8,'Axe 2 Règles de gestion'!$D$2:$F$354,3, FALSE) -> L'agent bénéficie des dispositions applicables aux agents contractuels pour la formation professionnelle, sauf dispositions particulières. | AA8: ADI_I_200 | AB8: =VLOOKUP(AA8,'Axe 2 Règles de gestion'!$D$2:$F$354,3, FALSE) -> L'agent lié par un contrat de mission scientifique bénéficie de façon prioritaire de 20 jours de décharge de service dédiés à des actions de formation. | BG8: ABS_C_010 | BH8: =VLOOKUP(BG8,'Axe 2 Règles de gestion'!$D$2:$F$354,3, FALSE) -> L'agent doit être en activité. | BI8: ABS_C_003 | BJ8: =VLOOKUP(BI8,'Axe 2 Règles de gestion'!$D$2:$F$354,3, FALSE) -> La date de début du congé/absence doit être antérieure ou égale à la date de fin réelle du congé/absence. | BK8: ABS_C_004 | BL8: =VLOOKUP(BK8,'Axe 2 Règles de gestion'!$D$2:$F$354,3, FALSE) -> La date de début du congé/absence doit être antérieure ou égale à la date de fin prévisionnelle du congé/absence. | BM8: ABS_C_009 | BN8: =VLOOKUP(BM8,'Axe 2 Règles de gestion'!$D$2:$F$354,3, FALSE) -> La date de fin réelle ou la date de fin prévisionnelle du congé/absence doit être saisie. | BO8: ABS_C_019 | BP8: =VLOOKUP(BO8,'Axe 2 Règles de gestion'!$D$2:$F$354,3, FALSE) -> Si l'absence ne commence pas par une demi-journée et si l'absence précédente ne finit pas par une demi journée, la date de début de l'absence saisie est postérieure à la date de fin réelle de l'absence précédente. | BQ8: ABS_C_020 | BR8: =VLOOKUP(BQ8,'Axe 2 Règles de gestion'!$D$2:$F$354,3, FALSE) -> Si l'absence ne commence pas par une demi-journée et si l'absence précédente ne finit pas par une demi journée, la date de début de l'absence saisie est postérieure à la date de fin prévisionnelle de l'absence précédente. | BS8: ABS_C_026 | BT8: =VLOOKUP(BS8,'Axe 2 Règles de gestion'!$D$2:$F$354,3, FALSE) -> Dans le cas d'un congé autre que CLM, CLD, CGM et CITIS, l'indicateur de requalification doit être à non et les impacts spécifiques à la requalification ne doivent pas être mobilisés ou l'impact rémunération est vide. | BU8: ABS_C_002 | BV8: =VLOOKUP(BU8,'Axe 2 Règles de gestion'!$D$2:$F$354,3, FALSE) -> La date de début du congé/absence doit être postérieure ou égale à la date de début du lien juridique. | BW8: ABS_C_005 | BX8: =VLOOKUP(BW8,'Axe 2 Règles de gestion'!$D$2:$F$354,3, FALSE) -> La date de fin réelle du congé/absence doit être antérieure ou égale à la date limite de fin réelle ou prévisionnelle du lien juridique. | BY8: ABS_C_006 | BZ8: =VLOOKUP(BY8,'Axe 2 Règles de gestion'!$D$2:$F$354,3, FALSE) -> La date de fin prévisionnelle du congé/absence doit être antérieure ou égale à la date limite de fin réelle ou prévisionnelle du lien juridique. | CA8: ABS_C_007 | CB8: =VLOOKUP(CA8,'Axe 2 Règles de gestion'!$D$2:$F$354,3, FALSE) -> La date de fin réelle du congé/absence doit être antérieure à la date limite de départ à la retraite. | CC8: ABS_C_008 | CD8: =VLOOKUP(CC8,'Axe 2 Règles de gestion'!$D$2:$F$354,3, FALSE) -> La date de fin prévisionnelle du congé/absence doit être antérieure à la date limite de départ à la retraite.
A9: 22.00.00 | B9: A | C9: 44714.668 | D9: D0007 | E9: Congés/Absence | F9: S0046 | G9: Autorisations d'absence | H9: E0427 | I9: Autorisation d'absence pour formation professionnelle | J9: Type de congé/absence saisi égal 'Autorisation d'absence pour formation professionnelle' | K9: A_COA_TYCOAB [Saisi] = 'CA001' | L9: T1088 | M9: Autorisation d'absence pour formation professionnelle | N9: Création Modification | Q9: Contractuel recruté sur contrat post doctoral | R9: P0267 | S9: N | T9: Particulier | U9: Passant | V9: 44507 | X9: ADI_I_203 ET ADI_I_201 ET ABS_C_010 ET ABS_C_003 ET ABS_C_004 ET ABS_C_009 ET ABS_C_019 ET ABS_C_020 ET ABS_C_026 ET ABS_C_002 ET ABS_C_005 ET ABS_C_006 ET ABS_C_007 ET ABS_C_008 | Y9: ADI_I_203 | Z9: =VLOOKUP(Y9,'Axe 2 Règles de gestion'!$D$2:$F$354,3, FALSE) -> L'agent bénéficie des dispositions applicables aux agents contractuels pour la formation professionnelle, sauf dispositions particulières. | AA9: ADI_I_201 | AB9: =VLOOKUP(AA9,'Axe 2 Règles de gestion'!$D$2:$F$354,3, FALSE) -> L'agent lié par un contrat post doctoral bénéficie de façon prioritaire de 20 jours de décharge de service dédiés à des actions de formation. | BG9: ABS_C_010 | BH9: =VLOOKUP(BG9,'Axe 2 Règles de gestion'!$D$2:$F$354,3, FALSE) -> L'agent doit être en activité. | BI9: ABS_C_003 | BJ9: =VLOOKUP(BI9,'Axe 2 Règles de gestion'!$D$2:$F$354,3, FALSE) -> La date de début du congé/absence doit être antérieure ou égale à la date de fin réelle du congé/absence. | BK9: ABS_C_004 | BL9: =VLOOKUP(BK9,'Axe 2 Règles de gestion'!$D$2:$F$354,3, FALSE) -> La date de début du congé/absence doit être antérieure ou égale à la date de fin prévisionnelle du congé/absence. | BM9: ABS_C_009 | BN9: =VLOOKUP(BM9,'Axe 2 Règles de gestion'!$D$2:$F$354,3, FALSE) -> La date de fin réelle ou la date de fin prévisionnelle du congé/absence doit être saisie. | BO9: ABS_C_019 | BP9: =VLOOKUP(BO9,'Axe 2 Règles de gestion'!$D$2:$F$354,3, FALSE) -> Si l'absence ne commence pas par une demi-journée et si l'absence précédente ne finit pas par une demi journée, la date de début de l'absence saisie est postérieure à la date de fin réelle de l'absence précédente. | BQ9: ABS_C_020 | BR9: =VLOOKUP(BQ9,'Axe 2 Règles de gestion'!$D$2:$F$354,3, FALSE) -> Si l'absence ne commence pas par une demi-journée et si l'absence précédente ne finit pas par une demi journée, la date de début de l'absence saisie est postérieure à la date de fin prévisionnelle de l'absence précédente. | BS9: ABS_C_026 | BT9: =VLOOKUP(BS9,'Axe 2 Règles de gestion'!$D$2:$F$354,3, FALSE) -> Dans le cas d'un congé autre que CLM, CLD, CGM et CITIS, l'indicateur de requalification doit être à non et les impacts spécifiques à la requalification ne doivent pas être mobilisés ou l'impact rémunération est vide. | BU9: ABS_C_002 | BV9: =VLOOKUP(BU9,'Axe 2 Règles de gestion'!$D$2:$F$354,3, FALSE) -> La date de début du congé/absence doit être postérieure ou égale à la date de début du lien juridique. | BW9: ABS_C_005 | BX9: =VLOOKUP(BW9,'Axe 2 Règles de gestion'!$D$2:$F$354,3, FALSE) -> La date de fin réelle du congé/absence doit être antérieure ou égale à la date limite de fin réelle ou prévisionnelle du lien juridique. | BY9: ABS_C_006 | BZ9: =VLOOKUP(BY9,'Axe 2 Règles de gestion'!$D$2:$F$354,3, FALSE) -> La date de fin prévisionnelle du congé/absence doit être antérieure ou égale à la date limite de fin réelle ou prévisionnelle du lien juridique. | CA9: ABS_C_007 | CB9: =VLOOKUP(CA9,'Axe 2 Règles de gestion'!$D$2:$F$354,3, FALSE) -> La date de fin réelle du congé/absence doit être antérieure à la date limite de départ à la retraite. | CC9: ABS_C_008 | CD9: =VLOOKUP(CC9,'Axe 2 Règles de gestion'!$D$2:$F$354,3, FALSE) -> La date de fin prévisionnelle du congé/absence doit être antérieure à la date limite de départ à la retraite.
A10: 17.10.00 | B10: A | C10: 43152.5 | D10: D0007 | E10: Congés/Absence | F10: S0046 | G10: Autorisations d'absence | H10: E0428 | I10: Autorisations d'absences diverses | J10: Type de congé/absence saisi égal 'Autorisations d'absences diverses' | K10: A_COA_TYCOAB [Saisi] = 'CA009' | L10: T1089 | M10: Autorisations d'absences diverses | N10: Création Modification | Q10: Titulaire ou magistrat | R10: P0001 | S10: T | T10: Général | U10: Passant | V10: 40725 | X10: ABS_C_010 ET ABS_C_001 ET ABS_C_003 ET ABS_C_004 ET ABS_C_007 ET ABS_C_008 ET ABS_C_009 ET ABS_C_019 ET ABS_C_020 ET ABS_C_026 | BG10: ABS_C_010 | BH10: =VLOOKUP(BG10,'Axe 2 Règles de gestion'!$D$2:$F$354,3, FALSE) -> L'agent doit être en activité. | BI10: ABS_C_001 | BJ10: =VLOOKUP(BI10,'Axe 2 Règles de gestion'!$D$2:$F$354,3, FALSE) -> La date de début du congé/absence doit être postérieure ou égale à la date de recrutement dans la FPE ou dans la carrière militaire. | BK10: ABS_C_003 | BL10: =VLOOKUP(BK10,'Axe 2 Règles de gestion'!$D$2:$F$354,3, FALSE) -> La date de début du congé/absence doit être antérieure ou égale à la date de fin réelle du congé/absence. | BM10: ABS_C_004 | BN10: =VLOOKUP(BM10,'Axe 2 Règles de gestion'!$D$2:$F$354,3, FALSE) -> La date de début du congé/absence doit être antérieure ou égale à la date de fin prévisionnelle du congé/absence. | BO10: ABS_C_007 | BP10: =VLOOKUP(BO10,'Axe 2 Règles de gestion'!$D$2:$F$354,3, FALSE) -> La date de fin réelle du congé/absence doit être antérieure à la date limite de départ à la retraite. | BQ10: ABS_C_008 | BR10: =VLOOKUP(BQ10,'Axe 2 Règles de gestion'!$D$2:$F$354,3, FALSE) -> La date de fin prévisionnelle du congé/absence doit être antérieure à la date limite de départ à la retraite. | BS10: ABS_C_009 | BT10: =VLOOKUP(BS10,'Axe 2 Règles de gestion'!$D$2:$F$354,3, FALSE) -> La date de fin réelle ou la date de fin prévisionnelle du congé/absence doit être saisie. | BU10: ABS_C_019 | BV10: =VLOOKUP(BU10,'Axe 2 Règles de gestion'!$D$2:$F$354,3, FALSE) -> Si l'absence ne commence pas par une demi-journée et si l'absence précédente ne finit pas par une demi journée, la date de début de l'absence saisie est postérieure à la date de fin réelle de l'absence précédente. | BW10: ABS_C_020 | BX10: =VLOOKUP(BW10,'Axe 2 Règles de gestion'!$D$2:$F$354,3, FALSE) -> Si l'absence ne commence pas par une demi-journée et si l'absence précédente ne finit pas par une demi journée, la date de début de l'absence saisie est postérieure à la date de fin prévisionnelle de l'absence précédente. | BY10: ABS_C_026 | BZ10: =VLOOKUP(BY10,'Axe 2 Règles de gestion'!$D$2:$F$354,3, FALSE) -> Dans le cas d'un congé autre que CLM, CLD, CGM et CITIS, l'indicateur de requalification doit être à non et les impacts spécifiques à la requalification ne doivent pas être mobilisés ou l'impact rémunération est vide.
A11: 17.10.00 | B11: A | C11: 43152.5 | D11: D0007 | E11: Congés/Absence | F11: S0046 | G11: Autorisations d'absence | H11: E0428 | I11: Autorisations d'absences diverses | J11: Type de congé/absence saisi égal 'Autorisations d'absences diverses' | K11: A_COA_TYCOAB [Saisi] = 'CA009' | L11: T1089 | M11: Autorisations d'absences diverses | N11: Création Modification | Q11: Contractuel | R11: P0003 | S11: N | T11: Général | U11: Passant | V11: 40725 | X11: ABS_C_010 ET ABS_C_003 ET ABS_C_004 ET ABS_C_009 ET ABS_C_019 ET ABS_C_020 ET ABS_C_026 ET ABS_C_002 ET ABS_C_005 ET ABS_C_006 ET ABS_C_007 ET ABS_C_008 | BG11: ABS_C_010 | BH11: =VLOOKUP(BG11,'Axe 2 Règles de gestion'!$D$2:$F$354,3, FALSE) -> L'agent doit être en activité. | BI11: ABS_C_003 | BJ11: =VLOOKUP(BI11,'Axe 2 Règles de gestion'!$D$2:$F$354,3, FALSE) -> La date de début du congé/absence doit être antérieure ou égale à la date de fin réelle du congé/absence. | BK11: ABS_C_004 | BL11: =VLOOKUP(BK11,'Axe 2 Règles de gestion'!$D$2:$F$354,3, FALSE) -> La date de début du congé/absence doit être antérieure ou égale à la date de fin prévisionnelle du congé/absence. | BM11: ABS_C_009 | BN11: =VLOOKUP(BM11,'Axe 2 Règles de gestion'!$D$2:$F$354,3, FALSE) -> La date de fin réelle ou la date de fin prévisionnelle du congé/absence doit être saisie. | BO11: ABS_C_019 | BP11: =VLOOKUP(BO11,'Axe 2 Règles de gestion'!$D$2:$F$354,3, FALSE) -> Si l'absence ne commence pas par une demi-journée et si l'absence précédente ne finit pas par une demi journée, la date de début de l'absence saisie est postérieure à la date de fin réelle de l'absence précédente. | BQ11: ABS_C_020 | BR11: =VLOOKUP(BQ11,'Axe 2 Règles de gestion'!$D$2:$F$354,3, FALSE) -> Si l'absence ne commence pas par une demi-journée et si l'absence précédente ne finit pas par une demi journée, la date de début de l'absence saisie est postérieure à la date de fin prévisionnelle de l'absence précédente. | BS11: ABS_C_026 | BT11: =VLOOKUP(BS11,'Axe 2 Règles de gestion'!$D$2:$F$354,3, FALSE) -> Dans le cas d'un congé autre que CLM, CLD, CGM et CITIS, l'indicateur de requalification doit être à non et les impacts spécifiques à la requalification ne doivent pas être mobilisés ou l'impact rémunération est vide. | BU11: ABS_C_002 | BV11: =VLOOKUP(BU11,'Axe 2 Règles de gestion'!$D$2:$F$354,3, FALSE) -> La date de début du congé/absence doit être postérieure ou égale à la date de début du lien juridique. | BW11: ABS_C_005 | BX11: =VLOOKUP(BW11,'Axe 2 Règles de gestion'!$D$2:$F$354,3, FALSE) -> La date de fin réelle du congé/absence doit être antérieure ou égale à la date limite de fin réelle ou prévisionnelle du lien juridique. | BY11: ABS_C_006 | BZ11: =VLOOKUP(BY11,'Axe 2 Règles de gestion'!$D$2:$F$354,3, FALSE) -> La date de fin prévisionnelle du congé/absence doit être antérieure ou égale à la date limite de fin réelle ou prévisionnelle du lien juridique. | CA11: ABS_C_007 | CB11: =VLOOKUP(CA11,'Axe 2 Règles de gestion'!$D$2:$F$354,3, FALSE) -> La date de fin réelle du congé/absence doit être antérieure à la date limite de départ à la retraite. | CC11: ABS_C_008 | CD11: =VLOOKUP(CC11,'Axe 2 Règles de gestion'!$D$2:$F$354,3, FALSE) -> La date de fin prévisionnelle du congé/absence doit être antérieure à la date limite de départ à la retraite.
A12: 17.10.00 | B12: A | C12: 43152.5 | D12: D0007 | E12: Congés/Absence | F12: S0046 | G12: Autorisations d'absence | H12: E0428 | I12: Autorisations d'absences diverses | J12: Type de congé/absence saisi égal 'Autorisations d'absences diverses' | K12: A_COA_TYCOAB [Saisi] = 'CA009' | L12: T1089 | M12: Autorisations d'absences diverses | N12: Création Modification | Q12: Stagiaire ou auditeur ou élève | R12: P0004 | S12: S | T12: Général | U12: Passant | V12: 40725 | X12: ABS_C_010 ET ABS_C_001 ET ABS_C_003 ET ABS_C_004 ET ABS_C_007 ET ABS_C_008 ET ABS_C_009 ET ABS_C_019 ET ABS_C_020 ET ABS_C_026 | BG12: ABS_C_010 | BH12: =VLOOKUP(BG12,'Axe 2 Règles de gestion'!$D$2:$F$354,3, FALSE) -> L'agent doit être en activité. | BI12: ABS_C_001 | BJ12: =VLOOKUP(BI12,'Axe 2 Règles de gestion'!$D$2:$F$354,3, FALSE) -> La date de début du congé/absence doit être postérieure ou égale à la date de recrutement dans la FPE ou dans la carrière militaire. | BK12: ABS_C_003 | BL12: =VLOOKUP(BK12,'Axe 2 Règles de gestion'!$D$2:$F$354,3, FALSE) -> La date de début du congé/absence doit être antérieure ou égale à la date de fin réelle du congé/absence. | BM12: ABS_C_004 | BN12: =VLOOKUP(BM12,'Axe 2 Règles de gestion'!$D$2:$F$354,3, FALSE) -> La date de début du congé/absence doit être antérieure ou égale à la date de fin prévisionnelle du congé/absence. | BO12: ABS_C_007 | BP12: =VLOOKUP(BO12,'Axe 2 Règles de gestion'!$D$2:$F$354,3, FALSE) -> La date de fin réelle du congé/absence doit être antérieure à la date limite de départ à la retraite. | BQ12: ABS_C_008 | BR12: =VLOOKUP(BQ12,'Axe 2 Règles de gestion'!$D$2:$F$354,3, FALSE) -> La date de fin prévisionnelle du congé/absence doit être antérieure à la date limite de départ à la retraite. | BS12: ABS_C_009 | BT12: =VLOOKUP(BS12,'Axe 2 Règles de gestion'!$D$2:$F$354,3, FALSE) -> La date de fin réelle ou la date de fin prévisionnelle du congé/absence doit être saisie. | BU12: ABS_C_019 | BV12: =VLOOKUP(BU12,'Axe 2 Règles de gestion'!$D$2:$F$354,3, FALSE) -> Si l'absence ne commence pas par une demi-journée et si l'absence précédente ne finit pas par une demi journée, la date de début de l'absence saisie est postérieure à la date de fin réelle de l'absence précédente. | BW12: ABS_C_020 | BX12: =VLOOKUP(BW12,'Axe 2 Règles de gestion'!$D$2:$F$354,3, FALSE) -> Si l'absence ne commence pas par une demi-journée et si l'absence précédente ne finit pas par une demi journée, la date de début de l'absence saisie est postérieure à la date de fin prévisionnelle de l'absence précédente. | BY12: ABS_C_026 | BZ12: =VLOOKUP(BY12,'Axe 2 Règles de gestion'!$D$2:$F$354,3, FALSE) -> Dans le cas d'un congé autre que CLM, CLD, CGM et CITIS, l'indicateur de requalification doit être à non et les impacts spécifiques à la requalification ne doivent pas être mobilisés ou l'impact rémunération est vide.
A13: 17.10.00 | B13: A | C13: 43189.5 | D13: D0007 | E13: Congés/Absence | F13: S0046 | G13: Autorisations d'absence | H13: E0428 | I13: Autorisations d'absences diverses | J13: Type de congé/absence saisi égal 'Autorisations d'absences diverses' | K13: A_COA_TYCOAB [Saisi] = 'CA009' | L13: T1089 | M13: Autorisations d'absences diverses | N13: Création Modification | Q13: Ouvrier d'état | R13: P0005 | S13: O | T13: Général | U13: Passant | V13: 40725 | X13: ABS_C_010 ET ABS_C_003 ET ABS_C_004 ET ABS_C_009 ET ABS_C_019 ET ABS_C_020 ET ABS_C_026 ET ABS_C_002 ET ABS_C_005 ET ABS_C_006 ET ABS_C_007 ET ABS_C_008 | BG13: ABS_C_010 | BH13: =VLOOKUP(BG13,'Axe 2 Règles de gestion'!$D$2:$F$354,3, FALSE) -> L'agent doit être en activité. | BI13: ABS_C_003 | BJ13: =VLOOKUP(BI13,'Axe 2 Règles de gestion'!$D$2:$F$354,3, FALSE) -> La date de début du congé/absence doit être antérieure ou égale à la date de fin réelle du congé/absence. | BK13: ABS_C_004 | BL13: =VLOOKUP(BK13,'Axe 2 Règles de gestion'!$D$2:$F$354,3, FALSE) -> La date de début du congé/absence doit être antérieure ou égale à la date de fin prévisionnelle du congé/absence. | BM13: ABS_C_009 | BN13: =VLOOKUP(BM13,'Axe 2 Règles de gestion'!$D$2:$F$354,3, FALSE) -> La date de fin réelle ou la date de fin prévisionnelle du congé/absence doit être saisie. | BO13: ABS_C_019 | BP13: =VLOOKUP(BO13,'Axe 2 Règles de gestion'!$D$2:$F$354,3, FALSE) -> Si l'absence ne commence pas par une demi-journée et si l'absence précédente ne finit pas par une demi journée, la date de début de l'absence saisie est postérieure à la date de fin réelle de l'absence précédente. | BQ13: ABS_C_020 | BR13: =VLOOKUP(BQ13,'Axe 2 Règles de gestion'!$D$2:$F$354,3, FALSE) -> Si l'absence ne commence pas par une demi-journée et si l'absence précédente ne finit pas par une demi journée, la date de début de l'absence saisie est postérieure à la date de fin prévisionnelle de l'absence précédente. | BS13: ABS_C_026 | BT13: =VLOOKUP(BS13,'Axe 2 Règles de gestion'!$D$2:$F$354,3, FALSE) -> Dans le cas d'un congé autre que CLM, CLD, CGM et CITIS, l'indicateur de requalification doit être à non et les impacts spécifiques à la requalification ne doivent pas être mobilisés ou l'impact rémunération est vide. | BU13: ABS_C_002 | BV13: =VLOOKUP(BU13,'Axe 2 Règles de gestion'!$D$2:$F$354,3, FALSE) -> La date de début du congé/absence doit être postérieure ou égale à la date de début du lien juridique. | BW13: ABS_C_005 | BX13: =VLOOKUP(BW13,'Axe 2 Règles de gestion'!$D$2:$F$354,3, FALSE) -> La date de fin réelle du congé/absence doit être antérieure ou égale à la date limite de fin réelle ou prévisionnelle du lien juridique. | BY13: ABS_C_006 | BZ13: =VLOOKUP(BY13,'Axe 2 Règles de gestion'!$D$2:$F$354,3, FALSE) -> La date de fin prévisionnelle du congé/absence doit être antérieure ou égale à la date limite de fin réelle ou prévisionnelle du lien juridique. | CA13: ABS_C_007 | CB13: =VLOOKUP(CA13,'Axe 2 Règles de gestion'!$D$2:$F$354,3, FALSE) -> La date de fin réelle du congé/absence doit être antérieure à la date limite de départ à la retraite. | CC13: ABS_C_008 | CD13: =VLOOKUP(CC13,'Axe 2 Règles de gestion'!$D$2:$F$354,3, FALSE) -> La date de fin prévisionnelle du congé/absence doit être antérieure à la date limite de départ à la retraite.
A14: 17.10.00 | B14: A | C14: 43152.5 | D14: D0007 | E14: Congés/Absence | F14: S0046 | G14: Autorisations d'absence | H14: E0428 | I14: Autorisations d'absences diverses | J14: Type de congé/absence saisi égal 'Autorisations d'absences diverses' | K14: A_COA_TYCOAB [Saisi] = 'CA009' | L14: T1089 | M14: Autorisations d'absences diverses | N14: Création Modification | Q14: Personnel civil payé à l'acte ou à la tâche | R14: P0054 | S14: N | T14: Particulier | U14: Exclu | V14: 40725
A15: 17.10.00 | B15: A | C15: 43152.5 | D15: D0007 | E15: Congés/Absence | F15: S0046 | G15: Autorisations d'absence | H15: E0428 | I15: Autorisations d'absences diverses | J15: Type de congé/absence saisi égal 'Autorisations d'absences diverses' | K15: A_COA_TYCOAB [Saisi] = 'CA009' | L15: T1089 | M15: Autorisations d'absences diverses | N15: Création Modification | Q15: Volontaire de service civique outre-mer | R15: P0179 | S15: N | T15: Particulier | U15: Exclu | V15: 40725
A16: 22.10.00 | B16: M | C16: 44917.607 | D16: D0007 | E16: Congés/Absence | F16: S0046 | G16: Autorisations d'absence | H16: E0429 | I16: Autorisations d'absence avec rémunération pour mandat électif local | J16: Type de congé/absence saisi égal 'Autorisations d'absence avec rémunération pour mandat électif local' | K16: A_COA_TYCOAB [Saisi] = 'CA005' | L16: T1090 | M16: Autorisations d'absence avec rémunération pour mandat électif local | N16: Création Modification | Q16: Titulaire ou magistrat | R16: P0001 | S16: T | T16: Général | U16: Passant | V16: 40725 | W16: 43827 | X16: ABS_C_010 ET ABS_C_001 ET ABS_C_003 ET ABS_C_004 ET ABS_C_007 ET ABS_C_008 ET ABS_C_009 ET ABS_C_019 ET ABS_C_020 ET ABS_C_026 | BG16: ABS_C_010 | BH16: =VLOOKUP(BG16,'Axe 2 Règles de gestion'!$D$2:$F$354,3, FALSE) -> L'agent doit être en activité. | BI16: ABS_C_001 | BJ16: =VLOOKUP(BI16,'Axe 2 Règles de gestion'!$D$2:$F$354,3, FALSE) -> La date de début du congé/absence doit être postérieure ou égale à la date de recrutement dans la FPE ou dans la carrière militaire. | BK16: ABS_C_003 | BL16: =VLOOKUP(BK16,'Axe 2 Règles de gestion'!$D$2:$F$354,3, FALSE) -> La date de début du congé/absence doit être antérieure ou égale à la date de fin réelle du congé/absence. | BM16: ABS_C_004 | BN16: =VLOOKUP(BM16,'Axe 2 Règles de gestion'!$D$2:$F$354,3, FALSE) -> La date de début du congé/absence doit être antérieure ou égale à la date de fin prévisionnelle du congé/absence. | BO16: ABS_C_007 | BP16: =VLOOKUP(BO16,'Axe 2 Règles de gestion'!$D$2:$F$354,3, FALSE) -> La date de fin réelle du congé/absence doit être antérieure à la date limite de départ à la retraite. | BQ16: ABS_C_008 | BR16: =VLOOKUP(BQ16,'Axe 2 Règles de gestion'!$D$2:$F$354,3, FALSE) -> La date de fin prévisionnelle du congé/absence doit être antérieure à la date limite de départ à la retraite. | BS16: ABS_C_009 | BT16: =VLOOKUP(BS16,'Axe 2 Règles de gestion'!$D$2:$F$354,3, FALSE) -> La date de fin réelle ou la date de fin prévisionnelle du congé/absence doit être saisie. | BU16: ABS_C_019 | BV16: =VLOOKUP(BU16,'Axe 2 Règles de gestion'!$D$2:$F$354,3, FALSE) -> Si l'absence ne commence pas par une demi-journée et si l'absence précédente ne finit pas par une demi journée, la date de début de l'absence saisie est postérieure à la date de fin réelle de l'absence précédente. | BW16: ABS_C_020 | BX16: =VLOOKUP(BW16,'Axe 2 Règles de gestion'!$D$2:$F$354,3, FALSE) -> Si l'absence ne commence pas par une demi-journée et si l'absence précédente ne finit pas par une demi journée, la date de début de l'absence saisie est postérieure à la date de fin prévisionnelle de l'absence précédente. | BY16: ABS_C_026 | BZ16: =VLOOKUP(BY16,'Axe 2 Règles de gestion'!$D$2:$F$354,3, FALSE) -> Dans le cas d'un congé autre que CLM, CLD, CGM et CITIS, l'indicateur de requalification doit être à non et les impacts spécifiques à la requalification ne doivent pas être mobilisés ou l'impact rémunération est vide.
A17: 22.10.00 | B17: A | C17: 44917.607 | D17: D0007 | E17: Congés/Absence | F17: S0046 | G17: Autorisations d'absence | H17: E0429 | I17: Autorisations d'absence avec rémunération pour mandat électif local | J17: Type de congé/absence saisi égal 'Autorisations d'absence avec rémunération pour mandat électif local' | K17: A_COA_TYCOAB [Saisi] = 'CA005' | L17: T1090 | M17: Autorisations d'absence avec rémunération pour mandat électif local | N17: Création Modification | Q17: Titulaire ou magistrat | R17: P0001 | S17: T | T17: Général | U17: Passant | V17: 43828 | X17: ADI_I_116 ET ADI_I_117 ET ADI_I_118 ET ABS_C_010 ET ABS_C_001 ET ABS_C_003 ET ABS_C_004 ET ABS_C_007 ET ABS_C_008 ET ABS_C_009 ET ABS_C_019 ET ABS_C_020 ET ABS_C_026 | Y17: ADI_I_116 | Z17: =VLOOKUP(Y17,'Axe 2 Règles de gestion'!$D$2:$F$354,3, FALSE) -> L'agent doit être élu d'un conseil municipal, d'un conseil départemental ou d'un conseil régional. | AA17: ADI_I_117 | AB17: =VLOOKUP(AA17,'Axe 2 Règles de gestion'!$D$2:$F$354,3, FALSE) -> Des autorisations d'absence sont accordées à l'agent pour se rendre et participer aux séances plénières, aux réunions des commissions dont il est membre et aux réunions et assemblées des organismes où il représente la collectivité. | AC17: ADI_I_118 | AD17: =VLOOKUP(AC17,'Axe 2 Règles de gestion'!$D$2:$F$354,3, FALSE) -> L'agent doit informer l'administration de la date de la séance ou de la réunion dès qu'il en a connaissance. | BG17: ABS_C_010 | BH17: =VLOOKUP(BG17,'Axe 2 Règles de gestion'!$D$2:$F$354,3, FALSE) -> L'agent doit être en activité. | BI17: ABS_C_001 | BJ17: =VLOOKUP(BI17,'Axe 2 Règles de gestion'!$D$2:$F$354,3, FALSE) -> La date de début du congé/absence doit être postérieure ou égale à la date de recrutement dans la FPE ou dans la carrière militaire. | BK17: ABS_C_003 | BL17: =VLOOKUP(BK17,'Axe 2 Règles de gestion'!$D$2:$F$354,3, FALSE) -> La date de début du congé/absence doit être antérieure ou égale à la date de fin réelle du congé/absence. | BM17: ABS_C_004 | BN17: =VLOOKUP(BM17,'Axe 2 Règles de gestion'!$D$2:$F$354,3, FALSE) -> La date de début du congé/absence doit être antérieure ou égale à la date de fin prévisionnelle du congé/absence. | BO17: ABS_C_007 | BP17: =VLOOKUP(BO17,'Axe 2 Règles de gestion'!$D$2:$F$354,3, FALSE) -> La date de fin réelle du congé/absence doit être antérieure à la date limite de départ à la retraite. | BQ17: ABS_C_008 | BR17: =VLOOKUP(BQ17,'Axe 2 Règles de gestion'!$D$2:$F$354,3, FALSE) -> La date de fin prévisionnelle du congé/absence doit être antérieure à la date limite de départ à la retraite. | BS17: ABS_C_009 | BT17: =VLOOKUP(BS17,'Axe 2 Règles de gestion'!$D$2:$F$354,3, FALSE) -> La date de fin réelle ou la date de fin prévisionnelle du congé/absence doit être saisie. | BU17: ABS_C_019 | BV17: =VLOOKUP(BU17,'Axe 2 Règles de gestion'!$D$2:$F$354,3, FALSE) -> Si l'absence ne commence pas par une demi-journée et si l'absence précédente ne finit pas par une demi journée, la date de début de l'absence saisie est postérieure à la date de fin réelle de l'absence précédente. | BW17: ABS_C_020 | BX17: =VLOOKUP(BW17,'Axe 2 Règles de gestion'!$D$2:$F$354,3, FALSE) -> Si l'absence ne commence pas par une demi-journée et si l'absence précédente ne finit pas par une demi journée, la date de début de l'absence saisie est postérieure à la date de fin prévisionnelle de l'absence précédente. | BY17: ABS_C_026 | BZ17: =VLOOKUP(BY17,'Axe 2 Règles de gestion'!$D$2:$F$354,3, FALSE) -> Dans le cas d'un congé autre que CLM, CLD, CGM et CITIS, l'indicateur de requalification doit être à non et les impacts spécifiques à la requalification ne doivent pas être mobilisés ou l'impact rémunération est vide.
A18: 22.10.00 | B18: M | C18: 44917.603 | D18: D0007 | E18: Congés/Absence | F18: S0046 | G18: Autorisations d'absence | H18: E0429 | I18: Autorisations d'absence avec rémunération pour mandat électif local | J18: Type de congé/absence saisi égal 'Autorisations d'absence avec rémunération pour mandat électif local' | K18: A_COA_TYCOAB [Saisi] = 'CA005' | L18: T1090 | M18: Autorisations d'absence avec rémunération pour mandat électif local | N18: Création Modification | Q18: Contractuel | R18: P0003 | S18: N | T18: Général | U18: Passant | V18: 40725 | W18: 43827 | X18: ABS_C_010 ET ABS_C_003 ET ABS_C_004 ET ABS_C_009 ET ABS_C_019 ET ABS_C_020 ET ABS_C_026 ET ABS_C_002 ET ABS_C_005 ET ABS_C_006 ET ABS_C_007 ET ABS_C_008 | BG18: ABS_C_010 | BH18: =VLOOKUP(BG18,'Axe 2 Règles de gestion'!$D$2:$F$354,3, FALSE) -> L'agent doit être en activité. | BI18: ABS_C_003 | BJ18: =VLOOKUP(BI18,'Axe 2 Règles de gestion'!$D$2:$F$354,3, FALSE) -> La date de début du congé/absence doit être antérieure ou égale à la date de fin réelle du congé/absence. | BK18: ABS_C_004 | BL18: =VLOOKUP(BK18,'Axe 2 Règles de gestion'!$D$2:$F$354,3, FALSE) -> La date de début du congé/absence doit être antérieure ou égale à la date de fin prévisionnelle du congé/absence. | BM18: ABS_C_009 | BN18: =VLOOKUP(BM18,'Axe 2 Règles de gestion'!$D$2:$F$354,3, FALSE) -> La date de fin réelle ou la date de fin prévisionnelle du congé/absence doit être saisie. | BO18: ABS_C_019 | BP18: =VLOOKUP(BO18,'Axe 2 Règles de gestion'!$D$2:$F$354,3, FALSE) -> Si l'absence ne commence pas par une demi-journée et si l'absence précédente ne finit pas par une demi journée, la date de début de l'absence saisie est postérieure à la date de fin réelle de l'absence précédente. | BQ18: ABS_C_020 | BR18: =VLOOKUP(BQ18,'Axe 2 Règles de gestion'!$D$2:$F$354,3, FALSE) -> Si l'absence ne commence pas par une demi-journée et si l'absence précédente ne finit pas par une demi journée, la date de début de l'absence saisie est postérieure à la date de fin prévisionnelle de l'absence précédente. | BS18: ABS_C_026 | BT18: =VLOOKUP(BS18,'Axe 2 Règles de gestion'!$D$2:$F$354,3, FALSE) -> Dans le cas d'un congé autre que CLM, CLD, CGM et CITIS, l'indicateur de requalification doit être à non et les impacts spécifiques à la requalification ne doivent pas être mobilisés ou l'impact rémunération est vide. | BU18: ABS_C_002 | BV18: =VLOOKUP(BU18,'Axe 2 Règles de gestion'!$D$2:$F$354,3, FALSE) -> La date de début du congé/absence doit être postérieure ou égale à la date de début du lien juridique. | BW18: ABS_C_005 | BX18: =VLOOKUP(BW18,'Axe 2 Règles de gestion'!$D$2:$F$354,3, FALSE) -> La date de fin réelle du congé/absence doit être antérieure ou égale à la date limite de fin réelle ou prévisionnelle du lien juridique. | BY18: ABS_C_006 | BZ18: =VLOOKUP(BY18,'Axe 2 Règles de gestion'!$D$2:$F$354,3, FALSE) -> La date de fin prévisionnelle du congé/absence doit être antérieure ou égale à la date limite de fin réelle ou prévisionnelle du lien juridique. | CA18: ABS_C_007 | CB18: =VLOOKUP(CA18,'Axe 2 Règles de gestion'!$D$2:$F$354,3, FALSE) -> La date de fin réelle du congé/absence doit être antérieure à la date limite de départ à la retraite. | CC18: ABS_C_008 | CD18: =VLOOKUP(CC18,'Axe 2 Règles de gestion'!$D$2:$F$354,3, FALSE) -> La date de fin prévisionnelle du congé/absence doit être antérieure à la date limite de départ à la retraite.
A19: 22.10.00 | B19: A | C19: 44917.603 | D19: D0007 | E19: Congés/Absence | F19: S0046 | G19: Autorisations d'absence | H19: E0429 | I19: Autorisations d'absence avec rémunération pour mandat électif local | J19: Type de congé/absence saisi égal 'Autorisations d'absence avec rémunération pour mandat électif local' | K19: A_COA_TYCOAB [Saisi] = 'CA005' | L19: T1090 | M19: Autorisations d'absence avec rémunération pour mandat électif local | N19: Création Modification | Q19: Contractuel | R19: P0003 | S19: N | T19: Général | U19: Passant | V19: 43828 | X19: ADI_I_116 ET ADI_I_117 ET ADI_I_118 ET ABS_C_010 ET ABS_C_003 ET ABS_C_004 ET ABS_C_009 ET ABS_C_019 ET ABS_C_020 ET ABS_C_026 ET ABS_C_002 ET ABS_C_005 ET ABS_C_006 ET ABS_C_007 ET ABS_C_008 | Y19: ADI_I_116 | Z19: =VLOOKUP(Y19,'Axe 2 Règles de gestion'!$D$2:$F$354,3, FALSE) -> L'agent doit être élu d'un conseil municipal, d'un conseil départemental ou d'un conseil régional. | AA19: ADI_I_117 | AB19: =VLOOKUP(AA19,'Axe 2 Règles de gestion'!$D$2:$F$354,3, FALSE) -> Des autorisations d'absence sont accordées à l'agent pour se rendre et participer aux séances plénières, aux réunions des commissions dont il est membre et aux réunions et assemblées des organismes où il représente la collectivité. | AC19: ADI_I_118 | AD19: =VLOOKUP(AC19,'Axe 2 Règles de gestion'!$D$2:$F$354,3, FALSE) -> L'agent doit informer l'administration de la date de la séance ou de la réunion dès qu'il en a connaissance. | BG19: ABS_C_010 | BH19: =VLOOKUP(BG19,'Axe 2 Règles de gestion'!$D$2:$F$354,3, FALSE) -> L'agent doit être en activité. | BI19: ABS_C_003 | BJ19: =VLOOKUP(BI19,'Axe 2 Règles de gestion'!$D$2:$F$354,3, FALSE) -> La date de début du congé/absence doit être antérieure ou égale à la date de fin réelle du congé/absence. | BK19: ABS_C_004 | BL19: =VLOOKUP(BK19,'Axe 2 Règles de gestion'!$D$2:$F$354,3, FALSE) -> La date de début du congé/absence doit être antérieure ou égale à la date de fin prévisionnelle du congé/absence. | BM19: ABS_C_009 | BN19: =VLOOKUP(BM19,'Axe 2 Règles de gestion'!$D$2:$F$354,3, FALSE) -> La date de fin réelle ou la date de fin prévisionnelle du congé/absence doit être saisie. | BO19: ABS_C_019 | BP19: =VLOOKUP(BO19,'Axe 2 Règles de gestion'!$D$2:$F$354,3, FALSE) -> Si l'absence ne commence pas par une demi-journée et si l'absence précédente ne finit pas par une demi journée, la date de début de l'absence saisie est postérieure à la date de fin réelle de l'absence précédente. | BQ19: ABS_C_020 | BR19: =VLOOKUP(BQ19,'Axe 2 Règles de gestion'!$D$2:$F$354,3, FALSE) -> Si l'absence ne commence pas par une demi-journée et si l'absence précédente ne finit pas par une demi journée, la date de début de l'absence saisie est postérieure à la date de fin prévisionnelle de l'absence précédente. | BS19: ABS_C_026 | BT19: =VLOOKUP(BS19,'Axe 2 Règles de gestion'!$D$2:$F$354,3, FALSE) -> Dans le cas d'un congé autre que CLM, CLD, CGM et CITIS, l'indicateur de requalification doit être à non et les impacts spécifiques à la requalification ne doivent pas être mobilisés ou l'impact rémunération est vide. | BU19: ABS_C_002 | BV19: =VLOOKUP(BU19,'Axe 2 Règles de gestion'!$D$2:$F$354,3, FALSE) -> La date de début du congé/absence doit être postérieure ou égale à la date de début du lien juridique. | BW19: ABS_C_005 | BX19: =VLOOKUP(BW19,'Axe 2 Règles de gestion'!$D$2:$F$354,3, FALSE) -> La date de fin réelle du congé/absence doit être antérieure ou égale à la date limite de fin réelle ou prévisionnelle du lien juridique. | BY19: ABS_C_006 | BZ19: =VLOOKUP(BY19,'Axe 2 Règles de gestion'!$D$2:$F$354,3, FALSE) -> La date de fin prévisionnelle du congé/absence doit être antérieure ou égale à la date limite de fin réelle ou prévisionnelle du lien juridique. | CA19: ABS_C_007 | CB19: =VLOOKUP(CA19,'Axe 2 Règles de gestion'!$D$2:$F$354,3, FALSE) -> La date de fin réelle du congé/absence doit être antérieure à la date limite de départ à la retraite. | CC19: ABS_C_008 | CD19: =VLOOKUP(CC19,'Axe 2 Règles de gestion'!$D$2:$F$354,3, FALSE) -> La date de fin prévisionnelle du congé/absence doit être antérieure à la date limite de départ à la retraite.
A20: 22.10.00 | B20: M | C20: 44917.606 | D20: D0007 | E20: Congés/Absence | F20: S0046 | G20: Autorisations d'absence | H20: E0429 | I20: Autorisations d'absence avec rémunération pour mandat électif local | J20: Type de congé/absence saisi égal 'Autorisations d'absence avec rémunération pour mandat électif local' | K20: A_COA_TYCOAB [Saisi] = 'CA005' | L20: T1090 | M20: Autorisations d'absence avec rémunération pour mandat électif local | N20: Création Modification | Q20: Stagiaire ou auditeur ou élève | R20: P0004 | S20: S | T20: Général | U20: Passant | V20: 40725 | W20: 43827 | X20: ABS_C_010 ET ABS_C_001 ET ABS_C_003 ET ABS_C_004 ET ABS_C_007 ET ABS_C_008 ET ABS_C_009 ET ABS_C_019 ET ABS_C_020 ET ABS_C_026 | BG20: ABS_C_010 | BH20: =VLOOKUP(BG20,'Axe 2 Règles de gestion'!$D$2:$F$354,3, FALSE) -> L'agent doit être en activité. | BI20: ABS_C_001 | BJ20: =VLOOKUP(BI20,'Axe 2 Règles de gestion'!$D$2:$F$354,3, FALSE) -> La date de début du congé/absence doit être postérieure ou égale à la date de recrutement dans la FPE ou dans la carrière militaire. | BK20: ABS_C_003 | BL20: =VLOOKUP(BK20,'Axe 2 Règles de gestion'!$D$2:$F$354,3, FALSE) -> La date de début du congé/absence doit être antérieure ou égale à la date de fin réelle du congé/absence. | BM20: ABS_C_004 | BN20: =VLOOKUP(BM20,'Axe 2 Règles de gestion'!$D$2:$F$354,3, FALSE) -> La date de début du congé/absence doit être antérieure ou égale à la date de fin prévisionnelle du congé/absence. | BO20: ABS_C_007 | BP20: =VLOOKUP(BO20,'Axe 2 Règles de gestion'!$D$2:$F$354,3, FALSE) -> La date de fin réelle du congé/absence doit être antérieure à la date limite de départ à la retraite. | BQ20: ABS_C_008 | BR20: =VLOOKUP(BQ20,'Axe 2 Règles de gestion'!$D$2:$F$354,3, FALSE) -> La date de fin prévisionnelle du congé/absence doit être antérieure à la date limite de départ à la retraite. | BS20: ABS_C_009 | BT20: =VLOOKUP(BS20,'Axe 2 Règles de gestion'!$D$2:$F$354,3, FALSE) -> La date de fin réelle ou la date de fin prévisionnelle du congé/absence doit être saisie. | BU20: ABS_C_019 | BV20: =VLOOKUP(BU20,'Axe 2 Règles de gestion'!$D$2:$F$354,3, FALSE) -> Si l'absence ne commence pas par une demi-journée et si l'absence précédente ne finit pas par une demi journée, la date de début de l'absence saisie est postérieure à la date de fin réelle de l'absence précédente. | BW20: ABS_C_020 | BX20: =VLOOKUP(BW20,'Axe 2 Règles de gestion'!$D$2:$F$354,3, FALSE) -> Si l'absence ne commence pas par une demi-journée et si l'absence précédente ne finit pas par une demi journée, la date de début de l'absence saisie est postérieure à la date de fin prévisionnelle de l'absence précédente. | BY20: ABS_C_026 | BZ20: =VLOOKUP(BY20,'Axe 2 Règles de gestion'!$D$2:$F$354,3, FALSE) -> Dans le cas d'un congé autre que CLM, CLD, CGM et CITIS, l'indicateur de requalification doit être à non et les impacts spécifiques à la requalification ne doivent pas être mobilisés ou l'impact rémunération est vide.
A21: 22.10.00 | B21: A | C21: 44917.606 | D21: D0007 | E21: Congés/Absence | F21: S0046 | G21: Autorisations d'absence | H21: E0429 | I21: Autorisations d'absence avec rémunération pour mandat électif local | J21: Type de congé/absence saisi égal 'Autorisations d'absence avec rémunération pour mandat électif local' | K21: A_COA_TYCOAB [Saisi] = 'CA005' | L21: T1090 | M21: Autorisations d'absence avec rémunération pour mandat électif local | N21: Création Modification | Q21: Stagiaire ou auditeur ou élève | R21: P0004 | S21: S | T21: Général | U21: Passant | V21: 43828 | X21: ADI_I_116 ET ADI_I_117 ET ADI_I_118 ET ABS_C_010 ET ABS_C_001 ET ABS_C_003 ET ABS_C_004 ET ABS_C_007 ET ABS_C_008 ET ABS_C_009 ET ABS_C_019 ET ABS_C_020 ET ABS_C_026 | Y21: ADI_I_116 | Z21: =VLOOKUP(Y21,'Axe 2 Règles de gestion'!$D$2:$F$354,3, FALSE) -> L'agent doit être élu d'un conseil municipal, d'un conseil départemental ou d'un conseil régional. | AA21: ADI_I_117 | AB21: =VLOOKUP(AA21,'Axe 2 Règles de gestion'!$D$2:$F$354,3, FALSE) -> Des autorisations d'absence sont accordées à l'agent pour se rendre et participer aux séances plénières, aux réunions des commissions dont il est membre et aux réunions et assemblées des organismes où il représente la collectivité. | AC21: ADI_I_118 | AD21: =VLOOKUP(AC21,'Axe 2 Règles de gestion'!$D$2:$F$354,3, FALSE) -> L'agent doit informer l'administration de la date de la séance ou de la réunion dès qu'il en a connaissance. | BG21: ABS_C_010 | BH21: =VLOOKUP(BG21,'Axe 2 Règles de gestion'!$D$2:$F$354,3, FALSE) -> L'agent doit être en activité. | BI21: ABS_C_001 | BJ21: =VLOOKUP(BI21,'Axe 2 Règles de gestion'!$D$2:$F$354,3, FALSE) -> La date de début du congé/absence doit être postérieure ou égale à la date de recrutement dans la FPE ou dans la carrière militaire. | BK21: ABS_C_003 | BL21: =VLOOKUP(BK21,'Axe 2 Règles de gestion'!$D$2:$F$354,3, FALSE) -> La date de début du congé/absence doit être antérieure ou égale à la date de fin réelle du congé/absence. | BM21: ABS_C_004 | BN21: =VLOOKUP(BM21,'Axe 2 Règles de gestion'!$D$2:$F$354,3, FALSE) -> La date de début du congé/absence doit être antérieure ou égale à la date de fin prévisionnelle du congé/absence. | BO21: ABS_C_007 | BP21: =VLOOKUP(BO21,'Axe 2 Règles de gestion'!$D$2:$F$354,3, FALSE) -> La date de fin réelle du congé/absence doit être antérieure à la date limite de départ à la retraite. | BQ21: ABS_C_008 | BR21: =VLOOKUP(BQ21,'Axe 2 Règles de gestion'!$D$2:$F$354,3, FALSE) -> La date de fin prévisionnelle du congé/absence doit être antérieure à la date limite de départ à la retraite. | BS21: ABS_C_009 | BT21: =VLOOKUP(BS21,'Axe 2 Règles de gestion'!$D$2:$F$354,3, FALSE) -> La date de fin réelle ou la date de fin prévisionnelle du congé/absence doit être saisie. | BU21: ABS_C_019 | BV21: =VLOOKUP(BU21,'Axe 2 Règles de gestion'!$D$2:$F$354,3, FALSE) -> Si l'absence ne commence pas par une demi-journée et si l'absence précédente ne finit pas par une demi journée, la date de début de l'absence saisie est postérieure à la date de fin réelle de l'absence précédente. | BW21: ABS_C_020 | BX21: =VLOOKUP(BW21,'Axe 2 Règles de gestion'!$D$2:$F$354,3, FALSE) -> Si l'absence ne commence pas par une demi-journée et si l'absence précédente ne finit pas par une demi journée, la date de début de l'absence saisie est postérieure à la date de fin prévisionnelle de l'absence précédente. | BY21: ABS_C_026 | BZ21: =VLOOKUP(BY21,'Axe 2 Règles de gestion'!$D$2:$F$354,3, FALSE) -> Dans le cas d'un congé autre que CLM, CLD, CGM et CITIS, l'indicateur de requalification doit être à non et les impacts spécifiques à la requalification ne doivent pas être mobilisés ou l'impact rémunération est vide.
