Workbook
Name date_DIADC: 'Mode opératoire'!#REF!
Name notice_DIADC: 'Mode opératoire'!#REF!
Name notice_ENCHN: 'Mode opératoire'!$B$1:$B$4
Name notice_ICA: 'Mode opératoire'!#REF!

Sheet Mode opératoire
B1: MODE OPERATOIRE
B2: "La transaction s'effectue au niveau de la rubrique ""Congés/absences"", elle inclut l'ensemble des sous-rubriques listées ci-dessous : - Congés/absences - Complément pour congé / absence : impact rémunération - Compteurs des droits à congés - Compteurs de périodes de congés On notera que : La sous-rubrique ""Complément pour congé / absence : impact rémunération"" est réputée, suite au découpage des absences en tranche de rémunération, avoir des dates de début et de fin alignées sur les dates de début et de fin de la sous-rubrique ""Congés/absences"" (contrôle bloquant)"

Sheet Axe 1 Enchainement des RG
A1: Version | B1: Type de mise à jour | C1: Date de mise à jour | D1: Identifiant Domaine | E1: Libellé du Domaine | F1: Identifiant Sous-domaine | G1: Libellé du Sous-domaine | H1: Identifiant Evénement | I1: Libellé de l'évènement | J1: Libellé condition déclenchement Evènement | K1: Condition déclenchement Evènement | L1: Identifiant type d'évènement | M1: Libellé type d'évènement | N1: Type de mise à jour | O1: Libellé condition déclenchement Type Evènement | P1: Condition déclenchement Type Evènement | Q1: Libellé Population | R1: Codification Population | S1: Typologie de population | T1: Général / Particulier | U1: Passant / Exclu | V1: Date de début | W1: Date de fin | X1: Règles mobilisées | Y1: Identifiant Règle de contrôle intellectuel 1 | Z1: Libellé Règle de contrôle intellectuel 1 | AA1: Identifiant Règle de contrôle intellectuel 2 | AB1: Libellé Règle de contrôle intellectuel 2 | AC1: Identifiant Règle de contrôle intellectuel 3 | AD1: Libellé Règle de contrôle intellectuel 3 | AE1: Identifiant Règle de contrôle intellectuel 4 | AF1: Libellé Règle de contrôle intellectuel 4 | AG1: Identifiant Règle de contrôle intellectuel 5 | AH1: Libellé Règle de contrôle intellectuel 5 | AI1: Identifiant Règle de contrôle intellectuel 6 | AJ1: Libellé Règle de contrôle intellectuel 6 | AK1: Identifiant Règle de contrôle intellectuel 7 | AL1: Libellé Règle de contrôle intellectuel 7 | AM1: Identifiant Règle de contrôle intellectuel 8 | AN1: Libellé Règle de contrôle intellectuel 8 | AO1: Identifiant Règle de contrôle intellectuel 9 | AP1: Libellé Règle de contrôle intellectuel 9 | AQ1: Identifiant Règle de condition 1 | AR1: Libellé Règle de condition 1 | AS1: Identifiant Règle de condition 2 | AT1: Libellé Règle de condition 2 | AU1: Identifiant Règle de contrôle 1 | AV1: Libellé Règle de contrôle 1 | AW1: Identifiant Règle de contrôle 2 | AX1: Libellé Règle de contrôle 2 | AY1: Identifiant Règle de contrôle 3 | AZ1: Libellé Règle de contrôle 3 | BA1: Identifiant Règle de contrôle 4 | BB1: Libellé Règle de contrôle 4 | BC1: Identifiant Règle de contrôle 5 | BD1: Libellé Règle de contrôle 5 | BE1: Identifiant Règle de contrôle 6 | BF1: Libellé Règle de contrôle 6 | BG1: Identifiant Règle de contrôle 7 | BH1: Libellé Règle de contrôle 7 | BI1: Identifiant Règle de contrôle 8 | BJ1: Libellé Règle de contrôle 8 | BK1: Identifiant Règle de contrôle 9 | BL1: Libellé Règle de contrôle 9 | BM1: FIME | BN1: Statut de travail
A2: 26.00.00 | B2: M | C2: 46099.591 | D2: D0007 | E2: Congés/Absence | F2: S0196 | G2: Autorisations d'absence syndicales | H2: E0855 | I2: Autorisation d'absence pour crédit de temps syndical | J2: Type de congé/absence saisi égal 'Autorisation d'absence pour crédit de temps syndical' | K2: A_COA_TYCOAB [Saisi] = 'CA055' | L2: T2116 | M2: Autorisation d'absence pour crédit de temps syndical | N2: Création Modification | Q2: Titulaire ou magistrat | R2: P0001 | S2: T | T2: Général | U2: Passant | V2: 40725 | W2: 41427 | X2: AAS_D_210 ET AAS_D_213 ET ABS_C_010 ET ABS_C_001 ET ABS_C_003 ET ABS_C_004 ET ABS_C_007 ET ABS_C_008 ET ABS_C_009 ET ABS_C_019 ET ABS_C_020 | AQ2: AAS_D_210 | AR2: =VLOOKUP(AQ2,'Axe 2 Règles de gestion'!$D$2:$F$54,3, FALSE) -> La durée prévisionnelle de l'autorisation d'absence pour crédit de temps syndical est au minimum d'une demi-journée. | AS2: AAS_D_213 | AT2: =VLOOKUP(AS2,'Axe 2 Règles de gestion'!$D$2:$F$54,3, FALSE) -> La durée réelle de l'autorisation d'absence pour crédit de temps syndical est au minimum d'une demi-journée. | AU2: ABS_C_010 | AV2: =VLOOKUP(AU2,'Axe 2 Règles de gestion'!$D$2:$F$54,3, FALSE) -> L'agent doit être en activité. | AW2: ABS_C_001 | AX2: =VLOOKUP(AW2,'Axe 2 Règles de gestion'!$D$2:$F$54,3, FALSE) -> La date de début du congé/absence doit être postérieure ou égale à la date de recrutement dans la FPE ou dans la carrière militaire. | AY2: ABS_C_003 | AZ2: =VLOOKUP(AY2,'Axe 2 Règles de gestion'!$D$2:$F$54,3, FALSE) -> La date de début du congé/absence doit être antérieure ou égale à la date de fin réelle du congé/absence. | BA2: ABS_C_004 | BB2: =VLOOKUP(BA2,'Axe 2 Règles de gestion'!$D$2:$F$54,3, FALSE) -> La date de début du congé/absence doit être antérieure ou égale à la date de fin prévisionnelle du congé/absence. | BC2: ABS_C_007 | BD2: =VLOOKUP(BC2,'Axe 2 Règles de gestion'!$D$2:$F$54,3, FALSE) -> La date de fin réelle du congé/absence doit être antérieure à la date limite de départ à la retraite. | BE2: ABS_C_008 | BF2: =VLOOKUP(BE2,'Axe 2 Règles de gestion'!$D$2:$F$54,3, FALSE) -> La date de fin prévisionnelle du congé/absence doit être antérieure à la date limite de départ à la retraite. | BG2: ABS_C_009 | BH2: =VLOOKUP(BG2,'Axe 2 Règles de gestion'!$D$2:$F$54,3, FALSE) -> La date de fin réelle ou la date de fin prévisionnelle du congé/absence doit être saisie. | BI2: ABS_C_019 | BJ2: =VLOOKUP(BI2,'Axe 2 Règles de gestion'!$D$2:$F$54,3, FALSE) -> Si l'absence ne commence pas par une demi-journée et si l'absence précédente ne finit pas par une demi journée, la date de début de l'absence saisie est postérieure à la date de fin réelle de l'absence précédente. | BK2: ABS_C_020 | BL2: =VLOOKUP(BK2,'Axe 2 Règles de gestion'!$D$2:$F$54,3, FALSE) -> Si l'absence ne commence pas par une demi-journée et si l'absence précédente ne finit pas par une demi journée, la date de début de l'absence saisie est postérieure à la date de fin prévisionnelle de l'absence précédente. | BM2: 2026-25
A3: 26.00.00 | B3: M | C3: 46099.592 | D3: D0007 | E3: Congés/Absence | F3: S0196 | G3: Autorisations d'absence syndicales | H3: E0855 | I3: Autorisation d'absence pour crédit de temps syndical | J3: Type de congé/absence saisi égal 'Autorisation d'absence pour crédit de temps syndical' | K3: A_COA_TYCOAB [Saisi] = 'CA055' | L3: T2116 | M3: Autorisation d'absence pour crédit de temps syndical | N3: Création Modification | Q3: Titulaire ou magistrat | R3: P0001 | S3: T | T3: Général | U3: Passant | V3: 41428 | W3: 45688 | X3: AAS_D_210 ET AAS_D_213 ET ABS_C_010 ET ABS_C_001 ET ABS_C_003 ET ABS_C_004 ET ABS_C_007 ET ABS_C_008 ET ABS_C_009 ET ABS_C_019 ET ABS_C_020 | AQ3: AAS_D_210 | AR3: =VLOOKUP(AQ3,'Axe 2 Règles de gestion'!$D$2:$F$54,3, FALSE) -> La durée prévisionnelle de l'autorisation d'absence pour crédit de temps syndical est au minimum d'une demi-journée. | AS3: AAS_D_213 | AT3: =VLOOKUP(AS3,'Axe 2 Règles de gestion'!$D$2:$F$54,3, FALSE) -> La durée réelle de l'autorisation d'absence pour crédit de temps syndical est au minimum d'une demi-journée. | AU3: ABS_C_010 | AV3: =VLOOKUP(AU3,'Axe 2 Règles de gestion'!$D$2:$F$54,3, FALSE) -> L'agent doit être en activité. | AW3: ABS_C_001 | AX3: =VLOOKUP(AW3,'Axe 2 Règles de gestion'!$D$2:$F$54,3, FALSE) -> La date de début du congé/absence doit être postérieure ou égale à la date de recrutement dans la FPE ou dans la carrière militaire. | AY3: ABS_C_003 | AZ3: =VLOOKUP(AY3,'Axe 2 Règles de gestion'!$D$2:$F$54,3, FALSE) -> La date de début du congé/absence doit être antérieure ou égale à la date de fin réelle du congé/absence. | BA3: ABS_C_004 | BB3: =VLOOKUP(BA3,'Axe 2 Règles de gestion'!$D$2:$F$54,3, FALSE) -> La date de début du congé/absence doit être antérieure ou égale à la date de fin prévisionnelle du congé/absence. | BC3: ABS_C_007 | BD3: =VLOOKUP(BC3,'Axe 2 Règles de gestion'!$D$2:$F$54,3, FALSE) -> La date de fin réelle du congé/absence doit être antérieure à la date limite de départ à la retraite. | BE3: ABS_C_008 | BF3: =VLOOKUP(BE3,'Axe 2 Règles de gestion'!$D$2:$F$54,3, FALSE) -> La date de fin prévisionnelle du congé/absence doit être antérieure à la date limite de départ à la retraite. | BG3: ABS_C_009 | BH3: =VLOOKUP(BG3,'Axe 2 Règles de gestion'!$D$2:$F$54,3, FALSE) -> La date de fin réelle ou la date de fin prévisionnelle du congé/absence doit être saisie. | BI3: ABS_C_019 | BJ3: =VLOOKUP(BI3,'Axe 2 Règles de gestion'!$D$2:$F$54,3, FALSE) -> Si l'absence ne commence pas par une demi-journée et si l'absence précédente ne finit pas par une demi journée, la date de début de l'absence saisie est postérieure à la date de fin réelle de l'absence précédente. | BK3: ABS_C_020 | BL3: =VLOOKUP(BK3,'Axe 2 Règles de gestion'!$D$2:$F$54,3, FALSE) -> Si l'absence ne commence pas par une demi-journée et si l'absence précédente ne finit pas par une demi journée, la date de début de l'absence saisie est postérieure à la date de fin prévisionnelle de l'absence précédente. | BM3: 2026-25
A4: 26.00.00 | B4: M | C4: 46175.448 | D4: D0007 | E4: Congés/Absence | F4: S0196 | G4: Autorisations d'absence syndicales | H4: E0855 | I4: Autorisation d'absence pour crédit de temps syndical | J4: Type de congé/absence saisi égal 'Autorisation d'absence pour crédit de temps syndical' | K4: A_COA_TYCOAB [Saisi] = 'CA055' | L4: T2116 | M4: Autorisation d'absence pour crédit de temps syndical | N4: Création Modification | Q4: Titulaire ou magistrat | R4: P0001 | S4: T | T4: Général | U4: Passant | V4: 45689 | X4: AAS_I_013 ET AAS_I_014 ET AAS_D_210 ET AAS_D_213 ET ABS_C_010 ET ABS_C_001 ET ABS_C_003 ET ABS_C_004 ET ABS_C_007 ET ABS_C_008 ET ABS_C_009 ET ABS_C_019 ET ABS_C_020 | Y4: AAS_I_013 | Z4: =VLOOKUP(Y4,'Axe 2 Règles de gestion'!$D$2:$F$54,3, FALSE) -> L'agent doit être chargé d'une activité syndicale. | AA4: AAS_I_014 | AB4: =VLOOKUP(AA4,'Axe 2 Règles de gestion'!$D$2:$F$54,3, FALSE) -> L'agent, désigné comme bénéficiaire de crédits d'heures par une organisation syndicale, peut bénéficier de crédits d'heures pour remplir ses obligations syndicales. | AQ4: AAS_D_210 | AR4: =VLOOKUP(AQ4,'Axe 2 Règles de gestion'!$D$2:$F$54,3, FALSE) -> La durée prévisionnelle de l'autorisation d'absence pour crédit de temps syndical est au minimum d'une demi-journée. | AS4: AAS_D_213 | AT4: =VLOOKUP(AS4,'Axe 2 Règles de gestion'!$D$2:$F$54,3, FALSE) -> La durée réelle de l'autorisation d'absence pour crédit de temps syndical est au minimum d'une demi-journée. | AU4: ABS_C_010 | AV4: =VLOOKUP(AU4,'Axe 2 Règles de gestion'!$D$2:$F$54,3, FALSE) -> L'agent doit être en activité. | AW4: ABS_C_001 | AX4: =VLOOKUP(AW4,'Axe 2 Règles de gestion'!$D$2:$F$54,3, FALSE) -> La date de début du congé/absence doit être postérieure ou égale à la date de recrutement dans la FPE ou dans la carrière militaire. | AY4: ABS_C_003 | AZ4: =VLOOKUP(AY4,'Axe 2 Règles de gestion'!$D$2:$F$54,3, FALSE) -> La date de début du congé/absence doit être antérieure ou égale à la date de fin réelle du congé/absence. | BA4: ABS_C_004 | BB4: =VLOOKUP(BA4,'Axe 2 Règles de gestion'!$D$2:$F$54,3, FALSE) -> La date de début du congé/absence doit être antérieure ou égale à la date de fin prévisionnelle du congé/absence. | BC4: ABS_C_007 | BD4: =VLOOKUP(BC4,'Axe 2 Règles de gestion'!$D$2:$F$54,3, FALSE) -> La date de fin réelle du congé/absence doit être antérieure à la date limite de départ à la retraite. | BE4: ABS_C_008 | BF4: =VLOOKUP(BE4,'Axe 2 Règles de gestion'!$D$2:$F$54,3, FALSE) -> La date de fin prévisionnelle du congé/absence doit être antérieure à la date limite de départ à la retraite. | BG4: ABS_C_009 | BH4: =VLOOKUP(BG4,'Axe 2 Règles de gestion'!$D$2:$F$54,3, FALSE) -> La date de fin réelle ou la date de fin prévisionnelle du congé/absence doit être saisie. | BI4: ABS_C_019 | BJ4: =VLOOKUP(BI4,'Axe 2 Règles de gestion'!$D$2:$F$54,3, FALSE) -> Si l'absence ne commence pas par une demi-journée et si l'absence précédente ne finit pas par une demi journée, la date de début de l'absence saisie est postérieure à la date de fin réelle de l'absence précédente. | BK4: ABS_C_020 | BL4: =VLOOKUP(BK4,'Axe 2 Règles de gestion'!$D$2:$F$54,3, FALSE) -> Si l'absence ne commence pas par une demi-journée et si l'absence précédente ne finit pas par une demi journée, la date de début de l'absence saisie est postérieure à la date de fin prévisionnelle de l'absence précédente. | BM4: 2026-25
A5: 26.00.00 | B5: A | C5: 46099.595 | D5: D0007 | E5: Congés/Absence | F5: S0196 | G5: Autorisations d'absence syndicales | H5: E0855 | I5: Autorisation d'absence pour crédit de temps syndical | J5: Type de congé/absence saisi égal 'Autorisation d'absence pour crédit de temps syndical' | K5: A_COA_TYCOAB [Saisi] = 'CA055' | L5: T2116 | M5: Autorisation d'absence pour crédit de temps syndical | N5: Création Modification | Q5: Militaire | R5: P0002 | S5: M | T5: Général | U5: Exclu | V5: 45689 | BM5: 2026-25
A6: 26.00.00 | B6: M | C6: 46099.597 | D6: D0007 | E6: Congés/Absence | F6: S0196 | G6: Autorisations d'absence syndicales | H6: E0855 | I6: Autorisation d'absence pour crédit de temps syndical | J6: Type de congé/absence saisi égal 'Autorisation d'absence pour crédit de temps syndical' | K6: A_COA_TYCOAB [Saisi] = 'CA055' | L6: T2116 | M6: Autorisation d'absence pour crédit de temps syndical | N6: Création Modification | Q6: Contractuel | R6: P0003 | S6: N | T6: Général | U6: Passant | V6: 40725 | W6: 41427 | X6: AAS_D_210 ET AAS_D_213 ET ABS_C_010 ET ABS_C_001 ET ABS_C_003 ET ABS_C_004 ET ABS_C_007 ET ABS_C_008 ET ABS_C_009 ET ABS_C_019 ET ABS_C_020 | AQ6: AAS_D_210 | AR6: =VLOOKUP(AQ6,'Axe 2 Règles de gestion'!$D$2:$F$54,3, FALSE) -> La durée prévisionnelle de l'autorisation d'absence pour crédit de temps syndical est au minimum d'une demi-journée. | AS6: AAS_D_213 | AT6: =VLOOKUP(AS6,'Axe 2 Règles de gestion'!$D$2:$F$54,3, FALSE) -> La durée réelle de l'autorisation d'absence pour crédit de temps syndical est au minimum d'une demi-journée. | AU6: ABS_C_010 | AV6: =VLOOKUP(AU6,'Axe 2 Règles de gestion'!$D$2:$F$54,3, FALSE) -> L'agent doit être en activité. | AW6: ABS_C_001 | AX6: =VLOOKUP(AW6,'Axe 2 Règles de gestion'!$D$2:$F$54,3, FALSE) -> La date de début du congé/absence doit être postérieure ou égale à la date de recrutement dans la FPE ou dans la carrière militaire. | AY6: ABS_C_003 | AZ6: =VLOOKUP(AY6,'Axe 2 Règles de gestion'!$D$2:$F$54,3, FALSE) -> La date de début du congé/absence doit être antérieure ou égale à la date de fin réelle du congé/absence. | BA6: ABS_C_004 | BB6: =VLOOKUP(BA6,'Axe 2 Règles de gestion'!$D$2:$F$54,3, FALSE) -> La date de début du congé/absence doit être antérieure ou égale à la date de fin prévisionnelle du congé/absence. | BC6: ABS_C_007 | BD6: =VLOOKUP(BC6,'Axe 2 Règles de gestion'!$D$2:$F$54,3, FALSE) -> La date de fin réelle du congé/absence doit être antérieure à la date limite de départ à la retraite. | BE6: ABS_C_008 | BF6: =VLOOKUP(BE6,'Axe 2 Règles de gestion'!$D$2:$F$54,3, FALSE) -> La date de fin prévisionnelle du congé/absence doit être antérieure à la date limite de départ à la retraite. | BG6: ABS_C_009 | BH6: =VLOOKUP(BG6,'Axe 2 Règles de gestion'!$D$2:$F$54,3, FALSE) -> La date de fin réelle ou la date de fin prévisionnelle du congé/absence doit être saisie. | BI6: ABS_C_019 | BJ6: =VLOOKUP(BI6,'Axe 2 Règles de gestion'!$D$2:$F$54,3, FALSE) -> Si l'absence ne commence pas par une demi-journée et si l'absence précédente ne finit pas par une demi journée, la date de début de l'absence saisie est postérieure à la date de fin réelle de l'absence précédente. | BK6: ABS_C_020 | BL6: =VLOOKUP(BK6,'Axe 2 Règles de gestion'!$D$2:$F$54,3, FALSE) -> Si l'absence ne commence pas par une demi-journée et si l'absence précédente ne finit pas par une demi journée, la date de début de l'absence saisie est postérieure à la date de fin prévisionnelle de l'absence précédente. | BM6: 2026-25
A7: 26.00.00 | B7: M | C7: 46099.598 | D7: D0007 | E7: Congés/Absence | F7: S0196 | G7: Autorisations d'absence syndicales | H7: E0855 | I7: Autorisation d'absence pour crédit de temps syndical | J7: Type de congé/absence saisi égal 'Autorisation d'absence pour crédit de temps syndical' | K7: A_COA_TYCOAB [Saisi] = 'CA055' | L7: T2116 | M7: Autorisation d'absence pour crédit de temps syndical | N7: Création Modification | Q7: Contractuel | R7: P0003 | S7: N | T7: Général | U7: Passant | V7: 41428 | W7: 45688 | X7: AAS_D_210 ET AAS_D_213 ET ABS_C_010 ET ABS_C_001 ET ABS_C_003 ET ABS_C_004 ET ABS_C_007 ET ABS_C_008 ET ABS_C_009 ET ABS_C_019 ET ABS_C_020 | AQ7: AAS_D_210 | AR7: =VLOOKUP(AQ7,'Axe 2 Règles de gestion'!$D$2:$F$54,3, FALSE) -> La durée prévisionnelle de l'autorisation d'absence pour crédit de temps syndical est au minimum d'une demi-journée. | AS7: AAS_D_213 | AT7: =VLOOKUP(AS7,'Axe 2 Règles de gestion'!$D$2:$F$54,3, FALSE) -> La durée réelle de l'autorisation d'absence pour crédit de temps syndical est au minimum d'une demi-journée. | AU7: ABS_C_010 | AV7: =VLOOKUP(AU7,'Axe 2 Règles de gestion'!$D$2:$F$54,3, FALSE) -> L'agent doit être en activité. | AW7: ABS_C_001 | AX7: =VLOOKUP(AW7,'Axe 2 Règles de gestion'!$D$2:$F$54,3, FALSE) -> La date de début du congé/absence doit être postérieure ou égale à la date de recrutement dans la FPE ou dans la carrière militaire. | AY7: ABS_C_003 | AZ7: =VLOOKUP(AY7,'Axe 2 Règles de gestion'!$D$2:$F$54,3, FALSE) -> La date de début du congé/absence doit être antérieure ou égale à la date de fin réelle du congé/absence. | BA7: ABS_C_004 | BB7: =VLOOKUP(BA7,'Axe 2 Règles de gestion'!$D$2:$F$54,3, FALSE) -> La date de début du congé/absence doit être antérieure ou égale à la date de fin prévisionnelle du congé/absence. | BC7: ABS_C_007 | BD7: =VLOOKUP(BC7,'Axe 2 Règles de gestion'!$D$2:$F$54,3, FALSE) -> La date de fin réelle du congé/absence doit être antérieure à la date limite de départ à la retraite. | BE7: ABS_C_008 | BF7: =VLOOKUP(BE7,'Axe 2 Règles de gestion'!$D$2:$F$54,3, FALSE) -> La date de fin prévisionnelle du congé/absence doit être antérieure à la date limite de départ à la retraite. | BG7: ABS_C_009 | BH7: =VLOOKUP(BG7,'Axe 2 Règles de gestion'!$D$2:$F$54,3, FALSE) -> La date de fin réelle ou la date de fin prévisionnelle du congé/absence doit être saisie. | BI7: ABS_C_019 | BJ7: =VLOOKUP(BI7,'Axe 2 Règles de gestion'!$D$2:$F$54,3, FALSE) -> Si l'absence ne commence pas par une demi-journée et si l'absence précédente ne finit pas par une demi journée, la date de début de l'absence saisie est postérieure à la date de fin réelle de l'absence précédente. | BK7: ABS_C_020 | BL7: =VLOOKUP(BK7,'Axe 2 Règles de gestion'!$D$2:$F$54,3, FALSE) -> Si l'absence ne commence pas par une demi-journée et si l'absence précédente ne finit pas par une demi journée, la date de début de l'absence saisie est postérieure à la date de fin prévisionnelle de l'absence précédente. | BM7: 2026-25
A8: 26.00.00 | B8: M | C8: 46175.448 | D8: D0007 | E8: Congés/Absence | F8: S0196 | G8: Autorisations d'absence syndicales | H8: E0855 | I8: Autorisation d'absence pour crédit de temps syndical | J8: Type de congé/absence saisi égal 'Autorisation d'absence pour crédit de temps syndical' | K8: A_COA_TYCOAB [Saisi] = 'CA055' | L8: T2116 | M8: Autorisation d'absence pour crédit de temps syndical | N8: Création Modification | Q8: Contractuel | R8: P0003 | S8: N | T8: Général | U8: Passant | V8: 45689 | X8: AAS_I_013 ET AAS_I_014 ET AAS_D_210 ET AAS_D_213 ET ABS_C_010 ET ABS_C_001 ET ABS_C_003 ET ABS_C_004 ET ABS_C_007 ET ABS_C_008 ET ABS_C_009 ET ABS_C_019 ET ABS_C_020 | Y8: AAS_I_013 | Z8: =VLOOKUP(Y8,'Axe 2 Règles de gestion'!$D$2:$F$54,3, FALSE) -> L'agent doit être chargé d'une activité syndicale. | AA8: AAS_I_014 | AB8: =VLOOKUP(AA8,'Axe 2 Règles de gestion'!$D$2:$F$54,3, FALSE) -> L'agent, désigné comme bénéficiaire de crédits d'heures par une organisation syndicale, peut bénéficier de crédits d'heures pour remplir ses obligations syndicales. | AQ8: AAS_D_210 | AR8: =VLOOKUP(AQ8,'Axe 2 Règles de gestion'!$D$2:$F$54,3, FALSE) -> La durée prévisionnelle de l'autorisation d'absence pour crédit de temps syndical est au minimum d'une demi-journée. | AS8: AAS_D_213 | AT8: =VLOOKUP(AS8,'Axe 2 Règles de gestion'!$D$2:$F$54,3, FALSE) -> La durée réelle de l'autorisation d'absence pour crédit de temps syndical est au minimum d'une demi-journée. | AU8: ABS_C_010 | AV8: =VLOOKUP(AU8,'Axe 2 Règles de gestion'!$D$2:$F$54,3, FALSE) -> L'agent doit être en activité. | AW8: ABS_C_001 | AX8: =VLOOKUP(AW8,'Axe 2 Règles de gestion'!$D$2:$F$54,3, FALSE) -> La date de début du congé/absence doit être postérieure ou égale à la date de recrutement dans la FPE ou dans la carrière militaire. | AY8: ABS_C_003 | AZ8: =VLOOKUP(AY8,'Axe 2 Règles de gestion'!$D$2:$F$54,3, FALSE) -> La date de début du congé/absence doit être antérieure ou égale à la date de fin réelle du congé/absence. | BA8: ABS_C_004 | BB8: =VLOOKUP(BA8,'Axe 2 Règles de gestion'!$D$2:$F$54,3, FALSE) -> La date de début du congé/absence doit être antérieure ou égale à la date de fin prévisionnelle du congé/absence. | BC8: ABS_C_007 | BD8: =VLOOKUP(BC8,'Axe 2 Règles de gestion'!$D$2:$F$54,3, FALSE) -> La date de fin réelle du congé/absence doit être antérieure à la date limite de départ à la retraite. | BE8: ABS_C_008 | BF8: =VLOOKUP(BE8,'Axe 2 Règles de gestion'!$D$2:$F$54,3, FALSE) -> La date de fin prévisionnelle du congé/absence doit être antérieure à la date limite de départ à la retraite. | BG8: ABS_C_009 | BH8: =VLOOKUP(BG8,'Axe 2 Règles de gestion'!$D$2:$F$54,3, FALSE) -> La date de fin réelle ou la date de fin prévisionnelle du congé/absence doit être saisie. | BI8: ABS_C_019 | BJ8: =VLOOKUP(BI8,'Axe 2 Règles de gestion'!$D$2:$F$54,3, FALSE) -> Si l'absence ne commence pas par une demi-journée et si l'absence précédente ne finit pas par une demi journée, la date de début de l'absence saisie est postérieure à la date de fin réelle de l'absence précédente. | BK8: ABS_C_020 | BL8: =VLOOKUP(BK8,'Axe 2 Règles de gestion'!$D$2:$F$54,3, FALSE) -> Si l'absence ne commence pas par une demi-journée et si l'absence précédente ne finit pas par une demi journée, la date de début de l'absence saisie est postérieure à la date de fin prévisionnelle de l'absence précédente. | BM8: 2026-25
A9: 26.00.00 | B9: M | C9: 46099.599 | D9: D0007 | E9: Congés/Absence | F9: S0196 | G9: Autorisations d'absence syndicales | H9: E0855 | I9: Autorisation d'absence pour crédit de temps syndical | J9: Type de congé/absence saisi égal 'Autorisation d'absence pour crédit de temps syndical' | K9: A_COA_TYCOAB [Saisi] = 'CA055' | L9: T2116 | M9: Autorisation d'absence pour crédit de temps syndical | N9: Création Modification | Q9: Stagiaire ou auditeur ou élève | R9: P0004 | S9: S | T9: Général | U9: Passant | V9: 40725 | W9: 41427 | X9: AAS_D_210 ET AAS_D_213 ET ABS_C_010 ET ABS_C_001 ET ABS_C_003 ET ABS_C_004 ET ABS_C_007 ET ABS_C_008 ET ABS_C_009 ET ABS_C_019 ET ABS_C_020 | AQ9: AAS_D_210 | AR9: =VLOOKUP(AQ9,'Axe 2 Règles de gestion'!$D$2:$F$54,3, FALSE) -> La durée prévisionnelle de l'autorisation d'absence pour crédit de temps syndical est au minimum d'une demi-journée. | AS9: AAS_D_213 | AT9: =VLOOKUP(AS9,'Axe 2 Règles de gestion'!$D$2:$F$54,3, FALSE) -> La durée réelle de l'autorisation d'absence pour crédit de temps syndical est au minimum d'une demi-journée. | AU9: ABS_C_010 | AV9: =VLOOKUP(AU9,'Axe 2 Règles de gestion'!$D$2:$F$54,3, FALSE) -> L'agent doit être en activité. | AW9: ABS_C_001 | AX9: =VLOOKUP(AW9,'Axe 2 Règles de gestion'!$D$2:$F$54,3, FALSE) -> La date de début du congé/absence doit être postérieure ou égale à la date de recrutement dans la FPE ou dans la carrière militaire. | AY9: ABS_C_003 | AZ9: =VLOOKUP(AY9,'Axe 2 Règles de gestion'!$D$2:$F$54,3, FALSE) -> La date de début du congé/absence doit être antérieure ou égale à la date de fin réelle du congé/absence. | BA9: ABS_C_004 | BB9: =VLOOKUP(BA9,'Axe 2 Règles de gestion'!$D$2:$F$54,3, FALSE) -> La date de début du congé/absence doit être antérieure ou égale à la date de fin prévisionnelle du congé/absence. | BC9: ABS_C_007 | BD9: =VLOOKUP(BC9,'Axe 2 Règles de gestion'!$D$2:$F$54,3, FALSE) -> La date de fin réelle du congé/absence doit être antérieure à la date limite de départ à la retraite. | BE9: ABS_C_008 | BF9: =VLOOKUP(BE9,'Axe 2 Règles de gestion'!$D$2:$F$54,3, FALSE) -> La date de fin prévisionnelle du congé/absence doit être antérieure à la date limite de départ à la retraite. | BG9: ABS_C_009 | BH9: =VLOOKUP(BG9,'Axe 2 Règles de gestion'!$D$2:$F$54,3, FALSE) -> La date de fin réelle ou la date de fin prévisionnelle du congé/absence doit être saisie. | BI9: ABS_C_019 | BJ9: =VLOOKUP(BI9,'Axe 2 Règles de gestion'!$D$2:$F$54,3, FALSE) -> Si l'absence ne commence pas par une demi-journée et si l'absence précédente ne finit pas par une demi journée, la date de début de l'absence saisie est postérieure à la date de fin réelle de l'absence précédente. | BK9: ABS_C_020 | BL9: =VLOOKUP(BK9,'Axe 2 Règles de gestion'!$D$2:$F$54,3, FALSE) -> Si l'absence ne commence pas par une demi-journée et si l'absence précédente ne finit pas par une demi journée, la date de début de l'absence saisie est postérieure à la date de fin prévisionnelle de l'absence précédente. | BM9: 2026-25
A10: 26.00.00 | B10: M | C10: 46099.6 | D10: D0007 | E10: Congés/Absence | F10: S0196 | G10: Autorisations d'absence syndicales | H10: E0855 | I10: Autorisation d'absence pour crédit de temps syndical | J10: Type de congé/absence saisi égal 'Autorisation d'absence pour crédit de temps syndical' | K10: A_COA_TYCOAB [Saisi] = 'CA055' | L10: T2116 | M10: Autorisation d'absence pour crédit de temps syndical | N10: Création Modification | Q10: Stagiaire ou auditeur ou élève | R10: P0004 | S10: S | T10: Général | U10: Passant | V10: 41428 | W10: 45688 | X10: AAS_D_210 ET AAS_D_213 ET ABS_C_010 ET ABS_C_001 ET ABS_C_003 ET ABS_C_004 ET ABS_C_007 ET ABS_C_008 ET ABS_C_009 ET ABS_C_019 ET ABS_C_020 | AQ10: AAS_D_210 | AR10: =VLOOKUP(AQ10,'Axe 2 Règles de gestion'!$D$2:$F$54,3, FALSE) -> La durée prévisionnelle de l'autorisation d'absence pour crédit de temps syndical est au minimum d'une demi-journée. | AS10: AAS_D_213 | AT10: =VLOOKUP(AS10,'Axe 2 Règles de gestion'!$D$2:$F$54,3, FALSE) -> La durée réelle de l'autorisation d'absence pour crédit de temps syndical est au minimum d'une demi-journée. | AU10: ABS_C_010 | AV10: =VLOOKUP(AU10,'Axe 2 Règles de gestion'!$D$2:$F$54,3, FALSE) -> L'agent doit être en activité. | AW10: ABS_C_001 | AX10: =VLOOKUP(AW10,'Axe 2 Règles de gestion'!$D$2:$F$54,3, FALSE) -> La date de début du congé/absence doit être postérieure ou égale à la date de recrutement dans la FPE ou dans la carrière militaire. | AY10: ABS_C_003 | AZ10: =VLOOKUP(AY10,'Axe 2 Règles de gestion'!$D$2:$F$54,3, FALSE) -> La date de début du congé/absence doit être antérieure ou égale à la date de fin réelle du congé/absence. | BA10: ABS_C_004 | BB10: =VLOOKUP(BA10,'Axe 2 Règles de gestion'!$D$2:$F$54,3, FALSE) -> La date de début du congé/absence doit être antérieure ou égale à la date de fin prévisionnelle du congé/absence. | BC10: ABS_C_007 | BD10: =VLOOKUP(BC10,'Axe 2 Règles de gestion'!$D$2:$F$54,3, FALSE) -> La date de fin réelle du congé/absence doit être antérieure à la date limite de départ à la retraite. | BE10: ABS_C_008 | BF10: =VLOOKUP(BE10,'Axe 2 Règles de gestion'!$D$2:$F$54,3, FALSE) -> La date de fin prévisionnelle du congé/absence doit être antérieure à la date limite de départ à la retraite. | BG10: ABS_C_009 | BH10: =VLOOKUP(BG10,'Axe 2 Règles de gestion'!$D$2:$F$54,3, FALSE) -> La date de fin réelle ou la date de fin prévisionnelle du congé/absence doit être saisie. | BI10: ABS_C_019 | BJ10: =VLOOKUP(BI10,'Axe 2 Règles de gestion'!$D$2:$F$54,3, FALSE) -> Si l'absence ne commence pas par une demi-journée et si l'absence précédente ne finit pas par une demi journée, la date de début de l'absence saisie est postérieure à la date de fin réelle de l'absence précédente. | BK10: ABS_C_020 | BL10: =VLOOKUP(BK10,'Axe 2 Règles de gestion'!$D$2:$F$54,3, FALSE) -> Si l'absence ne commence pas par une demi-journée et si l'absence précédente ne finit pas par une demi journée, la date de début de l'absence saisie est postérieure à la date de fin prévisionnelle de l'absence précédente. | BM10: 2026-25
A11: 26.00.00 | B11: M | C11: 46175.448 | D11: D0007 | E11: Congés/Absence | F11: S0196 | G11: Autorisations d'absence syndicales | H11: E0855 | I11: Autorisation d'absence pour crédit de temps syndical | J11: Type de congé/absence saisi égal 'Autorisation d'absence pour crédit de temps syndical' | K11: A_COA_TYCOAB [Saisi] = 'CA055' | L11: T2116 | M11: Autorisation d'absence pour crédit de temps syndical | N11: Création Modification | Q11: Stagiaire ou auditeur ou élève | R11: P0004 | S11: S | T11: Général | U11: Passant | V11: 45689 | X11: AAS_I_012 ET AAS_I_013 ET AAS_I_014 ET AAS_D_210 ET AAS_D_213 ET ABS_C_010 ET ABS_C_001 ET ABS_C_003 ET ABS_C_004 ET ABS_C_007 ET ABS_C_008 ET ABS_C_009 ET ABS_C_019 ET ABS_C_020 | Y11: AAS_I_012 | Z11: =VLOOKUP(Y11,'Axe 2 Règles de gestion'!$D$2:$F$54,3, FALSE) -> L'agent bénéficie des dispositions applicables aux agents titulaires pour les autorisations d'absence syndicales. | AA11: AAS_I_013 | AB11: =VLOOKUP(AA11,'Axe 2 Règles de gestion'!$D$2:$F$54,3, FALSE) -> L'agent doit être chargé d'une activité syndicale. | AC11: AAS_I_014 | AD11: =VLOOKUP(AC11,'Axe 2 Règles de gestion'!$D$2:$F$54,3, FALSE) -> L'agent, désigné comme bénéficiaire de crédits d'heures par une organisation syndicale, peut bénéficier de crédits d'heures pour remplir ses obligations syndicales. | AQ11: AAS_D_210 | AR11: =VLOOKUP(AQ11,'Axe 2 Règles de gestion'!$D$2:$F$54,3, FALSE) -> La durée prévisionnelle de l'autorisation d'absence pour crédit de temps syndical est au minimum d'une demi-journée. | AS11: AAS_D_213 | AT11: =VLOOKUP(AS11,'Axe 2 Règles de gestion'!$D$2:$F$54,3, FALSE) -> La durée réelle de l'autorisation d'absence pour crédit de temps syndical est au minimum d'une demi-journée. | AU11: ABS_C_010 | AV11: =VLOOKUP(AU11,'Axe 2 Règles de gestion'!$D$2:$F$54,3, FALSE) -> L'agent doit être en activité. | AW11: ABS_C_001 | AX11: =VLOOKUP(AW11,'Axe 2 Règles de gestion'!$D$2:$F$54,3, FALSE) -> La date de début du congé/absence doit être postérieure ou égale à la date de recrutement dans la FPE ou dans la carrière militaire. | AY11: ABS_C_003 | AZ11: =VLOOKUP(AY11,'Axe 2 Règles de gestion'!$D$2:$F$54,3, FALSE) -> La date de début du congé/absence doit être antérieure ou égale à la date de fin réelle du congé/absence. | BA11: ABS_C_004 | BB11: =VLOOKUP(BA11,'Axe 2 Règles de gestion'!$D$2:$F$54,3, FALSE) -> La date de début du congé/absence doit être antérieure ou égale à la date de fin prévisionnelle du congé/absence. | BC11: ABS_C_007 | BD11: =VLOOKUP(BC11,'Axe 2 Règles de gestion'!$D$2:$F$54,3, FALSE) -> La date de fin réelle du congé/absence doit être antérieure à la date limite de départ à la retraite. | BE11: ABS_C_008 | BF11: =VLOOKUP(BE11,'Axe 2 Règles de gestion'!$D$2:$F$54,3, FALSE) -> La date de fin prévisionnelle du congé/absence doit être antérieure à la date limite de départ à la retraite. | BG11: ABS_C_009 | BH11: =VLOOKUP(BG11,'Axe 2 Règles de gestion'!$D$2:$F$54,3, FALSE) -> La date de fin réelle ou la date de fin prévisionnelle du congé/absence doit être saisie. | BI11: ABS_C_019 | BJ11: =VLOOKUP(BI11,'Axe 2 Règles de gestion'!$D$2:$F$54,3, FALSE) -> Si l'absence ne commence pas par une demi-journée et si l'absence précédente ne finit pas par une demi journée, la date de début de l'absence saisie est postérieure à la date de fin réelle de l'absence précédente. | BK11: ABS_C_020 | BL11: =VLOOKUP(BK11,'Axe 2 Règles de gestion'!$D$2:$F$54,3, FALSE) -> Si l'absence ne commence pas par une demi-journée et si l'absence précédente ne finit pas par une demi journée, la date de début de l'absence saisie est postérieure à la date de fin prévisionnelle de l'absence précédente. | BM11: 2026-25
A12: 26.00.00 | B12: M | C12: 46099.602 | D12: D0007 | E12: Congés/Absence | F12: S0196 | G12: Autorisations d'absence syndicales | H12: E0855 | I12: Autorisation d'absence pour crédit de temps syndical | J12: Type de congé/absence saisi égal 'Autorisation d'absence pour crédit de temps syndical' | K12: A_COA_TYCOAB [Saisi] = 'CA055' | L12: T2116 | M12: Autorisation d'absence pour crédit de temps syndical | N12: Création Modification | Q12: Ouvrier d'état | R12: P0005 | S12: O | T12: Général | U12: Passant | V12: 40725 | W12: 41427 | X12: AAS_D_210 ET AAS_D_213 ET ABS_C_010 ET ABS_C_001 ET ABS_C_003 ET ABS_C_004 ET ABS_C_007 ET ABS_C_008 ET ABS_C_009 ET ABS_C_019 ET ABS_C_020 | AQ12: AAS_D_210 | AR12: =VLOOKUP(AQ12,'Axe 2 Règles de gestion'!$D$2:$F$54,3, FALSE) -> La durée prévisionnelle de l'autorisation d'absence pour crédit de temps syndical est au minimum d'une demi-journée. | AS12: AAS_D_213 | AT12: =VLOOKUP(AS12,'Axe 2 Règles de gestion'!$D$2:$F$54,3, FALSE) -> La durée réelle de l'autorisation d'absence pour crédit de temps syndical est au minimum d'une demi-journée. | AU12: ABS_C_010 | AV12: =VLOOKUP(AU12,'Axe 2 Règles de gestion'!$D$2:$F$54,3, FALSE) -> L'agent doit être en activité. | AW12: ABS_C_001 | AX12: =VLOOKUP(AW12,'Axe 2 Règles de gestion'!$D$2:$F$54,3, FALSE) -> La date de début du congé/absence doit être postérieure ou égale à la date de recrutement dans la FPE ou dans la carrière militaire. | AY12: ABS_C_003 | AZ12: =VLOOKUP(AY12,'Axe 2 Règles de gestion'!$D$2:$F$54,3, FALSE) -> La date de début du congé/absence doit être antérieure ou égale à la date de fin réelle du congé/absence. | BA12: ABS_C_004 | BB12: =VLOOKUP(BA12,'Axe 2 Règles de gestion'!$D$2:$F$54,3, FALSE) -> La date de début du congé/absence doit être antérieure ou égale à la date de fin prévisionnelle du congé/absence. | BC12: ABS_C_007 | BD12: =VLOOKUP(BC12,'Axe 2 Règles de gestion'!$D$2:$F$54,3, FALSE) -> La date de fin réelle du congé/absence doit être antérieure à la date limite de départ à la retraite. | BE12: ABS_C_008 | BF12: =VLOOKUP(BE12,'Axe 2 Règles de gestion'!$D$2:$F$54,3, FALSE) -> La date de fin prévisionnelle du congé/absence doit être antérieure à la date limite de départ à la retraite. | BG12: ABS_C_009 | BH12: =VLOOKUP(BG12,'Axe 2 Règles de gestion'!$D$2:$F$54,3, FALSE) -> La date de fin réelle ou la date de fin prévisionnelle du congé/absence doit être saisie. | BI12: ABS_C_019 | BJ12: =VLOOKUP(BI12,'Axe 2 Règles de gestion'!$D$2:$F$54,3, FALSE) -> Si l'absence ne commence pas par une demi-journée et si l'absence précédente ne finit pas par une demi journée, la date de début de l'absence saisie est postérieure à la date de fin réelle de l'absence précédente. | BK12: ABS_C_020 | BL12: =VLOOKUP(BK12,'Axe 2 Règles de gestion'!$D$2:$F$54,3, FALSE) -> Si l'absence ne commence pas par une demi-journée et si l'absence précédente ne finit pas par une demi journée, la date de début de l'absence saisie est postérieure à la date de fin prévisionnelle de l'absence précédente. | BM12: 2026-25
A13: 26.00.00 | B13: M | C13: 46099.602 | D13: D0007 | E13: Congés/Absence | F13: S0196 | G13: Autorisations d'absence syndicales | H13: E0855 | I13: Autorisation d'absence pour crédit de temps syndical | J13: Type de congé/absence saisi égal 'Autorisation d'absence pour crédit de temps syndical' | K13: A_COA_TYCOAB [Saisi] = 'CA055' | L13: T2116 | M13: Autorisation d'absence pour crédit de temps syndical | N13: Création Modification | Q13: Ouvrier d'état | R13: P0005 | S13: O | T13: Général | U13: Passant | V13: 41428 | W13: 45688 | X13: AAS_D_210 ET AAS_D_213 ET ABS_C_010 ET ABS_C_001 ET ABS_C_003 ET ABS_C_004 ET ABS_C_007 ET ABS_C_008 ET ABS_C_009 ET ABS_C_019 ET ABS_C_020 | AQ13: AAS_D_210 | AR13: =VLOOKUP(AQ13,'Axe 2 Règles de gestion'!$D$2:$F$54,3, FALSE) -> La durée prévisionnelle de l'autorisation d'absence pour crédit de temps syndical est au minimum d'une demi-journée. | AS13: AAS_D_213 | AT13: =VLOOKUP(AS13,'Axe 2 Règles de gestion'!$D$2:$F$54,3, FALSE) -> La durée réelle de l'autorisation d'absence pour crédit de temps syndical est au minimum d'une demi-journée. | AU13: ABS_C_010 | AV13: =VLOOKUP(AU13,'Axe 2 Règles de gestion'!$D$2:$F$54,3, FALSE) -> L'agent doit être en activité. | AW13: ABS_C_001 | AX13: =VLOOKUP(AW13,'Axe 2 Règles de gestion'!$D$2:$F$54,3, FALSE) -> La date de début du congé/absence doit être postérieure ou égale à la date de recrutement dans la FPE ou dans la carrière militaire. | AY13: ABS_C_003 | AZ13: =VLOOKUP(AY13,'Axe 2 Règles de gestion'!$D$2:$F$54,3, FALSE) -> La date de début du congé/absence doit être antérieure ou égale à la date de fin réelle du congé/absence. | BA13: ABS_C_004 | BB13: =VLOOKUP(BA13,'Axe 2 Règles de gestion'!$D$2:$F$54,3, FALSE) -> La date de début du congé/absence doit être antérieure ou égale à la date de fin prévisionnelle du congé/absence. | BC13: ABS_C_007 | BD13: =VLOOKUP(BC13,'Axe 2 Règles de gestion'!$D$2:$F$54,3, FALSE) -> La date de fin réelle du congé/absence doit être antérieure à la date limite de départ à la retraite. | BE13: ABS_C_008 | BF13: =VLOOKUP(BE13,'Axe 2 Règles de gestion'!$D$2:$F$54,3, FALSE) -> La date de fin prévisionnelle du congé/absence doit être antérieure à la date limite de départ à la retraite. | BG13: ABS_C_009 | BH13: =VLOOKUP(BG13,'Axe 2 Règles de gestion'!$D$2:$F$54,3, FALSE) -> La date de fin réelle ou la date de fin prévisionnelle du congé/absence doit être saisie. | BI13: ABS_C_019 | BJ13: =VLOOKUP(BI13,'Axe 2 Règles de gestion'!$D$2:$F$54,3, FALSE) -> Si l'absence ne commence pas par une demi-journée et si l'absence précédente ne finit pas par une demi journée, la date de début de l'absence saisie est postérieure à la date de fin réelle de l'absence précédente. | BK13: ABS_C_020 | BL13: =VLOOKUP(BK13,'Axe 2 Règles de gestion'!$D$2:$F$54,3, FALSE) -> Si l'absence ne commence pas par une demi-journée et si l'absence précédente ne finit pas par une demi journée, la date de début de l'absence saisie est postérieure à la date de fin prévisionnelle de l'absence précédente. | BM13: 2026-25
A14: 25.10.00 | B14: A | C14: 46006.653 | D14: D0007 | E14: Congés/Absence | F14: S0196 | G14: Autorisations d'absence syndicales | H14: E0855 | I14: Autorisation d'absence pour crédit de temps syndical | J14: Type de congé/absence saisi égal 'Autorisation d'absence pour crédit de temps syndical' | K14: A_COA_TYCOAB [Saisi] = 'CA055' | L14: T2116 | M14: Autorisation d'absence pour crédit de temps syndical | N14: Création Modification | Q14: Ouvrier d'état | R14: P0005 | S14: O | T14: Général | U14: Exclu | V14: 45689
A15: 26.00.00 | B15: M | C15: 46099.61 | D15: D0007 | E15: Congés/Absence | F15: S0196 | G15: Autorisations d'absence syndicales | H15: E0855 | I15: Autorisation d'absence pour crédit de temps syndical | J15: Type de congé/absence saisi égal 'Autorisation d'absence pour crédit de temps syndical' | K15: A_COA_TYCOAB [Saisi] = 'CA055' | L15: T2116 | M15: Autorisation d'absence pour crédit de temps syndical | N15: Création Modification | Q15: Magistrat de l'ordre judiciaire | R15: P0007 | S15: T | T15: Particulier | U15: Passant | V15: 40725 | W15: 41427 | X15: AAS_D_211 ET AAS_D_214 ET ABS_C_010 ET ABS_C_001 ET ABS_C_003 ET ABS_C_004 ET ABS_C_007 ET ABS_C_008 ET ABS_C_009 ET ABS_C_019 ET ABS_C_020 | AQ15: AAS_D_211 | AR15: =VLOOKUP(AQ15,'Axe 2 Règles de gestion'!$D$2:$F$54,3, FALSE) -> La durée prévisionnelle de l'autorisation d'absence pour crédit de temps syndical est au minimum d'une demi-journée. | AS15: AAS_D_214 | AT15: =VLOOKUP(AS15,'Axe 2 Règles de gestion'!$D$2:$F$54,3, FALSE) -> La durée réelle de l'autorisation d'absence pour crédit de temps syndical est au minimum d'une demi-journée. | AU15: ABS_C_010 | AV15: =VLOOKUP(AU15,'Axe 2 Règles de gestion'!$D$2:$F$54,3, FALSE) -> L'agent doit être en activité. | AW15: ABS_C_001 | AX15: =VLOOKUP(AW15,'Axe 2 Règles de gestion'!$D$2:$F$54,3, FALSE) -> La date de début du congé/absence doit être postérieure ou égale à la date de recrutement dans la FPE ou dans la carrière militaire. | AY15: ABS_C_003 | AZ15: =VLOOKUP(AY15,'Axe 2 Règles de gestion'!$D$2:$F$54,3, FALSE) -> La date de début du congé/absence doit être antérieure ou égale à la date de fin réelle du congé/absence. | BA15: ABS_C_004 | BB15: =VLOOKUP(BA15,'Axe 2 Règles de gestion'!$D$2:$F$54,3, FALSE) -> La date de début du congé/absence doit être antérieure ou égale à la date de fin prévisionnelle du congé/absence. | BC15: ABS_C_007 | BD15: =VLOOKUP(BC15,'Axe 2 Règles de gestion'!$D$2:$F$54,3, FALSE) -> La date de fin réelle du congé/absence doit être antérieure à la date limite de départ à la retraite. | BE15: ABS_C_008 | BF15: =VLOOKUP(BE15,'Axe 2 Règles de gestion'!$D$2:$F$54,3, FALSE) -> La date de fin prévisionnelle du congé/absence doit être antérieure à la date limite de départ à la retraite. | BG15: ABS_C_009 | BH15: =VLOOKUP(BG15,'Axe 2 Règles de gestion'!$D$2:$F$54,3, FALSE) -> La date de fin réelle ou la date de fin prévisionnelle du congé/absence doit être saisie. | BI15: ABS_C_019 | BJ15: =VLOOKUP(BI15,'Axe 2 Règles de gestion'!$D$2:$F$54,3, FALSE) -> Si l'absence ne commence pas par une demi-journée et si l'absence précédente ne finit pas par une demi journée, la date de début de l'absence saisie est postérieure à la date de fin réelle de l'absence précédente. | BK15: ABS_C_020 | BL15: =VLOOKUP(BK15,'Axe 2 Règles de gestion'!$D$2:$F$54,3, FALSE) -> Si l'absence ne commence pas par une demi-journée et si l'absence précédente ne finit pas par une demi journée, la date de début de l'absence saisie est postérieure à la date de fin prévisionnelle de l'absence précédente. | BM15: 2026-25
A16: 26.00.00 | B16: M | C16: 46099.617 | D16: D0007 | E16: Congés/Absence | F16: S0196 | G16: Autorisations d'absence syndicales | H16: E0855 | I16: Autorisation d'absence pour crédit de temps syndical | J16: Type de congé/absence saisi égal 'Autorisation d'absence pour crédit de temps syndical' | K16: A_COA_TYCOAB [Saisi] = 'CA055' | L16: T2116 | M16: Autorisation d'absence pour crédit de temps syndical | N16: Création Modification | Q16: Magistrat de l'ordre judiciaire | R16: P0007 | S16: T | T16: Particulier | U16: Passant | V16: 41428 | W16: 45688 | X16: AAS_D_210 ET AAS_D_213 ET ABS_C_010 ET ABS_C_001 ET ABS_C_003 ET ABS_C_004 ET ABS_C_007 ET ABS_C_008 ET ABS_C_009 ET ABS_C_019 ET ABS_C_020 | AQ16: AAS_D_210 | AR16: =VLOOKUP(AQ16,'Axe 2 Règles de gestion'!$D$2:$F$54,3, FALSE) -> La durée prévisionnelle de l'autorisation d'absence pour crédit de temps syndical est au minimum d'une demi-journée. | AS16: AAS_D_213 | AT16: =VLOOKUP(AS16,'Axe 2 Règles de gestion'!$D$2:$F$54,3, FALSE) -> La durée réelle de l'autorisation d'absence pour crédit de temps syndical est au minimum d'une demi-journée. | AU16: ABS_C_010 | AV16: =VLOOKUP(AU16,'Axe 2 Règles de gestion'!$D$2:$F$54,3, FALSE) -> L'agent doit être en activité. | AW16: ABS_C_001 | AX16: =VLOOKUP(AW16,'Axe 2 Règles de gestion'!$D$2:$F$54,3, FALSE) -> La date de début du congé/absence doit être postérieure ou égale à la date de recrutement dans la FPE ou dans la carrière militaire. | AY16: ABS_C_003 | AZ16: =VLOOKUP(AY16,'Axe 2 Règles de gestion'!$D$2:$F$54,3, FALSE) -> La date de début du congé/absence doit être antérieure ou égale à la date de fin réelle du congé/absence. | BA16: ABS_C_004 | BB16: =VLOOKUP(BA16,'Axe 2 Règles de gestion'!$D$2:$F$54,3, FALSE) -> La date de début du congé/absence doit être antérieure ou égale à la date de fin prévisionnelle du congé/absence. | BC16: ABS_C_007 | BD16: =VLOOKUP(BC16,'Axe 2 Règles de gestion'!$D$2:$F$54,3, FALSE) -> La date de fin réelle du congé/absence doit être antérieure à la date limite de départ à la retraite. | BE16: ABS_C_008 | BF16: =VLOOKUP(BE16,'Axe 2 Règles de gestion'!$D$2:$F$54,3, FALSE) -> La date de fin prévisionnelle du congé/absence doit être antérieure à la date limite de départ à la retraite. | BG16: ABS_C_009 | BH16: =VLOOKUP(BG16,'Axe 2 Règles de gestion'!$D$2:$F$54,3, FALSE) -> La date de fin réelle ou la date de fin prévisionnelle du congé/absence doit être saisie. | BI16: ABS_C_019 | BJ16: =VLOOKUP(BI16,'Axe 2 Règles de gestion'!$D$2:$F$54,3, FALSE) -> Si l'absence ne commence pas par une demi-journée et si l'absence précédente ne finit pas par une demi journée, la date de début de l'absence saisie est postérieure à la date de fin réelle de l'absence précédente. | BK16: ABS_C_020 | BL16: =VLOOKUP(BK16,'Axe 2 Règles de gestion'!$D$2:$F$54,3, FALSE) -> Si l'absence ne commence pas par une demi-journée et si l'absence précédente ne finit pas par une demi journée, la date de début de l'absence saisie est postérieure à la date de fin prévisionnelle de l'absence précédente. | BM16: 2026-25
A17: 26.00.00 | B17: M | C17: 46175.449 | D17: D0007 | E17: Congés/Absence | F17: S0196 | G17: Autorisations d'absence syndicales | H17: E0855 | I17: Autorisation d'absence pour crédit de temps syndical | J17: Type de congé/absence saisi égal 'Autorisation d'absence pour crédit de temps syndical' | K17: A_COA_TYCOAB [Saisi] = 'CA055' | L17: T2116 | M17: Autorisation d'absence pour crédit de temps syndical | N17: Création Modification | Q17: Magistrat de l'ordre judiciaire | R17: P0007 | S17: T | T17: Particulier | U17: Passant | V17: 45689 | X17: AAS_I_142 ET AAS_I_013 ET AAS_I_014 ET AAS_D_210 ET AAS_D_213 ET ABS_C_010 ET ABS_C_001 ET ABS_C_003 ET ABS_C_004 ET ABS_C_007 ET ABS_C_008 ET ABS_C_009 ET ABS_C_019 ET ABS_C_020 | Y17: AAS_I_142 | Z17: =VLOOKUP(Y17,'Axe 2 Règles de gestion'!$D$2:$F$54,3, FALSE) -> L'agent bénéficie des dispositions applicables aux agents titulaires pour les autorisations d'absence syndicales. | AA17: AAS_I_013 | AB17: =VLOOKUP(AA17,'Axe 2 Règles de gestion'!$D$2:$F$54,3, FALSE) -> L'agent doit être chargé d'une activité syndicale. | AC17: AAS_I_014 | AD17: =VLOOKUP(AC17,'Axe 2 Règles de gestion'!$D$2:$F$54,3, FALSE) -> L'agent, désigné comme bénéficiaire de crédits d'heures par une organisation syndicale, peut bénéficier de crédits d'heures pour remplir ses obligations syndicales. | AQ17: AAS_D_210 | AR17: =VLOOKUP(AQ17,'Axe 2 Règles de gestion'!$D$2:$F$54,3, FALSE) -> La durée prévisionnelle de l'autorisation d'absence pour crédit de temps syndical est au minimum d'une demi-journée. | AS17: AAS_D_213 | AT17: =VLOOKUP(AS17,'Axe 2 Règles de gestion'!$D$2:$F$54,3, FALSE) -> La durée réelle de l'autorisation d'absence pour crédit de temps syndical est au minimum d'une demi-journée. | AU17: ABS_C_010 | AV17: =VLOOKUP(AU17,'Axe 2 Règles de gestion'!$D$2:$F$54,3, FALSE) -> L'agent doit être en activité. | AW17: ABS_C_001 | AX17: =VLOOKUP(AW17,'Axe 2 Règles de gestion'!$D$2:$F$54,3, FALSE) -> La date de début du congé/absence doit être postérieure ou égale à la date de recrutement dans la FPE ou dans la carrière militaire. | AY17: ABS_C_003 | AZ17: =VLOOKUP(AY17,'Axe 2 Règles de gestion'!$D$2:$F$54,3, FALSE) -> La date de début du congé/absence doit être antérieure ou égale à la date de fin réelle du congé/absence. | BA17: ABS_C_004 | BB17: =VLOOKUP(BA17,'Axe 2 Règles de gestion'!$D$2:$F$54,3, FALSE) -> La date de début du congé/absence doit être antérieure ou égale à la date de fin prévisionnelle du congé/absence. | BC17: ABS_C_007 | BD17: =VLOOKUP(BC17,'Axe 2 Règles de gestion'!$D$2:$F$54,3, FALSE) -> La date de fin réelle du congé/absence doit être antérieure à la date limite de départ à la retraite. | BE17: ABS_C_008 | BF17: =VLOOKUP(BE17,'Axe 2 Règles de gestion'!$D$2:$F$54,3, FALSE) -> La date de fin prévisionnelle du congé/absence doit être antérieure à la date limite de départ à la retraite. | BG17: ABS_C_009 | BH17: =VLOOKUP(BG17,'Axe 2 Règles de gestion'!$D$2:$F$54,3, FALSE) -> La date de fin réelle ou la date de fin prévisionnelle du congé/absence doit être saisie. | BI17: ABS_C_019 | BJ17: =VLOOKUP(BI17,'Axe 2 Règles de gestion'!$D$2:$F$54,3, FALSE) -> Si l'absence ne commence pas par une demi-journée et si l'absence précédente ne finit pas par une demi journée, la date de début de l'absence saisie est postérieure à la date de fin réelle de l'absence précédente. | BK17: ABS_C_020 | BL17: =VLOOKUP(BK17,'Axe 2 Règles de gestion'!$D$2:$F$54,3, FALSE) -> Si l'absence ne commence pas par une demi-journée et si l'absence précédente ne finit pas par une demi journée, la date de début de l'absence saisie est postérieure à la date de fin prévisionnelle de l'absence précédente. | BM17: 2026-25
A18: 26.00.00 | B18: A | C18: 46099.62 | D18: D0007 | E18: Congés/Absence | F18: S0196 | G18: Autorisations d'absence syndicales | H18: E0855 | I18: Autorisation d'absence pour crédit de temps syndical | J18: Type de congé/absence saisi égal 'Autorisation d'absence pour crédit de temps syndical' | K18: A_COA_TYCOAB [Saisi] = 'CA055' | L18: T2116 | M18: Autorisation d'absence pour crédit de temps syndical | N18: Création Modification | Q18: Ouvrier de la défense ou assimilé | R18: P0197 | S18: O | T18: Particulier | U18: Passant | V18: 45689 | X18: AAS_I_027 ET AAS_I_028 ET AAS_I_029 ET AAS_I_030 ET AAS_I_031 ET AAS_I_032 ET AAS_I_033 ET ABS_C_010 ET ABS_C_001 ET ABS_C_003 ET ABS_C_004 ET ABS_C_007 ET ABS_C_008 ET ABS_C_009 | Y18: AAS_I_027 | Z18: =VLOOKUP(Y18,'Axe 2 Règles de gestion'!$D$2:$F$54,3, FALSE) -> L'agent doit être chargé d'un mandat syndical. | AA18: AAS_I_028 | AB18: =VLOOKUP(AA18,'Axe 2 Règles de gestion'!$D$2:$F$54,3, FALSE) -> L'agent, désigné comme bénéficiaire de crédits d'heures par une organisation syndicale, peut bénéficier, sur demande, de crédits d'heures pour remplir ses obligations syndicales. | AC18: AAS_I_029 | AD18: =VLOOKUP(AC18,'Axe 2 Règles de gestion'!$D$2:$F$54,3, FALSE) -> L'organisation syndicale adresse au chef d'organisme son besoin en identifiant le nom de l'agent bénéficiaire du crédit d'heures, la date et la durée de l'absence exprimée en heure(s). Cette durée comprend les éventuels délais de route. | AE18: AAS_I_030 | AF18: =VLOOKUP(AE18,'Axe 2 Règles de gestion'!$D$2:$F$54,3, FALSE) -> Cette absence est d'une demi-journée minimum lorsque ce crédit d'heures est utilisé pour participer aux activités en qualité de défenseur syndical au Conseil de prud'hommes et la cour d'appel en matière prud'homale. | AG18: AAS_I_031 | AH18: =VLOOKUP(AG18,'Axe 2 Règles de gestion'!$D$2:$F$54,3, FALSE) -> L'agent doit ensuite adresser sa demande auprès de son chef d'organisme au moins 1 semaine à l'avance. Toutefois, dans une situation d'urgence particulière, ce délai peut être ramené à 48 heures. | AI18: AAS_I_032 | AJ18: =VLOOKUP(AI18,'Axe 2 Règles de gestion'!$D$2:$F$54,3, FALSE) -> Le chef d'organisme doit rendre son avis sur la demande d'absence. Son avis doit porter sur la conciliation de cette autorisation avec le bon fonctionnement du service. | AK18: AAS_I_033 | AL18: =VLOOKUP(AK18,'Axe 2 Règles de gestion'!$D$2:$F$54,3, FALSE) -> En cas de refus, le chef d'organisme doit motiver sa décision. | AU18: ABS_C_010 | AV18: =VLOOKUP(AU18,'Axe 2 Règles de gestion'!$D$2:$F$54,3, FALSE) -> L'agent doit être en activité. | AW18: ABS_C_001 | AX18: =VLOOKUP(AW18,'Axe 2 Règles de gestion'!$D$2:$F$54,3, FALSE) -> La date de début du congé/absence doit être postérieure ou égale à la date de recrutement dans la FPE ou dans la carrière militaire. | AY18: ABS_C_003 | AZ18: =VLOOKUP(AY18,'Axe 2 Règles de gestion'!$D$2:$F$54,3, FALSE) -> La date de début du congé/absence doit être antérieure ou égale à la date de fin réelle du congé/absence. | BA18: ABS_C_004 | BB18: =VLOOKUP(BA18,'Axe 2 Règles de gestion'!$D$2:$F$54,3, FALSE) -> La date de début du congé/absence doit être antérieure ou égale à la date de fin prévisionnelle du congé/absence. | BC18: ABS_C_007 | BD18: =VLOOKUP(BC18,'Axe 2 Règles de gestion'!$D$2:$F$54,3, FALSE) -> La date de fin réelle du congé/absence doit être antérieure à la date limite de départ à la retraite. | BE18: ABS_C_008 | BF18: =VLOOKUP(BE18,'Axe 2 Règles de gestion'!$D$2:$F$54,3, FALSE) -> La date de fin prévisionnelle du congé/absence doit être antérieure à la date limite de départ à la retraite. | BG18: ABS_C_009 | BH18: =VLOOKUP(BG18,'Axe 2 Règles de gestion'!$D$2:$F$54,3, FALSE) -> La date de fin réelle ou la date de fin prévisionnelle du congé/absence doit être saisie. | BM18: 2026-25
A19: 26.00.00 | B19: M | C19: 46113.416 | D19: D0007 | E19: Congés/Absence | F19: S0196 | G19: Autorisations d'absence syndicales | H19: E1054 | I19: Autorisation d'absence pour siéger dans une instance de dialogue social | J19: Type de congé/absence saisi égal 'Autorisation d'absence pour siéger dans une instance de dialogue social' | K19: A_COA_TYCOAB [Saisi] = 'CA004' | L19: T2505 | M19: Autorisation d'absence pour siéger dans une instance de dialogue social | N19: Création Modification | Q19: Titulaire ou magistrat | R19: P0001 | S19: T | T19: Général | U19: Passant | V19: 45689 | X19: AAS_I_005 ET AAS_I_007 ET AAS_I_039 ET AAS_I_009 ET AAS_I_010 ET AAS_D_027 ET AAS_D_028 ET ABS_C_010 ET ABS_C_001 ET ABS_C_003 ET ABS_C_004 ET ABS_C_007 ET ABS_C_008 ET ABS_C_009 | Y19: AAS_I_005 | Z19: =VLOOKUP(Y19,'Axe 2 Règles de gestion'!$D$2:$F$54,3, FALSE) -> L'agent doit être représentant du personnel, titulaire ou suppléant, ou expert. | AA19: AAS_I_007 | AB19: =VLOOKUP(AA19,'Axe 2 Règles de gestion'!$D$2:$F$54,3, FALSE) -> L'agent doit présenter sa convocation ou un document l'informant de la réunion de l'organisme dans lequel il est appelé à siéger. | AC19: AAS_I_039 | AD19: =VLOOKUP(AC19,'Axe 2 Règles de gestion'!$D$2:$F$54,3, FALSE) -> La durée de cette autorisation correspond à la durée prévisible de la réunion et des éventuels délais de route pour se rendre à la réunion. | AE19: AAS_I_009 | AF19: =VLOOKUP(AE19,'Axe 2 Règles de gestion'!$D$2:$F$54,3, FALSE) -> La durée prévisionnelle de l'autorisation d'absence comprend les délais de route, la durée prévisible de la réunion, le temps nécessaire à la préparation et au compte rendu des travaux. | AG19: AAS_I_010 | AH19: =VLOOKUP(AG19,'Axe 2 Règles de gestion'!$D$2:$F$54,3, FALSE) -> Le temps nécessaire à la préparation et au compte rendu des travaux ne peut être supérieur à la durée prévisible de la réunion. | AQ19: AAS_D_027 | AR19: =VLOOKUP(AQ19,'Axe 2 Règles de gestion'!$D$2:$F$54,3, FALSE) -> Pour l'agent appelé à siéger aux commissions administratives paritaires, la durée de l'absence est égale à la durée prévisible de la réunion et ne peut dépasser une durée prévisionnelle de 2 jours. | AS19: AAS_D_028 | AT19: =VLOOKUP(AS19,'Axe 2 Règles de gestion'!$D$2:$F$54,3, FALSE) -> Pour l'agent appelé à siéger aux commissions administratives paritaires, la durée de l'absence est égale à la durée prévisible de la réunion et ne peut dépasser une durée réelle de 2 jours. | AU19: ABS_C_010 | AV19: =VLOOKUP(AU19,'Axe 2 Règles de gestion'!$D$2:$F$54,3, FALSE) -> L'agent doit être en activité. | AW19: ABS_C_001 | AX19: =VLOOKUP(AW19,'Axe 2 Règles de gestion'!$D$2:$F$54,3, FALSE) -> La date de début du congé/absence doit être postérieure ou égale à la date de recrutement dans la FPE ou dans la carrière militaire. | AY19: ABS_C_003 | AZ19: =VLOOKUP(AY19,'Axe 2 Règles de gestion'!$D$2:$F$54,3, FALSE) -> La date de début du congé/absence doit être antérieure ou égale à la date de fin réelle du congé/absence. | BA19: ABS_C_004 | BB19: =VLOOKUP(BA19,'Axe 2 Règles de gestion'!$D$2:$F$54,3, FALSE) -> La date de début du congé/absence doit être antérieure ou égale à la date de fin prévisionnelle du congé/absence. | BC19: ABS_C_007 | BD19: =VLOOKUP(BC19,'Axe 2 Règles de gestion'!$D$2:$F$54,3, FALSE) -> La date de fin réelle du congé/absence doit être antérieure à la date limite de départ à la retraite. | BE19: ABS_C_008 | BF19: =VLOOKUP(BE19,'Axe 2 Règles de gestion'!$D$2:$F$54,3, FALSE) -> La date de fin prévisionnelle du congé/absence doit être antérieure à la date limite de départ à la retraite. | BG19: ABS_C_009 | BH19: =VLOOKUP(BG19,'Axe 2 Règles de gestion'!$D$2:$F$54,3, FALSE) -> La date de fin réelle ou la date de fin prévisionnelle du congé/absence doit être saisie. | BM19: 2026-07 / 2026-25
A20: 26.00.00 | B20: A | C20: 46113.417 | D20: D0007 | E20: Congés/Absence | F20: S0196 | G20: Autorisations d'absence syndicales | H20: E1054 | I20: Autorisation d'absence pour siéger dans une instance de dialogue social | J20: Type de congé/absence saisi égal 'Autorisation d'absence pour siéger dans une instance de dialogue social' | K20: A_COA_TYCOAB [Saisi] = 'CA004' | L20: T2505 | M20: Autorisation d'absence pour siéger dans une instance de dialogue social | N20: Création Modification | Q20: Militaire | R20: P0002 | S20: M | T20: Général | U20: Exclu | V20: 45689 | BM20: 2026-25
