Workbook

Sheet Mode opératoire
B1: MODE OPERATOIRE
B2: La transaction s'effectue au niveau de la rubrique "Congés/absences", elle inclut l'ensemble des sous-rubriques listées ci-dessous : Congés/absences Complément pour congé / absence : impact rémunération On notera que : La sous-rubrique "Complément pour congé / absence : impact rémunération" est réputée, suite au découpage des absences en tranche de rémunération, avoir des dates de début et de fin alignées sur les dates de début et de fin de la sous-rubrique "Congés/absences" (contrôle bloquant)

Sheet Axe 1 Enchainement des RG
A1: Version | B1: Type de mise à jour | C1: Date de mise à jour | D1: Identifiant Domaine | E1: Libellé du Domaine | F1: Identifiant Sous-domaine | G1: Libellé du Sous-domaine | H1: Identifiant Evénement | I1: Libellé de l'évènement | J1: Libellé condition déclenchement Evènement | K1: Condition déclenchement Evènement | L1: Identifiant type d'évènement | M1: Libellé type d'évènement | N1: Type de mise à jour | O1: Libellé condition déclenchement Type Evènement | P1: Condition déclenchement Type Evènement | Q1: Libellé Population | R1: Codification Population | S1: Général / Particulier | T1: Passant / Exclu | U1: Date de début | V1: Date de fin | W1: Règles mobilisées | X1: Identifiant Règle de contrôle intellectuel 1 | Y1: Libellé Règle de contrôle intellectuel 1 | Z1: Identifiant Règle de contrôle intellectuel 2 | AA1: Libellé Règle de contrôle intellectuel 2 | AB1: Identifiant Règle de contrôle intellectuel 3 | AC1: Libellé Règle de contrôle intellectuel 3 | AD1: Identifiant Règle de contrôle intellectuel 4 | AE1: Libellé Règle de contrôle intellectuel 4 | AF1: Identifiant Règle de contrôle intellectuel 5 | AG1: Libellé Règle de contrôle intellectuel 5 | AH1: Identifiant Règle de contrôle intellectuel 6 | AI1: Libellé Règle de contrôle intellectuel 6 | AJ1: Identifiant Règle de contrôle intellectuel 7 | AK1: Libellé Règle de contrôle intellectuel 7 | AL1: Identifiant Règle de contrôle intellectuel 8 | AM1: Libellé Règle de contrôle intellectuel 8 | AN1: Identifiant Règle de contrôle intellectuel 9 | AO1: Libellé Règle de contrôle intellectuel 9 | AP1: Identifiant Règle de contrôle intellectuel 10 | AQ1: Libellé Règle de contrôle intellectuel 10 | AR1: Identifiant Règle de contrôle intellectuel 11 | AS1: Libellé Règle de contrôle intellectuel 11 | AT1: Identifiant Règle de contrôle intellectuel 12 | AU1: Libellé Règle de contrôle intellectuel 12 | AV1: Identifiant Règle de condition 1 | AW1: Libellé Règle de condition 1 | AX1: Identifiant Règle de condition 2 | AY1: Libellé Règle de condition 2 | AZ1: Identifiant Règle de condition 3 | BA1: Libellé Règle de condition 3 | BB1: Identifiant Règle de condition 4 | BC1: Libellé Règle de condition 4 | BD1: Identifiant Règle de condition 5 | BE1: Libellé Règle de condition 5 | BF1: Identifiant Règle de condition 6 | BG1: Libellé Règle de condition 6 | BH1: Identifiant Règle de contrôle 1 | BI1: Libellé Règle de contrôle 1 | BJ1: Identifiant Règle de contrôle 2 | BK1: Libellé Règle de contrôle 2 | BL1: Identifiant Règle de contrôle 3 | BM1: Libellé Règle de contrôle 3 | BN1: Identifiant Règle de contrôle 4 | BO1: Libellé Règle de contrôle 4 | BP1: Identifiant Règle de contrôle 5 | BQ1: Libellé Règle de contrôle 5 | BR1: Identifiant Règle de contrôle 6 | BS1: Libellé Règle de contrôle 6 | BT1: Identifiant Règle de contrôle 7 | BU1: Libellé Règle de contrôle 7 | BV1: Identifiant Règle de contrôle 8 | BW1: Libellé Règle de contrôle 8 | BX1: Identifiant Règle de contrôle 9 | BY1: Libellé Règle de contrôle 9 | BZ1: FIME | CA1: Statut de travail
A2: 22.10.00 | B2: A | C2: 44854.471 | D2: D0007 | E2: Congés/Absence | F2: S0156 | G2: Congé pour création ou reprise d'entreprise | H2: E0893 | I2: Congé pour création ou reprise d'entreprise | J2: Type de congé/absence saisi = 'Congé pour création ou reprise d'entreprise' | K2: A_COA_TYCOAB [Saisi] = 'CF014' | L2: T2198 | M2: Congé pour création ou reprise d'entreprise - Demande | N2: Création Modification | O2: La valeur de l'Etat du congé est 'Initial' et la valeur de l'Etat du congé saisie est différente de celle avant saisie | P2: A_COA_ETCOMA [Saisi] = 'EC01' ET A_COA_ETCOMA [Saisi] <> A_COA_ETCOMA [Valeur avant saisie] | Q2: Titulaire ou magistrat | R2: P0001 | S2: Général | T2: Exclu | U2: 43831
A3: 22.10.00 | B3: A | C3: 44854.484 | D3: D0007 | E3: Congés/Absence | F3: S0156 | G3: Congé pour création ou reprise d'entreprise | H3: E0893 | I3: Congé pour création ou reprise d'entreprise | J3: Type de congé/absence saisi = 'Congé pour création ou reprise d'entreprise' | K3: A_COA_TYCOAB [Saisi] = 'CF014' | L3: T2199 | M3: Congé pour création ou reprise d'entreprise - Renouvellement | N3: Création Modification | O3: La valeur de l'Etat du congé est 'Renouvellement' et la valeur de l'Etat du congé saisie est différente de celle avant saisie | P3: A_COA_ETCOMA [Saisi] = 'EC02' ET A_COA_ETCOMA [Saisi] <> A_COA_ETCOMA [Valeur avant saisie] | Q3: Titulaire ou magistrat | R3: P0001 | S3: Général | T3: Exclu | U3: 43831
A4: 22.10.00 | B4: A | C4: 44854.493 | D4: D0007 | E4: Congés/Absence | F4: S0156 | G4: Congé pour création ou reprise d'entreprise | H4: E0893 | I4: Congé pour création ou reprise d'entreprise | J4: Type de congé/absence saisi = 'Congé pour création ou reprise d'entreprise' | K4: A_COA_TYCOAB [Saisi] = 'CF014' | L4: T2200 | M4: Congé pour création ou reprise d'entreprise - Fin | N4: Modification | O4: La valeur de l'Etat du congé saisie est égale à celle avant saisie | P4: A_COA_ETCOMA [Saisi] = A_COA_ETCOMA [Valeur avant saisie] | Q4: Titulaire ou magistrat | R4: P0001 | S4: Général | T4: Exclu | U4: 43831
A5: 22.10.00 | B5: A | C5: 44854.472 | D5: D0007 | E5: Congés/Absence | F5: S0156 | G5: Congé pour création ou reprise d'entreprise | H5: E0893 | I5: Congé pour création ou reprise d'entreprise | J5: Type de congé/absence saisi = 'Congé pour création ou reprise d'entreprise' | K5: A_COA_TYCOAB [Saisi] = 'CF014' | L5: T2198 | M5: Congé pour création ou reprise d'entreprise - Demande | N5: Création Modification | O5: La valeur de l'Etat du congé est 'Initial' et la valeur de l'Etat du congé saisie est différente de celle avant saisie | P5: A_COA_ETCOMA [Saisi] = 'EC01' ET A_COA_ETCOMA [Saisi] <> A_COA_ETCOMA [Valeur avant saisie] | Q5: Militaire | R5: P0002 | S5: Général | T5: Exclu | U5: 43831
A6: 22.10.00 | B6: A | C6: 44854.485 | D6: D0007 | E6: Congés/Absence | F6: S0156 | G6: Congé pour création ou reprise d'entreprise | H6: E0893 | I6: Congé pour création ou reprise d'entreprise | J6: Type de congé/absence saisi = 'Congé pour création ou reprise d'entreprise' | K6: A_COA_TYCOAB [Saisi] = 'CF014' | L6: T2199 | M6: Congé pour création ou reprise d'entreprise - Renouvellement | N6: Création Modification | O6: La valeur de l'Etat du congé est 'Renouvellement' et la valeur de l'Etat du congé saisie est différente de celle avant saisie | P6: A_COA_ETCOMA [Saisi] = 'EC02' ET A_COA_ETCOMA [Saisi] <> A_COA_ETCOMA [Valeur avant saisie] | Q6: Militaire | R6: P0002 | S6: Général | T6: Exclu | U6: 43831
A7: 22.10.00 | B7: A | C7: 44854.493 | D7: D0007 | E7: Congés/Absence | F7: S0156 | G7: Congé pour création ou reprise d'entreprise | H7: E0893 | I7: Congé pour création ou reprise d'entreprise | J7: Type de congé/absence saisi = 'Congé pour création ou reprise d'entreprise' | K7: A_COA_TYCOAB [Saisi] = 'CF014' | L7: T2200 | M7: Congé pour création ou reprise d'entreprise - Fin | N7: Modification | O7: La valeur de l'Etat du congé saisie est égale à celle avant saisie | P7: A_COA_ETCOMA [Saisi] = A_COA_ETCOMA [Valeur avant saisie] | Q7: Militaire | R7: P0002 | S7: Général | T7: Exclu | U7: 43831
A8: 22.10.00 | B8: A | C8: 44854.472 | D8: D0007 | E8: Congés/Absence | F8: S0156 | G8: Congé pour création ou reprise d'entreprise | H8: E0893 | I8: Congé pour création ou reprise d'entreprise | J8: Type de congé/absence saisi = 'Congé pour création ou reprise d'entreprise' | K8: A_COA_TYCOAB [Saisi] = 'CF014' | L8: T2198 | M8: Congé pour création ou reprise d'entreprise - Demande | N8: Création Modification | O8: La valeur de l'Etat du congé est 'Initial' et la valeur de l'Etat du congé saisie est différente de celle avant saisie | P8: A_COA_ETCOMA [Saisi] = 'EC01' ET A_COA_ETCOMA [Saisi] <> A_COA_ETCOMA [Valeur avant saisie] | Q8: Contractuel | R8: P0003 | S8: Général | T8: Exclu | U8: 43831
A9: 22.10.00 | B9: A | C9: 44854.485 | D9: D0007 | E9: Congés/Absence | F9: S0156 | G9: Congé pour création ou reprise d'entreprise | H9: E0893 | I9: Congé pour création ou reprise d'entreprise | J9: Type de congé/absence saisi = 'Congé pour création ou reprise d'entreprise' | K9: A_COA_TYCOAB [Saisi] = 'CF014' | L9: T2199 | M9: Congé pour création ou reprise d'entreprise - Renouvellement | N9: Création Modification | O9: La valeur de l'Etat du congé est 'Renouvellement' et la valeur de l'Etat du congé saisie est différente de celle avant saisie | P9: A_COA_ETCOMA [Saisi] = 'EC02' ET A_COA_ETCOMA [Saisi] <> A_COA_ETCOMA [Valeur avant saisie] | Q9: Contractuel | R9: P0003 | S9: Général | T9: Exclu | U9: 43831
A10: 22.10.00 | B10: A | C10: 44854.494 | D10: D0007 | E10: Congés/Absence | F10: S0156 | G10: Congé pour création ou reprise d'entreprise | H10: E0893 | I10: Congé pour création ou reprise d'entreprise | J10: Type de congé/absence saisi = 'Congé pour création ou reprise d'entreprise' | K10: A_COA_TYCOAB [Saisi] = 'CF014' | L10: T2200 | M10: Congé pour création ou reprise d'entreprise - Fin | N10: Modification | O10: La valeur de l'Etat du congé saisie est égale à celle avant saisie | P10: A_COA_ETCOMA [Saisi] = A_COA_ETCOMA [Valeur avant saisie] | Q10: Contractuel | R10: P0003 | S10: Général | T10: Exclu | U10: 43831
A11: 22.10.00 | B11: A | C11: 44854.474 | D11: D0007 | E11: Congés/Absence | F11: S0156 | G11: Congé pour création ou reprise d'entreprise | H11: E0893 | I11: Congé pour création ou reprise d'entreprise | J11: Type de congé/absence saisi = 'Congé pour création ou reprise d'entreprise' | K11: A_COA_TYCOAB [Saisi] = 'CF014' | L11: T2198 | M11: Congé pour création ou reprise d'entreprise - Demande | N11: Création Modification | O11: La valeur de l'Etat du congé est 'Initial' et la valeur de l'Etat du congé saisie est différente de celle avant saisie | P11: A_COA_ETCOMA [Saisi] = 'EC01' ET A_COA_ETCOMA [Saisi] <> A_COA_ETCOMA [Valeur avant saisie] | Q11: Stagiaire ou auditeur ou élève | R11: P0004 | S11: Général | T11: Exclu | U11: 43831
A12: 22.10.00 | B12: A | C12: 44854.486 | D12: D0007 | E12: Congés/Absence | F12: S0156 | G12: Congé pour création ou reprise d'entreprise | H12: E0893 | I12: Congé pour création ou reprise d'entreprise | J12: Type de congé/absence saisi = 'Congé pour création ou reprise d'entreprise' | K12: A_COA_TYCOAB [Saisi] = 'CF014' | L12: T2199 | M12: Congé pour création ou reprise d'entreprise - Renouvellement | N12: Création Modification | O12: La valeur de l'Etat du congé est 'Renouvellement' et la valeur de l'Etat du congé saisie est différente de celle avant saisie | P12: A_COA_ETCOMA [Saisi] = 'EC02' ET A_COA_ETCOMA [Saisi] <> A_COA_ETCOMA [Valeur avant saisie] | Q12: Stagiaire ou auditeur ou élève | R12: P0004 | S12: Général | T12: Exclu | U12: 43831
A13: 22.10.00 | B13: A | C13: 44854.494 | D13: D0007 | E13: Congés/Absence | F13: S0156 | G13: Congé pour création ou reprise d'entreprise | H13: E0893 | I13: Congé pour création ou reprise d'entreprise | J13: Type de congé/absence saisi = 'Congé pour création ou reprise d'entreprise' | K13: A_COA_TYCOAB [Saisi] = 'CF014' | L13: T2200 | M13: Congé pour création ou reprise d'entreprise - Fin | N13: Modification | O13: La valeur de l'Etat du congé saisie est égale à celle avant saisie | P13: A_COA_ETCOMA [Saisi] = A_COA_ETCOMA [Valeur avant saisie] | Q13: Stagiaire ou auditeur ou élève | R13: P0004 | S13: Général | T13: Exclu | U13: 43831
... A16: 22.10.00 | B16: A | C16: 44854.494 | D16: D0007 | E16: Congés/Absence | F16: S0156 | G16: Congé pour création ou reprise d'entreprise | H16: E0893 | I16: Congé pour création ou reprise d'entreprise | J16: Type de congé/absence saisi = 'Congé pour création ou reprise d'entreprise' | K16: A_COA_TYCOAB [Saisi] = 'CF014' | L16: T2200 | M16: Congé pour création ou reprise d'entreprise - Fin | N16: Modification | O16: La valeur de l'Etat du congé saisie est égale à celle avant saisie | P16: A_COA_ETCOMA [Saisi] = A_COA_ETCOMA [Valeur avant saisie] | Q16: Ouvrier d'état | R16: P0005 | S16: Général | T16: Exclu | U16: 43831
A17: 22.10.00 | B17: A | C17: 44887.5 | D17: D0007 | E17: Congés/Absence | F17: S0156 | G17: Congé pour création ou reprise d'entreprise | H17: E0893 | I17: Congé pour création ou reprise d'entreprise | J17: Type de congé/absence saisi = 'Congé pour création ou reprise d'entreprise' | K17: A_COA_TYCOAB [Saisi] = 'CF014' | L17: T2198 | M17: Congé pour création ou reprise d'entreprise - Demande | N17: Création Modification | O17: La valeur de l'Etat du congé est 'Initial' et la valeur de l'Etat du congé saisie est différente de celle avant saisie | P17: A_COA_ETCOMA [Saisi] = 'EC01' ET A_COA_ETCOMA [Saisi] <> A_COA_ETCOMA [Valeur avant saisie] | Q17: Militaire sous contrat | R17: P0145 | S17: Particulier | T17: Passant | U17: 43831 | W17: CCE_I_003 ET CCE_I_017 ET CCE_I_001 ET CCE_I_002 ET CCE_I_004 ET CCE_I_005 ET CCE_I_006 ET CCE_I_007 ET CCE_I_008 ET CCE_I_009 ET CCE_I_010 ET CCE_I_011 ET CCE_D_003 ET CCE_D_004 ET CCE_D_002 ET CCE_D_001 ET CCE_D_008 ET CCE_D_009 ET ABS_C_002 ET ABS_C_003 ET ABS_C_004 ET ABS_C_007 ET ABS_C_008 ET ABS_C_009 ET ABS_C_019 ET ABS_C_020 ET ABS_C_026 | X17: CCE_I_003 | Y17: =VLOOKUP(X17,'Axe 2 Règles de gestion'!$D$2:$F$40,3, FALSE) -> Le bénéfice d'un congé pour création ou reprise d'entreprise est exclusif de tout congé de reconversion et de congé complémentaire de reconversion. | Z17: CCE_I_017 | AA17: =VLOOKUP(Z17,'Axe 2 Règles de gestion'!$D$2:$F$40,3, FALSE) -> L'interdiction d'exercer à titre professionnel une activité privée lucrative et de participer aux organes de direction de sociétés ou d'associations à but lucratif n'est pas applicable dans le cadre de ce congé. | AB17: CCE_I_001 | AC17: =VLOOKUP(AB17,'Axe 2 Règles de gestion'!$D$2:$F$40,3, FALSE) -> Le militaire doit présenter une demande écrite à l'autorité dont il relève 2 mois au moins avant la date de création ou de reprise de l'entreprise. | AD17: CCE_I_002 | AE17: =VLOOKUP(AD17,'Axe 2 Règles de gestion'!$D$2:$F$40,3, FALSE) -> La demande mentionne la forme et l'objet social de l'entreprise susceptible d'être créée, son secteur et sa branche d'activité et, le cas échéant, la nature et le montant des subventions publiques dont cette entreprise est susceptible de bénéficier. | AF17: CCE_I_004 | AG17: =VLOOKUP(AF17,'Axe 2 Règles de gestion'!$D$2:$F$40,3, FALSE) -> Le ministre compétent saisit la commission de déontologie des militaires de cette demande dans le mois qui suit la date à laquelle elle l'a reçue. | AH17: CCE_I_005 | AI17: =VLOOKUP(AH17,'Axe 2 Règles de gestion'!$D$2:$F$40,3, FALSE) -> La commission rend son avis dans un délai d'1 mois à compter de l'enregistrement du dossier de saisine. | AJ17: CCE_I_006 | AK17: =VLOOKUP(AJ17,'Axe 2 Règles de gestion'!$D$2:$F$40,3, FALSE) -> L'absence d'avis de la commission à l'expiration du délai vaut avis favorable. | AL17: CCE_I_007 | AM17: =VLOOKUP(AL17,'Axe 2 Règles de gestion'!$D$2:$F$40,3, FALSE) -> L'avis de la commission est transmis au ministre compétent pour décision qui doit intervenir dans un délai d'1 mois à compter de la réception du dossier. | AN17: CCE_I_008 | AO17: =VLOOKUP(AN17,'Axe 2 Règles de gestion'!$D$2:$F$40,3, FALSE) -> L'absence de décision du ministre compétent dans le délai vaut refus d'attribution du congé. | AP17: CCE_I_009 | AQ17: =VLOOKUP(AP17,'Axe 2 Règles de gestion'!$D$2:$F$40,3, FALSE) -> En cas de décision favorable, le ministre compétent doit mentionner la durée du congé accordé. | AR17: CCE_I_010 | AS17: =VLOOKUP(AR17,'Axe 2 Règles de gestion'!$D$2:$F$40,3, FALSE) -> Pendant la durée du congé, le militaire se consacre obligatoirement à la création et à l'exploitation de l'entreprise qu'il crée ou reprend. | AT17: CCE_I_011 | AU17: =VLOOKUP(AT17,'Axe 2 Règles de gestion'!$D$2:$F$40,3, FALSE) -> Le ministre compétent peut faire procéder aux enquêtes nécessaires afin de vérifier si l'activité du militaire est conforme à l'objet du congé. | AV17: CCE_D_003 | AW17: =VLOOKUP(AV17,'Axe 2 Règles de gestion'!$D$2:$F$40,3, FALSE) -> La durée maximale de chaque période est de 1 an (date de fin prévisionnelle de l'absence). | AX17: CCE_D_004 | AY17: =VLOOKUP(AX17,'Axe 2 Règles de gestion'!$D$2:$F$40,3, FALSE) -> La durée maximale de chaque période est de 1 an (date de fin réelle de l'absence). | AZ17: CCE_D_002 | BA17: =VLOOKUP(AZ17,'Axe 2 Règles de gestion'!$D$2:$F$40,3, FALSE) -> Le militaire doit avoir accompli au moins 8 ans de services militaires effectifs. | BB17: CCE_D_001 | BC17: =VLOOKUP(BB17,'Axe 2 Règles de gestion'!$D$2:$F$40,3, FALSE) -> Le militaire est en activité. | BD17: CCE_D_008 | BE17: =VLOOKUP(BD17,'Axe 2 Règles de gestion'!$D$2:$F$40,3, FALSE) -> La date de fin réelle du congé doit être antérieure ou égale à la date limite de fin réelle ou prévisionnelle du lien juridique. Cependant le militaire peut voir son contrat prorogé jusqu'à la date de fin du congé dans la limite de la durée de service. | BF17: CCE_D_009 | BG17: =VLOOKUP(BF17,'Axe 2 Règles de gestion'!$D$2:$F$40,3, FALSE) -> La date de fin prévisionnelle du congé doit être antérieure ou égale à la date limite de fin réelle ou prévisionnelle du lien juridique. Cependant le militaire peut voir son contrat prorogé jusqu'à la date de fin du congé dans la limite de la durée de service. | BH17: ABS_C_002 | BI17: =VLOOKUP(BH17,'Axe 2 Règles de gestion'!$D$2:$F$40,3, FALSE) -> La date de début du congé/absence doit être postérieure ou égale à la date de début du lien juridique. | BJ17: ABS_C_003 | BK17: =VLOOKUP(BJ17,'Axe 2 Règles de gestion'!$D$2:$F$40,3, FALSE) -> La date de début du congé/absence doit être antérieure ou égale à la date de fin réelle du congé/absence. | BL17: ABS_C_004 | BM17: =VLOOKUP(BL17,'Axe 2 Règles de gestion'!$D$2:$F$40,3, FALSE) -> La date de début du congé/absence doit être antérieure ou égale à la date de fin prévisionnelle du congé/absence. | BN17: ABS_C_007 | BO17: =VLOOKUP(BN17,'Axe 2 Règles de gestion'!$D$2:$F$40,3, FALSE) -> La date de fin réelle du congé/absence doit être antérieure à la date limite de départ à la retraite. | BP17: ABS_C_008 | BQ17: =VLOOKUP(BP17,'Axe 2 Règles de gestion'!$D$2:$F$40,3, FALSE) -> La date de fin prévisionnelle du congé/absence doit être antérieure à la date limite de départ à la retraite. | BR17: ABS_C_009 | BS17: =VLOOKUP(BR17,'Axe 2 Règles de gestion'!$D$2:$F$40,3, FALSE) -> La date de fin réelle ou la date de fin prévisionnelle du congé/absence doit être saisie. | BT17: ABS_C_019 | BU17: =VLOOKUP(BT17,'Axe 2 Règles de gestion'!$D$2:$F$40,3, FALSE) -> Si l'absence ne commence pas par une demi-journée et si l'absence précédente ne finit pas par une demi journée, la date de début de l'absence saisie est postérieure à la date de fin réelle de l'absence précédente. | BV17: ABS_C_020 | BW17: =VLOOKUP(BV17,'Axe 2 Règles de gestion'!$D$2:$F$40,3, FALSE) -> Si l'absence ne commence pas par une demi-journée et si l'absence précédente ne finit pas par une demi journée, la date de début de l'absence saisie est postérieure à la date de fin prévisionnelle de l'absence précédente. | BX17: ABS_C_026 | BY17: =VLOOKUP(BX17,'Axe 2 Règles de gestion'!$D$2:$F$40,3, FALSE) -> Dans le cas d'un congé autre que CLM, CLD, CGM et CITIS, l'indicateur de requalification doit être à non et les impacts spécifiques à la requalification ne doivent pas être mobilisés ou l'impact rémunération est vide.
A18: 22.10.00 | B18: A | C18: 44887.501 | D18: D0007 | E18: Congés/Absence | F18: S0156 | G18: Congé pour création ou reprise d'entreprise | H18: E0893 | I18: Congé pour création ou reprise d'entreprise | J18: Type de congé/absence saisi = 'Congé pour création ou reprise d'entreprise' | K18: A_COA_TYCOAB [Saisi] = 'CF014' | L18: T2199 | M18: Congé pour création ou reprise d'entreprise - Renouvellement | N18: Création Modification | O18: La valeur de l'Etat du congé est 'Renouvellement' et la valeur de l'Etat du congé saisie est différente de celle avant saisie | P18: A_COA_ETCOMA [Saisi] = 'EC02' ET A_COA_ETCOMA [Saisi] <> A_COA_ETCOMA [Valeur avant saisie] | Q18: Militaire sous contrat | R18: P0145 | S18: Particulier | T18: Passant | U18: 43831 | W18: CCE_I_017 ET CCE_I_014 ET CCE_I_002 ET CCE_I_004 ET CCE_I_005 ET CCE_I_006 ET CCE_I_007 ET CCE_I_008 ET CCE_I_009 ET CCE_I_015 ET CCE_I_010 ET CCE_I_011 ET CCE_D_003 ET CCE_D_004 ET CCE_D_005 ET CCE_D_008 ET CCE_D_009 ET ABS_C_002 ET ABS_C_003 ET ABS_C_004 ET ABS_C_007 ET ABS_C_008 ET ABS_C_009 ET ABS_C_019 ET ABS_C_020 ET ABS_C_026 | X18: CCE_I_017 | Y18: =VLOOKUP(X18,'Axe 2 Règles de gestion'!$D$2:$F$40,3, FALSE) -> L'interdiction d'exercer à titre professionnel une activité privée lucrative et de participer aux organes de direction de sociétés ou d'associations à but lucratif n'est pas applicable dans le cadre de ce congé. | Z18: CCE_I_014 | AA18: =VLOOKUP(Z18,'Axe 2 Règles de gestion'!$D$2:$F$40,3, FALSE) -> Le militaire qui souhaite prolonger la durée du congé doit en faire la demande au moins 2 mois avant l'échéance de la date mentionnée dans l'autorisation initiale. | AB18: CCE_I_002 | AC18: =VLOOKUP(AB18,'Axe 2 Règles de gestion'!$D$2:$F$40,3, FALSE) -> La demande mentionne la forme et l'objet social de l'entreprise susceptible d'être créée, son secteur et sa branche d'activité et, le cas échéant, la nature et le montant des subventions publiques dont cette entreprise est susceptible de bénéficier. | AD18: CCE_I_004 | AE18: =VLOOKUP(AD18,'Axe 2 Règles de gestion'!$D$2:$F$40,3, FALSE) -> Le ministre compétent saisit la commission de déontologie des militaires de cette demande dans le mois qui suit la date à laquelle elle l'a reçue. | AF18: CCE_I_005 | AG18: =VLOOKUP(AF18,'Axe 2 Règles de gestion'!$D$2:$F$40,3, FALSE) -> La commission rend son avis dans un délai d'1 mois à compter de l'enregistrement du dossier de saisine. | AH18: CCE_I_006 | AI18: =VLOOKUP(AH18,'Axe 2 Règles de gestion'!$D$2:$F$40,3, FALSE) -> L'absence d'avis de la commission à l'expiration du délai vaut avis favorable. | AJ18: CCE_I_007 | AK18: =VLOOKUP(AJ18,'Axe 2 Règles de gestion'!$D$2:$F$40,3, FALSE) -> L'avis de la commission est transmis au ministre compétent pour décision qui doit intervenir dans un délai d'1 mois à compter de la réception du dossier. | AL18: CCE_I_008 | AM18: =VLOOKUP(AL18,'Axe 2 Règles de gestion'!$D$2:$F$40,3, FALSE) -> L'absence de décision du ministre compétent dans le délai vaut refus d'attribution du congé. | AN18: CCE_I_009 | AO18: =VLOOKUP(AN18,'Axe 2 Règles de gestion'!$D$2:$F$40,3, FALSE) -> En cas de décision favorable, le ministre compétent doit mentionner la durée du congé accordé. | AP18: CCE_I_015 | AQ18: =VLOOKUP(AP18,'Axe 2 Règles de gestion'!$D$2:$F$40,3, FALSE) -> Toutefois si l'objet social de l'entreprise, son secteur et sa branche d'activité sont identiques à ceux de la demande initiale, l'autorisation de prorogation du congé est de droit. L'avis de la commission de déontologie n'est alors pas sollicité. | AR18: CCE_I_010 | AS18: =VLOOKUP(AR18,'Axe 2 Règles de gestion'!$D$2:$F$40,3, FALSE) -> Pendant la durée du congé, le militaire se consacre obligatoirement à la création et à l'exploitation de l'entreprise qu'il crée ou reprend. | AT18: CCE_I_011 | AU18: =VLOOKUP(AT18,'Axe 2 Règles de gestion'!$D$2:$F$40,3, FALSE) -> Le ministre compétent peut faire procéder aux enquêtes nécessaires afin de vérifier si l'activité du militaire est conforme à l'objet du congé. | AV18: CCE_D_003 | AW18: =VLOOKUP(AV18,'Axe 2 Règles de gestion'!$D$2:$F$40,3, FALSE) -> La durée maximale de chaque période est de 1 an (date de fin prévisionnelle de l'absence). | AX18: CCE_D_004 | AY18: =VLOOKUP(AX18,'Axe 2 Règles de gestion'!$D$2:$F$40,3, FALSE) -> La durée maximale de chaque période est de 1 an (date de fin réelle de l'absence). | AZ18: CCE_D_005 | BA18: =VLOOKUP(AZ18,'Axe 2 Règles de gestion'!$D$2:$F$40,3, FALSE) -> Le congé est renouvelable 1 fois. | BB18: CCE_D_008 | BC18: =VLOOKUP(BB18,'Axe 2 Règles de gestion'!$D$2:$F$40,3, FALSE) -> La date de fin réelle du congé doit être antérieure ou égale à la date limite de fin réelle ou prévisionnelle du lien juridique. Cependant le militaire peut voir son contrat prorogé jusqu'à la date de fin du congé dans la limite de la durée de service. | BD18: CCE_D_009 | BE18: =VLOOKUP(BD18,'Axe 2 Règles de gestion'!$D$2:$F$40,3, FALSE) -> La date de fin prévisionnelle du congé doit être antérieure ou égale à la date limite de fin réelle ou prévisionnelle du lien juridique. Cependant le militaire peut voir son contrat prorogé jusqu'à la date de fin du congé dans la limite de la durée de service. | BH18: ABS_C_002 | BI18: =VLOOKUP(BH18,'Axe 2 Règles de gestion'!$D$2:$F$40,3, FALSE) -> La date de début du congé/absence doit être postérieure ou égale à la date de début du lien juridique. | BJ18: ABS_C_003 | BK18: =VLOOKUP(BJ18,'Axe 2 Règles de gestion'!$D$2:$F$40,3, FALSE) -> La date de début du congé/absence doit être antérieure ou égale à la date de fin réelle du congé/absence. | BL18: ABS_C_004 | BM18: =VLOOKUP(BL18,'Axe 2 Règles de gestion'!$D$2:$F$40,3, FALSE) -> La date de début du congé/absence doit être antérieure ou égale à la date de fin prévisionnelle du congé/absence. | BN18: ABS_C_007 | BO18: =VLOOKUP(BN18,'Axe 2 Règles de gestion'!$D$2:$F$40,3, FALSE) -> La date de fin réelle du congé/absence doit être antérieure à la date limite de départ à la retraite. | BP18: ABS_C_008 | BQ18: =VLOOKUP(BP18,'Axe 2 Règles de gestion'!$D$2:$F$40,3, FALSE) -> La date de fin prévisionnelle du congé/absence doit être antérieure à la date limite de départ à la retraite. | BR18: ABS_C_009 | BS18: =VLOOKUP(BR18,'Axe 2 Règles de gestion'!$D$2:$F$40,3, FALSE) -> La date de fin réelle ou la date de fin prévisionnelle du congé/absence doit être saisie. | BT18: ABS_C_019 | BU18: =VLOOKUP(BT18,'Axe 2 Règles de gestion'!$D$2:$F$40,3, FALSE) -> Si l'absence ne commence pas par une demi-journée et si l'absence précédente ne finit pas par une demi journée, la date de début de l'absence saisie est postérieure à la date de fin réelle de l'absence précédente. | BV18: ABS_C_020 | BW18: =VLOOKUP(BV18,'Axe 2 Règles de gestion'!$D$2:$F$40,3, FALSE) -> Si l'absence ne commence pas par une demi-journée et si l'absence précédente ne finit pas par une demi journée, la date de début de l'absence saisie est postérieure à la date de fin prévisionnelle de l'absence précédente. | BX18: ABS_C_026 | BY18: =VLOOKUP(BX18,'Axe 2 Règles de gestion'!$D$2:$F$40,3, FALSE) -> Dans le cas d'un congé autre que CLM, CLD, CGM et CITIS, l'indicateur de requalification doit être à non et les impacts spécifiques à la requalification ne doivent pas être mobilisés ou l'impact rémunération est vide.
A19: 22.10.00 | B19: A | C19: 44854.498 | D19: D0007 | E19: Congés/Absence | F19: S0156 | G19: Congé pour création ou reprise d'entreprise | H19: E0893 | I19: Congé pour création ou reprise d'entreprise | J19: Type de congé/absence saisi = 'Congé pour création ou reprise d'entreprise' | K19: A_COA_TYCOAB [Saisi] = 'CF014' | L19: T2200 | M19: Congé pour création ou reprise d'entreprise - Fin | N19: Modification | O19: La valeur de l'Etat du congé saisie est égale à celle avant saisie | P19: A_COA_ETCOMA [Saisi] = A_COA_ETCOMA [Valeur avant saisie] | Q19: Militaire sous contrat | R19: P0145 | S19: Particulier | T19: Passant | U19: 43831 | W19: CCE_I_012 ET CCE_I_016 ET CCE_I_013 ET CCE_D_003 ET CCE_D_004 ET CCE_D_008 ET CCE_D_009 ET ABS_C_003 ET ABS_C_004 ET ABS_C_007 ET ABS_C_008 ET ABS_C_009 ET ABS_C_026 | X19: CCE_I_012 | Y19: =VLOOKUP(X19,'Axe 2 Règles de gestion'!$D$2:$F$40,3, FALSE) -> Si le congé n'est pas mis à profit pour créer, reprendre ou exploiter une entreprise, le ministre compétent notifie au militaire la fin du congé par anticipation. Il est alors radié des cadres ou rayé des contrôles. | Z19: CCE_I_016 | AA19: =VLOOKUP(Z19,'Axe 2 Règles de gestion'!$D$2:$F$40,3, FALSE) -> Le militaire qui souhaite interrompre le congé doit en faire la demande au moins 2 mois avant l'expiration du congé. Il est alors affecté dans un emploi de son grade. | AB19: CCE_I_013 | AC19: =VLOOKUP(AB19,'Axe 2 Règles de gestion'!$D$2:$F$40,3, FALSE) -> Le militaire est radié des cadres ou rayé des contrôles à titre définitif à l'expiration de ce congé. | AV19: CCE_D_003 | AW19: =VLOOKUP(AV19,'Axe 2 Règles de gestion'!$D$2:$F$40,3, FALSE) -> La durée maximale de chaque période est de 1 an (date de fin prévisionnelle de l'absence). | AX19: CCE_D_004 | AY19: =VLOOKUP(AX19,'Axe 2 Règles de gestion'!$D$2:$F$40,3, FALSE) -> La durée maximale de chaque période est de 1 an (date de fin réelle de l'absence). | AZ19: CCE_D_008 | BA19: =VLOOKUP(AZ19,'Axe 2 Règles de gestion'!$D$2:$F$40,3, FALSE) -> La date de fin réelle du congé doit être antérieure ou égale à la date limite de fin réelle ou prévisionnelle du lien juridique. Cependant le militaire peut voir son contrat prorogé jusqu'à la date de fin du congé dans la limite de la durée de service. | BB19: CCE_D_009 | BC19: =VLOOKUP(BB19,'Axe 2 Règles de gestion'!$D$2:$F$40,3, FALSE) -> La date de fin prévisionnelle du congé doit être antérieure ou égale à la date limite de fin réelle ou prévisionnelle du lien juridique. Cependant le militaire peut voir son contrat prorogé jusqu'à la date de fin du congé dans la limite de la durée de service. | BH19: ABS_C_003 | BI19: =VLOOKUP(BH19,'Axe 2 Règles de gestion'!$D$2:$F$40,3, FALSE) -> La date de début du congé/absence doit être antérieure ou égale à la date de fin réelle du congé/absence. | BJ19: ABS_C_004 | BK19: =VLOOKUP(BJ19,'Axe 2 Règles de gestion'!$D$2:$F$40,3, FALSE) -> La date de début du congé/absence doit être antérieure ou égale à la date de fin prévisionnelle du congé/absence. | BL19: ABS_C_007 | BM19: =VLOOKUP(BL19,'Axe 2 Règles de gestion'!$D$2:$F$40,3, FALSE) -> La date de fin réelle du congé/absence doit être antérieure à la date limite de départ à la retraite. | BN19: ABS_C_008 | BO19: =VLOOKUP(BN19,'Axe 2 Règles de gestion'!$D$2:$F$40,3, FALSE) -> La date de fin prévisionnelle du congé/absence doit être antérieure à la date limite de départ à la retraite. | BP19: ABS_C_009 | BQ19: =VLOOKUP(BP19,'Axe 2 Règles de gestion'!$D$2:$F$40,3, FALSE) -> La date de fin réelle ou la date de fin prévisionnelle du congé/absence doit être saisie. | BR19: ABS_C_026 | BS19: =VLOOKUP(BR19,'Axe 2 Règles de gestion'!$D$2:$F$40,3, FALSE) -> Dans le cas d'un congé autre que CLM, CLD, CGM et CITIS, l'indicateur de requalification doit être à non et les impacts spécifiques à la requalification ne doivent pas être mobilisés ou l'impact rémunération est vide.
A20: 22.10.00 | B20: A | C20: 44854.481 | D20: D0007 | E20: Congés/Absence | F20: S0156 | G20: Congé pour création ou reprise d'entreprise | H20: E0893 | I20: Congé pour création ou reprise d'entreprise | J20: Type de congé/absence saisi = 'Congé pour création ou reprise d'entreprise' | K20: A_COA_TYCOAB [Saisi] = 'CF014' | L20: T2198 | M20: Congé pour création ou reprise d'entreprise - Demande | N20: Création Modification | O20: La valeur de l'Etat du congé est 'Initial' et la valeur de l'Etat du congé saisie est différente de celle avant saisie | P20: A_COA_ETCOMA [Saisi] = 'EC01' ET A_COA_ETCOMA [Saisi] <> A_COA_ETCOMA [Valeur avant saisie] | Q20: Militaire de carrière | R20: P0189 | S20: Particulier | T20: Passant | U20: 43831 | W20: CCE_I_003 ET CCE_I_017 ET CCE_I_001 ET CCE_I_002 ET CCE_I_004 ET CCE_I_005 ET CCE_I_006 ET CCE_I_007 ET CCE_I_008 ET CCE_I_009 ET CCE_I_010 ET CCE_I_011 ET CCE_D_003 ET CCE_D_004 ET CCE_D_002 ET CCE_D_001 ET ABS_C_001 ET ABS_C_003 ET ABS_C_004 ET ABS_C_007 ET ABS_C_008 ET ABS_C_009 ET ABS_C_019 ET ABS_C_020 ET ABS_C_026 | X20: CCE_I_003 | Y20: =VLOOKUP(X20,'Axe 2 Règles de gestion'!$D$2:$F$40,3, FALSE) -> Le bénéfice d'un congé pour création ou reprise d'entreprise est exclusif de tout congé de reconversion et de congé complémentaire de reconversion. | Z20: CCE_I_017 | AA20: =VLOOKUP(Z20,'Axe 2 Règles de gestion'!$D$2:$F$40,3, FALSE) -> L'interdiction d'exercer à titre professionnel une activité privée lucrative et de participer aux organes de direction de sociétés ou d'associations à but lucratif n'est pas applicable dans le cadre de ce congé. | AB20: CCE_I_001 | AC20: =VLOOKUP(AB20,'Axe 2 Règles de gestion'!$D$2:$F$40,3, FALSE) -> Le militaire doit présenter une demande écrite à l'autorité dont il relève 2 mois au moins avant la date de création ou de reprise de l'entreprise. | AD20: CCE_I_002 | AE20: =VLOOKUP(AD20,'Axe 2 Règles de gestion'!$D$2:$F$40,3, FALSE) -> La demande mentionne la forme et l'objet social de l'entreprise susceptible d'être créée, son secteur et sa branche d'activité et, le cas échéant, la nature et le montant des subventions publiques dont cette entreprise est susceptible de bénéficier. | AF20: CCE_I_004 | AG20: =VLOOKUP(AF20,'Axe 2 Règles de gestion'!$D$2:$F$40,3, FALSE) -> Le ministre compétent saisit la commission de déontologie des militaires de cette demande dans le mois qui suit la date à laquelle elle l'a reçue. | AH20: CCE_I_005 | AI20: =VLOOKUP(AH20,'Axe 2 Règles de gestion'!$D$2:$F$40,3, FALSE) -> La commission rend son avis dans un délai d'1 mois à compter de l'enregistrement du dossier de saisine. | AJ20: CCE_I_006 | AK20: =VLOOKUP(AJ20,'Axe 2 Règles de gestion'!$D$2:$F$40,3, FALSE) -> L'absence d'avis de la commission à l'expiration du délai vaut avis favorable. | AL20: CCE_I_007 | AM20: =VLOOKUP(AL20,'Axe 2 Règles de gestion'!$D$2:$F$40,3, FALSE) -> L'avis de la commission est transmis au ministre compétent pour décision qui doit intervenir dans un délai d'1 mois à compter de la réception du dossier. | AN20: CCE_I_008 | AO20: =VLOOKUP(AN20,'Axe 2 Règles de gestion'!$D$2:$F$40,3, FALSE) -> L'absence de décision du ministre compétent dans le délai vaut refus d'attribution du congé. | AP20: CCE_I_009 | AQ20: =VLOOKUP(AP20,'Axe 2 Règles de gestion'!$D$2:$F$40,3, FALSE) -> En cas de décision favorable, le ministre compétent doit mentionner la durée du congé accordé. | AR20: CCE_I_010 | AS20: =VLOOKUP(AR20,'Axe 2 Règles de gestion'!$D$2:$F$40,3, FALSE) -> Pendant la durée du congé, le militaire se consacre obligatoirement à la création et à l'exploitation de l'entreprise qu'il crée ou reprend. | AT20: CCE_I_011 | AU20: =VLOOKUP(AT20,'Axe 2 Règles de gestion'!$D$2:$F$40,3, FALSE) -> Le ministre compétent peut faire procéder aux enquêtes nécessaires afin de vérifier si l'activité du militaire est conforme à l'objet du congé. | AV20: CCE_D_003 | AW20: =VLOOKUP(AV20,'Axe 2 Règles de gestion'!$D$2:$F$40,3, FALSE) -> La durée maximale de chaque période est de 1 an (date de fin prévisionnelle de l'absence). | AX20: CCE_D_004 | AY20: =VLOOKUP(AX20,'Axe 2 Règles de gestion'!$D$2:$F$40,3, FALSE) -> La durée maximale de chaque période est de 1 an (date de fin réelle de l'absence). | AZ20: CCE_D_002 | BA20: =VLOOKUP(AZ20,'Axe 2 Règles de gestion'!$D$2:$F$40,3, FALSE) -> Le militaire doit avoir accompli au moins 8 ans de services militaires effectifs. | BB20: CCE_D_001 | BC20: =VLOOKUP(BB20,'Axe 2 Règles de gestion'!$D$2:$F$40,3, FALSE) -> Le militaire est en activité. | BH20: ABS_C_001 | BI20: =VLOOKUP(BH20,'Axe 2 Règles de gestion'!$D$2:$F$40,3, FALSE) -> La date de début du congé/absence doit être postérieure ou égale à la date de recrutement dans la FPE ou dans la carrière militaire. | BJ20: ABS_C_003 | BK20: =VLOOKUP(BJ20,'Axe 2 Règles de gestion'!$D$2:$F$40,3, FALSE) -> La date de début du congé/absence doit être antérieure ou égale à la date de fin réelle du congé/absence. | BL20: ABS_C_004 | BM20: =VLOOKUP(BL20,'Axe 2 Règles de gestion'!$D$2:$F$40,3, FALSE) -> La date de début du congé/absence doit être antérieure ou égale à la date de fin prévisionnelle du congé/absence. | BN20: ABS_C_007 | BO20: =VLOOKUP(BN20,'Axe 2 Règles de gestion'!$D$2:$F$40,3, FALSE) -> La date de fin réelle du congé/absence doit être antérieure à la date limite de départ à la retraite. | BP20: ABS_C_008 | BQ20: =VLOOKUP(BP20,'Axe 2 Règles de gestion'!$D$2:$F$40,3, FALSE) -> La date de fin prévisionnelle du congé/absence doit être antérieure à la date limite de départ à la retraite. | BR20: ABS_C_009 | BS20: =VLOOKUP(BR20,'Axe 2 Règles de gestion'!$D$2:$F$40,3, FALSE) -> La date de fin réelle ou la date de fin prévisionnelle du congé/absence doit être saisie. | BT20: ABS_C_019 | BU20: =VLOOKUP(BT20,'Axe 2 Règles de gestion'!$D$2:$F$40,3, FALSE) -> Si l'absence ne commence pas par une demi-journée et si l'absence précédente ne finit pas par une demi journée, la date de début de l'absence saisie est postérieure à la date de fin réelle de l'absence précédente. | BV20: ABS_C_020 | BW20: =VLOOKUP(BV20,'Axe 2 Règles de gestion'!$D$2:$F$40,3, FALSE) -> Si l'absence ne commence pas par une demi-journée et si l'absence précédente ne finit pas par une demi journée, la date de début de l'absence saisie est postérieure à la date de fin prévisionnelle de l'absence précédente. | BX20: ABS_C_026 | BY20: =VLOOKUP(BX20,'Axe 2 Règles de gestion'!$D$2:$F$40,3, FALSE) -> Dans le cas d'un congé autre que CLM, CLD, CGM et CITIS, l'indicateur de requalification doit être à non et les impacts spécifiques à la requalification ne doivent pas être mobilisés ou l'impact rémunération est vide.
A21: 22.10.00 | B21: A | C21: 44854.49 | D21: D0007 | E21: Congés/Absence | F21: S0156 | G21: Congé pour création ou reprise d'entreprise | H21: E0893 | I21: Congé pour création ou reprise d'entreprise | J21: Type de congé/absence saisi = 'Congé pour création ou reprise d'entreprise' | K21: A_COA_TYCOAB [Saisi] = 'CF014' | L21: T2199 | M21: Congé pour création ou reprise d'entreprise - Renouvellement | N21: Création Modification | O21: La valeur de l'Etat du congé est 'Renouvellement' et la valeur de l'Etat du congé saisie est différente de celle avant saisie | P21: A_COA_ETCOMA [Saisi] = 'EC02' ET A_COA_ETCOMA [Saisi] <> A_COA_ETCOMA [Valeur avant saisie] | Q21: Militaire de carrière | R21: P0189 | S21: Particulier | T21: Passant | U21: 43831 | W21: CCE_I_017 ET CCE_I_014 ET CCE_I_002 ET CCE_I_004 ET CCE_I_005 ET CCE_I_006 ET CCE_I_007 ET CCE_I_008 ET CCE_I_009 ET CCE_I_015 ET CCE_I_010 ET CCE_I_011 ET CCE_D_003 ET CCE_D_004 ET CCE_D_005 ET ABS_C_003 ET ABS_C_004 ET ABS_C_007 ET ABS_C_008 ET ABS_C_009 ET ABS_C_019 ET ABS_C_020 ET ABS_C_026 | X21: CCE_I_017 | Y21: =VLOOKUP(X21,'Axe 2 Règles de gestion'!$D$2:$F$40,3, FALSE) -> L'interdiction d'exercer à titre professionnel une activité privée lucrative et de participer aux organes de direction de sociétés ou d'associations à but lucratif n'est pas applicable dans le cadre de ce congé. | Z21: CCE_I_014 | AA21: =VLOOKUP(Z21,'Axe 2 Règles de gestion'!$D$2:$F$40,3, FALSE) -> Le militaire qui souhaite prolonger la durée du congé doit en faire la demande au moins 2 mois avant l'échéance de la date mentionnée dans l'autorisation initiale. | AB21: CCE_I_002 | AC21: =VLOOKUP(AB21,'Axe 2 Règles de gestion'!$D$2:$F$40,3, FALSE) -> La demande mentionne la forme et l'objet social de l'entreprise susceptible d'être créée, son secteur et sa branche d'activité et, le cas échéant, la nature et le montant des subventions publiques dont cette entreprise est susceptible de bénéficier. | AD21: CCE_I_004 | AE21: =VLOOKUP(AD21,'Axe 2 Règles de gestion'!$D$2:$F$40,3, FALSE) -> Le ministre compétent saisit la commission de déontologie des militaires de cette demande dans le mois qui suit la date à laquelle elle l'a reçue. | AF21: CCE_I_005 | AG21: =VLOOKUP(AF21,'Axe 2 Règles de gestion'!$D$2:$F$40,3, FALSE) -> La commission rend son avis dans un délai d'1 mois à compter de l'enregistrement du dossier de saisine. | AH21: CCE_I_006 | AI21: =VLOOKUP(AH21,'Axe 2 Règles de gestion'!$D$2:$F$40,3, FALSE) -> L'absence d'avis de la commission à l'expiration du délai vaut avis favorable. | AJ21: CCE_I_007 | AK21: =VLOOKUP(AJ21,'Axe 2 Règles de gestion'!$D$2:$F$40,3, FALSE) -> L'avis de la commission est transmis au ministre compétent pour décision qui doit intervenir dans un délai d'1 mois à compter de la réception du dossier. | AL21: CCE_I_008 | AM21: =VLOOKUP(AL21,'Axe 2 Règles de gestion'!$D$2:$F$40,3, FALSE) -> L'absence de décision du ministre compétent dans le délai vaut refus d'attribution du congé. | AN21: CCE_I_009 | AO21: =VLOOKUP(AN21,'Axe 2 Règles de gestion'!$D$2:$F$40,3, FALSE) -> En cas de décision favorable, le ministre compétent doit mentionner la durée du congé accordé. | AP21: CCE_I_015 | AQ21: =VLOOKUP(AP21,'Axe 2 Règles de gestion'!$D$2:$F$40,3, FALSE) -> Toutefois si l'objet social de l'entreprise, son secteur et sa branche d'activité sont identiques à ceux de la demande initiale, l'autorisation de prorogation du congé est de droit. L'avis de la commission de déontologie n'est alors pas sollicité. | AR21: CCE_I_010 | AS21: =VLOOKUP(AR21,'Axe 2 Règles de gestion'!$D$2:$F$40,3, FALSE) -> Pendant la durée du congé, le militaire se consacre obligatoirement à la création et à l'exploitation de l'entreprise qu'il crée ou reprend. | AT21: CCE_I_011 | AU21: =VLOOKUP(AT21,'Axe 2 Règles de gestion'!$D$2:$F$40,3, FALSE) -> Le ministre compétent peut faire procéder aux enquêtes nécessaires afin de vérifier si l'activité du militaire est conforme à l'objet du congé. | AV21: CCE_D_003 | AW21: =VLOOKUP(AV21,'Axe 2 Règles de gestion'!$D$2:$F$40,3, FALSE) -> La durée maximale de chaque période est de 1 an (date de fin prévisionnelle de l'absence). | AX21: CCE_D_004 | AY21: =VLOOKUP(AX21,'Axe 2 Règles de gestion'!$D$2:$F$40,3, FALSE) -> La durée maximale de chaque période est de 1 an (date de fin réelle de l'absence). | AZ21: CCE_D_005 | BA21: =VLOOKUP(AZ21,'Axe 2 Règles de gestion'!$D$2:$F$40,3, FALSE) -> Le congé est renouvelable 1 fois. | BH21: ABS_C_003 | BI21: =VLOOKUP(BH21,'Axe 2 Règles de gestion'!$D$2:$F$40,3, FALSE) -> La date de début du congé/absence doit être antérieure ou égale à la date de fin réelle du congé/absence. | BJ21: ABS_C_004 | BK21: =VLOOKUP(BJ21,'Axe 2 Règles de gestion'!$D$2:$F$40,3, FALSE) -> La date de début du congé/absence doit être antérieure ou égale à la date de fin prévisionnelle du congé/absence. | BL21: ABS_C_007 | BM21: =VLOOKUP(BL21,'Axe 2 Règles de gestion'!$D$2:$F$40,3, FALSE) -> La date de fin réelle du congé/absence doit être antérieure à la date limite de départ à la retraite. | BN21: ABS_C_008 | BO21: =VLOOKUP(BN21,'Axe 2 Règles de gestion'!$D$2:$F$40,3, FALSE) -> La date de fin prévisionnelle du congé/absence doit être antérieure à la date limite de départ à la retraite. | BP21: ABS_C_009 | BQ21: =VLOOKUP(BP21,'Axe 2 Règles de gestion'!$D$2:$F$40,3, FALSE) -> La date de fin réelle ou la date de fin prévisionnelle du congé/absence doit être saisie. | BR21: ABS_C_019 | BS21: =VLOOKUP(BR21,'Axe 2 Règles de gestion'!$D$2:$F$40,3, FALSE) -> Si l'absence ne commence pas par une demi-journée et si l'absence précédente ne finit pas par une demi journée, la date de début de l'absence saisie est postérieure à la date de fin réelle de l'absence précédente. | BT21: ABS_C_020 | BU21: =VLOOKUP(BT21,'Axe 2 Règles de gestion'!$D$2:$F$40,3, FALSE) -> Si l'absence ne commence pas par une demi-journée et si l'absence précédente ne finit pas par une demi journée, la date de début de l'absence saisie est postérieure à la date de fin prévisionnelle de l'absence précédente. | BV21: ABS_C_026 | BW21: =VLOOKUP(BV21,'Axe 2 Règles de gestion'!$D$2:$F$40,3, FALSE) -> Dans le cas d'un congé autre que CLM, CLD, CGM et CITIS, l'indicateur de requalification doit être à non et les impacts spécifiques à la requalification ne doivent pas être mobilisés ou l'impact rémunération est vide.
A22: 22.10.00 | B22: A | C22: 44854.497 | D22: D0007 | E22: Congés/Absence | F22: S0156 | G22: Congé pour création ou reprise d'entreprise | H22: E0893 | I22: Congé pour création ou reprise d'entreprise | J22: Type de congé/absence saisi = 'Congé pour création ou reprise d'entreprise' | K22: A_COA_TYCOAB [Saisi] = 'CF014' | L22: T2200 | M22: Congé pour création ou reprise d'entreprise - Fin | N22: Modification | O22: La valeur de l'Etat du congé saisie est égale à celle avant saisie | P22: A_COA_ETCOMA [Saisi] = A_COA_ETCOMA [Valeur avant saisie] | Q22: Militaire de carrière | R22: P0189 | S22: Particulier | T22: Passant | U22: 43831 | W22: CCE_I_012 ET CCE_I_016 ET CCE_I_013 ET CCE_D_003 ET CCE_D_004 ET ABS_C_003 ET ABS_C_004 ET ABS_C_007 ET ABS_C_008 ET ABS_C_009 ET ABS_C_026 | X22: CCE_I_012 | Y22: =VLOOKUP(X22,'Axe 2 Règles de gestion'!$D$2:$F$40,3, FALSE) -> Si le congé n'est pas mis à profit pour créer, reprendre ou exploiter une entreprise, le ministre compétent notifie au militaire la fin du congé par anticipation. Il est alors radié des cadres ou rayé des contrôles. | Z22: CCE_I_016 | AA22: =VLOOKUP(Z22,'Axe 2 Règles de gestion'!$D$2:$F$40,3, FALSE) -> Le militaire qui souhaite interrompre le congé doit en faire la demande au moins 2 mois avant l'expiration du congé. Il est alors affecté dans un emploi de son grade. | AB22: CCE_I_013 | AC22: =VLOOKUP(AB22,'Axe 2 Règles de gestion'!$D$2:$F$40,3, FALSE) -> Le militaire est radié des cadres ou rayé des contrôles à titre définitif à l'expiration de ce congé. | AV22: CCE_D_003 | AW22: =VLOOKUP(AV22,'Axe 2 Règles de gestion'!$D$2:$F$40,3, FALSE) -> La durée maximale de chaque période est de 1 an (date de fin prévisionnelle de l'absence). | AX22: CCE_D_004 | AY22: =VLOOKUP(AX22,'Axe 2 Règles de gestion'!$D$2:$F$40,3, FALSE) -> La durée maximale de chaque période est de 1 an (date de fin réelle de l'absence). | BH22: ABS_C_003 | BI22: =VLOOKUP(BH22,'Axe 2 Règles de gestion'!$D$2:$F$40,3, FALSE) -> La date de début du congé/absence doit être antérieure ou égale à la date de fin réelle du congé/absence. | BJ22: ABS_C_004 | BK22: =VLOOKUP(BJ22,'Axe 2 Règles de gestion'!$D$2:$F$40,3, FALSE) -> La date de début du congé/absence doit être antérieure ou égale à la date de fin prévisionnelle du congé/absence. | BL22: ABS_C_007 | BM22: =VLOOKUP(BL22,'Axe 2 Règles de gestion'!$D$2:$F$40,3, FALSE) -> La date de fin réelle du congé/absence doit être antérieure à la date limite de départ à la retraite. | BN22: ABS_C_008 | BO22: =VLOOKUP(BN22,'Axe 2 Règles de gestion'!$D$2:$F$40,3, FALSE) -> La date de fin prévisionnelle du congé/absence doit être antérieure à la date limite de départ à la retraite. | BP22: ABS_C_009 | BQ22: =VLOOKUP(BP22,'Axe 2 Règles de gestion'!$D$2:$F$40,3, FALSE) -> La date de fin réelle ou la date de fin prévisionnelle du congé/absence doit être saisie. | BR22: ABS_C_026 | BS22: =VLOOKUP(BR22,'Axe 2 Règles de gestion'!$D$2:$F$40,3, FALSE) -> Dans le cas d'un congé autre que CLM, CLD, CGM et CITIS, l'indicateur de requalification doit être à non et les impacts spécifiques à la requalification ne doivent pas être mobilisés ou l'impact rémunération est vide.

Sheet Axe 1 Enchaînement RG Impact
A1: Version | B1: Type de mise à jour | C1: Date de mise à jour | D1: Identifiant Domaine | E1: Libellé du Domaine | F1: Identifiant Sous-domaine | G1: Libellé du Sous-domaine | H1: Identifiant Evénement | I1: Libellé de l'évènement | J1: Libellé condition déclenchement Evènement | K1: Condition déclenchement Evènement | L1: Identifiant type d'évènement | M1: Libellé type d'évènement | N1: Type de mise à jour | O1: Libellé condition déclenchement Type Evènement | P1: Condition déclenchement Type Evènement | Q1: Libellé Population | R1: Codification Population | S1: Général / Particulier | T1: Passant / Exclu | U1: Date de début | V1: Date de fin | W1: Impacts | X1: Identifiant Impacts 1 | Y1: Libellé Impacts 1 | Z1: Identifiant Impacts 2 | AA1: Libellé Impacts 2 | AB1: Identifiant Impacts 3 | AC1: Libellé Impacts 3 | AD1: Identifiant Impacts 4 | AE1: Libellé Impacts 4 | AF1: FIME | AG1: Statut de travail
A2: 22.10.00 | B2: A | C2: 44854.471 | D2: D0007 | E2: Congés/Absence | F2: S0156 | G2: Congé pour création ou reprise d'entreprise | H2: E0893 | I2: Congé pour création ou reprise d'entreprise | J2: Type de congé/absence saisi = 'Congé pour création ou reprise d'entreprise' | K2: A_COA_TYCOAB [Saisi] = 'CF014' | L2: T2198 | M2: Congé pour création ou reprise d'entreprise - Demande | N2: Création Modification | O2: La valeur de l'Etat du congé est 'Initial' et la valeur de l'Etat du congé saisie est différente de celle avant saisie | P2: A_COA_ETCOMA [Saisi] = 'EC01' ET A_COA_ETCOMA [Saisi] <> A_COA_ETCOMA [Valeur avant saisie] | Q2: Titulaire ou magistrat | R2: P0001 | S2: Général | T2: Exclu | U2: 43831
A3: 22.10.00 | B3: A | C3: 44854.484 | D3: D0007 | E3: Congés/Absence | F3: S0156 | G3: Congé pour création ou reprise d'entreprise | H3: E0893 | I3: Congé pour création ou reprise d'entreprise | J3: Type de congé/absence saisi = 'Congé pour création ou reprise d'entreprise' | K3: A_COA_TYCOAB [Saisi] = 'CF014' | L3: T2199 | M3: Congé pour création ou reprise d'entreprise - Renouvellement | N3: Création Modification | O3: La valeur de l'Etat du congé est 'Renouvellement' et la valeur de l'Etat du congé saisie est différente de celle avant saisie | P3: A_COA_ETCOMA [Saisi] = 'EC02' ET A_COA_ETCOMA [Saisi] <> A_COA_ETCOMA [Valeur avant saisie] | Q3: Titulaire ou magistrat | R3: P0001 | S3: Général | T3: Exclu | U3: 43831
A4: 22.10.00 | B4: A | C4: 44854.493 | D4: D0007 | E4: Congés/Absence | F4: S0156 | G4: Congé pour création ou reprise d'entreprise | H4: E0893 | I4: Congé pour création ou reprise d'entreprise | J4: Type de congé/absence saisi = 'Congé pour création ou reprise d'entreprise' | K4: A_COA_TYCOAB [Saisi] = 'CF014' | L4: T2200 | M4: Congé pour création ou reprise d'entreprise - Fin | N4: Modification | O4: La valeur de l'Etat du congé saisie est égale à celle avant saisie | P4: A_COA_ETCOMA [Saisi] = A_COA_ETCOMA [Valeur avant saisie] | Q4: Titulaire ou magistrat | R4: P0001 | S4: Général | T4: Exclu | U4: 43831
A5: 22.10.00 | B5: A | C5: 44854.472 | D5: D0007 | E5: Congés/Absence | F5: S0156 | G5: Congé pour création ou reprise d'entreprise | H5: E0893 | I5: Congé pour création ou reprise d'entreprise | J5: Type de congé/absence saisi = 'Congé pour création ou reprise d'entreprise' | K5: A_COA_TYCOAB [Saisi] = 'CF014' | L5: T2198 | M5: Congé pour création ou reprise d'entreprise - Demande | N5: Création Modification | O5: La valeur de l'Etat du congé est 'Initial' et la valeur de l'Etat du congé saisie est différente de celle avant saisie | P5: A_COA_ETCOMA [Saisi] = 'EC01' ET A_COA_ETCOMA [Saisi] <> A_COA_ETCOMA [Valeur avant saisie] | Q5: Militaire | R5: P0002 | S5: Général | T5: Exclu | U5: 43831
A6: 22.10.00 | B6: A | C6: 44854.485 | D6: D0007 | E6: Congés/Absence | F6: S0156 | G6: Congé pour création ou reprise d'entreprise | H6: E0893 | I6: Congé pour création ou reprise d'entreprise | J6: Type de congé/absence saisi = 'Congé pour création ou reprise d'entreprise' | K6: A_COA_TYCOAB [Saisi] = 'CF014' | L6: T2199 | M6: Congé pour création ou reprise d'entreprise - Renouvellement | N6: Création Modification | O6: La valeur de l'Etat du congé est 'Renouvellement' et la valeur de l'Etat du congé saisie est différente de celle avant saisie | P6: A_COA_ETCOMA [Saisi] = 'EC02' ET A_COA_ETCOMA [Saisi] <> A_COA_ETCOMA [Valeur avant saisie] | Q6: Militaire | R6: P0002 | S6: Général | T6: Exclu | U6: 43831
A7: 22.10.00 | B7: A | C7: 44854.493 | D7: D0007 | E7: Congés/Absence | F7: S0156 | G7: Congé pour création ou reprise d'entreprise | H7: E0893 | I7: Congé pour création ou reprise d'entreprise | J7: Type de congé/absence saisi = 'Congé pour création ou reprise d'entreprise' | K7: A_COA_TYCOAB [Saisi] = 'CF014' | L7: T2200 | M7: Congé pour création ou reprise d'entreprise - Fin | N7: Modification | O7: La valeur de l'Etat du congé saisie est égale à celle avant saisie | P7: A_COA_ETCOMA [Saisi] = A_COA_ETCOMA [Valeur avant saisie] | Q7: Militaire | R7: P0002 | S7: Général | T7: Exclu | U7: 43831
A8: 22.10.00 | B8: A | C8: 44854.472 | D8: D0007 | E8: Congés/Absence | F8: S0156 | G8: Congé pour création ou reprise d'entreprise | H8: E0893 | I8: Congé pour création ou reprise d'entreprise | J8: Type de congé/absence saisi = 'Congé pour création ou reprise d'entreprise' | K8: A_COA_TYCOAB [Saisi] = 'CF014' | L8: T2198 | M8: Congé pour création ou reprise d'entreprise - Demande | N8: Création Modification | O8: La valeur de l'Etat du congé est 'Initial' et la valeur de l'Etat du congé saisie est différente de celle avant saisie | P8: A_COA_ETCOMA [Saisi] = 'EC01' ET A_COA_ETCOMA [Saisi] <> A_COA_ETCOMA [Valeur avant saisie] | Q8: Contractuel | R8: P0003 | S8: Général | T8: Exclu | U8: 43831
A9: 22.10.00 | B9: A | C9: 44854.485 | D9: D0007 | E9: Congés/Absence | F9: S0156 | G9: Congé pour création ou reprise d'entreprise | H9: E0893 | I9: Congé pour création ou reprise d'entreprise | J9: Type de congé/absence saisi = 'Congé pour création ou reprise d'entreprise' | K9: A_COA_TYCOAB [Saisi] = 'CF014' | L9: T2199 | M9: Congé pour création ou reprise d'entreprise - Renouvellement | N9: Création Modification | O9: La valeur de l'Etat du congé est 'Renouvellement' et la valeur de l'Etat du congé saisie est différente de celle avant saisie | P9: A_COA_ETCOMA [Saisi] = 'EC02' ET A_COA_ETCOMA [Saisi] <> A_COA_ETCOMA [Valeur avant saisie] | Q9: Contractuel | R9: P0003 | S9: Général | T9: Exclu | U9: 43831
A10: 22.10.00 | B10: A | C10: 44854.494 | D10: D0007 | E10: Congés/Absence | F10: S0156 | G10: Congé pour création ou reprise d'entreprise | H10: E0893 | I10: Congé pour création ou reprise d'entreprise | J10: Type de congé/absence saisi = 'Congé pour création ou reprise d'entreprise' | K10: A_COA_TYCOAB [Saisi] = 'CF014' | L10: T2200 | M10: Congé pour création ou reprise d'entreprise - Fin | N10: Modification | O10: La valeur de l'Etat du congé saisie est égale à celle avant saisie | P10: A_COA_ETCOMA [Saisi] = A_COA_ETCOMA [Valeur avant saisie] | Q10: Contractuel | R10: P0003 | S10: Général | T10: Exclu | U10: 43831
A11: 22.10.00 | B11: A | C11: 44854.474 | D11: D0007 | E11: Congés/Absence | F11: S0156 | G11: Congé pour création ou reprise d'entreprise | H11: E0893 | I11: Congé pour création ou reprise d'entreprise | J11: Type de congé/absence saisi = 'Congé pour création ou reprise d'entreprise' | K11: A_COA_TYCOAB [Saisi] = 'CF014' | L11: T2198 | M11: Congé pour création ou reprise d'entreprise - Demande | N11: Création Modification | O11: La valeur de l'Etat du congé est 'Initial' et la valeur de l'Etat du congé saisie est différente de celle avant saisie | P11: A_COA_ETCOMA [Saisi] = 'EC01' ET A_COA_ETCOMA [Saisi] <> A_COA_ETCOMA [Valeur avant saisie] | Q11: Stagiaire ou auditeur ou élève | R11: P0004 | S11: Général | T11: Exclu | U11: 43831
A12: 22.10.00 | B12: A | C12: 44854.486 | D12: D0007 | E12: Congés/Absence | F12: S0156 | G12: Congé pour création ou reprise d'entreprise | H12: E0893 | I12: Congé pour création ou reprise d'entreprise | J12: Type de congé/absence saisi = 'Congé pour création ou reprise d'entreprise' | K12: A_COA_TYCOAB [Saisi] = 'CF014' | L12: T2199 | M12: Congé pour création ou reprise d'entreprise - Renouvellement | N12: Création Modification | O12: La valeur de l'Etat du congé est 'Renouvellement' et la valeur de l'Etat du congé saisie est différente de celle avant saisie | P12: A_COA_ETCOMA [Saisi] = 'EC02' ET A_COA_ETCOMA [Saisi] <> A_COA_ETCOMA [Valeur avant saisie] | Q12: Stagiaire ou auditeur ou élève | R12: P0004 | S12: Général | T12: Exclu | U12: 43831
A13: 22.10.00 | B13: A | C13: 44854.494 | D13: D0007 | E13: Congés/Absence | F13: S0156 | G13: Congé pour création ou reprise d'entreprise | H13: E0893 | I13: Congé pour création ou reprise d'entreprise | J13: Type de congé/absence saisi = 'Congé pour création ou reprise d'entreprise' | K13: A_COA_TYCOAB [Saisi] = 'CF014' | L13: T2200 | M13: Congé pour création ou reprise d'entreprise - Fin | N13: Modification | O13: La valeur de l'Etat du congé saisie est égale à celle avant saisie | P13: A_COA_ETCOMA [Saisi] = A_COA_ETCOMA [Valeur avant saisie] | Q13: Stagiaire ou auditeur ou élève | R13: P0004 | S13: Général | T13: Exclu | U13: 43831
... A16: 22.10.00 | B16: A | C16: 44854.494 | D16: D0007 | E16: Congés/Absence | F16: S0156 | G16: Congé pour création ou reprise d'entreprise | H16: E0893 | I16: Congé pour création ou reprise d'entreprise | J16: Type de congé/absence saisi = 'Congé pour création ou reprise d'entreprise' | K16: A_COA_TYCOAB [Saisi] = 'CF014' | L16: T2200 | M16: Congé pour création ou reprise d'entreprise - Fin | N16: Modification | O16: La valeur de l'Etat du congé saisie est égale à celle avant saisie | P16: A_COA_ETCOMA [Saisi] = A_COA_ETCOMA [Valeur avant saisie] | Q16: Ouvrier d'état | R16: P0005 | S16: Général | T16: Exclu | U16: 43831
A17: 22.10.00 | B17: A | C17: 44887.5 | D17: D0007 | E17: Congés/Absence | F17: S0156 | G17: Congé pour création ou reprise d'entreprise | H17: E0893 | I17: Congé pour création ou reprise d'entreprise | J17: Type de congé/absence saisi = 'Congé pour création ou reprise d'entreprise' | K17: A_COA_TYCOAB [Saisi] = 'CF014' | L17: T2198 | M17: Congé pour création ou reprise d'entreprise - Demande | N17: Création Modification | O17: La valeur de l'Etat du congé est 'Initial' et la valeur de l'Etat du congé saisie est différente de celle avant saisie | P17: A_COA_ETCOMA [Saisi] = 'EC01' ET A_COA_ETCOMA [Saisi] <> A_COA_ETCOMA [Valeur avant saisie] | Q17: Militaire sous contrat | R17: P0145 | S17: Particulier | T17: Passant | U17: 43831 | W17: CCE_P_001 ET CCE_P_002 ET CCE_P_003 ET CCE_P_005 | X17: CCE_P_001 | Y17: =VLOOKUP(X17,'Axe 2 Règles de gestion'!$D$2:$F$40,3, FALSE) -> Rémunération : Durant ce congé, le militaire perçoit la rémunération de son grade. | Z17: CCE_P_002 | AA17: =VLOOKUP(Z17,'Axe 2 Règles de gestion'!$D$2:$F$40,3, FALSE) -> Carrière : La durée de ce congé compte pour les droits à avancement. | AB17: CCE_P_003 | AC17: =VLOOKUP(AB17,'Axe 2 Règles de gestion'!$D$2:$F$40,3, FALSE) -> Retraite : La durée de ce congé compte pour les droits à pension. | AD17: CCE_P_005 | AE17: =VLOOKUP(AD17,'Axe 2 Règles de gestion'!$D$2:$F$40,3, FALSE) -> Acte : Un acte administratif doit être produit.
A18: 22.10.00 | B18: A | C18: 44887.501 | D18: D0007 | E18: Congés/Absence | F18: S0156 | G18: Congé pour création ou reprise d'entreprise | H18: E0893 | I18: Congé pour création ou reprise d'entreprise | J18: Type de congé/absence saisi = 'Congé pour création ou reprise d'entreprise' | K18: A_COA_TYCOAB [Saisi] = 'CF014' | L18: T2199 | M18: Congé pour création ou reprise d'entreprise - Renouvellement | N18: Création Modification | O18: La valeur de l'Etat du congé est 'Renouvellement' et la valeur de l'Etat du congé saisie est différente de celle avant saisie | P18: A_COA_ETCOMA [Saisi] = 'EC02' ET A_COA_ETCOMA [Saisi] <> A_COA_ETCOMA [Valeur avant saisie] | Q18: Militaire sous contrat | R18: P0145 | S18: Particulier | T18: Passant | U18: 43831 | W18: CCE_P_004 ET CCE_P_002 ET CCE_P_003 ET CCE_P_005 | X18: CCE_P_004 | Y18: =VLOOKUP(X18,'Axe 2 Règles de gestion'!$D$2:$F$40,3, FALSE) -> Rémunération : Lorsque le congé est renouvelé, le militaire perçoit pendant la période de renouvellement, la rémunération de son grade réduite de moitié. | Z18: CCE_P_002 | AA18: =VLOOKUP(Z18,'Axe 2 Règles de gestion'!$D$2:$F$40,3, FALSE) -> Carrière : La durée de ce congé compte pour les droits à avancement. | AB18: CCE_P_003 | AC18: =VLOOKUP(AB18,'Axe 2 Règles de gestion'!$D$2:$F$40,3, FALSE) -> Retraite : La durée de ce congé compte pour les droits à pension. | AD18: CCE_P_005 | AE18: =VLOOKUP(AD18,'Axe 2 Règles de gestion'!$D$2:$F$40,3, FALSE) -> Acte : Un acte administratif doit être produit.
