Workbook

Sheet Mode opératoire
B1: MODE OPERATOIRE
B2: La transaction s'effectue pour l'évènement E0971 'Compte épargne-temps' au niveau des sous rubriques : - Compte épargne-temps - Ouverture - Compte épargne-temps - Alimentation - Compte épargne-temps - Choix d'option La transaction s'effectue pour l'évènement E0972 'Compte épargne-temps historique' au niveau de la sous rubrique : - Compte épargne-temps historique - Choix d'option La transaction s'effectue pour l'évènement E0973 'Compte épargne-temps - Mobilité/Fin de fonction' au niveau de la sous rubrique : - Compte épargne-temps - Mobilité/Fin de fonction

Sheet Axe 1 Enchainement des RG
A1: Version | B1: Type de mise à jour | C1: Date de mise à jour | D1: Identifiant Domaine | E1: Libellé du Domaine | F1: Identifiant Sous-domaine | G1: Libellé du Sous-domaine | H1: Identifiant Evénement | I1: Libellé de l'évènement | J1: Libellé condition déclenchement Evènement | K1: Condition déclenchement Evènement | L1: Identifiant type d'évènement | M1: Libellé type d'évènement | N1: Type de mise à jour | O1: Libellé condition déclenchement Type Evènement | P1: Condition déclenchement Type Evènement | Q1: Libellé Population | R1: Codification Population | S1: Général / Particulier | T1: Passant / Exclu | U1: Date de début | V1: Date de fin | W1: Règles mobilisées | X1: Identifiant Règle de contrôle intellectuel 1 | Y1: Libellé Règle de contrôle intellectuel 1 | Z1: Identifiant Règle de contrôle intellectuel 2 | AA1: Libellé Règle de contrôle intellectuel 2 | AB1: Identifiant Règle de contrôle intellectuel 3 | AC1: Libellé Règle de contrôle intellectuel 3 | AD1: Identifiant Règle de contrôle intellectuel 4 | AE1: Libellé Règle de contrôle intellectuel 4 | AF1: Identifiant Règle de contrôle intellectuel 5 | AG1: Libellé Règle de contrôle intellectuel 5 | AH1: Identifiant Règle de contrôle intellectuel 6 | AI1: Libellé Règle de contrôle intellectuel 6 | AJ1: Identifiant Règle de condition 1 | AK1: Libellé Règle de condition 1 | AL1: Identifiant Règle de condition 2 | AM1: Libellé Règle de condition 2 | AN1: Identifiant Règle de condition 3 | AO1: Libellé Règle de condition 3 | AP1: Identifiant Règle de condition 4 | AQ1: Libellé Règle de condition 4 | AR1: Identifiant Règle de contrôle 1 | AS1: Libellé Règle de contrôle 1 | AT1: Identifiant Règle de contrôle 2 | AU1: Libellé Règle de contrôle 2 | AV1: Identifiant Règle de contrôle 3 | AW1: Libellé Règle de contrôle 3 | AX1: Identifiant Règle de contrôle 4 | AY1: Libellé Règle de contrôle 4 | AZ1: FIME | BA1: Statut de travail
A2: 24.10.00 | B2: A | C2: 45628.64 | D2: D0007 | E2: Congés/Absence | F2: S0183 | G2: Compte épargne-temps | H2: E0971 | I2: Compte épargne-temps (CET) | J2: La date d'observation saisie du CET est non vide | K2: A_CET_DAGCET [Saisi] <> Vide | L2: T2358 | M2: Compte épargne-temps - Ouverture | N2: Création Modification | O2: La date d'ouverture saisie est non vide et la date de l'opération est vide | P2: A_CET_DCRCET [Saisi] <> VIDE ET A_CET_DOOCET [Saisi] = VIDE | Q2: Titulaire ou magistrat | R2: P0001 | S2: Général | T2: Passant | U2: 45323 | W2: CET_I_050 ET CET_D_400 ET CET_D_407 ET CET_C_017 ET CET_C_031 | X2: CET_I_050 | Y2: =VLOOKUP(X2,'Axe 2 Règles de gestion'!$D$2:$F$43,3, FALSE) -> L'agent doit effectuer une demande d'ouverture d'un compte épargne-temps. | AJ2: CET_D_400 | AK2: =VLOOKUP(AJ2,'Axe 2 Règles de gestion'!$D$2:$F$43,3, FALSE) -> L'agent ne doit pas relever des régimes d'obligation de service. | AL2: CET_D_407 | AM2: =VLOOKUP(AL2,'Axe 2 Règles de gestion'!$D$2:$F$43,3, FALSE) -> L'agent est employé de manière continue et a accompli au moins 1 année de service. | AR2: CET_C_017 | AS2: =VLOOKUP(AR2,'Axe 2 Règles de gestion'!$D$2:$F$43,3, FALSE) -> La date d'ouverture du compte épargne temps global doit être postérieure ou égale à la date d'entrée dans le SIRH. | AT2: CET_C_031 | AU2: =VLOOKUP(AT2,'Axe 2 Règles de gestion'!$D$2:$F$43,3, FALSE) -> Les champs "Origine", "Nombre de jours de l'opération", "Nombre de jours pour valorisation financière" et "Nombre de jours pour cotisation RAFP" ne doivent pas être renseignés.
A3: 24.10.00 | B3: A | C3: 45628.644 | D3: D0007 | E3: Congés/Absence | F3: S0183 | G3: Compte épargne-temps | H3: E0971 | I3: Compte épargne-temps (CET) | J3: La date d'observation saisie du CET est non vide | K3: A_CET_DAGCET [Saisi] <> Vide | L3: T2359 | M3: Compte épargne-temps - Alimentation | N3: Création Modification | O3: La date de l'opération saisie est non vide et le sens de l'opération est "Versé" | P3: A_CET_DOOCET [Saisi] <> Vide ET A_CET_SEOCET [Saisi] = 'V' | Q3: Titulaire ou magistrat | R3: P0001 | S3: Général | T3: Passant | U3: 45323 | V3: 45688 | W3: CET_I_061 ET CET_I_060 ET CET_D_401 ET CET_D_402 ET CET_D_403 ET CET_D_404 ET CET_C_023 ET CET_C_026 | X3: CET_I_061 | Y3: =VLOOKUP(X3,'Axe 2 Règles de gestion'!$D$2:$F$43,3, FALSE) -> Pour les agents en service à l'étranger, le compte épargne-temps est alimenté par le report des jours de congés annuels dont ils bénéficient au titre du pays dans lequel ils sont affectés. | Z3: CET_I_060 | AA3: =VLOOKUP(Z3,'Axe 2 Règles de gestion'!$D$2:$F$43,3, FALSE) -> L'agent ne peut pas alimenter son compte épargne-temps par le report de congés bonifiés. | AJ3: CET_D_401 | AK3: =VLOOKUP(AJ3,'Axe 2 Règles de gestion'!$D$2:$F$43,3, FALSE) -> L'agent peut alimenter son compte épargne-temps par le report de jours de réduction du temps de travail, par le report de congés annuels et de fractionnement et si un arrêté le prévoit par le report de jours de repos compensateur. | AL3: CET_D_402 | AM3: =VLOOKUP(AL3,'Axe 2 Règles de gestion'!$D$2:$F$43,3, FALSE) -> L'agent pour pouvoir alimenter son compte épargne-temps doit avoir pris dans l'année au moins 20 jours de congés. | AN3: CET_D_403 | AO3: =VLOOKUP(AN3,'Axe 2 Règles de gestion'!$D$2:$F$43,3, FALSE) -> Lorsque le compte épargne-temps atteint 15 jours, l'agent peut épargner ensuite chaque année 10 jours au maximum. | AP3: CET_D_404 | AQ3: =VLOOKUP(AP3,'Axe 2 Règles de gestion'!$D$2:$F$43,3, FALSE) -> L'agent peut au titre de l'année 2024, lorsque le compte épargne-temps atteint 15 jours, épargner 20 jours au maximum en raison de l'organisation des jeux olympiques et paralympiques. | AR3: CET_C_023 | AS3: =VLOOKUP(AR3,'Axe 2 Règles de gestion'!$D$2:$F$43,3, FALSE) -> Lorsque le sens de l'opération est à "Versé", le compteur global saisi est égal au compteur global de l'occurrence précédente auquel sont ajoutés les jours versés. | AT3: CET_C_026 | AU3: =VLOOKUP(AT3,'Axe 2 Règles de gestion'!$D$2:$F$43,3, FALSE) -> Lorsque le sens de l'opération est égal à "versé", le nombre de jours pour valorisation financière et le nombre de jours pour cotisation RAFP ne doivent pas être renseignés.
A4: 24.10.00 | B4: A | C4: 45628.645 | D4: D0007 | E4: Congés/Absence | F4: S0183 | G4: Compte épargne-temps | H4: E0971 | I4: Compte épargne-temps (CET) | J4: La date d'observation saisie du CET est non vide | K4: A_CET_DAGCET [Saisi] <> Vide | L4: T2359 | M4: Compte épargne-temps - Alimentation | N4: Création Modification | O4: La date de l'opération saisie est non vide et le sens de l'opération est "Versé" | P4: A_CET_DOOCET [Saisi] <> Vide ET A_CET_SEOCET [Saisi] = 'V' | Q4: Titulaire ou magistrat | R4: P0001 | S4: Général | T4: Passant | U4: 45689 | W4: CET_I_061 ET CET_I_060 ET CET_D_401 ET CET_D_402 ET CET_D_403 ET CET_C_023 ET CET_C_026 | X4: CET_I_061 | Y4: =VLOOKUP(X4,'Axe 2 Règles de gestion'!$D$2:$F$43,3, FALSE) -> Pour les agents en service à l'étranger, le compte épargne-temps est alimenté par le report des jours de congés annuels dont ils bénéficient au titre du pays dans lequel ils sont affectés. | Z4: CET_I_060 | AA4: =VLOOKUP(Z4,'Axe 2 Règles de gestion'!$D$2:$F$43,3, FALSE) -> L'agent ne peut pas alimenter son compte épargne-temps par le report de congés bonifiés. | AJ4: CET_D_401 | AK4: =VLOOKUP(AJ4,'Axe 2 Règles de gestion'!$D$2:$F$43,3, FALSE) -> L'agent peut alimenter son compte épargne-temps par le report de jours de réduction du temps de travail, par le report de congés annuels et de fractionnement et si un arrêté le prévoit par le report de jours de repos compensateur. | AL4: CET_D_402 | AM4: =VLOOKUP(AL4,'Axe 2 Règles de gestion'!$D$2:$F$43,3, FALSE) -> L'agent pour pouvoir alimenter son compte épargne-temps doit avoir pris dans l'année au moins 20 jours de congés. | AN4: CET_D_403 | AO4: =VLOOKUP(AN4,'Axe 2 Règles de gestion'!$D$2:$F$43,3, FALSE) -> Lorsque le compte épargne-temps atteint 15 jours, l'agent peut épargner ensuite chaque année 10 jours au maximum. | AR4: CET_C_023 | AS4: =VLOOKUP(AR4,'Axe 2 Règles de gestion'!$D$2:$F$43,3, FALSE) -> Lorsque le sens de l'opération est à "Versé", le compteur global saisi est égal au compteur global de l'occurrence précédente auquel sont ajoutés les jours versés. | AT4: CET_C_026 | AU4: =VLOOKUP(AT4,'Axe 2 Règles de gestion'!$D$2:$F$43,3, FALSE) -> Lorsque le sens de l'opération est égal à "versé", le nombre de jours pour valorisation financière et le nombre de jours pour cotisation RAFP ne doivent pas être renseignés.
A5: 24.10.00 | B5: A | C5: 45628.659 | D5: D0007 | E5: Congés/Absence | F5: S0183 | G5: Compte épargne-temps | H5: E0971 | I5: Compte épargne-temps (CET) | J5: La date d'observation saisie du CET est non vide | K5: A_CET_DAGCET [Saisi] <> Vide | L5: T2360 | M5: Compte épargne-temps - Choix d'option | N5: Création Modification | O5: La date de l'opération saisie est non vide et le sens de l'opération est "Consommé" | P5: A_CET_DOOCET [Saisi] <> Vide ET A_CET_SEOCET [Saisi] = 'C' | Q5: Titulaire ou magistrat | R5: P0001 | S5: Général | T5: Passant | U5: 45323 | W5: CET_I_052 ET CET_I_054 ET CET_I_055 ET CET_I_057 ET CET_I_059 ET CET_D_405 ET CET_D_406 ET CET_D_408 ET CET_C_004 ET CET_C_024 ET CET_C_027 | X5: CET_I_052 | Y5: =VLOOKUP(X5,'Axe 2 Règles de gestion'!$D$2:$F$43,3, FALSE) -> L'agent est informé chaque année, par l'administration, des jours épargnés et consommés. | Z5: CET_I_054 | AA5: =VLOOKUP(Z5,'Axe 2 Règles de gestion'!$D$2:$F$43,3, FALSE) -> Si le nombre de jours inscrits est supérieur à 15 jours au terme de l'année civile, l'agent ne peut utiliser ces 15 jours que sous forme de congés, pour les autres jours il doit exercer une option au plus le tard le 31 janvier de l'année suivante. | AB5: CET_I_055 | AC5: =VLOOKUP(AB5,'Axe 2 Règles de gestion'!$D$2:$F$43,3, FALSE) -> L'agent peut opter dans les proportions qu'il souhaite pour un prise en compte au sein du régime de retraite additionnelle de la fonction publique, pour une indemnisation ou pour un maintien sur le compte épargne-temps. | AD5: CET_I_057 | AE5: =VLOOKUP(AD5,'Axe 2 Règles de gestion'!$D$2:$F$43,3, FALSE) -> Si l'agent n'exerce pas son droit d'option, les jours au-delà de 15 sont pris en compte au sein du régime de retraite additionnelle de la fonction publique. | AF5: CET_I_059 | AG5: =VLOOKUP(AF5,'Axe 2 Règles de gestion'!$D$2:$F$43,3, FALSE) -> Les années suivantes, les jours ainsi épargnés excédant le plafond global de jours prévu peuvent être maintenus sur le compte épargne-temps ou être consommés. | AJ5: CET_D_405 | AK5: =VLOOKUP(AJ5,'Axe 2 Règles de gestion'!$D$2:$F$43,3, FALSE) -> Le nombre de jours maintenus sur le compte épargne-temps ne doit pas dépasser un plafond annuel de 60 jours. | AL5: CET_D_406 | AM5: =VLOOKUP(AL5,'Axe 2 Règles de gestion'!$D$2:$F$43,3, FALSE) -> Au terme de l'année 2024, en raison de l'organisation des jeux olympiques et paralympiques, ce plafond annuel passe à 70 jours ou si le nombre de jours épargnés au terme de l'année 2023 excède 60 jours, au nombre de jours épargnés augmentés de 10 jours. | AN5: CET_D_408 | AO5: =VLOOKUP(AN5,'Axe 2 Règles de gestion'!$D$2:$F$43,3, FALSE) -> Si le nombre de jours inscrits sur le compte épargne-temps est inférieur ou égal à 15 jours au terme de l'année civile, l'agent ne peut utiliser ces jours épargnés que sous forme de congés. | AR5: CET_C_004 | AS5: =VLOOKUP(AR5,'Axe 2 Règles de gestion'!$D$2:$F$43,3, FALSE) -> Le nombre de jours de l'opération doit être inférieur ou égal au nombre de jours du compteur global du CET. | AT5: CET_C_024 | AU5: =VLOOKUP(AT5,'Axe 2 Règles de gestion'!$D$2:$F$43,3, FALSE) -> Lorsque le sens de l'opération est à "consommé", le compteur global saisi est égal au compteur global de l'occurrence précédente duquel sont soustraits les jours consommés en congés, les jours pour valorisation financière et les jours pour cotisation RAFP. | AV5: CET_C_027 | AW5: =VLOOKUP(AV5,'Axe 2 Règles de gestion'!$D$2:$F$43,3, FALSE) -> Lorsque le sens de l'opération est égal à "consommé", l'origine des jours n'est pas à renseigner.
A6: 24.10.00 | B6: A | C6: 45628.64 | D6: D0007 | E6: Congés/Absence | F6: S0183 | G6: Compte épargne-temps | H6: E0971 | I6: Compte épargne-temps (CET) | J6: La date d'observation saisie du CET est non vide | K6: A_CET_DAGCET [Saisi] <> Vide | L6: T2358 | M6: Compte épargne-temps - Ouverture | N6: Création Modification | O6: La date d'ouverture saisie est non vide et la date de l'opération est vide | P6: A_CET_DCRCET [Saisi] <> VIDE ET A_CET_DOOCET [Saisi] = VIDE | Q6: Militaire | R6: P0002 | S6: Général | T6: Exclu | U6: 45323
A7: 24.10.00 | B7: A | C7: 45628.645 | D7: D0007 | E7: Congés/Absence | F7: S0183 | G7: Compte épargne-temps | H7: E0971 | I7: Compte épargne-temps (CET) | J7: La date d'observation saisie du CET est non vide | K7: A_CET_DAGCET [Saisi] <> Vide | L7: T2359 | M7: Compte épargne-temps - Alimentation | N7: Création Modification | O7: La date de l'opération saisie est non vide et le sens de l'opération est "Versé" | P7: A_CET_DOOCET [Saisi] <> Vide ET A_CET_SEOCET [Saisi] = 'V' | Q7: Militaire | R7: P0002 | S7: Général | T7: Exclu | U7: 45323
A8: 24.10.00 | B8: A | C8: 45628.66 | D8: D0007 | E8: Congés/Absence | F8: S0183 | G8: Compte épargne-temps | H8: E0971 | I8: Compte épargne-temps (CET) | J8: La date d'observation saisie du CET est non vide | K8: A_CET_DAGCET [Saisi] <> Vide | L8: T2360 | M8: Compte épargne-temps - Choix d'option | N8: Création Modification | O8: La date de l'opération saisie est non vide et le sens de l'opération est "Consommé" | P8: A_CET_DOOCET [Saisi] <> Vide ET A_CET_SEOCET [Saisi] = 'C' | Q8: Militaire | R8: P0002 | S8: Général | T8: Exclu | U8: 45323
A9: 24.10.00 | B9: A | C9: 45628.64 | D9: D0007 | E9: Congés/Absence | F9: S0183 | G9: Compte épargne-temps | H9: E0971 | I9: Compte épargne-temps (CET) | J9: La date d'observation saisie du CET est non vide | K9: A_CET_DAGCET [Saisi] <> Vide | L9: T2358 | M9: Compte épargne-temps - Ouverture | N9: Création Modification | O9: La date d'ouverture saisie est non vide et la date de l'opération est vide | P9: A_CET_DCRCET [Saisi] <> VIDE ET A_CET_DOOCET [Saisi] = VIDE | Q9: Contractuel | R9: P0003 | S9: Général | T9: Passant | U9: 45323 | W9: CET_I_050 ET CET_D_400 ET CET_D_407 ET CET_C_017 ET CET_C_031 | X9: CET_I_050 | Y9: =VLOOKUP(X9,'Axe 2 Règles de gestion'!$D$2:$F$43,3, FALSE) -> L'agent doit effectuer une demande d'ouverture d'un compte épargne-temps. | AJ9: CET_D_400 | AK9: =VLOOKUP(AJ9,'Axe 2 Règles de gestion'!$D$2:$F$43,3, FALSE) -> L'agent ne doit pas relever des régimes d'obligation de service. | AL9: CET_D_407 | AM9: =VLOOKUP(AL9,'Axe 2 Règles de gestion'!$D$2:$F$43,3, FALSE) -> L'agent est employé de manière continue et a accompli au moins 1 année de service. | AR9: CET_C_017 | AS9: =VLOOKUP(AR9,'Axe 2 Règles de gestion'!$D$2:$F$43,3, FALSE) -> La date d'ouverture du compte épargne temps global doit être postérieure ou égale à la date d'entrée dans le SIRH. | AT9: CET_C_031 | AU9: =VLOOKUP(AT9,'Axe 2 Règles de gestion'!$D$2:$F$43,3, FALSE) -> Les champs "Origine", "Nombre de jours de l'opération", "Nombre de jours pour valorisation financière" et "Nombre de jours pour cotisation RAFP" ne doivent pas être renseignés.
A10: 24.10.00 | B10: A | C10: 45635.722 | D10: D0007 | E10: Congés/Absence | F10: S0183 | G10: Compte épargne-temps | H10: E0971 | I10: Compte épargne-temps (CET) | J10: La date d'observation saisie du CET est non vide | K10: A_CET_DAGCET [Saisi] <> Vide | L10: T2359 | M10: Compte épargne-temps - Alimentation | N10: Création Modification | O10: La date de l'opération saisie est non vide et le sens de l'opération est "Versé" | P10: A_CET_DOOCET [Saisi] <> Vide ET A_CET_SEOCET [Saisi] = 'V' | Q10: Contractuel | R10: P0003 | S10: Général | T10: Passant | U10: 45323 | V10: 45688 | W10: CET_I_061 ET CET_I_060 ET CET_D_401 ET CET_D_402 ET CET_D_403 ET CET_D_404 ET CET_C_023 ET CET_C_026 | X10: CET_I_061 | Y10: =VLOOKUP(X10,'Axe 2 Règles de gestion'!$D$2:$F$43,3, FALSE) -> Pour les agents en service à l'étranger, le compte épargne-temps est alimenté par le report des jours de congés annuels dont ils bénéficient au titre du pays dans lequel ils sont affectés. | Z10: CET_I_060 | AA10: =VLOOKUP(Z10,'Axe 2 Règles de gestion'!$D$2:$F$43,3, FALSE) -> L'agent ne peut pas alimenter son compte épargne-temps par le report de congés bonifiés. | AJ10: CET_D_401 | AK10: =VLOOKUP(AJ10,'Axe 2 Règles de gestion'!$D$2:$F$43,3, FALSE) -> L'agent peut alimenter son compte épargne-temps par le report de jours de réduction du temps de travail, par le report de congés annuels et de fractionnement et si un arrêté le prévoit par le report de jours de repos compensateur. | AL10: CET_D_402 | AM10: =VLOOKUP(AL10,'Axe 2 Règles de gestion'!$D$2:$F$43,3, FALSE) -> L'agent pour pouvoir alimenter son compte épargne-temps doit avoir pris dans l'année au moins 20 jours de congés. | AN10: CET_D_403 | AO10: =VLOOKUP(AN10,'Axe 2 Règles de gestion'!$D$2:$F$43,3, FALSE) -> Lorsque le compte épargne-temps atteint 15 jours, l'agent peut épargner ensuite chaque année 10 jours au maximum. | AP10: CET_D_404 | AQ10: =VLOOKUP(AP10,'Axe 2 Règles de gestion'!$D$2:$F$43,3, FALSE) -> L'agent peut au titre de l'année 2024, lorsque le compte épargne-temps atteint 15 jours, épargner 20 jours au maximum en raison de l'organisation des jeux olympiques et paralympiques. | AR10: CET_C_023 | AS10: =VLOOKUP(AR10,'Axe 2 Règles de gestion'!$D$2:$F$43,3, FALSE) -> Lorsque le sens de l'opération est à "Versé", le compteur global saisi est égal au compteur global de l'occurrence précédente auquel sont ajoutés les jours versés. | AT10: CET_C_026 | AU10: =VLOOKUP(AT10,'Axe 2 Règles de gestion'!$D$2:$F$43,3, FALSE) -> Lorsque le sens de l'opération est égal à "versé", le nombre de jours pour valorisation financière et le nombre de jours pour cotisation RAFP ne doivent pas être renseignés.
A11: 24.10.00 | B11: A | C11: 45635.722 | D11: D0007 | E11: Congés/Absence | F11: S0183 | G11: Compte épargne-temps | H11: E0971 | I11: Compte épargne-temps (CET) | J11: La date d'observation saisie du CET est non vide | K11: A_CET_DAGCET [Saisi] <> Vide | L11: T2359 | M11: Compte épargne-temps - Alimentation | N11: Création Modification | O11: La date de l'opération saisie est non vide et le sens de l'opération est "Versé" | P11: A_CET_DOOCET [Saisi] <> Vide ET A_CET_SEOCET [Saisi] = 'V' | Q11: Contractuel | R11: P0003 | S11: Général | T11: Passant | U11: 45689 | W11: CET_I_061 ET CET_I_060 ET CET_D_401 ET CET_D_402 ET CET_D_403 ET CET_C_023 ET CET_C_026 | X11: CET_I_061 | Y11: =VLOOKUP(X11,'Axe 2 Règles de gestion'!$D$2:$F$43,3, FALSE) -> Pour les agents en service à l'étranger, le compte épargne-temps est alimenté par le report des jours de congés annuels dont ils bénéficient au titre du pays dans lequel ils sont affectés. | Z11: CET_I_060 | AA11: =VLOOKUP(Z11,'Axe 2 Règles de gestion'!$D$2:$F$43,3, FALSE) -> L'agent ne peut pas alimenter son compte épargne-temps par le report de congés bonifiés. | AJ11: CET_D_401 | AK11: =VLOOKUP(AJ11,'Axe 2 Règles de gestion'!$D$2:$F$43,3, FALSE) -> L'agent peut alimenter son compte épargne-temps par le report de jours de réduction du temps de travail, par le report de congés annuels et de fractionnement et si un arrêté le prévoit par le report de jours de repos compensateur. | AL11: CET_D_402 | AM11: =VLOOKUP(AL11,'Axe 2 Règles de gestion'!$D$2:$F$43,3, FALSE) -> L'agent pour pouvoir alimenter son compte épargne-temps doit avoir pris dans l'année au moins 20 jours de congés. | AN11: CET_D_403 | AO11: =VLOOKUP(AN11,'Axe 2 Règles de gestion'!$D$2:$F$43,3, FALSE) -> Lorsque le compte épargne-temps atteint 15 jours, l'agent peut épargner ensuite chaque année 10 jours au maximum. | AR11: CET_C_023 | AS11: =VLOOKUP(AR11,'Axe 2 Règles de gestion'!$D$2:$F$43,3, FALSE) -> Lorsque le sens de l'opération est à "Versé", le compteur global saisi est égal au compteur global de l'occurrence précédente auquel sont ajoutés les jours versés. | AT11: CET_C_026 | AU11: =VLOOKUP(AT11,'Axe 2 Règles de gestion'!$D$2:$F$43,3, FALSE) -> Lorsque le sens de l'opération est égal à "versé", le nombre de jours pour valorisation financière et le nombre de jours pour cotisation RAFP ne doivent pas être renseignés.
A12: 24.10.00 | B12: A | C12: 45628.66 | D12: D0007 | E12: Congés/Absence | F12: S0183 | G12: Compte épargne-temps | H12: E0971 | I12: Compte épargne-temps (CET) | J12: La date d'observation saisie du CET est non vide | K12: A_CET_DAGCET [Saisi] <> Vide | L12: T2360 | M12: Compte épargne-temps - Choix d'option | N12: Création Modification | O12: La date de l'opération saisie est non vide et le sens de l'opération est "Consommé" | P12: A_CET_DOOCET [Saisi] <> Vide ET A_CET_SEOCET [Saisi] = 'C' | Q12: Contractuel | R12: P0003 | S12: Général | T12: Passant | U12: 45323 | W12: CET_I_052 ET CET_I_054 ET CET_I_056 ET CET_I_058 ET CET_I_059 ET CET_D_405 ET CET_D_406 ET CET_D_408 ET CET_C_004 ET CET_C_024 ET CET_C_027 | X12: CET_I_052 | Y12: =VLOOKUP(X12,'Axe 2 Règles de gestion'!$D$2:$F$43,3, FALSE) -> L'agent est informé chaque année, par l'administration, des jours épargnés et consommés. | Z12: CET_I_054 | AA12: =VLOOKUP(Z12,'Axe 2 Règles de gestion'!$D$2:$F$43,3, FALSE) -> Si le nombre de jours inscrits est supérieur à 15 jours au terme de l'année civile, l'agent ne peut utiliser ces 15 jours que sous forme de congés, pour les autres jours il doit exercer une option au plus le tard le 31 janvier de l'année suivante. | AB12: CET_I_056 | AC12: =VLOOKUP(AB12,'Axe 2 Règles de gestion'!$D$2:$F$43,3, FALSE) -> L'agent peut opter dans les proportions qu'il souhaite pour une indemnisation ou pour un maintien sur le compte épargne-temps. | AD12: CET_I_058 | AE12: =VLOOKUP(AD12,'Axe 2 Règles de gestion'!$D$2:$F$43,3, FALSE) -> Si l'agent n'exerce pas son droit d'option, les jours au-delà de 15 sont indemnisés. | AF12: CET_I_059 | AG12: =VLOOKUP(AF12,'Axe 2 Règles de gestion'!$D$2:$F$43,3, FALSE) -> Les années suivantes, les jours ainsi épargnés excédant le plafond global de jours prévu peuvent être maintenus sur le compte épargne-temps ou être consommés. | AJ12: CET_D_405 | AK12: =VLOOKUP(AJ12,'Axe 2 Règles de gestion'!$D$2:$F$43,3, FALSE) -> Le nombre de jours maintenus sur le compte épargne-temps ne doit pas dépasser un plafond annuel de 60 jours. | AL12: CET_D_406 | AM12: =VLOOKUP(AL12,'Axe 2 Règles de gestion'!$D$2:$F$43,3, FALSE) -> Au terme de l'année 2024, en raison de l'organisation des jeux olympiques et paralympiques, ce plafond annuel passe à 70 jours ou si le nombre de jours épargnés au terme de l'année 2023 excède 60 jours, au nombre de jours épargnés augmentés de 10 jours. | AN12: CET_D_408 | AO12: =VLOOKUP(AN12,'Axe 2 Règles de gestion'!$D$2:$F$43,3, FALSE) -> Si le nombre de jours inscrits sur le compte épargne-temps est inférieur ou égal à 15 jours au terme de l'année civile, l'agent ne peut utiliser ces jours épargnés que sous forme de congés. | AR12: CET_C_004 | AS12: =VLOOKUP(AR12,'Axe 2 Règles de gestion'!$D$2:$F$43,3, FALSE) -> Le nombre de jours de l'opération doit être inférieur ou égal au nombre de jours du compteur global du CET. | AT12: CET_C_024 | AU12: =VLOOKUP(AT12,'Axe 2 Règles de gestion'!$D$2:$F$43,3, FALSE) -> Lorsque le sens de l'opération est à "consommé", le compteur global saisi est égal au compteur global de l'occurrence précédente duquel sont soustraits les jours consommés en congés, les jours pour valorisation financière et les jours pour cotisation RAFP. | AV12: CET_C_027 | AW12: =VLOOKUP(AV12,'Axe 2 Règles de gestion'!$D$2:$F$43,3, FALSE) -> Lorsque le sens de l'opération est égal à "consommé", l'origine des jours n'est pas à renseigner.
A13: 24.10.00 | B13: A | C13: 45628.641 | D13: D0007 | E13: Congés/Absence | F13: S0183 | G13: Compte épargne-temps | H13: E0971 | I13: Compte épargne-temps (CET) | J13: La date d'observation saisie du CET est non vide | K13: A_CET_DAGCET [Saisi] <> Vide | L13: T2358 | M13: Compte épargne-temps - Ouverture | N13: Création Modification | O13: La date d'ouverture saisie est non vide et la date de l'opération est vide | P13: A_CET_DCRCET [Saisi] <> VIDE ET A_CET_DOOCET [Saisi] = VIDE | Q13: Stagiaire ou auditeur ou élève | R13: P0004 | S13: Général | T13: Exclu | U13: 45323
A14: 24.10.00 | B14: A | C14: 45628.647 | D14: D0007 | E14: Congés/Absence | F14: S0183 | G14: Compte épargne-temps | H14: E0971 | I14: Compte épargne-temps (CET) | J14: La date d'observation saisie du CET est non vide | K14: A_CET_DAGCET [Saisi] <> Vide | L14: T2359 | M14: Compte épargne-temps - Alimentation | N14: Création Modification | O14: La date de l'opération saisie est non vide et le sens de l'opération est "Versé" | P14: A_CET_DOOCET [Saisi] <> Vide ET A_CET_SEOCET [Saisi] = 'V' | Q14: Stagiaire ou auditeur ou élève | R14: P0004 | S14: Général | T14: Exclu | U14: 45323
A15: 24.10.00 | B15: A | C15: 45628.661 | D15: D0007 | E15: Congés/Absence | F15: S0183 | G15: Compte épargne-temps | H15: E0971 | I15: Compte épargne-temps (CET) | J15: La date d'observation saisie du CET est non vide | K15: A_CET_DAGCET [Saisi] <> Vide | L15: T2360 | M15: Compte épargne-temps - Choix d'option | N15: Création Modification | O15: La date de l'opération saisie est non vide et le sens de l'opération est "Consommé" | P15: A_CET_DOOCET [Saisi] <> Vide ET A_CET_SEOCET [Saisi] = 'C' | Q15: Stagiaire ou auditeur ou élève | R15: P0004 | S15: Général | T15: Exclu | U15: 45323
A16: 25.10.00 | B16: A | C16: 45994.647 | D16: D0007 | E16: Congés/Absence | F16: S0183 | G16: Compte épargne-temps | H16: E0971 | I16: Compte épargne-temps (CET) | J16: La date d'observation saisie du CET est non vide | K16: A_CET_DAGCET [Saisi] <> Vide | L16: T2358 | M16: Compte épargne-temps - Ouverture | N16: Création Modification | O16: La date d'ouverture saisie est non vide et la date de l'opération est vide | P16: A_CET_DCRCET [Saisi] <> VIDE ET A_CET_DOOCET [Saisi] = VIDE | Q16: Ouvrier d'état | R16: P0005 | S16: Général | T16: Passant | U16: 45901 | W16: CET_C_017 | AR16: CET_C_017 | AS16: =VLOOKUP(AR16,'Axe 2 Règles de gestion'!$D$2:$F$43,3, FALSE) -> La date d'ouverture du compte épargne temps global doit être postérieure ou égale à la date d'entrée dans le SIRH. | AZ16: 2025-114
A17: 25.10.00 | B17: A | C17: 45994.65 | D17: D0007 | E17: Congés/Absence | F17: S0183 | G17: Compte épargne-temps | H17: E0971 | I17: Compte épargne-temps (CET) | J17: La date d'observation saisie du CET est non vide | K17: A_CET_DAGCET [Saisi] <> Vide | L17: T2359 | M17: Compte épargne-temps - Alimentation | N17: Création Modification | O17: La date de l'opération saisie est non vide et le sens de l'opération est "Versé" | P17: A_CET_DOOCET [Saisi] <> Vide ET A_CET_SEOCET [Saisi] = 'V' | Q17: Ouvrier d'état | R17: P0005 | S17: Général | T17: Passant | U17: 45901 | W17: CET_C_023 | AR17: CET_C_023 | AS17: =VLOOKUP(AR17,'Axe 2 Règles de gestion'!$D$2:$F$43,3, FALSE) -> Lorsque le sens de l'opération est à "Versé", le compteur global saisi est égal au compteur global de l'occurrence précédente auquel sont ajoutés les jours versés. | AZ17: 2025-114
A18: 25.10.00 | B18: A | C18: 45994.651 | D18: D0007 | E18: Congés/Absence | F18: S0183 | G18: Compte épargne-temps | H18: E0971 | I18: Compte épargne-temps (CET) | J18: La date d'observation saisie du CET est non vide | K18: A_CET_DAGCET [Saisi] <> Vide | L18: T2360 | M18: Compte épargne-temps - Choix d'option | N18: Création Modification | O18: La date de l'opération saisie est non vide et le sens de l'opération est "Consommé" | P18: A_CET_DOOCET [Saisi] <> Vide ET A_CET_SEOCET [Saisi] = 'C' | Q18: Ouvrier d'état | R18: P0005 | S18: Général | T18: Passant | U18: 45901 | W18: CET_C_004 | AR18: CET_C_004 | AS18: =VLOOKUP(AR18,'Axe 2 Règles de gestion'!$D$2:$F$43,3, FALSE) -> Le nombre de jours de l'opération doit être inférieur ou égal au nombre de jours du compteur global du CET. | AZ18: 2025-114
A19: 24.10.00 | B19: A | C19: 45628.642 | D19: D0007 | E19: Congés/Absence | F19: S0183 | G19: Compte épargne-temps | H19: E0971 | I19: Compte épargne-temps (CET) | J19: La date d'observation saisie du CET est non vide | K19: A_CET_DAGCET [Saisi] <> Vide | L19: T2358 | M19: Compte épargne-temps - Ouverture | N19: Création Modification | O19: La date d'ouverture saisie est non vide et la date de l'opération est vide | P19: A_CET_DCRCET [Saisi] <> VIDE ET A_CET_DOOCET [Saisi] = VIDE | Q19: Expert technique international | R19: P0018 | S19: Particulier | T19: Exclu | U19: 45323
A20: 24.10.00 | B20: A | C20: 45628.647 | D20: D0007 | E20: Congés/Absence | F20: S0183 | G20: Compte épargne-temps | H20: E0971 | I20: Compte épargne-temps (CET) | J20: La date d'observation saisie du CET est non vide | K20: A_CET_DAGCET [Saisi] <> Vide | L20: T2359 | M20: Compte épargne-temps - Alimentation | N20: Création Modification | O20: La date de l'opération saisie est non vide et le sens de l'opération est "Versé" | P20: A_CET_DOOCET [Saisi] <> Vide ET A_CET_SEOCET [Saisi] = 'V' | Q20: Expert technique international | R20: P0018 | S20: Particulier | T20: Exclu | U20: 45323
A21: 24.10.00 | B21: A | C21: 45628.662 | D21: D0007 | E21: Congés/Absence | F21: S0183 | G21: Compte épargne-temps | H21: E0971 | I21: Compte épargne-temps (CET) | J21: La date d'observation saisie du CET est non vide | K21: A_CET_DAGCET [Saisi] <> Vide | L21: T2360 | M21: Compte épargne-temps - Choix d'option | N21: Création Modification | O21: La date de l'opération saisie est non vide et le sens de l'opération est "Consommé" | P21: A_CET_DOOCET [Saisi] <> Vide ET A_CET_SEOCET [Saisi] = 'C' | Q21: Expert technique international | R21: P0018 | S21: Particulier | T21: Exclu | U21: 45323
A22: 24.10.00 | B22: A | C22: 45628.642 | D22: D0007 | E22: Congés/Absence | F22: S0183 | G22: Compte épargne-temps | H22: E0971 | I22: Compte épargne-temps (CET) | J22: La date d'observation saisie du CET est non vide | K22: A_CET_DAGCET [Saisi] <> Vide | L22: T2358 | M22: Compte épargne-temps - Ouverture | N22: Création Modification | O22: La date d'ouverture saisie est non vide et la date de l'opération est vide | P22: A_CET_DCRCET [Saisi] <> VIDE ET A_CET_DOOCET [Saisi] = VIDE | Q22: Personnel civil payé à l'acte ou à la tâche | R22: P0054 | S22: Particulier | T22: Exclu | U22: 45323
A23: 24.10.00 | B23: A | C23: 45628.648 | D23: D0007 | E23: Congés/Absence | F23: S0183 | G23: Compte épargne-temps | H23: E0971 | I23: Compte épargne-temps (CET) | J23: La date d'observation saisie du CET est non vide | K23: A_CET_DAGCET [Saisi] <> Vide | L23: T2359 | M23: Compte épargne-temps - Alimentation | N23: Création Modification | O23: La date de l'opération saisie est non vide et le sens de l'opération est "Versé" | P23: A_CET_DOOCET [Saisi] <> Vide ET A_CET_SEOCET [Saisi] = 'V' | Q23: Personnel civil payé à l'acte ou à la tâche | R23: P0054 | S23: Particulier | T23: Exclu | U23: 45323
A24: 24.10.00 | B24: A | C24: 45628.662 | D24: D0007 | E24: Congés/Absence | F24: S0183 | G24: Compte épargne-temps | H24: E0971 | I24: Compte épargne-temps (CET) | J24: La date d'observation saisie du CET est non vide | K24: A_CET_DAGCET [Saisi] <> Vide | L24: T2360 | M24: Compte épargne-temps - Choix d'option | N24: Création Modification | O24: La date de l'opération saisie est non vide et le sens de l'opération est "Consommé" | P24: A_CET_DOOCET [Saisi] <> Vide ET A_CET_SEOCET [Saisi] = 'C' | Q24: Personnel civil payé à l'acte ou à la tâche | R24: P0054 | S24: Particulier | T24: Exclu | U24: 45323
A25: 24.10.00 | B25: A | C25: 45628.642 | D25: D0007 | E25: Congés/Absence | F25: S0183 | G25: Compte épargne-temps | H25: E0971 | I25: Compte épargne-temps (CET) | J25: La date d'observation saisie du CET est non vide | K25: A_CET_DAGCET [Saisi] <> Vide | L25: T2358 | M25: Compte épargne-temps - Ouverture | N25: Création Modification | O25: La date d'ouverture saisie est non vide et la date de l'opération est vide | P25: A_CET_DCRCET [Saisi] <> VIDE ET A_CET_DOOCET [Saisi] = VIDE | Q25: Contractuel de droit privé | R25: P0072 | S25: Particulier | T25: Exclu | U25: 45323
A26: 24.10.00 | B26: A | C26: 45628.648 | D26: D0007 | E26: Congés/Absence | F26: S0183 | G26: Compte épargne-temps | H26: E0971 | I26: Compte épargne-temps (CET) | J26: La date d'observation saisie du CET est non vide | K26: A_CET_DAGCET [Saisi] <> Vide | L26: T2359 | M26: Compte épargne-temps - Alimentation | N26: Création Modification | O26: La date de l'opération saisie est non vide et le sens de l'opération est "Versé" | P26: A_CET_DOOCET [Saisi] <> Vide ET A_CET_SEOCET [Saisi] = 'V' | Q26: Contractuel de droit privé | R26: P0072 | S26: Particulier | T26: Exclu | U26: 45323
A27: 24.10.00 | B27: A | C27: 45628.662 | D27: D0007 | E27: Congés/Absence | F27: S0183 | G27: Compte épargne-temps | H27: E0971 | I27: Compte épargne-temps (CET) | J27: La date d'observation saisie du CET est non vide | K27: A_CET_DAGCET [Saisi] <> Vide | L27: T2360 | M27: Compte épargne-temps - Choix d'option | N27: Création Modification | O27: La date de l'opération saisie est non vide et le sens de l'opération est "Consommé" | P27: A_CET_DOOCET [Saisi] <> Vide ET A_CET_SEOCET [Saisi] = 'C' | Q27: Contractuel de droit privé | R27: P0072 | S27: Particulier | T27: Exclu | U27: 45323
A28: 25.10.00 | B28: A | C28: 45994.438 | D28: D0007 | E28: Congés/Absence | F28: S0183 | G28: Compte épargne-temps | H28: E0971 | I28: Compte épargne-temps (CET) | J28: La date d'observation saisie du CET est non vide | K28: A_CET_DAGCET [Saisi] <> Vide | L28: T2358 | M28: Compte épargne-temps - Ouverture | N28: Création Modification | O28: La date d'ouverture saisie est non vide et la date de l'opération est vide | P28: A_CET_DCRCET [Saisi] <> VIDE ET A_CET_DOOCET [Saisi] = VIDE | Q28: Ouvrier des parcs et ateliers ou assimilé confirmé | R28: P0096 | S28: Particulier | T28: Passant | U28: 45901 | W28: CET_I_036 ET CET_I_050 ET CET_D_400 ET CET_D_407 ET CET_C_017 ET CET_C_031 | X28: CET_I_036 | Y28: =VLOOKUP(X28,'Axe 2 Règles de gestion'!$D$2:$F$43,3, FALSE) -> L'agent bénéficie des dispositions applicables aux agents titulaires pour le compte épargne-temps, sauf dispositions contraires. | Z28: CET_I_050 | AA28: =VLOOKUP(Z28,'Axe 2 Règles de gestion'!$D$2:$F$43,3, FALSE) -> L'agent doit effectuer une demande d'ouverture d'un compte épargne-temps. | AJ28: CET_D_400 | AK28: =VLOOKUP(AJ28,'Axe 2 Règles de gestion'!$D$2:$F$43,3, FALSE) -> L'agent ne doit pas relever des régimes d'obligation de service. | AL28: CET_D_407 | AM28: =VLOOKUP(AL28,'Axe 2 Règles de gestion'!$D$2:$F$43,3, FALSE) -> L'agent est employé de manière continue et a accompli au moins 1 année de service. | AR28: CET_C_017 | AS28: =VLOOKUP(AR28,'Axe 2 Règles de gestion'!$D$2:$F$43,3, FALSE) -> La date d'ouverture du compte épargne temps global doit être postérieure ou égale à la date d'entrée dans le SIRH. | AT28: CET_C_031 | AU28: =VLOOKUP(AT28,'Axe 2 Règles de gestion'!$D$2:$F$43,3, FALSE) -> Les champs "Origine", "Nombre de jours de l'opération", "Nombre de jours pour valorisation financière" et "Nombre de jours pour cotisation RAFP" ne doivent pas être renseignés. | AZ28: 2025-114
A29: 25.10.00 | B29: A | C29: 45994.44 | D29: D0007 | E29: Congés/Absence | F29: S0183 | G29: Compte épargne-temps | H29: E0971 | I29: Compte épargne-temps (CET) | J29: La date d'observation saisie du CET est non vide | K29: A_CET_DAGCET [Saisi] <> Vide | L29: T2359 | M29: Compte épargne-temps - Alimentation | N29: Création Modification | O29: La date de l'opération saisie est non vide et le sens de l'opération est "Versé" | P29: A_CET_DOOCET [Saisi] <> Vide ET A_CET_SEOCET [Saisi] = 'V' | Q29: Ouvrier des parcs et ateliers ou assimilé confirmé | R29: P0096 | S29: Particulier | T29: Passant | U29: 45901 | W29: CET_I_036 ET CET_I_061 ET CET_I_060 ET CET_D_401 ET CET_D_402 ET CET_D_403 ET CET_C_023 ET CET_C_026 | X29: CET_I_036 | Y29: =VLOOKUP(X29,'Axe 2 Règles de gestion'!$D$2:$F$43,3, FALSE) -> L'agent bénéficie des dispositions applicables aux agents titulaires pour le compte épargne-temps, sauf dispositions contraires. | Z29: CET_I_061 | AA29: =VLOOKUP(Z29,'Axe 2 Règles de gestion'!$D$2:$F$43,3, FALSE) -> Pour les agents en service à l'étranger, le compte épargne-temps est alimenté par le report des jours de congés annuels dont ils bénéficient au titre du pays dans lequel ils sont affectés. | AB29: CET_I_060 | AC29: =VLOOKUP(AB29,'Axe 2 Règles de gestion'!$D$2:$F$43,3, FALSE) -> L'agent ne peut pas alimenter son compte épargne-temps par le report de congés bonifiés. | AJ29: CET_D_401 | AK29: =VLOOKUP(AJ29,'Axe 2 Règles de gestion'!$D$2:$F$43,3, FALSE) -> L'agent peut alimenter son compte épargne-temps par le report de jours de réduction du temps de travail, par le report de congés annuels et de fractionnement et si un arrêté le prévoit par le report de jours de repos compensateur. | AL29: CET_D_402 | AM29: =VLOOKUP(AL29,'Axe 2 Règles de gestion'!$D$2:$F$43,3, FALSE) -> L'agent pour pouvoir alimenter son compte épargne-temps doit avoir pris dans l'année au moins 20 jours de congés. | AN29: CET_D_403 | AO29: =VLOOKUP(AN29,'Axe 2 Règles de gestion'!$D$2:$F$43,3, FALSE) -> Lorsque le compte épargne-temps atteint 15 jours, l'agent peut épargner ensuite chaque année 10 jours au maximum. | AR29: CET_C_023 | AS29: =VLOOKUP(AR29,'Axe 2 Règles de gestion'!$D$2:$F$43,3, FALSE) -> Lorsque le sens de l'opération est à "Versé", le compteur global saisi est égal au compteur global de l'occurrence précédente auquel sont ajoutés les jours versés. | AT29: CET_C_026 | AU29: =VLOOKUP(AT29,'Axe 2 Règles de gestion'!$D$2:$F$43,3, FALSE) -> Lorsque le sens de l'opération est égal à "versé", le nombre de jours pour valorisation financière et le nombre de jours pour cotisation RAFP ne doivent pas être renseignés. | AZ29: 2025-114
A30: 25.10.00 | B30: A | C30: 45994.442 | D30: D0007 | E30: Congés/Absence | F30: S0183 | G30: Compte épargne-temps | H30: E0971 | I30: Compte épargne-temps (CET) | J30: La date d'observation saisie du CET est non vide | K30: A_CET_DAGCET [Saisi] <> Vide | L30: T2360 | M30: Compte épargne-temps - Choix d'option | N30: Création Modification | O30: La date de l'opération saisie est non vide et le sens de l'opération est "Consommé" | P30: A_CET_DOOCET [Saisi] <> Vide ET A_CET_SEOCET [Saisi] = 'C' | Q30: Ouvrier des parcs et ateliers ou assimilé confirmé | R30: P0096 | S30: Particulier | T30: Passant | U30: 45901 | W30: CET_I_036 ET CET_I_052 ET CET_I_054 ET CET_I_037 ET CET_I_038 ET CET_I_059 ET CET_D_405 ET CET_D_406 ET CET_D_408 ET CET_C_004 ET CET_C_024 ET CET_C_027 | X30: CET_I_036 | Y30: =VLOOKUP(X30,'Axe 2 Règles de gestion'!$D$2:$F$43,3, FALSE) -> L'agent bénéficie des dispositions applicables aux agents titulaires pour le compte épargne-temps, sauf dispositions contraires. | Z30: CET_I_052 | AA30: =VLOOKUP(Z30,'Axe 2 Règles de gestion'!$D$2:$F$43,3, FALSE) -> L'agent est informé chaque année, par l'administration, des jours épargnés et consommés. | AB30: CET_I_054 | AC30: =VLOOKUP(AB30,'Axe 2 Règles de gestion'!$D$2:$F$43,3, FALSE) -> Si le nombre de jours inscrits est supérieur à 15 jours au terme de l'année civile, l'agent ne peut utiliser ces 15 jours que sous forme de congés, pour les autres jours il doit exercer une option au plus le tard le 31 janvier de l'année suivante. | AD30: CET_I_037 | AE30: =VLOOKUP(AD30,'Axe 2 Règles de gestion'!$D$2:$F$43,3, FALSE) -> L'agent peut opter dans les proportions qu'il souhaite pour une indemnisation ou pour un maintien sur le compte épargne-temps. | AF30: CET_I_038 | AG30: =VLOOKUP(AF30,'Axe 2 Règles de gestion'!$D$2:$F$43,3, FALSE) -> Si l'agent n'exerce pas son droit d'option, les jours au-delà de 15 sont indemnisés. | AH30: CET_I_059 | AI30: =VLOOKUP(AH30,'Axe 2 Règles de gestion'!$D$2:$F$43,3, FALSE) -> Les années suivantes, les jours ainsi épargnés excédant le plafond global de jours prévu peuvent être maintenus sur le compte épargne-temps ou être consommés. | AJ30: CET_D_405 | AK30: =VLOOKUP(AJ30,'Axe 2 Règles de gestion'!$D$2:$F$43,3, FALSE) -> Le nombre de jours maintenus sur le compte épargne-temps ne doit pas dépasser un plafond annuel de 60 jours. | AL30: CET_D_406 | AM30: =VLOOKUP(AL30,'Axe 2 Règles de gestion'!$D$2:$F$43,3, FALSE) -> Au terme de l'année 2024, en raison de l'organisation des jeux olympiques et paralympiques, ce plafond annuel passe à 70 jours ou si le nombre de jours épargnés au terme de l'année 2023 excède 60 jours, au nombre de jours épargnés augmentés de 10 jours. | AN30: CET_D_408 | AO30: =VLOOKUP(AN30,'Axe 2 Règles de gestion'!$D$2:$F$43,3, FALSE) -> Si le nombre de jours inscrits sur le compte épargne-temps est inférieur ou égal à 15 jours au terme de l'année civile, l'agent ne peut utiliser ces jours épargnés que sous forme de congés. | AR30: CET_C_004 | AS30: =VLOOKUP(AR30,'Axe 2 Règles de gestion'!$D$2:$F$43,3, FALSE) -> Le nombre de jours de l'opération doit être inférieur ou égal au nombre de jours du compteur global du CET. | AT30: CET_C_024 | AU30: =VLOOKUP(AT30,'Axe 2 Règles de gestion'!$D$2:$F$43,3, FALSE) -> Lorsque le sens de l'opération est à "consommé", le compteur global saisi est égal au compteur global de l'occurrence précédente duquel sont soustraits les jours consommés en congés, les jours pour valorisation financière et les jours pour cotisation RAFP. | AV30: CET_C_027 | AW30: =VLOOKUP(AV30,'Axe 2 Règles de gestion'!$D$2:$F$43,3, FALSE) -> Lorsque le sens de l'opération est égal à "consommé", l'origine des jours n'est pas à renseigner. | AZ30: 2025-114
A31: 24.10.00 | B31: A | C31: 45628.643 | D31: D0007 | E31: Congés/Absence | F31: S0183 | G31: Compte épargne-temps | H31: E0971 | I31: Compte épargne-temps (CET) | J31: La date d'observation saisie du CET est non vide | K31: A_CET_DAGCET [Saisi] <> Vide | L31: T2358 | M31: Compte épargne-temps - Ouverture | N31: Création Modification | O31: La date d'ouverture saisie est non vide et la date de l'opération est vide | P31: A_CET_DCRCET [Saisi] <> VIDE ET A_CET_DOOCET [Saisi] = VIDE | Q31: Volontaire International | R31: P0178 | S31: Particulier | T31: Exclu | U31: 45323
A32: 24.10.00 | B32: A | C32: 45628.648 | D32: D0007 | E32: Congés/Absence | F32: S0183 | G32: Compte épargne-temps | H32: E0971 | I32: Compte épargne-temps (CET) | J32: La date d'observation saisie du CET est non vide | K32: A_CET_DAGCET [Saisi] <> Vide | L32: T2359 | M32: Compte épargne-temps - Alimentation | N32: Création Modification | O32: La date de l'opération saisie est non vide et le sens de l'opération est "Versé" | P32: A_CET_DOOCET [Saisi] <> Vide ET A_CET_SEOCET [Saisi] = 'V' | Q32: Volontaire International | R32: P0178 | S32: Particulier | T32: Exclu | U32: 45323
A33: 24.10.00 | B33: A | C33: 45628.662 | D33: D0007 | E33: Congés/Absence | F33: S0183 | G33: Compte épargne-temps | H33: E0971 | I33: Compte épargne-temps (CET) | J33: La date d'observation saisie du CET est non vide | K33: A_CET_DAGCET [Saisi] <> Vide | L33: T2360 | M33: Compte épargne-temps - Choix d'option | N33: Création Modification | O33: La date de l'opération saisie est non vide et le sens de l'opération est "Consommé" | P33: A_CET_DOOCET [Saisi] <> Vide ET A_CET_SEOCET [Saisi] = 'C' | Q33: Volontaire International | R33: P0178 | S33: Particulier | T33: Exclu | U33: 45323
A34: 24.10.00 | B34: A | C34: 45628.643 | D34: D0007 | E34: Congés/Absence | F34: S0183 | G34: Compte épargne-temps | H34: E0971 | I34: Compte épargne-temps (CET) | J34: La date d'observation saisie du CET est non vide | K34: A_CET_DAGCET [Saisi] <> Vide | L34: T2358 | M34: Compte épargne-temps - Ouverture | N34: Création Modification | O34: La date d'ouverture saisie est non vide et la date de l'opération est vide | P34: A_CET_DCRCET [Saisi] <> VIDE ET A_CET_DOOCET [Saisi] = VIDE | Q34: Personnel civil de coopération (assistant technique) | R34: P0214 | S34: Particulier | T34: Exclu | U34: 45323
A35: 24.10.00 | B35: A | C35: 45628.649 | D35: D0007 | E35: Congés/Absence | F35: S0183 | G35: Compte épargne-temps | H35: E0971 | I35: Compte épargne-temps (CET) | J35: La date d'observation saisie du CET est non vide | K35: A_CET_DAGCET [Saisi] <> Vide | L35: T2359 | M35: Compte épargne-temps - Alimentation | N35: Création Modification | O35: La date de l'opération saisie est non vide et le sens de l'opération est "Versé" | P35: A_CET_DOOCET [Saisi] <> Vide ET A_CET_SEOCET [Saisi] = 'V' | Q35: Personnel civil de coopération (assistant technique) | R35: P0214 | S35: Particulier | T35: Exclu | U35: 45323
A36: 24.10.00 | B36: A | C36: 45628.663 | D36: D0007 | E36: Congés/Absence | F36: S0183 | G36: Compte épargne-temps | H36: E0971 | I36: Compte épargne-temps (CET) | J36: La date d'observation saisie du CET est non vide | K36: A_CET_DAGCET [Saisi] <> Vide | L36: T2360 | M36: Compte épargne-temps - Choix d'option | N36: Création Modification | O36: La date de l'opération saisie est non vide et le sens de l'opération est "Consommé" | P36: A_CET_DOOCET [Saisi] <> Vide ET A_CET_SEOCET [Saisi] = 'C' | Q36: Personnel civil de coopération (assistant technique) | R36: P0214 | S36: Particulier | T36: Exclu | U36: 45323
A37: 25.10.00 | B37: A | C37: 45994.446 | D37: D0007 | E37: Congés/Absence | F37: S0183 | G37: Compte épargne-temps | H37: E0971 | I37: Compte épargne-temps (CET) | J37: La date d'observation saisie du CET est non vide | K37: A_CET_DAGCET [Saisi] <> Vide | L37: T2358 | M37: Compte épargne-temps - Ouverture | N37: Création Modification | O37: La date d'ouverture saisie est non vide et la date de l'opération est vide | P37: A_CET_DCRCET [Saisi] <> VIDE ET A_CET_DOOCET [Saisi] = VIDE | Q37: Ouvrier des parcs et ateliers stagiaire | R37: P0226 | S37: Particulier | T37: Exclu | U37: 45901 | AZ37: 2025-114
A38: 25.10.00 | B38: A | C38: 45994.649 | D38: D0007 | E38: Congés/Absence | F38: S0183 | G38: Compte épargne-temps | H38: E0971 | I38: Compte épargne-temps (CET) | J38: La date d'observation saisie du CET est non vide | K38: A_CET_DAGCET [Saisi] <> Vide | L38: T2359 | M38: Compte épargne-temps - Alimentation | N38: Création Modification | O38: La date de l'opération saisie est non vide et le sens de l'opération est "Versé" | P38: A_CET_DOOCET [Saisi] <> Vide ET A_CET_SEOCET [Saisi] = 'V' | Q38: Ouvrier des parcs et ateliers stagiaire | R38: P0226 | S38: Particulier | T38: Exclu | U38: 45901 | AZ38: 2025-114
A39: 25.10.00 | B39: A | C39: 45994.651 | D39: D0007 | E39: Congés/Absence | F39: S0183 | G39: Compte épargne-temps | H39: E0971 | I39: Compte épargne-temps (CET) | J39: La date d'observation saisie du CET est non vide | K39: A_CET_DAGCET [Saisi] <> Vide | L39: T2360 | M39: Compte épargne-temps - Choix d'option | N39: Création Modification | O39: La date de l'opération saisie est non vide et le sens de l'opération est "Consommé" | P39: A_CET_DOOCET [Saisi] <> Vide ET A_CET_SEOCET [Saisi] = 'C' | Q39: Ouvrier des parcs et ateliers stagiaire | R39: P0226 | S39: Particulier | T39: Exclu | U39: 45901 | AZ39: 2025-114
A40: 24.10.00 | B40: A | C40: 45628.665 | D40: D0007 | E40: Congés/Absence | F40: S0183 | G40: Compte épargne-temps | H40: E0972 | I40: Compte épargne-temps (CET) historique | J40: La date d'observation saisie du CET historique est non vide | K40: A_CET_DAGTRA [Saisi] <> Vide | L40: T2361 | M40: Compte épargne-temps historique - Choix d'option | N40: Création Modification | O40: La date de l'opération saisie est non vide pour le CET historique | P40: A_CET_DOOCET [Saisi] <> Vide #pour le CET historique# | Q40: Titulaire ou magistrat | R40: P0001 | S40: Général | T40: Passant | U40: 45323 | W40: CET_I_062 ET CET_I_069 ET CET_C_004 ET CET_C_024 ET CET_C_027 ET CET_C_030 | X40: CET_I_062 | Y40: =VLOOKUP(X40,'Axe 2 Règles de gestion'!$D$2:$F$43,3, FALSE) -> L'agent titulaire d'un compte épargne-temps historique peut utiliser ses jours épargnés sous forme de congés ou les faire indemniser ou pour une prise en compte au sein du régime additionnel de la fonction publique. | Z40: CET_I_069 | AA40: =VLOOKUP(Z40,'Axe 2 Règles de gestion'!$D$2:$F$43,3, FALSE) -> Depuis 2009, l'ouverture et l'alimentation du compte épargne-temps historique ne sont plus autorisées. | AR40: CET_C_004 | AS40: =VLOOKUP(AR40,'Axe 2 Règles de gestion'!$D$2:$F$43,3, FALSE) -> Le nombre de jours de l'opération doit être inférieur ou égal au nombre de jours du compteur global du CET. | AT40: CET_C_024 | AU40: =VLOOKUP(AT40,'Axe 2 Règles de gestion'!$D$2:$F$43,3, FALSE) -> Lorsque le sens de l'opération est à "consommé", le compteur global saisi est égal au compteur global de l'occurrence précédente duquel sont soustraits les jours consommés en congés, les jours pour valorisation financière et les jours pour cotisation RAFP. | AV40: CET_C_027 | AW40: =VLOOKUP(AV40,'Axe 2 Règles de gestion'!$D$2:$F$43,3, FALSE) -> Lorsque le sens de l'opération est égal à "consommé", l'origine des jours n'est pas à renseigner. | AX40: CET_C_030 | AY40: =VLOOKUP(AX40,'Axe 2 Règles de gestion'!$D$2:$F$43,3, FALSE) -> Le sens de l'opération doit être à "consommé".
...

Sheet Axe 1 Enchaînement RG Impact
A1: Version | B1: Type de mise à jour | C1: Date de mise à jour | D1: Identifiant Domaine | E1: Libellé du Domaine | F1: Identifiant Sous-domaine | G1: Libellé du Sous-domaine | H1: Identifiant Evénement | I1: Libellé de l'évènement | J1: Libellé condition déclenchement Evènement | K1: Condition déclenchement Evènement | L1: Identifiant type d'évènement | M1: Libellé type d'évènement | N1: Type de mise à jour | O1: Libellé condition déclenchement Type Evènement | P1: Condition déclenchement Type Evènement | Q1: Libellé Population | R1: Codification Population | S1: Général / Particulier | T1: Passant / Exclu | U1: Date de début | V1: Date de fin | W1: Impacts | X1: Identifiant Impacts 1 | Y1: Libellé Impacts 1 | Z1: Identifiant Impacts 2 | AA1: Libellé Impacts 2 | AB1: Identifiant Impacts 3 | AC1: Libellé Impacts 3 | AD1: FIME | AE1: Statut de travail
A2: 24.10.00 | B2: A | C2: 45628.64 | D2: D0007 | E2: Congés/Absence | F2: S0183 | G2: Compte épargne-temps | H2: E0971 | I2: Compte épargne-temps (CET) | J2: La date d'observation saisie du CET est non vide | K2: A_CET_DAGCET [Saisi] <> Vide | L2: T2358 | M2: Compte épargne-temps - Ouverture | N2: Création Modification | O2: La date d'ouverture saisie est non vide et la date de l'opération est vide | P2: A_CET_DCRCET [Saisi] <> VIDE ET A_CET_DOOCET [Saisi] = VIDE | Q2: Titulaire ou magistrat | R2: P0001 | S2: Général | T2: Passant | U2: 45323 | W2: CET_P_001 ET CET_P_006 ET CET_P_007 | X2: CET_P_001 | Y2: =VLOOKUP(X2,'Axe 2 Règles de gestion'!$D$2:$F$43,3, FALSE) -> Rémunération : En cas d'indemnisation, le montant versé est un montant forfaitaire qui dépend de la catégorie statutaire d'appartenance de l'agent. | Z2: CET_P_006 | AA2: =VLOOKUP(Z2,'Axe 2 Règles de gestion'!$D$2:$F$43,3, FALSE) -> Stage : L'agent ne peut pas demander l'ouverture ou l'utilisation d'un compte épargne-temps durant la durée de son stage. | AB2: CET_P_007 | AC2: =VLOOKUP(AB2,'Axe 2 Règles de gestion'!$D$2:$F$43,3, FALSE) -> Congés annuels : L'agent conserve son droit à congé annuel.
A3: 24.10.00 | B3: A | C3: 45628.644 | D3: D0007 | E3: Congés/Absence | F3: S0183 | G3: Compte épargne-temps | H3: E0971 | I3: Compte épargne-temps (CET) | J3: La date d'observation saisie du CET est non vide | K3: A_CET_DAGCET [Saisi] <> Vide | L3: T2359 | M3: Compte épargne-temps - Alimentation | N3: Création Modification | O3: La date de l'opération saisie est non vide et le sens de l'opération est "Versé" | P3: A_CET_DOOCET [Saisi] <> Vide ET A_CET_SEOCET [Saisi] = 'V' | Q3: Titulaire ou magistrat | R3: P0001 | S3: Général | T3: Passant | U3: 45323 | V3: 45688 | W3: CET_P_001 ET CET_P_006 ET CET_P_007 | X3: CET_P_001 | Y3: =VLOOKUP(X3,'Axe 2 Règles de gestion'!$D$2:$F$43,3, FALSE) -> Rémunération : En cas d'indemnisation, le montant versé est un montant forfaitaire qui dépend de la catégorie statutaire d'appartenance de l'agent. | Z3: CET_P_006 | AA3: =VLOOKUP(Z3,'Axe 2 Règles de gestion'!$D$2:$F$43,3, FALSE) -> Stage : L'agent ne peut pas demander l'ouverture ou l'utilisation d'un compte épargne-temps durant la durée de son stage. | AB3: CET_P_007 | AC3: =VLOOKUP(AB3,'Axe 2 Règles de gestion'!$D$2:$F$43,3, FALSE) -> Congés annuels : L'agent conserve son droit à congé annuel.
A4: 24.10.00 | B4: A | C4: 45628.645 | D4: D0007 | E4: Congés/Absence | F4: S0183 | G4: Compte épargne-temps | H4: E0971 | I4: Compte épargne-temps (CET) | J4: La date d'observation saisie du CET est non vide | K4: A_CET_DAGCET [Saisi] <> Vide | L4: T2359 | M4: Compte épargne-temps - Alimentation | N4: Création Modification | O4: La date de l'opération saisie est non vide et le sens de l'opération est "Versé" | P4: A_CET_DOOCET [Saisi] <> Vide ET A_CET_SEOCET [Saisi] = 'V' | Q4: Titulaire ou magistrat | R4: P0001 | S4: Général | T4: Passant | U4: 45689 | W4: CET_P_001 ET CET_P_006 ET CET_P_007 | X4: CET_P_001 | Y4: =VLOOKUP(X4,'Axe 2 Règles de gestion'!$D$2:$F$43,3, FALSE) -> Rémunération : En cas d'indemnisation, le montant versé est un montant forfaitaire qui dépend de la catégorie statutaire d'appartenance de l'agent. | Z4: CET_P_006 | AA4: =VLOOKUP(Z4,'Axe 2 Règles de gestion'!$D$2:$F$43,3, FALSE) -> Stage : L'agent ne peut pas demander l'ouverture ou l'utilisation d'un compte épargne-temps durant la durée de son stage. | AB4: CET_P_007 | AC4: =VLOOKUP(AB4,'Axe 2 Règles de gestion'!$D$2:$F$43,3, FALSE) -> Congés annuels : L'agent conserve son droit à congé annuel.
A5: 24.10.00 | B5: A | C5: 45628.659 | D5: D0007 | E5: Congés/Absence | F5: S0183 | G5: Compte épargne-temps | H5: E0971 | I5: Compte épargne-temps (CET) | J5: La date d'observation saisie du CET est non vide | K5: A_CET_DAGCET [Saisi] <> Vide | L5: T2360 | M5: Compte épargne-temps - Choix d'option | N5: Création Modification | O5: La date de l'opération saisie est non vide et le sens de l'opération est "Consommé" | P5: A_CET_DOOCET [Saisi] <> Vide ET A_CET_SEOCET [Saisi] = 'C' | Q5: Titulaire ou magistrat | R5: P0001 | S5: Général | T5: Passant | U5: 45323 | W5: CET_P_001 ET CET_P_006 ET CET_P_007 | X5: CET_P_001 | Y5: =VLOOKUP(X5,'Axe 2 Règles de gestion'!$D$2:$F$43,3, FALSE) -> Rémunération : En cas d'indemnisation, le montant versé est un montant forfaitaire qui dépend de la catégorie statutaire d'appartenance de l'agent. | Z5: CET_P_006 | AA5: =VLOOKUP(Z5,'Axe 2 Règles de gestion'!$D$2:$F$43,3, FALSE) -> Stage : L'agent ne peut pas demander l'ouverture ou l'utilisation d'un compte épargne-temps durant la durée de son stage. | AB5: CET_P_007 | AC5: =VLOOKUP(AB5,'Axe 2 Règles de gestion'!$D$2:$F$43,3, FALSE) -> Congés annuels : L'agent conserve son droit à congé annuel.
A6: 24.10.00 | B6: A | C6: 45628.64 | D6: D0007 | E6: Congés/Absence | F6: S0183 | G6: Compte épargne-temps | H6: E0971 | I6: Compte épargne-temps (CET) | J6: La date d'observation saisie du CET est non vide | K6: A_CET_DAGCET [Saisi] <> Vide | L6: T2358 | M6: Compte épargne-temps - Ouverture | N6: Création Modification | O6: La date d'ouverture saisie est non vide et la date de l'opération est vide | P6: A_CET_DCRCET [Saisi] <> VIDE ET A_CET_DOOCET [Saisi] = VIDE | Q6: Militaire | R6: P0002 | S6: Général | T6: Exclu | U6: 45323
A7: 24.10.00 | B7: A | C7: 45628.645 | D7: D0007 | E7: Congés/Absence | F7: S0183 | G7: Compte épargne-temps | H7: E0971 | I7: Compte épargne-temps (CET) | J7: La date d'observation saisie du CET est non vide | K7: A_CET_DAGCET [Saisi] <> Vide | L7: T2359 | M7: Compte épargne-temps - Alimentation | N7: Création Modification | O7: La date de l'opération saisie est non vide et le sens de l'opération est "Versé" | P7: A_CET_DOOCET [Saisi] <> Vide ET A_CET_SEOCET [Saisi] = 'V' | Q7: Militaire | R7: P0002 | S7: Général | T7: Exclu | U7: 45323
A8: 24.10.00 | B8: A | C8: 45628.66 | D8: D0007 | E8: Congés/Absence | F8: S0183 | G8: Compte épargne-temps | H8: E0971 | I8: Compte épargne-temps (CET) | J8: La date d'observation saisie du CET est non vide | K8: A_CET_DAGCET [Saisi] <> Vide | L8: T2360 | M8: Compte épargne-temps - Choix d'option | N8: Création Modification | O8: La date de l'opération saisie est non vide et le sens de l'opération est "Consommé" | P8: A_CET_DOOCET [Saisi] <> Vide ET A_CET_SEOCET [Saisi] = 'C' | Q8: Militaire | R8: P0002 | S8: Général | T8: Exclu | U8: 45323
A9: 24.10.00 | B9: A | C9: 45628.64 | D9: D0007 | E9: Congés/Absence | F9: S0183 | G9: Compte épargne-temps | H9: E0971 | I9: Compte épargne-temps (CET) | J9: La date d'observation saisie du CET est non vide | K9: A_CET_DAGCET [Saisi] <> Vide | L9: T2358 | M9: Compte épargne-temps - Ouverture | N9: Création Modification | O9: La date d'ouverture saisie est non vide et la date de l'opération est vide | P9: A_CET_DCRCET [Saisi] <> VIDE ET A_CET_DOOCET [Saisi] = VIDE | Q9: Contractuel | R9: P0003 | S9: Général | T9: Passant | U9: 45323 | W9: CET_P_001 ET CET_P_007 | X9: CET_P_001 | Y9: =VLOOKUP(X9,'Axe 2 Règles de gestion'!$D$2:$F$43,3, FALSE) -> Rémunération : En cas d'indemnisation, le montant versé est un montant forfaitaire qui dépend de la catégorie statutaire d'appartenance de l'agent. | Z9: CET_P_007 | AA9: =VLOOKUP(Z9,'Axe 2 Règles de gestion'!$D$2:$F$43,3, FALSE) -> Congés annuels : L'agent conserve son droit à congé annuel.
A10: 24.10.00 | B10: A | C10: 45635.722 | D10: D0007 | E10: Congés/Absence | F10: S0183 | G10: Compte épargne-temps | H10: E0971 | I10: Compte épargne-temps (CET) | J10: La date d'observation saisie du CET est non vide | K10: A_CET_DAGCET [Saisi] <> Vide | L10: T2359 | M10: Compte épargne-temps - Alimentation | N10: Création Modification | O10: La date de l'opération saisie est non vide et le sens de l'opération est "Versé" | P10: A_CET_DOOCET [Saisi] <> Vide ET A_CET_SEOCET [Saisi] = 'V' | Q10: Contractuel | R10: P0003 | S10: Général | T10: Passant | U10: 45323 | V10: 45688 | W10: CET_P_001 ET CET_P_007 | X10: CET_P_001 | Y10: =VLOOKUP(X10,'Axe 2 Règles de gestion'!$D$2:$F$43,3, FALSE) -> Rémunération : En cas d'indemnisation, le montant versé est un montant forfaitaire qui dépend de la catégorie statutaire d'appartenance de l'agent. | Z10: CET_P_007 | AA10: =VLOOKUP(Z10,'Axe 2 Règles de gestion'!$D$2:$F$43,3, FALSE) -> Congés annuels : L'agent conserve son droit à congé annuel.
A11: 24.10.00 | B11: A | C11: 45635.722 | D11: D0007 | E11: Congés/Absence | F11: S0183 | G11: Compte épargne-temps | H11: E0971 | I11: Compte épargne-temps (CET) | J11: La date d'observation saisie du CET est non vide | K11: A_CET_DAGCET [Saisi] <> Vide | L11: T2359 | M11: Compte épargne-temps - Alimentation | N11: Création Modification | O11: La date de l'opération saisie est non vide et le sens de l'opération est "Versé" | P11: A_CET_DOOCET [Saisi] <> Vide ET A_CET_SEOCET [Saisi] = 'V' | Q11: Contractuel | R11: P0003 | S11: Général | T11: Passant | U11: 45689 | W11: CET_P_001 ET CET_P_007 | X11: CET_P_001 | Y11: =VLOOKUP(X11,'Axe 2 Règles de gestion'!$D$2:$F$43,3, FALSE) -> Rémunération : En cas d'indemnisation, le montant versé est un montant forfaitaire qui dépend de la catégorie statutaire d'appartenance de l'agent. | Z11: CET_P_007 | AA11: =VLOOKUP(Z11,'Axe 2 Règles de gestion'!$D$2:$F$43,3, FALSE) -> Congés annuels : L'agent conserve son droit à congé annuel.
