Workbook
Name date_DIADC: 'Mode opératoire'!#REF!
Name notice_DIADC: 'Mode opératoire'!#REF!
Name notice_ENCHN: 'Mode opératoire'!$B$1:$B$4
Name notice_ICA: 'Mode opératoire'!#REF!

Sheet Mode opératoire
B1: MODE OPERATOIRE
B2: La transaction s'effectue au niveau de la rubrique "Congés/Absence", elle inclut l'ensemble des sous-rubriques listées ci-dessous : - Congés/Absence - Complément pour congé / absence : impact rémunération - Compteurs de périodes de congés On notera que : La sous-rubrique "Complément pour congé / absence : impact rémunération" est réputée, suite au découpage des absences en tranche de rémunération, avoir des dates de début et de fin alignées sur les dates de début et de fin de la sous-rubrique"Congés/absences" (contrôle bloquant)

Sheet Axe 1 Enchainement des RG
A1: Version | B1: Type de mise à jour | C1: Date de mise à jour | D1: Identifiant Domaine | E1: Libellé du Domaine | F1: Identifiant Sous-domaine | G1: Libellé du Sous-domaine | H1: Identifiant Evénement | I1: Libellé de l'évènement | J1: Libellé condition déclenchement Evènement | K1: Condition déclenchement Evènement | L1: Identifiant type d'évènement | M1: Libellé type d'évènement | N1: Type de mise à jour | O1: Libellé condition déclenchement Type Evènement | P1: Condition déclenchement Type Evènement | Q1: Libellé Population | R1: Codification Population | S1: Typologie de population | T1: Général / Particulier | U1: Passant / Exclu | V1: Date de début | W1: Date de fin | X1: Règles mobilisées | Y1: Identifiant Règle de contrôle intellectuel 1 | Z1: Libellé Règle de contrôle intellectuel 1 | AA1: Identifiant Règle de contrôle intellectuel 2 | AB1: Libellé Règle de contrôle intellectuel 2 | AC1: Identifiant Règle de contrôle intellectuel 3 | AD1: Libellé Règle de contrôle intellectuel 3 | AE1: Identifiant Règle de contrôle intellectuel 4 | AF1: Libellé Règle de contrôle intellectuel 4 | AG1: Identifiant Règle de contrôle intellectuel 5 | AH1: Libellé Règle de contrôle intellectuel 5 | AI1: Identifiant Règle de contrôle intellectuel 6 | AJ1: Libellé Règle de contrôle intellectuel 6 | AK1: Identifiant Règle de contrôle intellectuel 7 | AL1: Libellé Règle de contrôle intellectuel 7 | AM1: Identifiant Règle de contrôle intellectuel 8 | AN1: Libellé Règle de contrôle intellectuel 8 | AO1: Identifiant Règle de contrôle intellectuel 9 | AP1: Libellé Règle de contrôle intellectuel 9 | AQ1: Identifiant Règle de contrôle intellectuel 10 | AR1: Libellé Règle de contrôle intellectuel 10 | AS1: Identifiant Règle de contrôle intellectuel 11 | AT1: Libellé Règle de contrôle intellectuel 11 | AU1: Identifiant Règle de contrôle intellectuel 12 | AV1: Libellé Règle de contrôle intellectuel 12 | AW1: Identifiant Règle de contrôle intellectuel 13 | AX1: Libellé Règle de contrôle intellectuel 13 | AY1: Identifiant Règle de contrôle intellectuel 14 | AZ1: Libellé Règle de contrôle intellectuel 14 | BA1: Identifiant Règle de contrôle intellectuel 15 | BB1: Libellé Règle de contrôle intellectuel 15 | BC1: Identifiant Règle de contrôle intellectuel 16 | BD1: Libellé Règle de contrôle intellectuel 16 | BE1: Identifiant Règle de condition 1 | BF1: Libellé Règle de condition 1 | BG1: Identifiant Règle de condition 2 | BH1: Libellé Règle de condition 2 | BI1: Identifiant Règle de condition 3 | BJ1: Libellé Règle de condition 3 | BK1: Identifiant Règle de condition 4 | BL1: Libellé Règle de condition 4 | BM1: Identifiant Règle de condition 5 | BN1: Libellé Règle de condition 5 | BO1: Identifiant Règle de condition 6 | BP1: Libellé Règle de condition 6 | BQ1: Identifiant Règle de condition 7 | BR1: Libellé Règle de condition 7 | BS1: Identifiant Règle de condition 8 | BT1: Libellé Règle de condition 8 | BU1: Identifiant Règle de condition 9 | BV1: Libellé Règle de condition 9 | BW1: Identifiant Règle de contrôle 1 | BX1: Libellé Règle de contrôle 1 | BY1: Identifiant Règle de contrôle 2 | BZ1: Libellé Règle de contrôle 2 | CA1: Identifiant Règle de contrôle 3 | CB1: Libellé Règle de contrôle 3 | CC1: Identifiant Règle de contrôle 4 | CD1: Libellé Règle de contrôle 4 | CE1: Identifiant Règle de contrôle 5 | CF1: Libellé Règle de contrôle 5 | CG1: Identifiant Règle de contrôle 6 | CH1: Libellé Règle de contrôle 6 | CI1: Identifiant Règle de contrôle 7 | CJ1: Libellé Règle de contrôle 7 | CK1: Identifiant Règle de contrôle 8 | CL1: Libellé Règle de contrôle 8 | CM1: Identifiant Règle de contrôle 9 | CN1: Libellé Règle de contrôle 9 | CO1: Identifiant Règle de contrôle 10 | CP1: Libellé Règle de contrôle 10 | CQ1: Identifiant Règle de contrôle 11 | CR1: Libellé Règle de contrôle 11 | CS1: Identifiant Règle de contrôle 12 | CT1: Libellé Règle de contrôle 12 | CU1: Identifiant Règle de contrôle 13 | CV1: Libellé Règle de contrôle 13 | CW1: Identifiant Règle de contrôle 14 | CX1: Libellé Règle de contrôle 14 | CY1: Identifiant Règle de contrôle 15 | CZ1: Libellé Règle de contrôle 15 | DA1: Identifiant Règle de contrôle 16 | DB1: Libellé Règle de contrôle 16 | DC1: Identifiant Règle de contrôle 17 | DD1: Libellé Règle de contrôle 17 | DE1: Identifiant Règle de contrôle 18 | DF1: Libellé Règle de contrôle 18 | DG1: Identifiant Règle de contrôle 19 | DH1: Libellé Règle de contrôle 19 | DI1: Identifiant Règle de contrôle 20 | DJ1: Libellé Règle de contrôle 20 | DK1: Identifiant Règle de contrôle 21 | DL1: Libellé Règle de contrôle 21 | DM1: Identifiant Règle de contrôle 22 | DN1: Libellé Règle de contrôle 22 | DO1: Identifiant Règle de contrôle 23 | DP1: Libellé Règle de contrôle 23 | DQ1: FIME | DR1: Statut de travail
A2: 17.10.00 | B2: A | C2: 43152.5 | D2: D0007 | E2: Congés/Absence | F2: S0056 | G2: Congé de grave maladie | H2: E0477 | I2: Congé de grave maladie | J2: Type de congé/absence saisi = "Congé de grave maladie" | K2: A_COA_TYCOAB [Saisi] = 'CM300' | L2: T1163 | M2: Congé de grave maladie - Initial | N2: Création Modification | O2: La valeur de l'Etat du congé est égale à 'initial' et la valeur de l'Etat du congé saisie est différente de celle avant saisie | P2: A_COA_ETCOMA [Saisi] = 'EC01' ET A_COA_ETCOMA [Saisi] <> A_COA_ETCOMA [Valeur avant saisie] | Q2: Titulaire ou magistrat | R2: P0001 | S2: T | T2: Général | U2: Exclu | V2: 40725
A3: 17.10.00 | B3: A | C3: 43152.5 | D3: D0007 | E3: Congés/Absence | F3: S0056 | G3: Congé de grave maladie | H3: E0477 | I3: Congé de grave maladie | J3: Type de congé/absence saisi = "Congé de grave maladie" | K3: A_COA_TYCOAB [Saisi] = 'CM300' | L3: T1164 | M3: Congé de grave maladie - Prolongation | N3: Création Modification | O3: La valeur de l'Etat du congé est égale à 'Renouvellement' et la valeur de l'Etat du congé saisie est différente de celle avant saisie | P3: A_COA_ETCOMA [Saisi] = 'EC02' ET A_COA_ETCOMA [Saisi] <> A_COA_ETCOMA [Valeur avant saisie] | Q3: Titulaire ou magistrat | R3: P0001 | S3: T | T3: Général | U3: Exclu | V3: 40725
A4: 17.10.00 | B4: A | C4: 43152.5 | D4: D0007 | E4: Congés/Absence | F4: S0056 | G4: Congé de grave maladie | H4: E0477 | I4: Congé de grave maladie | J4: Type de congé/absence saisi = "Congé de grave maladie" | K4: A_COA_TYCOAB [Saisi] = 'CM300' | L4: T1165 | M4: Congé de grave maladie - Fin | N4: Modification | O4: La valeur de l'Etat du congé saisie est égale à celle avant saisie | P4: A_COA_ETCOMA [Saisi] = A_COA_ETCOMA [Valeur avant saisie] | Q4: Titulaire ou magistrat | R4: P0001 | S4: T | T4: Général | U4: Exclu | V4: 40725
A5: 17.10.00 | B5: A | C5: 43152.5 | D5: D0007 | E5: Congés/Absence | F5: S0056 | G5: Congé de grave maladie | H5: E0477 | I5: Congé de grave maladie | J5: Type de congé/absence saisi = "Congé de grave maladie" | K5: A_COA_TYCOAB [Saisi] = 'CM300' | L5: T1163 | M5: Congé de grave maladie - Initial | N5: Création Modification | O5: La valeur de l'Etat du congé est égale à 'initial' et la valeur de l'Etat du congé saisie est différente de celle avant saisie | P5: A_COA_ETCOMA [Saisi] = 'EC01' ET A_COA_ETCOMA [Saisi] <> A_COA_ETCOMA [Valeur avant saisie] | Q5: Militaire | R5: P0002 | S5: M | T5: Général | U5: Exclu | V5: 40725
A6: 17.10.00 | B6: A | C6: 43152.5 | D6: D0007 | E6: Congés/Absence | F6: S0056 | G6: Congé de grave maladie | H6: E0477 | I6: Congé de grave maladie | J6: Type de congé/absence saisi = "Congé de grave maladie" | K6: A_COA_TYCOAB [Saisi] = 'CM300' | L6: T1164 | M6: Congé de grave maladie - Prolongation | N6: Création Modification | O6: La valeur de l'Etat du congé est égale à 'Renouvellement' et la valeur de l'Etat du congé saisie est différente de celle avant saisie | P6: A_COA_ETCOMA [Saisi] = 'EC02' ET A_COA_ETCOMA [Saisi] <> A_COA_ETCOMA [Valeur avant saisie] | Q6: Militaire | R6: P0002 | S6: M | T6: Général | U6: Exclu | V6: 40725
A7: 17.10.00 | B7: A | C7: 43152.5 | D7: D0007 | E7: Congés/Absence | F7: S0056 | G7: Congé de grave maladie | H7: E0477 | I7: Congé de grave maladie | J7: Type de congé/absence saisi = "Congé de grave maladie" | K7: A_COA_TYCOAB [Saisi] = 'CM300' | L7: T1165 | M7: Congé de grave maladie - Fin | N7: Modification | O7: La valeur de l'Etat du congé saisie est égale à celle avant saisie | P7: A_COA_ETCOMA [Saisi] = A_COA_ETCOMA [Valeur avant saisie] | Q7: Militaire | R7: P0002 | S7: M | T7: Général | U7: Exclu | V7: 40725
A8: 22.00.00 | B8: M | C8: 45520.824 | D8: D0007 | E8: Congés/Absence | F8: S0056 | G8: Congé de grave maladie | H8: E0477 | I8: Congé de grave maladie | J8: Type de congé/absence saisi = "Congé de grave maladie" | K8: A_COA_TYCOAB [Saisi] = 'CM300' | L8: T1163 | M8: Congé de grave maladie - Initial | N8: Création Modification | O8: La valeur de l'Etat du congé est égale à 'initial' et la valeur de l'Etat du congé saisie est différente de celle avant saisie | P8: A_COA_ETCOMA [Saisi] = 'EC01' ET A_COA_ETCOMA [Saisi] <> A_COA_ETCOMA [Valeur avant saisie] | Q8: Contractuel | R8: P0003 | S8: N | T8: Général | U8: Passant | V8: 40725 | W8: 44633 | X8: CGM_I_057 ET CGM_I_045 ET CGM_I_025 ET CGM_I_065 ET CGM_I_069 ET CGM_I_097 ET CGM_I_077 ET CGM_I_021 ET CGM_I_029 ET CGM_I_041 ET CGM_I_061 ET CGM_I_109 ET CGM_I_037 ET CGM_I_073 ET CGM_D_007 ET CGM_D_008 ET CGM_D_002 ET CGM_D_009 ET CGM_D_003 ET CGM_D_042 ET CGM_D_045 ET ABS_C_002 ET ABS_C_003 ET ABS_C_004 ET ABS_C_005 ET ABS_C_006 ET ABS_C_007 ET ABS_C_008 ET ABS_C_009 ET ABS_C_015 ET ABS_C_016 ET ABS_C_018 ET ABS_C_019 ET ABS_C_020 ET ABS_C_023 ET ABS_C_024 ET ABS_C_025 | Y8: CGM_I_057 | Z8: =VLOOKUP(Y8,'Axe 2 Règles de gestion'!$D$2:$F$225,3, FALSE) -> Le bénéfice d'un congé de grave maladie demandé pour une affection qui n'est pas inscrite sur la liste indicative de maladies peut être accordé après l'avis du comité médical compétent. | AA8: CGM_I_045 | AB8: =VLOOKUP(AA8,'Axe 2 Règles de gestion'!$D$2:$F$225,3, FALSE) -> L'agent ou son représentant légal doit adresser à son chef de service une demande. | AC8: CGM_I_025 | AD8: =VLOOKUP(AC8,'Axe 2 Règles de gestion'!$D$2:$F$225,3, FALSE) -> La demande doit être appuyée d'un certificat du médecin traitant spécifiant que l'agent est susceptible de bénéficier d'un congé de grave maladie. | AE8: CGM_I_065 | AF8: =VLOOKUP(AE8,'Axe 2 Règles de gestion'!$D$2:$F$225,3, FALSE) -> Le congé peut être octroyé d'office au vu d'une attestation médicale ou d'un rapport des supérieurs hiérarchiques. | AG8: CGM_I_069 | AH8: =VLOOKUP(AG8,'Axe 2 Règles de gestion'!$D$2:$F$225,3, FALSE) -> Le dossier doit être appuyé d'un rapport du médecin de prévention. | AI8: CGM_I_097 | AJ8: =VLOOKUP(AI8,'Axe 2 Règles de gestion'!$D$2:$F$225,3, FALSE) -> Si le chef de service est à l'origine de l'examen médical de l'agent, le rapport écrit du médecin doit figurer au dossier soumis au comité médical. | AK8: CGM_I_077 | AL8: =VLOOKUP(AK8,'Axe 2 Règles de gestion'!$D$2:$F$225,3, FALSE) -> Le secrétaire du comité médical fait procéder à la contre-visite du demandeur par un médecin agréé. | AM8: CGM_I_021 | AN8: =VLOOKUP(AM8,'Axe 2 Règles de gestion'!$D$2:$F$225,3, FALSE) -> En cas de contestation par l'administration ou l'agent de la décision du comité médical, ce dernier est soumis au comité médical supérieur. | AO8: CGM_I_029 | AP8: =VLOOKUP(AO8,'Axe 2 Règles de gestion'!$D$2:$F$225,3, FALSE) -> La durée du congé est fixée sur la proposition du comité médical. | AQ8: CGM_I_041 | AR8: =VLOOKUP(AQ8,'Axe 2 Règles de gestion'!$D$2:$F$225,3, FALSE) -> L'agent est tenu de notifier ses changements de résidence successifs au chef de service chargé de la gestion du personnel de l'administration dont il dépend. | AS8: CGM_I_061 | AT8: =VLOOKUP(AS8,'Axe 2 Règles de gestion'!$D$2:$F$225,3, FALSE) -> Le chef de service s'assure par les contrôles appropriés que l'agent n'exerce pas pendant son congé d'activité interdite. | AU8: CGM_I_109 | AV8: =VLOOKUP(AU8,'Axe 2 Règles de gestion'!$D$2:$F$225,3, FALSE) -> Un contrôle pourra être effectué à tout moment par un médecin agréé de l'administration. Si les conclusions du médecin agréé donnent lieu à contestation, le comité médical peut être saisi. | AW8: CGM_I_037 | AX8: =VLOOKUP(AW8,'Axe 2 Règles de gestion'!$D$2:$F$225,3, FALSE) -> L'agent doit se soumettre, sous le contrôle du médecin agréé, et s'il y a lieu, du comité médical compétent, aux prescriptions et aux visites de contrôles que son état comporte. | AY8: CGM_I_073 | AZ8: =VLOOKUP(AY8,'Axe 2 Règles de gestion'!$D$2:$F$225,3, FALSE) -> Le refus répété et sans motif valable de se soumettre aux visites de contrôle peut entraîner, après mise en demeure de l'agent, la perte du bénéfice du congé. | BE8: CGM_D_007 | BF8: =VLOOKUP(BE8,'Axe 2 Règles de gestion'!$D$2:$F$225,3, FALSE) -> Le CGM peut être accordé pour chaque période pour une durée maximale de 6 mois. | BG8: CGM_D_008 | BH8: =VLOOKUP(BG8,'Axe 2 Règles de gestion'!$D$2:$F$225,3, FALSE) -> La durée du CGM est de 3 ans maximum. Pour certaines pathologies, le CGM peut être accordé de manière fractionnée : les droits aux 3 ans de congé sont alors appréciés sur une période de référence de 4 ans. | BI8: CGM_D_002 | BJ8: =VLOOKUP(BI8,'Axe 2 Règles de gestion'!$D$2:$F$225,3, FALSE) -> L'agent doit être en activité. | BK8: CGM_D_009 | BL8: =VLOOKUP(BK8,'Axe 2 Règles de gestion'!$D$2:$F$225,3, FALSE) -> L'agent qui a obtenu un congé de grave maladie pour une affection non liée à un accident de service ou maladie professionnelle ne peut bénéficier d'un autre congé de cette nature, s'il n'a pas auparavant repris l'exercice de ses fonctions pendant un an. | BM8: CGM_D_003 | BN8: =VLOOKUP(BM8,'Axe 2 Règles de gestion'!$D$2:$F$225,3, FALSE) -> L'agent doit compter au moins 3 ans de services. | BO8: CGM_D_042 | BP8: =VLOOKUP(BO8,'Axe 2 Règles de gestion'!$D$2:$F$225,3, FALSE) -> La 1ère année est rémunérée à plein traitement. | BQ8: CGM_D_045 | BR8: =VLOOKUP(BQ8,'Axe 2 Règles de gestion'!$D$2:$F$225,3, FALSE) -> Les 2ème et 3ème années sont rémunérées à demi-traitement. | BW8: ABS_C_002 | BX8: =VLOOKUP(BW8,'Axe 2 Règles de gestion'!$D$2:$F$225,3, FALSE) -> La date de début du congé/absence doit être postérieure ou égale à la date de début du lien juridique. | BY8: ABS_C_003 | BZ8: =VLOOKUP(BY8,'Axe 2 Règles de gestion'!$D$2:$F$225,3, FALSE) -> La date de début du congé/absence doit être antérieure ou égale à la date de fin réelle du congé/absence. | CA8: ABS_C_004 | CB8: =VLOOKUP(CA8,'Axe 2 Règles de gestion'!$D$2:$F$225,3, FALSE) -> La date de début du congé/absence doit être antérieure ou égale à la date de fin prévisionnelle du congé/absence. | CC8: ABS_C_005 | CD8: =VLOOKUP(CC8,'Axe 2 Règles de gestion'!$D$2:$F$225,3, FALSE) -> La date de fin réelle du congé/absence doit être antérieure ou égale à la date limite de fin réelle ou prévisionnelle du lien juridique. | CE8: ABS_C_006 | CF8: =VLOOKUP(CE8,'Axe 2 Règles de gestion'!$D$2:$F$225,3, FALSE) -> La date de fin prévisionnelle du congé/absence doit être antérieure ou égale à la date limite de fin réelle ou prévisionnelle du lien juridique. | CG8: ABS_C_007 | CH8: =VLOOKUP(CG8,'Axe 2 Règles de gestion'!$D$2:$F$225,3, FALSE) -> La date de fin réelle du congé/absence doit être antérieure à la date limite de départ à la retraite. | CI8: ABS_C_008 | CJ8: =VLOOKUP(CI8,'Axe 2 Règles de gestion'!$D$2:$F$225,3, FALSE) -> La date de fin prévisionnelle du congé/absence doit être antérieure à la date limite de départ à la retraite. | CK8: ABS_C_009 | CL8: =VLOOKUP(CK8,'Axe 2 Règles de gestion'!$D$2:$F$225,3, FALSE) -> La date de fin réelle ou la date de fin prévisionnelle du congé/absence doit être saisie. | CM8: ABS_C_015 | CN8: =VLOOKUP(CM8,'Axe 2 Règles de gestion'!$D$2:$F$225,3, FALSE) -> Pour chaque période d'absence découpée, la date de début d'impact rémunération doit être égale à la date de début du congé/absence. | CO8: ABS_C_016 | CP8: =VLOOKUP(CO8,'Axe 2 Règles de gestion'!$D$2:$F$225,3, FALSE) -> Pour chaque période d'absence découpée, la date de fin d'impact rémunération doit être égale à la date de fin prévisionnelle du congé/absence. | CQ8: ABS_C_018 | CR8: =VLOOKUP(CQ8,'Axe 2 Règles de gestion'!$D$2:$F$225,3, FALSE) -> Pour chaque période d'absence découpée, la date de fin d'impact rémunération doit être égale à la date de fin réelle du congé/absence. | CS8: ABS_C_019 | CT8: =VLOOKUP(CS8,'Axe 2 Règles de gestion'!$D$2:$F$225,3, FALSE) -> Si l'absence ne commence pas par une demi-journée et si l'absence précédente ne finit pas par une demi journée, la date de début de l'absence saisie est postérieure à la date de fin réelle de l'absence précédente. | CU8: ABS_C_020 | CV8: =VLOOKUP(CU8,'Axe 2 Règles de gestion'!$D$2:$F$225,3, FALSE) -> Si l'absence ne commence pas par une demi-journée et si l'absence précédente ne finit pas par une demi journée, la date de début de l'absence saisie est postérieure à la date de fin prévisionnelle de l'absence précédente. | CW8: ABS_C_023 | CX8: =VLOOKUP(CW8,'Axe 2 Règles de gestion'!$D$2:$F$225,3, FALSE) -> L'état du congé est renseigné. | CY8: ABS_C_024 | CZ8: =VLOOKUP(CY8,'Axe 2 Règles de gestion'!$D$2:$F$225,3, FALSE) -> Si le CMO est requalifié en CLM/CLD/CGM/CITIS alors l'impact rémunération saisi doit être un impact spécifique à la requalification. | DA8: ABS_C_025 | DB8: =VLOOKUP(DA8,'Axe 2 Règles de gestion'!$D$2:$F$225,3, FALSE) -> Si le congé/absence n'est pas issu d'une requalification d'un CMO ou d'un CITIS, alors l'impact rémunération saisi ne doit pas être un impact spécifique à la requalification.
A9: 24.10.00 | B9: M | C9: 45520.824 | D9: D0007 | E9: Congés/Absence | F9: S0056 | G9: Congé de grave maladie | H9: E0477 | I9: Congé de grave maladie | J9: Type de congé/absence saisi = "Congé de grave maladie" | K9: A_COA_TYCOAB [Saisi] = 'CM300' | L9: T1163 | M9: Congé de grave maladie - Initial | N9: Création Modification | O9: La valeur de l'Etat du congé est égale à 'initial' et la valeur de l'Etat du congé saisie est différente de celle avant saisie | P9: A_COA_ETCOMA [Saisi] = 'EC01' ET A_COA_ETCOMA [Saisi] <> A_COA_ETCOMA [Valeur avant saisie] | Q9: Contractuel | R9: P0003 | S9: N | T9: Général | U9: Passant | V9: 44634 | W9: 45535 | X9: CGM_I_174 ET CGM_I_195 ET CGM_I_105 ET CGM_I_199 ET CGM_I_178 ET CGM_I_182 ET CGM_I_207 ET CGM_I_213 ET CGM_I_129 ET CGM_I_165 ET CGM_I_073 ET CGM_D_007 ET CGM_D_008 ET CGM_D_002 ET CGM_D_009 ET CGM_D_003 ET CGM_D_042 ET CGM_D_045 ET ABS_C_002 ET ABS_C_003 ET ABS_C_004 ET ABS_C_005 ET ABS_C_006 ET ABS_C_007 ET ABS_C_008 ET ABS_C_009 ET ABS_C_015 ET ABS_C_016 ET ABS_C_018 ET ABS_C_019 ET ABS_C_020 ET ABS_C_023 ET ABS_C_024 ET ABS_C_025 | Y9: CGM_I_174 | Z9: =VLOOKUP(Y9,'Axe 2 Règles de gestion'!$D$2:$F$225,3, FALSE) -> Le bénéfice d'un congé de grave maladie demandé pour une affection qui n'est pas inscrite sur la liste indicative de maladies peut être accordé après l'avis du conseil médical compétent. | AA9: CGM_I_195 | AB9: =VLOOKUP(AA9,'Axe 2 Règles de gestion'!$D$2:$F$225,3, FALSE) -> L'agent doit adresser à son chef de service une demande appuyée d'un certificat d'un médecin. | AC9: CGM_I_105 | AD9: =VLOOKUP(AC9,'Axe 2 Règles de gestion'!$D$2:$F$225,3, FALSE) -> L'avis du conseil médical doit être rendu. | AE9: CGM_I_199 | AF9: =VLOOKUP(AE9,'Axe 2 Règles de gestion'!$D$2:$F$225,3, FALSE) -> Le médecin adresse au président du conseil médical un résumé de ses observations et toute pièce justifiant la situation de l'agent. | AG9: CGM_I_178 | AH9: =VLOOKUP(AG9,'Axe 2 Règles de gestion'!$D$2:$F$225,3, FALSE) -> Le congé peut être octroyé d'office au vu d'une attestation médicale ou d'un rapport des supérieurs hiérarchiques. Le chef de service saisit alors le conseil médical. | AI9: CGM_I_182 | AJ9: =VLOOKUP(AI9,'Axe 2 Règles de gestion'!$D$2:$F$225,3, FALSE) -> Si le chef de service saisit le conseil médical, il informe de cette saisine le médecin du travail qui transmet un rapport au conseil médical. | AK9: CGM_I_207 | AL9: =VLOOKUP(AK9,'Axe 2 Règles de gestion'!$D$2:$F$225,3, FALSE) -> Un contrôle pourra être effectué à tout moment par un médecin agréé de l'administration. | AM9: CGM_I_213 | AN9: =VLOOKUP(AM9,'Axe 2 Règles de gestion'!$D$2:$F$225,3, FALSE) -> L'avis d'un conseil médical rendu en formation restreinte peut être contesté devant le conseil médical supérieur par l'administration ou l'agent dans le délai de deux mois à compter de sa notification. | AO9: CGM_I_129 | AP9: =VLOOKUP(AO9,'Axe 2 Règles de gestion'!$D$2:$F$225,3, FALSE) -> L'agent informe l'administration de tout changement de domicile et, sauf en cas d'hospitalisation, de toute absence du domicile supérieure à deux semaines. Il informe l'administration de ses dates et lieux de séjour. | AQ9: CGM_I_165 | AR9: =VLOOKUP(AQ9,'Axe 2 Règles de gestion'!$D$2:$F$225,3, FALSE) -> L'agent doit se soumettre aux visites de contrôle prescrites par le médecin agréé ou le conseil médical. | AS9: CGM_I_073 | AT9: =VLOOKUP(AS9,'Axe 2 Règles de gestion'!$D$2:$F$225,3, FALSE) -> Le refus répété et sans motif valable de se soumettre aux visites de contrôle peut entraîner, après mise en demeure de l'agent, la perte du bénéfice du congé. | BE9: CGM_D_007 | BF9: =VLOOKUP(BE9,'Axe 2 Règles de gestion'!$D$2:$F$225,3, FALSE) -> Le CGM peut être accordé pour chaque période pour une durée maximale de 6 mois. | BG9: CGM_D_008 | BH9: =VLOOKUP(BG9,'Axe 2 Règles de gestion'!$D$2:$F$225,3, FALSE) -> La durée du CGM est de 3 ans maximum. Pour certaines pathologies, le CGM peut être accordé de manière fractionnée : les droits aux 3 ans de congé sont alors appréciés sur une période de référence de 4 ans. | BI9: CGM_D_002 | BJ9: =VLOOKUP(BI9,'Axe 2 Règles de gestion'!$D$2:$F$225,3, FALSE) -> L'agent doit être en activité. | BK9: CGM_D_009 | BL9: =VLOOKUP(BK9,'Axe 2 Règles de gestion'!$D$2:$F$225,3, FALSE) -> L'agent qui a obtenu un congé de grave maladie pour une affection non liée à un accident de service ou maladie professionnelle ne peut bénéficier d'un autre congé de cette nature, s'il n'a pas auparavant repris l'exercice de ses fonctions pendant un an. | BM9: CGM_D_003 | BN9: =VLOOKUP(BM9,'Axe 2 Règles de gestion'!$D$2:$F$225,3, FALSE) -> L'agent doit compter au moins 3 ans de services. | BO9: CGM_D_042 | BP9: =VLOOKUP(BO9,'Axe 2 Règles de gestion'!$D$2:$F$225,3, FALSE) -> La 1ère année est rémunérée à plein traitement. | BQ9: CGM_D_045 | BR9: =VLOOKUP(BQ9,'Axe 2 Règles de gestion'!$D$2:$F$225,3, FALSE) -> Les 2ème et 3ème années sont rémunérées à demi-traitement. | BW9: ABS_C_002 | BX9: =VLOOKUP(BW9,'Axe 2 Règles de gestion'!$D$2:$F$225,3, FALSE) -> La date de début du congé/absence doit être postérieure ou égale à la date de début du lien juridique. | BY9: ABS_C_003 | BZ9: =VLOOKUP(BY9,'Axe 2 Règles de gestion'!$D$2:$F$225,3, FALSE) -> La date de début du congé/absence doit être antérieure ou égale à la date de fin réelle du congé/absence. | CA9: ABS_C_004 | CB9: =VLOOKUP(CA9,'Axe 2 Règles de gestion'!$D$2:$F$225,3, FALSE) -> La date de début du congé/absence doit être antérieure ou égale à la date de fin prévisionnelle du congé/absence. | CC9: ABS_C_005 | CD9: =VLOOKUP(CC9,'Axe 2 Règles de gestion'!$D$2:$F$225,3, FALSE) -> La date de fin réelle du congé/absence doit être antérieure ou égale à la date limite de fin réelle ou prévisionnelle du lien juridique. | CE9: ABS_C_006 | CF9: =VLOOKUP(CE9,'Axe 2 Règles de gestion'!$D$2:$F$225,3, FALSE) -> La date de fin prévisionnelle du congé/absence doit être antérieure ou égale à la date limite de fin réelle ou prévisionnelle du lien juridique. | CG9: ABS_C_007 | CH9: =VLOOKUP(CG9,'Axe 2 Règles de gestion'!$D$2:$F$225,3, FALSE) -> La date de fin réelle du congé/absence doit être antérieure à la date limite de départ à la retraite. | CI9: ABS_C_008 | CJ9: =VLOOKUP(CI9,'Axe 2 Règles de gestion'!$D$2:$F$225,3, FALSE) -> La date de fin prévisionnelle du congé/absence doit être antérieure à la date limite de départ à la retraite. | CK9: ABS_C_009 | CL9: =VLOOKUP(CK9,'Axe 2 Règles de gestion'!$D$2:$F$225,3, FALSE) -> La date de fin réelle ou la date de fin prévisionnelle du congé/absence doit être saisie. | CM9: ABS_C_015 | CN9: =VLOOKUP(CM9,'Axe 2 Règles de gestion'!$D$2:$F$225,3, FALSE) -> Pour chaque période d'absence découpée, la date de début d'impact rémunération doit être égale à la date de début du congé/absence. | CO9: ABS_C_016 | CP9: =VLOOKUP(CO9,'Axe 2 Règles de gestion'!$D$2:$F$225,3, FALSE) -> Pour chaque période d'absence découpée, la date de fin d'impact rémunération doit être égale à la date de fin prévisionnelle du congé/absence. | CQ9: ABS_C_018 | CR9: =VLOOKUP(CQ9,'Axe 2 Règles de gestion'!$D$2:$F$225,3, FALSE) -> Pour chaque période d'absence découpée, la date de fin d'impact rémunération doit être égale à la date de fin réelle du congé/absence. | CS9: ABS_C_019 | CT9: =VLOOKUP(CS9,'Axe 2 Règles de gestion'!$D$2:$F$225,3, FALSE) -> Si l'absence ne commence pas par une demi-journée et si l'absence précédente ne finit pas par une demi journée, la date de début de l'absence saisie est postérieure à la date de fin réelle de l'absence précédente. | CU9: ABS_C_020 | CV9: =VLOOKUP(CU9,'Axe 2 Règles de gestion'!$D$2:$F$225,3, FALSE) -> Si l'absence ne commence pas par une demi-journée et si l'absence précédente ne finit pas par une demi journée, la date de début de l'absence saisie est postérieure à la date de fin prévisionnelle de l'absence précédente. | CW9: ABS_C_023 | CX9: =VLOOKUP(CW9,'Axe 2 Règles de gestion'!$D$2:$F$225,3, FALSE) -> L'état du congé est renseigné. | CY9: ABS_C_024 | CZ9: =VLOOKUP(CY9,'Axe 2 Règles de gestion'!$D$2:$F$225,3, FALSE) -> Si le CMO est requalifié en CLM/CLD/CGM/CITIS alors l'impact rémunération saisi doit être un impact spécifique à la requalification. | DA9: ABS_C_025 | DB9: =VLOOKUP(DA9,'Axe 2 Règles de gestion'!$D$2:$F$225,3, FALSE) -> Si le congé/absence n'est pas issu d'une requalification d'un CMO ou d'un CITIS, alors l'impact rémunération saisi ne doit pas être un impact spécifique à la requalification.
A10: 25.10.00 | B10: M | C10: 45922.467 | D10: D0007 | E10: Congés/Absence | F10: S0056 | G10: Congé de grave maladie | H10: E0477 | I10: Congé de grave maladie | J10: Type de congé/absence saisi = "Congé de grave maladie" | K10: A_COA_TYCOAB [Saisi] = 'CM300' | L10: T1163 | M10: Congé de grave maladie - Initial | N10: Création Modification | O10: La valeur de l'Etat du congé est égale à 'initial' et la valeur de l'Etat du congé saisie est différente de celle avant saisie | P10: A_COA_ETCOMA [Saisi] = 'EC01' ET A_COA_ETCOMA [Saisi] <> A_COA_ETCOMA [Valeur avant saisie] | Q10: Contractuel | R10: P0003 | S10: N | T10: Général | U10: Passant | V10: 45536 | X10: CGM_I_174 ET CGM_I_195 ET CGM_I_105 ET CGM_I_199 ET CGM_I_178 ET CGM_I_182 ET CGM_I_207 ET CGM_I_213 ET CGM_I_129 ET CGM_I_165 ET CGM_I_073 ET CGM_D_007 ET CGM_D_008 ET CGM_D_009 ET CGM_D_004 ET CGM_D_005 ET CGM_D_006 ET CGM_D_002 ET ABS_C_002 ET ABS_C_003 ET ABS_C_004 ET ABS_C_005 ET ABS_C_006 ET ABS_C_007 ET ABS_C_008 ET ABS_C_009 ET ABS_C_015 ET ABS_C_016 ET ABS_C_018 ET ABS_C_019 ET ABS_C_020 ET ABS_C_023 ET ABS_C_024 ET ABS_C_025 ET ABS_C_011 | Y10: CGM_I_174 | Z10: =VLOOKUP(Y10,'Axe 2 Règles de gestion'!$D$2:$F$225,3, FALSE) -> Le bénéfice d'un congé de grave maladie demandé pour une affection qui n'est pas inscrite sur la liste indicative de maladies peut être accordé après l'avis du conseil médical compétent. | AA10: CGM_I_195 | AB10: =VLOOKUP(AA10,'Axe 2 Règles de gestion'!$D$2:$F$225,3, FALSE) -> L'agent doit adresser à son chef de service une demande appuyée d'un certificat d'un médecin. | AC10: CGM_I_105 | AD10: =VLOOKUP(AC10,'Axe 2 Règles de gestion'!$D$2:$F$225,3, FALSE) -> L'avis du conseil médical doit être rendu. | AE10: CGM_I_199 | AF10: =VLOOKUP(AE10,'Axe 2 Règles de gestion'!$D$2:$F$225,3, FALSE) -> Le médecin adresse au président du conseil médical un résumé de ses observations et toute pièce justifiant la situation de l'agent. | AG10: CGM_I_178 | AH10: =VLOOKUP(AG10,'Axe 2 Règles de gestion'!$D$2:$F$225,3, FALSE) -> Le congé peut être octroyé d'office au vu d'une attestation médicale ou d'un rapport des supérieurs hiérarchiques. Le chef de service saisit alors le conseil médical. | AI10: CGM_I_182 | AJ10: =VLOOKUP(AI10,'Axe 2 Règles de gestion'!$D$2:$F$225,3, FALSE) -> Si le chef de service saisit le conseil médical, il informe de cette saisine le médecin du travail qui transmet un rapport au conseil médical. | AK10: CGM_I_207 | AL10: =VLOOKUP(AK10,'Axe 2 Règles de gestion'!$D$2:$F$225,3, FALSE) -> Un contrôle pourra être effectué à tout moment par un médecin agréé de l'administration. | AM10: CGM_I_213 | AN10: =VLOOKUP(AM10,'Axe 2 Règles de gestion'!$D$2:$F$225,3, FALSE) -> L'avis d'un conseil médical rendu en formation restreinte peut être contesté devant le conseil médical supérieur par l'administration ou l'agent dans le délai de deux mois à compter de sa notification. | AO10: CGM_I_129 | AP10: =VLOOKUP(AO10,'Axe 2 Règles de gestion'!$D$2:$F$225,3, FALSE) -> L'agent informe l'administration de tout changement de domicile et, sauf en cas d'hospitalisation, de toute absence du domicile supérieure à deux semaines. Il informe l'administration de ses dates et lieux de séjour. | AQ10: CGM_I_165 | AR10: =VLOOKUP(AQ10,'Axe 2 Règles de gestion'!$D$2:$F$225,3, FALSE) -> L'agent doit se soumettre aux visites de contrôle prescrites par le médecin agréé ou le conseil médical. | AS10: CGM_I_073 | AT10: =VLOOKUP(AS10,'Axe 2 Règles de gestion'!$D$2:$F$225,3, FALSE) -> Le refus répété et sans motif valable de se soumettre aux visites de contrôle peut entraîner, après mise en demeure de l'agent, la perte du bénéfice du congé. | BE10: CGM_D_007 | BF10: =VLOOKUP(BE10,'Axe 2 Règles de gestion'!$D$2:$F$225,3, FALSE) -> Le CGM peut être accordé pour chaque période pour une durée maximale de 6 mois. | BG10: CGM_D_008 | BH10: =VLOOKUP(BG10,'Axe 2 Règles de gestion'!$D$2:$F$225,3, FALSE) -> La durée du CGM est de 3 ans maximum. Pour certaines pathologies, le CGM peut être accordé de manière fractionnée : les droits aux 3 ans de congé sont alors appréciés sur une période de référence de 4 ans. | BI10: CGM_D_009 | BJ10: =VLOOKUP(BI10,'Axe 2 Règles de gestion'!$D$2:$F$225,3, FALSE) -> L'agent qui a obtenu un congé de grave maladie pour une affection non liée à un accident de service ou maladie professionnelle ne peut bénéficier d'un autre congé de cette nature, s'il n'a pas auparavant repris l'exercice de ses fonctions pendant un an. | BK10: CGM_D_004 | BL10: =VLOOKUP(BK10,'Axe 2 Règles de gestion'!$D$2:$F$225,3, FALSE) -> L'agent doit compter au moins 4 mois de services effectués en qualité d'agent public pour le compte des personnes publiques mentionnées à l'article L. 2 du code général de la fonction publique. | BM10: CGM_D_005 | BN10: =VLOOKUP(BM10,'Axe 2 Règles de gestion'!$D$2:$F$225,3, FALSE) -> La première année du congé de grave maladie est rémunérée à plein traitement. | BO10: CGM_D_006 | BP10: =VLOOKUP(BO10,'Axe 2 Règles de gestion'!$D$2:$F$225,3, FALSE) -> La deuxième et la troisième années du congé de grave maladie sont rémunérées à 60% du traitement. | BQ10: CGM_D_002 | BR10: =VLOOKUP(BQ10,'Axe 2 Règles de gestion'!$D$2:$F$225,3, FALSE) -> L'agent doit être en activité. | BW10: ABS_C_002 | BX10: =VLOOKUP(BW10,'Axe 2 Règles de gestion'!$D$2:$F$225,3, FALSE) -> La date de début du congé/absence doit être postérieure ou égale à la date de début du lien juridique. | BY10: ABS_C_003 | BZ10: =VLOOKUP(BY10,'Axe 2 Règles de gestion'!$D$2:$F$225,3, FALSE) -> La date de début du congé/absence doit être antérieure ou égale à la date de fin réelle du congé/absence. | CA10: ABS_C_004 | CB10: =VLOOKUP(CA10,'Axe 2 Règles de gestion'!$D$2:$F$225,3, FALSE) -> La date de début du congé/absence doit être antérieure ou égale à la date de fin prévisionnelle du congé/absence. | CC10: ABS_C_005 | CD10: =VLOOKUP(CC10,'Axe 2 Règles de gestion'!$D$2:$F$225,3, FALSE) -> La date de fin réelle du congé/absence doit être antérieure ou égale à la date limite de fin réelle ou prévisionnelle du lien juridique. | CE10: ABS_C_006 | CF10: =VLOOKUP(CE10,'Axe 2 Règles de gestion'!$D$2:$F$225,3, FALSE) -> La date de fin prévisionnelle du congé/absence doit être antérieure ou égale à la date limite de fin réelle ou prévisionnelle du lien juridique. | CG10: ABS_C_007 | CH10: =VLOOKUP(CG10,'Axe 2 Règles de gestion'!$D$2:$F$225,3, FALSE) -> La date de fin réelle du congé/absence doit être antérieure à la date limite de départ à la retraite. | CI10: ABS_C_008 | CJ10: =VLOOKUP(CI10,'Axe 2 Règles de gestion'!$D$2:$F$225,3, FALSE) -> La date de fin prévisionnelle du congé/absence doit être antérieure à la date limite de départ à la retraite. | CK10: ABS_C_009 | CL10: =VLOOKUP(CK10,'Axe 2 Règles de gestion'!$D$2:$F$225,3, FALSE) -> La date de fin réelle ou la date de fin prévisionnelle du congé/absence doit être saisie. | CM10: ABS_C_015 | CN10: =VLOOKUP(CM10,'Axe 2 Règles de gestion'!$D$2:$F$225,3, FALSE) -> Pour chaque période d'absence découpée, la date de début d'impact rémunération doit être égale à la date de début du congé/absence. | CO10: ABS_C_016 | CP10: =VLOOKUP(CO10,'Axe 2 Règles de gestion'!$D$2:$F$225,3, FALSE) -> Pour chaque période d'absence découpée, la date de fin d'impact rémunération doit être égale à la date de fin prévisionnelle du congé/absence. | CQ10: ABS_C_018 | CR10: =VLOOKUP(CQ10,'Axe 2 Règles de gestion'!$D$2:$F$225,3, FALSE) -> Pour chaque période d'absence découpée, la date de fin d'impact rémunération doit être égale à la date de fin réelle du congé/absence. | CS10: ABS_C_019 | CT10: =VLOOKUP(CS10,'Axe 2 Règles de gestion'!$D$2:$F$225,3, FALSE) -> Si l'absence ne commence pas par une demi-journée et si l'absence précédente ne finit pas par une demi journée, la date de début de l'absence saisie est postérieure à la date de fin réelle de l'absence précédente. | CU10: ABS_C_020 | CV10: =VLOOKUP(CU10,'Axe 2 Règles de gestion'!$D$2:$F$225,3, FALSE) -> Si l'absence ne commence pas par une demi-journée et si l'absence précédente ne finit pas par une demi journée, la date de début de l'absence saisie est postérieure à la date de fin prévisionnelle de l'absence précédente. | CW10: ABS_C_023 | CX10: =VLOOKUP(CW10,'Axe 2 Règles de gestion'!$D$2:$F$225,3, FALSE) -> L'état du congé est renseigné. | CY10: ABS_C_024 | CZ10: =VLOOKUP(CY10,'Axe 2 Règles de gestion'!$D$2:$F$225,3, FALSE) -> Si le CMO est requalifié en CLM/CLD/CGM/CITIS alors l'impact rémunération saisi doit être un impact spécifique à la requalification. | DA10: ABS_C_025 | DB10: =VLOOKUP(DA10,'Axe 2 Règles de gestion'!$D$2:$F$225,3, FALSE) -> Si le congé/absence n'est pas issu d'une requalification d'un CMO ou d'un CITIS, alors l'impact rémunération saisi ne doit pas être un impact spécifique à la requalification. | DC10: ABS_C_011 | DD10: =VLOOKUP(DC10,'Axe 2 Règles de gestion'!$D$2:$F$225,3, FALSE) -> Attention : La date d'effet l'avis du conseil médical doit être saisie afin d'être récupérée automatiquement lors de la génération de l'acte.
A11: 22.00.00 | B11: M | C11: 45520.826 | D11: D0007 | E11: Congés/Absence | F11: S0056 | G11: Congé de grave maladie | H11: E0477 | I11: Congé de grave maladie | J11: Type de congé/absence saisi = "Congé de grave maladie" | K11: A_COA_TYCOAB [Saisi] = 'CM300' | L11: T1164 | M11: Congé de grave maladie - Prolongation | N11: Création Modification | O11: La valeur de l'Etat du congé est égale à 'Renouvellement' et la valeur de l'Etat du congé saisie est différente de celle avant saisie | P11: A_COA_ETCOMA [Saisi] = 'EC02' ET A_COA_ETCOMA [Saisi] <> A_COA_ETCOMA [Valeur avant saisie] | Q11: Contractuel | R11: P0003 | S11: N | T11: Général | U11: Passant | V11: 40725 | W11: 44633 | X11: CGM_I_013 ET CGM_I_049 ET CGM_I_077 ET CGM_I_081 ET CGM_I_021 ET CGM_I_029 ET CGM_I_041 ET CGM_I_061 ET CGM_I_109 ET CGM_I_037 ET CGM_I_073 ET CGM_I_001 ET CGM_I_005 ET CGM_I_093 ET CGM_D_007 ET CGM_D_008 ET CGM_D_042 ET CGM_D_045 ET ABS_C_002 ET ABS_C_003 ET ABS_C_004 ET ABS_C_005 ET ABS_C_006 ET ABS_C_007 ET ABS_C_008 ET ABS_C_009 ET ABS_C_015 ET ABS_C_016 ET ABS_C_018 ET ABS_C_019 ET ABS_C_020 ET ABS_C_023 ET ABS_C_024 ET ABS_C_025 | Y11: CGM_I_013 | Z11: =VLOOKUP(Y11,'Axe 2 Règles de gestion'!$D$2:$F$225,3, FALSE) -> Avant l'expiration de chaque période de congé et à l'occasion de chaque demande de renouvellement, l'agent est tenu de produire à son administration certaines justifications. | AA11: CGM_I_049 | AB11: =VLOOKUP(AA11,'Axe 2 Règles de gestion'!$D$2:$F$225,3, FALSE) -> L'agent ou son représentant légal doit adresser la demande de renouvellement à l'administration 1 mois avant l'expiration de la période en cours appuyée d'un certificat du médecin traitant. | AC11: CGM_I_077 | AD11: =VLOOKUP(AC11,'Axe 2 Règles de gestion'!$D$2:$F$225,3, FALSE) -> Le secrétaire du comité médical fait procéder à la contre-visite du demandeur par un médecin agréé. | AE11: CGM_I_081 | AF11: =VLOOKUP(AE11,'Axe 2 Règles de gestion'!$D$2:$F$225,3, FALSE) -> Lorsque l'agent sollicite l'octroi de l'ultime période de congé rétribué à laquelle il a droit, le comité médical doit également se prononcer sur l'aptitude ou l'inaptitude présumée de l'agent à reprendre ses fonctions à l'issue de cette prolongation. | AG11: CGM_I_021 | AH11: =VLOOKUP(AG11,'Axe 2 Règles de gestion'!$D$2:$F$225,3, FALSE) -> En cas de contestation par l'administration ou l'agent de la décision du comité médical, ce dernier est soumis au comité médical supérieur. | AI11: CGM_I_029 | AJ11: =VLOOKUP(AI11,'Axe 2 Règles de gestion'!$D$2:$F$225,3, FALSE) -> La durée du congé est fixée sur la proposition du comité médical. | AK11: CGM_I_041 | AL11: =VLOOKUP(AK11,'Axe 2 Règles de gestion'!$D$2:$F$225,3, FALSE) -> L'agent est tenu de notifier ses changements de résidence successifs au chef de service chargé de la gestion du personnel de l'administration dont il dépend. | AM11: CGM_I_061 | AN11: =VLOOKUP(AM11,'Axe 2 Règles de gestion'!$D$2:$F$225,3, FALSE) -> Le chef de service s'assure par les contrôles appropriés que l'agent n'exerce pas pendant son congé d'activité interdite. | AO11: CGM_I_109 | AP11: =VLOOKUP(AO11,'Axe 2 Règles de gestion'!$D$2:$F$225,3, FALSE) -> Un contrôle pourra être effectué à tout moment par un médecin agréé de l'administration. Si les conclusions du médecin agréé donnent lieu à contestation, le comité médical peut être saisi. | AQ11: CGM_I_037 | AR11: =VLOOKUP(AQ11,'Axe 2 Règles de gestion'!$D$2:$F$225,3, FALSE) -> L'agent doit se soumettre, sous le contrôle du médecin agréé, et s'il y a lieu, du comité médical compétent, aux prescriptions et aux visites de contrôles que son état comporte. | AS11: CGM_I_073 | AT11: =VLOOKUP(AS11,'Axe 2 Règles de gestion'!$D$2:$F$225,3, FALSE) -> Le refus répété et sans motif valable de se soumettre aux visites de contrôle peut entraîner, après mise en demeure de l'agent, la perte du bénéfice du congé. | AU11: CGM_I_001 | AV11: =VLOOKUP(AU11,'Axe 2 Règles de gestion'!$D$2:$F$225,3, FALSE) -> A l'issue de chaque période de congé, l'agent doit passer un examen et le comité médical compétent doit se prononcer sur son état de santé. | AW11: CGM_I_005 | AX11: =VLOOKUP(AW11,'Axe 2 Règles de gestion'!$D$2:$F$225,3, FALSE) -> Cet examen peut être demandé soit par l'agent, soit par l'administration dont il relève. | AY11: CGM_I_093 | AZ11: =VLOOKUP(AY11,'Axe 2 Règles de gestion'!$D$2:$F$225,3, FALSE) -> Si l'agent est reconnu inapte à exercer ses fonctions, le congé continue à courir ou est renouvelé. | BE11: CGM_D_007 | BF11: =VLOOKUP(BE11,'Axe 2 Règles de gestion'!$D$2:$F$225,3, FALSE) -> Le CGM peut être accordé pour chaque période pour une durée maximale de 6 mois. | BG11: CGM_D_008 | BH11: =VLOOKUP(BG11,'Axe 2 Règles de gestion'!$D$2:$F$225,3, FALSE) -> La durée du CGM est de 3 ans maximum. Pour certaines pathologies, le CGM peut être accordé de manière fractionnée : les droits aux 3 ans de congé sont alors appréciés sur une période de référence de 4 ans. | BI11: CGM_D_042 | BJ11: =VLOOKUP(BI11,'Axe 2 Règles de gestion'!$D$2:$F$225,3, FALSE) -> La 1ère année est rémunérée à plein traitement. | BK11: CGM_D_045 | BL11: =VLOOKUP(BK11,'Axe 2 Règles de gestion'!$D$2:$F$225,3, FALSE) -> Les 2ème et 3ème années sont rémunérées à demi-traitement. | BW11: ABS_C_002 | BX11: =VLOOKUP(BW11,'Axe 2 Règles de gestion'!$D$2:$F$225,3, FALSE) -> La date de début du congé/absence doit être postérieure ou égale à la date de début du lien juridique. | BY11: ABS_C_003 | BZ11: =VLOOKUP(BY11,'Axe 2 Règles de gestion'!$D$2:$F$225,3, FALSE) -> La date de début du congé/absence doit être antérieure ou égale à la date de fin réelle du congé/absence. | CA11: ABS_C_004 | CB11: =VLOOKUP(CA11,'Axe 2 Règles de gestion'!$D$2:$F$225,3, FALSE) -> La date de début du congé/absence doit être antérieure ou égale à la date de fin prévisionnelle du congé/absence. | CC11: ABS_C_005 | CD11: =VLOOKUP(CC11,'Axe 2 Règles de gestion'!$D$2:$F$225,3, FALSE) -> La date de fin réelle du congé/absence doit être antérieure ou égale à la date limite de fin réelle ou prévisionnelle du lien juridique. | CE11: ABS_C_006 | CF11: =VLOOKUP(CE11,'Axe 2 Règles de gestion'!$D$2:$F$225,3, FALSE) -> La date de fin prévisionnelle du congé/absence doit être antérieure ou égale à la date limite de fin réelle ou prévisionnelle du lien juridique. | CG11: ABS_C_007 | CH11: =VLOOKUP(CG11,'Axe 2 Règles de gestion'!$D$2:$F$225,3, FALSE) -> La date de fin réelle du congé/absence doit être antérieure à la date limite de départ à la retraite. | CI11: ABS_C_008 | CJ11: =VLOOKUP(CI11,'Axe 2 Règles de gestion'!$D$2:$F$225,3, FALSE) -> La date de fin prévisionnelle du congé/absence doit être antérieure à la date limite de départ à la retraite. | CK11: ABS_C_009 | CL11: =VLOOKUP(CK11,'Axe 2 Règles de gestion'!$D$2:$F$225,3, FALSE) -> La date de fin réelle ou la date de fin prévisionnelle du congé/absence doit être saisie. | CM11: ABS_C_015 | CN11: =VLOOKUP(CM11,'Axe 2 Règles de gestion'!$D$2:$F$225,3, FALSE) -> Pour chaque période d'absence découpée, la date de début d'impact rémunération doit être égale à la date de début du congé/absence. | CO11: ABS_C_016 | CP11: =VLOOKUP(CO11,'Axe 2 Règles de gestion'!$D$2:$F$225,3, FALSE) -> Pour chaque période d'absence découpée, la date de fin d'impact rémunération doit être égale à la date de fin prévisionnelle du congé/absence. | CQ11: ABS_C_018 | CR11: =VLOOKUP(CQ11,'Axe 2 Règles de gestion'!$D$2:$F$225,3, FALSE) -> Pour chaque période d'absence découpée, la date de fin d'impact rémunération doit être égale à la date de fin réelle du congé/absence. | CS11: ABS_C_019 | CT11: =VLOOKUP(CS11,'Axe 2 Règles de gestion'!$D$2:$F$225,3, FALSE) -> Si l'absence ne commence pas par une demi-journée et si l'absence précédente ne finit pas par une demi journée, la date de début de l'absence saisie est postérieure à la date de fin réelle de l'absence précédente. | CU11: ABS_C_020 | CV11: =VLOOKUP(CU11,'Axe 2 Règles de gestion'!$D$2:$F$225,3, FALSE) -> Si l'absence ne commence pas par une demi-journée et si l'absence précédente ne finit pas par une demi journée, la date de début de l'absence saisie est postérieure à la date de fin prévisionnelle de l'absence précédente. | CW11: ABS_C_023 | CX11: =VLOOKUP(CW11,'Axe 2 Règles de gestion'!$D$2:$F$225,3, FALSE) -> L'état du congé est renseigné. | CY11: ABS_C_024 | CZ11: =VLOOKUP(CY11,'Axe 2 Règles de gestion'!$D$2:$F$225,3, FALSE) -> Si le CMO est requalifié en CLM/CLD/CGM/CITIS alors l'impact rémunération saisi doit être un impact spécifique à la requalification. | DA11: ABS_C_025 | DB11: =VLOOKUP(DA11,'Axe 2 Règles de gestion'!$D$2:$F$225,3, FALSE) -> Si le congé/absence n'est pas issu d'une requalification d'un CMO ou d'un CITIS, alors l'impact rémunération saisi ne doit pas être un impact spécifique à la requalification.
A12: 24.10.00 | B12: M | C12: 45520.826 | D12: D0007 | E12: Congés/Absence | F12: S0056 | G12: Congé de grave maladie | H12: E0477 | I12: Congé de grave maladie | J12: Type de congé/absence saisi = "Congé de grave maladie" | K12: A_COA_TYCOAB [Saisi] = 'CM300' | L12: T1164 | M12: Congé de grave maladie - Prolongation | N12: Création Modification | O12: La valeur de l'Etat du congé est égale à 'Renouvellement' et la valeur de l'Etat du congé saisie est différente de celle avant saisie | P12: A_COA_ETCOMA [Saisi] = 'EC02' ET A_COA_ETCOMA [Saisi] <> A_COA_ETCOMA [Valeur avant saisie] | Q12: Contractuel | R12: P0003 | S12: N | T12: Général | U12: Passant | V12: 44634 | W12: 45535 | X12: CGM_I_203 ET CGM_I_206 ET CGM_I_121 ET CGM_I_125 ET CGM_I_207 ET CGM_I_213 ET CGM_I_129 ET CGM_I_165 ET CGM_I_073 ET CGM_I_157 ET CGM_D_007 ET CGM_D_008 ET CGM_D_042 ET CGM_D_045 ET ABS_C_002 ET ABS_C_003 ET ABS_C_004 ET ABS_C_005 ET ABS_C_006 ET ABS_C_007 ET ABS_C_008 ET ABS_C_009 ET ABS_C_015 ET ABS_C_016 ET ABS_C_018 ET ABS_C_019 ET ABS_C_020 ET ABS_C_023 ET ABS_C_024 ET ABS_C_025 | Y12: CGM_I_203 | Z12: =VLOOKUP(Y12,'Axe 2 Règles de gestion'!$D$2:$F$225,3, FALSE) -> Pour obtenir le renouvellement au terme d'une période en cours, l'agent adresse à l'administration un certificat médical de son médecin prolongeant le congé initial et précisant sa durée. | AA12: CGM_I_206 | AB12: =VLOOKUP(AA12,'Axe 2 Règles de gestion'!$D$2:$F$225,3, FALSE) -> Lorsque le congé est octroyé après saisine du conseil médical par le chef de service, l'administration fait procéder, au terme de chaque période, à l'examen médical de l'agent. Le renouvellement est accordé au vu de l'avis du médecin agréé. | AC12: CGM_I_121 | AD12: =VLOOKUP(AC12,'Axe 2 Règles de gestion'!$D$2:$F$225,3, FALSE) -> Lorsque la période rémunérée à plein traitement n'est pas épuisée, le renouvellement est accordé sans saisine du conseil médical. L'administration fait procéder à l'examen de l'agent, qui s'y soumet, par un médecin agréé au moins une fois par an. | AE12: CGM_I_125 | AF12: =VLOOKUP(AE12,'Axe 2 Règles de gestion'!$D$2:$F$225,3, FALSE) -> Lorsque la période rémunérée à plein traitement est épuisée, le conseil médical en formation restreinte est consulté pour avis sur le renouvellement du congé. | AG12: CGM_I_207 | AH12: =VLOOKUP(AG12,'Axe 2 Règles de gestion'!$D$2:$F$225,3, FALSE) -> Un contrôle pourra être effectué à tout moment par un médecin agréé de l'administration. | AI12: CGM_I_213 | AJ12: =VLOOKUP(AI12,'Axe 2 Règles de gestion'!$D$2:$F$225,3, FALSE) -> L'avis d'un conseil médical rendu en formation restreinte peut être contesté devant le conseil médical supérieur par l'administration ou l'agent dans le délai de deux mois à compter de sa notification. | AK12: CGM_I_129 | AL12: =VLOOKUP(AK12,'Axe 2 Règles de gestion'!$D$2:$F$225,3, FALSE) -> L'agent informe l'administration de tout changement de domicile et, sauf en cas d'hospitalisation, de toute absence du domicile supérieure à deux semaines. Il informe l'administration de ses dates et lieux de séjour. | AM12: CGM_I_165 | AN12: =VLOOKUP(AM12,'Axe 2 Règles de gestion'!$D$2:$F$225,3, FALSE) -> L'agent doit se soumettre aux visites de contrôle prescrites par le médecin agréé ou le conseil médical. | AO12: CGM_I_073 | AP12: =VLOOKUP(AO12,'Axe 2 Règles de gestion'!$D$2:$F$225,3, FALSE) -> Le refus répété et sans motif valable de se soumettre aux visites de contrôle peut entraîner, après mise en demeure de l'agent, la perte du bénéfice du congé. | AQ12: CGM_I_157 | AR12: =VLOOKUP(AQ12,'Axe 2 Règles de gestion'!$D$2:$F$225,3, FALSE) -> Si l'agent est reconnu inapte à exercer ses fonctions par le conseil médical, le congé continue à courir ou est renouvelé pour une nouvelle période sous réserve des droits restants. | BE12: CGM_D_007 | BF12: =VLOOKUP(BE12,'Axe 2 Règles de gestion'!$D$2:$F$225,3, FALSE) -> Le CGM peut être accordé pour chaque période pour une durée maximale de 6 mois. | BG12: CGM_D_008 | BH12: =VLOOKUP(BG12,'Axe 2 Règles de gestion'!$D$2:$F$225,3, FALSE) -> La durée du CGM est de 3 ans maximum. Pour certaines pathologies, le CGM peut être accordé de manière fractionnée : les droits aux 3 ans de congé sont alors appréciés sur une période de référence de 4 ans. | BI12: CGM_D_042 | BJ12: =VLOOKUP(BI12,'Axe 2 Règles de gestion'!$D$2:$F$225,3, FALSE) -> La 1ère année est rémunérée à plein traitement. | BK12: CGM_D_045 | BL12: =VLOOKUP(BK12,'Axe 2 Règles de gestion'!$D$2:$F$225,3, FALSE) -> Les 2ème et 3ème années sont rémunérées à demi-traitement. | BW12: ABS_C_002 | BX12: =VLOOKUP(BW12,'Axe 2 Règles de gestion'!$D$2:$F$225,3, FALSE) -> La date de début du congé/absence doit être postérieure ou égale à la date de début du lien juridique. | BY12: ABS_C_003 | BZ12: =VLOOKUP(BY12,'Axe 2 Règles de gestion'!$D$2:$F$225,3, FALSE) -> La date de début du congé/absence doit être antérieure ou égale à la date de fin réelle du congé/absence. | CA12: ABS_C_004 | CB12: =VLOOKUP(CA12,'Axe 2 Règles de gestion'!$D$2:$F$225,3, FALSE) -> La date de début du congé/absence doit être antérieure ou égale à la date de fin prévisionnelle du congé/absence. | CC12: ABS_C_005 | CD12: =VLOOKUP(CC12,'Axe 2 Règles de gestion'!$D$2:$F$225,3, FALSE) -> La date de fin réelle du congé/absence doit être antérieure ou égale à la date limite de fin réelle ou prévisionnelle du lien juridique. | CE12: ABS_C_006 | CF12: =VLOOKUP(CE12,'Axe 2 Règles de gestion'!$D$2:$F$225,3, FALSE) -> La date de fin prévisionnelle du congé/absence doit être antérieure ou égale à la date limite de fin réelle ou prévisionnelle du lien juridique. | CG12: ABS_C_007 | CH12: =VLOOKUP(CG12,'Axe 2 Règles de gestion'!$D$2:$F$225,3, FALSE) -> La date de fin réelle du congé/absence doit être antérieure à la date limite de départ à la retraite. | CI12: ABS_C_008 | CJ12: =VLOOKUP(CI12,'Axe 2 Règles de gestion'!$D$2:$F$225,3, FALSE) -> La date de fin prévisionnelle du congé/absence doit être antérieure à la date limite de départ à la retraite. | CK12: ABS_C_009 | CL12: =VLOOKUP(CK12,'Axe 2 Règles de gestion'!$D$2:$F$225,3, FALSE) -> La date de fin réelle ou la date de fin prévisionnelle du congé/absence doit être saisie. | CM12: ABS_C_015 | CN12: =VLOOKUP(CM12,'Axe 2 Règles de gestion'!$D$2:$F$225,3, FALSE) -> Pour chaque période d'absence découpée, la date de début d'impact rémunération doit être égale à la date de début du congé/absence. | CO12: ABS_C_016 | CP12: =VLOOKUP(CO12,'Axe 2 Règles de gestion'!$D$2:$F$225,3, FALSE) -> Pour chaque période d'absence découpée, la date de fin d'impact rémunération doit être égale à la date de fin prévisionnelle du congé/absence. | CQ12: ABS_C_018 | CR12: =VLOOKUP(CQ12,'Axe 2 Règles de gestion'!$D$2:$F$225,3, FALSE) -> Pour chaque période d'absence découpée, la date de fin d'impact rémunération doit être égale à la date de fin réelle du congé/absence. | CS12: ABS_C_019 | CT12: =VLOOKUP(CS12,'Axe 2 Règles de gestion'!$D$2:$F$225,3, FALSE) -> Si l'absence ne commence pas par une demi-journée et si l'absence précédente ne finit pas par une demi journée, la date de début de l'absence saisie est postérieure à la date de fin réelle de l'absence précédente. | CU12: ABS_C_020 | CV12: =VLOOKUP(CU12,'Axe 2 Règles de gestion'!$D$2:$F$225,3, FALSE) -> Si l'absence ne commence pas par une demi-journée et si l'absence précédente ne finit pas par une demi journée, la date de début de l'absence saisie est postérieure à la date de fin prévisionnelle de l'absence précédente. | CW12: ABS_C_023 | CX12: =VLOOKUP(CW12,'Axe 2 Règles de gestion'!$D$2:$F$225,3, FALSE) -> L'état du congé est renseigné. | CY12: ABS_C_024 | CZ12: =VLOOKUP(CY12,'Axe 2 Règles de gestion'!$D$2:$F$225,3, FALSE) -> Si le CMO est requalifié en CLM/CLD/CGM/CITIS alors l'impact rémunération saisi doit être un impact spécifique à la requalification. | DA12: ABS_C_025 | DB12: =VLOOKUP(DA12,'Axe 2 Règles de gestion'!$D$2:$F$225,3, FALSE) -> Si le congé/absence n'est pas issu d'une requalification d'un CMO ou d'un CITIS, alors l'impact rémunération saisi ne doit pas être un impact spécifique à la requalification.
