Workbook

Sheet Mode opératoire
B1: MODE OPERATOIRE
B2: La transaction s'effectue au niveau de la rubrique "Congés/absences", elle inclut l'ensemble des sous-rubriques listées ci-dessous : - Congés/absences - Complément pour congé / absence : impact rémunération - Compteurs de périodes de congés On notera que : La sous-rubrique "Complément pour congé / absence : impact rémunération" est réputée, suite au découpage des absences en tranche de rémunération, avoir des dates de début et de fin alignées sur les dates de début et de fin de la sous-rubrique "Congés/absences" (contrôle bloquant) Parmi les non titulaires, les populations suivantes ne sont pas traitées pour le moment : - Les enseignants contractuels ou agréés d'établissement privé sous contrat d'association ou sous contrat simple à titre définitif ou à titre provisoire - MEN - Les maitres délégués d'établissement privé sous contrat d'association - MEN

Sheet Axe 1 Enchainement des RG
A1: Version | B1: Type de mise à jour | C1: Date de mise à jour | D1: Identifiant Domaine | E1: Libellé du Domaine | F1: Identifiant Sous-domaine | G1: Libellé du Sous-domaine | H1: Identifiant Evénement | I1: Libellé de l'évènement | J1: Libellé condition déclenchement Evènement | K1: Condition déclenchement Evènement | L1: Identifiant type d'évènement | M1: Libellé type d'évènement | N1: Type de mise à jour | O1: Libellé condition déclenchement Type Evènement | P1: Condition déclenchement Type Evènement | Q1: Libellé Population | R1: Codification Population | S1: Général / Particulier | T1: Passant / Exclu | U1: Date de début | V1: Date de fin | W1: Règles mobilisées | X1: Identifiant Règle de contrôle intellectuel 1 | Y1: Libellé Règle de contrôle intellectuel 1 | Z1: Identifiant Règle de contrôle intellectuel 2 | AA1: Libellé Règle de contrôle intellectuel 2 | AB1: Identifiant Règle de contrôle intellectuel 3 | AC1: Libellé Règle de contrôle intellectuel 3 | AD1: Identifiant Règle de contrôle intellectuel 4 | AE1: Libellé Règle de contrôle intellectuel 4 | AF1: Identifiant Règle de contrôle intellectuel 5 | AG1: Libellé Règle de contrôle intellectuel 5 | AH1: Identifiant Règle de contrôle intellectuel 6 | AI1: Libellé Règle de contrôle intellectuel 6 | AJ1: Identifiant Règle de contrôle intellectuel 7 | AK1: Libellé Règle de contrôle intellectuel 7 | AL1: Identifiant Règle de contrôle intellectuel 8 | AM1: Libellé Règle de contrôle intellectuel 8 | AN1: Identifiant Règle de contrôle intellectuel 9 | AO1: Libellé Règle de contrôle intellectuel 9 | AP1: Identifiant Règle de contrôle intellectuel 10 | AQ1: Libellé Règle de contrôle intellectuel 10 | AR1: Identifiant Règle de contrôle intellectuel 11 | AS1: Libellé Règle de contrôle intellectuel 11 | AT1: Identifiant Règle de condition 1 | AU1: Libellé Règle de condition 1 | AV1: Identifiant Règle de condition 2 | AW1: Libellé Règle de condition 2 | AX1: Identifiant Règle de condition 3 | AY1: Libellé Règle de condition 3 | AZ1: Identifiant Règle de condition 4 | BA1: Libellé Règle de condition 4 | BB1: Identifiant Règle de condition 5 | BC1: Libellé Règle de condition 5 | BD1: Identifiant Règle de condition 6 | BE1: Libellé Règle de condition 6 | BF1: Identifiant Règle de contrôle 1 | BG1: Libellé Règle de contrôle 1 | BH1: Identifiant Règle de contrôle 2 | BI1: Libellé Règle de contrôle 2 | BJ1: Identifiant Règle de contrôle 3 | BK1: Libellé Règle de contrôle 3 | BL1: Identifiant Règle de contrôle 4 | BM1: Libellé Règle de contrôle 4 | BN1: Identifiant Règle de contrôle 5 | BO1: Libellé Règle de contrôle 5 | BP1: Identifiant Règle de contrôle 6 | BQ1: Libellé Règle de contrôle 6 | BR1: Identifiant Règle de contrôle 7 | BS1: Libellé Règle de contrôle 7 | BT1: Identifiant Règle de contrôle 8 | BU1: Libellé Règle de contrôle 8 | BV1: Identifiant Règle de contrôle 9 | BW1: Libellé Règle de contrôle 9 | BX1: Identifiant Règle de contrôle 10 | BY1: Libellé Règle de contrôle 10 | BZ1: Identifiant Règle de contrôle 11 | CA1: Libellé Règle de contrôle 11 | CB1: Identifiant Règle de contrôle 12 | CC1: Libellé Règle de contrôle 12 | CD1: Identifiant Règle de contrôle 13 | CE1: Libellé Règle de contrôle 13 | CF1: Identifiant Règle de contrôle 14 | CG1: Libellé Règle de contrôle 14 | CH1: FIME | CI1: Statut de travail
A2: 21.00.00 | B2: M | C2: 44337.578 | D2: D0007 | E2: Congés/Absence | F2: S0072 | G2: Congé pour raisons de famille | H2: E0499 | I2: Congé d'accompagnement d'une personne en fin de vie | J2: Le Type de congé/absence est 'Congé d'accompagnement d'une personne en fin de vie' | K2: A_COA_TYCOAB [Saisi] = 'CG100' | L2: T1204 | M2: Congé d'accompagnement d'une personne en fin de vie - Demande | N2: Création | Q2: Titulaire ou magistrat | R2: P0001 | S2: Général | T2: Exclu | U2: 40725 | V2: 44561
A3: 21.00.00 | B3: M | C3: 44337.584 | D3: D0007 | E3: Congés/Absence | F3: S0072 | G3: Congé pour raisons de famille | H3: E0499 | I3: Congé d'accompagnement d'une personne en fin de vie | J3: Le Type de congé/absence est 'Congé d'accompagnement d'une personne en fin de vie' | K3: A_COA_TYCOAB [Saisi] = 'CG100' | L3: T1205 | M3: Congé d'accompagnement d'une personne en fin de vie - Fin | N3: Modification | Q3: Titulaire ou magistrat | R3: P0001 | S3: Général | T3: Exclu | U3: 40725 | V3: 44561
A4: 18.10.00 | B4: M | C4: 43152.5 | D4: D0007 | E4: Congés/Absence | F4: S0072 | G4: Congé pour raisons de famille | H4: E0499 | I4: Congé d'accompagnement d'une personne en fin de vie | J4: Le Type de congé/absence est 'Congé d'accompagnement d'une personne en fin de vie' | K4: A_COA_TYCOAB [Saisi] = 'CG100' | L4: T1204 | M4: Congé d'accompagnement d'une personne en fin de vie - Demande | N4: Création | Q4: Contractuel | R4: P0003 | S4: Général | T4: Passant | U4: 40725 | V4: 41294 | W4: CDI_D_236 ET CDI_D_240 ET CDI_D_600 ET ABS_C_002 ET ABS_C_003 ET ABS_C_004 ET ABS_C_005 ET ABS_C_006 ET ABS_C_007 ET ABS_C_008 ET ABS_C_009 ET ABS_C_019 ET ABS_C_020 ET ABS_C_026 | AT4: CDI_D_236 | AU4: =VLOOKUP(AT4,'Axe 2 Règles de gestion'!$D$2:$F$564,3, FALSE) -> L'agent doit être en activité. | AV4: CDI_D_240 | AW4: =VLOOKUP(AV4,'Axe 2 Règles de gestion'!$D$2:$F$564,3, FALSE) -> La durée réelle maximale du congé d'accompagnement d'une personne en fin de vie est de 3 mois par personne accompagnée. | AX4: CDI_D_600 | AY4: =VLOOKUP(AX4,'Axe 2 Règles de gestion'!$D$2:$F$564,3, FALSE) -> La durée prévisionnelle maximale du congé d'accompagnement d'une personne en fin de vie est de 3 mois par personne accompagnée. | BF4: ABS_C_002 | BG4: =VLOOKUP(BF4,'Axe 2 Règles de gestion'!$D$2:$F$564,3, FALSE) -> La date de début du congé/absence doit être postérieure ou égale à la date de début du lien juridique. | BH4: ABS_C_003 | BI4: =VLOOKUP(BH4,'Axe 2 Règles de gestion'!$D$2:$F$564,3, FALSE) -> La date de début du congé/absence doit être antérieure ou égale à la date de fin réelle du congé/absence. | BJ4: ABS_C_004 | BK4: =VLOOKUP(BJ4,'Axe 2 Règles de gestion'!$D$2:$F$564,3, FALSE) -> La date de début du congé/absence doit être antérieure ou égale à la date de fin prévisionnelle du congé/absence. | BL4: ABS_C_005 | BM4: =VLOOKUP(BL4,'Axe 2 Règles de gestion'!$D$2:$F$564,3, FALSE) -> La date de fin réelle du congé/absence doit être antérieure ou égale à la date limite de fin réelle ou prévisionnelle du lien juridique. | BN4: ABS_C_006 | BO4: =VLOOKUP(BN4,'Axe 2 Règles de gestion'!$D$2:$F$564,3, FALSE) -> La date de fin prévisionnelle du congé/absence doit être antérieure ou égale à la date limite de fin réelle ou prévisionnelle du lien juridique. | BP4: ABS_C_007 | BQ4: =VLOOKUP(BP4,'Axe 2 Règles de gestion'!$D$2:$F$564,3, FALSE) -> La date de fin réelle du congé/absence doit être antérieure à la date limite de départ à la retraite. | BR4: ABS_C_008 | BS4: =VLOOKUP(BR4,'Axe 2 Règles de gestion'!$D$2:$F$564,3, FALSE) -> La date de fin prévisionnelle du congé/absence doit être antérieure à la date limite de départ à la retraite. | BT4: ABS_C_009 | BU4: =VLOOKUP(BT4,'Axe 2 Règles de gestion'!$D$2:$F$564,3, FALSE) -> La date de fin réelle ou la date de fin prévisionnelle du congé/absence doit être saisie. | BV4: ABS_C_019 | BW4: =VLOOKUP(BV4,'Axe 2 Règles de gestion'!$D$2:$F$564,3, FALSE) -> Si l'absence ne commence pas par une demi-journée et si l'absence précédente ne finit pas par une demi journée, la date de début de l'absence saisie est postérieure à la date de fin réelle de l'absence précédente. | BX4: ABS_C_020 | BY4: =VLOOKUP(BX4,'Axe 2 Règles de gestion'!$D$2:$F$564,3, FALSE) -> Si l'absence ne commence pas par une demi-journée et si l'absence précédente ne finit pas par une demi journée, la date de début de l'absence saisie est postérieure à la date de fin prévisionnelle de l'absence précédente. | BZ4: ABS_C_026 | CA4: =VLOOKUP(BZ4,'Axe 2 Règles de gestion'!$D$2:$F$564,3, FALSE) -> Dans le cas d'un congé autre que CLM, CLD, CGM et CITIS, l'indicateur de requalification doit être à non et les impacts spécifiques à la requalification ne doivent pas être mobilisés ou l'impact rémunération est vide.
A5: 21.00.00 | B5: M | C5: 44337.58 | D5: D0007 | E5: Congés/Absence | F5: S0072 | G5: Congé pour raisons de famille | H5: E0499 | I5: Congé d'accompagnement d'une personne en fin de vie | J5: Le Type de congé/absence est 'Congé d'accompagnement d'une personne en fin de vie' | K5: A_COA_TYCOAB [Saisi] = 'CG100' | L5: T1204 | M5: Congé d'accompagnement d'une personne en fin de vie - Demande | N5: Création | Q5: Contractuel | R5: P0003 | S5: Général | T5: Exclu | U5: 41295 | V5: 44561
A6: 18.10.00 | B6: M | C6: 43152.5 | D6: D0007 | E6: Congés/Absence | F6: S0072 | G6: Congé pour raisons de famille | H6: E0499 | I6: Congé d'accompagnement d'une personne en fin de vie | J6: Le Type de congé/absence est 'Congé d'accompagnement d'une personne en fin de vie' | K6: A_COA_TYCOAB [Saisi] = 'CG100' | L6: T1205 | M6: Congé d'accompagnement d'une personne en fin de vie - Fin | N6: Modification | Q6: Contractuel | R6: P0003 | S6: Général | T6: Passant | U6: 40725 | V6: 41294 | W6: CDI_D_240 ET CDI_D_600 ET ABS_C_003 ET ABS_C_004 ET ABS_C_005 ET ABS_C_006 ET ABS_C_007 ET ABS_C_008 ET ABS_C_009 ET ABS_C_026 | AT6: CDI_D_240 | AU6: =VLOOKUP(AT6,'Axe 2 Règles de gestion'!$D$2:$F$564,3, FALSE) -> La durée réelle maximale du congé d'accompagnement d'une personne en fin de vie est de 3 mois par personne accompagnée. | AV6: CDI_D_600 | AW6: =VLOOKUP(AV6,'Axe 2 Règles de gestion'!$D$2:$F$564,3, FALSE) -> La durée prévisionnelle maximale du congé d'accompagnement d'une personne en fin de vie est de 3 mois par personne accompagnée. | BF6: ABS_C_003 | BG6: =VLOOKUP(BF6,'Axe 2 Règles de gestion'!$D$2:$F$564,3, FALSE) -> La date de début du congé/absence doit être antérieure ou égale à la date de fin réelle du congé/absence. | BH6: ABS_C_004 | BI6: =VLOOKUP(BH6,'Axe 2 Règles de gestion'!$D$2:$F$564,3, FALSE) -> La date de début du congé/absence doit être antérieure ou égale à la date de fin prévisionnelle du congé/absence. | BJ6: ABS_C_005 | BK6: =VLOOKUP(BJ6,'Axe 2 Règles de gestion'!$D$2:$F$564,3, FALSE) -> La date de fin réelle du congé/absence doit être antérieure ou égale à la date limite de fin réelle ou prévisionnelle du lien juridique. | BL6: ABS_C_006 | BM6: =VLOOKUP(BL6,'Axe 2 Règles de gestion'!$D$2:$F$564,3, FALSE) -> La date de fin prévisionnelle du congé/absence doit être antérieure ou égale à la date limite de fin réelle ou prévisionnelle du lien juridique. | BN6: ABS_C_007 | BO6: =VLOOKUP(BN6,'Axe 2 Règles de gestion'!$D$2:$F$564,3, FALSE) -> La date de fin réelle du congé/absence doit être antérieure à la date limite de départ à la retraite. | BP6: ABS_C_008 | BQ6: =VLOOKUP(BP6,'Axe 2 Règles de gestion'!$D$2:$F$564,3, FALSE) -> La date de fin prévisionnelle du congé/absence doit être antérieure à la date limite de départ à la retraite. | BR6: ABS_C_009 | BS6: =VLOOKUP(BR6,'Axe 2 Règles de gestion'!$D$2:$F$564,3, FALSE) -> La date de fin réelle ou la date de fin prévisionnelle du congé/absence doit être saisie. | BT6: ABS_C_026 | BU6: =VLOOKUP(BT6,'Axe 2 Règles de gestion'!$D$2:$F$564,3, FALSE) -> Dans le cas d'un congé autre que CLM, CLD, CGM et CITIS, l'indicateur de requalification doit être à non et les impacts spécifiques à la requalification ne doivent pas être mobilisés ou l'impact rémunération est vide.
A7: 21.00.00 | B7: M | C7: 44337.583 | D7: D0007 | E7: Congés/Absence | F7: S0072 | G7: Congé pour raisons de famille | H7: E0499 | I7: Congé d'accompagnement d'une personne en fin de vie | J7: Le Type de congé/absence est 'Congé d'accompagnement d'une personne en fin de vie' | K7: A_COA_TYCOAB [Saisi] = 'CG100' | L7: T1205 | M7: Congé d'accompagnement d'une personne en fin de vie - Fin | N7: Modification | Q7: Contractuel | R7: P0003 | S7: Général | T7: Exclu | U7: 41295 | V7: 44561
A8: 21.00.00 | B8: M | C8: 44337.579 | D8: D0007 | E8: Congés/Absence | F8: S0072 | G8: Congé pour raisons de famille | H8: E0499 | I8: Congé d'accompagnement d'une personne en fin de vie | J8: Le Type de congé/absence est 'Congé d'accompagnement d'une personne en fin de vie' | K8: A_COA_TYCOAB [Saisi] = 'CG100' | L8: T1204 | M8: Congé d'accompagnement d'une personne en fin de vie - Demande | N8: Création | Q8: Stagiaire ou auditeur ou élève | R8: P0004 | S8: Général | T8: Exclu | U8: 40725 | V8: 44561
A9: 21.00.00 | B9: M | C9: 44337.584 | D9: D0007 | E9: Congés/Absence | F9: S0072 | G9: Congé pour raisons de famille | H9: E0499 | I9: Congé d'accompagnement d'une personne en fin de vie | J9: Le Type de congé/absence est 'Congé d'accompagnement d'une personne en fin de vie' | K9: A_COA_TYCOAB [Saisi] = 'CG100' | L9: T1205 | M9: Congé d'accompagnement d'une personne en fin de vie - Fin | N9: Modification | Q9: Stagiaire ou auditeur ou élève | R9: P0004 | S9: Général | T9: Exclu | U9: 40725 | V9: 44561
A10: 21.00.00 | B10: M | C10: 44337.462 | D10: D0007 | E10: Congés/Absence | F10: S0072 | G10: Congé pour raisons de famille | H10: E0499 | I10: Congé d'accompagnement d'une personne en fin de vie | J10: Le Type de congé/absence est 'Congé d'accompagnement d'une personne en fin de vie' | K10: A_COA_TYCOAB [Saisi] = 'CG100' | L10: T1204 | M10: Congé d'accompagnement d'une personne en fin de vie - Demande | N10: Création | Q10: Ouvrier d'état | R10: P0005 | S10: Général | T10: Passant | U10: 40725 | V10: 44561 | W10: CDI_I_177 ET CDI_I_176 ET CDI_D_163 ET CDI_D_617 ET CDI_D_158 ET ABS_C_002 ET ABS_C_003 ET ABS_C_004 ET ABS_C_005 ET ABS_C_006 ET ABS_C_007 ET ABS_C_008 ET ABS_C_009 ET ABS_C_019 ET ABS_C_020 ET ABS_C_026 | X10: CDI_I_177 | Y10: =VLOOKUP(X10,'Axe 2 Règles de gestion'!$D$2:$F$564,3, FALSE) -> L'agent doit faire une demande écrite auprès de l'administration. | Z10: CDI_I_176 | AA10: =VLOOKUP(Z10,'Axe 2 Règles de gestion'!$D$2:$F$564,3, FALSE) -> Ce congé est de droit lorsqu'un ascendant, un descendant ou une personne partageant le domicile de l'agent fait l'objet de soins palliatifs. | AT10: CDI_D_163 | AU10: =VLOOKUP(AT10,'Axe 2 Règles de gestion'!$D$2:$F$564,3, FALSE) -> La durée réelle maximale du congé d'accompagnement d'une personne en fin de vie est de 3 mois par personne accompagnée. | AV10: CDI_D_617 | AW10: =VLOOKUP(AV10,'Axe 2 Règles de gestion'!$D$2:$F$564,3, FALSE) -> La durée prévisionnelle maximale du congé d'accompagnement d'une personne en fin de vie est de 3 mois par personne accompagnée. | AX10: CDI_D_158 | AY10: =VLOOKUP(AX10,'Axe 2 Règles de gestion'!$D$2:$F$564,3, FALSE) -> L'agent doit être en activité. | BF10: ABS_C_002 | BG10: =VLOOKUP(BF10,'Axe 2 Règles de gestion'!$D$2:$F$564,3, FALSE) -> La date de début du congé/absence doit être postérieure ou égale à la date de début du lien juridique. | BH10: ABS_C_003 | BI10: =VLOOKUP(BH10,'Axe 2 Règles de gestion'!$D$2:$F$564,3, FALSE) -> La date de début du congé/absence doit être antérieure ou égale à la date de fin réelle du congé/absence. | BJ10: ABS_C_004 | BK10: =VLOOKUP(BJ10,'Axe 2 Règles de gestion'!$D$2:$F$564,3, FALSE) -> La date de début du congé/absence doit être antérieure ou égale à la date de fin prévisionnelle du congé/absence. | BL10: ABS_C_005 | BM10: =VLOOKUP(BL10,'Axe 2 Règles de gestion'!$D$2:$F$564,3, FALSE) -> La date de fin réelle du congé/absence doit être antérieure ou égale à la date limite de fin réelle ou prévisionnelle du lien juridique. | BN10: ABS_C_006 | BO10: =VLOOKUP(BN10,'Axe 2 Règles de gestion'!$D$2:$F$564,3, FALSE) -> La date de fin prévisionnelle du congé/absence doit être antérieure ou égale à la date limite de fin réelle ou prévisionnelle du lien juridique. | BP10: ABS_C_007 | BQ10: =VLOOKUP(BP10,'Axe 2 Règles de gestion'!$D$2:$F$564,3, FALSE) -> La date de fin réelle du congé/absence doit être antérieure à la date limite de départ à la retraite. | BR10: ABS_C_008 | BS10: =VLOOKUP(BR10,'Axe 2 Règles de gestion'!$D$2:$F$564,3, FALSE) -> La date de fin prévisionnelle du congé/absence doit être antérieure à la date limite de départ à la retraite. | BT10: ABS_C_009 | BU10: =VLOOKUP(BT10,'Axe 2 Règles de gestion'!$D$2:$F$564,3, FALSE) -> La date de fin réelle ou la date de fin prévisionnelle du congé/absence doit être saisie. | BV10: ABS_C_019 | BW10: =VLOOKUP(BV10,'Axe 2 Règles de gestion'!$D$2:$F$564,3, FALSE) -> Si l'absence ne commence pas par une demi-journée et si l'absence précédente ne finit pas par une demi journée, la date de début de l'absence saisie est postérieure à la date de fin réelle de l'absence précédente. | BX10: ABS_C_020 | BY10: =VLOOKUP(BX10,'Axe 2 Règles de gestion'!$D$2:$F$564,3, FALSE) -> Si l'absence ne commence pas par une demi-journée et si l'absence précédente ne finit pas par une demi journée, la date de début de l'absence saisie est postérieure à la date de fin prévisionnelle de l'absence précédente. | BZ10: ABS_C_026 | CA10: =VLOOKUP(BZ10,'Axe 2 Règles de gestion'!$D$2:$F$564,3, FALSE) -> Dans le cas d'un congé autre que CLM, CLD, CGM et CITIS, l'indicateur de requalification doit être à non et les impacts spécifiques à la requalification ne doivent pas être mobilisés ou l'impact rémunération est vide.
A11: 21.00.00 | B11: M | C11: 44337.463 | D11: D0007 | E11: Congés/Absence | F11: S0072 | G11: Congé pour raisons de famille | H11: E0499 | I11: Congé d'accompagnement d'une personne en fin de vie | J11: Le Type de congé/absence est 'Congé d'accompagnement d'une personne en fin de vie' | K11: A_COA_TYCOAB [Saisi] = 'CG100' | L11: T1205 | M11: Congé d'accompagnement d'une personne en fin de vie - Fin | N11: Modification | Q11: Ouvrier d'état | R11: P0005 | S11: Général | T11: Passant | U11: 40725 | V11: 44561 | W11: CDI_I_178 ET CDI_D_163 ET CDI_D_617 ET ABS_C_003 ET ABS_C_004 ET ABS_C_005 ET ABS_C_006 ET ABS_C_007 ET ABS_C_008 ET ABS_C_009 ET ABS_C_026 | X11: CDI_I_178 | Y11: =VLOOKUP(X11,'Axe 2 Règles de gestion'!$D$2:$F$564,3, FALSE) -> Ce congé peut prendre fin soit à l'expiration de la période de 3 mois, soit dans les 3 jours qui suivent le décès de la personne accompagnée, soit à la demande de l'agent. | AT11: CDI_D_163 | AU11: =VLOOKUP(AT11,'Axe 2 Règles de gestion'!$D$2:$F$564,3, FALSE) -> La durée réelle maximale du congé d'accompagnement d'une personne en fin de vie est de 3 mois par personne accompagnée. | AV11: CDI_D_617 | AW11: =VLOOKUP(AV11,'Axe 2 Règles de gestion'!$D$2:$F$564,3, FALSE) -> La durée prévisionnelle maximale du congé d'accompagnement d'une personne en fin de vie est de 3 mois par personne accompagnée. | BF11: ABS_C_003 | BG11: =VLOOKUP(BF11,'Axe 2 Règles de gestion'!$D$2:$F$564,3, FALSE) -> La date de début du congé/absence doit être antérieure ou égale à la date de fin réelle du congé/absence. | BH11: ABS_C_004 | BI11: =VLOOKUP(BH11,'Axe 2 Règles de gestion'!$D$2:$F$564,3, FALSE) -> La date de début du congé/absence doit être antérieure ou égale à la date de fin prévisionnelle du congé/absence. | BJ11: ABS_C_005 | BK11: =VLOOKUP(BJ11,'Axe 2 Règles de gestion'!$D$2:$F$564,3, FALSE) -> La date de fin réelle du congé/absence doit être antérieure ou égale à la date limite de fin réelle ou prévisionnelle du lien juridique. | BL11: ABS_C_006 | BM11: =VLOOKUP(BL11,'Axe 2 Règles de gestion'!$D$2:$F$564,3, FALSE) -> La date de fin prévisionnelle du congé/absence doit être antérieure ou égale à la date limite de fin réelle ou prévisionnelle du lien juridique. | BN11: ABS_C_007 | BO11: =VLOOKUP(BN11,'Axe 2 Règles de gestion'!$D$2:$F$564,3, FALSE) -> La date de fin réelle du congé/absence doit être antérieure à la date limite de départ à la retraite. | BP11: ABS_C_008 | BQ11: =VLOOKUP(BP11,'Axe 2 Règles de gestion'!$D$2:$F$564,3, FALSE) -> La date de fin prévisionnelle du congé/absence doit être antérieure à la date limite de départ à la retraite. | BR11: ABS_C_009 | BS11: =VLOOKUP(BR11,'Axe 2 Règles de gestion'!$D$2:$F$564,3, FALSE) -> La date de fin réelle ou la date de fin prévisionnelle du congé/absence doit être saisie. | BT11: ABS_C_026 | BU11: =VLOOKUP(BT11,'Axe 2 Règles de gestion'!$D$2:$F$564,3, FALSE) -> Dans le cas d'un congé autre que CLM, CLD, CGM et CITIS, l'indicateur de requalification doit être à non et les impacts spécifiques à la requalification ne doivent pas être mobilisés ou l'impact rémunération est vide.
A12: 17.10.00 | B12: A | C12: 43152.5 | D12: D0007 | E12: Congés/Absence | F12: S0072 | G12: Congé pour raisons de famille | H12: E0499 | I12: Congé d'accompagnement d'une personne en fin de vie | J12: Le Type de congé/absence est 'Congé d'accompagnement d'une personne en fin de vie' | K12: A_COA_TYCOAB [Saisi] = 'CG100' | L12: T1204 | M12: Congé d'accompagnement d'une personne en fin de vie - Demande | N12: Création | Q12: Conseiller ou avocat général à la Cour de cassation en service extraordinaire | R12: P0046 | S12: Particulier | T12: Exclu | U12: 40725 | V12: 41294
A13: 17.10.00 | B13: A | C13: 43152.5 | D13: D0007 | E13: Congés/Absence | F13: S0072 | G13: Congé pour raisons de famille | H13: E0499 | I13: Congé d'accompagnement d'une personne en fin de vie | J13: Le Type de congé/absence est 'Congé d'accompagnement d'une personne en fin de vie' | K13: A_COA_TYCOAB [Saisi] = 'CG100' | L13: T1205 | M13: Congé d'accompagnement d'une personne en fin de vie - Fin | N13: Modification | Q13: Conseiller ou avocat général à la Cour de cassation en service extraordinaire | R13: P0046 | S13: Particulier | T13: Exclu | U13: 40725 | V13: 41294
A14: 17.10.00 | B14: A | C14: 43152.5 | D14: D0007 | E14: Congés/Absence | F14: S0072 | G14: Congé pour raisons de famille | H14: E0499 | I14: Congé d'accompagnement d'une personne en fin de vie | J14: Le Type de congé/absence est 'Congé d'accompagnement d'une personne en fin de vie' | K14: A_COA_TYCOAB [Saisi] = 'CG100' | L14: T1204 | M14: Congé d'accompagnement d'une personne en fin de vie - Demande | N14: Création | Q14: Personnel civil payé à l'acte ou à la tâche | R14: P0054 | S14: Particulier | T14: Exclu | U14: 40725 | V14: 41294
A15: 17.10.00 | B15: A | C15: 43152.5 | D15: D0007 | E15: Congés/Absence | F15: S0072 | G15: Congé pour raisons de famille | H15: E0499 | I15: Congé d'accompagnement d'une personne en fin de vie | J15: Le Type de congé/absence est 'Congé d'accompagnement d'une personne en fin de vie' | K15: A_COA_TYCOAB [Saisi] = 'CG100' | L15: T1205 | M15: Congé d'accompagnement d'une personne en fin de vie - Fin | N15: Modification | Q15: Personnel civil payé à l'acte ou à la tâche | R15: P0054 | S15: Particulier | T15: Exclu | U15: 40725 | V15: 41294
A16: 17.10.00 | B16: A | C16: 43152.5 | D16: D0007 | E16: Congés/Absence | F16: S0072 | G16: Congé pour raisons de famille | H16: E0499 | I16: Congé d'accompagnement d'une personne en fin de vie | J16: Le Type de congé/absence est 'Congé d'accompagnement d'une personne en fin de vie' | K16: A_COA_TYCOAB [Saisi] = 'CG100' | L16: T1204 | M16: Congé d'accompagnement d'une personne en fin de vie - Demande | N16: Création | Q16: Contractuel en service à l'étranger | R16: P0069 | S16: Particulier | T16: Exclu | U16: 40725 | V16: 41294
A17: 17.10.00 | B17: A | C17: 43152.5 | D17: D0007 | E17: Congés/Absence | F17: S0072 | G17: Congé pour raisons de famille | H17: E0499 | I17: Congé d'accompagnement d'une personne en fin de vie | J17: Le Type de congé/absence est 'Congé d'accompagnement d'une personne en fin de vie' | K17: A_COA_TYCOAB [Saisi] = 'CG100' | L17: T1205 | M17: Congé d'accompagnement d'une personne en fin de vie - Fin | N17: Modification | Q17: Contractuel en service à l'étranger | R17: P0069 | S17: Particulier | T17: Exclu | U17: 40725 | V17: 41294
A18: 17.10.00 | B18: A | C18: 43152.5 | D18: D0007 | E18: Congés/Absence | F18: S0072 | G18: Congé pour raisons de famille | H18: E0499 | I18: Congé d'accompagnement d'une personne en fin de vie | J18: Le Type de congé/absence est 'Congé d'accompagnement d'une personne en fin de vie' | K18: A_COA_TYCOAB [Saisi] = 'CG100' | L18: T1204 | M18: Congé d'accompagnement d'une personne en fin de vie - Demande | N18: Création | Q18: Contractuel de droit privé | R18: P0072 | S18: Particulier | T18: Exclu | U18: 40725 | V18: 41294
A19: 17.10.00 | B19: A | C19: 43152.5 | D19: D0007 | E19: Congés/Absence | F19: S0072 | G19: Congé pour raisons de famille | H19: E0499 | I19: Congé d'accompagnement d'une personne en fin de vie | J19: Le Type de congé/absence est 'Congé d'accompagnement d'une personne en fin de vie' | K19: A_COA_TYCOAB [Saisi] = 'CG100' | L19: T1205 | M19: Congé d'accompagnement d'une personne en fin de vie - Fin | N19: Modification | Q19: Contractuel de droit privé | R19: P0072 | S19: Particulier | T19: Exclu | U19: 40725 | V19: 41294
A20: 17.10.00 | B20: A | C20: 43152.5 | D20: D0007 | E20: Congés/Absence | F20: S0072 | G20: Congé pour raisons de famille | H20: E0499 | I20: Congé d'accompagnement d'une personne en fin de vie | J20: Le Type de congé/absence est 'Congé d'accompagnement d'une personne en fin de vie' | K20: A_COA_TYCOAB [Saisi] = 'CG100' | L20: T1204 | M20: Congé d'accompagnement d'une personne en fin de vie - Demande | N20: Création | Q20: Personnel hospitalo-universitaire | R20: P0091 | S20: Particulier | T20: Exclu | U20: 40725 | V20: 41294
A21: 17.10.00 | B21: A | C21: 43152.5 | D21: D0007 | E21: Congés/Absence | F21: S0072 | G21: Congé pour raisons de famille | H21: E0499 | I21: Congé d'accompagnement d'une personne en fin de vie | J21: Le Type de congé/absence est 'Congé d'accompagnement d'une personne en fin de vie' | K21: A_COA_TYCOAB [Saisi] = 'CG100' | L21: T1205 | M21: Congé d'accompagnement d'une personne en fin de vie - Fin | N21: Modification | Q21: Personnel hospitalo-universitaire | R21: P0091 | S21: Particulier | T21: Exclu | U21: 40725 | V21: 41294
A22: 21.00.00 | B22: M | C22: 44337.581 | D22: D0007 | E22: Congés/Absence | F22: S0072 | G22: Congé pour raisons de famille | H22: E0499 | I22: Congé d'accompagnement d'une personne en fin de vie | J22: Le Type de congé/absence est 'Congé d'accompagnement d'une personne en fin de vie' | K22: A_COA_TYCOAB [Saisi] = 'CG100' | L22: T1204 | M22: Congé d'accompagnement d'une personne en fin de vie - Demande | N22: Création | Q22: Ouvrier des parcs et ateliers confirmé non affilié ou stagiaire | R22: P0185 | S22: Particulier | T22: Exclu | U22: 40725 | V22: 44561
A23: 21.00.00 | B23: M | C23: 44337.583 | D23: D0007 | E23: Congés/Absence | F23: S0072 | G23: Congé pour raisons de famille | H23: E0499 | I23: Congé d'accompagnement d'une personne en fin de vie | J23: Le Type de congé/absence est 'Congé d'accompagnement d'une personne en fin de vie' | K23: A_COA_TYCOAB [Saisi] = 'CG100' | L23: T1205 | M23: Congé d'accompagnement d'une personne en fin de vie - Fin | N23: Modification | Q23: Ouvrier des parcs et ateliers confirmé non affilié ou stagiaire | R23: P0185 | S23: Particulier | T23: Exclu | U23: 40725 | V23: 44561
... A27: 21.00.00 | B27: M | C27: 44337.583 | D27: D0007 | E27: Congés/Absence | F27: S0072 | G27: Congé pour raisons de famille | H27: E0499 | I27: Congé d'accompagnement d'une personne en fin de vie | J27: Le Type de congé/absence est 'Congé d'accompagnement d'une personne en fin de vie' | K27: A_COA_TYCOAB [Saisi] = 'CG100' | L27: T1205 | M27: Congé d'accompagnement d'une personne en fin de vie - Fin | N27: Modification | Q27: Ouvrier du service des alcools confirmé non affilié | R27: P0221 | S27: Particulier | T27: Exclu | U27: 40725 | V27: 44561
A28: 21.10.00 | B28: M | C28: 44469.651 | D28: D0007 | E28: Congés/Absence | F28: S0072 | G28: Congé pour raisons de famille | H28: E0500 | I28: Congé de solidarité familiale | J28: Le Type de congé/absence est 'Congé de solidarité familiale' | K28: A_COA_TYCOAB [Saisi] = 'CG103' | L28: T1206 | M28: Congé de solidarité familiale - Demande | N28: Création Modification | O28: La valeur de l'Etat du congé est différente de 'Renouvellement' et la valeur de l'Etat du congé saisie est différente de celle avant saisie | P28: A_COA_ETCOMA [Saisi] <> 'EC02' ET A_COA_ETCOMA [Saisi] <> A_COA_ETCOMA [Valeur avant saisie] | Q28: Titulaire ou magistrat | R28: P0001 | S28: Général | T28: Passant | U28: 40725 | W28: CDI_I_001 ET CDI_I_002 ET CDI_I_003 ET CDI_I_004 ET CDI_D_121 ET CDI_D_521 ET CDI_D_122 ET CDI_D_123 ET CDI_D_601 ET CDI_D_117 ET ABS_C_001 ET ABS_C_003 ET ABS_C_004 ET ABS_C_007 ET ABS_C_008 ET ABS_C_009 ET ABS_C_019 ET ABS_C_020 ET ABS_C_023 ET ABS_C_026 ET ABS_C_065 | X28: CDI_I_001 | Y28: =VLOOKUP(X28,'Axe 2 Règles de gestion'!$D$2:$F$564,3, FALSE) -> Le congé est accordé si un ascendant, descendant, un frère ou une sœur, une personne partageant le même domicile ou l'ayant désigné comme sa personne de confiance souffre d'une pathologie mettant en jeu le pronostic vital ou en phase avancée ou terminale d'une affection grave et incurable, quelle qu'en soit la cause. | Z28: CDI_I_002 | AA28: =VLOOKUP(Z28,'Axe 2 Règles de gestion'!$D$2:$F$564,3, FALSE) -> L'agent doit faire la demande par écrit. Elle est accordée de droit. | AB28: CDI_I_003 | AC28: =VLOOKUP(AB28,'Axe 2 Règles de gestion'!$D$2:$F$564,3, FALSE) -> La demande doit être appuyée d'un certificat médical attestant que la personne accompagnée souffre d'une pathologie mettant en jeu le pronostic vital ou en phase avancée ou terminale d'une affection grave et incurable, quelle qu'en soit la cause. | AD28: CDI_I_004 | AE28: =VLOOKUP(AD28,'Axe 2 Règles de gestion'!$D$2:$F$564,3, FALSE) -> Le congé peut être fractionné ou pris de manière continue. | AT28: CDI_D_121 | AU28: =VLOOKUP(AT28,'Axe 2 Règles de gestion'!$D$2:$F$564,3, FALSE) -> Le congé de solidarité familiale, ou son renouvellement, est accordé pour une durée réelle maximale de trois mois. | AV28: CDI_D_521 | AW28: =VLOOKUP(AV28,'Axe 2 Règles de gestion'!$D$2:$F$564,3, FALSE) -> Le congé de solidarité familiale, ou son renouvellement, est accordé pour une durée prévisionnelle maximale de trois mois. | AX28: CDI_D_122 | AY28: =VLOOKUP(AX28,'Axe 2 Règles de gestion'!$D$2:$F$564,3, FALSE) -> Le congé de solidarité familiale peut être fractionné mais ne peut, renouvellement inclus, excéder les 6 mois. | AZ28: CDI_D_123 | BA28: =VLOOKUP(AZ28,'Axe 2 Règles de gestion'!$D$2:$F$564,3, FALSE) -> Le congé de solidarité familiale peut être fractionné mais chaque période doit être d'une durée réelle minimale de 7 jours consécutifs. | BB28: CDI_D_601 | BC28: =VLOOKUP(BB28,'Axe 2 Règles de gestion'!$D$2:$F$564,3, FALSE) -> Le congé de solidarité familiale peut être fractionné mais chaque période doit être d'une durée prévisionnelle minimale de 7 jours consécutifs. | BD28: CDI_D_117 | BE28: =VLOOKUP(BD28,'Axe 2 Règles de gestion'!$D$2:$F$564,3, FALSE) -> L'agent doit être en activité. | BF28: ABS_C_001 | BG28: =VLOOKUP(BF28,'Axe 2 Règles de gestion'!$D$2:$F$564,3, FALSE) -> La date de début du congé/absence doit être postérieure ou égale à la date de recrutement dans la FPE ou dans la carrière militaire. | BH28: ABS_C_003 | BI28: =VLOOKUP(BH28,'Axe 2 Règles de gestion'!$D$2:$F$564,3, FALSE) -> La date de début du congé/absence doit être antérieure ou égale à la date de fin réelle du congé/absence. | BJ28: ABS_C_004 | BK28: =VLOOKUP(BJ28,'Axe 2 Règles de gestion'!$D$2:$F$564,3, FALSE) -> La date de début du congé/absence doit être antérieure ou égale à la date de fin prévisionnelle du congé/absence. | BL28: ABS_C_007 | BM28: =VLOOKUP(BL28,'Axe 2 Règles de gestion'!$D$2:$F$564,3, FALSE) -> La date de fin réelle du congé/absence doit être antérieure à la date limite de départ à la retraite. | BN28: ABS_C_008 | BO28: =VLOOKUP(BN28,'Axe 2 Règles de gestion'!$D$2:$F$564,3, FALSE) -> La date de fin prévisionnelle du congé/absence doit être antérieure à la date limite de départ à la retraite. | BP28: ABS_C_009 | BQ28: =VLOOKUP(BP28,'Axe 2 Règles de gestion'!$D$2:$F$564,3, FALSE) -> La date de fin réelle ou la date de fin prévisionnelle du congé/absence doit être saisie. | BR28: ABS_C_019 | BS28: =VLOOKUP(BR28,'Axe 2 Règles de gestion'!$D$2:$F$564,3, FALSE) -> Si l'absence ne commence pas par une demi-journée et si l'absence précédente ne finit pas par une demi journée, la date de début de l'absence saisie est postérieure à la date de fin réelle de l'absence précédente. | BT28: ABS_C_020 | BU28: =VLOOKUP(BT28,'Axe 2 Règles de gestion'!$D$2:$F$564,3, FALSE) -> Si l'absence ne commence pas par une demi-journée et si l'absence précédente ne finit pas par une demi journée, la date de début de l'absence saisie est postérieure à la date de fin prévisionnelle de l'absence précédente. | BV28: ABS_C_023 | BW28: =VLOOKUP(BV28,'Axe 2 Règles de gestion'!$D$2:$F$564,3, FALSE) -> L'état du congé est renseigné. | BX28: ABS_C_026 | BY28: =VLOOKUP(BX28,'Axe 2 Règles de gestion'!$D$2:$F$564,3, FALSE) -> Dans le cas d'un congé autre que CLM, CLD, CGM et CITIS, l'indicateur de requalification doit être à non et les impacts spécifiques à la requalification ne doivent pas être mobilisés ou l'impact rémunération est vide. | BZ28: ABS_C_065 | CA28: =VLOOKUP(BZ28,'Axe 2 Règles de gestion'!$D$2:$F$564,3, FALSE) -> L'agent en congé de présence parentale / congé de proche aidant / congé de solidarité familiale ne peut se voir accorder de manière simultanée un temps partiel pour congé de présence parentale / pour congé de proche aidant / pour congé de solidarité familiale.
A29: 21.10.00 | B29: M | C29: 44469.651 | D29: D0007 | E29: Congés/Absence | F29: S0072 | G29: Congé pour raisons de famille | H29: E0500 | I29: Congé de solidarité familiale | J29: Le Type de congé/absence est 'Congé de solidarité familiale' | K29: A_COA_TYCOAB [Saisi] = 'CG103' | L29: T1207 | M29: Congé de solidarité familiale - Renouvellement | N29: Création Modification | O29: La valeur de l'Etat du congé est égale à 'Renouvellement' et la valeur de l'Etat du congé saisie est différente de celle avant saisie | P29: A_COA_ETCOMA [Saisi] = 'EC02' ET A_COA_ETCOMA [Saisi] <> A_COA_ETCOMA [Valeur avant saisie] | Q29: Titulaire ou magistrat | R29: P0001 | S29: Général | T29: Passant | U29: 40725 | W29: CDI_I_001 ET CDI_I_002 ET CDI_I_003 ET CDI_I_004 ET CDI_D_121 ET CDI_D_521 ET CDI_D_122 ET CDI_D_123 ET CDI_D_601 ET CDI_D_117 ET ABS_C_001 ET ABS_C_003 ET ABS_C_004 ET ABS_C_007 ET ABS_C_008 ET ABS_C_009 ET ABS_C_019 ET ABS_C_020 ET ABS_C_023 ET ABS_C_026 ET ABS_C_065 | X29: CDI_I_001 | Y29: =VLOOKUP(X29,'Axe 2 Règles de gestion'!$D$2:$F$564,3, FALSE) -> Le congé est accordé si un ascendant, descendant, un frère ou une sœur, une personne partageant le même domicile ou l'ayant désigné comme sa personne de confiance souffre d'une pathologie mettant en jeu le pronostic vital ou en phase avancée ou terminale d'une affection grave et incurable, quelle qu'en soit la cause. | Z29: CDI_I_002 | AA29: =VLOOKUP(Z29,'Axe 2 Règles de gestion'!$D$2:$F$564,3, FALSE) -> L'agent doit faire la demande par écrit. Elle est accordée de droit. | AB29: CDI_I_003 | AC29: =VLOOKUP(AB29,'Axe 2 Règles de gestion'!$D$2:$F$564,3, FALSE) -> La demande doit être appuyée d'un certificat médical attestant que la personne accompagnée souffre d'une pathologie mettant en jeu le pronostic vital ou en phase avancée ou terminale d'une affection grave et incurable, quelle qu'en soit la cause. | AD29: CDI_I_004 | AE29: =VLOOKUP(AD29,'Axe 2 Règles de gestion'!$D$2:$F$564,3, FALSE) -> Le congé peut être fractionné ou pris de manière continue. | AT29: CDI_D_121 | AU29: =VLOOKUP(AT29,'Axe 2 Règles de gestion'!$D$2:$F$564,3, FALSE) -> Le congé de solidarité familiale, ou son renouvellement, est accordé pour une durée réelle maximale de trois mois. | AV29: CDI_D_521 | AW29: =VLOOKUP(AV29,'Axe 2 Règles de gestion'!$D$2:$F$564,3, FALSE) -> Le congé de solidarité familiale, ou son renouvellement, est accordé pour une durée prévisionnelle maximale de trois mois. | AX29: CDI_D_122 | AY29: =VLOOKUP(AX29,'Axe 2 Règles de gestion'!$D$2:$F$564,3, FALSE) -> Le congé de solidarité familiale peut être fractionné mais ne peut, renouvellement inclus, excéder les 6 mois. | AZ29: CDI_D_123 | BA29: =VLOOKUP(AZ29,'Axe 2 Règles de gestion'!$D$2:$F$564,3, FALSE) -> Le congé de solidarité familiale peut être fractionné mais chaque période doit être d'une durée réelle minimale de 7 jours consécutifs. | BB29: CDI_D_601 | BC29: =VLOOKUP(BB29,'Axe 2 Règles de gestion'!$D$2:$F$564,3, FALSE) -> Le congé de solidarité familiale peut être fractionné mais chaque période doit être d'une durée prévisionnelle minimale de 7 jours consécutifs. | BD29: CDI_D_117 | BE29: =VLOOKUP(BD29,'Axe 2 Règles de gestion'!$D$2:$F$564,3, FALSE) -> L'agent doit être en activité. | BF29: ABS_C_001 | BG29: =VLOOKUP(BF29,'Axe 2 Règles de gestion'!$D$2:$F$564,3, FALSE) -> La date de début du congé/absence doit être postérieure ou égale à la date de recrutement dans la FPE ou dans la carrière militaire. | BH29: ABS_C_003 | BI29: =VLOOKUP(BH29,'Axe 2 Règles de gestion'!$D$2:$F$564,3, FALSE) -> La date de début du congé/absence doit être antérieure ou égale à la date de fin réelle du congé/absence. | BJ29: ABS_C_004 | BK29: =VLOOKUP(BJ29,'Axe 2 Règles de gestion'!$D$2:$F$564,3, FALSE) -> La date de début du congé/absence doit être antérieure ou égale à la date de fin prévisionnelle du congé/absence. | BL29: ABS_C_007 | BM29: =VLOOKUP(BL29,'Axe 2 Règles de gestion'!$D$2:$F$564,3, FALSE) -> La date de fin réelle du congé/absence doit être antérieure à la date limite de départ à la retraite. | BN29: ABS_C_008 | BO29: =VLOOKUP(BN29,'Axe 2 Règles de gestion'!$D$2:$F$564,3, FALSE) -> La date de fin prévisionnelle du congé/absence doit être antérieure à la date limite de départ à la retraite. | BP29: ABS_C_009 | BQ29: =VLOOKUP(BP29,'Axe 2 Règles de gestion'!$D$2:$F$564,3, FALSE) -> La date de fin réelle ou la date de fin prévisionnelle du congé/absence doit être saisie. | BR29: ABS_C_019 | BS29: =VLOOKUP(BR29,'Axe 2 Règles de gestion'!$D$2:$F$564,3, FALSE) -> Si l'absence ne commence pas par une demi-journée et si l'absence précédente ne finit pas par une demi journée, la date de début de l'absence saisie est postérieure à la date de fin réelle de l'absence précédente. | BT29: ABS_C_020 | BU29: =VLOOKUP(BT29,'Axe 2 Règles de gestion'!$D$2:$F$564,3, FALSE) -> Si l'absence ne commence pas par une demi-journée et si l'absence précédente ne finit pas par une demi journée, la date de début de l'absence saisie est postérieure à la date de fin prévisionnelle de l'absence précédente. | BV29: ABS_C_023 | BW29: =VLOOKUP(BV29,'Axe 2 Règles de gestion'!$D$2:$F$564,3, FALSE) -> L'état du congé est renseigné. | BX29: ABS_C_026 | BY29: =VLOOKUP(BX29,'Axe 2 Règles de gestion'!$D$2:$F$564,3, FALSE) -> Dans le cas d'un congé autre que CLM, CLD, CGM et CITIS, l'indicateur de requalification doit être à non et les impacts spécifiques à la requalification ne doivent pas être mobilisés ou l'impact rémunération est vide. | BZ29: ABS_C_065 | CA29: =VLOOKUP(BZ29,'Axe 2 Règles de gestion'!$D$2:$F$564,3, FALSE) -> L'agent en congé de présence parentale / congé de proche aidant / congé de solidarité familiale ne peut se voir accorder de manière simultanée un temps partiel pour congé de présence parentale / pour congé de proche aidant / pour congé de solidarité familiale.
A30: 20.10.00 | B30: M | C30: 44054.675 | D30: D0007 | E30: Congés/Absence | F30: S0072 | G30: Congé pour raisons de famille | H30: E0500 | I30: Congé de solidarité familiale | J30: Le Type de congé/absence est 'Congé de solidarité familiale' | K30: A_COA_TYCOAB [Saisi] = 'CG103' | L30: T1208 | M30: Congé de solidarité familiale - Fin | N30: Modification | O30: La valeur de l'Etat du congé saisie est égale à celle avant saisie | P30: A_COA_ETCOMA [Saisi] = A_COA_ETCOMA [Valeur avant saisie] | Q30: Titulaire ou magistrat | R30: P0001 | S30: Général | T30: Passant | U30: 40725 | V30: 43951 | W30: CDI_I_005 ET CDI_D_121 ET CDI_D_521 ET CDI_D_122 ET CDI_D_123 ET CDI_D_601 ET ABS_C_003 ET ABS_C_004 ET ABS_C_007 ET ABS_C_008 ET ABS_C_009 ET ABS_C_023 ET ABS_C_026 | X30: CDI_I_005 | Y30: =VLOOKUP(X30,'Axe 2 Règles de gestion'!$D$2:$F$564,3, FALSE) -> Le congé prend fin à l'issue de la période de 3 mois ou dans les 3 jours suivant le décès de la personnes accompagnée ou à la demande de l'agent. | AT30: CDI_D_121 | AU30: =VLOOKUP(AT30,'Axe 2 Règles de gestion'!$D$2:$F$564,3, FALSE) -> Le congé de solidarité familiale, ou son renouvellement, est accordé pour une durée réelle maximale de trois mois. | AV30: CDI_D_521 | AW30: =VLOOKUP(AV30,'Axe 2 Règles de gestion'!$D$2:$F$564,3, FALSE) -> Le congé de solidarité familiale, ou son renouvellement, est accordé pour une durée prévisionnelle maximale de trois mois. | AX30: CDI_D_122 | AY30: =VLOOKUP(AX30,'Axe 2 Règles de gestion'!$D$2:$F$564,3, FALSE) -> Le congé de solidarité familiale peut être fractionné mais ne peut, renouvellement inclus, excéder les 6 mois. | AZ30: CDI_D_123 | BA30: =VLOOKUP(AZ30,'Axe 2 Règles de gestion'!$D$2:$F$564,3, FALSE) -> Le congé de solidarité familiale peut être fractionné mais chaque période doit être d'une durée réelle minimale de 7 jours consécutifs. | BB30: CDI_D_601 | BC30: =VLOOKUP(BB30,'Axe 2 Règles de gestion'!$D$2:$F$564,3, FALSE) -> Le congé de solidarité familiale peut être fractionné mais chaque période doit être d'une durée prévisionnelle minimale de 7 jours consécutifs. | BF30: ABS_C_003 | BG30: =VLOOKUP(BF30,'Axe 2 Règles de gestion'!$D$2:$F$564,3, FALSE) -> La date de début du congé/absence doit être antérieure ou égale à la date de fin réelle du congé/absence. | BH30: ABS_C_004 | BI30: =VLOOKUP(BH30,'Axe 2 Règles de gestion'!$D$2:$F$564,3, FALSE) -> La date de début du congé/absence doit être antérieure ou égale à la date de fin prévisionnelle du congé/absence. | BJ30: ABS_C_007 | BK30: =VLOOKUP(BJ30,'Axe 2 Règles de gestion'!$D$2:$F$564,3, FALSE) -> La date de fin réelle du congé/absence doit être antérieure à la date limite de départ à la retraite. | BL30: ABS_C_008 | BM30: =VLOOKUP(BL30,'Axe 2 Règles de gestion'!$D$2:$F$564,3, FALSE) -> La date de fin prévisionnelle du congé/absence doit être antérieure à la date limite de départ à la retraite. | BN30: ABS_C_009 | BO30: =VLOOKUP(BN30,'Axe 2 Règles de gestion'!$D$2:$F$564,3, FALSE) -> La date de fin réelle ou la date de fin prévisionnelle du congé/absence doit être saisie. | BP30: ABS_C_023 | BQ30: =VLOOKUP(BP30,'Axe 2 Règles de gestion'!$D$2:$F$564,3, FALSE) -> L'état du congé est renseigné. | BR30: ABS_C_026 | BS30: =VLOOKUP(BR30,'Axe 2 Règles de gestion'!$D$2:$F$564,3, FALSE) -> Dans le cas d'un congé autre que CLM, CLD, CGM et CITIS, l'indicateur de requalification doit être à non et les impacts spécifiques à la requalification ne doivent pas être mobilisés ou l'impact rémunération est vide.
A31: 21.10.00 | B31: M | C31: 44469.652 | D31: D0007 | E31: Congés/Absence | F31: S0072 | G31: Congé pour raisons de famille | H31: E0500 | I31: Congé de solidarité familiale | J31: Le Type de congé/absence est 'Congé de solidarité familiale' | K31: A_COA_TYCOAB [Saisi] = 'CG103' | L31: T1208 | M31: Congé de solidarité familiale - Fin | N31: Modification | O31: La valeur de l'Etat du congé saisie est égale à celle avant saisie | P31: A_COA_ETCOMA [Saisi] = A_COA_ETCOMA [Valeur avant saisie] | Q31: Titulaire ou magistrat | R31: P0001 | S31: Général | T31: Passant | U31: 43952 | W31: CDI_I_005 ET CDI_I_192 ET CDI_D_121 ET CDI_D_521 ET CDI_D_122 ET CDI_D_123 ET CDI_D_601 ET ABS_C_003 ET ABS_C_004 ET ABS_C_007 ET ABS_C_008 ET ABS_C_009 ET ABS_C_023 ET ABS_C_026 ET ABS_C_065 | X31: CDI_I_005 | Y31: =VLOOKUP(X31,'Axe 2 Règles de gestion'!$D$2:$F$564,3, FALSE) -> Le congé prend fin à l'issue de la période de 3 mois ou dans les 3 jours suivant le décès de la personnes accompagnée ou à la demande de l'agent. | Z31: CDI_I_192 | AA31: =VLOOKUP(Z31,'Axe 2 Règles de gestion'!$D$2:$F$564,3, FALSE) -> A l'issue du congé, l'agent ne relevant pas des régimes d'obligations de service qui en fait la demande, bénéficie de plein droit des droits à congés accumulés sur son compte épargne-temps sans que les nécessités de service puissent être opposées. | AT31: CDI_D_121 | AU31: =VLOOKUP(AT31,'Axe 2 Règles de gestion'!$D$2:$F$564,3, FALSE) -> Le congé de solidarité familiale, ou son renouvellement, est accordé pour une durée réelle maximale de trois mois. | AV31: CDI_D_521 | AW31: =VLOOKUP(AV31,'Axe 2 Règles de gestion'!$D$2:$F$564,3, FALSE) -> Le congé de solidarité familiale, ou son renouvellement, est accordé pour une durée prévisionnelle maximale de trois mois. | AX31: CDI_D_122 | AY31: =VLOOKUP(AX31,'Axe 2 Règles de gestion'!$D$2:$F$564,3, FALSE) -> Le congé de solidarité familiale peut être fractionné mais ne peut, renouvellement inclus, excéder les 6 mois. | AZ31: CDI_D_123 | BA31: =VLOOKUP(AZ31,'Axe 2 Règles de gestion'!$D$2:$F$564,3, FALSE) -> Le congé de solidarité familiale peut être fractionné mais chaque période doit être d'une durée réelle minimale de 7 jours consécutifs. | BB31: CDI_D_601 | BC31: =VLOOKUP(BB31,'Axe 2 Règles de gestion'!$D$2:$F$564,3, FALSE) -> Le congé de solidarité familiale peut être fractionné mais chaque période doit être d'une durée prévisionnelle minimale de 7 jours consécutifs. | BF31: ABS_C_003 | BG31: =VLOOKUP(BF31,'Axe 2 Règles de gestion'!$D$2:$F$564,3, FALSE) -> La date de début du congé/absence doit être antérieure ou égale à la date de fin réelle du congé/absence. | BH31: ABS_C_004 | BI31: =VLOOKUP(BH31,'Axe 2 Règles de gestion'!$D$2:$F$564,3, FALSE) -> La date de début du congé/absence doit être antérieure ou égale à la date de fin prévisionnelle du congé/absence. | BJ31: ABS_C_007 | BK31: =VLOOKUP(BJ31,'Axe 2 Règles de gestion'!$D$2:$F$564,3, FALSE) -> La date de fin réelle du congé/absence doit être antérieure à la date limite de départ à la retraite. | BL31: ABS_C_008 | BM31: =VLOOKUP(BL31,'Axe 2 Règles de gestion'!$D$2:$F$564,3, FALSE) -> La date de fin prévisionnelle du congé/absence doit être antérieure à la date limite de départ à la retraite. | BN31: ABS_C_009 | BO31: =VLOOKUP(BN31,'Axe 2 Règles de gestion'!$D$2:$F$564,3, FALSE) -> La date de fin réelle ou la date de fin prévisionnelle du congé/absence doit être saisie. | BP31: ABS_C_023 | BQ31: =VLOOKUP(BP31,'Axe 2 Règles de gestion'!$D$2:$F$564,3, FALSE) -> L'état du congé est renseigné. | BR31: ABS_C_026 | BS31: =VLOOKUP(BR31,'Axe 2 Règles de gestion'!$D$2:$F$564,3, FALSE) -> Dans le cas d'un congé autre que CLM, CLD, CGM et CITIS, l'indicateur de requalification doit être à non et les impacts spécifiques à la requalification ne doivent pas être mobilisés ou l'impact rémunération est vide. | BT31: ABS_C_065 | BU31: =VLOOKUP(BT31,'Axe 2 Règles de gestion'!$D$2:$F$564,3, FALSE) -> L'agent en congé de présence parentale / congé de proche aidant / congé de solidarité familiale ne peut se voir accorder de manière simultanée un temps partiel pour congé de présence parentale / pour congé de proche aidant / pour congé de solidarité familiale.
A32: 17.10.00 | B32: A | C32: 43152.5 | D32: D0007 | E32: Congés/Absence | F32: S0072 | G32: Congé pour raisons de famille | H32: E0500 | I32: Congé de solidarité familiale | J32: Le Type de congé/absence est 'Congé de solidarité familiale' | K32: A_COA_TYCOAB [Saisi] = 'CG103' | L32: T1206 | M32: Congé de solidarité familiale - Demande | N32: Création Modification | O32: La valeur de l'Etat du congé est différente de 'Renouvellement' et la valeur de l'Etat du congé saisie est différente de celle avant saisie | P32: A_COA_ETCOMA [Saisi] <> 'EC02' ET A_COA_ETCOMA [Saisi] <> A_COA_ETCOMA [Valeur avant saisie] | Q32: Contractuel | R32: P0003 | S32: Général | T32: Exclu | U32: 40725 | V32: 41294
A33: 21.10.00 | B33: M | C33: 44469.65 | D33: D0007 | E33: Congés/Absence | F33: S0072 | G33: Congé pour raisons de famille | H33: E0500 | I33: Congé de solidarité familiale | J33: Le Type de congé/absence est 'Congé de solidarité familiale' | K33: A_COA_TYCOAB [Saisi] = 'CG103' | L33: T1206 | M33: Congé de solidarité familiale - Demande | N33: Création Modification | O33: La valeur de l'Etat du congé est différente de 'Renouvellement' et la valeur de l'Etat du congé saisie est différente de celle avant saisie | P33: A_COA_ETCOMA [Saisi] <> 'EC02' ET A_COA_ETCOMA [Saisi] <> A_COA_ETCOMA [Valeur avant saisie] | Q33: Contractuel | R33: P0003 | S33: Général | T33: Passant | U33: 41295 | W33: CDI_I_011 ET CDI_I_012 ET CDI_I_013 ET CDI_I_014 ET CDI_D_216 ET CDI_D_602 ET CDI_D_603 ET CDI_D_218 ET CDI_D_604 ET CDI_D_212 ET ABS_C_002 ET ABS_C_003 ET ABS_C_004 ET ABS_C_005 ET ABS_C_006 ET ABS_C_007 ET ABS_C_008 ET ABS_C_009 ET ABS_C_019 ET ABS_C_020 ET ABS_C_023 ET ABS_C_026 ET ABS_C_065 | X33: CDI_I_011 | Y33: =VLOOKUP(X33,'Axe 2 Règles de gestion'!$D$2:$F$564,3, FALSE) -> Le congé est accordé si un ascendant, descendant, un frère ou une sœur, une personne partageant le même domicile ou l'ayant désigné comme sa personne de confiance souffre d'une pathologie mettant en jeu le pronostic vital ou en phase avancée ou terminale d'une affection grave et incurable, quelle qu'en soit la cause. | Z33: CDI_I_012 | AA33: =VLOOKUP(Z33,'Axe 2 Règles de gestion'!$D$2:$F$564,3, FALSE) -> L'agent doit faire la demande par écrit. Elle est accordée de droit. | AB33: CDI_I_013 | AC33: =VLOOKUP(AB33,'Axe 2 Règles de gestion'!$D$2:$F$564,3, FALSE) -> La demande doit être appuyée d'un certificat médical attestant que la personne accompagnée souffre d'une pathologie mettant en jeu le pronostic vital ou en phase avancée ou terminale d'une affection grave et incurable, quelle qu'en soit la cause. | AD33: CDI_I_014 | AE33: =VLOOKUP(AD33,'Axe 2 Règles de gestion'!$D$2:$F$564,3, FALSE) -> Le congé peut être fractionné ou pris de manière continue. | AT33: CDI_D_216 | AU33: =VLOOKUP(AT33,'Axe 2 Règles de gestion'!$D$2:$F$564,3, FALSE) -> Le congé de solidarité familiale, ou son renouvellement, est accordé pour une durée réelle maximale de trois mois. | AV33: CDI_D_602 | AW33: =VLOOKUP(AV33,'Axe 2 Règles de gestion'!$D$2:$F$564,3, FALSE) -> Le congé de solidarité familiale, ou son renouvellement, est accordé pour une durée prévisionnelle maximale de trois mois. | AX33: CDI_D_603 | AY33: =VLOOKUP(AX33,'Axe 2 Règles de gestion'!$D$2:$F$564,3, FALSE) -> Le congé de solidarité familiale peut être fractionné mais ne peut, renouvellement inclus, excéder les 6 mois. | AZ33: CDI_D_218 | BA33: =VLOOKUP(AZ33,'Axe 2 Règles de gestion'!$D$2:$F$564,3, FALSE) -> Le congé de solidarité familiale peut être fractionné mais chaque période doit être d'une durée réelle minimale de 7 jours consécutifs. | BB33: CDI_D_604 | BC33: =VLOOKUP(BB33,'Axe 2 Règles de gestion'!$D$2:$F$564,3, FALSE) -> Le congé de solidarité familiale peut être fractionné mais chaque période doit être d'une durée prévisionnelle minimale de 7 jours consécutifs. | BD33: CDI_D_212 | BE33: =VLOOKUP(BD33,'Axe 2 Règles de gestion'!$D$2:$F$564,3, FALSE) -> L'agent doit être en activité. | BF33: ABS_C_002 | BG33: =VLOOKUP(BF33,'Axe 2 Règles de gestion'!$D$2:$F$564,3, FALSE) -> La date de début du congé/absence doit être postérieure ou égale à la date de début du lien juridique. | BH33: ABS_C_003 | BI33: =VLOOKUP(BH33,'Axe 2 Règles de gestion'!$D$2:$F$564,3, FALSE) -> La date de début du congé/absence doit être antérieure ou égale à la date de fin réelle du congé/absence. | BJ33: ABS_C_004 | BK33: =VLOOKUP(BJ33,'Axe 2 Règles de gestion'!$D$2:$F$564,3, FALSE) -> La date de début du congé/absence doit être antérieure ou égale à la date de fin prévisionnelle du congé/absence. | BL33: ABS_C_005 | BM33: =VLOOKUP(BL33,'Axe 2 Règles de gestion'!$D$2:$F$564,3, FALSE) -> La date de fin réelle du congé/absence doit être antérieure ou égale à la date limite de fin réelle ou prévisionnelle du lien juridique. | BN33: ABS_C_006 | BO33: =VLOOKUP(BN33,'Axe 2 Règles de gestion'!$D$2:$F$564,3, FALSE) -> La date de fin prévisionnelle du congé/absence doit être antérieure ou égale à la date limite de fin réelle ou prévisionnelle du lien juridique. | BP33: ABS_C_007 | BQ33: =VLOOKUP(BP33,'Axe 2 Règles de gestion'!$D$2:$F$564,3, FALSE) -> La date de fin réelle du congé/absence doit être antérieure à la date limite de départ à la retraite. | BR33: ABS_C_008 | BS33: =VLOOKUP(BR33,'Axe 2 Règles de gestion'!$D$2:$F$564,3, FALSE) -> La date de fin prévisionnelle du congé/absence doit être antérieure à la date limite de départ à la retraite. | BT33: ABS_C_009 | BU33: =VLOOKUP(BT33,'Axe 2 Règles de gestion'!$D$2:$F$564,3, FALSE) -> La date de fin réelle ou la date de fin prévisionnelle du congé/absence doit être saisie. | BV33: ABS_C_019 | BW33: =VLOOKUP(BV33,'Axe 2 Règles de gestion'!$D$2:$F$564,3, FALSE) -> Si l'absence ne commence pas par une demi-journée et si l'absence précédente ne finit pas par une demi journée, la date de début de l'absence saisie est postérieure à la date de fin réelle de l'absence précédente. | BX33: ABS_C_020 | BY33: =VLOOKUP(BX33,'Axe 2 Règles de gestion'!$D$2:$F$564,3, FALSE) -> Si l'absence ne commence pas par une demi-journée et si l'absence précédente ne finit pas par une demi journée, la date de début de l'absence saisie est postérieure à la date de fin prévisionnelle de l'absence précédente. | BZ33: ABS_C_023 | CA33: =VLOOKUP(BZ33,'Axe 2 Règles de gestion'!$D$2:$F$564,3, FALSE) -> L'état du congé est renseigné. | CB33: ABS_C_026 | CC33: =VLOOKUP(CB33,'Axe 2 Règles de gestion'!$D$2:$F$564,3, FALSE) -> Dans le cas d'un congé autre que CLM, CLD, CGM et CITIS, l'indicateur de requalification doit être à non et les impacts spécifiques à la requalification ne doivent pas être mobilisés ou l'impact rémunération est vide. | CD33: ABS_C_065 | CE33: =VLOOKUP(CD33,'Axe 2 Règles de gestion'!$D$2:$F$564,3, FALSE) -> L'agent en congé de présence parentale / congé de proche aidant / congé de solidarité familiale ne peut se voir accorder de manière simultanée un temps partiel pour congé de présence parentale / pour congé de proche aidant / pour congé de solidarité familiale.
A34: 17.10.00 | B34: A | C34: 43152.5 | D34: D0007 | E34: Congés/Absence | F34: S0072 | G34: Congé pour raisons de famille | H34: E0500 | I34: Congé de solidarité familiale | J34: Le Type de congé/absence est 'Congé de solidarité familiale' | K34: A_COA_TYCOAB [Saisi] = 'CG103' | L34: T1207 | M34: Congé de solidarité familiale - Renouvellement | N34: Création Modification | O34: La valeur de l'Etat du congé est égale à 'Renouvellement' et la valeur de l'Etat du congé saisie est différente de celle avant saisie | P34: A_COA_ETCOMA [Saisi] = 'EC02' ET A_COA_ETCOMA [Saisi] <> A_COA_ETCOMA [Valeur avant saisie] | Q34: Contractuel | R34: P0003 | S34: Général | T34: Exclu | U34: 40725 | V34: 41294
