Workbook
Name date_DIADC: 'Mode opératoire'!#REF!
Name notice_DIADC: 'Mode opératoire'!#REF!
Name notice_ENCHN: 'Mode opératoire'!$B$1:$B$4
Name notice_ICA: 'Mode opératoire'!#REF!

Sheet Mode opératoire
B1: MODE OPERATOIRE
B2: La transaction s'effectue pour l'évènement E0971 'Compte épargne-temps' au niveau des sous rubriques : - Compte épargne-temps - Ouverture - Compte épargne-temps - Alimentation - Compte épargne-temps - Choix d'option La transaction s'effectue pour l'évènement E0972 'Compte épargne-temps historique' au niveau de la sous rubrique : - Compte épargne-temps historique - Choix d'option La transaction s'effectue pour l'évènement E0973 'Compte épargne-temps - Mobilité/Fin de fonction' au niveau de la sous rubrique : - Compte épargne-temps - Mobilité/Fin de fonction

Sheet Axe 1 Enchainement des RG
A1: Version | B1: Type de mise à jour | C1: Date de mise à jour | D1: Identifiant Domaine | E1: Libellé du Domaine | F1: Identifiant Sous-domaine | G1: Libellé du Sous-domaine | H1: Identifiant Evénement | I1: Libellé de l'évènement | J1: Libellé condition déclenchement Evènement | K1: Condition déclenchement Evènement | L1: Identifiant type d'évènement | M1: Libellé type d'évènement | N1: Type de mise à jour | O1: Libellé condition déclenchement Type Evènement | P1: Condition déclenchement Type Evènement | Q1: Libellé Population | R1: Codification Population | S1: Typologie de population | T1: Général / Particulier | U1: Passant / Exclu | V1: Date de début | W1: Date de fin | X1: Règles mobilisées | Y1: Identifiant Règle de contrôle intellectuel 1 | Z1: Libellé Règle de contrôle intellectuel 1 | AA1: Identifiant Règle de contrôle intellectuel 2 | AB1: Libellé Règle de contrôle intellectuel 2 | AC1: Identifiant Règle de contrôle intellectuel 3 | AD1: Libellé Règle de contrôle intellectuel 3 | AE1: Identifiant Règle de contrôle intellectuel 4 | AF1: Libellé Règle de contrôle intellectuel 4 | AG1: Identifiant Règle de contrôle intellectuel 5 | AH1: Libellé Règle de contrôle intellectuel 5 | AI1: Identifiant Règle de contrôle intellectuel 6 | AJ1: Libellé Règle de contrôle intellectuel 6 | AK1: Identifiant Règle de contrôle intellectuel 7 | AL1: Libellé Règle de contrôle intellectuel 7 | AM1: Identifiant Règle de condition 1 | AN1: Libellé Règle de condition 1 | AO1: Identifiant Règle de condition 2 | AP1: Libellé Règle de condition 2 | AQ1: Identifiant Règle de condition 3 | AR1: Libellé Règle de condition 3 | AS1: Identifiant Règle de condition 4 | AT1: Libellé Règle de condition 4 | AU1: Identifiant Règle de contrôle 1 | AV1: Libellé Règle de contrôle 1 | AW1: Identifiant Règle de contrôle 2 | AX1: Libellé Règle de contrôle 2 | AY1: Identifiant Règle de contrôle 3 | AZ1: Libellé Règle de contrôle 3 | BA1: Identifiant Règle de contrôle 4 | BB1: Libellé Règle de contrôle 4 | BC1: FIME | BD1: Statut de travail
A2: 24.10.00 | B2: A | C2: 45628.64 | D2: D0007 | E2: Congés/Absence | F2: S0183 | G2: Compte épargne-temps | H2: E0971 | I2: Compte épargne-temps (CET) | J2: La date d'observation saisie du CET est non vide | K2: A_CET_DAGCET [Saisi] <> Vide | L2: T2358 | M2: Compte épargne-temps - Ouverture | N2: Création Modification | O2: La date d'ouverture saisie est non vide et la date de l'opération est vide | P2: A_CET_DCRCET [Saisi] <> VIDE ET A_CET_DOOCET [Saisi] = VIDE | Q2: Titulaire ou magistrat | R2: P0001 | S2: T | T2: Général | U2: Passant | V2: 45323 | X2: CET_I_050 ET CET_D_400 ET CET_D_407 ET CET_C_017 ET CET_C_031 | Y2: CET_I_050 | Z2: =VLOOKUP(Y2,'Axe 2 Règles de gestion'!$D$2:$F$61,3, FALSE) -> L'agent doit effectuer une demande d'ouverture d'un compte épargne-temps. | AM2: CET_D_400 | AN2: =VLOOKUP(AM2,'Axe 2 Règles de gestion'!$D$2:$F$61,3, FALSE) -> L'agent ne doit pas relever des régimes d'obligation de service. | AO2: CET_D_407 | AP2: =VLOOKUP(AO2,'Axe 2 Règles de gestion'!$D$2:$F$61,3, FALSE) -> L'agent est employé de manière continue et a accompli au moins 1 année de service. | AU2: CET_C_017 | AV2: =VLOOKUP(AU2,'Axe 2 Règles de gestion'!$D$2:$F$61,3, FALSE) -> La date d'ouverture du compte épargne temps global doit être postérieure ou égale à la date d'entrée dans le SIRH. | AW2: CET_C_031 | AX2: =VLOOKUP(AW2,'Axe 2 Règles de gestion'!$D$2:$F$61,3, FALSE) -> Les champs "Origine", "Nombre de jours de l'opération", "Nombre de jours pour valorisation financière" et "Nombre de jours pour cotisation RAFP" ne doivent pas être renseignés.
A3: 24.10.00 | B3: A | C3: 45628.644 | D3: D0007 | E3: Congés/Absence | F3: S0183 | G3: Compte épargne-temps | H3: E0971 | I3: Compte épargne-temps (CET) | J3: La date d'observation saisie du CET est non vide | K3: A_CET_DAGCET [Saisi] <> Vide | L3: T2359 | M3: Compte épargne-temps - Alimentation | N3: Création Modification | O3: La date de l'opération saisie est non vide et le sens de l'opération est "Versé" | P3: A_CET_DOOCET [Saisi] <> Vide ET A_CET_SEOCET [Saisi] = 'V' | Q3: Titulaire ou magistrat | R3: P0001 | S3: T | T3: Général | U3: Passant | V3: 45323 | W3: 45688 | X3: CET_I_061 ET CET_I_060 ET CET_D_401 ET CET_D_402 ET CET_D_403 ET CET_D_404 ET CET_C_023 ET CET_C_026 | Y3: CET_I_061 | Z3: =VLOOKUP(Y3,'Axe 2 Règles de gestion'!$D$2:$F$61,3, FALSE) -> Pour les agents en service à l'étranger, le compte épargne-temps est alimenté par le report des jours de congés annuels dont ils bénéficient au titre du pays dans lequel ils sont affectés. | AA3: CET_I_060 | AB3: =VLOOKUP(AA3,'Axe 2 Règles de gestion'!$D$2:$F$61,3, FALSE) -> L'agent ne peut pas alimenter son compte épargne-temps par le report de congés bonifiés. | AM3: CET_D_401 | AN3: =VLOOKUP(AM3,'Axe 2 Règles de gestion'!$D$2:$F$61,3, FALSE) -> L'agent peut alimenter son compte épargne-temps par le report de jours de réduction du temps de travail, par le report de congés annuels et de fractionnement et si un arrêté le prévoit par le report de jours de repos compensateur. | AO3: CET_D_402 | AP3: =VLOOKUP(AO3,'Axe 2 Règles de gestion'!$D$2:$F$61,3, FALSE) -> L'agent pour pouvoir alimenter son compte épargne-temps doit avoir pris dans l'année au moins 20 jours de congés. | AQ3: CET_D_403 | AR3: =VLOOKUP(AQ3,'Axe 2 Règles de gestion'!$D$2:$F$61,3, FALSE) -> Lorsque le compte épargne-temps atteint 15 jours, l'agent peut épargner ensuite chaque année 10 jours au maximum. | AS3: CET_D_404 | AT3: =VLOOKUP(AS3,'Axe 2 Règles de gestion'!$D$2:$F$61,3, FALSE) -> L'agent peut au titre de l'année 2024, lorsque le compte épargne-temps atteint 15 jours, épargner 20 jours au maximum en raison de l'organisation des jeux olympiques et paralympiques. | AU3: CET_C_023 | AV3: =VLOOKUP(AU3,'Axe 2 Règles de gestion'!$D$2:$F$61,3, FALSE) -> Lorsque le sens de l'opération est à "Versé", le compteur global saisi est égal au compteur global de l'occurrence précédente auquel sont ajoutés les jours versés. | AW3: CET_C_026 | AX3: =VLOOKUP(AW3,'Axe 2 Règles de gestion'!$D$2:$F$61,3, FALSE) -> Lorsque le sens de l'opération est égal à "versé", le nombre de jours pour valorisation financière et le nombre de jours pour cotisation RAFP ne doivent pas être renseignés.
A4: 24.10.00 | B4: A | C4: 45628.645 | D4: D0007 | E4: Congés/Absence | F4: S0183 | G4: Compte épargne-temps | H4: E0971 | I4: Compte épargne-temps (CET) | J4: La date d'observation saisie du CET est non vide | K4: A_CET_DAGCET [Saisi] <> Vide | L4: T2359 | M4: Compte épargne-temps - Alimentation | N4: Création Modification | O4: La date de l'opération saisie est non vide et le sens de l'opération est "Versé" | P4: A_CET_DOOCET [Saisi] <> Vide ET A_CET_SEOCET [Saisi] = 'V' | Q4: Titulaire ou magistrat | R4: P0001 | S4: T | T4: Général | U4: Passant | V4: 45689 | X4: CET_I_061 ET CET_I_060 ET CET_D_401 ET CET_D_402 ET CET_D_403 ET CET_C_023 ET CET_C_026 | Y4: CET_I_061 | Z4: =VLOOKUP(Y4,'Axe 2 Règles de gestion'!$D$2:$F$61,3, FALSE) -> Pour les agents en service à l'étranger, le compte épargne-temps est alimenté par le report des jours de congés annuels dont ils bénéficient au titre du pays dans lequel ils sont affectés. | AA4: CET_I_060 | AB4: =VLOOKUP(AA4,'Axe 2 Règles de gestion'!$D$2:$F$61,3, FALSE) -> L'agent ne peut pas alimenter son compte épargne-temps par le report de congés bonifiés. | AM4: CET_D_401 | AN4: =VLOOKUP(AM4,'Axe 2 Règles de gestion'!$D$2:$F$61,3, FALSE) -> L'agent peut alimenter son compte épargne-temps par le report de jours de réduction du temps de travail, par le report de congés annuels et de fractionnement et si un arrêté le prévoit par le report de jours de repos compensateur. | AO4: CET_D_402 | AP4: =VLOOKUP(AO4,'Axe 2 Règles de gestion'!$D$2:$F$61,3, FALSE) -> L'agent pour pouvoir alimenter son compte épargne-temps doit avoir pris dans l'année au moins 20 jours de congés. | AQ4: CET_D_403 | AR4: =VLOOKUP(AQ4,'Axe 2 Règles de gestion'!$D$2:$F$61,3, FALSE) -> Lorsque le compte épargne-temps atteint 15 jours, l'agent peut épargner ensuite chaque année 10 jours au maximum. | AU4: CET_C_023 | AV4: =VLOOKUP(AU4,'Axe 2 Règles de gestion'!$D$2:$F$61,3, FALSE) -> Lorsque le sens de l'opération est à "Versé", le compteur global saisi est égal au compteur global de l'occurrence précédente auquel sont ajoutés les jours versés. | AW4: CET_C_026 | AX4: =VLOOKUP(AW4,'Axe 2 Règles de gestion'!$D$2:$F$61,3, FALSE) -> Lorsque le sens de l'opération est égal à "versé", le nombre de jours pour valorisation financière et le nombre de jours pour cotisation RAFP ne doivent pas être renseignés.
A5: 24.10.00 | B5: A | C5: 45628.659 | D5: D0007 | E5: Congés/Absence | F5: S0183 | G5: Compte épargne-temps | H5: E0971 | I5: Compte épargne-temps (CET) | J5: La date d'observation saisie du CET est non vide | K5: A_CET_DAGCET [Saisi] <> Vide | L5: T2360 | M5: Compte épargne-temps - Choix d'option | N5: Création Modification | O5: La date de l'opération saisie est non vide et le sens de l'opération est "Consommé" | P5: A_CET_DOOCET [Saisi] <> Vide ET A_CET_SEOCET [Saisi] = 'C' | Q5: Titulaire ou magistrat | R5: P0001 | S5: T | T5: Général | U5: Passant | V5: 45323 | X5: CET_I_052 ET CET_I_054 ET CET_I_055 ET CET_I_057 ET CET_I_059 ET CET_D_405 ET CET_D_406 ET CET_D_408 ET CET_C_004 ET CET_C_024 ET CET_C_027 | Y5: CET_I_052 | Z5: =VLOOKUP(Y5,'Axe 2 Règles de gestion'!$D$2:$F$61,3, FALSE) -> L'agent est informé chaque année, par l'administration, des jours épargnés et consommés. | AA5: CET_I_054 | AB5: =VLOOKUP(AA5,'Axe 2 Règles de gestion'!$D$2:$F$61,3, FALSE) -> Si le nombre de jours inscrits est supérieur à 15 jours au terme de l'année civile, l'agent ne peut utiliser ces 15 jours que sous forme de congés, pour les autres jours il doit exercer une option au plus le tard le 31 janvier de l'année suivante. | AC5: CET_I_055 | AD5: =VLOOKUP(AC5,'Axe 2 Règles de gestion'!$D$2:$F$61,3, FALSE) -> L'agent peut opter dans les proportions qu'il souhaite pour un prise en compte au sein du régime de retraite additionnelle de la fonction publique, pour une indemnisation ou pour un maintien sur le compte épargne-temps. | AE5: CET_I_057 | AF5: =VLOOKUP(AE5,'Axe 2 Règles de gestion'!$D$2:$F$61,3, FALSE) -> Si l'agent n'exerce pas son droit d'option, les jours au-delà de 15 sont pris en compte au sein du régime de retraite additionnelle de la fonction publique. | AG5: CET_I_059 | AH5: =VLOOKUP(AG5,'Axe 2 Règles de gestion'!$D$2:$F$61,3, FALSE) -> Les années suivantes, les jours ainsi épargnés excédant le plafond global de jours prévu peuvent être maintenus sur le compte épargne-temps ou être consommés. | AM5: CET_D_405 | AN5: =VLOOKUP(AM5,'Axe 2 Règles de gestion'!$D$2:$F$61,3, FALSE) -> Le nombre de jours maintenus sur le compte épargne-temps ne doit pas dépasser un plafond annuel de 60 jours. | AO5: CET_D_406 | AP5: =VLOOKUP(AO5,'Axe 2 Règles de gestion'!$D$2:$F$61,3, FALSE) -> Au terme de l'année 2024, en raison de l'organisation des jeux olympiques et paralympiques, ce plafond annuel passe à 70 jours ou si le nombre de jours épargnés au terme de l'année 2023 excède 60 jours, au nombre de jours épargnés augmentés de 10 jours. | AQ5: CET_D_408 | AR5: =VLOOKUP(AQ5,'Axe 2 Règles de gestion'!$D$2:$F$61,3, FALSE) -> Si le nombre de jours inscrits sur le compte épargne-temps est inférieur ou égal à 15 jours au terme de l'année civile, l'agent ne peut utiliser ces jours épargnés que sous forme de congés. | AU5: CET_C_004 | AV5: =VLOOKUP(AU5,'Axe 2 Règles de gestion'!$D$2:$F$61,3, FALSE) -> Le nombre de jours de l'opération doit être inférieur ou égal au nombre de jours du compteur global du CET. | AW5: CET_C_024 | AX5: =VLOOKUP(AW5,'Axe 2 Règles de gestion'!$D$2:$F$61,3, FALSE) -> Lorsque le sens de l'opération est à "consommé", le compteur global saisi est égal au compteur global de l'occurrence précédente duquel sont soustraits les jours consommés en congés, les jours pour valorisation financière et les jours pour cotisation RAFP. | AY5: CET_C_027 | AZ5: =VLOOKUP(AY5,'Axe 2 Règles de gestion'!$D$2:$F$61,3, FALSE) -> Lorsque le sens de l'opération est égal à "consommé", l'origine des jours n'est pas à renseigner.
A6: 24.10.00 | B6: A | C6: 45628.64 | D6: D0007 | E6: Congés/Absence | F6: S0183 | G6: Compte épargne-temps | H6: E0971 | I6: Compte épargne-temps (CET) | J6: La date d'observation saisie du CET est non vide | K6: A_CET_DAGCET [Saisi] <> Vide | L6: T2358 | M6: Compte épargne-temps - Ouverture | N6: Création Modification | O6: La date d'ouverture saisie est non vide et la date de l'opération est vide | P6: A_CET_DCRCET [Saisi] <> VIDE ET A_CET_DOOCET [Saisi] = VIDE | Q6: Militaire | R6: P0002 | S6: M | T6: Général | U6: Exclu | V6: 45323
A7: 24.10.00 | B7: A | C7: 45628.645 | D7: D0007 | E7: Congés/Absence | F7: S0183 | G7: Compte épargne-temps | H7: E0971 | I7: Compte épargne-temps (CET) | J7: La date d'observation saisie du CET est non vide | K7: A_CET_DAGCET [Saisi] <> Vide | L7: T2359 | M7: Compte épargne-temps - Alimentation | N7: Création Modification | O7: La date de l'opération saisie est non vide et le sens de l'opération est "Versé" | P7: A_CET_DOOCET [Saisi] <> Vide ET A_CET_SEOCET [Saisi] = 'V' | Q7: Militaire | R7: P0002 | S7: M | T7: Général | U7: Exclu | V7: 45323
A8: 24.10.00 | B8: A | C8: 45628.66 | D8: D0007 | E8: Congés/Absence | F8: S0183 | G8: Compte épargne-temps | H8: E0971 | I8: Compte épargne-temps (CET) | J8: La date d'observation saisie du CET est non vide | K8: A_CET_DAGCET [Saisi] <> Vide | L8: T2360 | M8: Compte épargne-temps - Choix d'option | N8: Création Modification | O8: La date de l'opération saisie est non vide et le sens de l'opération est "Consommé" | P8: A_CET_DOOCET [Saisi] <> Vide ET A_CET_SEOCET [Saisi] = 'C' | Q8: Militaire | R8: P0002 | S8: M | T8: Général | U8: Exclu | V8: 45323
A9: 24.10.00 | B9: A | C9: 45628.64 | D9: D0007 | E9: Congés/Absence | F9: S0183 | G9: Compte épargne-temps | H9: E0971 | I9: Compte épargne-temps (CET) | J9: La date d'observation saisie du CET est non vide | K9: A_CET_DAGCET [Saisi] <> Vide | L9: T2358 | M9: Compte épargne-temps - Ouverture | N9: Création Modification | O9: La date d'ouverture saisie est non vide et la date de l'opération est vide | P9: A_CET_DCRCET [Saisi] <> VIDE ET A_CET_DOOCET [Saisi] = VIDE | Q9: Contractuel | R9: P0003 | S9: N | T9: Général | U9: Passant | V9: 45323 | X9: CET_I_050 ET CET_D_400 ET CET_D_407 ET CET_C_017 ET CET_C_031 | Y9: CET_I_050 | Z9: =VLOOKUP(Y9,'Axe 2 Règles de gestion'!$D$2:$F$61,3, FALSE) -> L'agent doit effectuer une demande d'ouverture d'un compte épargne-temps. | AM9: CET_D_400 | AN9: =VLOOKUP(AM9,'Axe 2 Règles de gestion'!$D$2:$F$61,3, FALSE) -> L'agent ne doit pas relever des régimes d'obligation de service. | AO9: CET_D_407 | AP9: =VLOOKUP(AO9,'Axe 2 Règles de gestion'!$D$2:$F$61,3, FALSE) -> L'agent est employé de manière continue et a accompli au moins 1 année de service. | AU9: CET_C_017 | AV9: =VLOOKUP(AU9,'Axe 2 Règles de gestion'!$D$2:$F$61,3, FALSE) -> La date d'ouverture du compte épargne temps global doit être postérieure ou égale à la date d'entrée dans le SIRH. | AW9: CET_C_031 | AX9: =VLOOKUP(AW9,'Axe 2 Règles de gestion'!$D$2:$F$61,3, FALSE) -> Les champs "Origine", "Nombre de jours de l'opération", "Nombre de jours pour valorisation financière" et "Nombre de jours pour cotisation RAFP" ne doivent pas être renseignés.
A10: 24.10.00 | B10: A | C10: 45635.722 | D10: D0007 | E10: Congés/Absence | F10: S0183 | G10: Compte épargne-temps | H10: E0971 | I10: Compte épargne-temps (CET) | J10: La date d'observation saisie du CET est non vide | K10: A_CET_DAGCET [Saisi] <> Vide | L10: T2359 | M10: Compte épargne-temps - Alimentation | N10: Création Modification | O10: La date de l'opération saisie est non vide et le sens de l'opération est "Versé" | P10: A_CET_DOOCET [Saisi] <> Vide ET A_CET_SEOCET [Saisi] = 'V' | Q10: Contractuel | R10: P0003 | S10: N | T10: Général | U10: Passant | V10: 45323 | W10: 45688 | X10: CET_I_061 ET CET_I_060 ET CET_D_401 ET CET_D_402 ET CET_D_403 ET CET_D_404 ET CET_C_023 ET CET_C_026 | Y10: CET_I_061 | Z10: =VLOOKUP(Y10,'Axe 2 Règles de gestion'!$D$2:$F$61,3, FALSE) -> Pour les agents en service à l'étranger, le compte épargne-temps est alimenté par le report des jours de congés annuels dont ils bénéficient au titre du pays dans lequel ils sont affectés. | AA10: CET_I_060 | AB10: =VLOOKUP(AA10,'Axe 2 Règles de gestion'!$D$2:$F$61,3, FALSE) -> L'agent ne peut pas alimenter son compte épargne-temps par le report de congés bonifiés. | AM10: CET_D_401 | AN10: =VLOOKUP(AM10,'Axe 2 Règles de gestion'!$D$2:$F$61,3, FALSE) -> L'agent peut alimenter son compte épargne-temps par le report de jours de réduction du temps de travail, par le report de congés annuels et de fractionnement et si un arrêté le prévoit par le report de jours de repos compensateur. | AO10: CET_D_402 | AP10: =VLOOKUP(AO10,'Axe 2 Règles de gestion'!$D$2:$F$61,3, FALSE) -> L'agent pour pouvoir alimenter son compte épargne-temps doit avoir pris dans l'année au moins 20 jours de congés. | AQ10: CET_D_403 | AR10: =VLOOKUP(AQ10,'Axe 2 Règles de gestion'!$D$2:$F$61,3, FALSE) -> Lorsque le compte épargne-temps atteint 15 jours, l'agent peut épargner ensuite chaque année 10 jours au maximum. | AS10: CET_D_404 | AT10: =VLOOKUP(AS10,'Axe 2 Règles de gestion'!$D$2:$F$61,3, FALSE) -> L'agent peut au titre de l'année 2024, lorsque le compte épargne-temps atteint 15 jours, épargner 20 jours au maximum en raison de l'organisation des jeux olympiques et paralympiques. | AU10: CET_C_023 | AV10: =VLOOKUP(AU10,'Axe 2 Règles de gestion'!$D$2:$F$61,3, FALSE) -> Lorsque le sens de l'opération est à "Versé", le compteur global saisi est égal au compteur global de l'occurrence précédente auquel sont ajoutés les jours versés. | AW10: CET_C_026 | AX10: =VLOOKUP(AW10,'Axe 2 Règles de gestion'!$D$2:$F$61,3, FALSE) -> Lorsque le sens de l'opération est égal à "versé", le nombre de jours pour valorisation financière et le nombre de jours pour cotisation RAFP ne doivent pas être renseignés.
A11: 24.10.00 | B11: A | C11: 45635.722 | D11: D0007 | E11: Congés/Absence | F11: S0183 | G11: Compte épargne-temps | H11: E0971 | I11: Compte épargne-temps (CET) | J11: La date d'observation saisie du CET est non vide | K11: A_CET_DAGCET [Saisi] <> Vide | L11: T2359 | M11: Compte épargne-temps - Alimentation | N11: Création Modification | O11: La date de l'opération saisie est non vide et le sens de l'opération est "Versé" | P11: A_CET_DOOCET [Saisi] <> Vide ET A_CET_SEOCET [Saisi] = 'V' | Q11: Contractuel | R11: P0003 | S11: N | T11: Général | U11: Passant | V11: 45689 | X11: CET_I_061 ET CET_I_060 ET CET_D_401 ET CET_D_402 ET CET_D_403 ET CET_C_023 ET CET_C_026 | Y11: CET_I_061 | Z11: =VLOOKUP(Y11,'Axe 2 Règles de gestion'!$D$2:$F$61,3, FALSE) -> Pour les agents en service à l'étranger, le compte épargne-temps est alimenté par le report des jours de congés annuels dont ils bénéficient au titre du pays dans lequel ils sont affectés. | AA11: CET_I_060 | AB11: =VLOOKUP(AA11,'Axe 2 Règles de gestion'!$D$2:$F$61,3, FALSE) -> L'agent ne peut pas alimenter son compte épargne-temps par le report de congés bonifiés. | AM11: CET_D_401 | AN11: =VLOOKUP(AM11,'Axe 2 Règles de gestion'!$D$2:$F$61,3, FALSE) -> L'agent peut alimenter son compte épargne-temps par le report de jours de réduction du temps de travail, par le report de congés annuels et de fractionnement et si un arrêté le prévoit par le report de jours de repos compensateur. | AO11: CET_D_402 | AP11: =VLOOKUP(AO11,'Axe 2 Règles de gestion'!$D$2:$F$61,3, FALSE) -> L'agent pour pouvoir alimenter son compte épargne-temps doit avoir pris dans l'année au moins 20 jours de congés. | AQ11: CET_D_403 | AR11: =VLOOKUP(AQ11,'Axe 2 Règles de gestion'!$D$2:$F$61,3, FALSE) -> Lorsque le compte épargne-temps atteint 15 jours, l'agent peut épargner ensuite chaque année 10 jours au maximum. | AU11: CET_C_023 | AV11: =VLOOKUP(AU11,'Axe 2 Règles de gestion'!$D$2:$F$61,3, FALSE) -> Lorsque le sens de l'opération est à "Versé", le compteur global saisi est égal au compteur global de l'occurrence précédente auquel sont ajoutés les jours versés. | AW11: CET_C_026 | AX11: =VLOOKUP(AW11,'Axe 2 Règles de gestion'!$D$2:$F$61,3, FALSE) -> Lorsque le sens de l'opération est égal à "versé", le nombre de jours pour valorisation financière et le nombre de jours pour cotisation RAFP ne doivent pas être renseignés.
A12: 24.10.00 | B12: A | C12: 45628.66 | D12: D0007 | E12: Congés/Absence | F12: S0183 | G12: Compte épargne-temps | H12: E0971 | I12: Compte épargne-temps (CET) | J12: La date d'observation saisie du CET est non vide | K12: A_CET_DAGCET [Saisi] <> Vide | L12: T2360 | M12: Compte épargne-temps - Choix d'option | N12: Création Modification | O12: La date de l'opération saisie est non vide et le sens de l'opération est "Consommé" | P12: A_CET_DOOCET [Saisi] <> Vide ET A_CET_SEOCET [Saisi] = 'C' | Q12: Contractuel | R12: P0003 | S12: N | T12: Général | U12: Passant | V12: 45323 | X12: CET_I_052 ET CET_I_054 ET CET_I_056 ET CET_I_058 ET CET_I_059 ET CET_D_405 ET CET_D_406 ET CET_D_408 ET CET_C_004 ET CET_C_024 ET CET_C_027 | Y12: CET_I_052 | Z12: =VLOOKUP(Y12,'Axe 2 Règles de gestion'!$D$2:$F$61,3, FALSE) -> L'agent est informé chaque année, par l'administration, des jours épargnés et consommés. | AA12: CET_I_054 | AB12: =VLOOKUP(AA12,'Axe 2 Règles de gestion'!$D$2:$F$61,3, FALSE) -> Si le nombre de jours inscrits est supérieur à 15 jours au terme de l'année civile, l'agent ne peut utiliser ces 15 jours que sous forme de congés, pour les autres jours il doit exercer une option au plus le tard le 31 janvier de l'année suivante. | AC12: CET_I_056 | AD12: =VLOOKUP(AC12,'Axe 2 Règles de gestion'!$D$2:$F$61,3, FALSE) -> L'agent peut opter dans les proportions qu'il souhaite pour une indemnisation ou pour un maintien sur le compte épargne-temps. | AE12: CET_I_058 | AF12: =VLOOKUP(AE12,'Axe 2 Règles de gestion'!$D$2:$F$61,3, FALSE) -> Si l'agent n'exerce pas son droit d'option, les jours au-delà de 15 sont indemnisés. | AG12: CET_I_059 | AH12: =VLOOKUP(AG12,'Axe 2 Règles de gestion'!$D$2:$F$61,3, FALSE) -> Les années suivantes, les jours ainsi épargnés excédant le plafond global de jours prévu peuvent être maintenus sur le compte épargne-temps ou être consommés. | AM12: CET_D_405 | AN12: =VLOOKUP(AM12,'Axe 2 Règles de gestion'!$D$2:$F$61,3, FALSE) -> Le nombre de jours maintenus sur le compte épargne-temps ne doit pas dépasser un plafond annuel de 60 jours. | AO12: CET_D_406 | AP12: =VLOOKUP(AO12,'Axe 2 Règles de gestion'!$D$2:$F$61,3, FALSE) -> Au terme de l'année 2024, en raison de l'organisation des jeux olympiques et paralympiques, ce plafond annuel passe à 70 jours ou si le nombre de jours épargnés au terme de l'année 2023 excède 60 jours, au nombre de jours épargnés augmentés de 10 jours. | AQ12: CET_D_408 | AR12: =VLOOKUP(AQ12,'Axe 2 Règles de gestion'!$D$2:$F$61,3, FALSE) -> Si le nombre de jours inscrits sur le compte épargne-temps est inférieur ou égal à 15 jours au terme de l'année civile, l'agent ne peut utiliser ces jours épargnés que sous forme de congés. | AU12: CET_C_004 | AV12: =VLOOKUP(AU12,'Axe 2 Règles de gestion'!$D$2:$F$61,3, FALSE) -> Le nombre de jours de l'opération doit être inférieur ou égal au nombre de jours du compteur global du CET. | AW12: CET_C_024 | AX12: =VLOOKUP(AW12,'Axe 2 Règles de gestion'!$D$2:$F$61,3, FALSE) -> Lorsque le sens de l'opération est à "consommé", le compteur global saisi est égal au compteur global de l'occurrence précédente duquel sont soustraits les jours consommés en congés, les jours pour valorisation financière et les jours pour cotisation RAFP. | AY12: CET_C_027 | AZ12: =VLOOKUP(AY12,'Axe 2 Règles de gestion'!$D$2:$F$61,3, FALSE) -> Lorsque le sens de l'opération est égal à "consommé", l'origine des jours n'est pas à renseigner.
A13: 24.10.00 | B13: A | C13: 45628.641 | D13: D0007 | E13: Congés/Absence | F13: S0183 | G13: Compte épargne-temps | H13: E0971 | I13: Compte épargne-temps (CET) | J13: La date d'observation saisie du CET est non vide | K13: A_CET_DAGCET [Saisi] <> Vide | L13: T2358 | M13: Compte épargne-temps - Ouverture | N13: Création Modification | O13: La date d'ouverture saisie est non vide et la date de l'opération est vide | P13: A_CET_DCRCET [Saisi] <> VIDE ET A_CET_DOOCET [Saisi] = VIDE | Q13: Stagiaire ou auditeur ou élève | R13: P0004 | S13: S | T13: Général | U13: Exclu | V13: 45323
A14: 24.10.00 | B14: A | C14: 45628.647 | D14: D0007 | E14: Congés/Absence | F14: S0183 | G14: Compte épargne-temps | H14: E0971 | I14: Compte épargne-temps (CET) | J14: La date d'observation saisie du CET est non vide | K14: A_CET_DAGCET [Saisi] <> Vide | L14: T2359 | M14: Compte épargne-temps - Alimentation | N14: Création Modification | O14: La date de l'opération saisie est non vide et le sens de l'opération est "Versé" | P14: A_CET_DOOCET [Saisi] <> Vide ET A_CET_SEOCET [Saisi] = 'V' | Q14: Stagiaire ou auditeur ou élève | R14: P0004 | S14: S | T14: Général | U14: Exclu | V14: 45323
A15: 24.10.00 | B15: A | C15: 45628.661 | D15: D0007 | E15: Congés/Absence | F15: S0183 | G15: Compte épargne-temps | H15: E0971 | I15: Compte épargne-temps (CET) | J15: La date d'observation saisie du CET est non vide | K15: A_CET_DAGCET [Saisi] <> Vide | L15: T2360 | M15: Compte épargne-temps - Choix d'option | N15: Création Modification | O15: La date de l'opération saisie est non vide et le sens de l'opération est "Consommé" | P15: A_CET_DOOCET [Saisi] <> Vide ET A_CET_SEOCET [Saisi] = 'C' | Q15: Stagiaire ou auditeur ou élève | R15: P0004 | S15: S | T15: Général | U15: Exclu | V15: 45323
A16: 26.00.00 | B16: M | C16: 46175.674 | D16: D0007 | E16: Congés/Absence | F16: S0183 | G16: Compte épargne-temps | H16: E0971 | I16: Compte épargne-temps (CET) | J16: La date d'observation saisie du CET est non vide | K16: A_CET_DAGCET [Saisi] <> Vide | L16: T2358 | M16: Compte épargne-temps - Ouverture | N16: Création Modification | O16: La date d'ouverture saisie est non vide et la date de l'opération est vide | P16: A_CET_DCRCET [Saisi] <> VIDE ET A_CET_DOOCET [Saisi] = VIDE | Q16: Ouvrier d'état | R16: P0005 | S16: O | T16: Général | U16: Passant | V16: 45901 | X16: CET_C_017 ET CET_C_031 | AU16: CET_C_017 | AV16: =VLOOKUP(AU16,'Axe 2 Règles de gestion'!$D$2:$F$61,3, FALSE) -> La date d'ouverture du compte épargne temps global doit être postérieure ou égale à la date d'entrée dans le SIRH. | AW16: CET_C_031 | AX16: =VLOOKUP(AW16,'Axe 2 Règles de gestion'!$D$2:$F$61,3, FALSE) -> Les champs "Origine", "Nombre de jours de l'opération", "Nombre de jours pour valorisation financière" et "Nombre de jours pour cotisation RAFP" ne doivent pas être renseignés. | BC16: 2026-45
A17: 26.00.00 | B17: M | C17: 46175.674 | D17: D0007 | E17: Congés/Absence | F17: S0183 | G17: Compte épargne-temps | H17: E0971 | I17: Compte épargne-temps (CET) | J17: La date d'observation saisie du CET est non vide | K17: A_CET_DAGCET [Saisi] <> Vide | L17: T2359 | M17: Compte épargne-temps - Alimentation | N17: Création Modification | O17: La date de l'opération saisie est non vide et le sens de l'opération est "Versé" | P17: A_CET_DOOCET [Saisi] <> Vide ET A_CET_SEOCET [Saisi] = 'V' | Q17: Ouvrier d'état | R17: P0005 | S17: O | T17: Général | U17: Passant | V17: 45901 | X17: CET_C_004 ET CET_C_017 ET CET_C_023 | AU17: CET_C_004 | AV17: =VLOOKUP(AU17,'Axe 2 Règles de gestion'!$D$2:$F$61,3, FALSE) -> Le nombre de jours de l'opération doit être inférieur ou égal au nombre de jours du compteur global du CET. | AW17: CET_C_017 | AX17: =VLOOKUP(AW17,'Axe 2 Règles de gestion'!$D$2:$F$61,3, FALSE) -> La date d'ouverture du compte épargne temps global doit être postérieure ou égale à la date d'entrée dans le SIRH. | AY17: CET_C_023 | AZ17: =VLOOKUP(AY17,'Axe 2 Règles de gestion'!$D$2:$F$61,3, FALSE) -> Lorsque le sens de l'opération est à "Versé", le compteur global saisi est égal au compteur global de l'occurrence précédente auquel sont ajoutés les jours versés. | BC17: 2026-45
A18: 26.00.00 | B18: M | C18: 46175.675 | D18: D0007 | E18: Congés/Absence | F18: S0183 | G18: Compte épargne-temps | H18: E0971 | I18: Compte épargne-temps (CET) | J18: La date d'observation saisie du CET est non vide | K18: A_CET_DAGCET [Saisi] <> Vide | L18: T2360 | M18: Compte épargne-temps - Choix d'option | N18: Création Modification | O18: La date de l'opération saisie est non vide et le sens de l'opération est "Consommé" | P18: A_CET_DOOCET [Saisi] <> Vide ET A_CET_SEOCET [Saisi] = 'C' | Q18: Ouvrier d'état | R18: P0005 | S18: O | T18: Général | U18: Passant | V18: 45901 | X18: CET_C_004 ET CET_C_024 ET CET_C_027 | AU18: CET_C_004 | AV18: =VLOOKUP(AU18,'Axe 2 Règles de gestion'!$D$2:$F$61,3, FALSE) -> Le nombre de jours de l'opération doit être inférieur ou égal au nombre de jours du compteur global du CET. | AW18: CET_C_024 | AX18: =VLOOKUP(AW18,'Axe 2 Règles de gestion'!$D$2:$F$61,3, FALSE) -> Lorsque le sens de l'opération est à "consommé", le compteur global saisi est égal au compteur global de l'occurrence précédente duquel sont soustraits les jours consommés en congés, les jours pour valorisation financière et les jours pour cotisation RAFP. | AY18: CET_C_027 | AZ18: =VLOOKUP(AY18,'Axe 2 Règles de gestion'!$D$2:$F$61,3, FALSE) -> Lorsque le sens de l'opération est égal à "consommé", l'origine des jours n'est pas à renseigner. | BC18: 2026-45
A19: 24.10.00 | B19: A | C19: 45628.642 | D19: D0007 | E19: Congés/Absence | F19: S0183 | G19: Compte épargne-temps | H19: E0971 | I19: Compte épargne-temps (CET) | J19: La date d'observation saisie du CET est non vide | K19: A_CET_DAGCET [Saisi] <> Vide | L19: T2358 | M19: Compte épargne-temps - Ouverture | N19: Création Modification | O19: La date d'ouverture saisie est non vide et la date de l'opération est vide | P19: A_CET_DCRCET [Saisi] <> VIDE ET A_CET_DOOCET [Saisi] = VIDE | Q19: Expert technique international | R19: P0018 | S19: N | T19: Particulier | U19: Exclu | V19: 45323
A20: 24.10.00 | B20: A | C20: 45628.647 | D20: D0007 | E20: Congés/Absence | F20: S0183 | G20: Compte épargne-temps | H20: E0971 | I20: Compte épargne-temps (CET) | J20: La date d'observation saisie du CET est non vide | K20: A_CET_DAGCET [Saisi] <> Vide | L20: T2359 | M20: Compte épargne-temps - Alimentation | N20: Création Modification | O20: La date de l'opération saisie est non vide et le sens de l'opération est "Versé" | P20: A_CET_DOOCET [Saisi] <> Vide ET A_CET_SEOCET [Saisi] = 'V' | Q20: Expert technique international | R20: P0018 | S20: N | T20: Particulier | U20: Exclu | V20: 45323
A21: 24.10.00 | B21: A | C21: 45628.662 | D21: D0007 | E21: Congés/Absence | F21: S0183 | G21: Compte épargne-temps | H21: E0971 | I21: Compte épargne-temps (CET) | J21: La date d'observation saisie du CET est non vide | K21: A_CET_DAGCET [Saisi] <> Vide | L21: T2360 | M21: Compte épargne-temps - Choix d'option | N21: Création Modification | O21: La date de l'opération saisie est non vide et le sens de l'opération est "Consommé" | P21: A_CET_DOOCET [Saisi] <> Vide ET A_CET_SEOCET [Saisi] = 'C' | Q21: Expert technique international | R21: P0018 | S21: N | T21: Particulier | U21: Exclu | V21: 45323
A22: 24.10.00 | B22: A | C22: 45628.642 | D22: D0007 | E22: Congés/Absence | F22: S0183 | G22: Compte épargne-temps | H22: E0971 | I22: Compte épargne-temps (CET) | J22: La date d'observation saisie du CET est non vide | K22: A_CET_DAGCET [Saisi] <> Vide | L22: T2358 | M22: Compte épargne-temps - Ouverture | N22: Création Modification | O22: La date d'ouverture saisie est non vide et la date de l'opération est vide | P22: A_CET_DCRCET [Saisi] <> VIDE ET A_CET_DOOCET [Saisi] = VIDE | Q22: Personnel civil payé à l'acte ou à la tâche | R22: P0054 | S22: N | T22: Particulier | U22: Exclu | V22: 45323
A23: 24.10.00 | B23: A | C23: 45628.648 | D23: D0007 | E23: Congés/Absence | F23: S0183 | G23: Compte épargne-temps | H23: E0971 | I23: Compte épargne-temps (CET) | J23: La date d'observation saisie du CET est non vide | K23: A_CET_DAGCET [Saisi] <> Vide | L23: T2359 | M23: Compte épargne-temps - Alimentation | N23: Création Modification | O23: La date de l'opération saisie est non vide et le sens de l'opération est "Versé" | P23: A_CET_DOOCET [Saisi] <> Vide ET A_CET_SEOCET [Saisi] = 'V' | Q23: Personnel civil payé à l'acte ou à la tâche | R23: P0054 | S23: N | T23: Particulier | U23: Exclu | V23: 45323
A24: 24.10.00 | B24: A | C24: 45628.662 | D24: D0007 | E24: Congés/Absence | F24: S0183 | G24: Compte épargne-temps | H24: E0971 | I24: Compte épargne-temps (CET) | J24: La date d'observation saisie du CET est non vide | K24: A_CET_DAGCET [Saisi] <> Vide | L24: T2360 | M24: Compte épargne-temps - Choix d'option | N24: Création Modification | O24: La date de l'opération saisie est non vide et le sens de l'opération est "Consommé" | P24: A_CET_DOOCET [Saisi] <> Vide ET A_CET_SEOCET [Saisi] = 'C' | Q24: Personnel civil payé à l'acte ou à la tâche | R24: P0054 | S24: N | T24: Particulier | U24: Exclu | V24: 45323
A25: 24.10.00 | B25: A | C25: 45628.642 | D25: D0007 | E25: Congés/Absence | F25: S0183 | G25: Compte épargne-temps | H25: E0971 | I25: Compte épargne-temps (CET) | J25: La date d'observation saisie du CET est non vide | K25: A_CET_DAGCET [Saisi] <> Vide | L25: T2358 | M25: Compte épargne-temps - Ouverture | N25: Création Modification | O25: La date d'ouverture saisie est non vide et la date de l'opération est vide | P25: A_CET_DCRCET [Saisi] <> VIDE ET A_CET_DOOCET [Saisi] = VIDE | Q25: Contractuel de droit privé | R25: P0072 | S25: N | T25: Particulier | U25: Exclu | V25: 45323
A26: 24.10.00 | B26: A | C26: 45628.648 | D26: D0007 | E26: Congés/Absence | F26: S0183 | G26: Compte épargne-temps | H26: E0971 | I26: Compte épargne-temps (CET) | J26: La date d'observation saisie du CET est non vide | K26: A_CET_DAGCET [Saisi] <> Vide | L26: T2359 | M26: Compte épargne-temps - Alimentation | N26: Création Modification | O26: La date de l'opération saisie est non vide et le sens de l'opération est "Versé" | P26: A_CET_DOOCET [Saisi] <> Vide ET A_CET_SEOCET [Saisi] = 'V' | Q26: Contractuel de droit privé | R26: P0072 | S26: N | T26: Particulier | U26: Exclu | V26: 45323
A27: 24.10.00 | B27: A | C27: 45628.662 | D27: D0007 | E27: Congés/Absence | F27: S0183 | G27: Compte épargne-temps | H27: E0971 | I27: Compte épargne-temps (CET) | J27: La date d'observation saisie du CET est non vide | K27: A_CET_DAGCET [Saisi] <> Vide | L27: T2360 | M27: Compte épargne-temps - Choix d'option | N27: Création Modification | O27: La date de l'opération saisie est non vide et le sens de l'opération est "Consommé" | P27: A_CET_DOOCET [Saisi] <> Vide ET A_CET_SEOCET [Saisi] = 'C' | Q27: Contractuel de droit privé | R27: P0072 | S27: N | T27: Particulier | U27: Exclu | V27: 45323
A28: 26.00.00 | B28: A | C28: 46175.676 | D28: D0007 | E28: Congés/Absence | F28: S0183 | G28: Compte épargne-temps | H28: E0971 | I28: Compte épargne-temps (CET) | J28: La date d'observation saisie du CET est non vide | K28: A_CET_DAGCET [Saisi] <> Vide | L28: T2358 | M28: Compte épargne-temps - Ouverture | N28: Création Modification | O28: La date d'ouverture saisie est non vide et la date de l'opération est vide | P28: A_CET_DCRCET [Saisi] <> VIDE ET A_CET_DOOCET [Saisi] = VIDE | Q28: Ouvrier de la défense réglementé affilié | R28: P0093 | S28: O | T28: Particulier | U28: Passant | V28: 45323 | X28: CET_I_031 ET CET_I_005 ET CET_D_412 ET CET_D_409 ET CET_C_017 ET CET_C_031 | Y28: CET_I_031 | Z28: =VLOOKUP(Y28,'Axe 2 Règles de gestion'!$D$2:$F$61,3, FALSE) -> L'agent demande l'ouverture d'un compte épargne-temps auprès du service gestionnaire. | AA28: CET_I_005 | AB28: =VLOOKUP(AA28,'Axe 2 Règles de gestion'!$D$2:$F$61,3, FALSE) -> Une instruction du ministre de la Défense détermine, dans le respect de l'intérêt du service, les règles d'ouverture, de fonctionnement, de gestion et de fermeture du compte épargne-temps, ainsi que les modalités de son utilisation par l'agent. | AM28: CET_D_412 | AN28: =VLOOKUP(AM28,'Axe 2 Règles de gestion'!$D$2:$F$61,3, FALSE) -> Les agents exerçant des fonctions d'enseignement et dont les obligations horaires ont été prédéfinies et quantifiées dans des régimes d'obligations de service n'ont pas le droit au CET. | AO28: CET_D_409 | AP28: =VLOOKUP(AO28,'Axe 2 Règles de gestion'!$D$2:$F$61,3, FALSE) -> L'agent doit être employé de manière continue et avoir accompli au moins 1 année de service au sein du ministère de la Défense ou de ses établissements publics. | AU28: CET_C_017 | AV28: =VLOOKUP(AU28,'Axe 2 Règles de gestion'!$D$2:$F$61,3, FALSE) -> La date d'ouverture du compte épargne temps global doit être postérieure ou égale à la date d'entrée dans le SIRH. | AW28: CET_C_031 | AX28: =VLOOKUP(AW28,'Axe 2 Règles de gestion'!$D$2:$F$61,3, FALSE) -> Les champs "Origine", "Nombre de jours de l'opération", "Nombre de jours pour valorisation financière" et "Nombre de jours pour cotisation RAFP" ne doivent pas être renseignés. | BC28: 2026-45
A29: 26.00.00 | B29: A | C29: 46175.677 | D29: D0007 | E29: Congés/Absence | F29: S0183 | G29: Compte épargne-temps | H29: E0971 | I29: Compte épargne-temps (CET) | J29: La date d'observation saisie du CET est non vide | K29: A_CET_DAGCET [Saisi] <> Vide | L29: T2359 | M29: Compte épargne-temps - Alimentation | N29: Création Modification | O29: La date de l'opération saisie est non vide et le sens de l'opération est "Versé" | P29: A_CET_DOOCET [Saisi] <> Vide ET A_CET_SEOCET [Saisi] = 'V' | Q29: Ouvrier de la défense réglementé affilié | R29: P0093 | S29: O | T29: Particulier | U29: Passant | V29: 45323 | X29: CET_I_008 ET CET_I_032 ET CET_D_092 ET CET_D_215 ET CET_D_410 ET CET_C_004 ET CET_C_017 ET CET_C_023 ET CET_C_026 | Y29: CET_I_008 | Z29: =VLOOKUP(Y29,'Axe 2 Règles de gestion'!$D$2:$F$61,3, FALSE) -> L'administration informe annuellement l'agent des droits épargnés et consommés. | AA29: CET_I_032 | AB29: =VLOOKUP(AA29,'Axe 2 Règles de gestion'!$D$2:$F$61,3, FALSE) -> L'agent demande, en une fois, au service gestionnaire l'alimentation de son compte épargne-temps avant le 31 décembre de l'année en cours. | AM29: CET_D_092 | AN29: =VLOOKUP(AM29,'Axe 2 Règles de gestion'!$D$2:$F$61,3, FALSE) -> Le CET est alimenté par le report de jours de réduction du temps de travail (ARTT), par le report de congés annuels, le report des jours de repos compensateur et/ou le report d'une partie des congés de fin de séjour pour les ouvriers de l'Etat mutés dans les DOM, les TOM ou à l'étranger. | AO29: CET_D_215 | AP29: =VLOOKUP(AO29,'Axe 2 Règles de gestion'!$D$2:$F$61,3, FALSE) -> Le nombre de jours de congés pris dans l'année doit être supérieur ou égal à 20 jours. | AQ29: CET_D_410 | AR29: =VLOOKUP(AQ29,'Axe 2 Règles de gestion'!$D$2:$F$61,3, FALSE) -> Le CET peut être alimenté dans la limite de 18 jours par an. | AU29: CET_C_004 | AV29: =VLOOKUP(AU29,'Axe 2 Règles de gestion'!$D$2:$F$61,3, FALSE) -> Le nombre de jours de l'opération doit être inférieur ou égal au nombre de jours du compteur global du CET. | AW29: CET_C_017 | AX29: =VLOOKUP(AW29,'Axe 2 Règles de gestion'!$D$2:$F$61,3, FALSE) -> La date d'ouverture du compte épargne temps global doit être postérieure ou égale à la date d'entrée dans le SIRH. | AY29: CET_C_023 | AZ29: =VLOOKUP(AY29,'Axe 2 Règles de gestion'!$D$2:$F$61,3, FALSE) -> Lorsque le sens de l'opération est à "Versé", le compteur global saisi est égal au compteur global de l'occurrence précédente auquel sont ajoutés les jours versés. | BA29: CET_C_026 | BB29: =VLOOKUP(BA29,'Axe 2 Règles de gestion'!$D$2:$F$61,3, FALSE) -> Lorsque le sens de l'opération est égal à "versé", le nombre de jours pour valorisation financière et le nombre de jours pour cotisation RAFP ne doivent pas être renseignés. | BC29: 2026-45
A30: 26.00.00 | B30: A | C30: 46175.679 | D30: D0007 | E30: Congés/Absence | F30: S0183 | G30: Compte épargne-temps | H30: E0971 | I30: Compte épargne-temps (CET) | J30: La date d'observation saisie du CET est non vide | K30: A_CET_DAGCET [Saisi] <> Vide | L30: T2360 | M30: Compte épargne-temps - Choix d'option | N30: Création Modification | O30: La date de l'opération saisie est non vide et le sens de l'opération est "Consommé" | P30: A_CET_DOOCET [Saisi] <> Vide ET A_CET_SEOCET [Saisi] = 'C' | Q30: Ouvrier de la défense réglementé affilié | R30: P0093 | S30: O | T30: Particulier | U30: Passant | V30: 45323 | X30: CET_I_008 ET CET_I_034 ET CET_I_035 ET CET_I_071 ET CET_I_072 ET CET_I_073 ET CET_I_074 ET CET_D_411 ET CET_C_004 ET CET_C_024 ET CET_C_027 | Y30: CET_I_008 | Z30: =VLOOKUP(Y30,'Axe 2 Règles de gestion'!$D$2:$F$61,3, FALSE) -> L'administration informe annuellement l'agent des droits épargnés et consommés. | AA30: CET_I_034 | AB30: =VLOOKUP(AA30,'Axe 2 Règles de gestion'!$D$2:$F$61,3, FALSE) -> La demande d'utilisation du compte épargne-temps de l'agent doit être déposée auprès du service gestionnaire dans un délai de 2 mois avant un congé d'au plus 40 jours ouvrés pris en continu et dans un délai de 4 mois s'il est d'une plus longue durée. | AC30: CET_I_035 | AD30: =VLOOKUP(AC30,'Axe 2 Règles de gestion'!$D$2:$F$61,3, FALSE) -> Le service gestionnaire informe l'agent que si le nombre de jours épargnés est d'au moins 40, alors les droits à congés doivent être exercés dans un délai de 10 ans à compter de cette notification. | AE30: CET_I_071 | AF30: =VLOOKUP(AE30,'Axe 2 Règles de gestion'!$D$2:$F$61,3, FALSE) -> Les droits à congés acquis au titre du compte épargne-temps ne peuvent être exercés qu'à compter de la date à laquelle l'agent a accumulé 40 jours sur son compte. | AG30: CET_I_072 | AH30: =VLOOKUP(AG30,'Axe 2 Règles de gestion'!$D$2:$F$61,3, FALSE) -> L'agent qui n'a pu, du fait de l'administration, utiliser à cette échéance les droits à congés accumulés sur son compte épargne-temps en bénéficie de plein droit. | AI30: CET_I_073 | AJ30: =VLOOKUP(AI30,'Axe 2 Règles de gestion'!$D$2:$F$61,3, FALSE) -> Lorsque l'agent a bénéficié de congés de présence parentale, de congés de longue maladie ou de congés de longue durée, le délai est prorogé d'une durée égale à celle desdits congés. | AK30: CET_I_074 | AL30: =VLOOKUP(AK30,'Axe 2 Règles de gestion'!$D$2:$F$61,3, FALSE) -> Les conditions de durée minimum d'accumulation et de délai, ne peuvent être opposées aux agents à la date de leur radiation des contrôles ou de leur licenciement. | AM30: CET_D_411 | AN30: =VLOOKUP(AM30,'Axe 2 Règles de gestion'!$D$2:$F$61,3, FALSE) -> Le CET ne peut être utilisé que pour rémunérer des congés d'une durée minimale de 5 jours ouvrés. | AU30: CET_C_004 | AV30: =VLOOKUP(AU30,'Axe 2 Règles de gestion'!$D$2:$F$61,3, FALSE) -> Le nombre de jours de l'opération doit être inférieur ou égal au nombre de jours du compteur global du CET. | AW30: CET_C_024 | AX30: =VLOOKUP(AW30,'Axe 2 Règles de gestion'!$D$2:$F$61,3, FALSE) -> Lorsque le sens de l'opération est à "consommé", le compteur global saisi est égal au compteur global de l'occurrence précédente duquel sont soustraits les jours consommés en congés, les jours pour valorisation financière et les jours pour cotisation RAFP. | AY30: CET_C_027 | AZ30: =VLOOKUP(AY30,'Axe 2 Règles de gestion'!$D$2:$F$61,3, FALSE) -> Lorsque le sens de l'opération est égal à "consommé", l'origine des jours n'est pas à renseigner. | BC30: 2026-45
A31: 25.10.00 | B31: A | C31: 45994.438 | D31: D0007 | E31: Congés/Absence | F31: S0183 | G31: Compte épargne-temps | H31: E0971 | I31: Compte épargne-temps (CET) | J31: La date d'observation saisie du CET est non vide | K31: A_CET_DAGCET [Saisi] <> Vide | L31: T2358 | M31: Compte épargne-temps - Ouverture | N31: Création Modification | O31: La date d'ouverture saisie est non vide et la date de l'opération est vide | P31: A_CET_DCRCET [Saisi] <> VIDE ET A_CET_DOOCET [Saisi] = VIDE | Q31: Ouvrier des parcs et ateliers ou assimilé confirmé | R31: P0096 | S31: O | T31: Particulier | U31: Passant | V31: 45901 | X31: CET_I_036 ET CET_I_050 ET CET_D_400 ET CET_D_407 ET CET_C_017 ET CET_C_031 | Y31: CET_I_036 | Z31: =VLOOKUP(Y31,'Axe 2 Règles de gestion'!$D$2:$F$61,3, FALSE) -> L'agent bénéficie des dispositions applicables aux agents titulaires pour le compte épargne-temps, sauf dispositions contraires. | AA31: CET_I_050 | AB31: =VLOOKUP(AA31,'Axe 2 Règles de gestion'!$D$2:$F$61,3, FALSE) -> L'agent doit effectuer une demande d'ouverture d'un compte épargne-temps. | AM31: CET_D_400 | AN31: =VLOOKUP(AM31,'Axe 2 Règles de gestion'!$D$2:$F$61,3, FALSE) -> L'agent ne doit pas relever des régimes d'obligation de service. | AO31: CET_D_407 | AP31: =VLOOKUP(AO31,'Axe 2 Règles de gestion'!$D$2:$F$61,3, FALSE) -> L'agent est employé de manière continue et a accompli au moins 1 année de service. | AU31: CET_C_017 | AV31: =VLOOKUP(AU31,'Axe 2 Règles de gestion'!$D$2:$F$61,3, FALSE) -> La date d'ouverture du compte épargne temps global doit être postérieure ou égale à la date d'entrée dans le SIRH. | AW31: CET_C_031 | AX31: =VLOOKUP(AW31,'Axe 2 Règles de gestion'!$D$2:$F$61,3, FALSE) -> Les champs "Origine", "Nombre de jours de l'opération", "Nombre de jours pour valorisation financière" et "Nombre de jours pour cotisation RAFP" ne doivent pas être renseignés.
A32: 25.10.00 | B32: A | C32: 45994.44 | D32: D0007 | E32: Congés/Absence | F32: S0183 | G32: Compte épargne-temps | H32: E0971 | I32: Compte épargne-temps (CET) | J32: La date d'observation saisie du CET est non vide | K32: A_CET_DAGCET [Saisi] <> Vide | L32: T2359 | M32: Compte épargne-temps - Alimentation | N32: Création Modification | O32: La date de l'opération saisie est non vide et le sens de l'opération est "Versé" | P32: A_CET_DOOCET [Saisi] <> Vide ET A_CET_SEOCET [Saisi] = 'V' | Q32: Ouvrier des parcs et ateliers ou assimilé confirmé | R32: P0096 | S32: O | T32: Particulier | U32: Passant | V32: 45901 | X32: CET_I_036 ET CET_I_061 ET CET_I_060 ET CET_D_401 ET CET_D_402 ET CET_D_403 ET CET_C_023 ET CET_C_026 | Y32: CET_I_036 | Z32: =VLOOKUP(Y32,'Axe 2 Règles de gestion'!$D$2:$F$61,3, FALSE) -> L'agent bénéficie des dispositions applicables aux agents titulaires pour le compte épargne-temps, sauf dispositions contraires. | AA32: CET_I_061 | AB32: =VLOOKUP(AA32,'Axe 2 Règles de gestion'!$D$2:$F$61,3, FALSE) -> Pour les agents en service à l'étranger, le compte épargne-temps est alimenté par le report des jours de congés annuels dont ils bénéficient au titre du pays dans lequel ils sont affectés. | AC32: CET_I_060 | AD32: =VLOOKUP(AC32,'Axe 2 Règles de gestion'!$D$2:$F$61,3, FALSE) -> L'agent ne peut pas alimenter son compte épargne-temps par le report de congés bonifiés. | AM32: CET_D_401 | AN32: =VLOOKUP(AM32,'Axe 2 Règles de gestion'!$D$2:$F$61,3, FALSE) -> L'agent peut alimenter son compte épargne-temps par le report de jours de réduction du temps de travail, par le report de congés annuels et de fractionnement et si un arrêté le prévoit par le report de jours de repos compensateur. | AO32: CET_D_402 | AP32: =VLOOKUP(AO32,'Axe 2 Règles de gestion'!$D$2:$F$61,3, FALSE) -> L'agent pour pouvoir alimenter son compte épargne-temps doit avoir pris dans l'année au moins 20 jours de congés. | AQ32: CET_D_403 | AR32: =VLOOKUP(AQ32,'Axe 2 Règles de gestion'!$D$2:$F$61,3, FALSE) -> Lorsque le compte épargne-temps atteint 15 jours, l'agent peut épargner ensuite chaque année 10 jours au maximum. | AU32: CET_C_023 | AV32: =VLOOKUP(AU32,'Axe 2 Règles de gestion'!$D$2:$F$61,3, FALSE) -> Lorsque le sens de l'opération est à "Versé", le compteur global saisi est égal au compteur global de l'occurrence précédente auquel sont ajoutés les jours versés. | AW32: CET_C_026 | AX32: =VLOOKUP(AW32,'Axe 2 Règles de gestion'!$D$2:$F$61,3, FALSE) -> Lorsque le sens de l'opération est égal à "versé", le nombre de jours pour valorisation financière et le nombre de jours pour cotisation RAFP ne doivent pas être renseignés.
A33: 25.10.00 | B33: A | C33: 45994.442 | D33: D0007 | E33: Congés/Absence | F33: S0183 | G33: Compte épargne-temps | H33: E0971 | I33: Compte épargne-temps (CET) | J33: La date d'observation saisie du CET est non vide | K33: A_CET_DAGCET [Saisi] <> Vide | L33: T2360 | M33: Compte épargne-temps - Choix d'option | N33: Création Modification | O33: La date de l'opération saisie est non vide et le sens de l'opération est "Consommé" | P33: A_CET_DOOCET [Saisi] <> Vide ET A_CET_SEOCET [Saisi] = 'C' | Q33: Ouvrier des parcs et ateliers ou assimilé confirmé | R33: P0096 | S33: O | T33: Particulier | U33: Passant | V33: 45901 | X33: CET_I_036 ET CET_I_052 ET CET_I_054 ET CET_I_037 ET CET_I_038 ET CET_I_059 ET CET_D_405 ET CET_D_406 ET CET_D_408 ET CET_C_004 ET CET_C_024 ET CET_C_027 | Y33: CET_I_036 | Z33: =VLOOKUP(Y33,'Axe 2 Règles de gestion'!$D$2:$F$61,3, FALSE) -> L'agent bénéficie des dispositions applicables aux agents titulaires pour le compte épargne-temps, sauf dispositions contraires. | AA33: CET_I_052 | AB33: =VLOOKUP(AA33,'Axe 2 Règles de gestion'!$D$2:$F$61,3, FALSE) -> L'agent est informé chaque année, par l'administration, des jours épargnés et consommés. | AC33: CET_I_054 | AD33: =VLOOKUP(AC33,'Axe 2 Règles de gestion'!$D$2:$F$61,3, FALSE) -> Si le nombre de jours inscrits est supérieur à 15 jours au terme de l'année civile, l'agent ne peut utiliser ces 15 jours que sous forme de congés, pour les autres jours il doit exercer une option au plus le tard le 31 janvier de l'année suivante. | AE33: CET_I_037 | AF33: =VLOOKUP(AE33,'Axe 2 Règles de gestion'!$D$2:$F$61,3, FALSE) -> L'agent peut opter dans les proportions qu'il souhaite pour une indemnisation ou pour un maintien sur le compte épargne-temps. | AG33: CET_I_038 | AH33: =VLOOKUP(AG33,'Axe 2 Règles de gestion'!$D$2:$F$61,3, FALSE) -> Si l'agent n'exerce pas son droit d'option, les jours au-delà de 15 sont indemnisés. | AI33: CET_I_059 | AJ33: =VLOOKUP(AI33,'Axe 2 Règles de gestion'!$D$2:$F$61,3, FALSE) -> Les années suivantes, les jours ainsi épargnés excédant le plafond global de jours prévu peuvent être maintenus sur le compte épargne-temps ou être consommés. | AM33: CET_D_405 | AN33: =VLOOKUP(AM33,'Axe 2 Règles de gestion'!$D$2:$F$61,3, FALSE) -> Le nombre de jours maintenus sur le compte épargne-temps ne doit pas dépasser un plafond annuel de 60 jours. | AO33: CET_D_406 | AP33: =VLOOKUP(AO33,'Axe 2 Règles de gestion'!$D$2:$F$61,3, FALSE) -> Au terme de l'année 2024, en raison de l'organisation des jeux olympiques et paralympiques, ce plafond annuel passe à 70 jours ou si le nombre de jours épargnés au terme de l'année 2023 excède 60 jours, au nombre de jours épargnés augmentés de 10 jours. | AQ33: CET_D_408 | AR33: =VLOOKUP(AQ33,'Axe 2 Règles de gestion'!$D$2:$F$61,3, FALSE) -> Si le nombre de jours inscrits sur le compte épargne-temps est inférieur ou égal à 15 jours au terme de l'année civile, l'agent ne peut utiliser ces jours épargnés que sous forme de congés. | AU33: CET_C_004 | AV33: =VLOOKUP(AU33,'Axe 2 Règles de gestion'!$D$2:$F$61,3, FALSE) -> Le nombre de jours de l'opération doit être inférieur ou égal au nombre de jours du compteur global du CET. | AW33: CET_C_024 | AX33: =VLOOKUP(AW33,'Axe 2 Règles de gestion'!$D$2:$F$61,3, FALSE) -> Lorsque le sens de l'opération est à "consommé", le compteur global saisi est égal au compteur global de l'occurrence précédente duquel sont soustraits les jours consommés en congés, les jours pour valorisation financière et les jours pour cotisation RAFP. | AY33: CET_C_027 | AZ33: =VLOOKUP(AY33,'Axe 2 Règles de gestion'!$D$2:$F$61,3, FALSE) -> Lorsque le sens de l'opération est égal à "consommé", l'origine des jours n'est pas à renseigner.
A34: 24.10.00 | B34: A | C34: 45628.643 | D34: D0007 | E34: Congés/Absence | F34: S0183 | G34: Compte épargne-temps | H34: E0971 | I34: Compte épargne-temps (CET) | J34: La date d'observation saisie du CET est non vide | K34: A_CET_DAGCET [Saisi] <> Vide | L34: T2358 | M34: Compte épargne-temps - Ouverture | N34: Création Modification | O34: La date d'ouverture saisie est non vide et la date de l'opération est vide | P34: A_CET_DCRCET [Saisi] <> VIDE ET A_CET_DOOCET [Saisi] = VIDE | Q34: Volontaire International | R34: P0178 | S34: N | T34: Particulier | U34: Exclu | V34: 45323
A35: 24.10.00 | B35: A | C35: 45628.648 | D35: D0007 | E35: Congés/Absence | F35: S0183 | G35: Compte épargne-temps | H35: E0971 | I35: Compte épargne-temps (CET) | J35: La date d'observation saisie du CET est non vide | K35: A_CET_DAGCET [Saisi] <> Vide | L35: T2359 | M35: Compte épargne-temps - Alimentation | N35: Création Modification | O35: La date de l'opération saisie est non vide et le sens de l'opération est "Versé" | P35: A_CET_DOOCET [Saisi] <> Vide ET A_CET_SEOCET [Saisi] = 'V' | Q35: Volontaire International | R35: P0178 | S35: N | T35: Particulier | U35: Exclu | V35: 45323
A36: 24.10.00 | B36: A | C36: 45628.662 | D36: D0007 | E36: Congés/Absence | F36: S0183 | G36: Compte épargne-temps | H36: E0971 | I36: Compte épargne-temps (CET) | J36: La date d'observation saisie du CET est non vide | K36: A_CET_DAGCET [Saisi] <> Vide | L36: T2360 | M36: Compte épargne-temps - Choix d'option | N36: Création Modification | O36: La date de l'opération saisie est non vide et le sens de l'opération est "Consommé" | P36: A_CET_DOOCET [Saisi] <> Vide ET A_CET_SEOCET [Saisi] = 'C' | Q36: Volontaire International | R36: P0178 | S36: N | T36: Particulier | U36: Exclu | V36: 45323
A37: 26.00.00 | B37: A | C37: 46175.679 | D37: D0007 | E37: Congés/Absence | F37: S0183 | G37: Compte épargne-temps | H37: E0971 | I37: Compte épargne-temps (CET) | J37: La date d'observation saisie du CET est non vide | K37: A_CET_DAGCET [Saisi] <> Vide | L37: T2358 | M37: Compte épargne-temps - Ouverture | N37: Création Modification | O37: La date d'ouverture saisie est non vide et la date de l'opération est vide | P37: A_CET_DCRCET [Saisi] <> VIDE ET A_CET_DOOCET [Saisi] = VIDE | Q37: Ouvrier de la défense auxiliaire non affilié ou temporaire non mensualisé | R37: P0182 | S37: O | T37: Particulier | U37: Exclu | V37: 45323 | BC37: 2026-45
A38: 26.00.00 | B38: A | C38: 46175.68 | D38: D0007 | E38: Congés/Absence | F38: S0183 | G38: Compte épargne-temps | H38: E0971 | I38: Compte épargne-temps (CET) | J38: La date d'observation saisie du CET est non vide | K38: A_CET_DAGCET [Saisi] <> Vide | L38: T2359 | M38: Compte épargne-temps - Alimentation | N38: Création Modification | O38: La date de l'opération saisie est non vide et le sens de l'opération est "Versé" | P38: A_CET_DOOCET [Saisi] <> Vide ET A_CET_SEOCET [Saisi] = 'V' | Q38: Ouvrier de la défense auxiliaire non affilié ou temporaire non mensualisé | R38: P0182 | S38: O | T38: Particulier | U38: Exclu | V38: 45323 | BC38: 2026-45
A39: 26.00.00 | B39: A | C39: 46175.681 | D39: D0007 | E39: Congés/Absence | F39: S0183 | G39: Compte épargne-temps | H39: E0971 | I39: Compte épargne-temps (CET) | J39: La date d'observation saisie du CET est non vide | K39: A_CET_DAGCET [Saisi] <> Vide | L39: T2360 | M39: Compte épargne-temps - Choix d'option | N39: Création Modification | O39: La date de l'opération saisie est non vide et le sens de l'opération est "Consommé" | P39: A_CET_DOOCET [Saisi] <> Vide ET A_CET_SEOCET [Saisi] = 'C' | Q39: Ouvrier de la défense auxiliaire non affilié ou temporaire non mensualisé | R39: P0182 | S39: O | T39: Particulier | U39: Exclu | V39: 45323 | BC39: 2026-45
A40: 24.10.00 | B40: A | C40: 45628.643 | D40: D0007 | E40: Congés/Absence | F40: S0183 | G40: Compte épargne-temps | H40: E0971 | I40: Compte épargne-temps (CET) | J40: La date d'observation saisie du CET est non vide | K40: A_CET_DAGCET [Saisi] <> Vide | L40: T2358 | M40: Compte épargne-temps - Ouverture | N40: Création Modification | O40: La date d'ouverture saisie est non vide et la date de l'opération est vide | P40: A_CET_DCRCET [Saisi] <> VIDE ET A_CET_DOOCET [Saisi] = VIDE | Q40: Personnel civil de coopération (assistant technique) | R40: P0214 | S40: N | T40: Particulier | U40: Exclu | V40: 45323
...

Sheet Axe 1 Enchaînement RG Impact
A1: Version | B1: Type de mise à jour | C1: Date de mise à jour | D1: Identifiant Domaine | E1: Libellé du Domaine | F1: Identifiant Sous-domaine | G1: Libellé du Sous-domaine | H1: Identifiant Evénement | I1: Libellé de l'évènement | J1: Libellé condition déclenchement Evènement | K1: Condition déclenchement Evènement | L1: Identifiant type d'évènement | M1: Libellé type d'évènement | N1: Type de mise à jour | O1: Libellé condition déclenchement Type Evènement | P1: Condition déclenchement Type Evènement | Q1: Libellé Population | R1: Codification Population | S1: Typologie de population | T1: Général / Particulier | U1: Passant / Exclu | V1: Date de début | W1: Date de fin | X1: Impacts | Y1: Identifiant Impacts 1 | Z1: Libellé Impacts 1 | AA1: Identifiant Impacts 2 | AB1: Libellé Impacts 2 | AC1: Identifiant Impacts 3 | AD1: Libellé Impacts 3 | AE1: FIME | AF1: Statut de travail
A2: 24.10.00 | B2: A | C2: 45628.64 | D2: D0007 | E2: Congés/Absence | F2: S0183 | G2: Compte épargne-temps | H2: E0971 | I2: Compte épargne-temps (CET) | J2: La date d'observation saisie du CET est non vide | K2: A_CET_DAGCET [Saisi] <> Vide | L2: T2358 | M2: Compte épargne-temps - Ouverture | N2: Création Modification | O2: La date d'ouverture saisie est non vide et la date de l'opération est vide | P2: A_CET_DCRCET [Saisi] <> VIDE ET A_CET_DOOCET [Saisi] = VIDE | Q2: Titulaire ou magistrat | R2: P0001 | S2: T | T2: Général | U2: Passant | V2: 45323 | X2: CET_P_001 ET CET_P_006 ET CET_P_007 | Y2: CET_P_001 | Z2: =VLOOKUP(Y2,'Axe 2 Règles de gestion'!$D$2:$F$61,3, FALSE) -> Rémunération : En cas d'indemnisation, le montant versé est un montant forfaitaire qui dépend de la catégorie statutaire d'appartenance de l'agent. | AA2: CET_P_006 | AB2: =VLOOKUP(AA2,'Axe 2 Règles de gestion'!$D$2:$F$61,3, FALSE) -> Stage : L'agent ne peut pas demander l'ouverture ou l'utilisation d'un compte épargne-temps durant la durée de son stage. | AC2: CET_P_007 | AD2: =VLOOKUP(AC2,'Axe 2 Règles de gestion'!$D$2:$F$61,3, FALSE) -> Congés annuels : L'agent conserve son droit à congé annuel.
