Workbook
Name date_DIADC: 'Mode opératoire'!#REF!
Name notice_DIADC: 'Mode opératoire'!#REF!
Name notice_ENCHN: 'Mode opératoire'!$B$1:$B$4
Name notice_ICA: 'Mode opératoire'!#REF!

Sheet Mode opératoire
B1: MODE OPERATOIRE
B2: La transaction s'effectue au niveau de la rubrique "Congés/absences", elle inclut l'ensemble des sous-rubriques listées ci-dessous : - Congés/absences - Complément pour congé / absence : impact rémunération - Compteurs de périodes de congés On notera que : La sous-rubrique "Complément pour congé / absence : impact rémunération" est réputée, suite au découpage des absences en tranche de rémunération, avoir des dates de début et de fin alignées sur les dates de début et de fin de la sous-rubrique "Congés/absences" (contrôle bloquant)

Sheet Axe 1 Enchainement des RG
A1: Version | B1: Type de mise à jour | C1: Date de mise à jour | D1: Identifiant Domaine | E1: Libellé du Domaine | F1: Identifiant Sous-domaine | G1: Libellé du Sous-domaine | H1: Identifiant Evénement | I1: Libellé de l'évènement | J1: Libellé condition déclenchement Evènement | K1: Condition déclenchement Evènement | L1: Identifiant type d'évènement | M1: Libellé type d'évènement | N1: Type de mise à jour | O1: Libellé condition déclenchement Type Evènement | P1: Condition déclenchement Type Evènement | Q1: Libellé Population | R1: Codification Population | S1: Typologie de population | T1: Général / Particulier | U1: Passant / Exclu | V1: Date de début | W1: Date de fin | X1: Règles mobilisées | Y1: Identifiant Règle de contrôle intellectuel 1 | Z1: Libellé Règle de contrôle intellectuel 1 | AA1: Identifiant Règle de contrôle intellectuel 2 | AB1: Libellé Règle de contrôle intellectuel 2 | AC1: Identifiant Règle de contrôle intellectuel 3 | AD1: Libellé Règle de contrôle intellectuel 3 | AE1: Identifiant Règle de contrôle intellectuel 4 | AF1: Libellé Règle de contrôle intellectuel 4 | AG1: Identifiant Règle de contrôle intellectuel 5 | AH1: Libellé Règle de contrôle intellectuel 5 | AI1: Identifiant Règle de contrôle intellectuel 6 | AJ1: Libellé Règle de contrôle intellectuel 6 | AK1: Identifiant Règle de contrôle intellectuel 7 | AL1: Libellé Règle de contrôle intellectuel 7 | AM1: Identifiant Règle de contrôle intellectuel 8 | AN1: Libellé Règle de contrôle intellectuel 8 | AO1: Identifiant Règle de contrôle intellectuel 9 | AP1: Libellé Règle de contrôle intellectuel 9 | AQ1: Identifiant Règle de contrôle intellectuel 10 | AR1: Libellé Règle de contrôle intellectuel 10 | AS1: Identifiant Règle de condition 1 | AT1: Libellé Règle de condition 1 | AU1: Identifiant Règle de condition 2 | AV1: Libellé Règle de condition 2 | AW1: Identifiant Règle de condition 3 | AX1: Libellé Règle de condition 3 | AY1: Identifiant Règle de contrôle 1 | AZ1: Libellé Règle de contrôle 1 | BA1: Identifiant Règle de contrôle 2 | BB1: Libellé Règle de contrôle 2 | BC1: Identifiant Règle de contrôle 3 | BD1: Libellé Règle de contrôle 3 | BE1: Identifiant Règle de contrôle 4 | BF1: Libellé Règle de contrôle 4 | BG1: Identifiant Règle de contrôle 5 | BH1: Libellé Règle de contrôle 5 | BI1: Identifiant Règle de contrôle 6 | BJ1: Libellé Règle de contrôle 6 | BK1: Identifiant Règle de contrôle 7 | BL1: Libellé Règle de contrôle 7 | BM1: Identifiant Règle de contrôle 8 | BN1: Libellé Règle de contrôle 8 | BO1: Identifiant Règle de contrôle 9 | BP1: Libellé Règle de contrôle 9 | BQ1: Identifiant Règle de contrôle 10 | BR1: Libellé Règle de contrôle 10 | BS1: FIME | BT1: Statut de travail
A2: 23.00.00 | B2: A | C2: 45084.43 | D2: D0007 | E2: Congés/Absence | F2: S0167 | G2: Congés annuels Jours ARTT | H2: E0933 | I2: Jours supplémentaires hors période (fractionnement) | J2: Type de congé/absence saisi est 'Jours supplémentaires hors période (fractionnement)' | K2: A_COA_TYCOAB [Saisi] = 'CV001' | L2: T2277 | M2: Jours supplémentaires hors période (fractionnement) | N2: Création Modification | Q2: Titulaire ou magistrat | R2: P0001 | S2: T | T2: Général | U2: Passant | V2: 44927 | X2: CFR_I_007 ET CFR_I_008 ET CFR_D_001 ET ABS_C_001 ET ABS_C_003 ET ABS_C_004 ET ABS_C_007 ET ABS_C_008 ET ABS_C_009 ET ABS_C_019 ET ABS_C_020 ET ABS_C_026 | Y2: CFR_I_007 | Z2: =VLOOKUP(Y2,'Axe 2 Règles de gestion'!$D$2:$F$146,3, FALSE) -> L'agent bénéficie d'1 jour de congé supplémentaire, dit « jour de fractionnement », lorsque le nombre de jours de congé annuel pris en dehors de la période du 1er mai au 31 octobre est de 5, 6 ou 7. | AA2: CFR_I_008 | AB2: =VLOOKUP(AA2,'Axe 2 Règles de gestion'!$D$2:$F$146,3, FALSE) -> L'agent bénéficie de 2 jours de congés supplémentaires, dit « jours de fractionnement », lorsque le nombre de jours de congé annuel pris en dehors de la période du 1er mai au 31 octobre est supérieur ou égal à 8. | AS2: CFR_D_001 | AT2: =VLOOKUP(AS2,'Axe 2 Règles de gestion'!$D$2:$F$146,3, FALSE) -> L'agent ne peut pas prendre plus de 2 jours de fractionnement par an. | AY2: ABS_C_001 | AZ2: =VLOOKUP(AY2,'Axe 2 Règles de gestion'!$D$2:$F$146,3, FALSE) -> La date de début du congé/absence doit être postérieure ou égale à la date de recrutement dans la FPE ou dans la carrière militaire. | BA2: ABS_C_003 | BB2: =VLOOKUP(BA2,'Axe 2 Règles de gestion'!$D$2:$F$146,3, FALSE) -> La date de début du congé/absence doit être antérieure ou égale à la date de fin réelle du congé/absence. | BC2: ABS_C_004 | BD2: =VLOOKUP(BC2,'Axe 2 Règles de gestion'!$D$2:$F$146,3, FALSE) -> La date de début du congé/absence doit être antérieure ou égale à la date de fin prévisionnelle du congé/absence. | BE2: ABS_C_007 | BF2: =VLOOKUP(BE2,'Axe 2 Règles de gestion'!$D$2:$F$146,3, FALSE) -> La date de fin réelle du congé/absence doit être antérieure à la date limite de départ à la retraite. | BG2: ABS_C_008 | BH2: =VLOOKUP(BG2,'Axe 2 Règles de gestion'!$D$2:$F$146,3, FALSE) -> La date de fin prévisionnelle du congé/absence doit être antérieure à la date limite de départ à la retraite. | BI2: ABS_C_009 | BJ2: =VLOOKUP(BI2,'Axe 2 Règles de gestion'!$D$2:$F$146,3, FALSE) -> La date de fin réelle ou la date de fin prévisionnelle du congé/absence doit être saisie. | BK2: ABS_C_019 | BL2: =VLOOKUP(BK2,'Axe 2 Règles de gestion'!$D$2:$F$146,3, FALSE) -> Si l'absence ne commence pas par une demi-journée et si l'absence précédente ne finit pas par une demi journée, la date de début de l'absence saisie est postérieure à la date de fin réelle de l'absence précédente. | BM2: ABS_C_020 | BN2: =VLOOKUP(BM2,'Axe 2 Règles de gestion'!$D$2:$F$146,3, FALSE) -> Si l'absence ne commence pas par une demi-journée et si l'absence précédente ne finit pas par une demi journée, la date de début de l'absence saisie est postérieure à la date de fin prévisionnelle de l'absence précédente. | BO2: ABS_C_026 | BP2: =VLOOKUP(BO2,'Axe 2 Règles de gestion'!$D$2:$F$146,3, FALSE) -> Dans le cas d'un congé autre que CLM, CLD, CGM et CITIS, l'indicateur de requalification doit être à non et les impacts spécifiques à la requalification ne doivent pas être mobilisés ou l'impact rémunération est vide.
A3: 24.10.00 | B3: A | C3: 45561.414 | D3: D0007 | E3: Congés/Absence | F3: S0167 | G3: Congés annuels Jours ARTT | H3: E0933 | I3: Jours supplémentaires hors période (fractionnement) | J3: Type de congé/absence saisi est 'Jours supplémentaires hors période (fractionnement)' | K3: A_COA_TYCOAB [Saisi] = 'CV001' | L3: T2277 | M3: Jours supplémentaires hors période (fractionnement) | N3: Création Modification | Q3: Militaire | R3: P0002 | S3: M | T3: Général | U3: Exclu | V3: 44927
A4: 23.00.00 | B4: A | C4: 45084.437 | D4: D0007 | E4: Congés/Absence | F4: S0167 | G4: Congés annuels Jours ARTT | H4: E0933 | I4: Jours supplémentaires hors période (fractionnement) | J4: Type de congé/absence saisi est 'Jours supplémentaires hors période (fractionnement)' | K4: A_COA_TYCOAB [Saisi] = 'CV001' | L4: T2277 | M4: Jours supplémentaires hors période (fractionnement) | N4: Création Modification | Q4: Contractuel | R4: P0003 | S4: N | T4: Général | U4: Passant | V4: 44927 | X4: CFR_I_001 ET CFR_I_007 ET CFR_I_008 ET CFR_D_001 ET ABS_C_002 ET ABS_C_003 ET ABS_C_004 ET ABS_C_005 ET ABS_C_006 ET ABS_C_009 ET ABS_C_019 ET ABS_C_020 ET ABS_C_026 | Y4: CFR_I_001 | Z4: =VLOOKUP(Y4,'Axe 2 Règles de gestion'!$D$2:$F$146,3, FALSE) -> L'agent bénéficie des dispositions applicables aux agents titulaires pour les jours de fractionnement. | AA4: CFR_I_007 | AB4: =VLOOKUP(AA4,'Axe 2 Règles de gestion'!$D$2:$F$146,3, FALSE) -> L'agent bénéficie d'1 jour de congé supplémentaire, dit « jour de fractionnement », lorsque le nombre de jours de congé annuel pris en dehors de la période du 1er mai au 31 octobre est de 5, 6 ou 7. | AC4: CFR_I_008 | AD4: =VLOOKUP(AC4,'Axe 2 Règles de gestion'!$D$2:$F$146,3, FALSE) -> L'agent bénéficie de 2 jours de congés supplémentaires, dit « jours de fractionnement », lorsque le nombre de jours de congé annuel pris en dehors de la période du 1er mai au 31 octobre est supérieur ou égal à 8. | AS4: CFR_D_001 | AT4: =VLOOKUP(AS4,'Axe 2 Règles de gestion'!$D$2:$F$146,3, FALSE) -> L'agent ne peut pas prendre plus de 2 jours de fractionnement par an. | AY4: ABS_C_002 | AZ4: =VLOOKUP(AY4,'Axe 2 Règles de gestion'!$D$2:$F$146,3, FALSE) -> La date de début du congé/absence doit être postérieure ou égale à la date de début du lien juridique. | BA4: ABS_C_003 | BB4: =VLOOKUP(BA4,'Axe 2 Règles de gestion'!$D$2:$F$146,3, FALSE) -> La date de début du congé/absence doit être antérieure ou égale à la date de fin réelle du congé/absence. | BC4: ABS_C_004 | BD4: =VLOOKUP(BC4,'Axe 2 Règles de gestion'!$D$2:$F$146,3, FALSE) -> La date de début du congé/absence doit être antérieure ou égale à la date de fin prévisionnelle du congé/absence. | BE4: ABS_C_005 | BF4: =VLOOKUP(BE4,'Axe 2 Règles de gestion'!$D$2:$F$146,3, FALSE) -> La date de fin réelle du congé/absence doit être antérieure ou égale à la date limite de fin réelle ou prévisionnelle du lien juridique. | BG4: ABS_C_006 | BH4: =VLOOKUP(BG4,'Axe 2 Règles de gestion'!$D$2:$F$146,3, FALSE) -> La date de fin prévisionnelle du congé/absence doit être antérieure ou égale à la date limite de fin réelle ou prévisionnelle du lien juridique. | BI4: ABS_C_009 | BJ4: =VLOOKUP(BI4,'Axe 2 Règles de gestion'!$D$2:$F$146,3, FALSE) -> La date de fin réelle ou la date de fin prévisionnelle du congé/absence doit être saisie. | BK4: ABS_C_019 | BL4: =VLOOKUP(BK4,'Axe 2 Règles de gestion'!$D$2:$F$146,3, FALSE) -> Si l'absence ne commence pas par une demi-journée et si l'absence précédente ne finit pas par une demi journée, la date de début de l'absence saisie est postérieure à la date de fin réelle de l'absence précédente. | BM4: ABS_C_020 | BN4: =VLOOKUP(BM4,'Axe 2 Règles de gestion'!$D$2:$F$146,3, FALSE) -> Si l'absence ne commence pas par une demi-journée et si l'absence précédente ne finit pas par une demi journée, la date de début de l'absence saisie est postérieure à la date de fin prévisionnelle de l'absence précédente. | BO4: ABS_C_026 | BP4: =VLOOKUP(BO4,'Axe 2 Règles de gestion'!$D$2:$F$146,3, FALSE) -> Dans le cas d'un congé autre que CLM, CLD, CGM et CITIS, l'indicateur de requalification doit être à non et les impacts spécifiques à la requalification ne doivent pas être mobilisés ou l'impact rémunération est vide.
A5: 23.00.00 | B5: A | C5: 45084.438 | D5: D0007 | E5: Congés/Absence | F5: S0167 | G5: Congés annuels Jours ARTT | H5: E0933 | I5: Jours supplémentaires hors période (fractionnement) | J5: Type de congé/absence saisi est 'Jours supplémentaires hors période (fractionnement)' | K5: A_COA_TYCOAB [Saisi] = 'CV001' | L5: T2277 | M5: Jours supplémentaires hors période (fractionnement) | N5: Création Modification | Q5: Stagiaire ou auditeur ou élève | R5: P0004 | S5: S | T5: Général | U5: Passant | V5: 44927 | X5: CFR_I_002 ET CFR_I_007 ET CFR_I_008 ET CFR_D_001 ET ABS_C_001 ET ABS_C_003 ET ABS_C_004 ET ABS_C_007 ET ABS_C_008 ET ABS_C_009 ET ABS_C_019 ET ABS_C_020 ET ABS_C_026 | Y5: CFR_I_002 | Z5: =VLOOKUP(Y5,'Axe 2 Règles de gestion'!$D$2:$F$146,3, FALSE) -> L'agent bénéficie des dispositions applicables aux agents titulaires pour les jours de fractionnement. | AA5: CFR_I_007 | AB5: =VLOOKUP(AA5,'Axe 2 Règles de gestion'!$D$2:$F$146,3, FALSE) -> L'agent bénéficie d'1 jour de congé supplémentaire, dit « jour de fractionnement », lorsque le nombre de jours de congé annuel pris en dehors de la période du 1er mai au 31 octobre est de 5, 6 ou 7. | AC5: CFR_I_008 | AD5: =VLOOKUP(AC5,'Axe 2 Règles de gestion'!$D$2:$F$146,3, FALSE) -> L'agent bénéficie de 2 jours de congés supplémentaires, dit « jours de fractionnement », lorsque le nombre de jours de congé annuel pris en dehors de la période du 1er mai au 31 octobre est supérieur ou égal à 8. | AS5: CFR_D_001 | AT5: =VLOOKUP(AS5,'Axe 2 Règles de gestion'!$D$2:$F$146,3, FALSE) -> L'agent ne peut pas prendre plus de 2 jours de fractionnement par an. | AY5: ABS_C_001 | AZ5: =VLOOKUP(AY5,'Axe 2 Règles de gestion'!$D$2:$F$146,3, FALSE) -> La date de début du congé/absence doit être postérieure ou égale à la date de recrutement dans la FPE ou dans la carrière militaire. | BA5: ABS_C_003 | BB5: =VLOOKUP(BA5,'Axe 2 Règles de gestion'!$D$2:$F$146,3, FALSE) -> La date de début du congé/absence doit être antérieure ou égale à la date de fin réelle du congé/absence. | BC5: ABS_C_004 | BD5: =VLOOKUP(BC5,'Axe 2 Règles de gestion'!$D$2:$F$146,3, FALSE) -> La date de début du congé/absence doit être antérieure ou égale à la date de fin prévisionnelle du congé/absence. | BE5: ABS_C_007 | BF5: =VLOOKUP(BE5,'Axe 2 Règles de gestion'!$D$2:$F$146,3, FALSE) -> La date de fin réelle du congé/absence doit être antérieure à la date limite de départ à la retraite. | BG5: ABS_C_008 | BH5: =VLOOKUP(BG5,'Axe 2 Règles de gestion'!$D$2:$F$146,3, FALSE) -> La date de fin prévisionnelle du congé/absence doit être antérieure à la date limite de départ à la retraite. | BI5: ABS_C_009 | BJ5: =VLOOKUP(BI5,'Axe 2 Règles de gestion'!$D$2:$F$146,3, FALSE) -> La date de fin réelle ou la date de fin prévisionnelle du congé/absence doit être saisie. | BK5: ABS_C_019 | BL5: =VLOOKUP(BK5,'Axe 2 Règles de gestion'!$D$2:$F$146,3, FALSE) -> Si l'absence ne commence pas par une demi-journée et si l'absence précédente ne finit pas par une demi journée, la date de début de l'absence saisie est postérieure à la date de fin réelle de l'absence précédente. | BM5: ABS_C_020 | BN5: =VLOOKUP(BM5,'Axe 2 Règles de gestion'!$D$2:$F$146,3, FALSE) -> Si l'absence ne commence pas par une demi-journée et si l'absence précédente ne finit pas par une demi journée, la date de début de l'absence saisie est postérieure à la date de fin prévisionnelle de l'absence précédente. | BO5: ABS_C_026 | BP5: =VLOOKUP(BO5,'Axe 2 Règles de gestion'!$D$2:$F$146,3, FALSE) -> Dans le cas d'un congé autre que CLM, CLD, CGM et CITIS, l'indicateur de requalification doit être à non et les impacts spécifiques à la requalification ne doivent pas être mobilisés ou l'impact rémunération est vide.
A6: 23.00.00 | B6: A | C6: 45084.438 | D6: D0007 | E6: Congés/Absence | F6: S0167 | G6: Congés annuels Jours ARTT | H6: E0933 | I6: Jours supplémentaires hors période (fractionnement) | J6: Type de congé/absence saisi est 'Jours supplémentaires hors période (fractionnement)' | K6: A_COA_TYCOAB [Saisi] = 'CV001' | L6: T2277 | M6: Jours supplémentaires hors période (fractionnement) | N6: Création Modification | Q6: Ouvrier d'état | R6: P0005 | S6: O | T6: Général | U6: Passant | V6: 44927 | X6: ABS_C_002 ET ABS_C_003 ET ABS_C_004 ET ABS_C_005 ET ABS_C_006 ET ABS_C_009 ET ABS_C_019 ET ABS_C_020 ET ABS_C_026 | AY6: ABS_C_002 | AZ6: =VLOOKUP(AY6,'Axe 2 Règles de gestion'!$D$2:$F$146,3, FALSE) -> La date de début du congé/absence doit être postérieure ou égale à la date de début du lien juridique. | BA6: ABS_C_003 | BB6: =VLOOKUP(BA6,'Axe 2 Règles de gestion'!$D$2:$F$146,3, FALSE) -> La date de début du congé/absence doit être antérieure ou égale à la date de fin réelle du congé/absence. | BC6: ABS_C_004 | BD6: =VLOOKUP(BC6,'Axe 2 Règles de gestion'!$D$2:$F$146,3, FALSE) -> La date de début du congé/absence doit être antérieure ou égale à la date de fin prévisionnelle du congé/absence. | BE6: ABS_C_005 | BF6: =VLOOKUP(BE6,'Axe 2 Règles de gestion'!$D$2:$F$146,3, FALSE) -> La date de fin réelle du congé/absence doit être antérieure ou égale à la date limite de fin réelle ou prévisionnelle du lien juridique. | BG6: ABS_C_006 | BH6: =VLOOKUP(BG6,'Axe 2 Règles de gestion'!$D$2:$F$146,3, FALSE) -> La date de fin prévisionnelle du congé/absence doit être antérieure ou égale à la date limite de fin réelle ou prévisionnelle du lien juridique. | BI6: ABS_C_009 | BJ6: =VLOOKUP(BI6,'Axe 2 Règles de gestion'!$D$2:$F$146,3, FALSE) -> La date de fin réelle ou la date de fin prévisionnelle du congé/absence doit être saisie. | BK6: ABS_C_019 | BL6: =VLOOKUP(BK6,'Axe 2 Règles de gestion'!$D$2:$F$146,3, FALSE) -> Si l'absence ne commence pas par une demi-journée et si l'absence précédente ne finit pas par une demi journée, la date de début de l'absence saisie est postérieure à la date de fin réelle de l'absence précédente. | BM6: ABS_C_020 | BN6: =VLOOKUP(BM6,'Axe 2 Règles de gestion'!$D$2:$F$146,3, FALSE) -> Si l'absence ne commence pas par une demi-journée et si l'absence précédente ne finit pas par une demi journée, la date de début de l'absence saisie est postérieure à la date de fin prévisionnelle de l'absence précédente. | BO6: ABS_C_026 | BP6: =VLOOKUP(BO6,'Axe 2 Règles de gestion'!$D$2:$F$146,3, FALSE) -> Dans le cas d'un congé autre que CLM, CLD, CGM et CITIS, l'indicateur de requalification doit être à non et les impacts spécifiques à la requalification ne doivent pas être mobilisés ou l'impact rémunération est vide.
A7: 23.00.00 | B7: A | C7: 45084.441 | D7: D0007 | E7: Congés/Absence | F7: S0167 | G7: Congés annuels Jours ARTT | H7: E0933 | I7: Jours supplémentaires hors période (fractionnement) | J7: Type de congé/absence saisi est 'Jours supplémentaires hors période (fractionnement)' | K7: A_COA_TYCOAB [Saisi] = 'CV001' | L7: T2277 | M7: Jours supplémentaires hors période (fractionnement) | N7: Création Modification | Q7: Magistrat de l'ordre judiciaire | R7: P0007 | S7: T | T7: Particulier | U7: Passant | V7: 44927 | X7: CFR_I_005 ET CFR_I_007 ET CFR_I_008 ET CFR_D_001 ET ABS_C_001 ET ABS_C_003 ET ABS_C_004 ET ABS_C_007 ET ABS_C_008 ET ABS_C_009 ET ABS_C_019 ET ABS_C_020 ET ABS_C_026 | Y7: CFR_I_005 | Z7: =VLOOKUP(Y7,'Axe 2 Règles de gestion'!$D$2:$F$146,3, FALSE) -> L'agent bénéficie des dispositions applicables aux agents titulaires pour les jours de fractionnement. | AA7: CFR_I_007 | AB7: =VLOOKUP(AA7,'Axe 2 Règles de gestion'!$D$2:$F$146,3, FALSE) -> L'agent bénéficie d'1 jour de congé supplémentaire, dit « jour de fractionnement », lorsque le nombre de jours de congé annuel pris en dehors de la période du 1er mai au 31 octobre est de 5, 6 ou 7. | AC7: CFR_I_008 | AD7: =VLOOKUP(AC7,'Axe 2 Règles de gestion'!$D$2:$F$146,3, FALSE) -> L'agent bénéficie de 2 jours de congés supplémentaires, dit « jours de fractionnement », lorsque le nombre de jours de congé annuel pris en dehors de la période du 1er mai au 31 octobre est supérieur ou égal à 8. | AS7: CFR_D_001 | AT7: =VLOOKUP(AS7,'Axe 2 Règles de gestion'!$D$2:$F$146,3, FALSE) -> L'agent ne peut pas prendre plus de 2 jours de fractionnement par an. | AY7: ABS_C_001 | AZ7: =VLOOKUP(AY7,'Axe 2 Règles de gestion'!$D$2:$F$146,3, FALSE) -> La date de début du congé/absence doit être postérieure ou égale à la date de recrutement dans la FPE ou dans la carrière militaire. | BA7: ABS_C_003 | BB7: =VLOOKUP(BA7,'Axe 2 Règles de gestion'!$D$2:$F$146,3, FALSE) -> La date de début du congé/absence doit être antérieure ou égale à la date de fin réelle du congé/absence. | BC7: ABS_C_004 | BD7: =VLOOKUP(BC7,'Axe 2 Règles de gestion'!$D$2:$F$146,3, FALSE) -> La date de début du congé/absence doit être antérieure ou égale à la date de fin prévisionnelle du congé/absence. | BE7: ABS_C_007 | BF7: =VLOOKUP(BE7,'Axe 2 Règles de gestion'!$D$2:$F$146,3, FALSE) -> La date de fin réelle du congé/absence doit être antérieure à la date limite de départ à la retraite. | BG7: ABS_C_008 | BH7: =VLOOKUP(BG7,'Axe 2 Règles de gestion'!$D$2:$F$146,3, FALSE) -> La date de fin prévisionnelle du congé/absence doit être antérieure à la date limite de départ à la retraite. | BI7: ABS_C_009 | BJ7: =VLOOKUP(BI7,'Axe 2 Règles de gestion'!$D$2:$F$146,3, FALSE) -> La date de fin réelle ou la date de fin prévisionnelle du congé/absence doit être saisie. | BK7: ABS_C_019 | BL7: =VLOOKUP(BK7,'Axe 2 Règles de gestion'!$D$2:$F$146,3, FALSE) -> Si l'absence ne commence pas par une demi-journée et si l'absence précédente ne finit pas par une demi journée, la date de début de l'absence saisie est postérieure à la date de fin réelle de l'absence précédente. | BM7: ABS_C_020 | BN7: =VLOOKUP(BM7,'Axe 2 Règles de gestion'!$D$2:$F$146,3, FALSE) -> Si l'absence ne commence pas par une demi-journée et si l'absence précédente ne finit pas par une demi journée, la date de début de l'absence saisie est postérieure à la date de fin prévisionnelle de l'absence précédente. | BO7: ABS_C_026 | BP7: =VLOOKUP(BO7,'Axe 2 Règles de gestion'!$D$2:$F$146,3, FALSE) -> Dans le cas d'un congé autre que CLM, CLD, CGM et CITIS, l'indicateur de requalification doit être à non et les impacts spécifiques à la requalification ne doivent pas être mobilisés ou l'impact rémunération est vide.
A8: 23.00.00 | B8: A | C8: 45084.441 | D8: D0007 | E8: Congés/Absence | F8: S0167 | G8: Congés annuels Jours ARTT | H8: E0933 | I8: Jours supplémentaires hors période (fractionnement) | J8: Type de congé/absence saisi est 'Jours supplémentaires hors période (fractionnement)' | K8: A_COA_TYCOAB [Saisi] = 'CV001' | L8: T2277 | M8: Jours supplémentaires hors période (fractionnement) | N8: Création Modification | Q8: Auditeur de justice | R8: P0009 | S8: S | T8: Particulier | U8: Passant | V8: 44927 | X8: CFR_I_006 ET CFR_I_007 ET CFR_I_008 ET CFR_D_001 ET ABS_C_001 ET ABS_C_003 ET ABS_C_004 ET ABS_C_007 ET ABS_C_008 ET ABS_C_009 ET ABS_C_019 ET ABS_C_020 ET ABS_C_026 | Y8: CFR_I_006 | Z8: =VLOOKUP(Y8,'Axe 2 Règles de gestion'!$D$2:$F$146,3, FALSE) -> L'agent bénéficie des dispositions applicables aux agents titulaires pour les jours de fractionnement. | AA8: CFR_I_007 | AB8: =VLOOKUP(AA8,'Axe 2 Règles de gestion'!$D$2:$F$146,3, FALSE) -> L'agent bénéficie d'1 jour de congé supplémentaire, dit « jour de fractionnement », lorsque le nombre de jours de congé annuel pris en dehors de la période du 1er mai au 31 octobre est de 5, 6 ou 7. | AC8: CFR_I_008 | AD8: =VLOOKUP(AC8,'Axe 2 Règles de gestion'!$D$2:$F$146,3, FALSE) -> L'agent bénéficie de 2 jours de congés supplémentaires, dit « jours de fractionnement », lorsque le nombre de jours de congé annuel pris en dehors de la période du 1er mai au 31 octobre est supérieur ou égal à 8. | AS8: CFR_D_001 | AT8: =VLOOKUP(AS8,'Axe 2 Règles de gestion'!$D$2:$F$146,3, FALSE) -> L'agent ne peut pas prendre plus de 2 jours de fractionnement par an. | AY8: ABS_C_001 | AZ8: =VLOOKUP(AY8,'Axe 2 Règles de gestion'!$D$2:$F$146,3, FALSE) -> La date de début du congé/absence doit être postérieure ou égale à la date de recrutement dans la FPE ou dans la carrière militaire. | BA8: ABS_C_003 | BB8: =VLOOKUP(BA8,'Axe 2 Règles de gestion'!$D$2:$F$146,3, FALSE) -> La date de début du congé/absence doit être antérieure ou égale à la date de fin réelle du congé/absence. | BC8: ABS_C_004 | BD8: =VLOOKUP(BC8,'Axe 2 Règles de gestion'!$D$2:$F$146,3, FALSE) -> La date de début du congé/absence doit être antérieure ou égale à la date de fin prévisionnelle du congé/absence. | BE8: ABS_C_007 | BF8: =VLOOKUP(BE8,'Axe 2 Règles de gestion'!$D$2:$F$146,3, FALSE) -> La date de fin réelle du congé/absence doit être antérieure à la date limite de départ à la retraite. | BG8: ABS_C_008 | BH8: =VLOOKUP(BG8,'Axe 2 Règles de gestion'!$D$2:$F$146,3, FALSE) -> La date de fin prévisionnelle du congé/absence doit être antérieure à la date limite de départ à la retraite. | BI8: ABS_C_009 | BJ8: =VLOOKUP(BI8,'Axe 2 Règles de gestion'!$D$2:$F$146,3, FALSE) -> La date de fin réelle ou la date de fin prévisionnelle du congé/absence doit être saisie. | BK8: ABS_C_019 | BL8: =VLOOKUP(BK8,'Axe 2 Règles de gestion'!$D$2:$F$146,3, FALSE) -> Si l'absence ne commence pas par une demi-journée et si l'absence précédente ne finit pas par une demi journée, la date de début de l'absence saisie est postérieure à la date de fin réelle de l'absence précédente. | BM8: ABS_C_020 | BN8: =VLOOKUP(BM8,'Axe 2 Règles de gestion'!$D$2:$F$146,3, FALSE) -> Si l'absence ne commence pas par une demi-journée et si l'absence précédente ne finit pas par une demi journée, la date de début de l'absence saisie est postérieure à la date de fin prévisionnelle de l'absence précédente. | BO8: ABS_C_026 | BP8: =VLOOKUP(BO8,'Axe 2 Règles de gestion'!$D$2:$F$146,3, FALSE) -> Dans le cas d'un congé autre que CLM, CLD, CGM et CITIS, l'indicateur de requalification doit être à non et les impacts spécifiques à la requalification ne doivent pas être mobilisés ou l'impact rémunération est vide.
A9: 23.00.00 | B9: A | C9: 45084.438 | D9: D0007 | E9: Congés/Absence | F9: S0167 | G9: Congés annuels Jours ARTT | H9: E0933 | I9: Jours supplémentaires hors période (fractionnement) | J9: Type de congé/absence saisi est 'Jours supplémentaires hors période (fractionnement)' | K9: A_COA_TYCOAB [Saisi] = 'CV001' | L9: T2277 | M9: Jours supplémentaires hors période (fractionnement) | N9: Création Modification | Q9: Expert technique international | R9: P0018 | S9: N | T9: Particulier | U9: Exclu | V9: 44927
A10: 23.00.00 | B10: A | C10: 45084.44 | D10: D0007 | E10: Congés/Absence | F10: S0167 | G10: Congés annuels Jours ARTT | H10: E0933 | I10: Jours supplémentaires hors période (fractionnement) | J10: Type de congé/absence saisi est 'Jours supplémentaires hors période (fractionnement)' | K10: A_COA_TYCOAB [Saisi] = 'CV001' | L10: T2277 | M10: Jours supplémentaires hors période (fractionnement) | N10: Création Modification | Q10: Contractuel de droit local | R10: P0053 | S10: N | T10: Particulier | U10: Exclu | V10: 44927
A11: 23.00.00 | B11: A | C11: 45084.438 | D11: D0007 | E11: Congés/Absence | F11: S0167 | G11: Congés annuels Jours ARTT | H11: E0933 | I11: Jours supplémentaires hors période (fractionnement) | J11: Type de congé/absence saisi est 'Jours supplémentaires hors période (fractionnement)' | K11: A_COA_TYCOAB [Saisi] = 'CV001' | L11: T2277 | M11: Jours supplémentaires hors période (fractionnement) | N11: Création Modification | Q11: Personnel civil payé à l'acte ou à la tâche | R11: P0054 | S11: N | T11: Particulier | U11: Exclu | V11: 44927
A12: 23.00.00 | B12: A | C12: 45084.44 | D12: D0007 | E12: Congés/Absence | F12: S0167 | G12: Congés annuels Jours ARTT | H12: E0933 | I12: Jours supplémentaires hors période (fractionnement) | J12: Type de congé/absence saisi est 'Jours supplémentaires hors période (fractionnement)' | K12: A_COA_TYCOAB [Saisi] = 'CV001' | L12: T2277 | M12: Jours supplémentaires hors période (fractionnement) | N12: Création Modification | Q12: Contractuel de droit privé | R12: P0072 | S12: N | T12: Particulier | U12: Passant | V12: 44927 | X12: CFR_I_009 ET CFR_I_010 ET CFR_D_002 ET ABS_C_002 ET ABS_C_003 ET ABS_C_004 ET ABS_C_005 ET ABS_C_006 ET ABS_C_009 ET ABS_C_019 ET ABS_C_020 ET ABS_C_026 | Y12: CFR_I_009 | Z12: =VLOOKUP(Y12,'Axe 2 Règles de gestion'!$D$2:$F$146,3, FALSE) -> L'agent bénéficie d'1 jour de congé supplémentaire, dit « jour de fractionnement », lorsqu'il prend entre 3 et 5 jours de congés payés en dehors de la période du 1er mai au 31 octobre. | AA12: CFR_I_010 | AB12: =VLOOKUP(AA12,'Axe 2 Règles de gestion'!$D$2:$F$146,3, FALSE) -> L'agent bénéficie de 2 jours de congé supplémentaire, dit « jours de fractionnement », lorsqu'il prend 6 jours de congés payés ou plus en dehors de la période du 1er mai au 31 octobre. | AS12: CFR_D_002 | AT12: =VLOOKUP(AS12,'Axe 2 Règles de gestion'!$D$2:$F$146,3, FALSE) -> L'agent ne peut pas prendre plus de 2 jours de fractionnement par an. | AY12: ABS_C_002 | AZ12: =VLOOKUP(AY12,'Axe 2 Règles de gestion'!$D$2:$F$146,3, FALSE) -> La date de début du congé/absence doit être postérieure ou égale à la date de début du lien juridique. | BA12: ABS_C_003 | BB12: =VLOOKUP(BA12,'Axe 2 Règles de gestion'!$D$2:$F$146,3, FALSE) -> La date de début du congé/absence doit être antérieure ou égale à la date de fin réelle du congé/absence. | BC12: ABS_C_004 | BD12: =VLOOKUP(BC12,'Axe 2 Règles de gestion'!$D$2:$F$146,3, FALSE) -> La date de début du congé/absence doit être antérieure ou égale à la date de fin prévisionnelle du congé/absence. | BE12: ABS_C_005 | BF12: =VLOOKUP(BE12,'Axe 2 Règles de gestion'!$D$2:$F$146,3, FALSE) -> La date de fin réelle du congé/absence doit être antérieure ou égale à la date limite de fin réelle ou prévisionnelle du lien juridique. | BG12: ABS_C_006 | BH12: =VLOOKUP(BG12,'Axe 2 Règles de gestion'!$D$2:$F$146,3, FALSE) -> La date de fin prévisionnelle du congé/absence doit être antérieure ou égale à la date limite de fin réelle ou prévisionnelle du lien juridique. | BI12: ABS_C_009 | BJ12: =VLOOKUP(BI12,'Axe 2 Règles de gestion'!$D$2:$F$146,3, FALSE) -> La date de fin réelle ou la date de fin prévisionnelle du congé/absence doit être saisie. | BK12: ABS_C_019 | BL12: =VLOOKUP(BK12,'Axe 2 Règles de gestion'!$D$2:$F$146,3, FALSE) -> Si l'absence ne commence pas par une demi-journée et si l'absence précédente ne finit pas par une demi journée, la date de début de l'absence saisie est postérieure à la date de fin réelle de l'absence précédente. | BM12: ABS_C_020 | BN12: =VLOOKUP(BM12,'Axe 2 Règles de gestion'!$D$2:$F$146,3, FALSE) -> Si l'absence ne commence pas par une demi-journée et si l'absence précédente ne finit pas par une demi journée, la date de début de l'absence saisie est postérieure à la date de fin prévisionnelle de l'absence précédente. | BO12: ABS_C_026 | BP12: =VLOOKUP(BO12,'Axe 2 Règles de gestion'!$D$2:$F$146,3, FALSE) -> Dans le cas d'un congé autre que CLM, CLD, CGM et CITIS, l'indicateur de requalification doit être à non et les impacts spécifiques à la requalification ne doivent pas être mobilisés ou l'impact rémunération est vide.
A13: 23.00.00 | B13: A | C13: 45084.438 | D13: D0007 | E13: Congés/Absence | F13: S0167 | G13: Congés annuels Jours ARTT | H13: E0933 | I13: Jours supplémentaires hors période (fractionnement) | J13: Type de congé/absence saisi est 'Jours supplémentaires hors période (fractionnement)' | K13: A_COA_TYCOAB [Saisi] = 'CV001' | L13: T2277 | M13: Jours supplémentaires hors période (fractionnement) | N13: Création Modification | Q13: Volontaire international ou de service civique outre-mer | R13: P0073 | S13: N | T13: Particulier | U13: Exclu | V13: 44927
A14: 23.00.00 | B14: A | C14: 45084.44 | D14: D0007 | E14: Congés/Absence | F14: S0167 | G14: Congés annuels Jours ARTT | H14: E0933 | I14: Jours supplémentaires hors période (fractionnement) | J14: Type de congé/absence saisi est 'Jours supplémentaires hors période (fractionnement)' | K14: A_COA_TYCOAB [Saisi] = 'CV001' | L14: T2277 | M14: Jours supplémentaires hors période (fractionnement) | N14: Création Modification | Q14: Enseignant contractuel de l'enseignement agricole privé sous contrat non définitif - Agriculture | R14: P0078 | S14: N | T14: Particulier | U14: Passant | V14: 44927 | X14: CFR_I_003 ET CFR_I_007 ET CFR_I_008 ET CFR_D_001 ET ABS_C_002 ET ABS_C_003 ET ABS_C_004 ET ABS_C_005 ET ABS_C_006 ET ABS_C_009 ET ABS_C_019 ET ABS_C_020 ET ABS_C_026 | Y14: CFR_I_003 | Z14: =VLOOKUP(Y14,'Axe 2 Règles de gestion'!$D$2:$F$146,3, FALSE) -> L'agent bénéficie des dispositions applicables aux agents titulaires pour les jours de fractionnement. | AA14: CFR_I_007 | AB14: =VLOOKUP(AA14,'Axe 2 Règles de gestion'!$D$2:$F$146,3, FALSE) -> L'agent bénéficie d'1 jour de congé supplémentaire, dit « jour de fractionnement », lorsque le nombre de jours de congé annuel pris en dehors de la période du 1er mai au 31 octobre est de 5, 6 ou 7. | AC14: CFR_I_008 | AD14: =VLOOKUP(AC14,'Axe 2 Règles de gestion'!$D$2:$F$146,3, FALSE) -> L'agent bénéficie de 2 jours de congés supplémentaires, dit « jours de fractionnement », lorsque le nombre de jours de congé annuel pris en dehors de la période du 1er mai au 31 octobre est supérieur ou égal à 8. | AS14: CFR_D_001 | AT14: =VLOOKUP(AS14,'Axe 2 Règles de gestion'!$D$2:$F$146,3, FALSE) -> L'agent ne peut pas prendre plus de 2 jours de fractionnement par an. | AY14: ABS_C_002 | AZ14: =VLOOKUP(AY14,'Axe 2 Règles de gestion'!$D$2:$F$146,3, FALSE) -> La date de début du congé/absence doit être postérieure ou égale à la date de début du lien juridique. | BA14: ABS_C_003 | BB14: =VLOOKUP(BA14,'Axe 2 Règles de gestion'!$D$2:$F$146,3, FALSE) -> La date de début du congé/absence doit être antérieure ou égale à la date de fin réelle du congé/absence. | BC14: ABS_C_004 | BD14: =VLOOKUP(BC14,'Axe 2 Règles de gestion'!$D$2:$F$146,3, FALSE) -> La date de début du congé/absence doit être antérieure ou égale à la date de fin prévisionnelle du congé/absence. | BE14: ABS_C_005 | BF14: =VLOOKUP(BE14,'Axe 2 Règles de gestion'!$D$2:$F$146,3, FALSE) -> La date de fin réelle du congé/absence doit être antérieure ou égale à la date limite de fin réelle ou prévisionnelle du lien juridique. | BG14: ABS_C_006 | BH14: =VLOOKUP(BG14,'Axe 2 Règles de gestion'!$D$2:$F$146,3, FALSE) -> La date de fin prévisionnelle du congé/absence doit être antérieure ou égale à la date limite de fin réelle ou prévisionnelle du lien juridique. | BI14: ABS_C_009 | BJ14: =VLOOKUP(BI14,'Axe 2 Règles de gestion'!$D$2:$F$146,3, FALSE) -> La date de fin réelle ou la date de fin prévisionnelle du congé/absence doit être saisie. | BK14: ABS_C_019 | BL14: =VLOOKUP(BK14,'Axe 2 Règles de gestion'!$D$2:$F$146,3, FALSE) -> Si l'absence ne commence pas par une demi-journée et si l'absence précédente ne finit pas par une demi journée, la date de début de l'absence saisie est postérieure à la date de fin réelle de l'absence précédente. | BM14: ABS_C_020 | BN14: =VLOOKUP(BM14,'Axe 2 Règles de gestion'!$D$2:$F$146,3, FALSE) -> Si l'absence ne commence pas par une demi-journée et si l'absence précédente ne finit pas par une demi journée, la date de début de l'absence saisie est postérieure à la date de fin prévisionnelle de l'absence précédente. | BO14: ABS_C_026 | BP14: =VLOOKUP(BO14,'Axe 2 Règles de gestion'!$D$2:$F$146,3, FALSE) -> Dans le cas d'un congé autre que CLM, CLD, CGM et CITIS, l'indicateur de requalification doit être à non et les impacts spécifiques à la requalification ne doivent pas être mobilisés ou l'impact rémunération est vide.
A15: 23.00.00 | B15: A | C15: 45084.44 | D15: D0007 | E15: Congés/Absence | F15: S0167 | G15: Congés annuels Jours ARTT | H15: E0933 | I15: Jours supplémentaires hors période (fractionnement) | J15: Type de congé/absence saisi est 'Jours supplémentaires hors période (fractionnement)' | K15: A_COA_TYCOAB [Saisi] = 'CV001' | L15: T2277 | M15: Jours supplémentaires hors période (fractionnement) | N15: Création Modification | Q15: Enseignant contractuel de l'enseignement agricole privé sous contrat définitif - Agriculture | R15: P0079 | S15: N | T15: Particulier | U15: Passant | V15: 44927 | X15: CFR_I_004 ET CFR_I_007 ET CFR_I_008 ET CFR_D_001 ET ABS_C_002 ET ABS_C_003 ET ABS_C_004 ET ABS_C_005 ET ABS_C_006 ET ABS_C_009 ET ABS_C_019 ET ABS_C_020 ET ABS_C_026 | Y15: CFR_I_004 | Z15: =VLOOKUP(Y15,'Axe 2 Règles de gestion'!$D$2:$F$146,3, FALSE) -> L'agent bénéficie des dispositions applicables aux agents titulaires pour les jours de fractionnement. | AA15: CFR_I_007 | AB15: =VLOOKUP(AA15,'Axe 2 Règles de gestion'!$D$2:$F$146,3, FALSE) -> L'agent bénéficie d'1 jour de congé supplémentaire, dit « jour de fractionnement », lorsque le nombre de jours de congé annuel pris en dehors de la période du 1er mai au 31 octobre est de 5, 6 ou 7. | AC15: CFR_I_008 | AD15: =VLOOKUP(AC15,'Axe 2 Règles de gestion'!$D$2:$F$146,3, FALSE) -> L'agent bénéficie de 2 jours de congés supplémentaires, dit « jours de fractionnement », lorsque le nombre de jours de congé annuel pris en dehors de la période du 1er mai au 31 octobre est supérieur ou égal à 8. | AS15: CFR_D_001 | AT15: =VLOOKUP(AS15,'Axe 2 Règles de gestion'!$D$2:$F$146,3, FALSE) -> L'agent ne peut pas prendre plus de 2 jours de fractionnement par an. | AY15: ABS_C_002 | AZ15: =VLOOKUP(AY15,'Axe 2 Règles de gestion'!$D$2:$F$146,3, FALSE) -> La date de début du congé/absence doit être postérieure ou égale à la date de début du lien juridique. | BA15: ABS_C_003 | BB15: =VLOOKUP(BA15,'Axe 2 Règles de gestion'!$D$2:$F$146,3, FALSE) -> La date de début du congé/absence doit être antérieure ou égale à la date de fin réelle du congé/absence. | BC15: ABS_C_004 | BD15: =VLOOKUP(BC15,'Axe 2 Règles de gestion'!$D$2:$F$146,3, FALSE) -> La date de début du congé/absence doit être antérieure ou égale à la date de fin prévisionnelle du congé/absence. | BE15: ABS_C_005 | BF15: =VLOOKUP(BE15,'Axe 2 Règles de gestion'!$D$2:$F$146,3, FALSE) -> La date de fin réelle du congé/absence doit être antérieure ou égale à la date limite de fin réelle ou prévisionnelle du lien juridique. | BG15: ABS_C_006 | BH15: =VLOOKUP(BG15,'Axe 2 Règles de gestion'!$D$2:$F$146,3, FALSE) -> La date de fin prévisionnelle du congé/absence doit être antérieure ou égale à la date limite de fin réelle ou prévisionnelle du lien juridique. | BI15: ABS_C_009 | BJ15: =VLOOKUP(BI15,'Axe 2 Règles de gestion'!$D$2:$F$146,3, FALSE) -> La date de fin réelle ou la date de fin prévisionnelle du congé/absence doit être saisie. | BK15: ABS_C_019 | BL15: =VLOOKUP(BK15,'Axe 2 Règles de gestion'!$D$2:$F$146,3, FALSE) -> Si l'absence ne commence pas par une demi-journée et si l'absence précédente ne finit pas par une demi journée, la date de début de l'absence saisie est postérieure à la date de fin réelle de l'absence précédente. | BM15: ABS_C_020 | BN15: =VLOOKUP(BM15,'Axe 2 Règles de gestion'!$D$2:$F$146,3, FALSE) -> Si l'absence ne commence pas par une demi-journée et si l'absence précédente ne finit pas par une demi journée, la date de début de l'absence saisie est postérieure à la date de fin prévisionnelle de l'absence précédente. | BO15: ABS_C_026 | BP15: =VLOOKUP(BO15,'Axe 2 Règles de gestion'!$D$2:$F$146,3, FALSE) -> Dans le cas d'un congé autre que CLM, CLD, CGM et CITIS, l'indicateur de requalification doit être à non et les impacts spécifiques à la requalification ne doivent pas être mobilisés ou l'impact rémunération est vide.
A16: 25.10.00 | B16: A | C16: 45994.409 | D16: D0007 | E16: Congés/Absence | F16: S0167 | G16: Congés annuels Jours ARTT | H16: E0933 | I16: Jours supplémentaires hors période (fractionnement) | J16: Type de congé/absence saisi est 'Jours supplémentaires hors période (fractionnement)' | K16: A_COA_TYCOAB [Saisi] = 'CV001' | L16: T2277 | M16: Jours supplémentaires hors période (fractionnement) | N16: Création Modification | Q16: Ouvrier des parcs et ateliers confirmé ou stagiaire | R16: P0143 | S16: O | T16: Particulier | U16: Passant | V16: 45901 | X16: CFR_I_015 ET CFR_I_007 ET CFR_I_008 ET CFR_D_001 ET ABS_C_001 ET ABS_C_003 ET ABS_C_004 ET ABS_C_007 ET ABS_C_008 ET ABS_C_009 ET ABS_C_019 ET ABS_C_020 ET ABS_C_026 | Y16: CFR_I_015 | Z16: =VLOOKUP(Y16,'Axe 2 Règles de gestion'!$D$2:$F$146,3, FALSE) -> L'agent bénéficie des dispositions applicables aux agents titulaires pour les jours de fractionnement. | AA16: CFR_I_007 | AB16: =VLOOKUP(AA16,'Axe 2 Règles de gestion'!$D$2:$F$146,3, FALSE) -> L'agent bénéficie d'1 jour de congé supplémentaire, dit « jour de fractionnement », lorsque le nombre de jours de congé annuel pris en dehors de la période du 1er mai au 31 octobre est de 5, 6 ou 7. | AC16: CFR_I_008 | AD16: =VLOOKUP(AC16,'Axe 2 Règles de gestion'!$D$2:$F$146,3, FALSE) -> L'agent bénéficie de 2 jours de congés supplémentaires, dit « jours de fractionnement », lorsque le nombre de jours de congé annuel pris en dehors de la période du 1er mai au 31 octobre est supérieur ou égal à 8. | AS16: CFR_D_001 | AT16: =VLOOKUP(AS16,'Axe 2 Règles de gestion'!$D$2:$F$146,3, FALSE) -> L'agent ne peut pas prendre plus de 2 jours de fractionnement par an. | AY16: ABS_C_001 | AZ16: =VLOOKUP(AY16,'Axe 2 Règles de gestion'!$D$2:$F$146,3, FALSE) -> La date de début du congé/absence doit être postérieure ou égale à la date de recrutement dans la FPE ou dans la carrière militaire. | BA16: ABS_C_003 | BB16: =VLOOKUP(BA16,'Axe 2 Règles de gestion'!$D$2:$F$146,3, FALSE) -> La date de début du congé/absence doit être antérieure ou égale à la date de fin réelle du congé/absence. | BC16: ABS_C_004 | BD16: =VLOOKUP(BC16,'Axe 2 Règles de gestion'!$D$2:$F$146,3, FALSE) -> La date de début du congé/absence doit être antérieure ou égale à la date de fin prévisionnelle du congé/absence. | BE16: ABS_C_007 | BF16: =VLOOKUP(BE16,'Axe 2 Règles de gestion'!$D$2:$F$146,3, FALSE) -> La date de fin réelle du congé/absence doit être antérieure à la date limite de départ à la retraite. | BG16: ABS_C_008 | BH16: =VLOOKUP(BG16,'Axe 2 Règles de gestion'!$D$2:$F$146,3, FALSE) -> La date de fin prévisionnelle du congé/absence doit être antérieure à la date limite de départ à la retraite. | BI16: ABS_C_009 | BJ16: =VLOOKUP(BI16,'Axe 2 Règles de gestion'!$D$2:$F$146,3, FALSE) -> La date de fin réelle ou la date de fin prévisionnelle du congé/absence doit être saisie. | BK16: ABS_C_019 | BL16: =VLOOKUP(BK16,'Axe 2 Règles de gestion'!$D$2:$F$146,3, FALSE) -> Si l'absence ne commence pas par une demi-journée et si l'absence précédente ne finit pas par une demi journée, la date de début de l'absence saisie est postérieure à la date de fin réelle de l'absence précédente. | BM16: ABS_C_020 | BN16: =VLOOKUP(BM16,'Axe 2 Règles de gestion'!$D$2:$F$146,3, FALSE) -> Si l'absence ne commence pas par une demi-journée et si l'absence précédente ne finit pas par une demi journée, la date de début de l'absence saisie est postérieure à la date de fin prévisionnelle de l'absence précédente. | BO16: ABS_C_026 | BP16: =VLOOKUP(BO16,'Axe 2 Règles de gestion'!$D$2:$F$146,3, FALSE) -> Dans le cas d'un congé autre que CLM, CLD, CGM et CITIS, l'indicateur de requalification doit être à non et les impacts spécifiques à la requalification ne doivent pas être mobilisés ou l'impact rémunération est vide.
A17: 23.00.00 | B17: A | C17: 45084.44 | D17: D0007 | E17: Congés/Absence | F17: S0167 | G17: Congés annuels Jours ARTT | H17: E0933 | I17: Jours supplémentaires hors période (fractionnement) | J17: Type de congé/absence saisi est 'Jours supplémentaires hors période (fractionnement)' | K17: A_COA_TYCOAB [Saisi] = 'CV001' | L17: T2277 | M17: Jours supplémentaires hors période (fractionnement) | N17: Création Modification | Q17: Ouvrier de la défense ou assimilé | R17: P0197 | S17: O | T17: Particulier | U17: Passant | V17: 44927 | X17: CFR_I_011 ET CFR_I_012 ET CFR_I_013 ET CFR_I_014 ET CFR_D_003 ET ABS_C_002 ET ABS_C_003 ET ABS_C_004 ET ABS_C_005 ET ABS_C_006 ET ABS_C_009 ET ABS_C_019 ET ABS_C_020 ET ABS_C_026 | Y17: CFR_I_011 | Z17: =VLOOKUP(Y17,'Axe 2 Règles de gestion'!$D$2:$F$146,3, FALSE) -> L'agent bénéficie d'1 jour de congé supplémentaire, dit « jour de fractionnement », lorsque le nombre de jours de congé annuel pris en dehors de la période du 1er mai au 31 octobre est de 5, 6 ou 7. | AA17: CFR_I_012 | AB17: =VLOOKUP(AA17,'Axe 2 Règles de gestion'!$D$2:$F$146,3, FALSE) -> L'agent bénéficie de 2 jours de congés supplémentaires, dit « jours de fractionnement », lorsque le nombre de jours de congé pris en dehors de la période du 1er mai au 31 octobre est supérieur ou égal à 8. | AC17: CFR_I_013 | AD17: =VLOOKUP(AC17,'Axe 2 Règles de gestion'!$D$2:$F$146,3, FALSE) -> L'agent ne peut pas poser, pendant la période du 1er mai au 31 octobre, les jours de fractionnement acquis. | AE17: CFR_I_014 | AF17: =VLOOKUP(AE17,'Axe 2 Règles de gestion'!$D$2:$F$146,3, FALSE) -> L'agent peut exceptionnellement poser le(s) jour(s) de fractionnement acquis jusqu'au 28 février de l'année suivante. | AS17: CFR_D_003 | AT17: =VLOOKUP(AS17,'Axe 2 Règles de gestion'!$D$2:$F$146,3, FALSE) -> L'agent ne peut pas prendre plus de 2 jours de fractionnement par an. | AY17: ABS_C_002 | AZ17: =VLOOKUP(AY17,'Axe 2 Règles de gestion'!$D$2:$F$146,3, FALSE) -> La date de début du congé/absence doit être postérieure ou égale à la date de début du lien juridique. | BA17: ABS_C_003 | BB17: =VLOOKUP(BA17,'Axe 2 Règles de gestion'!$D$2:$F$146,3, FALSE) -> La date de début du congé/absence doit être antérieure ou égale à la date de fin réelle du congé/absence. | BC17: ABS_C_004 | BD17: =VLOOKUP(BC17,'Axe 2 Règles de gestion'!$D$2:$F$146,3, FALSE) -> La date de début du congé/absence doit être antérieure ou égale à la date de fin prévisionnelle du congé/absence. | BE17: ABS_C_005 | BF17: =VLOOKUP(BE17,'Axe 2 Règles de gestion'!$D$2:$F$146,3, FALSE) -> La date de fin réelle du congé/absence doit être antérieure ou égale à la date limite de fin réelle ou prévisionnelle du lien juridique. | BG17: ABS_C_006 | BH17: =VLOOKUP(BG17,'Axe 2 Règles de gestion'!$D$2:$F$146,3, FALSE) -> La date de fin prévisionnelle du congé/absence doit être antérieure ou égale à la date limite de fin réelle ou prévisionnelle du lien juridique. | BI17: ABS_C_009 | BJ17: =VLOOKUP(BI17,'Axe 2 Règles de gestion'!$D$2:$F$146,3, FALSE) -> La date de fin réelle ou la date de fin prévisionnelle du congé/absence doit être saisie. | BK17: ABS_C_019 | BL17: =VLOOKUP(BK17,'Axe 2 Règles de gestion'!$D$2:$F$146,3, FALSE) -> Si l'absence ne commence pas par une demi-journée et si l'absence précédente ne finit pas par une demi journée, la date de début de l'absence saisie est postérieure à la date de fin réelle de l'absence précédente. | BM17: ABS_C_020 | BN17: =VLOOKUP(BM17,'Axe 2 Règles de gestion'!$D$2:$F$146,3, FALSE) -> Si l'absence ne commence pas par une demi-journée et si l'absence précédente ne finit pas par une demi journée, la date de début de l'absence saisie est postérieure à la date de fin prévisionnelle de l'absence précédente. | BO17: ABS_C_026 | BP17: =VLOOKUP(BO17,'Axe 2 Règles de gestion'!$D$2:$F$146,3, FALSE) -> Dans le cas d'un congé autre que CLM, CLD, CGM et CITIS, l'indicateur de requalification doit être à non et les impacts spécifiques à la requalification ne doivent pas être mobilisés ou l'impact rémunération est vide.
A18: 25.10.00 | B18: M | C18: 45932.672 | D18: D0007 | E18: Congés/Absence | F18: S0167 | G18: Congés annuels Jours ARTT | H18: E0934 | I18: Congés annuels avec traitement des agents en service en France | J18: Type de congé/absence saisi est 'Congés annuels avec traitement' et l'affectation opérationnelle de l'agent est en France | K18: A_COA_TYCOAB [Saisi] = 'CV000' ET [SELECTIONNER (UNITE_STRUC.O_UST_PAYS) POUR (UNITE_STRUC.O_UST_IDENTI = POSTE.O_UST_IDENTI1 ET POSTE.O_POS_IDENTI = O_POS_IDENTI1 [Dossier])] DANS ('FRA', 'GLP' ; 'MTQ' ; 'REU' ; 'GUF' ; 'MYT') | L18: T2278 | M18: Congés annuels avec traitement des agents en service en France | N18: Création Modification | Q18: Titulaire ou magistrat | R18: P0001 | S18: T | T18: Général | U18: Passant | V18: 44927 | W18: 45830 | X18: CAN_I_001 ET CAN_I_002 ET CAN_I_007 ET CAN_I_005 ET CAN_I_006 ET CAN_I_009 ET CAN_I_010 ET CAN_D_002 ET CAN_D_003 ET CAN_D_001 ET ABS_C_001 ET ABS_C_003 ET ABS_C_004 ET ABS_C_007 ET ABS_C_008 ET ABS_C_009 ET ABS_C_019 ET ABS_C_020 ET ABS_C_026 | Y18: CAN_I_001 | Z18: =VLOOKUP(Y18,'Axe 2 Règles de gestion'!$D$2:$F$146,3, FALSE) -> L'agent a droit pour 1 année de service accompli du 1er janvier au 31 décembre, à un congé annuel d'une durée égale à 5 fois ses obligations hebdomadaires de service appréciée en jours ouvrés. | AA18: CAN_I_002 | AB18: =VLOOKUP(AA18,'Axe 2 Règles de gestion'!$D$2:$F$146,3, FALSE) -> L'agent qui n'exerce pas ses fonctions pendant la totalité de la période de référence a droit à un congé annuel dont la durée est calculée au prorata de la durée des services accomplis. | AC18: CAN_I_007 | AD18: =VLOOKUP(AC18,'Axe 2 Règles de gestion'!$D$2:$F$146,3, FALSE) -> Le congé dû pour une année de service accompli ne peut se reporter sur l'année suivante, sauf autorisation exceptionnelle donnée par le chef de service. | AE18: CAN_I_005 | AF18: =VLOOKUP(AE18,'Axe 2 Règles de gestion'!$D$2:$F$146,3, FALSE) -> Le calendrier des congés est fixé par le chef du service, après consultation des agents intéressés, compte tenu des fractionnements et échelonnements de congés que l'intérêt du service peut rendre nécessaires. | AG18: CAN_I_006 | AH18: =VLOOKUP(AG18,'Axe 2 Règles de gestion'!$D$2:$F$146,3, FALSE) -> L'agent chargé de famille bénéficie d'une priorité pour le choix des périodes de congés annuels. | AI18: CAN_I_009 | AJ18: =VLOOKUP(AI18,'Axe 2 Règles de gestion'!$D$2:$F$146,3, FALSE) -> Un congé non pris ne donne lieu à aucune indemnité compensatrice. | AK18: CAN_I_010 | AL18: =VLOOKUP(AK18,'Axe 2 Règles de gestion'!$D$2:$F$146,3, FALSE) -> Le congé annuel peut être interrompu par les congés ordinaires de maladie, les congés de longue maladie, le congé de longue durée et les congés pour accident de service. | AS18: CAN_D_002 | AT18: =VLOOKUP(AS18,'Axe 2 Règles de gestion'!$D$2:$F$146,3, FALSE) -> La durée réelle ne peut pas dépasser 31 jours consécutifs sauf si l'agent bénéficie de don de jours ou s'il est autorisé à cumuler ses congés annuels pour se rendre dans son pays d'origine ou pour accompagner son conjoint se rendant dans son pays d'origine. | AU18: CAN_D_003 | AV18: =VLOOKUP(AU18,'Axe 2 Règles de gestion'!$D$2:$F$146,3, FALSE) -> La durée prévisionnelle ne peut pas dépasser 31 jours consécutifs sauf si l'agent bénéficie de don de jours ou s'il est autorisé à cumuler ses congés annuels pour se rendre dans son pays d'origine ou pour accompagner son conjoint se rendant dans son pays d'origine. | AW18: CAN_D_001 | AX18: =VLOOKUP(AW18,'Axe 2 Règles de gestion'!$D$2:$F$146,3, FALSE) -> L'agent est en activité. | AY18: ABS_C_001 | AZ18: =VLOOKUP(AY18,'Axe 2 Règles de gestion'!$D$2:$F$146,3, FALSE) -> La date de début du congé/absence doit être postérieure ou égale à la date de recrutement dans la FPE ou dans la carrière militaire. | BA18: ABS_C_003 | BB18: =VLOOKUP(BA18,'Axe 2 Règles de gestion'!$D$2:$F$146,3, FALSE) -> La date de début du congé/absence doit être antérieure ou égale à la date de fin réelle du congé/absence. | BC18: ABS_C_004 | BD18: =VLOOKUP(BC18,'Axe 2 Règles de gestion'!$D$2:$F$146,3, FALSE) -> La date de début du congé/absence doit être antérieure ou égale à la date de fin prévisionnelle du congé/absence. | BE18: ABS_C_007 | BF18: =VLOOKUP(BE18,'Axe 2 Règles de gestion'!$D$2:$F$146,3, FALSE) -> La date de fin réelle du congé/absence doit être antérieure à la date limite de départ à la retraite. | BG18: ABS_C_008 | BH18: =VLOOKUP(BG18,'Axe 2 Règles de gestion'!$D$2:$F$146,3, FALSE) -> La date de fin prévisionnelle du congé/absence doit être antérieure à la date limite de départ à la retraite. | BI18: ABS_C_009 | BJ18: =VLOOKUP(BI18,'Axe 2 Règles de gestion'!$D$2:$F$146,3, FALSE) -> La date de fin réelle ou la date de fin prévisionnelle du congé/absence doit être saisie. | BK18: ABS_C_019 | BL18: =VLOOKUP(BK18,'Axe 2 Règles de gestion'!$D$2:$F$146,3, FALSE) -> Si l'absence ne commence pas par une demi-journée et si l'absence précédente ne finit pas par une demi journée, la date de début de l'absence saisie est postérieure à la date de fin réelle de l'absence précédente. | BM18: ABS_C_020 | BN18: =VLOOKUP(BM18,'Axe 2 Règles de gestion'!$D$2:$F$146,3, FALSE) -> Si l'absence ne commence pas par une demi-journée et si l'absence précédente ne finit pas par une demi journée, la date de début de l'absence saisie est postérieure à la date de fin prévisionnelle de l'absence précédente. | BO18: ABS_C_026 | BP18: =VLOOKUP(BO18,'Axe 2 Règles de gestion'!$D$2:$F$146,3, FALSE) -> Dans le cas d'un congé autre que CLM, CLD, CGM et CITIS, l'indicateur de requalification doit être à non et les impacts spécifiques à la requalification ne doivent pas être mobilisés ou l'impact rémunération est vide.
A19: 25.10.00 | B19: A | C19: 45932.672 | D19: D0007 | E19: Congés/Absence | F19: S0167 | G19: Congés annuels Jours ARTT | H19: E0934 | I19: Congés annuels avec traitement des agents en service en France | J19: Type de congé/absence saisi est 'Congés annuels avec traitement' et l'affectation opérationnelle de l'agent est en France | K19: A_COA_TYCOAB [Saisi] = 'CV000' ET [SELECTIONNER (UNITE_STRUC.O_UST_PAYS) POUR (UNITE_STRUC.O_UST_IDENTI = POSTE.O_UST_IDENTI1 ET POSTE.O_POS_IDENTI = O_POS_IDENTI1 [Dossier])] DANS ('FRA', 'GLP' ; 'MTQ' ; 'REU' ; 'GUF' ; 'MYT') | L19: T2278 | M19: Congés annuels avec traitement des agents en service en France | N19: Création Modification | Q19: Titulaire ou magistrat | R19: P0001 | S19: T | T19: Général | U19: Passant | V19: 45831 | X19: CAN_I_001 ET CAN_I_002 ET CAN_I_006 ET CAN_I_010 ET CAN_I_007 ET CAN_I_048 ET CAN_I_055 ET CAN_I_056 ET CAN_I_057 ET CAN_D_002 ET CAN_D_003 ET CAN_D_001 ET ABS_C_001 ET ABS_C_003 ET ABS_C_004 ET ABS_C_007 ET ABS_C_008 ET ABS_C_009 ET ABS_C_019 ET ABS_C_020 ET ABS_C_026 | Y19: CAN_I_001 | Z19: =VLOOKUP(Y19,'Axe 2 Règles de gestion'!$D$2:$F$146,3, FALSE) -> L'agent a droit pour 1 année de service accompli du 1er janvier au 31 décembre, à un congé annuel d'une durée égale à 5 fois ses obligations hebdomadaires de service appréciée en jours ouvrés. | AA19: CAN_I_002 | AB19: =VLOOKUP(AA19,'Axe 2 Règles de gestion'!$D$2:$F$146,3, FALSE) -> L'agent qui n'exerce pas ses fonctions pendant la totalité de la période de référence a droit à un congé annuel dont la durée est calculée au prorata de la durée des services accomplis. | AC19: CAN_I_006 | AD19: =VLOOKUP(AC19,'Axe 2 Règles de gestion'!$D$2:$F$146,3, FALSE) -> L'agent chargé de famille bénéficie d'une priorité pour le choix des périodes de congés annuels. | AE19: CAN_I_010 | AF19: =VLOOKUP(AE19,'Axe 2 Règles de gestion'!$D$2:$F$146,3, FALSE) -> Le congé annuel peut être interrompu par les congés ordinaires de maladie, les congés de longue maladie, le congé de longue durée et les congés pour accident de service. | AG19: CAN_I_007 | AH19: =VLOOKUP(AG19,'Axe 2 Règles de gestion'!$D$2:$F$146,3, FALSE) -> Le congé dû pour une année de service accompli ne peut se reporter sur l'année suivante, sauf autorisation exceptionnelle donnée par le chef de service. | AI19: CAN_I_048 | AJ19: =VLOOKUP(AI19,'Axe 2 Règles de gestion'!$D$2:$F$146,3, FALSE) -> L'agent qui ne peut, du fait d'un congé pour raison de santé, ou d'un congé lié aux responsabilités parentales ou familiales, prendre son congé au cours de l'année au titre de laquelle il lui est dû, bénéficie d'une période de report de 15 mois. | AK19: CAN_I_055 | AL19: =VLOOKUP(AK19,'Axe 2 Règles de gestion'!$D$2:$F$146,3, FALSE) -> Sauf exceptions, un congé non pris ne donne lieu à aucune indemnité compensatrice. | AM19: CAN_I_056 | AN19: =VLOOKUP(AM19,'Axe 2 Règles de gestion'!$D$2:$F$146,3, FALSE) -> Lorsque l'agent n'a pas été en mesure de prendre son congé annuel avant la fin de la relation de travail, les droits non-utilisés donnent lieu à une indemnisation. | AO19: CAN_I_057 | AP19: =VLOOKUP(AO19,'Axe 2 Règles de gestion'!$D$2:$F$146,3, FALSE) -> Pour les droits non-consommés du fait d'un congé pour raison de santé, l'indemnité ne compense que les droits non-utilisés relevant des 4 premières semaines de congé annuel par période de référence. | AS19: CAN_D_002 | AT19: =VLOOKUP(AS19,'Axe 2 Règles de gestion'!$D$2:$F$146,3, FALSE) -> La durée réelle ne peut pas dépasser 31 jours consécutifs sauf si l'agent bénéficie de don de jours ou s'il est autorisé à cumuler ses congés annuels pour se rendre dans son pays d'origine ou pour accompagner son conjoint se rendant dans son pays d'origine. | AU19: CAN_D_003 | AV19: =VLOOKUP(AU19,'Axe 2 Règles de gestion'!$D$2:$F$146,3, FALSE) -> La durée prévisionnelle ne peut pas dépasser 31 jours consécutifs sauf si l'agent bénéficie de don de jours ou s'il est autorisé à cumuler ses congés annuels pour se rendre dans son pays d'origine ou pour accompagner son conjoint se rendant dans son pays d'origine. | AW19: CAN_D_001 | AX19: =VLOOKUP(AW19,'Axe 2 Règles de gestion'!$D$2:$F$146,3, FALSE) -> L'agent est en activité. | AY19: ABS_C_001 | AZ19: =VLOOKUP(AY19,'Axe 2 Règles de gestion'!$D$2:$F$146,3, FALSE) -> La date de début du congé/absence doit être postérieure ou égale à la date de recrutement dans la FPE ou dans la carrière militaire. | BA19: ABS_C_003 | BB19: =VLOOKUP(BA19,'Axe 2 Règles de gestion'!$D$2:$F$146,3, FALSE) -> La date de début du congé/absence doit être antérieure ou égale à la date de fin réelle du congé/absence. | BC19: ABS_C_004 | BD19: =VLOOKUP(BC19,'Axe 2 Règles de gestion'!$D$2:$F$146,3, FALSE) -> La date de début du congé/absence doit être antérieure ou égale à la date de fin prévisionnelle du congé/absence. | BE19: ABS_C_007 | BF19: =VLOOKUP(BE19,'Axe 2 Règles de gestion'!$D$2:$F$146,3, FALSE) -> La date de fin réelle du congé/absence doit être antérieure à la date limite de départ à la retraite. | BG19: ABS_C_008 | BH19: =VLOOKUP(BG19,'Axe 2 Règles de gestion'!$D$2:$F$146,3, FALSE) -> La date de fin prévisionnelle du congé/absence doit être antérieure à la date limite de départ à la retraite. | BI19: ABS_C_009 | BJ19: =VLOOKUP(BI19,'Axe 2 Règles de gestion'!$D$2:$F$146,3, FALSE) -> La date de fin réelle ou la date de fin prévisionnelle du congé/absence doit être saisie. | BK19: ABS_C_019 | BL19: =VLOOKUP(BK19,'Axe 2 Règles de gestion'!$D$2:$F$146,3, FALSE) -> Si l'absence ne commence pas par une demi-journée et si l'absence précédente ne finit pas par une demi journée, la date de début de l'absence saisie est postérieure à la date de fin réelle de l'absence précédente. | BM19: ABS_C_020 | BN19: =VLOOKUP(BM19,'Axe 2 Règles de gestion'!$D$2:$F$146,3, FALSE) -> Si l'absence ne commence pas par une demi-journée et si l'absence précédente ne finit pas par une demi journée, la date de début de l'absence saisie est postérieure à la date de fin prévisionnelle de l'absence précédente. | BO19: ABS_C_026 | BP19: =VLOOKUP(BO19,'Axe 2 Règles de gestion'!$D$2:$F$146,3, FALSE) -> Dans le cas d'un congé autre que CLM, CLD, CGM et CITIS, l'indicateur de requalification doit être à non et les impacts spécifiques à la requalification ne doivent pas être mobilisés ou l'impact rémunération est vide.
A20: 24.10.00 | B20: A | C20: 45561.415 | D20: D0007 | E20: Congés/Absence | F20: S0167 | G20: Congés annuels Jours ARTT | H20: E0934 | I20: Congés annuels avec traitement des agents en service en France | J20: Type de congé/absence saisi est 'Congés annuels avec traitement' et l'affectation opérationnelle de l'agent est en France | K20: A_COA_TYCOAB [Saisi] = 'CV000' ET [SELECTIONNER (UNITE_STRUC.O_UST_PAYS) POUR (UNITE_STRUC.O_UST_IDENTI = POSTE.O_UST_IDENTI1 ET POSTE.O_POS_IDENTI = O_POS_IDENTI1 [Dossier])] DANS ('FRA', 'GLP' ; 'MTQ' ; 'REU' ; 'GUF' ; 'MYT') | L20: T2278 | M20: Congés annuels avec traitement des agents en service en France | N20: Création Modification | Q20: Militaire | R20: P0002 | S20: M | T20: Général | U20: Exclu | V20: 44927
