Workbook
Name date_DIADC: 'Mode opératoire'!#REF!
Name notice_DIADC: 'Mode opératoire'!#REF!
Name notice_ENCHN: 'Mode opératoire'!$B$1:$B$4
Name notice_ICA: 'Mode opératoire'!#REF!

Sheet Mode opératoire
B1: MODE OPERATOIRE
B2: La transaction s'effectue au niveau de la rubrique "Congés/absences", elle inclut l'ensemble des sous-rubriques listées ci-dessous : - Congés/absences - Complément pour congé / absence : impact rémunération - Compteurs de périodes de congés On notera que : La sous-rubrique "Complément pour congé / absence : impact rémunération" est réputée, suite au découpage des absences en tranche de rémunération, avoir des dates de début et de fin alignées sur les dates de début et de fin de la sous-rubrique "Congés/absences" (contrôle bloquant)

Sheet Axe 1 Enchainement des RG
A1: Version | B1: Type de mise à jour | C1: Date de mise à jour | D1: Identifiant Domaine | E1: Libellé du Domaine | F1: Identifiant Sous-domaine | G1: Libellé du Sous-domaine | H1: Identifiant Evénement | I1: Libellé de l'évènement | J1: Libellé condition déclenchement Evènement | K1: Condition déclenchement Evènement | L1: Identifiant type d'évènement | M1: Libellé type d'évènement | N1: Type de mise à jour | O1: Libellé condition déclenchement Type Evènement | P1: Condition déclenchement Type Evènement | Q1: Libellé Population | R1: Codification Population | S1: Typologie de population | T1: Général / Particulier | U1: Passant / Exclu | V1: Date de début | W1: Date de fin | X1: Règles mobilisées | Y1: Identifiant Règle de contrôle intellectuel 1 | Z1: Libellé Règle de contrôle intellectuel 1 | AA1: Identifiant Règle de contrôle intellectuel 2 | AB1: Libellé Règle de contrôle intellectuel 2 | AC1: Identifiant Règle de contrôle intellectuel 3 | AD1: Libellé Règle de contrôle intellectuel 3 | AE1: Identifiant Règle de contrôle intellectuel 4 | AF1: Libellé Règle de contrôle intellectuel 4 | AG1: Identifiant Règle de contrôle intellectuel 5 | AH1: Libellé Règle de contrôle intellectuel 5 | AI1: Identifiant Règle de contrôle intellectuel 6 | AJ1: Libellé Règle de contrôle intellectuel 6 | AK1: Identifiant Règle de contrôle intellectuel 7 | AL1: Libellé Règle de contrôle intellectuel 7 | AM1: Identifiant Règle de contrôle intellectuel 8 | AN1: Libellé Règle de contrôle intellectuel 8 | AO1: Identifiant Règle de contrôle intellectuel 9 | AP1: Libellé Règle de contrôle intellectuel 9 | AQ1: Identifiant Règle de contrôle intellectuel 10 | AR1: Libellé Règle de contrôle intellectuel 10 | AS1: Identifiant Règle de contrôle intellectuel 11 | AT1: Libellé Règle de contrôle intellectuel 11 | AU1: Identifiant Règle de contrôle intellectuel 12 | AV1: Libellé Règle de contrôle intellectuel 12 | AW1: Identifiant Règle de contrôle intellectuel 13 | AX1: Libellé Règle de contrôle intellectuel 13 | AY1: Identifiant Règle de contrôle intellectuel 14 | AZ1: Libellé Règle de contrôle intellectuel 14 | BA1: Identifiant Règle de contrôle intellectuel 15 | BB1: Libellé Règle de contrôle intellectuel 15 | BC1: Identifiant Règle de contrôle intellectuel 16 | BD1: Libellé Règle de contrôle intellectuel 16 | BE1: Identifiant Règle de contrôle intellectuel 17 | BF1: Libellé Règle de contrôle intellectuel 17 | BG1: Identifiant Règle de contrôle intellectuel 18 | BH1: Libellé Règle de contrôle intellectuel 18 | BI1: Identifiant Règle de contrôle intellectuel 19 | BJ1: Libellé Règle de contrôle intellectuel 19 | BK1: Identifiant Règle de contrôle intellectuel 20 | BL1: Libellé Règle de contrôle intellectuel 20 | BM1: Identifiant Règle de contrôle intellectuel 21 | BN1: Libellé Règle de contrôle intellectuel 21 | BO1: Identifiant Règle de condition 1 | BP1: Libellé Règle de condition 1 | BQ1: Identifiant Règle de condition 2 | BR1: Libellé Règle de condition 2 | BS1: Identifiant Règle de condition 3 | BT1: Libellé Règle de condition 3 | BU1: Identifiant Règle de condition 4 | BV1: Libellé Règle de condition 4 | BW1: Identifiant Règle de condition 5 | BX1: Libellé Règle de condition 5 | BY1: Identifiant Règle de condition 6 | BZ1: Libellé Règle de condition 6 | CA1: Identifiant Règle de condition 7 | CB1: Libellé Règle de condition 7 | CC1: Identifiant Règle de contrôle 1 | CD1: Libellé Règle de contrôle 1 | CE1: Identifiant Règle de contrôle 2 | CF1: Libellé Règle de contrôle 2 | CG1: Identifiant Règle de contrôle 3 | CH1: Libellé Règle de contrôle 3 | CI1: Identifiant Règle de contrôle 4 | CJ1: Libellé Règle de contrôle 4 | CK1: Identifiant Règle de contrôle 5 | CL1: Libellé Règle de contrôle 5 | CM1: Identifiant Règle de contrôle 6 | CN1: Libellé Règle de contrôle 6 | CO1: Identifiant Règle de contrôle 7 | CP1: Libellé Règle de contrôle 7 | CQ1: Identifiant Règle de contrôle 8 | CR1: Libellé Règle de contrôle 8 | CS1: Identifiant Règle de contrôle 9 | CT1: Libellé Règle de contrôle 9 | CU1: Identifiant Règle de contrôle 10 | CV1: Libellé Règle de contrôle 10 | CW1: Identifiant Règle de contrôle 11 | CX1: Libellé Règle de contrôle 11 | CY1: Identifiant Règle de contrôle 12 | CZ1: Libellé Règle de contrôle 12 | DA1: Identifiant Règle de contrôle 13 | DB1: Libellé Règle de contrôle 13 | DC1: Identifiant Règle de contrôle 14 | DD1: Libellé Règle de contrôle 14 | DE1: Identifiant Règle de contrôle 15 | DF1: Libellé Règle de contrôle 15 | DG1: FIME | DH1: Statut de travail
A2: 21.00.00 | B2: M | C2: 45223.631 | D2: D0007 | E2: Congés/Absence | F2: S0057 | G2: Congé de présence parentale | H2: E0478 | I2: Congé de présence parentale | J2: Congé saisi égal à 'Congé de présence parentale' | K2: A_COA_TYCOAB [Saisi] = 'CG102' | L2: T1166 | M2: Congé de présence parentale - Initial | N2: Création Modification | O2: La valeur de l'Etat du congé est différente de 'Renouvellement' et la valeur de l'Etat du congé saisie est différente de celle avant saisie | P2: A_COA_ETCOMA [Saisi] <> 'EC02' ET A_COA_ETCOMA [Saisi] <> A_COA_ETCOMA [Valeur avant saisie] | Q2: Titulaire ou magistrat | R2: P0001 | S2: T | T2: Général | U2: Passant | V2: 40725 | W2: 44167 | X2: CPP_I_004 ET CPP_I_005 ET CPP_I_006 ET CPP_I_007 ET CPP_I_010 ET CPP_I_001 ET CPP_I_012 ET CPP_I_013 ET CPP_I_014 ET CPP_I_009 ET CPP_I_011 ET CPP_I_003 ET CPP_D_009 ET CPP_D_001 ET CPP_D_005 ET ABS_C_001 ET ABS_C_003 ET ABS_C_004 ET ABS_C_007 ET ABS_C_008 ET ABS_C_009 ET ABS_C_019 ET ABS_C_020 ET ABS_C_026 ET ABS_C_038 ET ABS_C_039 | Y2: CPP_I_004 | Z2: =VLOOKUP(Y2,'Axe 2 Règles de gestion'!$D$2:$F$366,3, FALSE) -> La demande doit être formulée par écrit au moins 15 jours avant le début du congé. | AA2: CPP_I_005 | AB2: =VLOOKUP(AA2,'Axe 2 Règles de gestion'!$D$2:$F$366,3, FALSE) -> La demande est accompagnée d'un certificat médical. | AC2: CPP_I_006 | AD2: =VLOOKUP(AC2,'Axe 2 Règles de gestion'!$D$2:$F$366,3, FALSE) -> Le certificat médical doit attester de la gravité de la maladie, de l'accident ou du handicap et de la nécessité de la présence soutenue d'un parent et de soins contraignants. Il doit également préciser la durée de l'absence. | AE2: CPP_I_007 | AF2: =VLOOKUP(AE2,'Axe 2 Règles de gestion'!$D$2:$F$366,3, FALSE) -> En cas d'urgence liée à l'état de santé de l'enfant, le congé débute à la date de la demande; l'agent transmet sous 15 jours le certificat médical requis. | AG2: CPP_I_010 | AH2: =VLOOKUP(AG2,'Axe 2 Règles de gestion'!$D$2:$F$366,3, FALSE) -> Si la durée du congé excède 6 mois, la pathologie et la nécessité de présence soutenue et de soins contraignants font tous les 6 mois l'objet d'un nouvel examen qui donne lieu à un certificat médical transmis sans délai à l'autorité dont relève l'agent. | AI2: CPP_I_001 | AJ2: =VLOOKUP(AI2,'Axe 2 Règles de gestion'!$D$2:$F$366,3, FALSE) -> Le congé est accordé de droit à l'agent. | AK2: CPP_I_012 | AL2: =VLOOKUP(AK2,'Axe 2 Règles de gestion'!$D$2:$F$366,3, FALSE) -> L'agent doit communiquer par écrit à l'autorité dont il relève le calendrier mensuel de ses journées de congé de présence parentale, au plus tard 15 jours avant le début de chaque mois. | AM2: CPP_I_013 | AN2: =VLOOKUP(AM2,'Axe 2 Règles de gestion'!$D$2:$F$366,3, FALSE) -> Lorsque l'agent souhaite prendre un ou plusieurs jours de congé ne correspondant pas au calendrier transmis, il doit en informer l'autorité au moins 48 heures à l'avance. | AO2: CPP_I_014 | AP2: =VLOOKUP(AO2,'Axe 2 Règles de gestion'!$D$2:$F$366,3, FALSE) -> L'autorité qui a accordé le congé fait procéder aux enquêtes nécessaires pour s'assurer que l'activité de l'agent est réellement consacrée à donner des soins à son enfant. | AQ2: CPP_I_009 | AR2: =VLOOKUP(AQ2,'Axe 2 Règles de gestion'!$D$2:$F$366,3, FALSE) -> En cas de rechute ou de récidive de la pathologie qui affecte l'enfant, le bénéfice du droit à congé peut être rouvert pour une nouvelle période sur présentation d'un certificat médical le justifiant. | AS2: CPP_I_011 | AT2: =VLOOKUP(AS2,'Axe 2 Règles de gestion'!$D$2:$F$366,3, FALSE) -> En cas de nouvelle pathologie affectant l'enfant, de même qu'en cas de rechute ou de récidive de la pathologie initialement traitée, un nouveau droit à congé est ouvert à l'issue de la période de 36 mois. | AU2: CPP_I_003 | AV2: =VLOOKUP(AU2,'Axe 2 Règles de gestion'!$D$2:$F$366,3, FALSE) -> Ce congé est ouvert au père ou à la mère. | BO2: CPP_D_009 | BP2: =VLOOKUP(BO2,'Axe 2 Règles de gestion'!$D$2:$F$366,3, FALSE) -> La durée réelle de congé de présence parentale dont peut bénéficier le fonctionnaire pour un même enfant et en raison d'une même pathologie est au maximum de 310 jours ouvrés au cours d'une période de 36 mois. (date de fin réelle de l'absence). | BQ2: CPP_D_001 | BR2: =VLOOKUP(BQ2,'Axe 2 Règles de gestion'!$D$2:$F$366,3, FALSE) -> L'agent doit être en activité. | BS2: CPP_D_005 | BT2: =VLOOKUP(BS2,'Axe 2 Règles de gestion'!$D$2:$F$366,3, FALSE) -> L'agent doit avoir un enfant lié à ce congé. | CC2: ABS_C_001 | CD2: =VLOOKUP(CC2,'Axe 2 Règles de gestion'!$D$2:$F$366,3, FALSE) -> La date de début du congé/absence doit être postérieure ou égale à la date de recrutement dans la FPE ou dans la carrière militaire. | CE2: ABS_C_003 | CF2: =VLOOKUP(CE2,'Axe 2 Règles de gestion'!$D$2:$F$366,3, FALSE) -> La date de début du congé/absence doit être antérieure ou égale à la date de fin réelle du congé/absence. | CG2: ABS_C_004 | CH2: =VLOOKUP(CG2,'Axe 2 Règles de gestion'!$D$2:$F$366,3, FALSE) -> La date de début du congé/absence doit être antérieure ou égale à la date de fin prévisionnelle du congé/absence. | CI2: ABS_C_007 | CJ2: =VLOOKUP(CI2,'Axe 2 Règles de gestion'!$D$2:$F$366,3, FALSE) -> La date de fin réelle du congé/absence doit être antérieure à la date limite de départ à la retraite. | CK2: ABS_C_008 | CL2: =VLOOKUP(CK2,'Axe 2 Règles de gestion'!$D$2:$F$366,3, FALSE) -> La date de fin prévisionnelle du congé/absence doit être antérieure à la date limite de départ à la retraite. | CM2: ABS_C_009 | CN2: =VLOOKUP(CM2,'Axe 2 Règles de gestion'!$D$2:$F$366,3, FALSE) -> La date de fin réelle ou la date de fin prévisionnelle du congé/absence doit être saisie. | CO2: ABS_C_019 | CP2: =VLOOKUP(CO2,'Axe 2 Règles de gestion'!$D$2:$F$366,3, FALSE) -> Si l'absence ne commence pas par une demi-journée et si l'absence précédente ne finit pas par une demi journée, la date de début de l'absence saisie est postérieure à la date de fin réelle de l'absence précédente. | CQ2: ABS_C_020 | CR2: =VLOOKUP(CQ2,'Axe 2 Règles de gestion'!$D$2:$F$366,3, FALSE) -> Si l'absence ne commence pas par une demi-journée et si l'absence précédente ne finit pas par une demi journée, la date de début de l'absence saisie est postérieure à la date de fin prévisionnelle de l'absence précédente. | CS2: ABS_C_026 | CT2: =VLOOKUP(CS2,'Axe 2 Règles de gestion'!$D$2:$F$366,3, FALSE) -> Dans le cas d'un congé autre que CLM, CLD, CGM et CITIS, l'indicateur de requalification doit être à non et les impacts spécifiques à la requalification ne doivent pas être mobilisés ou l'impact rémunération est vide. | CU2: ABS_C_038 | CV2: =VLOOKUP(CU2,'Axe 2 Règles de gestion'!$D$2:$F$366,3, FALSE) -> Le congé prend fin à la date de décès de l'enfant (date de fin réelle). | CW2: ABS_C_039 | CX2: =VLOOKUP(CW2,'Axe 2 Règles de gestion'!$D$2:$F$366,3, FALSE) -> Le congé prend fin à la date de décès de l'enfant (date de fin prévisionnelle).
A3: 23.10.00 | B3: M | C3: 45223.631 | D3: D0007 | E3: Congés/Absence | F3: S0057 | G3: Congé de présence parentale | H3: E0478 | I3: Congé de présence parentale | J3: Congé saisi égal à 'Congé de présence parentale' | K3: A_COA_TYCOAB [Saisi] = 'CG102' | L3: T1166 | M3: Congé de présence parentale - Initial | N3: Création Modification | O3: La valeur de l'Etat du congé est différente de 'Renouvellement' et la valeur de l'Etat du congé saisie est différente de celle avant saisie | P3: A_COA_ETCOMA [Saisi] <> 'EC02' ET A_COA_ETCOMA [Saisi] <> A_COA_ETCOMA [Valeur avant saisie] | Q3: Titulaire ou magistrat | R3: P0001 | S3: T | T3: Général | U3: Passant | V3: 44168 | W3: 45165 | X3: CPP_I_004 ET CPP_I_005 ET CPP_I_006 ET CPP_I_113 ET CPP_I_114 ET CPP_I_115 ET CPP_I_117 ET CPP_I_118 ET CPP_I_119 ET CPP_I_001 ET CPP_I_014 ET CPP_I_009 ET CPP_I_011 ET CPP_I_120 ET CPP_I_003 ET CPP_I_112 ET CPP_D_009 ET CPP_D_190 ET CPP_D_191 ET CPP_D_001 ET CPP_D_005 ET ABS_C_001 ET ABS_C_003 ET ABS_C_004 ET ABS_C_007 ET ABS_C_008 ET ABS_C_009 ET ABS_C_019 ET ABS_C_020 ET ABS_C_026 ET ABS_C_038 ET ABS_C_039 ET ABS_C_065 | Y3: CPP_I_004 | Z3: =VLOOKUP(Y3,'Axe 2 Règles de gestion'!$D$2:$F$366,3, FALSE) -> La demande doit être formulée par écrit au moins 15 jours avant le début du congé. | AA3: CPP_I_005 | AB3: =VLOOKUP(AA3,'Axe 2 Règles de gestion'!$D$2:$F$366,3, FALSE) -> La demande est accompagnée d'un certificat médical. | AC3: CPP_I_006 | AD3: =VLOOKUP(AC3,'Axe 2 Règles de gestion'!$D$2:$F$366,3, FALSE) -> Le certificat médical doit attester de la gravité de la maladie, de l'accident ou du handicap et de la nécessité de la présence soutenue d'un parent et de soins contraignants. Il doit également préciser la durée de l'absence. | AE3: CPP_I_113 | AF3: =VLOOKUP(AE3,'Axe 2 Règles de gestion'!$D$2:$F$366,3, FALSE) -> L'agent indique, dans sa demande de congé, la ou les modalités d'utilisation du congé et les dates de congé prévisionnelles afférentes. | AG3: CPP_I_114 | AH3: =VLOOKUP(AG3,'Axe 2 Règles de gestion'!$D$2:$F$366,3, FALSE) -> L'agent doit informer par écrit l'administration avec un préavis d'au moins 48 heures des changements de la ou des modalités d'utilisation et des dates de congé prévisionnelles afférentes. | AI3: CPP_I_115 | AJ3: =VLOOKUP(AI3,'Axe 2 Règles de gestion'!$D$2:$F$366,3, FALSE) -> Les délais de préavis liés à la demande du congé ne s'appliquent pas en cas de dégradation soudaine de l'état de santé de l'enfant ou en cas de situation de crise nécessitant une présence immédiate auprès de l'enfant. | AK3: CPP_I_117 | AL3: =VLOOKUP(AK3,'Axe 2 Règles de gestion'!$D$2:$F$366,3, FALSE) -> Les délais de préavis liés au changement de modalités d'utilisation du congé ne s'appliquent pas en cas de dégradation soudaine de l'état de santé de l'enfant ou en cas de situation de crise nécessitant une présence immédiate auprès de l'enfant. | AM3: CPP_I_118 | AN3: =VLOOKUP(AM3,'Axe 2 Règles de gestion'!$D$2:$F$366,3, FALSE) -> Les délais de préavis liés au changement de dates prévisionnelles du congé ne s'appliquent pas en cas de dégradation soudaine de l'état de santé de l'enfant ou en cas de situation de crise nécessitant une présence immédiate auprès de l'enfant. | AO3: CPP_I_119 | AP3: =VLOOKUP(AO3,'Axe 2 Règles de gestion'!$D$2:$F$366,3, FALSE) -> La durée prévisible de traitement fait l'objet d'un nouvel examen dans un délai compris entre 6 mois et 1 an maximum. Ce nouvel examen donne lieu à un certificat médical transmis à l'autorité dont relève l'agent. | AQ3: CPP_I_001 | AR3: =VLOOKUP(AQ3,'Axe 2 Règles de gestion'!$D$2:$F$366,3, FALSE) -> Le congé est accordé de droit à l'agent. | AS3: CPP_I_014 | AT3: =VLOOKUP(AS3,'Axe 2 Règles de gestion'!$D$2:$F$366,3, FALSE) -> L'autorité qui a accordé le congé fait procéder aux enquêtes nécessaires pour s'assurer que l'activité de l'agent est réellement consacrée à donner des soins à son enfant. | AU3: CPP_I_009 | AV3: =VLOOKUP(AU3,'Axe 2 Règles de gestion'!$D$2:$F$366,3, FALSE) -> En cas de rechute ou de récidive de la pathologie qui affecte l'enfant, le bénéfice du droit à congé peut être rouvert pour une nouvelle période sur présentation d'un certificat médical le justifiant. | AW3: CPP_I_011 | AX3: =VLOOKUP(AW3,'Axe 2 Règles de gestion'!$D$2:$F$366,3, FALSE) -> En cas de nouvelle pathologie affectant l'enfant, de même qu'en cas de rechute ou de récidive de la pathologie initialement traitée, un nouveau droit à congé est ouvert à l'issue de la période de 36 mois. | AY3: CPP_I_120 | AZ3: =VLOOKUP(AY3,'Axe 2 Règles de gestion'!$D$2:$F$366,3, FALSE) -> Lorsque la gravité de la pathologie de l'enfant initialement traitée nécessite une présence soutenue et des soins contraignants, un nouveau congé est ouvert à l'issue de la période de 36 mois sur présentation d'un certificat médical le justifiant. | BA3: CPP_I_003 | BB3: =VLOOKUP(BA3,'Axe 2 Règles de gestion'!$D$2:$F$366,3, FALSE) -> Ce congé est ouvert au père ou à la mère. | BC3: CPP_I_112 | BD3: =VLOOKUP(BC3,'Axe 2 Règles de gestion'!$D$2:$F$366,3, FALSE) -> Dans la limite de 36 mois, l'agent peut choisir d'utiliser les 310 jours ouvrés de congé sous la forme soit d'une période continue, soit d'une ou plusieurs périodes fractionnées d'au moins une journée soit d'un service à temps partiel. | BO3: CPP_D_009 | BP3: =VLOOKUP(BO3,'Axe 2 Règles de gestion'!$D$2:$F$366,3, FALSE) -> La durée réelle de congé de présence parentale dont peut bénéficier le fonctionnaire pour un même enfant et en raison d'une même pathologie est au maximum de 310 jours ouvrés au cours d'une période de 36 mois. (date de fin réelle de l'absence). | BQ3: CPP_D_190 | BR3: =VLOOKUP(BQ3,'Axe 2 Règles de gestion'!$D$2:$F$366,3, FALSE) -> Le congé de présence parentale peut être fractionné mais chaque absence doit être d'une durée réelle minimale de 1 jour. | BS3: CPP_D_191 | BT3: =VLOOKUP(BS3,'Axe 2 Règles de gestion'!$D$2:$F$366,3, FALSE) -> Le congé de présence parentale peut être fractionné mais chaque absence doit être d'une durée prévisionnelle minimale de 1 jour. | BU3: CPP_D_001 | BV3: =VLOOKUP(BU3,'Axe 2 Règles de gestion'!$D$2:$F$366,3, FALSE) -> L'agent doit être en activité. | BW3: CPP_D_005 | BX3: =VLOOKUP(BW3,'Axe 2 Règles de gestion'!$D$2:$F$366,3, FALSE) -> L'agent doit avoir un enfant lié à ce congé. | CC3: ABS_C_001 | CD3: =VLOOKUP(CC3,'Axe 2 Règles de gestion'!$D$2:$F$366,3, FALSE) -> La date de début du congé/absence doit être postérieure ou égale à la date de recrutement dans la FPE ou dans la carrière militaire. | CE3: ABS_C_003 | CF3: =VLOOKUP(CE3,'Axe 2 Règles de gestion'!$D$2:$F$366,3, FALSE) -> La date de début du congé/absence doit être antérieure ou égale à la date de fin réelle du congé/absence. | CG3: ABS_C_004 | CH3: =VLOOKUP(CG3,'Axe 2 Règles de gestion'!$D$2:$F$366,3, FALSE) -> La date de début du congé/absence doit être antérieure ou égale à la date de fin prévisionnelle du congé/absence. | CI3: ABS_C_007 | CJ3: =VLOOKUP(CI3,'Axe 2 Règles de gestion'!$D$2:$F$366,3, FALSE) -> La date de fin réelle du congé/absence doit être antérieure à la date limite de départ à la retraite. | CK3: ABS_C_008 | CL3: =VLOOKUP(CK3,'Axe 2 Règles de gestion'!$D$2:$F$366,3, FALSE) -> La date de fin prévisionnelle du congé/absence doit être antérieure à la date limite de départ à la retraite. | CM3: ABS_C_009 | CN3: =VLOOKUP(CM3,'Axe 2 Règles de gestion'!$D$2:$F$366,3, FALSE) -> La date de fin réelle ou la date de fin prévisionnelle du congé/absence doit être saisie. | CO3: ABS_C_019 | CP3: =VLOOKUP(CO3,'Axe 2 Règles de gestion'!$D$2:$F$366,3, FALSE) -> Si l'absence ne commence pas par une demi-journée et si l'absence précédente ne finit pas par une demi journée, la date de début de l'absence saisie est postérieure à la date de fin réelle de l'absence précédente. | CQ3: ABS_C_020 | CR3: =VLOOKUP(CQ3,'Axe 2 Règles de gestion'!$D$2:$F$366,3, FALSE) -> Si l'absence ne commence pas par une demi-journée et si l'absence précédente ne finit pas par une demi journée, la date de début de l'absence saisie est postérieure à la date de fin prévisionnelle de l'absence précédente. | CS3: ABS_C_026 | CT3: =VLOOKUP(CS3,'Axe 2 Règles de gestion'!$D$2:$F$366,3, FALSE) -> Dans le cas d'un congé autre que CLM, CLD, CGM et CITIS, l'indicateur de requalification doit être à non et les impacts spécifiques à la requalification ne doivent pas être mobilisés ou l'impact rémunération est vide. | CU3: ABS_C_038 | CV3: =VLOOKUP(CU3,'Axe 2 Règles de gestion'!$D$2:$F$366,3, FALSE) -> Le congé prend fin à la date de décès de l'enfant (date de fin réelle). | CW3: ABS_C_039 | CX3: =VLOOKUP(CW3,'Axe 2 Règles de gestion'!$D$2:$F$366,3, FALSE) -> Le congé prend fin à la date de décès de l'enfant (date de fin prévisionnelle). | CY3: ABS_C_065 | CZ3: =VLOOKUP(CY3,'Axe 2 Règles de gestion'!$D$2:$F$366,3, FALSE) -> L'agent en congé de présence parentale / congé de proche aidant / congé de solidarité familiale ne peut se voir accorder de manière simultanée un temps partiel pour congé de présence parentale / pour congé de proche aidant / pour congé de solidarité familiale.
A4: 23.10.00 | B4: M | C4: 45223.639 | D4: D0007 | E4: Congés/Absence | F4: S0057 | G4: Congé de présence parentale | H4: E0478 | I4: Congé de présence parentale | J4: Congé saisi égal à 'Congé de présence parentale' | K4: A_COA_TYCOAB [Saisi] = 'CG102' | L4: T1166 | M4: Congé de présence parentale - Initial | N4: Création Modification | O4: La valeur de l'Etat du congé est différente de 'Renouvellement' et la valeur de l'Etat du congé saisie est différente de celle avant saisie | P4: A_COA_ETCOMA [Saisi] <> 'EC02' ET A_COA_ETCOMA [Saisi] <> A_COA_ETCOMA [Valeur avant saisie] | Q4: Titulaire ou magistrat | R4: P0001 | S4: T | T4: Général | U4: Passant | V4: 45166 | X4: CPP_I_004 ET CPP_I_005 ET CPP_I_006 ET CPP_I_113 ET CPP_I_114 ET CPP_I_115 ET CPP_I_117 ET CPP_I_118 ET CPP_I_119 ET CPP_I_001 ET CPP_I_014 ET CPP_I_009 ET CPP_I_011 ET CPP_I_120 ET CPP_I_003 ET CPP_I_314 ET CPP_I_008 ET CPP_I_121 ET CPP_I_323 ET CPP_D_009 ET CPP_D_001 ET CPP_D_005 ET CPP_D_025 ET ABS_C_001 ET ABS_C_003 ET ABS_C_004 ET ABS_C_007 ET ABS_C_008 ET ABS_C_009 ET ABS_C_019 ET ABS_C_020 ET ABS_C_026 ET ABS_C_038 ET ABS_C_039 ET ABS_C_065 | Y4: CPP_I_004 | Z4: =VLOOKUP(Y4,'Axe 2 Règles de gestion'!$D$2:$F$366,3, FALSE) -> La demande doit être formulée par écrit au moins 15 jours avant le début du congé. | AA4: CPP_I_005 | AB4: =VLOOKUP(AA4,'Axe 2 Règles de gestion'!$D$2:$F$366,3, FALSE) -> La demande est accompagnée d'un certificat médical. | AC4: CPP_I_006 | AD4: =VLOOKUP(AC4,'Axe 2 Règles de gestion'!$D$2:$F$366,3, FALSE) -> Le certificat médical doit attester de la gravité de la maladie, de l'accident ou du handicap et de la nécessité de la présence soutenue d'un parent et de soins contraignants. Il doit également préciser la durée de l'absence. | AE4: CPP_I_113 | AF4: =VLOOKUP(AE4,'Axe 2 Règles de gestion'!$D$2:$F$366,3, FALSE) -> L'agent indique, dans sa demande de congé, la ou les modalités d'utilisation du congé et les dates de congé prévisionnelles afférentes. | AG4: CPP_I_114 | AH4: =VLOOKUP(AG4,'Axe 2 Règles de gestion'!$D$2:$F$366,3, FALSE) -> L'agent doit informer par écrit l'administration avec un préavis d'au moins 48 heures des changements de la ou des modalités d'utilisation et des dates de congé prévisionnelles afférentes. | AI4: CPP_I_115 | AJ4: =VLOOKUP(AI4,'Axe 2 Règles de gestion'!$D$2:$F$366,3, FALSE) -> Les délais de préavis liés à la demande du congé ne s'appliquent pas en cas de dégradation soudaine de l'état de santé de l'enfant ou en cas de situation de crise nécessitant une présence immédiate auprès de l'enfant. | AK4: CPP_I_117 | AL4: =VLOOKUP(AK4,'Axe 2 Règles de gestion'!$D$2:$F$366,3, FALSE) -> Les délais de préavis liés au changement de modalités d'utilisation du congé ne s'appliquent pas en cas de dégradation soudaine de l'état de santé de l'enfant ou en cas de situation de crise nécessitant une présence immédiate auprès de l'enfant. | AM4: CPP_I_118 | AN4: =VLOOKUP(AM4,'Axe 2 Règles de gestion'!$D$2:$F$366,3, FALSE) -> Les délais de préavis liés au changement de dates prévisionnelles du congé ne s'appliquent pas en cas de dégradation soudaine de l'état de santé de l'enfant ou en cas de situation de crise nécessitant une présence immédiate auprès de l'enfant. | AO4: CPP_I_119 | AP4: =VLOOKUP(AO4,'Axe 2 Règles de gestion'!$D$2:$F$366,3, FALSE) -> La durée prévisible de traitement fait l'objet d'un nouvel examen dans un délai compris entre 6 mois et 1 an maximum. Ce nouvel examen donne lieu à un certificat médical transmis à l'autorité dont relève l'agent. | AQ4: CPP_I_001 | AR4: =VLOOKUP(AQ4,'Axe 2 Règles de gestion'!$D$2:$F$366,3, FALSE) -> Le congé est accordé de droit à l'agent. | AS4: CPP_I_014 | AT4: =VLOOKUP(AS4,'Axe 2 Règles de gestion'!$D$2:$F$366,3, FALSE) -> L'autorité qui a accordé le congé fait procéder aux enquêtes nécessaires pour s'assurer que l'activité de l'agent est réellement consacrée à donner des soins à son enfant. | AU4: CPP_I_009 | AV4: =VLOOKUP(AU4,'Axe 2 Règles de gestion'!$D$2:$F$366,3, FALSE) -> En cas de rechute ou de récidive de la pathologie qui affecte l'enfant, le bénéfice du droit à congé peut être rouvert pour une nouvelle période sur présentation d'un certificat médical le justifiant. | AW4: CPP_I_011 | AX4: =VLOOKUP(AW4,'Axe 2 Règles de gestion'!$D$2:$F$366,3, FALSE) -> En cas de nouvelle pathologie affectant l'enfant, de même qu'en cas de rechute ou de récidive de la pathologie initialement traitée, un nouveau droit à congé est ouvert à l'issue de la période de 36 mois. | AY4: CPP_I_120 | AZ4: =VLOOKUP(AY4,'Axe 2 Règles de gestion'!$D$2:$F$366,3, FALSE) -> Lorsque la gravité de la pathologie de l'enfant initialement traitée nécessite une présence soutenue et des soins contraignants, un nouveau congé est ouvert à l'issue de la période de 36 mois sur présentation d'un certificat médical le justifiant. | BA4: CPP_I_003 | BB4: =VLOOKUP(BA4,'Axe 2 Règles de gestion'!$D$2:$F$366,3, FALSE) -> Ce congé est ouvert au père ou à la mère. | BC4: CPP_I_314 | BD4: =VLOOKUP(BC4,'Axe 2 Règles de gestion'!$D$2:$F$366,3, FALSE) -> Dans la limite de 36 mois, l'agent peut choisir d'utiliser les 310 jours ouvrés de congé sous la forme soit d'une période continue, soit d'une ou plusieurs périodes fractionnées d'au moins d'une demi-journée soit d'un service à temps partiel. | BE4: CPP_I_008 | BF4: =VLOOKUP(BE4,'Axe 2 Règles de gestion'!$D$2:$F$366,3, FALSE) -> Au terme de la durée initiale, le bénéfice du droit à congé peut être prolongé sur présentation d'un certificat médical le justifiant. | BG4: CPP_I_121 | BH4: =VLOOKUP(BG4,'Axe 2 Règles de gestion'!$D$2:$F$366,3, FALSE) -> La demande de renouvellement ou de prolongation du congé doit être adressée par écrit au supérieur hiérarchique au moins 15 jours avant le terme du congé. | BI4: CPP_I_323 | BJ4: =VLOOKUP(BI4,'Axe 2 Règles de gestion'!$D$2:$F$366,3, FALSE) -> Le congé de présence parentale peut être fractionné et chaque absence doit être d'une durée minimale d'une demi-journée. | BO4: CPP_D_009 | BP4: =VLOOKUP(BO4,'Axe 2 Règles de gestion'!$D$2:$F$366,3, FALSE) -> La durée réelle de congé de présence parentale dont peut bénéficier le fonctionnaire pour un même enfant et en raison d'une même pathologie est au maximum de 310 jours ouvrés au cours d'une période de 36 mois. (date de fin réelle de l'absence). | BQ4: CPP_D_001 | BR4: =VLOOKUP(BQ4,'Axe 2 Règles de gestion'!$D$2:$F$366,3, FALSE) -> L'agent doit être en activité. | BS4: CPP_D_005 | BT4: =VLOOKUP(BS4,'Axe 2 Règles de gestion'!$D$2:$F$366,3, FALSE) -> L'agent doit avoir un enfant lié à ce congé. | BU4: CPP_D_025 | BV4: =VLOOKUP(BU4,'Axe 2 Règles de gestion'!$D$2:$F$366,3, FALSE) -> Au terme de la durée réelle initiale, ou en cas de rechute ou de récidive de la pathologie qui affecte l'enfant, le bénéfice du droit à congé peut être prolongé ou rouvert pour une nouvelle période sur présentation d'un certificat médical le justifiant, dans la limite des 310 jours et des 36 mois. Le décompte de la période de 36 mois s'effectue à partir de la date initiale d'ouverture du droit à congé. | CC4: ABS_C_001 | CD4: =VLOOKUP(CC4,'Axe 2 Règles de gestion'!$D$2:$F$366,3, FALSE) -> La date de début du congé/absence doit être postérieure ou égale à la date de recrutement dans la FPE ou dans la carrière militaire. | CE4: ABS_C_003 | CF4: =VLOOKUP(CE4,'Axe 2 Règles de gestion'!$D$2:$F$366,3, FALSE) -> La date de début du congé/absence doit être antérieure ou égale à la date de fin réelle du congé/absence. | CG4: ABS_C_004 | CH4: =VLOOKUP(CG4,'Axe 2 Règles de gestion'!$D$2:$F$366,3, FALSE) -> La date de début du congé/absence doit être antérieure ou égale à la date de fin prévisionnelle du congé/absence. | CI4: ABS_C_007 | CJ4: =VLOOKUP(CI4,'Axe 2 Règles de gestion'!$D$2:$F$366,3, FALSE) -> La date de fin réelle du congé/absence doit être antérieure à la date limite de départ à la retraite. | CK4: ABS_C_008 | CL4: =VLOOKUP(CK4,'Axe 2 Règles de gestion'!$D$2:$F$366,3, FALSE) -> La date de fin prévisionnelle du congé/absence doit être antérieure à la date limite de départ à la retraite. | CM4: ABS_C_009 | CN4: =VLOOKUP(CM4,'Axe 2 Règles de gestion'!$D$2:$F$366,3, FALSE) -> La date de fin réelle ou la date de fin prévisionnelle du congé/absence doit être saisie. | CO4: ABS_C_019 | CP4: =VLOOKUP(CO4,'Axe 2 Règles de gestion'!$D$2:$F$366,3, FALSE) -> Si l'absence ne commence pas par une demi-journée et si l'absence précédente ne finit pas par une demi journée, la date de début de l'absence saisie est postérieure à la date de fin réelle de l'absence précédente. | CQ4: ABS_C_020 | CR4: =VLOOKUP(CQ4,'Axe 2 Règles de gestion'!$D$2:$F$366,3, FALSE) -> Si l'absence ne commence pas par une demi-journée et si l'absence précédente ne finit pas par une demi journée, la date de début de l'absence saisie est postérieure à la date de fin prévisionnelle de l'absence précédente. | CS4: ABS_C_026 | CT4: =VLOOKUP(CS4,'Axe 2 Règles de gestion'!$D$2:$F$366,3, FALSE) -> Dans le cas d'un congé autre que CLM, CLD, CGM et CITIS, l'indicateur de requalification doit être à non et les impacts spécifiques à la requalification ne doivent pas être mobilisés ou l'impact rémunération est vide. | CU4: ABS_C_038 | CV4: =VLOOKUP(CU4,'Axe 2 Règles de gestion'!$D$2:$F$366,3, FALSE) -> Le congé prend fin à la date de décès de l'enfant (date de fin réelle). | CW4: ABS_C_039 | CX4: =VLOOKUP(CW4,'Axe 2 Règles de gestion'!$D$2:$F$366,3, FALSE) -> Le congé prend fin à la date de décès de l'enfant (date de fin prévisionnelle). | CY4: ABS_C_065 | CZ4: =VLOOKUP(CY4,'Axe 2 Règles de gestion'!$D$2:$F$366,3, FALSE) -> L'agent en congé de présence parentale / congé de proche aidant / congé de solidarité familiale ne peut se voir accorder de manière simultanée un temps partiel pour congé de présence parentale / pour congé de proche aidant / pour congé de solidarité familiale.
A5: 21.00.00 | B5: M | C5: 45223.632 | D5: D0007 | E5: Congés/Absence | F5: S0057 | G5: Congé de présence parentale | H5: E0478 | I5: Congé de présence parentale | J5: Congé saisi égal à 'Congé de présence parentale' | K5: A_COA_TYCOAB [Saisi] = 'CG102' | L5: T1167 | M5: Congé de présence parentale - Renouvellement | N5: Création Modification | O5: La valeur de l'Etat du congé est 'Renouvellement' et la valeur de l'Etat du congé saisie est différente de celle avant saisie | P5: A_COA_ETCOMA [Saisi] = 'EC02' ET A_COA_ETCOMA [Saisi] <> A_COA_ETCOMA [Valeur avant saisie] | Q5: Titulaire ou magistrat | R5: P0001 | S5: T | T5: Général | U5: Passant | V5: 40725 | W5: 44167 | X5: CPP_I_008 ET CPP_I_010 ET CPP_I_012 ET CPP_I_013 ET CPP_I_014 ET CPP_D_025 ET CPP_D_001 ET CPP_D_005 ET ABS_C_003 ET ABS_C_004 ET ABS_C_007 ET ABS_C_008 ET ABS_C_009 ET ABS_C_019 ET ABS_C_020 ET ABS_C_026 ET ABS_C_038 ET ABS_C_039 | Y5: CPP_I_008 | Z5: =VLOOKUP(Y5,'Axe 2 Règles de gestion'!$D$2:$F$366,3, FALSE) -> Au terme de la durée initiale, le bénéfice du droit à congé peut être prolongé sur présentation d'un certificat médical le justifiant. | AA5: CPP_I_010 | AB5: =VLOOKUP(AA5,'Axe 2 Règles de gestion'!$D$2:$F$366,3, FALSE) -> Si la durée du congé excède 6 mois, la pathologie et la nécessité de présence soutenue et de soins contraignants font tous les 6 mois l'objet d'un nouvel examen qui donne lieu à un certificat médical transmis sans délai à l'autorité dont relève l'agent. | AC5: CPP_I_012 | AD5: =VLOOKUP(AC5,'Axe 2 Règles de gestion'!$D$2:$F$366,3, FALSE) -> L'agent doit communiquer par écrit à l'autorité dont il relève le calendrier mensuel de ses journées de congé de présence parentale, au plus tard 15 jours avant le début de chaque mois. | AE5: CPP_I_013 | AF5: =VLOOKUP(AE5,'Axe 2 Règles de gestion'!$D$2:$F$366,3, FALSE) -> Lorsque l'agent souhaite prendre un ou plusieurs jours de congé ne correspondant pas au calendrier transmis, il doit en informer l'autorité au moins 48 heures à l'avance. | AG5: CPP_I_014 | AH5: =VLOOKUP(AG5,'Axe 2 Règles de gestion'!$D$2:$F$366,3, FALSE) -> L'autorité qui a accordé le congé fait procéder aux enquêtes nécessaires pour s'assurer que l'activité de l'agent est réellement consacrée à donner des soins à son enfant. | BO5: CPP_D_025 | BP5: =VLOOKUP(BO5,'Axe 2 Règles de gestion'!$D$2:$F$366,3, FALSE) -> Au terme de la durée réelle initiale, ou en cas de rechute ou de récidive de la pathologie qui affecte l'enfant, le bénéfice du droit à congé peut être prolongé ou rouvert pour une nouvelle période sur présentation d'un certificat médical le justifiant, dans la limite des 310 jours et des 36 mois. Le décompte de la période de 36 mois s'effectue à partir de la date initiale d'ouverture du droit à congé. | BQ5: CPP_D_001 | BR5: =VLOOKUP(BQ5,'Axe 2 Règles de gestion'!$D$2:$F$366,3, FALSE) -> L'agent doit être en activité. | BS5: CPP_D_005 | BT5: =VLOOKUP(BS5,'Axe 2 Règles de gestion'!$D$2:$F$366,3, FALSE) -> L'agent doit avoir un enfant lié à ce congé. | CC5: ABS_C_003 | CD5: =VLOOKUP(CC5,'Axe 2 Règles de gestion'!$D$2:$F$366,3, FALSE) -> La date de début du congé/absence doit être antérieure ou égale à la date de fin réelle du congé/absence. | CE5: ABS_C_004 | CF5: =VLOOKUP(CE5,'Axe 2 Règles de gestion'!$D$2:$F$366,3, FALSE) -> La date de début du congé/absence doit être antérieure ou égale à la date de fin prévisionnelle du congé/absence. | CG5: ABS_C_007 | CH5: =VLOOKUP(CG5,'Axe 2 Règles de gestion'!$D$2:$F$366,3, FALSE) -> La date de fin réelle du congé/absence doit être antérieure à la date limite de départ à la retraite. | CI5: ABS_C_008 | CJ5: =VLOOKUP(CI5,'Axe 2 Règles de gestion'!$D$2:$F$366,3, FALSE) -> La date de fin prévisionnelle du congé/absence doit être antérieure à la date limite de départ à la retraite. | CK5: ABS_C_009 | CL5: =VLOOKUP(CK5,'Axe 2 Règles de gestion'!$D$2:$F$366,3, FALSE) -> La date de fin réelle ou la date de fin prévisionnelle du congé/absence doit être saisie. | CM5: ABS_C_019 | CN5: =VLOOKUP(CM5,'Axe 2 Règles de gestion'!$D$2:$F$366,3, FALSE) -> Si l'absence ne commence pas par une demi-journée et si l'absence précédente ne finit pas par une demi journée, la date de début de l'absence saisie est postérieure à la date de fin réelle de l'absence précédente. | CO5: ABS_C_020 | CP5: =VLOOKUP(CO5,'Axe 2 Règles de gestion'!$D$2:$F$366,3, FALSE) -> Si l'absence ne commence pas par une demi-journée et si l'absence précédente ne finit pas par une demi journée, la date de début de l'absence saisie est postérieure à la date de fin prévisionnelle de l'absence précédente. | CQ5: ABS_C_026 | CR5: =VLOOKUP(CQ5,'Axe 2 Règles de gestion'!$D$2:$F$366,3, FALSE) -> Dans le cas d'un congé autre que CLM, CLD, CGM et CITIS, l'indicateur de requalification doit être à non et les impacts spécifiques à la requalification ne doivent pas être mobilisés ou l'impact rémunération est vide. | CS5: ABS_C_038 | CT5: =VLOOKUP(CS5,'Axe 2 Règles de gestion'!$D$2:$F$366,3, FALSE) -> Le congé prend fin à la date de décès de l'enfant (date de fin réelle). | CU5: ABS_C_039 | CV5: =VLOOKUP(CU5,'Axe 2 Règles de gestion'!$D$2:$F$366,3, FALSE) -> Le congé prend fin à la date de décès de l'enfant (date de fin prévisionnelle).
A6: 23.10.00 | B6: M | C6: 45223.632 | D6: D0007 | E6: Congés/Absence | F6: S0057 | G6: Congé de présence parentale | H6: E0478 | I6: Congé de présence parentale | J6: Congé saisi égal à 'Congé de présence parentale' | K6: A_COA_TYCOAB [Saisi] = 'CG102' | L6: T1167 | M6: Congé de présence parentale - Renouvellement | N6: Création Modification | O6: La valeur de l'Etat du congé est 'Renouvellement' et la valeur de l'Etat du congé saisie est différente de celle avant saisie | P6: A_COA_ETCOMA [Saisi] = 'EC02' ET A_COA_ETCOMA [Saisi] <> A_COA_ETCOMA [Valeur avant saisie] | Q6: Titulaire ou magistrat | R6: P0001 | S6: T | T6: Général | U6: Passant | V6: 44168 | W6: 45165 | X6: CPP_I_008 ET CPP_I_121 ET CPP_I_119 ET CPP_I_113 ET CPP_I_114 ET CPP_I_116 ET CPP_I_117 ET CPP_I_118 ET CPP_I_112 ET CPP_D_025 ET CPP_D_190 ET CPP_D_191 ET CPP_D_138 ET CPP_D_141 ET ABS_C_003 ET ABS_C_004 ET ABS_C_007 ET ABS_C_008 ET ABS_C_009 ET ABS_C_019 ET ABS_C_020 ET ABS_C_026 ET ABS_C_038 ET ABS_C_039 ET ABS_C_065 | Y6: CPP_I_008 | Z6: =VLOOKUP(Y6,'Axe 2 Règles de gestion'!$D$2:$F$366,3, FALSE) -> Au terme de la durée initiale, le bénéfice du droit à congé peut être prolongé sur présentation d'un certificat médical le justifiant. | AA6: CPP_I_121 | AB6: =VLOOKUP(AA6,'Axe 2 Règles de gestion'!$D$2:$F$366,3, FALSE) -> La demande de renouvellement ou de prolongation du congé doit être adressée par écrit au supérieur hiérarchique au moins 15 jours avant le terme du congé. | AC6: CPP_I_119 | AD6: =VLOOKUP(AC6,'Axe 2 Règles de gestion'!$D$2:$F$366,3, FALSE) -> La durée prévisible de traitement fait l'objet d'un nouvel examen dans un délai compris entre 6 mois et 1 an maximum. Ce nouvel examen donne lieu à un certificat médical transmis à l'autorité dont relève l'agent. | AE6: CPP_I_113 | AF6: =VLOOKUP(AE6,'Axe 2 Règles de gestion'!$D$2:$F$366,3, FALSE) -> L'agent indique, dans sa demande de congé, la ou les modalités d'utilisation du congé et les dates de congé prévisionnelles afférentes. | AG6: CPP_I_114 | AH6: =VLOOKUP(AG6,'Axe 2 Règles de gestion'!$D$2:$F$366,3, FALSE) -> L'agent doit informer par écrit l'administration avec un préavis d'au moins 48 heures des changements de la ou des modalités d'utilisation et des dates de congé prévisionnelles afférentes. | AI6: CPP_I_116 | AJ6: =VLOOKUP(AI6,'Axe 2 Règles de gestion'!$D$2:$F$366,3, FALSE) -> Les délais de préavis liés au renouvellement du congé ne s'appliquent pas en cas de dégradation soudaine de l'état de santé de l'enfant ou en cas de situation de crise nécessitant une présence immédiate auprès de l'enfant. | AK6: CPP_I_117 | AL6: =VLOOKUP(AK6,'Axe 2 Règles de gestion'!$D$2:$F$366,3, FALSE) -> Les délais de préavis liés au changement de modalités d'utilisation du congé ne s'appliquent pas en cas de dégradation soudaine de l'état de santé de l'enfant ou en cas de situation de crise nécessitant une présence immédiate auprès de l'enfant. | AM6: CPP_I_118 | AN6: =VLOOKUP(AM6,'Axe 2 Règles de gestion'!$D$2:$F$366,3, FALSE) -> Les délais de préavis liés au changement de dates prévisionnelles du congé ne s'appliquent pas en cas de dégradation soudaine de l'état de santé de l'enfant ou en cas de situation de crise nécessitant une présence immédiate auprès de l'enfant. | AO6: CPP_I_112 | AP6: =VLOOKUP(AO6,'Axe 2 Règles de gestion'!$D$2:$F$366,3, FALSE) -> Dans la limite de 36 mois, l'agent peut choisir d'utiliser les 310 jours ouvrés de congé sous la forme soit d'une période continue, soit d'une ou plusieurs périodes fractionnées d'au moins une journée soit d'un service à temps partiel. | BO6: CPP_D_025 | BP6: =VLOOKUP(BO6,'Axe 2 Règles de gestion'!$D$2:$F$366,3, FALSE) -> Au terme de la durée réelle initiale, ou en cas de rechute ou de récidive de la pathologie qui affecte l'enfant, le bénéfice du droit à congé peut être prolongé ou rouvert pour une nouvelle période sur présentation d'un certificat médical le justifiant, dans la limite des 310 jours et des 36 mois. Le décompte de la période de 36 mois s'effectue à partir de la date initiale d'ouverture du droit à congé. | BQ6: CPP_D_190 | BR6: =VLOOKUP(BQ6,'Axe 2 Règles de gestion'!$D$2:$F$366,3, FALSE) -> Le congé de présence parentale peut être fractionné mais chaque absence doit être d'une durée réelle minimale de 1 jour. | BS6: CPP_D_191 | BT6: =VLOOKUP(BS6,'Axe 2 Règles de gestion'!$D$2:$F$366,3, FALSE) -> Le congé de présence parentale peut être fractionné mais chaque absence doit être d'une durée prévisionnelle minimale de 1 jour. | BU6: CPP_D_138 | BV6: =VLOOKUP(BU6,'Axe 2 Règles de gestion'!$D$2:$F$366,3, FALSE) -> L'agent doit être en activité. | BW6: CPP_D_141 | BX6: =VLOOKUP(BW6,'Axe 2 Règles de gestion'!$D$2:$F$366,3, FALSE) -> L'agent doit avoir un enfant lié à ce congé. | CC6: ABS_C_003 | CD6: =VLOOKUP(CC6,'Axe 2 Règles de gestion'!$D$2:$F$366,3, FALSE) -> La date de début du congé/absence doit être antérieure ou égale à la date de fin réelle du congé/absence. | CE6: ABS_C_004 | CF6: =VLOOKUP(CE6,'Axe 2 Règles de gestion'!$D$2:$F$366,3, FALSE) -> La date de début du congé/absence doit être antérieure ou égale à la date de fin prévisionnelle du congé/absence. | CG6: ABS_C_007 | CH6: =VLOOKUP(CG6,'Axe 2 Règles de gestion'!$D$2:$F$366,3, FALSE) -> La date de fin réelle du congé/absence doit être antérieure à la date limite de départ à la retraite. | CI6: ABS_C_008 | CJ6: =VLOOKUP(CI6,'Axe 2 Règles de gestion'!$D$2:$F$366,3, FALSE) -> La date de fin prévisionnelle du congé/absence doit être antérieure à la date limite de départ à la retraite. | CK6: ABS_C_009 | CL6: =VLOOKUP(CK6,'Axe 2 Règles de gestion'!$D$2:$F$366,3, FALSE) -> La date de fin réelle ou la date de fin prévisionnelle du congé/absence doit être saisie. | CM6: ABS_C_019 | CN6: =VLOOKUP(CM6,'Axe 2 Règles de gestion'!$D$2:$F$366,3, FALSE) -> Si l'absence ne commence pas par une demi-journée et si l'absence précédente ne finit pas par une demi journée, la date de début de l'absence saisie est postérieure à la date de fin réelle de l'absence précédente. | CO6: ABS_C_020 | CP6: =VLOOKUP(CO6,'Axe 2 Règles de gestion'!$D$2:$F$366,3, FALSE) -> Si l'absence ne commence pas par une demi-journée et si l'absence précédente ne finit pas par une demi journée, la date de début de l'absence saisie est postérieure à la date de fin prévisionnelle de l'absence précédente. | CQ6: ABS_C_026 | CR6: =VLOOKUP(CQ6,'Axe 2 Règles de gestion'!$D$2:$F$366,3, FALSE) -> Dans le cas d'un congé autre que CLM, CLD, CGM et CITIS, l'indicateur de requalification doit être à non et les impacts spécifiques à la requalification ne doivent pas être mobilisés ou l'impact rémunération est vide. | CS6: ABS_C_038 | CT6: =VLOOKUP(CS6,'Axe 2 Règles de gestion'!$D$2:$F$366,3, FALSE) -> Le congé prend fin à la date de décès de l'enfant (date de fin réelle). | CU6: ABS_C_039 | CV6: =VLOOKUP(CU6,'Axe 2 Règles de gestion'!$D$2:$F$366,3, FALSE) -> Le congé prend fin à la date de décès de l'enfant (date de fin prévisionnelle). | CW6: ABS_C_065 | CX6: =VLOOKUP(CW6,'Axe 2 Règles de gestion'!$D$2:$F$366,3, FALSE) -> L'agent en congé de présence parentale / congé de proche aidant / congé de solidarité familiale ne peut se voir accorder de manière simultanée un temps partiel pour congé de présence parentale / pour congé de proche aidant / pour congé de solidarité familiale.
A7: 24.00.00 | B7: M | C7: 45412.449 | D7: D0007 | E7: Congés/Absence | F7: S0057 | G7: Congé de présence parentale | H7: E0478 | I7: Congé de présence parentale | J7: Congé saisi égal à 'Congé de présence parentale' | K7: A_COA_TYCOAB [Saisi] = 'CG102' | L7: T1167 | M7: Congé de présence parentale - Renouvellement | N7: Création Modification | O7: La valeur de l'Etat du congé est 'Renouvellement' et la valeur de l'Etat du congé saisie est différente de celle avant saisie | P7: A_COA_ETCOMA [Saisi] = 'EC02' ET A_COA_ETCOMA [Saisi] <> A_COA_ETCOMA [Valeur avant saisie] | Q7: Titulaire ou magistrat | R7: P0001 | S7: T | T7: Général | U7: Passant | V7: 45166 | X7: CPP_I_321 ET CPP_I_322 ET CPP_I_121 ET CPP_I_119 ET CPP_I_113 ET CPP_I_114 ET CPP_I_116 ET CPP_I_117 ET CPP_I_118 ET CPP_I_314 ET CPP_I_323 ET CPP_D_267 ET CPP_D_138 ET CPP_D_141 ET CPP_D_013 ET ABS_C_003 ET ABS_C_004 ET ABS_C_007 ET ABS_C_008 ET ABS_C_009 ET ABS_C_019 ET ABS_C_020 ET ABS_C_026 ET ABS_C_038 ET ABS_C_039 ET ABS_C_065 | Y7: CPP_I_321 | Z7: =VLOOKUP(Y7,'Axe 2 Règles de gestion'!$D$2:$F$366,3, FALSE) -> Lorsque le nombre maximal de jours de congé est atteint avant le terme de la période initiale, le congé peut être renouvelé une fois au titre de la même maladie ou du même handicap ou du fait de l'accident dont l'enfant a été victime. | AA7: CPP_I_322 | AB7: =VLOOKUP(AA7,'Axe 2 Règles de gestion'!$D$2:$F$366,3, FALSE) -> Le congé est renouvelé pour au maximum 310 jours ouvrés sur une nouvelle période de 36 mois. | AC7: CPP_I_121 | AD7: =VLOOKUP(AC7,'Axe 2 Règles de gestion'!$D$2:$F$366,3, FALSE) -> La demande de renouvellement ou de prolongation du congé doit être adressée par écrit au supérieur hiérarchique au moins 15 jours avant le terme du congé. | AE7: CPP_I_119 | AF7: =VLOOKUP(AE7,'Axe 2 Règles de gestion'!$D$2:$F$366,3, FALSE) -> La durée prévisible de traitement fait l'objet d'un nouvel examen dans un délai compris entre 6 mois et 1 an maximum. Ce nouvel examen donne lieu à un certificat médical transmis à l'autorité dont relève l'agent. | AG7: CPP_I_113 | AH7: =VLOOKUP(AG7,'Axe 2 Règles de gestion'!$D$2:$F$366,3, FALSE) -> L'agent indique, dans sa demande de congé, la ou les modalités d'utilisation du congé et les dates de congé prévisionnelles afférentes. | AI7: CPP_I_114 | AJ7: =VLOOKUP(AI7,'Axe 2 Règles de gestion'!$D$2:$F$366,3, FALSE) -> L'agent doit informer par écrit l'administration avec un préavis d'au moins 48 heures des changements de la ou des modalités d'utilisation et des dates de congé prévisionnelles afférentes. | AK7: CPP_I_116 | AL7: =VLOOKUP(AK7,'Axe 2 Règles de gestion'!$D$2:$F$366,3, FALSE) -> Les délais de préavis liés au renouvellement du congé ne s'appliquent pas en cas de dégradation soudaine de l'état de santé de l'enfant ou en cas de situation de crise nécessitant une présence immédiate auprès de l'enfant. | AM7: CPP_I_117 | AN7: =VLOOKUP(AM7,'Axe 2 Règles de gestion'!$D$2:$F$366,3, FALSE) -> Les délais de préavis liés au changement de modalités d'utilisation du congé ne s'appliquent pas en cas de dégradation soudaine de l'état de santé de l'enfant ou en cas de situation de crise nécessitant une présence immédiate auprès de l'enfant. | AO7: CPP_I_118 | AP7: =VLOOKUP(AO7,'Axe 2 Règles de gestion'!$D$2:$F$366,3, FALSE) -> Les délais de préavis liés au changement de dates prévisionnelles du congé ne s'appliquent pas en cas de dégradation soudaine de l'état de santé de l'enfant ou en cas de situation de crise nécessitant une présence immédiate auprès de l'enfant. | AQ7: CPP_I_314 | AR7: =VLOOKUP(AQ7,'Axe 2 Règles de gestion'!$D$2:$F$366,3, FALSE) -> Dans la limite de 36 mois, l'agent peut choisir d'utiliser les 310 jours ouvrés de congé sous la forme soit d'une période continue, soit d'une ou plusieurs périodes fractionnées d'au moins d'une demi-journée soit d'un service à temps partiel. | AS7: CPP_I_323 | AT7: =VLOOKUP(AS7,'Axe 2 Règles de gestion'!$D$2:$F$366,3, FALSE) -> Le congé de présence parentale peut être fractionné et chaque absence doit être d'une durée minimale d'une demi-journée. | BO7: CPP_D_267 | BP7: =VLOOKUP(BO7,'Axe 2 Règles de gestion'!$D$2:$F$366,3, FALSE) -> Avant le terme de la durée réelle initiale, le bénéfice du droit à congé peut être renouvelé pour une nouvelle période sur présentation d'un certificat médical le justifiant, dans la limite des 310 jours et des 36 mois. | BQ7: CPP_D_138 | BR7: =VLOOKUP(BQ7,'Axe 2 Règles de gestion'!$D$2:$F$366,3, FALSE) -> L'agent doit être en activité. | BS7: CPP_D_141 | BT7: =VLOOKUP(BS7,'Axe 2 Règles de gestion'!$D$2:$F$366,3, FALSE) -> L'agent doit avoir un enfant lié à ce congé. | BU7: CPP_D_013 | BV7: =VLOOKUP(BU7,'Axe 2 Règles de gestion'!$D$2:$F$366,3, FALSE) -> Attention : L'acte de RENOUVELLEMENT est à utiliser uniquement après épuisement des 310 jours accordés par l'acte INITIAL. L'acte de PROLONGATION est à utiliser pour prolonger les droits accordés par l'acte INITIAL ou l'acte de RENOUVELLEMENT. | CC7: ABS_C_003 | CD7: =VLOOKUP(CC7,'Axe 2 Règles de gestion'!$D$2:$F$366,3, FALSE) -> La date de début du congé/absence doit être antérieure ou égale à la date de fin réelle du congé/absence. | CE7: ABS_C_004 | CF7: =VLOOKUP(CE7,'Axe 2 Règles de gestion'!$D$2:$F$366,3, FALSE) -> La date de début du congé/absence doit être antérieure ou égale à la date de fin prévisionnelle du congé/absence. | CG7: ABS_C_007 | CH7: =VLOOKUP(CG7,'Axe 2 Règles de gestion'!$D$2:$F$366,3, FALSE) -> La date de fin réelle du congé/absence doit être antérieure à la date limite de départ à la retraite. | CI7: ABS_C_008 | CJ7: =VLOOKUP(CI7,'Axe 2 Règles de gestion'!$D$2:$F$366,3, FALSE) -> La date de fin prévisionnelle du congé/absence doit être antérieure à la date limite de départ à la retraite. | CK7: ABS_C_009 | CL7: =VLOOKUP(CK7,'Axe 2 Règles de gestion'!$D$2:$F$366,3, FALSE) -> La date de fin réelle ou la date de fin prévisionnelle du congé/absence doit être saisie. | CM7: ABS_C_019 | CN7: =VLOOKUP(CM7,'Axe 2 Règles de gestion'!$D$2:$F$366,3, FALSE) -> Si l'absence ne commence pas par une demi-journée et si l'absence précédente ne finit pas par une demi journée, la date de début de l'absence saisie est postérieure à la date de fin réelle de l'absence précédente. | CO7: ABS_C_020 | CP7: =VLOOKUP(CO7,'Axe 2 Règles de gestion'!$D$2:$F$366,3, FALSE) -> Si l'absence ne commence pas par une demi-journée et si l'absence précédente ne finit pas par une demi journée, la date de début de l'absence saisie est postérieure à la date de fin prévisionnelle de l'absence précédente. | CQ7: ABS_C_026 | CR7: =VLOOKUP(CQ7,'Axe 2 Règles de gestion'!$D$2:$F$366,3, FALSE) -> Dans le cas d'un congé autre que CLM, CLD, CGM et CITIS, l'indicateur de requalification doit être à non et les impacts spécifiques à la requalification ne doivent pas être mobilisés ou l'impact rémunération est vide. | CS7: ABS_C_038 | CT7: =VLOOKUP(CS7,'Axe 2 Règles de gestion'!$D$2:$F$366,3, FALSE) -> Le congé prend fin à la date de décès de l'enfant (date de fin réelle). | CU7: ABS_C_039 | CV7: =VLOOKUP(CU7,'Axe 2 Règles de gestion'!$D$2:$F$366,3, FALSE) -> Le congé prend fin à la date de décès de l'enfant (date de fin prévisionnelle). | CW7: ABS_C_065 | CX7: =VLOOKUP(CW7,'Axe 2 Règles de gestion'!$D$2:$F$366,3, FALSE) -> L'agent en congé de présence parentale / congé de proche aidant / congé de solidarité familiale ne peut se voir accorder de manière simultanée un temps partiel pour congé de présence parentale / pour congé de proche aidant / pour congé de solidarité familiale.
A8: 21.00.00 | B8: M | C8: 44298.4 | D8: D0007 | E8: Congés/Absence | F8: S0057 | G8: Congé de présence parentale | H8: E0478 | I8: Congé de présence parentale | J8: Congé saisi égal à 'Congé de présence parentale' | K8: A_COA_TYCOAB [Saisi] = 'CG102' | L8: T1168 | M8: Congé de présence parentale - Fin (Ancien dispositif) | N8: Modification | O8: La valeur de l'Etat du congé saisie est égale à celle avant saisie et ((la date de début du congé saisie est strictement inférieure au 03/12/2020 et la typologie de population est différente de ouvrier ou de militaire) ou (la date de début du congé saisie est inférieure au 30/04/2022 et la typologie de la population est militaire) ou (la typologie de population saisie est égale à ouvrier)) | P8: A_COA_ETCOMA [Saisi] = A_COA_ETCOMA [Valeur avant saisie] ET ((A_COA_DADBCA [Saisi] < 03/12/2020 ET A_CAR_TYPPOP [Dossier] PAS DANS ('O','M')) OU (A_COA_DADBCA [Saisi] < 30/04/2022 ET A_CAR_TYPPOP [Dossier] = 'M') OU (A_CAR_TYPPOP [Dossier] = 'O')) | Q8: Titulaire ou magistrat | R8: P0001 | S8: T | T8: Général | U8: Passant | V8: 40725 | W8: 45261 | X8: CPP_I_015 ET CPP_I_016 ET CPP_I_002 ET CPP_D_025 ET CPP_D_005 ET ABS_C_003 ET ABS_C_004 ET ABS_C_007 ET ABS_C_008 ET ABS_C_009 ET ABS_C_026 ET ABS_C_038 ET ABS_C_039 | Y8: CPP_I_015 | Z8: =VLOOKUP(Y8,'Axe 2 Règles de gestion'!$D$2:$F$366,3, FALSE) -> Si l'agent renonce au bénéfice de la durée restant à courir de ce congé, il en informe l'autorité dont il relève avec un préavis de 15 jours. | AA8: CPP_I_016 | AB8: =VLOOKUP(AA8,'Axe 2 Règles de gestion'!$D$2:$F$366,3, FALSE) -> Le droit à congé cesse de plein droit en cas de décès de l'enfant. | AC8: CPP_I_002 | AD8: =VLOOKUP(AC8,'Axe 2 Règles de gestion'!$D$2:$F$366,3, FALSE) -> A l'issue de la période du congé ou en cas de diminution des ressources du ménage ou en cas de décès de l'enfant, l'agent est réaffecté dans son ancien emploi. | BO8: CPP_D_025 | BP8: =VLOOKUP(BO8,'Axe 2 Règles de gestion'!$D$2:$F$366,3, FALSE) -> Au terme de la durée réelle initiale, ou en cas de rechute ou de récidive de la pathologie qui affecte l'enfant, le bénéfice du droit à congé peut être prolongé ou rouvert pour une nouvelle période sur présentation d'un certificat médical le justifiant, dans la limite des 310 jours et des 36 mois. Le décompte de la période de 36 mois s'effectue à partir de la date initiale d'ouverture du droit à congé. | BQ8: CPP_D_005 | BR8: =VLOOKUP(BQ8,'Axe 2 Règles de gestion'!$D$2:$F$366,3, FALSE) -> L'agent doit avoir un enfant lié à ce congé. | CC8: ABS_C_003 | CD8: =VLOOKUP(CC8,'Axe 2 Règles de gestion'!$D$2:$F$366,3, FALSE) -> La date de début du congé/absence doit être antérieure ou égale à la date de fin réelle du congé/absence. | CE8: ABS_C_004 | CF8: =VLOOKUP(CE8,'Axe 2 Règles de gestion'!$D$2:$F$366,3, FALSE) -> La date de début du congé/absence doit être antérieure ou égale à la date de fin prévisionnelle du congé/absence. | CG8: ABS_C_007 | CH8: =VLOOKUP(CG8,'Axe 2 Règles de gestion'!$D$2:$F$366,3, FALSE) -> La date de fin réelle du congé/absence doit être antérieure à la date limite de départ à la retraite. | CI8: ABS_C_008 | CJ8: =VLOOKUP(CI8,'Axe 2 Règles de gestion'!$D$2:$F$366,3, FALSE) -> La date de fin prévisionnelle du congé/absence doit être antérieure à la date limite de départ à la retraite. | CK8: ABS_C_009 | CL8: =VLOOKUP(CK8,'Axe 2 Règles de gestion'!$D$2:$F$366,3, FALSE) -> La date de fin réelle ou la date de fin prévisionnelle du congé/absence doit être saisie. | CM8: ABS_C_026 | CN8: =VLOOKUP(CM8,'Axe 2 Règles de gestion'!$D$2:$F$366,3, FALSE) -> Dans le cas d'un congé autre que CLM, CLD, CGM et CITIS, l'indicateur de requalification doit être à non et les impacts spécifiques à la requalification ne doivent pas être mobilisés ou l'impact rémunération est vide. | CO8: ABS_C_038 | CP8: =VLOOKUP(CO8,'Axe 2 Règles de gestion'!$D$2:$F$366,3, FALSE) -> Le congé prend fin à la date de décès de l'enfant (date de fin réelle). | CQ8: ABS_C_039 | CR8: =VLOOKUP(CQ8,'Axe 2 Règles de gestion'!$D$2:$F$366,3, FALSE) -> Le congé prend fin à la date de décès de l'enfant (date de fin prévisionnelle).
A9: 25.10.00 | B9: M | C9: 45938.43 | D9: D0007 | E9: Congés/Absence | F9: S0057 | G9: Congé de présence parentale | H9: E0478 | I9: Congé de présence parentale | J9: Congé saisi égal à 'Congé de présence parentale' | K9: A_COA_TYCOAB [Saisi] = 'CG102' | L9: T1168 | M9: Congé de présence parentale - Fin (Ancien dispositif) | N9: Modification | O9: La valeur de l'Etat du congé saisie est égale à celle avant saisie et ((la date de début du congé saisie est strictement inférieure au 03/12/2020 et la typologie de population est différente de ouvrier ou de militaire) ou (la date de début du congé saisie est inférieure au 30/04/2022 et la typologie de la population est militaire) ou (la typologie de population saisie est égale à ouvrier)) | P9: A_COA_ETCOMA [Saisi] = A_COA_ETCOMA [Valeur avant saisie] ET ((A_COA_DADBCA [Saisi] < 03/12/2020 ET A_CAR_TYPPOP [Dossier] PAS DANS ('O','M')) OU (A_COA_DADBCA [Saisi] < 30/04/2022 ET A_CAR_TYPPOP [Dossier] = 'M') OU (A_CAR_TYPPOP [Dossier] = 'O')) | Q9: Titulaire ou magistrat | R9: P0001 | S9: T | T9: Général | U9: Exclu | V9: 45262 | W9: 45930
