Workbook

Sheet Mode opératoire
B1: MODE OPERATOIRE
B2: La transaction s'effectue au niveau de la rubrique "Congés/absences", elle inclut l'ensemble des sous-rubriques listées ci-dessous : - Congés/absences - Complément pour congé / absence : impact rémunération On notera que : La sous-rubrique "Complément pour congé / absence : impact rémunération" est réputée, suite au découpage des absences en tranche de rémunération, avoir des dates de début et de fin alignées sur les dates de début et de fin de la sous-rubrique "Congés/absences" (contrôle bloquant)

Sheet Axe 1 Enchainement des RG
A1: Version | B1: Type de mise à jour | C1: Date de mise à jour | D1: Identifiant Domaine | E1: Libellé du Domaine | F1: Identifiant Sous-domaine | G1: Libellé du Sous-domaine | H1: Identifiant Evénement | I1: Libellé de l'évènement | J1: Libellé condition déclenchement Evènement | K1: Condition déclenchement Evènement | L1: Identifiant type d'évènement | M1: Libellé type d'évènement | N1: Type de mise à jour | O1: Libellé condition déclenchement Type Evènement | P1: Condition déclenchement Type Evènement | Q1: Libellé Population | R1: Codification Population | S1: Général / Particulier | T1: Passant / Exclu | U1: Date de début | V1: Date de fin | W1: Règles mobilisées | X1: Identifiant Règle de contrôle intellectuel 1 | Y1: Libellé Règle de contrôle intellectuel 1 | Z1: Identifiant Règle de contrôle intellectuel 2 | AA1: Libellé Règle de contrôle intellectuel 2 | AB1: Identifiant Règle de contrôle intellectuel 3 | AC1: Libellé Règle de contrôle intellectuel 3 | AD1: Identifiant Règle de contrôle intellectuel 4 | AE1: Libellé Règle de contrôle intellectuel 4 | AF1: Identifiant Règle de contrôle intellectuel 5 | AG1: Libellé Règle de contrôle intellectuel 5 | AH1: Identifiant Règle de contrôle intellectuel 6 | AI1: Libellé Règle de contrôle intellectuel 6 | AJ1: Identifiant Règle de condition 1 | AK1: Libellé Règle de condition 1 | AL1: Identifiant Règle de condition 2 | AM1: Libellé Règle de condition 2 | AN1: Identifiant Règle de condition 3 | AO1: Libellé Règle de condition 3 | AP1: Identifiant Règle de condition 4 | AQ1: Libellé Règle de condition 4 | AR1: Identifiant Règle de condition 5 | AS1: Libellé Règle de condition 5 | AT1: Identifiant Règle de contrôle 1 | AU1: Libellé Règle de contrôle 1 | AV1: Identifiant Règle de contrôle 2 | AW1: Libellé Règle de contrôle 2 | AX1: Identifiant Règle de contrôle 3 | AY1: Libellé Règle de contrôle 3 | AZ1: Identifiant Règle de contrôle 4 | BA1: Libellé Règle de contrôle 4 | BB1: Identifiant Règle de contrôle 5 | BC1: Libellé Règle de contrôle 5 | BD1: Identifiant Règle de contrôle 6 | BE1: Libellé Règle de contrôle 6 | BF1: Identifiant Règle de contrôle 7 | BG1: Libellé Règle de contrôle 7 | BH1: Identifiant Règle de contrôle 8 | BI1: Libellé Règle de contrôle 8 | BJ1: Identifiant Règle de contrôle 9 | BK1: Libellé Règle de contrôle 9 | BL1: Identifiant Règle de contrôle 10 | BM1: Libellé Règle de contrôle 10 | BN1: Identifiant Règle de contrôle 11 | BO1: Libellé Règle de contrôle 11 | BP1: Identifiant Règle de contrôle 12 | BQ1: Libellé Règle de contrôle 12 | BR1: Identifiant Règle de contrôle 13 | BS1: Libellé Règle de contrôle 13 | BT1: FIME | BU1: Statut de travail
A2: 19.00.00 | B2: M | C2: 43571.724 | D2: D0007 | E2: Congés/Absence | F2: S0060 | G2: Congé formation syndicale | H2: E0484 | I2: Congé pour formation syndicale | J2: Type de congé/absence saisi = 'Congé pour formation syndicale' | K2: A_COA_TYCOAB [Saisi] = 'CF005' | L2: T1177 | M2: Congé pour formation syndicale - Demande | N2: Création | Q2: Titulaire ou magistrat | R2: P0001 | S2: Général | T2: Passant | U2: 40725 | W2: CFS_I_002 ET CFS_I_001 ET CFS_I_003 ET CFS_I_004 ET CFS_I_005 ET CFS_D_002 ET CDI_D_045 ET CFS_D_001 ET ABS_C_041 ET ABS_C_001 ET ABS_C_003 ET ABS_C_004 ET ABS_C_007 ET ABS_C_008 ET ABS_C_019 ET ABS_C_020 ET ABS_C_009 ET ABS_C_026 | X2: CFS_I_002 | Y2: =VLOOKUP(X2,'Axe 2 Règles de gestion'!$D$2:$F$51,3, FALSE) -> Le congé est accordé pour effectuer un stage ou suivre une session dans l'un des centres ou instituts qui figurent sur une liste arrêtée tous les 3 ans par le ministre chargé de la fonction publique. | Z2: CFS_I_001 | AA2: =VLOOKUP(Z2,'Axe 2 Règles de gestion'!$D$2:$F$51,3, FALSE) -> L'agent doit formuler sa demande par écrit au chef de service au moins 1 mois à l'avance. | AB2: CFS_I_003 | AC2: =VLOOKUP(AB2,'Axe 2 Règles de gestion'!$D$2:$F$51,3, FALSE) -> Le congé est réputé accordé, à défaut de réponse expresse de l'administration au plus tard le 15ème jour qui précède le début du stage ou de la session. | AD2: CFS_I_004 | AE2: =VLOOKUP(AD2,'Axe 2 Règles de gestion'!$D$2:$F$51,3, FALSE) -> L'administration ne peut refuser le bénéfice du congé que pour des raisons liées aux nécessités du service. | AF2: CFS_I_005 | AG2: =VLOOKUP(AF2,'Axe 2 Règles de gestion'!$D$2:$F$51,3, FALSE) -> La commission administrative paritaire ou la commission d'avancement est informée de la décision de rejet ainsi que des motifs de refus. | AJ2: CFS_D_002 | AK2: =VLOOKUP(AJ2,'Axe 2 Règles de gestion'!$D$2:$F$51,3, FALSE) -> Le congé de formation syndicale est d'une durée maximale de 12 jours ouvrables par an. | AL2: CDI_D_045 | AM2: =VLOOKUP(AL2,'Axe 2 Règles de gestion'!$D$2:$F$51,3, FALSE) -> Les congés "Congé de citoyenneté", "Congé pour siéger auprès d'une association, d'une mutuelle ou d'une instance de l'Etat ou d'une collectivité territoriale" et "Congé pour formation syndicale" ne peuvent se cumuler qu'à concurrence de 12 jours ouvrables pour une même année. | AN2: CFS_D_001 | AO2: =VLOOKUP(AN2,'Axe 2 Règles de gestion'!$D$2:$F$51,3, FALSE) -> L'agent doit être en activité. | AT2: ABS_C_041 | AU2: =VLOOKUP(AT2,'Axe 2 Règles de gestion'!$D$2:$F$51,3, FALSE) -> La période de référence du compteur de suivi du cumul total du congé saisi doit être initialisée sur une période allant du 01/01 au 31/12 de la même année. | AV2: ABS_C_001 | AW2: =VLOOKUP(AV2,'Axe 2 Règles de gestion'!$D$2:$F$51,3, FALSE) -> La date de début du congé/absence doit être postérieure ou égale à la date de recrutement dans la FPE ou dans la carrière militaire. | AX2: ABS_C_003 | AY2: =VLOOKUP(AX2,'Axe 2 Règles de gestion'!$D$2:$F$51,3, FALSE) -> La date de début du congé/absence doit être antérieure ou égale à la date de fin réelle du congé/absence. | AZ2: ABS_C_004 | BA2: =VLOOKUP(AZ2,'Axe 2 Règles de gestion'!$D$2:$F$51,3, FALSE) -> La date de début du congé/absence doit être antérieure ou égale à la date de fin prévisionnelle du congé/absence. | BB2: ABS_C_007 | BC2: =VLOOKUP(BB2,'Axe 2 Règles de gestion'!$D$2:$F$51,3, FALSE) -> La date de fin réelle du congé/absence doit être antérieure à la date limite de départ à la retraite. | BD2: ABS_C_008 | BE2: =VLOOKUP(BD2,'Axe 2 Règles de gestion'!$D$2:$F$51,3, FALSE) -> La date de fin prévisionnelle du congé/absence doit être antérieure à la date limite de départ à la retraite. | BF2: ABS_C_019 | BG2: =VLOOKUP(BF2,'Axe 2 Règles de gestion'!$D$2:$F$51,3, FALSE) -> Si l'absence ne commence pas par une demi-journée et si l'absence précédente ne finit pas par une demi journée, la date de début de l'absence saisie est postérieure à la date de fin réelle de l'absence précédente. | BH2: ABS_C_020 | BI2: =VLOOKUP(BH2,'Axe 2 Règles de gestion'!$D$2:$F$51,3, FALSE) -> Si l'absence ne commence pas par une demi-journée et si l'absence précédente ne finit pas par une demi journée, la date de début de l'absence saisie est postérieure à la date de fin prévisionnelle de l'absence précédente. | BJ2: ABS_C_009 | BK2: =VLOOKUP(BJ2,'Axe 2 Règles de gestion'!$D$2:$F$51,3, FALSE) -> La date de fin réelle ou la date de fin prévisionnelle du congé/absence doit être saisie. | BL2: ABS_C_026 | BM2: =VLOOKUP(BL2,'Axe 2 Règles de gestion'!$D$2:$F$51,3, FALSE) -> Dans le cas d'un congé autre que CLM, CLD, CGM et CITIS, l'indicateur de requalification doit être à non et les impacts spécifiques à la requalification ne doivent pas être mobilisés ou l'impact rémunération est vide.
A3: 19.00.00 | B3: M | C3: 43571.649 | D3: D0007 | E3: Congés/Absence | F3: S0060 | G3: Congé formation syndicale | H3: E0484 | I3: Congé pour formation syndicale | J3: Type de congé/absence saisi = 'Congé pour formation syndicale' | K3: A_COA_TYCOAB [Saisi] = 'CF005' | L3: T1636 | M3: Congé pour formation syndicale - Fin | N3: Modification | Q3: Titulaire ou magistrat | R3: P0001 | S3: Général | T3: Passant | U3: 40725 | W3: CFS_I_006 ET CFS_D_002 ET CDI_D_045 ET ABS_C_003 ET ABS_C_004 ET ABS_C_007 ET ABS_C_008 ET ABS_C_009 ET ABS_C_026 ET ABS_C_041 | X3: CFS_I_006 | Y3: =VLOOKUP(X3,'Axe 2 Règles de gestion'!$D$2:$F$51,3, FALSE) -> Lors de la reprise de fonctions, l'agent remet à son chef de service l'attestation d'assiduité délivrée à l'issue de son stage. | AJ3: CFS_D_002 | AK3: =VLOOKUP(AJ3,'Axe 2 Règles de gestion'!$D$2:$F$51,3, FALSE) -> Le congé de formation syndicale est d'une durée maximale de 12 jours ouvrables par an. | AL3: CDI_D_045 | AM3: =VLOOKUP(AL3,'Axe 2 Règles de gestion'!$D$2:$F$51,3, FALSE) -> Les congés "Congé de citoyenneté", "Congé pour siéger auprès d'une association, d'une mutuelle ou d'une instance de l'Etat ou d'une collectivité territoriale" et "Congé pour formation syndicale" ne peuvent se cumuler qu'à concurrence de 12 jours ouvrables pour une même année. | AT3: ABS_C_003 | AU3: =VLOOKUP(AT3,'Axe 2 Règles de gestion'!$D$2:$F$51,3, FALSE) -> La date de début du congé/absence doit être antérieure ou égale à la date de fin réelle du congé/absence. | AV3: ABS_C_004 | AW3: =VLOOKUP(AV3,'Axe 2 Règles de gestion'!$D$2:$F$51,3, FALSE) -> La date de début du congé/absence doit être antérieure ou égale à la date de fin prévisionnelle du congé/absence. | AX3: ABS_C_007 | AY3: =VLOOKUP(AX3,'Axe 2 Règles de gestion'!$D$2:$F$51,3, FALSE) -> La date de fin réelle du congé/absence doit être antérieure à la date limite de départ à la retraite. | AZ3: ABS_C_008 | BA3: =VLOOKUP(AZ3,'Axe 2 Règles de gestion'!$D$2:$F$51,3, FALSE) -> La date de fin prévisionnelle du congé/absence doit être antérieure à la date limite de départ à la retraite. | BB3: ABS_C_009 | BC3: =VLOOKUP(BB3,'Axe 2 Règles de gestion'!$D$2:$F$51,3, FALSE) -> La date de fin réelle ou la date de fin prévisionnelle du congé/absence doit être saisie. | BD3: ABS_C_026 | BE3: =VLOOKUP(BD3,'Axe 2 Règles de gestion'!$D$2:$F$51,3, FALSE) -> Dans le cas d'un congé autre que CLM, CLD, CGM et CITIS, l'indicateur de requalification doit être à non et les impacts spécifiques à la requalification ne doivent pas être mobilisés ou l'impact rémunération est vide. | BF3: ABS_C_041 | BG3: =VLOOKUP(BF3,'Axe 2 Règles de gestion'!$D$2:$F$51,3, FALSE) -> La période de référence du compteur de suivi du cumul total du congé saisi doit être initialisée sur une période allant du 01/01 au 31/12 de la même année.
A4: 22.10.00 | B4: A | C4: 44886.487 | D4: D0007 | E4: Congés/Absence | F4: S0060 | G4: Congé formation syndicale | H4: E0484 | I4: Congé pour formation syndicale | J4: Type de congé/absence saisi = 'Congé pour formation syndicale' | K4: A_COA_TYCOAB [Saisi] = 'CF005' | L4: T1177 | M4: Congé pour formation syndicale - Demande | N4: Création | Q4: Militaire | R4: P0002 | S4: Général | T4: Exclu | U4: 43831
A5: 22.10.00 | B5: A | C5: 44886.487 | D5: D0007 | E5: Congés/Absence | F5: S0060 | G5: Congé formation syndicale | H5: E0484 | I5: Congé pour formation syndicale | J5: Type de congé/absence saisi = 'Congé pour formation syndicale' | K5: A_COA_TYCOAB [Saisi] = 'CF005' | L5: T1636 | M5: Congé pour formation syndicale - Fin | N5: Modification | Q5: Militaire | R5: P0002 | S5: Général | T5: Exclu | U5: 43831
A6: 22.10.00 | B6: M | C6: 44832.52 | D6: D0007 | E6: Congés/Absence | F6: S0060 | G6: Congé formation syndicale | H6: E0484 | I6: Congé pour formation syndicale | J6: Type de congé/absence saisi = 'Congé pour formation syndicale' | K6: A_COA_TYCOAB [Saisi] = 'CF005' | L6: T1177 | M6: Congé pour formation syndicale - Demande | N6: Création | Q6: Contractuel | R6: P0003 | S6: Général | T6: Passant | U6: 40725 | V6: 44677 | W6: CFS_I_002 ET CFS_I_001 ET CFS_I_003 ET CFS_I_004 ET CFS_I_005 ET CFS_D_004 ET CDI_D_047 ET CFS_D_003 ET ABS_C_002 ET ABS_C_003 ET ABS_C_004 ET ABS_C_005 ET ABS_C_006 ET ABS_C_007 ET ABS_C_008 ET ABS_C_009 ET ABS_C_019 ET ABS_C_020 ET ABS_C_026 ET ABS_C_041 | X6: CFS_I_002 | Y6: =VLOOKUP(X6,'Axe 2 Règles de gestion'!$D$2:$F$51,3, FALSE) -> Le congé est accordé pour effectuer un stage ou suivre une session dans l'un des centres ou instituts qui figurent sur une liste arrêtée tous les 3 ans par le ministre chargé de la fonction publique. | Z6: CFS_I_001 | AA6: =VLOOKUP(Z6,'Axe 2 Règles de gestion'!$D$2:$F$51,3, FALSE) -> L'agent doit formuler sa demande par écrit au chef de service au moins 1 mois à l'avance. | AB6: CFS_I_003 | AC6: =VLOOKUP(AB6,'Axe 2 Règles de gestion'!$D$2:$F$51,3, FALSE) -> Le congé est réputé accordé, à défaut de réponse expresse de l'administration au plus tard le 15ème jour qui précède le début du stage ou de la session. | AD6: CFS_I_004 | AE6: =VLOOKUP(AD6,'Axe 2 Règles de gestion'!$D$2:$F$51,3, FALSE) -> L'administration ne peut refuser le bénéfice du congé que pour des raisons liées aux nécessités du service. | AF6: CFS_I_005 | AG6: =VLOOKUP(AF6,'Axe 2 Règles de gestion'!$D$2:$F$51,3, FALSE) -> La commission administrative paritaire ou la commission d'avancement est informée de la décision de rejet ainsi que des motifs de refus. | AJ6: CFS_D_004 | AK6: =VLOOKUP(AJ6,'Axe 2 Règles de gestion'!$D$2:$F$51,3, FALSE) -> Le congé est d'une durée maximale de 12 jours ouvrables par an. | AL6: CDI_D_047 | AM6: =VLOOKUP(AL6,'Axe 2 Règles de gestion'!$D$2:$F$51,3, FALSE) -> Les congés "Congé de formation de cadres et d'animateurs pour la jeunesse", "Congé pour siéger auprès d'une association, d'une mutuelle ou d'une instance de l'Etat ou d'une collectivité territoriale" et "Congé pour formation syndicale" ne peuvent se cumuler qu'à concurrence de 12 jours ouvrables pour une même année. | AN6: CFS_D_003 | AO6: =VLOOKUP(AN6,'Axe 2 Règles de gestion'!$D$2:$F$51,3, FALSE) -> L'agent doit être en activité. | AT6: ABS_C_002 | AU6: =VLOOKUP(AT6,'Axe 2 Règles de gestion'!$D$2:$F$51,3, FALSE) -> La date de début du congé/absence doit être postérieure ou égale à la date de début du lien juridique. | AV6: ABS_C_003 | AW6: =VLOOKUP(AV6,'Axe 2 Règles de gestion'!$D$2:$F$51,3, FALSE) -> La date de début du congé/absence doit être antérieure ou égale à la date de fin réelle du congé/absence. | AX6: ABS_C_004 | AY6: =VLOOKUP(AX6,'Axe 2 Règles de gestion'!$D$2:$F$51,3, FALSE) -> La date de début du congé/absence doit être antérieure ou égale à la date de fin prévisionnelle du congé/absence. | AZ6: ABS_C_005 | BA6: =VLOOKUP(AZ6,'Axe 2 Règles de gestion'!$D$2:$F$51,3, FALSE) -> La date de fin réelle du congé/absence doit être antérieure ou égale à la date limite de fin réelle ou prévisionnelle du lien juridique. | BB6: ABS_C_006 | BC6: =VLOOKUP(BB6,'Axe 2 Règles de gestion'!$D$2:$F$51,3, FALSE) -> La date de fin prévisionnelle du congé/absence doit être antérieure ou égale à la date limite de fin réelle ou prévisionnelle du lien juridique. | BD6: ABS_C_007 | BE6: =VLOOKUP(BD6,'Axe 2 Règles de gestion'!$D$2:$F$51,3, FALSE) -> La date de fin réelle du congé/absence doit être antérieure à la date limite de départ à la retraite. | BF6: ABS_C_008 | BG6: =VLOOKUP(BF6,'Axe 2 Règles de gestion'!$D$2:$F$51,3, FALSE) -> La date de fin prévisionnelle du congé/absence doit être antérieure à la date limite de départ à la retraite. | BH6: ABS_C_009 | BI6: =VLOOKUP(BH6,'Axe 2 Règles de gestion'!$D$2:$F$51,3, FALSE) -> La date de fin réelle ou la date de fin prévisionnelle du congé/absence doit être saisie. | BJ6: ABS_C_019 | BK6: =VLOOKUP(BJ6,'Axe 2 Règles de gestion'!$D$2:$F$51,3, FALSE) -> Si l'absence ne commence pas par une demi-journée et si l'absence précédente ne finit pas par une demi journée, la date de début de l'absence saisie est postérieure à la date de fin réelle de l'absence précédente. | BL6: ABS_C_020 | BM6: =VLOOKUP(BL6,'Axe 2 Règles de gestion'!$D$2:$F$51,3, FALSE) -> Si l'absence ne commence pas par une demi-journée et si l'absence précédente ne finit pas par une demi journée, la date de début de l'absence saisie est postérieure à la date de fin prévisionnelle de l'absence précédente. | BN6: ABS_C_026 | BO6: =VLOOKUP(BN6,'Axe 2 Règles de gestion'!$D$2:$F$51,3, FALSE) -> Dans le cas d'un congé autre que CLM, CLD, CGM et CITIS, l'indicateur de requalification doit être à non et les impacts spécifiques à la requalification ne doivent pas être mobilisés ou l'impact rémunération est vide. | BP6: ABS_C_041 | BQ6: =VLOOKUP(BP6,'Axe 2 Règles de gestion'!$D$2:$F$51,3, FALSE) -> La période de référence du compteur de suivi du cumul total du congé saisi doit être initialisée sur une période allant du 01/01 au 31/12 de la même année.
A7: 22.10.00 | B7: A | C7: 44832.521 | D7: D0007 | E7: Congés/Absence | F7: S0060 | G7: Congé formation syndicale | H7: E0484 | I7: Congé pour formation syndicale | J7: Type de congé/absence saisi = 'Congé pour formation syndicale' | K7: A_COA_TYCOAB [Saisi] = 'CF005' | L7: T1177 | M7: Congé pour formation syndicale - Demande | N7: Création | Q7: Contractuel | R7: P0003 | S7: Général | T7: Passant | U7: 44678 | W7: CFS_I_002 ET CFS_I_001 ET CFS_I_003 ET CFS_I_004 ET CFS_I_015 ET CFS_D_004 ET CDI_D_047 ET CFS_D_003 ET ABS_C_002 ET ABS_C_003 ET ABS_C_004 ET ABS_C_005 ET ABS_C_006 ET ABS_C_007 ET ABS_C_008 ET ABS_C_009 ET ABS_C_019 ET ABS_C_020 ET ABS_C_026 ET ABS_C_041 | X7: CFS_I_002 | Y7: =VLOOKUP(X7,'Axe 2 Règles de gestion'!$D$2:$F$51,3, FALSE) -> Le congé est accordé pour effectuer un stage ou suivre une session dans l'un des centres ou instituts qui figurent sur une liste arrêtée tous les 3 ans par le ministre chargé de la fonction publique. | Z7: CFS_I_001 | AA7: =VLOOKUP(Z7,'Axe 2 Règles de gestion'!$D$2:$F$51,3, FALSE) -> L'agent doit formuler sa demande par écrit au chef de service au moins 1 mois à l'avance. | AB7: CFS_I_003 | AC7: =VLOOKUP(AB7,'Axe 2 Règles de gestion'!$D$2:$F$51,3, FALSE) -> Le congé est réputé accordé, à défaut de réponse expresse de l'administration au plus tard le 15ème jour qui précède le début du stage ou de la session. | AD7: CFS_I_004 | AE7: =VLOOKUP(AD7,'Axe 2 Règles de gestion'!$D$2:$F$51,3, FALSE) -> L'administration ne peut refuser le bénéfice du congé que pour des raisons liées aux nécessités du service. | AF7: CFS_I_015 | AG7: =VLOOKUP(AF7,'Axe 2 Règles de gestion'!$D$2:$F$51,3, FALSE) -> La décision de refus d'octroi du congé fait l'objet d'une saisie pour avis de la commission consultative paritaire. | AJ7: CFS_D_004 | AK7: =VLOOKUP(AJ7,'Axe 2 Règles de gestion'!$D$2:$F$51,3, FALSE) -> Le congé est d'une durée maximale de 12 jours ouvrables par an. | AL7: CDI_D_047 | AM7: =VLOOKUP(AL7,'Axe 2 Règles de gestion'!$D$2:$F$51,3, FALSE) -> Les congés "Congé de formation de cadres et d'animateurs pour la jeunesse", "Congé pour siéger auprès d'une association, d'une mutuelle ou d'une instance de l'Etat ou d'une collectivité territoriale" et "Congé pour formation syndicale" ne peuvent se cumuler qu'à concurrence de 12 jours ouvrables pour une même année. | AN7: CFS_D_003 | AO7: =VLOOKUP(AN7,'Axe 2 Règles de gestion'!$D$2:$F$51,3, FALSE) -> L'agent doit être en activité. | AT7: ABS_C_002 | AU7: =VLOOKUP(AT7,'Axe 2 Règles de gestion'!$D$2:$F$51,3, FALSE) -> La date de début du congé/absence doit être postérieure ou égale à la date de début du lien juridique. | AV7: ABS_C_003 | AW7: =VLOOKUP(AV7,'Axe 2 Règles de gestion'!$D$2:$F$51,3, FALSE) -> La date de début du congé/absence doit être antérieure ou égale à la date de fin réelle du congé/absence. | AX7: ABS_C_004 | AY7: =VLOOKUP(AX7,'Axe 2 Règles de gestion'!$D$2:$F$51,3, FALSE) -> La date de début du congé/absence doit être antérieure ou égale à la date de fin prévisionnelle du congé/absence. | AZ7: ABS_C_005 | BA7: =VLOOKUP(AZ7,'Axe 2 Règles de gestion'!$D$2:$F$51,3, FALSE) -> La date de fin réelle du congé/absence doit être antérieure ou égale à la date limite de fin réelle ou prévisionnelle du lien juridique. | BB7: ABS_C_006 | BC7: =VLOOKUP(BB7,'Axe 2 Règles de gestion'!$D$2:$F$51,3, FALSE) -> La date de fin prévisionnelle du congé/absence doit être antérieure ou égale à la date limite de fin réelle ou prévisionnelle du lien juridique. | BD7: ABS_C_007 | BE7: =VLOOKUP(BD7,'Axe 2 Règles de gestion'!$D$2:$F$51,3, FALSE) -> La date de fin réelle du congé/absence doit être antérieure à la date limite de départ à la retraite. | BF7: ABS_C_008 | BG7: =VLOOKUP(BF7,'Axe 2 Règles de gestion'!$D$2:$F$51,3, FALSE) -> La date de fin prévisionnelle du congé/absence doit être antérieure à la date limite de départ à la retraite. | BH7: ABS_C_009 | BI7: =VLOOKUP(BH7,'Axe 2 Règles de gestion'!$D$2:$F$51,3, FALSE) -> La date de fin réelle ou la date de fin prévisionnelle du congé/absence doit être saisie. | BJ7: ABS_C_019 | BK7: =VLOOKUP(BJ7,'Axe 2 Règles de gestion'!$D$2:$F$51,3, FALSE) -> Si l'absence ne commence pas par une demi-journée et si l'absence précédente ne finit pas par une demi journée, la date de début de l'absence saisie est postérieure à la date de fin réelle de l'absence précédente. | BL7: ABS_C_020 | BM7: =VLOOKUP(BL7,'Axe 2 Règles de gestion'!$D$2:$F$51,3, FALSE) -> Si l'absence ne commence pas par une demi-journée et si l'absence précédente ne finit pas par une demi journée, la date de début de l'absence saisie est postérieure à la date de fin prévisionnelle de l'absence précédente. | BN7: ABS_C_026 | BO7: =VLOOKUP(BN7,'Axe 2 Règles de gestion'!$D$2:$F$51,3, FALSE) -> Dans le cas d'un congé autre que CLM, CLD, CGM et CITIS, l'indicateur de requalification doit être à non et les impacts spécifiques à la requalification ne doivent pas être mobilisés ou l'impact rémunération est vide. | BP7: ABS_C_041 | BQ7: =VLOOKUP(BP7,'Axe 2 Règles de gestion'!$D$2:$F$51,3, FALSE) -> La période de référence du compteur de suivi du cumul total du congé saisi doit être initialisée sur une période allant du 01/01 au 31/12 de la même année.
A8: 19.00.00 | B8: M | C8: 43572.462 | D8: D0007 | E8: Congés/Absence | F8: S0060 | G8: Congé formation syndicale | H8: E0484 | I8: Congé pour formation syndicale | J8: Type de congé/absence saisi = 'Congé pour formation syndicale' | K8: A_COA_TYCOAB [Saisi] = 'CF005' | L8: T1636 | M8: Congé pour formation syndicale - Fin | N8: Modification | Q8: Contractuel | R8: P0003 | S8: Général | T8: Passant | U8: 40725 | W8: CFS_I_006 ET CFS_D_004 ET CDI_D_047 ET ABS_C_003 ET ABS_C_004 ET ABS_C_005 ET ABS_C_006 ET ABS_C_007 ET ABS_C_008 ET ABS_C_009 ET ABS_C_026 ET ABS_C_041 | X8: CFS_I_006 | Y8: =VLOOKUP(X8,'Axe 2 Règles de gestion'!$D$2:$F$51,3, FALSE) -> Lors de la reprise de fonctions, l'agent remet à son chef de service l'attestation d'assiduité délivrée à l'issue de son stage. | AJ8: CFS_D_004 | AK8: =VLOOKUP(AJ8,'Axe 2 Règles de gestion'!$D$2:$F$51,3, FALSE) -> Le congé est d'une durée maximale de 12 jours ouvrables par an. | AL8: CDI_D_047 | AM8: =VLOOKUP(AL8,'Axe 2 Règles de gestion'!$D$2:$F$51,3, FALSE) -> Les congés "Congé de formation de cadres et d'animateurs pour la jeunesse", "Congé pour siéger auprès d'une association, d'une mutuelle ou d'une instance de l'Etat ou d'une collectivité territoriale" et "Congé pour formation syndicale" ne peuvent se cumuler qu'à concurrence de 12 jours ouvrables pour une même année. | AT8: ABS_C_003 | AU8: =VLOOKUP(AT8,'Axe 2 Règles de gestion'!$D$2:$F$51,3, FALSE) -> La date de début du congé/absence doit être antérieure ou égale à la date de fin réelle du congé/absence. | AV8: ABS_C_004 | AW8: =VLOOKUP(AV8,'Axe 2 Règles de gestion'!$D$2:$F$51,3, FALSE) -> La date de début du congé/absence doit être antérieure ou égale à la date de fin prévisionnelle du congé/absence. | AX8: ABS_C_005 | AY8: =VLOOKUP(AX8,'Axe 2 Règles de gestion'!$D$2:$F$51,3, FALSE) -> La date de fin réelle du congé/absence doit être antérieure ou égale à la date limite de fin réelle ou prévisionnelle du lien juridique. | AZ8: ABS_C_006 | BA8: =VLOOKUP(AZ8,'Axe 2 Règles de gestion'!$D$2:$F$51,3, FALSE) -> La date de fin prévisionnelle du congé/absence doit être antérieure ou égale à la date limite de fin réelle ou prévisionnelle du lien juridique. | BB8: ABS_C_007 | BC8: =VLOOKUP(BB8,'Axe 2 Règles de gestion'!$D$2:$F$51,3, FALSE) -> La date de fin réelle du congé/absence doit être antérieure à la date limite de départ à la retraite. | BD8: ABS_C_008 | BE8: =VLOOKUP(BD8,'Axe 2 Règles de gestion'!$D$2:$F$51,3, FALSE) -> La date de fin prévisionnelle du congé/absence doit être antérieure à la date limite de départ à la retraite. | BF8: ABS_C_009 | BG8: =VLOOKUP(BF8,'Axe 2 Règles de gestion'!$D$2:$F$51,3, FALSE) -> La date de fin réelle ou la date de fin prévisionnelle du congé/absence doit être saisie. | BH8: ABS_C_026 | BI8: =VLOOKUP(BH8,'Axe 2 Règles de gestion'!$D$2:$F$51,3, FALSE) -> Dans le cas d'un congé autre que CLM, CLD, CGM et CITIS, l'indicateur de requalification doit être à non et les impacts spécifiques à la requalification ne doivent pas être mobilisés ou l'impact rémunération est vide. | BJ8: ABS_C_041 | BK8: =VLOOKUP(BJ8,'Axe 2 Règles de gestion'!$D$2:$F$51,3, FALSE) -> La période de référence du compteur de suivi du cumul total du congé saisi doit être initialisée sur une période allant du 01/01 au 31/12 de la même année.
A9: 19.00.00 | B9: M | C9: 43571.725 | D9: D0007 | E9: Congés/Absence | F9: S0060 | G9: Congé formation syndicale | H9: E0484 | I9: Congé pour formation syndicale | J9: Type de congé/absence saisi = 'Congé pour formation syndicale' | K9: A_COA_TYCOAB [Saisi] = 'CF005' | L9: T1177 | M9: Congé pour formation syndicale - Demande | N9: Création | Q9: Stagiaire ou auditeur ou élève | R9: P0004 | S9: Général | T9: Passant | U9: 40725 | W9: CFS_I_002 ET CFS_I_001 ET CFS_I_003 ET CFS_I_004 ET CFS_I_005 ET CFS_D_002 ET CDI_D_045 ET CFS_D_001 ET ABS_C_001 ET ABS_C_003 ET ABS_C_004 ET ABS_C_007 ET ABS_C_008 ET ABS_C_009 ET ABS_C_019 ET ABS_C_020 ET ABS_C_026 ET ABS_C_041 | X9: CFS_I_002 | Y9: =VLOOKUP(X9,'Axe 2 Règles de gestion'!$D$2:$F$51,3, FALSE) -> Le congé est accordé pour effectuer un stage ou suivre une session dans l'un des centres ou instituts qui figurent sur une liste arrêtée tous les 3 ans par le ministre chargé de la fonction publique. | Z9: CFS_I_001 | AA9: =VLOOKUP(Z9,'Axe 2 Règles de gestion'!$D$2:$F$51,3, FALSE) -> L'agent doit formuler sa demande par écrit au chef de service au moins 1 mois à l'avance. | AB9: CFS_I_003 | AC9: =VLOOKUP(AB9,'Axe 2 Règles de gestion'!$D$2:$F$51,3, FALSE) -> Le congé est réputé accordé, à défaut de réponse expresse de l'administration au plus tard le 15ème jour qui précède le début du stage ou de la session. | AD9: CFS_I_004 | AE9: =VLOOKUP(AD9,'Axe 2 Règles de gestion'!$D$2:$F$51,3, FALSE) -> L'administration ne peut refuser le bénéfice du congé que pour des raisons liées aux nécessités du service. | AF9: CFS_I_005 | AG9: =VLOOKUP(AF9,'Axe 2 Règles de gestion'!$D$2:$F$51,3, FALSE) -> La commission administrative paritaire ou la commission d'avancement est informée de la décision de rejet ainsi que des motifs de refus. | AJ9: CFS_D_002 | AK9: =VLOOKUP(AJ9,'Axe 2 Règles de gestion'!$D$2:$F$51,3, FALSE) -> Le congé de formation syndicale est d'une durée maximale de 12 jours ouvrables par an. | AL9: CDI_D_045 | AM9: =VLOOKUP(AL9,'Axe 2 Règles de gestion'!$D$2:$F$51,3, FALSE) -> Les congés "Congé de citoyenneté", "Congé pour siéger auprès d'une association, d'une mutuelle ou d'une instance de l'Etat ou d'une collectivité territoriale" et "Congé pour formation syndicale" ne peuvent se cumuler qu'à concurrence de 12 jours ouvrables pour une même année. | AN9: CFS_D_001 | AO9: =VLOOKUP(AN9,'Axe 2 Règles de gestion'!$D$2:$F$51,3, FALSE) -> L'agent doit être en activité. | AT9: ABS_C_001 | AU9: =VLOOKUP(AT9,'Axe 2 Règles de gestion'!$D$2:$F$51,3, FALSE) -> La date de début du congé/absence doit être postérieure ou égale à la date de recrutement dans la FPE ou dans la carrière militaire. | AV9: ABS_C_003 | AW9: =VLOOKUP(AV9,'Axe 2 Règles de gestion'!$D$2:$F$51,3, FALSE) -> La date de début du congé/absence doit être antérieure ou égale à la date de fin réelle du congé/absence. | AX9: ABS_C_004 | AY9: =VLOOKUP(AX9,'Axe 2 Règles de gestion'!$D$2:$F$51,3, FALSE) -> La date de début du congé/absence doit être antérieure ou égale à la date de fin prévisionnelle du congé/absence. | AZ9: ABS_C_007 | BA9: =VLOOKUP(AZ9,'Axe 2 Règles de gestion'!$D$2:$F$51,3, FALSE) -> La date de fin réelle du congé/absence doit être antérieure à la date limite de départ à la retraite. | BB9: ABS_C_008 | BC9: =VLOOKUP(BB9,'Axe 2 Règles de gestion'!$D$2:$F$51,3, FALSE) -> La date de fin prévisionnelle du congé/absence doit être antérieure à la date limite de départ à la retraite. | BD9: ABS_C_009 | BE9: =VLOOKUP(BD9,'Axe 2 Règles de gestion'!$D$2:$F$51,3, FALSE) -> La date de fin réelle ou la date de fin prévisionnelle du congé/absence doit être saisie. | BF9: ABS_C_019 | BG9: =VLOOKUP(BF9,'Axe 2 Règles de gestion'!$D$2:$F$51,3, FALSE) -> Si l'absence ne commence pas par une demi-journée et si l'absence précédente ne finit pas par une demi journée, la date de début de l'absence saisie est postérieure à la date de fin réelle de l'absence précédente. | BH9: ABS_C_020 | BI9: =VLOOKUP(BH9,'Axe 2 Règles de gestion'!$D$2:$F$51,3, FALSE) -> Si l'absence ne commence pas par une demi-journée et si l'absence précédente ne finit pas par une demi journée, la date de début de l'absence saisie est postérieure à la date de fin prévisionnelle de l'absence précédente. | BJ9: ABS_C_026 | BK9: =VLOOKUP(BJ9,'Axe 2 Règles de gestion'!$D$2:$F$51,3, FALSE) -> Dans le cas d'un congé autre que CLM, CLD, CGM et CITIS, l'indicateur de requalification doit être à non et les impacts spécifiques à la requalification ne doivent pas être mobilisés ou l'impact rémunération est vide. | BL9: ABS_C_041 | BM9: =VLOOKUP(BL9,'Axe 2 Règles de gestion'!$D$2:$F$51,3, FALSE) -> La période de référence du compteur de suivi du cumul total du congé saisi doit être initialisée sur une période allant du 01/01 au 31/12 de la même année.
A10: 19.00.00 | B10: M | C10: 43572.461 | D10: D0007 | E10: Congés/Absence | F10: S0060 | G10: Congé formation syndicale | H10: E0484 | I10: Congé pour formation syndicale | J10: Type de congé/absence saisi = 'Congé pour formation syndicale' | K10: A_COA_TYCOAB [Saisi] = 'CF005' | L10: T1636 | M10: Congé pour formation syndicale - Fin | N10: Modification | Q10: Stagiaire ou auditeur ou élève | R10: P0004 | S10: Général | T10: Passant | U10: 40725 | W10: CFS_I_006 ET CFS_D_002 ET CDI_D_045 ET ABS_C_003 ET ABS_C_004 ET ABS_C_007 ET ABS_C_008 ET ABS_C_009 ET ABS_C_026 ET ABS_C_041 | X10: CFS_I_006 | Y10: =VLOOKUP(X10,'Axe 2 Règles de gestion'!$D$2:$F$51,3, FALSE) -> Lors de la reprise de fonctions, l'agent remet à son chef de service l'attestation d'assiduité délivrée à l'issue de son stage. | AJ10: CFS_D_002 | AK10: =VLOOKUP(AJ10,'Axe 2 Règles de gestion'!$D$2:$F$51,3, FALSE) -> Le congé de formation syndicale est d'une durée maximale de 12 jours ouvrables par an. | AL10: CDI_D_045 | AM10: =VLOOKUP(AL10,'Axe 2 Règles de gestion'!$D$2:$F$51,3, FALSE) -> Les congés "Congé de citoyenneté", "Congé pour siéger auprès d'une association, d'une mutuelle ou d'une instance de l'Etat ou d'une collectivité territoriale" et "Congé pour formation syndicale" ne peuvent se cumuler qu'à concurrence de 12 jours ouvrables pour une même année. | AT10: ABS_C_003 | AU10: =VLOOKUP(AT10,'Axe 2 Règles de gestion'!$D$2:$F$51,3, FALSE) -> La date de début du congé/absence doit être antérieure ou égale à la date de fin réelle du congé/absence. | AV10: ABS_C_004 | AW10: =VLOOKUP(AV10,'Axe 2 Règles de gestion'!$D$2:$F$51,3, FALSE) -> La date de début du congé/absence doit être antérieure ou égale à la date de fin prévisionnelle du congé/absence. | AX10: ABS_C_007 | AY10: =VLOOKUP(AX10,'Axe 2 Règles de gestion'!$D$2:$F$51,3, FALSE) -> La date de fin réelle du congé/absence doit être antérieure à la date limite de départ à la retraite. | AZ10: ABS_C_008 | BA10: =VLOOKUP(AZ10,'Axe 2 Règles de gestion'!$D$2:$F$51,3, FALSE) -> La date de fin prévisionnelle du congé/absence doit être antérieure à la date limite de départ à la retraite. | BB10: ABS_C_009 | BC10: =VLOOKUP(BB10,'Axe 2 Règles de gestion'!$D$2:$F$51,3, FALSE) -> La date de fin réelle ou la date de fin prévisionnelle du congé/absence doit être saisie. | BD10: ABS_C_026 | BE10: =VLOOKUP(BD10,'Axe 2 Règles de gestion'!$D$2:$F$51,3, FALSE) -> Dans le cas d'un congé autre que CLM, CLD, CGM et CITIS, l'indicateur de requalification doit être à non et les impacts spécifiques à la requalification ne doivent pas être mobilisés ou l'impact rémunération est vide. | BF10: ABS_C_041 | BG10: =VLOOKUP(BF10,'Axe 2 Règles de gestion'!$D$2:$F$51,3, FALSE) -> La période de référence du compteur de suivi du cumul total du congé saisi doit être initialisée sur une période allant du 01/01 au 31/12 de la même année.
A11: 19.00.00 | B11: M | C11: 43571.733 | D11: D0007 | E11: Congés/Absence | F11: S0060 | G11: Congé formation syndicale | H11: E0484 | I11: Congé pour formation syndicale | J11: Type de congé/absence saisi = 'Congé pour formation syndicale' | K11: A_COA_TYCOAB [Saisi] = 'CF005' | L11: T1177 | M11: Congé pour formation syndicale - Demande | N11: Création | Q11: Ouvrier d'état | R11: P0005 | S11: Général | T11: Passant | U11: 40725 | W11: CFS_I_002 ET CFS_I_001 ET CFS_I_003 ET CFS_I_004 ET CFS_I_005 ET CFS_D_004 ET CDI_D_047 ET CFS_D_014 ET ABS_C_002 ET ABS_C_003 ET ABS_C_004 ET ABS_C_005 ET ABS_C_006 ET ABS_C_007 ET ABS_C_008 ET ABS_C_009 ET ABS_C_019 ET ABS_C_020 ET ABS_C_026 ET ABS_C_041 | X11: CFS_I_002 | Y11: =VLOOKUP(X11,'Axe 2 Règles de gestion'!$D$2:$F$51,3, FALSE) -> Le congé est accordé pour effectuer un stage ou suivre une session dans l'un des centres ou instituts qui figurent sur une liste arrêtée tous les 3 ans par le ministre chargé de la fonction publique. | Z11: CFS_I_001 | AA11: =VLOOKUP(Z11,'Axe 2 Règles de gestion'!$D$2:$F$51,3, FALSE) -> L'agent doit formuler sa demande par écrit au chef de service au moins 1 mois à l'avance. | AB11: CFS_I_003 | AC11: =VLOOKUP(AB11,'Axe 2 Règles de gestion'!$D$2:$F$51,3, FALSE) -> Le congé est réputé accordé, à défaut de réponse expresse de l'administration au plus tard le 15ème jour qui précède le début du stage ou de la session. | AD11: CFS_I_004 | AE11: =VLOOKUP(AD11,'Axe 2 Règles de gestion'!$D$2:$F$51,3, FALSE) -> L'administration ne peut refuser le bénéfice du congé que pour des raisons liées aux nécessités du service. | AF11: CFS_I_005 | AG11: =VLOOKUP(AF11,'Axe 2 Règles de gestion'!$D$2:$F$51,3, FALSE) -> La commission administrative paritaire ou la commission d'avancement est informée de la décision de rejet ainsi que des motifs de refus. | AJ11: CFS_D_004 | AK11: =VLOOKUP(AJ11,'Axe 2 Règles de gestion'!$D$2:$F$51,3, FALSE) -> Le congé est d'une durée maximale de 12 jours ouvrables par an. | AL11: CDI_D_047 | AM11: =VLOOKUP(AL11,'Axe 2 Règles de gestion'!$D$2:$F$51,3, FALSE) -> Les congés "Congé de formation de cadres et d'animateurs pour la jeunesse", "Congé pour siéger auprès d'une association, d'une mutuelle ou d'une instance de l'Etat ou d'une collectivité territoriale" et "Congé pour formation syndicale" ne peuvent se cumuler qu'à concurrence de 12 jours ouvrables pour une même année. | AN11: CFS_D_014 | AO11: =VLOOKUP(AN11,'Axe 2 Règles de gestion'!$D$2:$F$51,3, FALSE) -> L'agent doit être en activité. | AT11: ABS_C_002 | AU11: =VLOOKUP(AT11,'Axe 2 Règles de gestion'!$D$2:$F$51,3, FALSE) -> La date de début du congé/absence doit être postérieure ou égale à la date de début du lien juridique. | AV11: ABS_C_003 | AW11: =VLOOKUP(AV11,'Axe 2 Règles de gestion'!$D$2:$F$51,3, FALSE) -> La date de début du congé/absence doit être antérieure ou égale à la date de fin réelle du congé/absence. | AX11: ABS_C_004 | AY11: =VLOOKUP(AX11,'Axe 2 Règles de gestion'!$D$2:$F$51,3, FALSE) -> La date de début du congé/absence doit être antérieure ou égale à la date de fin prévisionnelle du congé/absence. | AZ11: ABS_C_005 | BA11: =VLOOKUP(AZ11,'Axe 2 Règles de gestion'!$D$2:$F$51,3, FALSE) -> La date de fin réelle du congé/absence doit être antérieure ou égale à la date limite de fin réelle ou prévisionnelle du lien juridique. | BB11: ABS_C_006 | BC11: =VLOOKUP(BB11,'Axe 2 Règles de gestion'!$D$2:$F$51,3, FALSE) -> La date de fin prévisionnelle du congé/absence doit être antérieure ou égale à la date limite de fin réelle ou prévisionnelle du lien juridique. | BD11: ABS_C_007 | BE11: =VLOOKUP(BD11,'Axe 2 Règles de gestion'!$D$2:$F$51,3, FALSE) -> La date de fin réelle du congé/absence doit être antérieure à la date limite de départ à la retraite. | BF11: ABS_C_008 | BG11: =VLOOKUP(BF11,'Axe 2 Règles de gestion'!$D$2:$F$51,3, FALSE) -> La date de fin prévisionnelle du congé/absence doit être antérieure à la date limite de départ à la retraite. | BH11: ABS_C_009 | BI11: =VLOOKUP(BH11,'Axe 2 Règles de gestion'!$D$2:$F$51,3, FALSE) -> La date de fin réelle ou la date de fin prévisionnelle du congé/absence doit être saisie. | BJ11: ABS_C_019 | BK11: =VLOOKUP(BJ11,'Axe 2 Règles de gestion'!$D$2:$F$51,3, FALSE) -> Si l'absence ne commence pas par une demi-journée et si l'absence précédente ne finit pas par une demi journée, la date de début de l'absence saisie est postérieure à la date de fin réelle de l'absence précédente. | BL11: ABS_C_020 | BM11: =VLOOKUP(BL11,'Axe 2 Règles de gestion'!$D$2:$F$51,3, FALSE) -> Si l'absence ne commence pas par une demi-journée et si l'absence précédente ne finit pas par une demi journée, la date de début de l'absence saisie est postérieure à la date de fin prévisionnelle de l'absence précédente. | BN11: ABS_C_026 | BO11: =VLOOKUP(BN11,'Axe 2 Règles de gestion'!$D$2:$F$51,3, FALSE) -> Dans le cas d'un congé autre que CLM, CLD, CGM et CITIS, l'indicateur de requalification doit être à non et les impacts spécifiques à la requalification ne doivent pas être mobilisés ou l'impact rémunération est vide. | BP11: ABS_C_041 | BQ11: =VLOOKUP(BP11,'Axe 2 Règles de gestion'!$D$2:$F$51,3, FALSE) -> La période de référence du compteur de suivi du cumul total du congé saisi doit être initialisée sur une période allant du 01/01 au 31/12 de la même année.
A12: 19.00.00 | B12: M | C12: 43572.462 | D12: D0007 | E12: Congés/Absence | F12: S0060 | G12: Congé formation syndicale | H12: E0484 | I12: Congé pour formation syndicale | J12: Type de congé/absence saisi = 'Congé pour formation syndicale' | K12: A_COA_TYCOAB [Saisi] = 'CF005' | L12: T1636 | M12: Congé pour formation syndicale - Fin | N12: Modification | Q12: Ouvrier d'état | R12: P0005 | S12: Général | T12: Passant | U12: 40725 | W12: CFS_I_006 ET CFS_D_004 ET CDI_D_047 ET ABS_C_003 ET ABS_C_004 ET ABS_C_005 ET ABS_C_006 ET ABS_C_007 ET ABS_C_008 ET ABS_C_009 ET ABS_C_026 ET ABS_C_041 | X12: CFS_I_006 | Y12: =VLOOKUP(X12,'Axe 2 Règles de gestion'!$D$2:$F$51,3, FALSE) -> Lors de la reprise de fonctions, l'agent remet à son chef de service l'attestation d'assiduité délivrée à l'issue de son stage. | AJ12: CFS_D_004 | AK12: =VLOOKUP(AJ12,'Axe 2 Règles de gestion'!$D$2:$F$51,3, FALSE) -> Le congé est d'une durée maximale de 12 jours ouvrables par an. | AL12: CDI_D_047 | AM12: =VLOOKUP(AL12,'Axe 2 Règles de gestion'!$D$2:$F$51,3, FALSE) -> Les congés "Congé de formation de cadres et d'animateurs pour la jeunesse", "Congé pour siéger auprès d'une association, d'une mutuelle ou d'une instance de l'Etat ou d'une collectivité territoriale" et "Congé pour formation syndicale" ne peuvent se cumuler qu'à concurrence de 12 jours ouvrables pour une même année. | AT12: ABS_C_003 | AU12: =VLOOKUP(AT12,'Axe 2 Règles de gestion'!$D$2:$F$51,3, FALSE) -> La date de début du congé/absence doit être antérieure ou égale à la date de fin réelle du congé/absence. | AV12: ABS_C_004 | AW12: =VLOOKUP(AV12,'Axe 2 Règles de gestion'!$D$2:$F$51,3, FALSE) -> La date de début du congé/absence doit être antérieure ou égale à la date de fin prévisionnelle du congé/absence. | AX12: ABS_C_005 | AY12: =VLOOKUP(AX12,'Axe 2 Règles de gestion'!$D$2:$F$51,3, FALSE) -> La date de fin réelle du congé/absence doit être antérieure ou égale à la date limite de fin réelle ou prévisionnelle du lien juridique. | AZ12: ABS_C_006 | BA12: =VLOOKUP(AZ12,'Axe 2 Règles de gestion'!$D$2:$F$51,3, FALSE) -> La date de fin prévisionnelle du congé/absence doit être antérieure ou égale à la date limite de fin réelle ou prévisionnelle du lien juridique. | BB12: ABS_C_007 | BC12: =VLOOKUP(BB12,'Axe 2 Règles de gestion'!$D$2:$F$51,3, FALSE) -> La date de fin réelle du congé/absence doit être antérieure à la date limite de départ à la retraite. | BD12: ABS_C_008 | BE12: =VLOOKUP(BD12,'Axe 2 Règles de gestion'!$D$2:$F$51,3, FALSE) -> La date de fin prévisionnelle du congé/absence doit être antérieure à la date limite de départ à la retraite. | BF12: ABS_C_009 | BG12: =VLOOKUP(BF12,'Axe 2 Règles de gestion'!$D$2:$F$51,3, FALSE) -> La date de fin réelle ou la date de fin prévisionnelle du congé/absence doit être saisie. | BH12: ABS_C_026 | BI12: =VLOOKUP(BH12,'Axe 2 Règles de gestion'!$D$2:$F$51,3, FALSE) -> Dans le cas d'un congé autre que CLM, CLD, CGM et CITIS, l'indicateur de requalification doit être à non et les impacts spécifiques à la requalification ne doivent pas être mobilisés ou l'impact rémunération est vide. | BJ12: ABS_C_041 | BK12: =VLOOKUP(BJ12,'Axe 2 Règles de gestion'!$D$2:$F$51,3, FALSE) -> La période de référence du compteur de suivi du cumul total du congé saisi doit être initialisée sur une période allant du 01/01 au 31/12 de la même année.
A13: 17.10.00 | B13: A | C13: 43152.5 | D13: D0007 | E13: Congés/Absence | F13: S0060 | G13: Congé formation syndicale | H13: E0484 | I13: Congé pour formation syndicale | J13: Type de congé/absence saisi = 'Congé pour formation syndicale' | K13: A_COA_TYCOAB [Saisi] = 'CF005' | L13: T1177 | M13: Congé pour formation syndicale - Demande | N13: Création | Q13: Magistrat de l'ordre judiciaire | R13: P0007 | S13: Particulier | T13: Exclu | U13: 40725
A14: 17.10.00 | B14: A | C14: 43152.5 | D14: D0007 | E14: Congés/Absence | F14: S0060 | G14: Congé formation syndicale | H14: E0484 | I14: Congé pour formation syndicale | J14: Type de congé/absence saisi = 'Congé pour formation syndicale' | K14: A_COA_TYCOAB [Saisi] = 'CF005' | L14: T1636 | M14: Congé pour formation syndicale - Fin | N14: Modification | Q14: Magistrat de l'ordre judiciaire | R14: P0007 | S14: Particulier | T14: Exclu | U14: 40725
A15: 17.10.00 | B15: A | C15: 43152.5 | D15: D0007 | E15: Congés/Absence | F15: S0060 | G15: Congé formation syndicale | H15: E0484 | I15: Congé pour formation syndicale | J15: Type de congé/absence saisi = 'Congé pour formation syndicale' | K15: A_COA_TYCOAB [Saisi] = 'CF005' | L15: T1177 | M15: Congé pour formation syndicale - Demande | N15: Création | Q15: Auditeur de justice | R15: P0009 | S15: Particulier | T15: Exclu | U15: 40725
A16: 17.10.00 | B16: A | C16: 43152.5 | D16: D0007 | E16: Congés/Absence | F16: S0060 | G16: Congé formation syndicale | H16: E0484 | I16: Congé pour formation syndicale | J16: Type de congé/absence saisi = 'Congé pour formation syndicale' | K16: A_COA_TYCOAB [Saisi] = 'CF005' | L16: T1636 | M16: Congé pour formation syndicale - Fin | N16: Modification | Q16: Auditeur de justice | R16: P0009 | S16: Particulier | T16: Exclu | U16: 40725
A17: 17.10.00 | B17: A | C17: 43152.5 | D17: D0007 | E17: Congés/Absence | F17: S0060 | G17: Congé formation syndicale | H17: E0484 | I17: Congé pour formation syndicale | J17: Type de congé/absence saisi = 'Congé pour formation syndicale' | K17: A_COA_TYCOAB [Saisi] = 'CF005' | L17: T1177 | M17: Congé pour formation syndicale - Demande | N17: Création | Q17: Préfet ou sous-préfet | R17: P0016 | S17: Particulier | T17: Exclu | U17: 40725
A18: 17.10.00 | B18: A | C18: 43152.5 | D18: D0007 | E18: Congés/Absence | F18: S0060 | G18: Congé formation syndicale | H18: E0484 | I18: Congé pour formation syndicale | J18: Type de congé/absence saisi = 'Congé pour formation syndicale' | K18: A_COA_TYCOAB [Saisi] = 'CF005' | L18: T1636 | M18: Congé pour formation syndicale - Fin | N18: Modification | Q18: Préfet ou sous-préfet | R18: P0016 | S18: Particulier | T18: Exclu | U18: 40725
A19: 17.10.00 | B19: A | C19: 43152.5 | D19: D0007 | E19: Congés/Absence | F19: S0060 | G19: Congé formation syndicale | H19: E0484 | I19: Congé pour formation syndicale | J19: Type de congé/absence saisi = 'Congé pour formation syndicale' | K19: A_COA_TYCOAB [Saisi] = 'CF005' | L19: T1177 | M19: Congé pour formation syndicale - Demande | N19: Création | Q19: Contractuel sous contrat PACTE ou contractuel en situation de handicap avant titularisation | R19: P0037 | S19: Particulier | T19: Exclu | U19: 40725
A20: 17.10.00 | B20: A | C20: 43152.5 | D20: D0007 | E20: Congés/Absence | F20: S0060 | G20: Congé formation syndicale | H20: E0484 | I20: Congé pour formation syndicale | J20: Type de congé/absence saisi = 'Congé pour formation syndicale' | K20: A_COA_TYCOAB [Saisi] = 'CF005' | L20: T1636 | M20: Congé pour formation syndicale - Fin | N20: Modification | Q20: Contractuel sous contrat PACTE ou contractuel en situation de handicap avant titularisation | R20: P0037 | S20: Particulier | T20: Exclu | U20: 40725
A21: 17.10.00 | B21: A | C21: 43152.5 | D21: D0007 | E21: Congés/Absence | F21: S0060 | G21: Congé formation syndicale | H21: E0484 | I21: Congé pour formation syndicale | J21: Type de congé/absence saisi = 'Congé pour formation syndicale' | K21: A_COA_TYCOAB [Saisi] = 'CF005' | L21: T1177 | M21: Congé pour formation syndicale - Demande | N21: Création | Q21: Conseiller ou avocat général à la Cour de cassation en service extraordinaire | R21: P0046 | S21: Particulier | T21: Exclu | U21: 40725
A22: 17.10.00 | B22: A | C22: 43152.5 | D22: D0007 | E22: Congés/Absence | F22: S0060 | G22: Congé formation syndicale | H22: E0484 | I22: Congé pour formation syndicale | J22: Type de congé/absence saisi = 'Congé pour formation syndicale' | K22: A_COA_TYCOAB [Saisi] = 'CF005' | L22: T1636 | M22: Congé pour formation syndicale - Fin | N22: Modification | Q22: Conseiller ou avocat général à la Cour de cassation en service extraordinaire | R22: P0046 | S22: Particulier | T22: Exclu | U22: 40725
A23: 17.10.00 | B23: A | C23: 43152.5 | D23: D0007 | E23: Congés/Absence | F23: S0060 | G23: Congé formation syndicale | H23: E0484 | I23: Congé pour formation syndicale | J23: Type de congé/absence saisi = 'Congé pour formation syndicale' | K23: A_COA_TYCOAB [Saisi] = 'CF005' | L23: T1177 | M23: Congé pour formation syndicale - Demande | N23: Création | Q23: Personnel civil payé à l'acte ou à la tâche | R23: P0054 | S23: Particulier | T23: Exclu | U23: 40725
A24: 17.10.00 | B24: A | C24: 43152.5 | D24: D0007 | E24: Congés/Absence | F24: S0060 | G24: Congé formation syndicale | H24: E0484 | I24: Congé pour formation syndicale | J24: Type de congé/absence saisi = 'Congé pour formation syndicale' | K24: A_COA_TYCOAB [Saisi] = 'CF005' | L24: T1636 | M24: Congé pour formation syndicale - Fin | N24: Modification | Q24: Personnel civil payé à l'acte ou à la tâche | R24: P0054 | S24: Particulier | T24: Exclu | U24: 40725
... A26: 19.00.00 | B26: A | C26: 43572.474 | D26: D0007 | E26: Congés/Absence | F26: S0060 | G26: Congé formation syndicale | H26: E0484 | I26: Congé pour formation syndicale | J26: Type de congé/absence saisi = 'Congé pour formation syndicale' | K26: A_COA_TYCOAB [Saisi] = 'CF005' | L26: T1636 | M26: Congé pour formation syndicale - Fin | N26: Modification | Q26: Contractuel de droit privé | R26: P0072 | S26: Particulier | T26: Exclu | U26: 40725
A27: 25.10.00 | B27: A | C27: 45995.671 | D27: D0007 | E27: Congés/Absence | F27: S0060 | G27: Congé formation syndicale | H27: E0484 | I27: Congé pour formation syndicale | J27: Type de congé/absence saisi = 'Congé pour formation syndicale' | K27: A_COA_TYCOAB [Saisi] = 'CF005' | L27: T1177 | M27: Congé pour formation syndicale - Demande | N27: Création | Q27: Ouvrier des parcs et ateliers confirmé ou stagiaire | R27: P0143 | S27: Particulier | T27: Passant | U27: 45901 | W27: CFS_I_012 ET CFS_I_002 ET CFS_I_001 ET CFS_I_003 ET CFS_I_004 ET CFS_I_005 ET CFS_D_002 ET CDI_D_045 ET CFS_D_001 ET ABS_C_041 ET ABS_C_001 ET ABS_C_003 ET ABS_C_004 ET ABS_C_007 ET ABS_C_008 ET ABS_C_019 ET ABS_C_020 ET ABS_C_009 ET ABS_C_026 | X27: CFS_I_012 | Y27: =VLOOKUP(X27,'Axe 2 Règles de gestion'!$D$2:$F$51,3, FALSE) -> L'agent bénéficie des dispositions applicables aux agents titulaires pour le congé pour formation syndicale. | Z27: CFS_I_002 | AA27: =VLOOKUP(Z27,'Axe 2 Règles de gestion'!$D$2:$F$51,3, FALSE) -> Le congé est accordé pour effectuer un stage ou suivre une session dans l'un des centres ou instituts qui figurent sur une liste arrêtée tous les 3 ans par le ministre chargé de la fonction publique. | AB27: CFS_I_001 | AC27: =VLOOKUP(AB27,'Axe 2 Règles de gestion'!$D$2:$F$51,3, FALSE) -> L'agent doit formuler sa demande par écrit au chef de service au moins 1 mois à l'avance. | AD27: CFS_I_003 | AE27: =VLOOKUP(AD27,'Axe 2 Règles de gestion'!$D$2:$F$51,3, FALSE) -> Le congé est réputé accordé, à défaut de réponse expresse de l'administration au plus tard le 15ème jour qui précède le début du stage ou de la session. | AF27: CFS_I_004 | AG27: =VLOOKUP(AF27,'Axe 2 Règles de gestion'!$D$2:$F$51,3, FALSE) -> L'administration ne peut refuser le bénéfice du congé que pour des raisons liées aux nécessités du service. | AH27: CFS_I_005 | AI27: =VLOOKUP(AH27,'Axe 2 Règles de gestion'!$D$2:$F$51,3, FALSE) -> La commission administrative paritaire ou la commission d'avancement est informée de la décision de rejet ainsi que des motifs de refus. | AJ27: CFS_D_002 | AK27: =VLOOKUP(AJ27,'Axe 2 Règles de gestion'!$D$2:$F$51,3, FALSE) -> Le congé de formation syndicale est d'une durée maximale de 12 jours ouvrables par an. | AL27: CDI_D_045 | AM27: =VLOOKUP(AL27,'Axe 2 Règles de gestion'!$D$2:$F$51,3, FALSE) -> Les congés "Congé de citoyenneté", "Congé pour siéger auprès d'une association, d'une mutuelle ou d'une instance de l'Etat ou d'une collectivité territoriale" et "Congé pour formation syndicale" ne peuvent se cumuler qu'à concurrence de 12 jours ouvrables pour une même année. | AN27: CFS_D_001 | AO27: =VLOOKUP(AN27,'Axe 2 Règles de gestion'!$D$2:$F$51,3, FALSE) -> L'agent doit être en activité. | AT27: ABS_C_041 | AU27: =VLOOKUP(AT27,'Axe 2 Règles de gestion'!$D$2:$F$51,3, FALSE) -> La période de référence du compteur de suivi du cumul total du congé saisi doit être initialisée sur une période allant du 01/01 au 31/12 de la même année. | AV27: ABS_C_001 | AW27: =VLOOKUP(AV27,'Axe 2 Règles de gestion'!$D$2:$F$51,3, FALSE) -> La date de début du congé/absence doit être postérieure ou égale à la date de recrutement dans la FPE ou dans la carrière militaire. | AX27: ABS_C_003 | AY27: =VLOOKUP(AX27,'Axe 2 Règles de gestion'!$D$2:$F$51,3, FALSE) -> La date de début du congé/absence doit être antérieure ou égale à la date de fin réelle du congé/absence. | AZ27: ABS_C_004 | BA27: =VLOOKUP(AZ27,'Axe 2 Règles de gestion'!$D$2:$F$51,3, FALSE) -> La date de début du congé/absence doit être antérieure ou égale à la date de fin prévisionnelle du congé/absence. | BB27: ABS_C_007 | BC27: =VLOOKUP(BB27,'Axe 2 Règles de gestion'!$D$2:$F$51,3, FALSE) -> La date de fin réelle du congé/absence doit être antérieure à la date limite de départ à la retraite. | BD27: ABS_C_008 | BE27: =VLOOKUP(BD27,'Axe 2 Règles de gestion'!$D$2:$F$51,3, FALSE) -> La date de fin prévisionnelle du congé/absence doit être antérieure à la date limite de départ à la retraite. | BF27: ABS_C_019 | BG27: =VLOOKUP(BF27,'Axe 2 Règles de gestion'!$D$2:$F$51,3, FALSE) -> Si l'absence ne commence pas par une demi-journée et si l'absence précédente ne finit pas par une demi journée, la date de début de l'absence saisie est postérieure à la date de fin réelle de l'absence précédente. | BH27: ABS_C_020 | BI27: =VLOOKUP(BH27,'Axe 2 Règles de gestion'!$D$2:$F$51,3, FALSE) -> Si l'absence ne commence pas par une demi-journée et si l'absence précédente ne finit pas par une demi journée, la date de début de l'absence saisie est postérieure à la date de fin prévisionnelle de l'absence précédente. | BJ27: ABS_C_009 | BK27: =VLOOKUP(BJ27,'Axe 2 Règles de gestion'!$D$2:$F$51,3, FALSE) -> La date de fin réelle ou la date de fin prévisionnelle du congé/absence doit être saisie. | BL27: ABS_C_026 | BM27: =VLOOKUP(BL27,'Axe 2 Règles de gestion'!$D$2:$F$51,3, FALSE) -> Dans le cas d'un congé autre que CLM, CLD, CGM et CITIS, l'indicateur de requalification doit être à non et les impacts spécifiques à la requalification ne doivent pas être mobilisés ou l'impact rémunération est vide. | BT27: 2025-119
A28: 25.10.00 | B28: A | C28: 45995.67 | D28: D0007 | E28: Congés/Absence | F28: S0060 | G28: Congé formation syndicale | H28: E0484 | I28: Congé pour formation syndicale | J28: Type de congé/absence saisi = 'Congé pour formation syndicale' | K28: A_COA_TYCOAB [Saisi] = 'CF005' | L28: T1636 | M28: Congé pour formation syndicale - Fin | N28: Modification | Q28: Ouvrier des parcs et ateliers confirmé ou stagiaire | R28: P0143 | S28: Particulier | T28: Passant | U28: 45901 | W28: CFS_I_012 ET CFS_I_006 ET CFS_D_002 ET CDI_D_045 ET ABS_C_003 ET ABS_C_004 ET ABS_C_007 ET ABS_C_008 ET ABS_C_009 ET ABS_C_026 ET ABS_C_041 | X28: CFS_I_012 | Y28: =VLOOKUP(X28,'Axe 2 Règles de gestion'!$D$2:$F$51,3, FALSE) -> L'agent bénéficie des dispositions applicables aux agents titulaires pour le congé pour formation syndicale. | Z28: CFS_I_006 | AA28: =VLOOKUP(Z28,'Axe 2 Règles de gestion'!$D$2:$F$51,3, FALSE) -> Lors de la reprise de fonctions, l'agent remet à son chef de service l'attestation d'assiduité délivrée à l'issue de son stage. | AJ28: CFS_D_002 | AK28: =VLOOKUP(AJ28,'Axe 2 Règles de gestion'!$D$2:$F$51,3, FALSE) -> Le congé de formation syndicale est d'une durée maximale de 12 jours ouvrables par an. | AL28: CDI_D_045 | AM28: =VLOOKUP(AL28,'Axe 2 Règles de gestion'!$D$2:$F$51,3, FALSE) -> Les congés "Congé de citoyenneté", "Congé pour siéger auprès d'une association, d'une mutuelle ou d'une instance de l'Etat ou d'une collectivité territoriale" et "Congé pour formation syndicale" ne peuvent se cumuler qu'à concurrence de 12 jours ouvrables pour une même année. | AT28: ABS_C_003 | AU28: =VLOOKUP(AT28,'Axe 2 Règles de gestion'!$D$2:$F$51,3, FALSE) -> La date de début du congé/absence doit être antérieure ou égale à la date de fin réelle du congé/absence. | AV28: ABS_C_004 | AW28: =VLOOKUP(AV28,'Axe 2 Règles de gestion'!$D$2:$F$51,3, FALSE) -> La date de début du congé/absence doit être antérieure ou égale à la date de fin prévisionnelle du congé/absence. | AX28: ABS_C_007 | AY28: =VLOOKUP(AX28,'Axe 2 Règles de gestion'!$D$2:$F$51,3, FALSE) -> La date de fin réelle du congé/absence doit être antérieure à la date limite de départ à la retraite. | AZ28: ABS_C_008 | BA28: =VLOOKUP(AZ28,'Axe 2 Règles de gestion'!$D$2:$F$51,3, FALSE) -> La date de fin prévisionnelle du congé/absence doit être antérieure à la date limite de départ à la retraite. | BB28: ABS_C_009 | BC28: =VLOOKUP(BB28,'Axe 2 Règles de gestion'!$D$2:$F$51,3, FALSE) -> La date de fin réelle ou la date de fin prévisionnelle du congé/absence doit être saisie. | BD28: ABS_C_026 | BE28: =VLOOKUP(BD28,'Axe 2 Règles de gestion'!$D$2:$F$51,3, FALSE) -> Dans le cas d'un congé autre que CLM, CLD, CGM et CITIS, l'indicateur de requalification doit être à non et les impacts spécifiques à la requalification ne doivent pas être mobilisés ou l'impact rémunération est vide. | BF28: ABS_C_041 | BG28: =VLOOKUP(BF28,'Axe 2 Règles de gestion'!$D$2:$F$51,3, FALSE) -> La période de référence du compteur de suivi du cumul total du congé saisi doit être initialisée sur une période allant du 01/01 au 31/12 de la même année. | BT28: 2025-119
A29: 17.10.00 | B29: A | C29: 43152.5 | D29: D0007 | E29: Congés/Absence | F29: S0060 | G29: Congé formation syndicale | H29: E0484 | I29: Congé pour formation syndicale | J29: Type de congé/absence saisi = 'Congé pour formation syndicale' | K29: A_COA_TYCOAB [Saisi] = 'CF005' | L29: T1177 | M29: Congé pour formation syndicale - Demande | N29: Création | Q29: Préfet contractuel | R29: P0188 | S29: Particulier | T29: Exclu | U29: 40725
A30: 17.10.00 | B30: A | C30: 43152.5 | D30: D0007 | E30: Congés/Absence | F30: S0060 | G30: Congé formation syndicale | H30: E0484 | I30: Congé pour formation syndicale | J30: Type de congé/absence saisi = 'Congé pour formation syndicale' | K30: A_COA_TYCOAB [Saisi] = 'CF005' | L30: T1636 | M30: Congé pour formation syndicale - Fin | N30: Modification | Q30: Préfet contractuel | R30: P0188 | S30: Particulier | T30: Exclu | U30: 40725
A31: 17.10.00 | B31: A | C31: 43165.488 | D31: D0007 | E31: Congés/Absence | F31: S0060 | G31: Congé formation syndicale | H31: E0484 | I31: Congé pour formation syndicale | J31: Type de congé/absence saisi = 'Congé pour formation syndicale' | K31: A_COA_TYCOAB [Saisi] = 'CF005' | L31: T1177 | M31: Congé pour formation syndicale - Demande | N31: Création | Q31: Contractuel recruté pour présenter un concours administratif pour accéder à un corps ou cadre d'emplois de la fonction publique de l'Etat | R31: P0225 | S31: Particulier | T31: Exclu | U31: 43101
A32: 17.10.00 | B32: A | C32: 43165.488 | D32: D0007 | E32: Congés/Absence | F32: S0060 | G32: Congé formation syndicale | H32: E0484 | I32: Congé pour formation syndicale | J32: Type de congé/absence saisi = 'Congé pour formation syndicale' | K32: A_COA_TYCOAB [Saisi] = 'CF005' | L32: T1636 | M32: Congé pour formation syndicale - Fin | N32: Modification | Q32: Contractuel recruté pour présenter un concours administratif pour accéder à un corps ou cadre d'emplois de la fonction publique de l'Etat | R32: P0225 | S32: Particulier | T32: Exclu | U32: 43101
A33: 17.10.00 | B33: A | C33: 43152.5 | D33: D0007 | E33: Congés/Absence | F33: S0060 | G33: Congé formation syndicale | H33: E0485 | I33: Congé de formation économique, sociale et environnementale et de formation syndicale | J33: Type de congé/absence saisi égal 'Congé de formation économique, sociale et environnementale et de formation syndicale' | K33: A_COA_TYCOAB [Saisi] = 'CF012' | L33: T1178 | M33: Congé de formation économique, sociale et environnementale et de formation syndicale - Demande | N33: Création | Q33: Titulaire ou magistrat | R33: P0001 | S33: Général | T33: Exclu | U33: 40725
A34: 17.10.00 | B34: A | C34: 43152.5 | D34: D0007 | E34: Congés/Absence | F34: S0060 | G34: Congé formation syndicale | H34: E0485 | I34: Congé de formation économique, sociale et environnementale et de formation syndicale | J34: Type de congé/absence saisi égal 'Congé de formation économique, sociale et environnementale et de formation syndicale' | K34: A_COA_TYCOAB [Saisi] = 'CF012' | L34: T1744 | M34: Congé de formation économique, sociale et environnementale et de formation syndicale - Fin | N34: Modification | Q34: Titulaire ou magistrat | R34: P0001 | S34: Général | T34: Exclu | U34: 40725
A35: 22.10.00 | B35: A | C35: 44886.487 | D35: D0007 | E35: Congés/Absence | F35: S0060 | G35: Congé formation syndicale | H35: E0485 | I35: Congé de formation économique, sociale et environnementale et de formation syndicale | J35: Type de congé/absence saisi égal 'Congé de formation économique, sociale et environnementale et de formation syndicale' | K35: A_COA_TYCOAB [Saisi] = 'CF012' | L35: T1178 | M35: Congé de formation économique, sociale et environnementale et de formation syndicale - Demande | N35: Création | Q35: Militaire | R35: P0002 | S35: Général | T35: Exclu | U35: 43831
