Workbook

Sheet Mode opératoire
B1: MODE OPERATOIRE
B2: La transaction s'effectue au niveau de la rubrique "Cessation définitive de fonction ou de l'état militaire" qui comporte les deux sous rubriques "Cessation définitive de fonction ou de l'état militaire" et "Réalisation d'un préavis" On notera que pour une occurrence de la sous-rubrique "Cessation définitive de fonction ou de l'état militaire" il n'existe au maximum qu'une seule occurrence de la sous-rubrique "Réalisation d'un préavis"

Sheet Axe 1 Enchainement des RG
A1: Version | B1: Type de mise à jour | C1: Date de mise à jour | D1: Identifiant Domaine | E1: Libellé du Domaine | F1: Identifiant Sous-domaine | G1: Libellé du Sous-domaine | H1: Identifiant Evénement | I1: Libellé de l'évènement | J1: Libellé condition déclenchement Evènement | K1: Condition déclenchement Evènement | L1: Identifiant type d'évènement | M1: Libellé type d'évènement | N1: Type de mise à jour | O1: Libellé condition déclenchement Type Evènement | P1: Condition déclenchement Type Evènement | Q1: Libellé Population | R1: Codification Population | S1: Général / Particulier | T1: Passant / Exclu | U1: Date de début | V1: Date de fin | W1: Règles mobilisées | X1: Identifiant Règle de contrôle intellectuel 1 | Y1: Libellé Règle de contrôle intellectuel 1 | Z1: Identifiant Règle de contrôle intellectuel 2 | AA1: Libellé Règle de contrôle intellectuel 2 | AB1: Identifiant Règle de contrôle intellectuel 3 | AC1: Libellé Règle de contrôle intellectuel 3 | AD1: Identifiant Règle de contrôle intellectuel 4 | AE1: Libellé Règle de contrôle intellectuel 4 | AF1: Identifiant Règle de contrôle intellectuel 5 | AG1: Libellé Règle de contrôle intellectuel 5 | AH1: Identifiant Règle de contrôle intellectuel 6 | AI1: Libellé Règle de contrôle intellectuel 6 | AJ1: Identifiant Règle de contrôle intellectuel 7 | AK1: Libellé Règle de contrôle intellectuel 7 | AL1: Identifiant Règle de contrôle intellectuel 8 | AM1: Libellé Règle de contrôle intellectuel 8 | AN1: Identifiant Règle de contrôle intellectuel 9 | AO1: Libellé Règle de contrôle intellectuel 9 | AP1: Identifiant Règle de contrôle intellectuel 10 | AQ1: Libellé Règle de contrôle intellectuel 10 | AR1: Identifiant Règle de contrôle intellectuel 11 | AS1: Libellé Règle de contrôle intellectuel 11 | AT1: Identifiant Règle de contrôle intellectuel 12 | AU1: Libellé Règle de contrôle intellectuel 12 | AV1: Identifiant Règle de contrôle intellectuel 13 | AW1: Libellé Règle de contrôle intellectuel 13 | AX1: Identifiant Règle de contrôle intellectuel 14 | AY1: Libellé Règle de contrôle intellectuel 14 | AZ1: Identifiant Règle de contrôle intellectuel 15 | BA1: Libellé Règle de contrôle intellectuel 15 | BB1: Identifiant Règle de contrôle intellectuel 16 | BC1: Libellé Règle de contrôle intellectuel 16 | BD1: Identifiant Règle de contrôle intellectuel 17 | BE1: Libellé Règle de contrôle intellectuel 17 | BF1: Identifiant Règle de contrôle intellectuel 18 | BG1: Libellé Règle de contrôle intellectuel 18 | BH1: Identifiant Règle de condition 1 | BI1: Libellé Règle de condition 1 | BJ1: Identifiant Règle de condition 2 | BK1: Libellé Règle de condition 2 | BL1: Identifiant Règle de condition 3 | BM1: Libellé Règle de condition 3 | BN1: Identifiant Règle de contrôle 1 | BO1: Libellé Règle de contrôle 1 | BP1: Identifiant Règle de contrôle 2 | BQ1: Libellé Règle de contrôle 2 | BR1: Identifiant Règle de contrôle 3 | BS1: Libellé Règle de contrôle 3 | BT1: Identifiant Règle de contrôle 4 | BU1: Libellé Règle de contrôle 4 | BV1: Identifiant Règle de contrôle 5 | BW1: Libellé Règle de contrôle 5 | BX1: Identifiant Règle de contrôle 6 | BY1: Libellé Règle de contrôle 6 | BZ1: Identifiant Règle de contrôle 7 | CA1: Libellé Règle de contrôle 7 | CB1: Identifiant Règle de contrôle 8 | CC1: Libellé Règle de contrôle 8 | CD1: Identifiant Règle de contrôle 9 | CE1: Libellé Règle de contrôle 9 | CF1: Identifiant Règle de contrôle 10 | CG1: Libellé Règle de contrôle 10 | CH1: Identifiant Règle de contrôle 11 | CI1: Libellé Règle de contrôle 11 | CJ1: Identifiant Règle de contrôle 12 | CK1: Libellé Règle de contrôle 12 | CL1: Identifiant Règle de contrôle 13 | CM1: Libellé Règle de contrôle 13 | CN1: FIME | CO1: Statut de travail
A2: 23.10.00 | B2: M | C2: 45225.622 | D2: D0006 | E2: Cessation de fonction | F2: S0042 | G2: Cessation de fonction | H2: E0340 | I2: Révocation | J2: Motif cessation de fonction saisi égal à 'Révocation' | K2: A_CDF_MOTCFT [Saisi] = 'MC170' | L2: T0993 | M2: Révocation | N2: Création Modification | Q2: Titulaire ou magistrat | R2: P0001 | S2: Général | T2: Passant | U2: 40725 | W2: CEF_C_001 ET CEF_C_002 ET CEF_C_009 ET CEF_C_013 ET CEF_C_014 ET CEF_C_031 ET CEF_C_032 ET CEF_C_033 ET CEF_C_038 | BN2: CEF_C_001 | BO2: =VLOOKUP(BN2,'Axe 2 Règles de gestion'!$D$2:$F$379,3, FALSE) -> La date de cessation de fonctions doit être postérieure ou égale à la date d'entrée dans la FPE ou dans la carrière militaire. | BP2: CEF_C_002 | BQ2: =VLOOKUP(BP2,'Axe 2 Règles de gestion'!$D$2:$F$379,3, FALSE) -> La date de la cessation de fonctions doit être postérieure ou égale à la date de début de la dernière position en cours. | BR2: CEF_C_009 | BS2: =VLOOKUP(BR2,'Axe 2 Règles de gestion'!$D$2:$F$379,3, FALSE) -> Si les dates de début et de fin de préavis sont saisies, alors la date de fin du préavis doit être postérieure ou égale à la date de début du préavis. | BT2: CEF_C_013 | BU2: =VLOOKUP(BT2,'Axe 2 Règles de gestion'!$D$2:$F$379,3, FALSE) -> Si la date du dernier jour travaillé payé est saisie alors elle doit être antérieure ou égale à la date de cessation de fonctions. | BV2: CEF_C_014 | BW2: =VLOOKUP(BV2,'Axe 2 Règles de gestion'!$D$2:$F$379,3, FALSE) -> Si la date de début du préavis est saisie alors elle doit être postérieure ou égale à la date d'entrée dans la FPE ou dans la carrière militaire. | BX2: CEF_C_031 | BY2: =VLOOKUP(BX2,'Axe 2 Règles de gestion'!$D$2:$F$379,3, FALSE) -> Si l'agent est placé sur une position payée, alors le champ « Date du dernier jour travaillé payé » doit être saisi. | BZ2: CEF_C_032 | CA2: =VLOOKUP(BZ2,'Axe 2 Règles de gestion'!$D$2:$F$379,3, FALSE) -> La date de cessation de fonction doit être antérieure ou égale à la date limite de départ à la retraite | CB2: CEF_C_033 | CC2: =VLOOKUP(CB2,'Axe 2 Règles de gestion'!$D$2:$F$379,3, FALSE) -> Si la date de fin de préavis est saisie alors elle doit être antérieure ou égale à la date de cessation de fonction. | CD2: CEF_C_038 | CE2: =VLOOKUP(CD2,'Axe 2 Règles de gestion'!$D$2:$F$379,3, FALSE) -> Le champ " Date d'effet de la radiation des cadres ou des contrôles " doit être renseigné.
A3: 17.10.00 | B3: A | C3: 43152.5 | D3: D0006 | E3: Cessation de fonction | F3: S0042 | G3: Cessation de fonction | H3: E0340 | I3: Révocation | J3: Motif cessation de fonction saisi égal à 'Révocation' | K3: A_CDF_MOTCFT [Saisi] = 'MC170' | L3: T0993 | M3: Révocation | N3: Création Modification | Q3: Contractuel | R3: P0003 | S3: Général | T3: Exclu | U3: 40725 | V3: 42481
A4: 18.10.00 | B4: M | C4: 43389.366 | D4: D0006 | E4: Cessation de fonction | F4: S0042 | G4: Cessation de fonction | H4: E0340 | I4: Révocation | J4: Motif cessation de fonction saisi égal à 'Révocation' | K4: A_CDF_MOTCFT [Saisi] = 'MC170' | L4: T0993 | M4: Révocation | N4: Création Modification | Q4: Contractuel | R4: P0003 | S4: Général | T4: Passant | U4: 42482 | W4: CEF_C_002 ET CEF_C_004 ET CEF_C_008 ET CEF_C_011 ET CEF_C_012 ET CEF_C_013 ET CEF_C_027 ET CEF_C_031 ET CEF_C_032 ET CEF_C_033 | BN4: CEF_C_002 | BO4: =VLOOKUP(BN4,'Axe 2 Règles de gestion'!$D$2:$F$379,3, FALSE) -> La date de la cessation de fonctions doit être postérieure ou égale à la date de début de la dernière position en cours. | BP4: CEF_C_004 | BQ4: =VLOOKUP(BP4,'Axe 2 Règles de gestion'!$D$2:$F$379,3, FALSE) -> La date de cessation de fonction doit être postérieure ou égale à la date de début du lien juridique | BR4: CEF_C_008 | BS4: =VLOOKUP(BR4,'Axe 2 Règles de gestion'!$D$2:$F$379,3, FALSE) -> La date du dernier jour travaillé payé doit être antérieure ou égale à la date de fin réelle ou prévisionnelle du lien juridique | BT4: CEF_C_011 | BU4: =VLOOKUP(BT4,'Axe 2 Règles de gestion'!$D$2:$F$379,3, FALSE) -> La date de début du préavis doit être postérieure à la date de début du contrat. | BV4: CEF_C_012 | BW4: =VLOOKUP(BV4,'Axe 2 Règles de gestion'!$D$2:$F$379,3, FALSE) -> La date de fin du préavis doit être antérieure ou égale à la date de fin réelle ou prévisionnelle du lien juridique. | BX4: CEF_C_013 | BY4: =VLOOKUP(BX4,'Axe 2 Règles de gestion'!$D$2:$F$379,3, FALSE) -> Si la date du dernier jour travaillé payé est saisie alors elle doit être antérieure ou égale à la date de cessation de fonctions. | BZ4: CEF_C_027 | CA4: =VLOOKUP(BZ4,'Axe 2 Règles de gestion'!$D$2:$F$379,3, FALSE) -> La date de début du préavis doit être postérieure ou égale à la date de début de l'avenant au contrat. | CB4: CEF_C_031 | CC4: =VLOOKUP(CB4,'Axe 2 Règles de gestion'!$D$2:$F$379,3, FALSE) -> Si l'agent est placé sur une position payée, alors le champ « Date du dernier jour travaillé payé » doit être saisi. | CD4: CEF_C_032 | CE4: =VLOOKUP(CD4,'Axe 2 Règles de gestion'!$D$2:$F$379,3, FALSE) -> La date de cessation de fonction doit être antérieure ou égale à la date limite de départ à la retraite | CF4: CEF_C_033 | CG4: =VLOOKUP(CF4,'Axe 2 Règles de gestion'!$D$2:$F$379,3, FALSE) -> Si la date de fin de préavis est saisie alors elle doit être antérieure ou égale à la date de cessation de fonction.
A5: 17.10.00 | B5: A | C5: 43152.5 | D5: D0006 | E5: Cessation de fonction | F5: S0042 | G5: Cessation de fonction | H5: E0340 | I5: Révocation | J5: Motif cessation de fonction saisi égal à 'Révocation' | K5: A_CDF_MOTCFT [Saisi] = 'MC170' | L5: T0993 | M5: Révocation | N5: Création Modification | Q5: Stagiaire ou auditeur ou élève | R5: P0004 | S5: Général | T5: Exclu | U5: 40725
A6: 17.10.00 | B6: A | C6: 43189.5 | D6: D0006 | E6: Cessation de fonction | F6: S0042 | G6: Cessation de fonction | H6: E0340 | I6: Révocation | J6: Motif cessation de fonction saisi égal à 'Révocation' | K6: A_CDF_MOTCFT [Saisi] = 'MC170' | L6: T0993 | M6: Révocation | N6: Création Modification | Q6: Ouvrier d'état | R6: P0005 | S6: Général | T6: Exclu | U6: 40725
A7: 17.10.00 | B7: A | C7: 43152.5 | D7: D0006 | E7: Cessation de fonction | F7: S0042 | G7: Cessation de fonction | H7: E0340 | I7: Révocation | J7: Motif cessation de fonction saisi égal à 'Révocation' | K7: A_CDF_MOTCFT [Saisi] = 'MC170' | L7: T0993 | M7: Révocation | N7: Création Modification | Q7: Personnel civil payé à l'acte ou à la tâche | R7: P0054 | S7: Particulier | T7: Exclu | U7: 42482
A8: 17.10.00 | B8: A | C8: 43152.5 | D8: D0006 | E8: Cessation de fonction | F8: S0042 | G8: Cessation de fonction | H8: E0340 | I8: Révocation | J8: Motif cessation de fonction saisi égal à 'Révocation' | K8: A_CDF_MOTCFT [Saisi] = 'MC170' | L8: T0993 | M8: Révocation | N8: Création Modification | Q8: Contractuel de droit privé | R8: P0072 | S8: Particulier | T8: Exclu | U8: 42482
A9: 17.10.00 | B9: A | C9: 43152.5 | D9: D0006 | E9: Cessation de fonction | F9: S0042 | G9: Cessation de fonction | H9: E0340 | I9: Révocation | J9: Motif cessation de fonction saisi égal à 'Révocation' | K9: A_CDF_MOTCFT [Saisi] = 'MC170' | L9: T0993 | M9: Révocation | N9: Création Modification | Q9: Contractuel sous contrat PACTE | R9: P0166 | S9: Particulier | T9: Exclu | U9: 42482
A10: 17.10.00 | B10: A | C10: 43152.5 | D10: D0006 | E10: Cessation de fonction | F10: S0042 | G10: Cessation de fonction | H10: E0340 | I10: Révocation | J10: Motif cessation de fonction saisi égal à 'Révocation' | K10: A_CDF_MOTCFT [Saisi] = 'MC170' | L10: T0993 | M10: Révocation | N10: Création Modification | Q10: Contractuel en situation de handicap ou contractuel conjoint de militaire décédé | R10: P0167 | S10: Particulier | T10: Exclu | U10: 42482
A11: 17.10.00 | B11: A | C11: 43165.465 | D11: D0006 | E11: Cessation de fonction | F11: S0042 | G11: Cessation de fonction | H11: E0340 | I11: Révocation | J11: Motif cessation de fonction saisi égal à 'Révocation' | K11: A_CDF_MOTCFT [Saisi] = 'MC170' | L11: T0993 | M11: Révocation | N11: Création Modification | Q11: Contractuel recruté pour présenter un concours administratif pour accéder à un corps ou cadre d'emplois de la fonction publique de l'Etat | R11: P0225 | S11: Particulier | T11: Exclu | U11: 43101
A12: 23.10.00 | B12: M | C12: 45225.649 | D12: D0006 | E12: Cessation de fonction | F12: S0042 | G12: Cessation de fonction | H12: E0341 | I12: Démission acceptée sur demande | J12: Motif cessation de fonction saisi égal à 'Démission acceptée sur demande' | K12: A_CDF_MOTCFT [Saisi] = 'MC121' | L12: T0994 | M12: Démission acceptée sur demande | N12: Création Modification | Q12: Titulaire ou magistrat | R12: P0001 | S12: Général | T12: Passant | U12: 40725 | W12: CEF_I_003 ET CEF_I_004 ET CEF_I_005 ET CEF_I_006 ET CEF_I_008 ET CEF_I_007 ET CEF_C_001 ET CEF_C_002 ET CEF_C_009 ET CEF_C_013 ET CEF_C_014 ET CEF_C_031 ET CEF_C_032 ET CEF_C_033 ET CEF_C_038 | X12: CEF_I_003 | Y12: =VLOOKUP(X12,'Axe 2 Règles de gestion'!$D$2:$F$379,3, FALSE) -> La démission ne peut résulter que d'une demande écrite de l'intéressé marquant sa volonté expresse de quitter son administration ou son service. | Z12: CEF_I_004 | AA12: =VLOOKUP(Z12,'Axe 2 Règles de gestion'!$D$2:$F$379,3, FALSE) -> La démission ne prend effet qu'à partir du moment où elle est acceptée par l'autorité investie du pouvoir de nomination et à la date fixée par cette autorité. | AB12: CEF_I_005 | AC12: =VLOOKUP(AB12,'Axe 2 Règles de gestion'!$D$2:$F$379,3, FALSE) -> La décision de l'autorité compétente doit intervenir dans un délai de 4 mois à compter de la réception de la demande de démission. | AD12: CEF_I_006 | AE12: =VLOOKUP(AD12,'Axe 2 Règles de gestion'!$D$2:$F$379,3, FALSE) -> En cas de refus, l'agent peut saisir la commission administrative paritaire compétente qui émettra un avis motivé et le transmettra à l'autorité compétente. | AF12: CEF_I_008 | AG12: =VLOOKUP(AF12,'Axe 2 Règles de gestion'!$D$2:$F$379,3, FALSE) -> L'acceptation de la démission la rend irrévocable. | AH12: CEF_I_007 | AI12: =VLOOKUP(AH12,'Axe 2 Règles de gestion'!$D$2:$F$379,3, FALSE) -> L'agent cessant ses fonctions avant la date fixée par l'administration peut faire l'objet d'une sanction disciplinaire. | BN12: CEF_C_001 | BO12: =VLOOKUP(BN12,'Axe 2 Règles de gestion'!$D$2:$F$379,3, FALSE) -> La date de cessation de fonctions doit être postérieure ou égale à la date d'entrée dans la FPE ou dans la carrière militaire. | BP12: CEF_C_002 | BQ12: =VLOOKUP(BP12,'Axe 2 Règles de gestion'!$D$2:$F$379,3, FALSE) -> La date de la cessation de fonctions doit être postérieure ou égale à la date de début de la dernière position en cours. | BR12: CEF_C_009 | BS12: =VLOOKUP(BR12,'Axe 2 Règles de gestion'!$D$2:$F$379,3, FALSE) -> Si les dates de début et de fin de préavis sont saisies, alors la date de fin du préavis doit être postérieure ou égale à la date de début du préavis. | BT12: CEF_C_013 | BU12: =VLOOKUP(BT12,'Axe 2 Règles de gestion'!$D$2:$F$379,3, FALSE) -> Si la date du dernier jour travaillé payé est saisie alors elle doit être antérieure ou égale à la date de cessation de fonctions. | BV12: CEF_C_014 | BW12: =VLOOKUP(BV12,'Axe 2 Règles de gestion'!$D$2:$F$379,3, FALSE) -> Si la date de début du préavis est saisie alors elle doit être postérieure ou égale à la date d'entrée dans la FPE ou dans la carrière militaire. | BX12: CEF_C_031 | BY12: =VLOOKUP(BX12,'Axe 2 Règles de gestion'!$D$2:$F$379,3, FALSE) -> Si l'agent est placé sur une position payée, alors le champ « Date du dernier jour travaillé payé » doit être saisi. | BZ12: CEF_C_032 | CA12: =VLOOKUP(BZ12,'Axe 2 Règles de gestion'!$D$2:$F$379,3, FALSE) -> La date de cessation de fonction doit être antérieure ou égale à la date limite de départ à la retraite | CB12: CEF_C_033 | CC12: =VLOOKUP(CB12,'Axe 2 Règles de gestion'!$D$2:$F$379,3, FALSE) -> Si la date de fin de préavis est saisie alors elle doit être antérieure ou égale à la date de cessation de fonction. | CD12: CEF_C_038 | CE12: =VLOOKUP(CD12,'Axe 2 Règles de gestion'!$D$2:$F$379,3, FALSE) -> Le champ " Date d'effet de la radiation des cadres ou des contrôles " doit être renseigné.
A13: 24.10.00 | B13: M | C13: 45608.61 | D13: D0006 | E13: Cessation de fonction | F13: S0042 | G13: Cessation de fonction | H13: E0341 | I13: Démission acceptée sur demande | J13: Motif cessation de fonction saisi égal à 'Démission acceptée sur demande' | K13: A_CDF_MOTCFT [Saisi] = 'MC121' | L13: T0994 | M13: Démission acceptée sur demande | N13: Création Modification | Q13: Contractuel | R13: P0003 | S13: Général | T13: Passant | U13: 40725 | W13: CEF_I_003 ET CEF_I_012 ET CEF_I_013 ET CEF_I_014 ET CEF_I_015 ET CEF_C_002 ET CEF_C_004 ET CEF_C_006 ET CEF_C_007 ET CEF_C_008 ET CEF_C_011 ET CEF_C_012 ET CEF_C_013 ET CEF_C_027 ET CEF_C_031 ET CEF_C_032 ET CEF_C_033 ET CEF_C_016 | X13: CEF_I_003 | Y13: =VLOOKUP(X13,'Axe 2 Règles de gestion'!$D$2:$F$379,3, FALSE) -> La démission ne peut résulter que d'une demande écrite de l'intéressé marquant sa volonté expresse de quitter son administration ou son service. | Z13: CEF_I_012 | AA13: =VLOOKUP(Z13,'Axe 2 Règles de gestion'!$D$2:$F$379,3, FALSE) -> La demande doit être envoyée par courrier recommandé. | AB13: CEF_I_013 | AC13: =VLOOKUP(AB13,'Axe 2 Règles de gestion'!$D$2:$F$379,3, FALSE) -> Le préavis à respecter est de 8 jours pour l'agent qui justifie auprès de l'autorité qui le recrute d'une ancienneté de services inférieure à 6 mois de services. | AD13: CEF_I_014 | AE13: =VLOOKUP(AD13,'Axe 2 Règles de gestion'!$D$2:$F$379,3, FALSE) -> Le préavis à respecter est de 1 mois pour celui qui justifie auprès de l'autorité qui le recrute d'une ancienneté de services comprise entre 6 mois et 2 ans. | AF13: CEF_I_015 | AG13: =VLOOKUP(AF13,'Axe 2 Règles de gestion'!$D$2:$F$379,3, FALSE) -> Le préavis à respecter est de 2 mois pour celui qui justifie auprès de l'autorité qui le recrute d'une ancienneté de services d'au moins 2 ans. | BN13: CEF_C_002 | BO13: =VLOOKUP(BN13,'Axe 2 Règles de gestion'!$D$2:$F$379,3, FALSE) -> La date de la cessation de fonctions doit être postérieure ou égale à la date de début de la dernière position en cours. | BP13: CEF_C_004 | BQ13: =VLOOKUP(BP13,'Axe 2 Règles de gestion'!$D$2:$F$379,3, FALSE) -> La date de cessation de fonction doit être postérieure ou égale à la date de début du lien juridique | BR13: CEF_C_006 | BS13: =VLOOKUP(BR13,'Axe 2 Règles de gestion'!$D$2:$F$379,3, FALSE) -> La date de notification de la rupture du contrat doit être antérieure à la date de fin réelle ou prévisionnelle du lien juridique | BT13: CEF_C_007 | BU13: =VLOOKUP(BT13,'Axe 2 Règles de gestion'!$D$2:$F$379,3, FALSE) -> La date de notification de la rupture du contrat doit être renseignée | BV13: CEF_C_008 | BW13: =VLOOKUP(BV13,'Axe 2 Règles de gestion'!$D$2:$F$379,3, FALSE) -> La date du dernier jour travaillé payé doit être antérieure ou égale à la date de fin réelle ou prévisionnelle du lien juridique | BX13: CEF_C_011 | BY13: =VLOOKUP(BX13,'Axe 2 Règles de gestion'!$D$2:$F$379,3, FALSE) -> La date de début du préavis doit être postérieure à la date de début du contrat. | BZ13: CEF_C_012 | CA13: =VLOOKUP(BZ13,'Axe 2 Règles de gestion'!$D$2:$F$379,3, FALSE) -> La date de fin du préavis doit être antérieure ou égale à la date de fin réelle ou prévisionnelle du lien juridique. | CB13: CEF_C_013 | CC13: =VLOOKUP(CB13,'Axe 2 Règles de gestion'!$D$2:$F$379,3, FALSE) -> Si la date du dernier jour travaillé payé est saisie alors elle doit être antérieure ou égale à la date de cessation de fonctions. | CD13: CEF_C_027 | CE13: =VLOOKUP(CD13,'Axe 2 Règles de gestion'!$D$2:$F$379,3, FALSE) -> La date de début du préavis doit être postérieure ou égale à la date de début de l'avenant au contrat. | CF13: CEF_C_031 | CG13: =VLOOKUP(CF13,'Axe 2 Règles de gestion'!$D$2:$F$379,3, FALSE) -> Si l'agent est placé sur une position payée, alors le champ « Date du dernier jour travaillé payé » doit être saisi. | CH13: CEF_C_032 | CI13: =VLOOKUP(CH13,'Axe 2 Règles de gestion'!$D$2:$F$379,3, FALSE) -> La date de cessation de fonction doit être antérieure ou égale à la date limite de départ à la retraite | CJ13: CEF_C_033 | CK13: =VLOOKUP(CJ13,'Axe 2 Règles de gestion'!$D$2:$F$379,3, FALSE) -> Si la date de fin de préavis est saisie alors elle doit être antérieure ou égale à la date de cessation de fonction. | CL13: CEF_C_016 | CM13: =VLOOKUP(CL13,'Axe 2 Règles de gestion'!$D$2:$F$379,3, FALSE) -> Attention : La date d'effet de la demande de l'agent doit être saisie afin d'être récupérée automatiquement lors de la génération de l'acte.
A14: 25.10.00 | B14: M | C14: 45967.454 | D14: D0006 | E14: Cessation de fonction | F14: S0042 | G14: Cessation de fonction | H14: E0341 | I14: Démission acceptée sur demande | J14: Motif cessation de fonction saisi égal à 'Démission acceptée sur demande' | K14: A_CDF_MOTCFT [Saisi] = 'MC121' | L14: T0994 | M14: Démission acceptée sur demande | N14: Création Modification | Q14: Stagiaire ou auditeur ou élève | R14: P0004 | S14: Général | T14: Passant | U14: 40725 | V14: 45930 | W14: CEF_I_009 ET CEF_I_010 ET CEF_I_011 ET CEF_C_001 ET CEF_C_002 ET CEF_C_009 ET CEF_C_013 ET CEF_C_014 ET CEF_C_031 ET CEF_C_032 ET CEF_C_033 | X14: CEF_I_009 | Y14: =VLOOKUP(X14,'Axe 2 Règles de gestion'!$D$2:$F$379,3, FALSE) -> L'agent adresse sa demande par écrit à l'autorité ayant le pouvoir de nomination. | Z14: CEF_I_010 | AA14: =VLOOKUP(Z14,'Axe 2 Règles de gestion'!$D$2:$F$379,3, FALSE) -> L'acceptation de la démission d'un fonctionnaire stagiaire la rend irrévocable. | AB14: CEF_I_011 | AC14: =VLOOKUP(AB14,'Axe 2 Règles de gestion'!$D$2:$F$379,3, FALSE) -> La demande de démission doit être adressée 1 mois au moins avant la date prévue pour la cessation de fonctions. | BN14: CEF_C_001 | BO14: =VLOOKUP(BN14,'Axe 2 Règles de gestion'!$D$2:$F$379,3, FALSE) -> La date de cessation de fonctions doit être postérieure ou égale à la date d'entrée dans la FPE ou dans la carrière militaire. | BP14: CEF_C_002 | BQ14: =VLOOKUP(BP14,'Axe 2 Règles de gestion'!$D$2:$F$379,3, FALSE) -> La date de la cessation de fonctions doit être postérieure ou égale à la date de début de la dernière position en cours. | BR14: CEF_C_009 | BS14: =VLOOKUP(BR14,'Axe 2 Règles de gestion'!$D$2:$F$379,3, FALSE) -> Si les dates de début et de fin de préavis sont saisies, alors la date de fin du préavis doit être postérieure ou égale à la date de début du préavis. | BT14: CEF_C_013 | BU14: =VLOOKUP(BT14,'Axe 2 Règles de gestion'!$D$2:$F$379,3, FALSE) -> Si la date du dernier jour travaillé payé est saisie alors elle doit être antérieure ou égale à la date de cessation de fonctions. | BV14: CEF_C_014 | BW14: =VLOOKUP(BV14,'Axe 2 Règles de gestion'!$D$2:$F$379,3, FALSE) -> Si la date de début du préavis est saisie alors elle doit être postérieure ou égale à la date d'entrée dans la FPE ou dans la carrière militaire. | BX14: CEF_C_031 | BY14: =VLOOKUP(BX14,'Axe 2 Règles de gestion'!$D$2:$F$379,3, FALSE) -> Si l'agent est placé sur une position payée, alors le champ « Date du dernier jour travaillé payé » doit être saisi. | BZ14: CEF_C_032 | CA14: =VLOOKUP(BZ14,'Axe 2 Règles de gestion'!$D$2:$F$379,3, FALSE) -> La date de cessation de fonction doit être antérieure ou égale à la date limite de départ à la retraite | CB14: CEF_C_033 | CC14: =VLOOKUP(CB14,'Axe 2 Règles de gestion'!$D$2:$F$379,3, FALSE) -> Si la date de fin de préavis est saisie alors elle doit être antérieure ou égale à la date de cessation de fonction. | CN14: 2025-96
A15: 25.10.00 | B15: A | C15: 45967.455 | D15: D0006 | E15: Cessation de fonction | F15: S0042 | G15: Cessation de fonction | H15: E0341 | I15: Démission acceptée sur demande | J15: Motif cessation de fonction saisi égal à 'Démission acceptée sur demande' | K15: A_CDF_MOTCFT [Saisi] = 'MC121' | L15: T0994 | M15: Démission acceptée sur demande | N15: Création Modification | Q15: Stagiaire ou auditeur ou élève | R15: P0004 | S15: Général | T15: Passant | U15: 45931 | W15: CEF_I_009 ET CEF_I_011 ET CEF_C_001 ET CEF_C_002 ET CEF_C_009 ET CEF_C_013 ET CEF_C_014 ET CEF_C_031 ET CEF_C_032 ET CEF_C_033 | X15: CEF_I_009 | Y15: =VLOOKUP(X15,'Axe 2 Règles de gestion'!$D$2:$F$379,3, FALSE) -> L'agent adresse sa demande par écrit à l'autorité ayant le pouvoir de nomination. | Z15: CEF_I_011 | AA15: =VLOOKUP(Z15,'Axe 2 Règles de gestion'!$D$2:$F$379,3, FALSE) -> La demande de démission doit être adressée 1 mois au moins avant la date prévue pour la cessation de fonctions. | BN15: CEF_C_001 | BO15: =VLOOKUP(BN15,'Axe 2 Règles de gestion'!$D$2:$F$379,3, FALSE) -> La date de cessation de fonctions doit être postérieure ou égale à la date d'entrée dans la FPE ou dans la carrière militaire. | BP15: CEF_C_002 | BQ15: =VLOOKUP(BP15,'Axe 2 Règles de gestion'!$D$2:$F$379,3, FALSE) -> La date de la cessation de fonctions doit être postérieure ou égale à la date de début de la dernière position en cours. | BR15: CEF_C_009 | BS15: =VLOOKUP(BR15,'Axe 2 Règles de gestion'!$D$2:$F$379,3, FALSE) -> Si les dates de début et de fin de préavis sont saisies, alors la date de fin du préavis doit être postérieure ou égale à la date de début du préavis. | BT15: CEF_C_013 | BU15: =VLOOKUP(BT15,'Axe 2 Règles de gestion'!$D$2:$F$379,3, FALSE) -> Si la date du dernier jour travaillé payé est saisie alors elle doit être antérieure ou égale à la date de cessation de fonctions. | BV15: CEF_C_014 | BW15: =VLOOKUP(BV15,'Axe 2 Règles de gestion'!$D$2:$F$379,3, FALSE) -> Si la date de début du préavis est saisie alors elle doit être postérieure ou égale à la date d'entrée dans la FPE ou dans la carrière militaire. | BX15: CEF_C_031 | BY15: =VLOOKUP(BX15,'Axe 2 Règles de gestion'!$D$2:$F$379,3, FALSE) -> Si l'agent est placé sur une position payée, alors le champ « Date du dernier jour travaillé payé » doit être saisi. | BZ15: CEF_C_032 | CA15: =VLOOKUP(BZ15,'Axe 2 Règles de gestion'!$D$2:$F$379,3, FALSE) -> La date de cessation de fonction doit être antérieure ou égale à la date limite de départ à la retraite | CB15: CEF_C_033 | CC15: =VLOOKUP(CB15,'Axe 2 Règles de gestion'!$D$2:$F$379,3, FALSE) -> Si la date de fin de préavis est saisie alors elle doit être antérieure ou égale à la date de cessation de fonction. | CN15: 2025-96
A16: 17.10.00 | B16: A | C16: 43189.5 | D16: D0006 | E16: Cessation de fonction | F16: S0042 | G16: Cessation de fonction | H16: E0341 | I16: Démission acceptée sur demande | J16: Motif cessation de fonction saisi égal à 'Démission acceptée sur demande' | K16: A_CDF_MOTCFT [Saisi] = 'MC121' | L16: T0994 | M16: Démission acceptée sur demande | N16: Création Modification | Q16: Ouvrier d'état | R16: P0005 | S16: Général | T16: Exclu | U16: 40725
A17: 17.10.00 | B17: A | C17: 43152.5 | D17: D0006 | E17: Cessation de fonction | F17: S0042 | G17: Cessation de fonction | H17: E0341 | I17: Démission acceptée sur demande | J17: Motif cessation de fonction saisi égal à 'Démission acceptée sur demande' | K17: A_CDF_MOTCFT [Saisi] = 'MC121' | L17: T0994 | M17: Démission acceptée sur demande | N17: Création Modification | Q17: Personnel civil payé à l'acte ou à la tâche | R17: P0054 | S17: Particulier | T17: Exclu | U17: 40725
A18: 18.10.00 | B18: M | C18: 43152.5 | D18: D0006 | E18: Cessation de fonction | F18: S0042 | G18: Cessation de fonction | H18: E0341 | I18: Démission acceptée sur demande | J18: Motif cessation de fonction saisi égal à 'Démission acceptée sur demande' | K18: A_CDF_MOTCFT [Saisi] = 'MC121' | L18: T0994 | M18: Démission acceptée sur demande | N18: Création Modification | Q18: Contractuel en service à l'étranger | R18: P0069 | S18: Particulier | T18: Passant | U18: 40725 | W18: CEF_C_002 ET CEF_C_004 ET CEF_C_006 ET CEF_C_007 ET CEF_C_008 ET CEF_C_011 ET CEF_C_012 ET CEF_C_013 ET CEF_C_027 ET CEF_C_031 ET CEF_C_032 ET CEF_C_033 | BN18: CEF_C_002 | BO18: =VLOOKUP(BN18,'Axe 2 Règles de gestion'!$D$2:$F$379,3, FALSE) -> La date de la cessation de fonctions doit être postérieure ou égale à la date de début de la dernière position en cours. | BP18: CEF_C_004 | BQ18: =VLOOKUP(BP18,'Axe 2 Règles de gestion'!$D$2:$F$379,3, FALSE) -> La date de cessation de fonction doit être postérieure ou égale à la date de début du lien juridique | BR18: CEF_C_006 | BS18: =VLOOKUP(BR18,'Axe 2 Règles de gestion'!$D$2:$F$379,3, FALSE) -> La date de notification de la rupture du contrat doit être antérieure à la date de fin réelle ou prévisionnelle du lien juridique | BT18: CEF_C_007 | BU18: =VLOOKUP(BT18,'Axe 2 Règles de gestion'!$D$2:$F$379,3, FALSE) -> La date de notification de la rupture du contrat doit être renseignée | BV18: CEF_C_008 | BW18: =VLOOKUP(BV18,'Axe 2 Règles de gestion'!$D$2:$F$379,3, FALSE) -> La date du dernier jour travaillé payé doit être antérieure ou égale à la date de fin réelle ou prévisionnelle du lien juridique | BX18: CEF_C_011 | BY18: =VLOOKUP(BX18,'Axe 2 Règles de gestion'!$D$2:$F$379,3, FALSE) -> La date de début du préavis doit être postérieure à la date de début du contrat. | BZ18: CEF_C_012 | CA18: =VLOOKUP(BZ18,'Axe 2 Règles de gestion'!$D$2:$F$379,3, FALSE) -> La date de fin du préavis doit être antérieure ou égale à la date de fin réelle ou prévisionnelle du lien juridique. | CB18: CEF_C_013 | CC18: =VLOOKUP(CB18,'Axe 2 Règles de gestion'!$D$2:$F$379,3, FALSE) -> Si la date du dernier jour travaillé payé est saisie alors elle doit être antérieure ou égale à la date de cessation de fonctions. | CD18: CEF_C_027 | CE18: =VLOOKUP(CD18,'Axe 2 Règles de gestion'!$D$2:$F$379,3, FALSE) -> La date de début du préavis doit être postérieure ou égale à la date de début de l'avenant au contrat. | CF18: CEF_C_031 | CG18: =VLOOKUP(CF18,'Axe 2 Règles de gestion'!$D$2:$F$379,3, FALSE) -> Si l'agent est placé sur une position payée, alors le champ « Date du dernier jour travaillé payé » doit être saisi. | CH18: CEF_C_032 | CI18: =VLOOKUP(CH18,'Axe 2 Règles de gestion'!$D$2:$F$379,3, FALSE) -> La date de cessation de fonction doit être antérieure ou égale à la date limite de départ à la retraite | CJ18: CEF_C_033 | CK18: =VLOOKUP(CJ18,'Axe 2 Règles de gestion'!$D$2:$F$379,3, FALSE) -> Si la date de fin de préavis est saisie alors elle doit être antérieure ou égale à la date de cessation de fonction.
A19: 18.10.00 | B19: M | C19: 43152.5 | D19: D0006 | E19: Cessation de fonction | F19: S0042 | G19: Cessation de fonction | H19: E0341 | I19: Démission acceptée sur demande | J19: Motif cessation de fonction saisi égal à 'Démission acceptée sur demande' | K19: A_CDF_MOTCFT [Saisi] = 'MC121' | L19: T0994 | M19: Démission acceptée sur demande | N19: Création Modification | Q19: Contractuel de droit privé | R19: P0072 | S19: Particulier | T19: Passant | U19: 40725 | W19: CEF_C_002 ET CEF_C_004 ET CEF_C_006 ET CEF_C_007 ET CEF_C_008 ET CEF_C_011 ET CEF_C_012 ET CEF_C_013 ET CEF_C_027 ET CEF_C_031 ET CEF_C_032 ET CEF_C_033 | BN19: CEF_C_002 | BO19: =VLOOKUP(BN19,'Axe 2 Règles de gestion'!$D$2:$F$379,3, FALSE) -> La date de la cessation de fonctions doit être postérieure ou égale à la date de début de la dernière position en cours. | BP19: CEF_C_004 | BQ19: =VLOOKUP(BP19,'Axe 2 Règles de gestion'!$D$2:$F$379,3, FALSE) -> La date de cessation de fonction doit être postérieure ou égale à la date de début du lien juridique | BR19: CEF_C_006 | BS19: =VLOOKUP(BR19,'Axe 2 Règles de gestion'!$D$2:$F$379,3, FALSE) -> La date de notification de la rupture du contrat doit être antérieure à la date de fin réelle ou prévisionnelle du lien juridique | BT19: CEF_C_007 | BU19: =VLOOKUP(BT19,'Axe 2 Règles de gestion'!$D$2:$F$379,3, FALSE) -> La date de notification de la rupture du contrat doit être renseignée | BV19: CEF_C_008 | BW19: =VLOOKUP(BV19,'Axe 2 Règles de gestion'!$D$2:$F$379,3, FALSE) -> La date du dernier jour travaillé payé doit être antérieure ou égale à la date de fin réelle ou prévisionnelle du lien juridique | BX19: CEF_C_011 | BY19: =VLOOKUP(BX19,'Axe 2 Règles de gestion'!$D$2:$F$379,3, FALSE) -> La date de début du préavis doit être postérieure à la date de début du contrat. | BZ19: CEF_C_012 | CA19: =VLOOKUP(BZ19,'Axe 2 Règles de gestion'!$D$2:$F$379,3, FALSE) -> La date de fin du préavis doit être antérieure ou égale à la date de fin réelle ou prévisionnelle du lien juridique. | CB19: CEF_C_013 | CC19: =VLOOKUP(CB19,'Axe 2 Règles de gestion'!$D$2:$F$379,3, FALSE) -> Si la date du dernier jour travaillé payé est saisie alors elle doit être antérieure ou égale à la date de cessation de fonctions. | CD19: CEF_C_027 | CE19: =VLOOKUP(CD19,'Axe 2 Règles de gestion'!$D$2:$F$379,3, FALSE) -> La date de début du préavis doit être postérieure ou égale à la date de début de l'avenant au contrat. | CF19: CEF_C_031 | CG19: =VLOOKUP(CF19,'Axe 2 Règles de gestion'!$D$2:$F$379,3, FALSE) -> Si l'agent est placé sur une position payée, alors le champ « Date du dernier jour travaillé payé » doit être saisi. | CH19: CEF_C_032 | CI19: =VLOOKUP(CH19,'Axe 2 Règles de gestion'!$D$2:$F$379,3, FALSE) -> La date de cessation de fonction doit être antérieure ou égale à la date limite de départ à la retraite | CJ19: CEF_C_033 | CK19: =VLOOKUP(CJ19,'Axe 2 Règles de gestion'!$D$2:$F$379,3, FALSE) -> Si la date de fin de préavis est saisie alors elle doit être antérieure ou égale à la date de cessation de fonction.
A20: 18.10.00 | B20: M | C20: 43152.5 | D20: D0006 | E20: Cessation de fonction | F20: S0042 | G20: Cessation de fonction | H20: E0341 | I20: Démission acceptée sur demande | J20: Motif cessation de fonction saisi égal à 'Démission acceptée sur demande' | K20: A_CDF_MOTCFT [Saisi] = 'MC121' | L20: T0994 | M20: Démission acceptée sur demande | N20: Création Modification | Q20: Enseignant contractuel de l'enseignement agricole privé sous contrat non définitif - Agriculture | R20: P0078 | S20: Particulier | T20: Passant | U20: 40725 | W20: CEF_C_002 ET CEF_C_004 ET CEF_C_006 ET CEF_C_007 ET CEF_C_008 ET CEF_C_011 ET CEF_C_012 ET CEF_C_013 ET CEF_C_027 ET CEF_C_031 ET CEF_C_032 ET CEF_C_033 | BN20: CEF_C_002 | BO20: =VLOOKUP(BN20,'Axe 2 Règles de gestion'!$D$2:$F$379,3, FALSE) -> La date de la cessation de fonctions doit être postérieure ou égale à la date de début de la dernière position en cours. | BP20: CEF_C_004 | BQ20: =VLOOKUP(BP20,'Axe 2 Règles de gestion'!$D$2:$F$379,3, FALSE) -> La date de cessation de fonction doit être postérieure ou égale à la date de début du lien juridique | BR20: CEF_C_006 | BS20: =VLOOKUP(BR20,'Axe 2 Règles de gestion'!$D$2:$F$379,3, FALSE) -> La date de notification de la rupture du contrat doit être antérieure à la date de fin réelle ou prévisionnelle du lien juridique | BT20: CEF_C_007 | BU20: =VLOOKUP(BT20,'Axe 2 Règles de gestion'!$D$2:$F$379,3, FALSE) -> La date de notification de la rupture du contrat doit être renseignée | BV20: CEF_C_008 | BW20: =VLOOKUP(BV20,'Axe 2 Règles de gestion'!$D$2:$F$379,3, FALSE) -> La date du dernier jour travaillé payé doit être antérieure ou égale à la date de fin réelle ou prévisionnelle du lien juridique | BX20: CEF_C_011 | BY20: =VLOOKUP(BX20,'Axe 2 Règles de gestion'!$D$2:$F$379,3, FALSE) -> La date de début du préavis doit être postérieure à la date de début du contrat. | BZ20: CEF_C_012 | CA20: =VLOOKUP(BZ20,'Axe 2 Règles de gestion'!$D$2:$F$379,3, FALSE) -> La date de fin du préavis doit être antérieure ou égale à la date de fin réelle ou prévisionnelle du lien juridique. | CB20: CEF_C_013 | CC20: =VLOOKUP(CB20,'Axe 2 Règles de gestion'!$D$2:$F$379,3, FALSE) -> Si la date du dernier jour travaillé payé est saisie alors elle doit être antérieure ou égale à la date de cessation de fonctions. | CD20: CEF_C_027 | CE20: =VLOOKUP(CD20,'Axe 2 Règles de gestion'!$D$2:$F$379,3, FALSE) -> La date de début du préavis doit être postérieure ou égale à la date de début de l'avenant au contrat. | CF20: CEF_C_031 | CG20: =VLOOKUP(CF20,'Axe 2 Règles de gestion'!$D$2:$F$379,3, FALSE) -> Si l'agent est placé sur une position payée, alors le champ « Date du dernier jour travaillé payé » doit être saisi. | CH20: CEF_C_032 | CI20: =VLOOKUP(CH20,'Axe 2 Règles de gestion'!$D$2:$F$379,3, FALSE) -> La date de cessation de fonction doit être antérieure ou égale à la date limite de départ à la retraite | CJ20: CEF_C_033 | CK20: =VLOOKUP(CJ20,'Axe 2 Règles de gestion'!$D$2:$F$379,3, FALSE) -> Si la date de fin de préavis est saisie alors elle doit être antérieure ou égale à la date de cessation de fonction.
A21: 18.10.00 | B21: M | C21: 43152.5 | D21: D0006 | E21: Cessation de fonction | F21: S0042 | G21: Cessation de fonction | H21: E0341 | I21: Démission acceptée sur demande | J21: Motif cessation de fonction saisi égal à 'Démission acceptée sur demande' | K21: A_CDF_MOTCFT [Saisi] = 'MC121' | L21: T0994 | M21: Démission acceptée sur demande | N21: Création Modification | Q21: Enseignant contractuel de l'enseignement agricole privé sous contrat définitif - Agriculture | R21: P0079 | S21: Particulier | T21: Passant | U21: 40725 | W21: CEF_C_002 ET CEF_C_004 ET CEF_C_006 ET CEF_C_007 ET CEF_C_008 ET CEF_C_011 ET CEF_C_012 ET CEF_C_013 ET CEF_C_027 ET CEF_C_031 ET CEF_C_032 ET CEF_C_033 | BN21: CEF_C_002 | BO21: =VLOOKUP(BN21,'Axe 2 Règles de gestion'!$D$2:$F$379,3, FALSE) -> La date de la cessation de fonctions doit être postérieure ou égale à la date de début de la dernière position en cours. | BP21: CEF_C_004 | BQ21: =VLOOKUP(BP21,'Axe 2 Règles de gestion'!$D$2:$F$379,3, FALSE) -> La date de cessation de fonction doit être postérieure ou égale à la date de début du lien juridique | BR21: CEF_C_006 | BS21: =VLOOKUP(BR21,'Axe 2 Règles de gestion'!$D$2:$F$379,3, FALSE) -> La date de notification de la rupture du contrat doit être antérieure à la date de fin réelle ou prévisionnelle du lien juridique | BT21: CEF_C_007 | BU21: =VLOOKUP(BT21,'Axe 2 Règles de gestion'!$D$2:$F$379,3, FALSE) -> La date de notification de la rupture du contrat doit être renseignée | BV21: CEF_C_008 | BW21: =VLOOKUP(BV21,'Axe 2 Règles de gestion'!$D$2:$F$379,3, FALSE) -> La date du dernier jour travaillé payé doit être antérieure ou égale à la date de fin réelle ou prévisionnelle du lien juridique | BX21: CEF_C_011 | BY21: =VLOOKUP(BX21,'Axe 2 Règles de gestion'!$D$2:$F$379,3, FALSE) -> La date de début du préavis doit être postérieure à la date de début du contrat. | BZ21: CEF_C_012 | CA21: =VLOOKUP(BZ21,'Axe 2 Règles de gestion'!$D$2:$F$379,3, FALSE) -> La date de fin du préavis doit être antérieure ou égale à la date de fin réelle ou prévisionnelle du lien juridique. | CB21: CEF_C_013 | CC21: =VLOOKUP(CB21,'Axe 2 Règles de gestion'!$D$2:$F$379,3, FALSE) -> Si la date du dernier jour travaillé payé est saisie alors elle doit être antérieure ou égale à la date de cessation de fonctions. | CD21: CEF_C_027 | CE21: =VLOOKUP(CD21,'Axe 2 Règles de gestion'!$D$2:$F$379,3, FALSE) -> La date de début du préavis doit être postérieure ou égale à la date de début de l'avenant au contrat. | CF21: CEF_C_031 | CG21: =VLOOKUP(CF21,'Axe 2 Règles de gestion'!$D$2:$F$379,3, FALSE) -> Si l'agent est placé sur une position payée, alors le champ « Date du dernier jour travaillé payé » doit être saisi. | CH21: CEF_C_032 | CI21: =VLOOKUP(CH21,'Axe 2 Règles de gestion'!$D$2:$F$379,3, FALSE) -> La date de cessation de fonction doit être antérieure ou égale à la date limite de départ à la retraite | CJ21: CEF_C_033 | CK21: =VLOOKUP(CJ21,'Axe 2 Règles de gestion'!$D$2:$F$379,3, FALSE) -> Si la date de fin de préavis est saisie alors elle doit être antérieure ou égale à la date de cessation de fonction.
A22: 18.10.00 | B22: M | C22: 43189.5 | D22: D0006 | E22: Cessation de fonction | F22: S0042 | G22: Cessation de fonction | H22: E0341 | I22: Démission acceptée sur demande | J22: Motif cessation de fonction saisi égal à 'Démission acceptée sur demande' | K22: A_CDF_MOTCFT [Saisi] = 'MC121' | L22: T0994 | M22: Démission acceptée sur demande | N22: Création Modification | Q22: Ouvrier du service des alcools | R22: P0094 | S22: Particulier | T22: Passant | U22: 40725 | W22: CEF_I_003 ET CEF_I_012 ET CEF_D_364 ET CEF_C_002 ET CEF_C_004 ET CEF_C_006 ET CEF_C_007 ET CEF_C_008 ET CEF_C_011 ET CEF_C_012 ET CEF_C_013 ET CEF_C_027 ET CEF_C_031 ET CEF_C_032 ET CEF_C_033 | X22: CEF_I_003 | Y22: =VLOOKUP(X22,'Axe 2 Règles de gestion'!$D$2:$F$379,3, FALSE) -> La démission ne peut résulter que d'une demande écrite de l'intéressé marquant sa volonté expresse de quitter son administration ou son service. | Z22: CEF_I_012 | AA22: =VLOOKUP(Z22,'Axe 2 Règles de gestion'!$D$2:$F$379,3, FALSE) -> La demande doit être envoyée par courrier recommandé. | BH22: CEF_D_364 | BI22: =VLOOKUP(BH22,'Axe 2 Règles de gestion'!$D$2:$F$379,3, FALSE) -> En cas de démission, le préavis est au minimum de un mois. | BN22: CEF_C_002 | BO22: =VLOOKUP(BN22,'Axe 2 Règles de gestion'!$D$2:$F$379,3, FALSE) -> La date de la cessation de fonctions doit être postérieure ou égale à la date de début de la dernière position en cours. | BP22: CEF_C_004 | BQ22: =VLOOKUP(BP22,'Axe 2 Règles de gestion'!$D$2:$F$379,3, FALSE) -> La date de cessation de fonction doit être postérieure ou égale à la date de début du lien juridique | BR22: CEF_C_006 | BS22: =VLOOKUP(BR22,'Axe 2 Règles de gestion'!$D$2:$F$379,3, FALSE) -> La date de notification de la rupture du contrat doit être antérieure à la date de fin réelle ou prévisionnelle du lien juridique | BT22: CEF_C_007 | BU22: =VLOOKUP(BT22,'Axe 2 Règles de gestion'!$D$2:$F$379,3, FALSE) -> La date de notification de la rupture du contrat doit être renseignée | BV22: CEF_C_008 | BW22: =VLOOKUP(BV22,'Axe 2 Règles de gestion'!$D$2:$F$379,3, FALSE) -> La date du dernier jour travaillé payé doit être antérieure ou égale à la date de fin réelle ou prévisionnelle du lien juridique | BX22: CEF_C_011 | BY22: =VLOOKUP(BX22,'Axe 2 Règles de gestion'!$D$2:$F$379,3, FALSE) -> La date de début du préavis doit être postérieure à la date de début du contrat. | BZ22: CEF_C_012 | CA22: =VLOOKUP(BZ22,'Axe 2 Règles de gestion'!$D$2:$F$379,3, FALSE) -> La date de fin du préavis doit être antérieure ou égale à la date de fin réelle ou prévisionnelle du lien juridique. | CB22: CEF_C_013 | CC22: =VLOOKUP(CB22,'Axe 2 Règles de gestion'!$D$2:$F$379,3, FALSE) -> Si la date du dernier jour travaillé payé est saisie alors elle doit être antérieure ou égale à la date de cessation de fonctions. | CD22: CEF_C_027 | CE22: =VLOOKUP(CD22,'Axe 2 Règles de gestion'!$D$2:$F$379,3, FALSE) -> La date de début du préavis doit être postérieure ou égale à la date de début de l'avenant au contrat. | CF22: CEF_C_031 | CG22: =VLOOKUP(CF22,'Axe 2 Règles de gestion'!$D$2:$F$379,3, FALSE) -> Si l'agent est placé sur une position payée, alors le champ « Date du dernier jour travaillé payé » doit être saisi. | CH22: CEF_C_032 | CI22: =VLOOKUP(CH22,'Axe 2 Règles de gestion'!$D$2:$F$379,3, FALSE) -> La date de cessation de fonction doit être antérieure ou égale à la date limite de départ à la retraite | CJ22: CEF_C_033 | CK22: =VLOOKUP(CJ22,'Axe 2 Règles de gestion'!$D$2:$F$379,3, FALSE) -> Si la date de fin de préavis est saisie alors elle doit être antérieure ou égale à la date de cessation de fonction.
A23: 18.10.00 | B23: M | C23: 43189.5 | D23: D0006 | E23: Cessation de fonction | F23: S0042 | G23: Cessation de fonction | H23: E0341 | I23: Démission acceptée sur demande | J23: Motif cessation de fonction saisi égal à 'Démission acceptée sur demande' | K23: A_CDF_MOTCFT [Saisi] = 'MC121' | L23: T0994 | M23: Démission acceptée sur demande | N23: Création Modification | Q23: Ouvrier du service du cadastre confirmé affilié | R23: P0095 | S23: Particulier | T23: Passant | U23: 40725 | W23: CEF_I_003 ET CEF_I_012 ET CEF_I_084 ET CEF_I_086 ET CEF_D_419 ET CEF_C_002 ET CEF_C_004 ET CEF_C_006 ET CEF_C_007 ET CEF_C_008 ET CEF_C_011 ET CEF_C_012 ET CEF_C_013 ET CEF_C_027 ET CEF_C_031 ET CEF_C_032 ET CEF_C_033 | X23: CEF_I_003 | Y23: =VLOOKUP(X23,'Axe 2 Règles de gestion'!$D$2:$F$379,3, FALSE) -> La démission ne peut résulter que d'une demande écrite de l'intéressé marquant sa volonté expresse de quitter son administration ou son service. | Z23: CEF_I_012 | AA23: =VLOOKUP(Z23,'Axe 2 Règles de gestion'!$D$2:$F$379,3, FALSE) -> La demande doit être envoyée par courrier recommandé. | AB23: CEF_I_084 | AC23: =VLOOKUP(AB23,'Axe 2 Règles de gestion'!$D$2:$F$379,3, FALSE) -> Si l'agent désire quitter son emploi, il doit en aviser par écrit le chef de service au moins 1 mois à l'avance, 8 jours s'il est stagiaire. | AD23: CEF_I_086 | AE23: =VLOOKUP(AD23,'Axe 2 Règles de gestion'!$D$2:$F$379,3, FALSE) -> La démission ne devient définitive qu'après acceptation par le Directeur Général des Impôts. | BH23: CEF_D_419 | BI23: =VLOOKUP(BH23,'Axe 2 Règles de gestion'!$D$2:$F$379,3, FALSE) -> Le préavis est de 8 jours, quelque soit la durée de services. | BN23: CEF_C_002 | BO23: =VLOOKUP(BN23,'Axe 2 Règles de gestion'!$D$2:$F$379,3, FALSE) -> La date de la cessation de fonctions doit être postérieure ou égale à la date de début de la dernière position en cours. | BP23: CEF_C_004 | BQ23: =VLOOKUP(BP23,'Axe 2 Règles de gestion'!$D$2:$F$379,3, FALSE) -> La date de cessation de fonction doit être postérieure ou égale à la date de début du lien juridique | BR23: CEF_C_006 | BS23: =VLOOKUP(BR23,'Axe 2 Règles de gestion'!$D$2:$F$379,3, FALSE) -> La date de notification de la rupture du contrat doit être antérieure à la date de fin réelle ou prévisionnelle du lien juridique | BT23: CEF_C_007 | BU23: =VLOOKUP(BT23,'Axe 2 Règles de gestion'!$D$2:$F$379,3, FALSE) -> La date de notification de la rupture du contrat doit être renseignée | BV23: CEF_C_008 | BW23: =VLOOKUP(BV23,'Axe 2 Règles de gestion'!$D$2:$F$379,3, FALSE) -> La date du dernier jour travaillé payé doit être antérieure ou égale à la date de fin réelle ou prévisionnelle du lien juridique | BX23: CEF_C_011 | BY23: =VLOOKUP(BX23,'Axe 2 Règles de gestion'!$D$2:$F$379,3, FALSE) -> La date de début du préavis doit être postérieure à la date de début du contrat. | BZ23: CEF_C_012 | CA23: =VLOOKUP(BZ23,'Axe 2 Règles de gestion'!$D$2:$F$379,3, FALSE) -> La date de fin du préavis doit être antérieure ou égale à la date de fin réelle ou prévisionnelle du lien juridique. | CB23: CEF_C_013 | CC23: =VLOOKUP(CB23,'Axe 2 Règles de gestion'!$D$2:$F$379,3, FALSE) -> Si la date du dernier jour travaillé payé est saisie alors elle doit être antérieure ou égale à la date de cessation de fonctions. | CD23: CEF_C_027 | CE23: =VLOOKUP(CD23,'Axe 2 Règles de gestion'!$D$2:$F$379,3, FALSE) -> La date de début du préavis doit être postérieure ou égale à la date de début de l'avenant au contrat. | CF23: CEF_C_031 | CG23: =VLOOKUP(CF23,'Axe 2 Règles de gestion'!$D$2:$F$379,3, FALSE) -> Si l'agent est placé sur une position payée, alors le champ « Date du dernier jour travaillé payé » doit être saisi. | CH23: CEF_C_032 | CI23: =VLOOKUP(CH23,'Axe 2 Règles de gestion'!$D$2:$F$379,3, FALSE) -> La date de cessation de fonction doit être antérieure ou égale à la date limite de départ à la retraite | CJ23: CEF_C_033 | CK23: =VLOOKUP(CJ23,'Axe 2 Règles de gestion'!$D$2:$F$379,3, FALSE) -> Si la date de fin de préavis est saisie alors elle doit être antérieure ou égale à la date de cessation de fonction.
A24: 25.10.00 | B24: M | C24: 45974.401 | D24: D0006 | E24: Cessation de fonction | F24: S0042 | G24: Cessation de fonction | H24: E0341 | I24: Démission acceptée sur demande | J24: Motif cessation de fonction saisi égal à 'Démission acceptée sur demande' | K24: A_CDF_MOTCFT [Saisi] = 'MC121' | L24: T0994 | M24: Démission acceptée sur demande | N24: Création Modification | Q24: Ouvrier des parcs et ateliers ou assimilé confirmé | R24: P0096 | S24: Particulier | T24: Passant | U24: 40725 | V24: 45900 | W24: CEF_I_003 ET CEF_I_012 ET CEF_I_099 ET CEF_D_117 ET CEF_C_002 ET CEF_C_004 ET CEF_C_006 ET CEF_C_007 ET CEF_C_008 ET CEF_C_011 ET CEF_C_012 ET CEF_C_013 ET CEF_C_027 ET CEF_C_031 ET CEF_C_032 ET CEF_C_033 | X24: CEF_I_003 | Y24: =VLOOKUP(X24,'Axe 2 Règles de gestion'!$D$2:$F$379,3, FALSE) -> La démission ne peut résulter que d'une demande écrite de l'intéressé marquant sa volonté expresse de quitter son administration ou son service. | Z24: CEF_I_012 | AA24: =VLOOKUP(Z24,'Axe 2 Règles de gestion'!$D$2:$F$379,3, FALSE) -> La demande doit être envoyée par courrier recommandé. | AB24: CEF_I_099 | AC24: =VLOOKUP(AB24,'Axe 2 Règles de gestion'!$D$2:$F$379,3, FALSE) -> Si l'agent désire quitter son emploi, il doit en aviser par écrit le chef de service au moins 1 mois à l'avance, 8 jours s'il est stagiaire. | BH24: CEF_D_117 | BI24: =VLOOKUP(BH24,'Axe 2 Règles de gestion'!$D$2:$F$379,3, FALSE) -> En cas de démission, le préavis est au minimum de un mois. | BN24: CEF_C_002 | BO24: =VLOOKUP(BN24,'Axe 2 Règles de gestion'!$D$2:$F$379,3, FALSE) -> La date de la cessation de fonctions doit être postérieure ou égale à la date de début de la dernière position en cours. | BP24: CEF_C_004 | BQ24: =VLOOKUP(BP24,'Axe 2 Règles de gestion'!$D$2:$F$379,3, FALSE) -> La date de cessation de fonction doit être postérieure ou égale à la date de début du lien juridique | BR24: CEF_C_006 | BS24: =VLOOKUP(BR24,'Axe 2 Règles de gestion'!$D$2:$F$379,3, FALSE) -> La date de notification de la rupture du contrat doit être antérieure à la date de fin réelle ou prévisionnelle du lien juridique | BT24: CEF_C_007 | BU24: =VLOOKUP(BT24,'Axe 2 Règles de gestion'!$D$2:$F$379,3, FALSE) -> La date de notification de la rupture du contrat doit être renseignée | BV24: CEF_C_008 | BW24: =VLOOKUP(BV24,'Axe 2 Règles de gestion'!$D$2:$F$379,3, FALSE) -> La date du dernier jour travaillé payé doit être antérieure ou égale à la date de fin réelle ou prévisionnelle du lien juridique | BX24: CEF_C_011 | BY24: =VLOOKUP(BX24,'Axe 2 Règles de gestion'!$D$2:$F$379,3, FALSE) -> La date de début du préavis doit être postérieure à la date de début du contrat. | BZ24: CEF_C_012 | CA24: =VLOOKUP(BZ24,'Axe 2 Règles de gestion'!$D$2:$F$379,3, FALSE) -> La date de fin du préavis doit être antérieure ou égale à la date de fin réelle ou prévisionnelle du lien juridique. | CB24: CEF_C_013 | CC24: =VLOOKUP(CB24,'Axe 2 Règles de gestion'!$D$2:$F$379,3, FALSE) -> Si la date du dernier jour travaillé payé est saisie alors elle doit être antérieure ou égale à la date de cessation de fonctions. | CD24: CEF_C_027 | CE24: =VLOOKUP(CD24,'Axe 2 Règles de gestion'!$D$2:$F$379,3, FALSE) -> La date de début du préavis doit être postérieure ou égale à la date de début de l'avenant au contrat. | CF24: CEF_C_031 | CG24: =VLOOKUP(CF24,'Axe 2 Règles de gestion'!$D$2:$F$379,3, FALSE) -> Si l'agent est placé sur une position payée, alors le champ « Date du dernier jour travaillé payé » doit être saisi. | CH24: CEF_C_032 | CI24: =VLOOKUP(CH24,'Axe 2 Règles de gestion'!$D$2:$F$379,3, FALSE) -> La date de cessation de fonction doit être antérieure ou égale à la date limite de départ à la retraite | CJ24: CEF_C_033 | CK24: =VLOOKUP(CJ24,'Axe 2 Règles de gestion'!$D$2:$F$379,3, FALSE) -> Si la date de fin de préavis est saisie alors elle doit être antérieure ou égale à la date de cessation de fonction. | CN24: 2025-112
A25: 18.10.00 | B25: M | C25: 43152.5 | D25: D0006 | E25: Cessation de fonction | F25: S0042 | G25: Cessation de fonction | H25: E0341 | I25: Démission acceptée sur demande | J25: Motif cessation de fonction saisi égal à 'Démission acceptée sur demande' | K25: A_CDF_MOTCFT [Saisi] = 'MC121' | L25: T0994 | M25: Démission acceptée sur demande | N25: Création Modification | Q25: Ministre ou personnel des secrétariats des cultes (Alsace Moselle) | R25: P0142 | S25: Particulier | T25: Passant | U25: 40725 | W25: CEF_C_002 ET CEF_C_004 ET CEF_C_006 ET CEF_C_007 ET CEF_C_008 ET CEF_C_011 ET CEF_C_012 ET CEF_C_013 ET CEF_C_027 ET CEF_C_031 ET CEF_C_032 ET CEF_C_033 | BN25: CEF_C_002 | BO25: =VLOOKUP(BN25,'Axe 2 Règles de gestion'!$D$2:$F$379,3, FALSE) -> La date de la cessation de fonctions doit être postérieure ou égale à la date de début de la dernière position en cours. | BP25: CEF_C_004 | BQ25: =VLOOKUP(BP25,'Axe 2 Règles de gestion'!$D$2:$F$379,3, FALSE) -> La date de cessation de fonction doit être postérieure ou égale à la date de début du lien juridique | BR25: CEF_C_006 | BS25: =VLOOKUP(BR25,'Axe 2 Règles de gestion'!$D$2:$F$379,3, FALSE) -> La date de notification de la rupture du contrat doit être antérieure à la date de fin réelle ou prévisionnelle du lien juridique | BT25: CEF_C_007 | BU25: =VLOOKUP(BT25,'Axe 2 Règles de gestion'!$D$2:$F$379,3, FALSE) -> La date de notification de la rupture du contrat doit être renseignée | BV25: CEF_C_008 | BW25: =VLOOKUP(BV25,'Axe 2 Règles de gestion'!$D$2:$F$379,3, FALSE) -> La date du dernier jour travaillé payé doit être antérieure ou égale à la date de fin réelle ou prévisionnelle du lien juridique | BX25: CEF_C_011 | BY25: =VLOOKUP(BX25,'Axe 2 Règles de gestion'!$D$2:$F$379,3, FALSE) -> La date de début du préavis doit être postérieure à la date de début du contrat. | BZ25: CEF_C_012 | CA25: =VLOOKUP(BZ25,'Axe 2 Règles de gestion'!$D$2:$F$379,3, FALSE) -> La date de fin du préavis doit être antérieure ou égale à la date de fin réelle ou prévisionnelle du lien juridique. | CB25: CEF_C_013 | CC25: =VLOOKUP(CB25,'Axe 2 Règles de gestion'!$D$2:$F$379,3, FALSE) -> Si la date du dernier jour travaillé payé est saisie alors elle doit être antérieure ou égale à la date de cessation de fonctions. | CD25: CEF_C_027 | CE25: =VLOOKUP(CD25,'Axe 2 Règles de gestion'!$D$2:$F$379,3, FALSE) -> La date de début du préavis doit être postérieure ou égale à la date de début de l'avenant au contrat. | CF25: CEF_C_031 | CG25: =VLOOKUP(CF25,'Axe 2 Règles de gestion'!$D$2:$F$379,3, FALSE) -> Si l'agent est placé sur une position payée, alors le champ « Date du dernier jour travaillé payé » doit être saisi. | CH25: CEF_C_032 | CI25: =VLOOKUP(CH25,'Axe 2 Règles de gestion'!$D$2:$F$379,3, FALSE) -> La date de cessation de fonction doit être antérieure ou égale à la date limite de départ à la retraite | CJ25: CEF_C_033 | CK25: =VLOOKUP(CJ25,'Axe 2 Règles de gestion'!$D$2:$F$379,3, FALSE) -> Si la date de fin de préavis est saisie alors elle doit être antérieure ou égale à la date de cessation de fonction.
A26: 25.10.00 | B26: A | C26: 45974.397 | D26: D0006 | E26: Cessation de fonction | F26: S0042 | G26: Cessation de fonction | H26: E0341 | I26: Démission acceptée sur demande | J26: Motif cessation de fonction saisi égal à 'Démission acceptée sur demande' | K26: A_CDF_MOTCFT [Saisi] = 'MC121' | L26: T0994 | M26: Démission acceptée sur demande | N26: Création Modification | Q26: Ouvrier des parcs et ateliers confirmé ou stagiaire | R26: P0143 | S26: Particulier | T26: Passant | U26: 45901 | W26: CEF_I_446 ET CEF_D_004 ET CEF_C_002 ET CEF_C_004 ET CEF_C_006 ET CEF_C_007 ET CEF_C_008 ET CEF_C_011 ET CEF_C_012 ET CEF_C_013 ET CEF_C_027 ET CEF_C_031 ET CEF_C_032 ET CEF_C_033 | X26: CEF_I_446 | Y26: =VLOOKUP(X26,'Axe 2 Règles de gestion'!$D$2:$F$379,3, FALSE) -> L'agent informe le chef de service ou le directeur de l'établissement de son intention de démissionner par lettre recommandée avec demande d'avis de réception. | BH26: CEF_D_004 | BI26: =VLOOKUP(BH26,'Axe 2 Règles de gestion'!$D$2:$F$379,3, FALSE) -> L'agent est tenu, dans ce cas, de respecter un préavis de 2 mois. | BN26: CEF_C_002 | BO26: =VLOOKUP(BN26,'Axe 2 Règles de gestion'!$D$2:$F$379,3, FALSE) -> La date de la cessation de fonctions doit être postérieure ou égale à la date de début de la dernière position en cours. | BP26: CEF_C_004 | BQ26: =VLOOKUP(BP26,'Axe 2 Règles de gestion'!$D$2:$F$379,3, FALSE) -> La date de cessation de fonction doit être postérieure ou égale à la date de début du lien juridique | BR26: CEF_C_006 | BS26: =VLOOKUP(BR26,'Axe 2 Règles de gestion'!$D$2:$F$379,3, FALSE) -> La date de notification de la rupture du contrat doit être antérieure à la date de fin réelle ou prévisionnelle du lien juridique | BT26: CEF_C_007 | BU26: =VLOOKUP(BT26,'Axe 2 Règles de gestion'!$D$2:$F$379,3, FALSE) -> La date de notification de la rupture du contrat doit être renseignée | BV26: CEF_C_008 | BW26: =VLOOKUP(BV26,'Axe 2 Règles de gestion'!$D$2:$F$379,3, FALSE) -> La date du dernier jour travaillé payé doit être antérieure ou égale à la date de fin réelle ou prévisionnelle du lien juridique | BX26: CEF_C_011 | BY26: =VLOOKUP(BX26,'Axe 2 Règles de gestion'!$D$2:$F$379,3, FALSE) -> La date de début du préavis doit être postérieure à la date de début du contrat. | BZ26: CEF_C_012 | CA26: =VLOOKUP(BZ26,'Axe 2 Règles de gestion'!$D$2:$F$379,3, FALSE) -> La date de fin du préavis doit être antérieure ou égale à la date de fin réelle ou prévisionnelle du lien juridique. | CB26: CEF_C_013 | CC26: =VLOOKUP(CB26,'Axe 2 Règles de gestion'!$D$2:$F$379,3, FALSE) -> Si la date du dernier jour travaillé payé est saisie alors elle doit être antérieure ou égale à la date de cessation de fonctions. | CD26: CEF_C_027 | CE26: =VLOOKUP(CD26,'Axe 2 Règles de gestion'!$D$2:$F$379,3, FALSE) -> La date de début du préavis doit être postérieure ou égale à la date de début de l'avenant au contrat. | CF26: CEF_C_031 | CG26: =VLOOKUP(CF26,'Axe 2 Règles de gestion'!$D$2:$F$379,3, FALSE) -> Si l'agent est placé sur une position payée, alors le champ « Date du dernier jour travaillé payé » doit être saisi. | CH26: CEF_C_032 | CI26: =VLOOKUP(CH26,'Axe 2 Règles de gestion'!$D$2:$F$379,3, FALSE) -> La date de cessation de fonction doit être antérieure ou égale à la date limite de départ à la retraite | CJ26: CEF_C_033 | CK26: =VLOOKUP(CJ26,'Axe 2 Règles de gestion'!$D$2:$F$379,3, FALSE) -> Si la date de fin de préavis est saisie alors elle doit être antérieure ou égale à la date de cessation de fonction. | CN26: 2025-112
