Workbook

Sheet Mode opératoire
B1: MODE OPERATOIRE
B2: Chaque événement porte sur une des sous-rubriques de la rubrique Poste L'événement "Poste" porte sur la sous-rubrique "Poste" L'événement "Poste-US de rattachement" porte sur la sous-rubrique "US de rattachement" L'événement "Attributs budgétairesdu poste" porte sur la sous-rubrique "Attributs budgétaires du poste" L'événement "Lien poste/attributs budgétaires" porte sur la sous-rubrique "Lien poste/attributs budgétaires" L'événement "Lien poste/emploi-type" porte sur la sous-rubrique "Lien poste/emploi-type" L'événement "Fonction du poste" porte sur la sous-rubrique "Fonction du poste" L'événement "Lien poste/propriété du poste" porte sur la sous-rubrique "Lien poste/propriété du poste" L'événement "Lien poste/compétences" porte sur la sous-rubrique "Lien poste/compétences" L'événement "Poste fichier GEST " porte sur la sous-rubrique "Poste fichier GEST "

Sheet Axe 1 Enchainement des RG
A1: Version | B1: Type de mise à jour | C1: Date de mise à jour | D1: Identifiant Domaine | E1: Libellé du Domaine | F1: Identifiant Sous-domaine | G1: Libellé du Sous-domaine | H1: Identifiant Evénement | I1: Libellé de l'évènement | J1: Libellé condition déclenchement Evènement | K1: Condition déclenchement Evènement | L1: Identifiant type d'évènement | M1: Libellé type d'évènement | N1: Type de mise à jour | O1: Libellé condition déclenchement Type Evènement | P1: Condition déclenchement Type Evènement | Q1: Libellé Population | R1: Codification Population | S1: Général / Particulier | T1: Passant / Exclu | U1: Date de début | V1: Date de fin | W1: Règles mobilisées | X1: Identifiant Règle de contrôle 1 | Y1: Libellé Règle de contrôle 1 | Z1: Identifiant Règle de contrôle 2 | AA1: Libellé Règle de contrôle 2 | AB1: Identifiant Règle de contrôle 3 | AC1: Libellé Règle de contrôle 3 | AD1: FIME | AE1: Statut de travail
A2: 17.10.00 | B2: A | C2: 43152.5 | D2: D0003 | E2: Organisation | F2: S0005 | G2: Gestion des postes | H2: E0081 | I2: Poste | J2: Identifiant du poste est saisi | K2: O_POS_IDENTI [Saisi] <> Vide | L2: T0161 | M2: Poste - Fermeture | N2: Modification | Q2: Titulaire ou magistrat | R2: P0001 | S2: Général | T2: Passant | U2: 40725 | W2: GPO_C_014 ET GPO_C_015 | X2: GPO_C_014 | Y2: =VLOOKUP(X2,'Axe 2 Règles de gestion'!$D$2:$F$22,3, FALSE) -> Un poste ne peut être fermé que si aucun agent n'est affecté sur ce poste à la date de fermeture ou dans le futur. | Z2: GPO_C_015 | AA2: =VLOOKUP(Z2,'Axe 2 Règles de gestion'!$D$2:$F$22,3, FALSE) -> La date de fermeture du poste doit être postérieure ou égale à sa date de création.
A3: 17.10.00 | B3: A | C3: 43152.5 | D3: D0003 | E3: Organisation | F3: S0005 | G3: Gestion des postes | H3: E0081 | I3: Poste | J3: Identifiant du poste est saisi | K3: O_POS_IDENTI [Saisi] <> Vide | L3: T0162 | M3: Poste - Suppression | N3: Suppression | Q3: Titulaire ou magistrat | R3: P0001 | S3: Général | T3: Passant | U3: 40725 | W3: GPO_C_016 | X3: GPO_C_016 | Y3: =VLOOKUP(X3,'Axe 2 Règles de gestion'!$D$2:$F$22,3, FALSE) -> Un poste ne peut être supprimé que si aucun agent n'a jamais été affecté sur le poste.
A4: 17.10.00 | B4: A | C4: 43152.5 | D4: D0003 | E4: Organisation | F4: S0005 | G4: Gestion des postes | H4: E0081 | I4: Poste | J4: Identifiant du poste est saisi | K4: O_POS_IDENTI [Saisi] <> Vide | L4: T1682 | M4: Poste - Création | N4: Création | Q4: Titulaire ou magistrat | R4: P0001 | S4: Général | T4: Passant | U4: 40725
A5: 17.10.00 | B5: A | C5: 43152.5 | D5: D0003 | E5: Organisation | F5: S0005 | G5: Gestion des postes | H5: E0081 | I5: Poste | J5: Identifiant du poste est saisi | K5: O_POS_IDENTI [Saisi] <> Vide | L5: T0161 | M5: Poste - Fermeture | N5: Modification | Q5: Militaire | R5: P0002 | S5: Général | T5: Passant | U5: 40725 | W5: GPO_C_014 ET GPO_C_015 | X5: GPO_C_014 | Y5: =VLOOKUP(X5,'Axe 2 Règles de gestion'!$D$2:$F$22,3, FALSE) -> Un poste ne peut être fermé que si aucun agent n'est affecté sur ce poste à la date de fermeture ou dans le futur. | Z5: GPO_C_015 | AA5: =VLOOKUP(Z5,'Axe 2 Règles de gestion'!$D$2:$F$22,3, FALSE) -> La date de fermeture du poste doit être postérieure ou égale à sa date de création.
A6: 17.10.00 | B6: A | C6: 43152.5 | D6: D0003 | E6: Organisation | F6: S0005 | G6: Gestion des postes | H6: E0081 | I6: Poste | J6: Identifiant du poste est saisi | K6: O_POS_IDENTI [Saisi] <> Vide | L6: T0162 | M6: Poste - Suppression | N6: Suppression | Q6: Militaire | R6: P0002 | S6: Général | T6: Passant | U6: 40725 | W6: GPO_C_016 | X6: GPO_C_016 | Y6: =VLOOKUP(X6,'Axe 2 Règles de gestion'!$D$2:$F$22,3, FALSE) -> Un poste ne peut être supprimé que si aucun agent n'a jamais été affecté sur le poste.
A7: 17.10.00 | B7: A | C7: 43152.5 | D7: D0003 | E7: Organisation | F7: S0005 | G7: Gestion des postes | H7: E0081 | I7: Poste | J7: Identifiant du poste est saisi | K7: O_POS_IDENTI [Saisi] <> Vide | L7: T1682 | M7: Poste - Création | N7: Création | Q7: Militaire | R7: P0002 | S7: Général | T7: Passant | U7: 40725
A8: 17.10.00 | B8: A | C8: 43152.5 | D8: D0003 | E8: Organisation | F8: S0005 | G8: Gestion des postes | H8: E0081 | I8: Poste | J8: Identifiant du poste est saisi | K8: O_POS_IDENTI [Saisi] <> Vide | L8: T0161 | M8: Poste - Fermeture | N8: Modification | Q8: Contractuel | R8: P0003 | S8: Général | T8: Passant | U8: 40725 | W8: GPO_C_014 ET GPO_C_015 | X8: GPO_C_014 | Y8: =VLOOKUP(X8,'Axe 2 Règles de gestion'!$D$2:$F$22,3, FALSE) -> Un poste ne peut être fermé que si aucun agent n'est affecté sur ce poste à la date de fermeture ou dans le futur. | Z8: GPO_C_015 | AA8: =VLOOKUP(Z8,'Axe 2 Règles de gestion'!$D$2:$F$22,3, FALSE) -> La date de fermeture du poste doit être postérieure ou égale à sa date de création.
A9: 17.10.00 | B9: A | C9: 43152.5 | D9: D0003 | E9: Organisation | F9: S0005 | G9: Gestion des postes | H9: E0081 | I9: Poste | J9: Identifiant du poste est saisi | K9: O_POS_IDENTI [Saisi] <> Vide | L9: T0162 | M9: Poste - Suppression | N9: Suppression | Q9: Contractuel | R9: P0003 | S9: Général | T9: Passant | U9: 40725 | W9: GPO_C_016 | X9: GPO_C_016 | Y9: =VLOOKUP(X9,'Axe 2 Règles de gestion'!$D$2:$F$22,3, FALSE) -> Un poste ne peut être supprimé que si aucun agent n'a jamais été affecté sur le poste.
A10: 17.10.00 | B10: A | C10: 43152.5 | D10: D0003 | E10: Organisation | F10: S0005 | G10: Gestion des postes | H10: E0081 | I10: Poste | J10: Identifiant du poste est saisi | K10: O_POS_IDENTI [Saisi] <> Vide | L10: T1682 | M10: Poste - Création | N10: Création | Q10: Contractuel | R10: P0003 | S10: Général | T10: Passant | U10: 40725
A11: 17.10.00 | B11: A | C11: 43152.5 | D11: D0003 | E11: Organisation | F11: S0005 | G11: Gestion des postes | H11: E0081 | I11: Poste | J11: Identifiant du poste est saisi | K11: O_POS_IDENTI [Saisi] <> Vide | L11: T0161 | M11: Poste - Fermeture | N11: Modification | Q11: Stagiaire ou auditeur ou élève | R11: P0004 | S11: Général | T11: Passant | U11: 40725 | W11: GPO_C_014 ET GPO_C_015 | X11: GPO_C_014 | Y11: =VLOOKUP(X11,'Axe 2 Règles de gestion'!$D$2:$F$22,3, FALSE) -> Un poste ne peut être fermé que si aucun agent n'est affecté sur ce poste à la date de fermeture ou dans le futur. | Z11: GPO_C_015 | AA11: =VLOOKUP(Z11,'Axe 2 Règles de gestion'!$D$2:$F$22,3, FALSE) -> La date de fermeture du poste doit être postérieure ou égale à sa date de création.
A12: 17.10.00 | B12: A | C12: 43152.5 | D12: D0003 | E12: Organisation | F12: S0005 | G12: Gestion des postes | H12: E0081 | I12: Poste | J12: Identifiant du poste est saisi | K12: O_POS_IDENTI [Saisi] <> Vide | L12: T0162 | M12: Poste - Suppression | N12: Suppression | Q12: Stagiaire ou auditeur ou élève | R12: P0004 | S12: Général | T12: Passant | U12: 40725 | W12: GPO_C_016 | X12: GPO_C_016 | Y12: =VLOOKUP(X12,'Axe 2 Règles de gestion'!$D$2:$F$22,3, FALSE) -> Un poste ne peut être supprimé que si aucun agent n'a jamais été affecté sur le poste.
A13: 17.10.00 | B13: A | C13: 43152.5 | D13: D0003 | E13: Organisation | F13: S0005 | G13: Gestion des postes | H13: E0081 | I13: Poste | J13: Identifiant du poste est saisi | K13: O_POS_IDENTI [Saisi] <> Vide | L13: T1682 | M13: Poste - Création | N13: Création | Q13: Stagiaire ou auditeur ou élève | R13: P0004 | S13: Général | T13: Passant | U13: 40725
A14: 17.10.00 | B14: A | C14: 43152.5 | D14: D0003 | E14: Organisation | F14: S0005 | G14: Gestion des postes | H14: E0081 | I14: Poste | J14: Identifiant du poste est saisi | K14: O_POS_IDENTI [Saisi] <> Vide | L14: T0161 | M14: Poste - Fermeture | N14: Modification | Q14: Ouvrier d'état | R14: P0005 | S14: Général | T14: Passant | U14: 40725 | W14: GPO_C_014 ET GPO_C_015 | X14: GPO_C_014 | Y14: =VLOOKUP(X14,'Axe 2 Règles de gestion'!$D$2:$F$22,3, FALSE) -> Un poste ne peut être fermé que si aucun agent n'est affecté sur ce poste à la date de fermeture ou dans le futur. | Z14: GPO_C_015 | AA14: =VLOOKUP(Z14,'Axe 2 Règles de gestion'!$D$2:$F$22,3, FALSE) -> La date de fermeture du poste doit être postérieure ou égale à sa date de création.
A15: 17.10.00 | B15: A | C15: 43152.5 | D15: D0003 | E15: Organisation | F15: S0005 | G15: Gestion des postes | H15: E0081 | I15: Poste | J15: Identifiant du poste est saisi | K15: O_POS_IDENTI [Saisi] <> Vide | L15: T0162 | M15: Poste - Suppression | N15: Suppression | Q15: Ouvrier d'état | R15: P0005 | S15: Général | T15: Passant | U15: 40725 | W15: GPO_C_016 | X15: GPO_C_016 | Y15: =VLOOKUP(X15,'Axe 2 Règles de gestion'!$D$2:$F$22,3, FALSE) -> Un poste ne peut être supprimé que si aucun agent n'a jamais été affecté sur le poste.
A16: 17.10.00 | B16: A | C16: 43152.5 | D16: D0003 | E16: Organisation | F16: S0005 | G16: Gestion des postes | H16: E0081 | I16: Poste | J16: Identifiant du poste est saisi | K16: O_POS_IDENTI [Saisi] <> Vide | L16: T1682 | M16: Poste - Création | N16: Création | Q16: Ouvrier d'état | R16: P0005 | S16: Général | T16: Passant | U16: 40725
A17: 17.10.00 | B17: A | C17: 43152.5 | D17: D0003 | E17: Organisation | F17: S0005 | G17: Gestion des postes | H17: E0082 | I17: Poste-US de rattachement | J17: Date de début du rattachement est saisie | K17: O_POS_DDLPUS [Saisi] <> Vide | L17: T0163 | M17: Poste-US de rattachement | N17: Création Modification | Q17: Titulaire ou magistrat | R17: P0001 | S17: Général | T17: Passant | U17: 40725 | W17: GPO_C_001 ET GPO_C_002 ET GPO_C_003 | X17: GPO_C_001 | Y17: =VLOOKUP(X17,'Axe 2 Règles de gestion'!$D$2:$F$22,3, FALSE) -> La date de début du rattachement du poste à une unité structurelle doit être postérieure ou égale à la date de création du poste. | Z17: GPO_C_002 | AA17: =VLOOKUP(Z17,'Axe 2 Règles de gestion'!$D$2:$F$22,3, FALSE) -> La date de début du rattachement du poste à l'unité structurelle doit être postérieure ou égale à la date de création de l'unité structurelle. | AB17: GPO_C_003 | AC17: =VLOOKUP(AB17,'Axe 2 Règles de gestion'!$D$2:$F$22,3, FALSE) -> La date de fin du rattachement du poste à une unité structurelle doit être postérieure ou égale à la date de début du rattachement
A18: 17.10.00 | B18: A | C18: 43152.5 | D18: D0003 | E18: Organisation | F18: S0005 | G18: Gestion des postes | H18: E0082 | I18: Poste-US de rattachement | J18: Date de début du rattachement est saisie | K18: O_POS_DDLPUS [Saisi] <> Vide | L18: T0163 | M18: Poste-US de rattachement | N18: Création Modification | Q18: Militaire | R18: P0002 | S18: Général | T18: Passant | U18: 40725 | W18: GPO_C_001 ET GPO_C_002 ET GPO_C_003 | X18: GPO_C_001 | Y18: =VLOOKUP(X18,'Axe 2 Règles de gestion'!$D$2:$F$22,3, FALSE) -> La date de début du rattachement du poste à une unité structurelle doit être postérieure ou égale à la date de création du poste. | Z18: GPO_C_002 | AA18: =VLOOKUP(Z18,'Axe 2 Règles de gestion'!$D$2:$F$22,3, FALSE) -> La date de début du rattachement du poste à l'unité structurelle doit être postérieure ou égale à la date de création de l'unité structurelle. | AB18: GPO_C_003 | AC18: =VLOOKUP(AB18,'Axe 2 Règles de gestion'!$D$2:$F$22,3, FALSE) -> La date de fin du rattachement du poste à une unité structurelle doit être postérieure ou égale à la date de début du rattachement
A19: 17.10.00 | B19: A | C19: 43152.5 | D19: D0003 | E19: Organisation | F19: S0005 | G19: Gestion des postes | H19: E0082 | I19: Poste-US de rattachement | J19: Date de début du rattachement est saisie | K19: O_POS_DDLPUS [Saisi] <> Vide | L19: T0163 | M19: Poste-US de rattachement | N19: Création Modification | Q19: Contractuel | R19: P0003 | S19: Général | T19: Passant | U19: 40725 | W19: GPO_C_001 ET GPO_C_002 ET GPO_C_003 | X19: GPO_C_001 | Y19: =VLOOKUP(X19,'Axe 2 Règles de gestion'!$D$2:$F$22,3, FALSE) -> La date de début du rattachement du poste à une unité structurelle doit être postérieure ou égale à la date de création du poste. | Z19: GPO_C_002 | AA19: =VLOOKUP(Z19,'Axe 2 Règles de gestion'!$D$2:$F$22,3, FALSE) -> La date de début du rattachement du poste à l'unité structurelle doit être postérieure ou égale à la date de création de l'unité structurelle. | AB19: GPO_C_003 | AC19: =VLOOKUP(AB19,'Axe 2 Règles de gestion'!$D$2:$F$22,3, FALSE) -> La date de fin du rattachement du poste à une unité structurelle doit être postérieure ou égale à la date de début du rattachement
A20: 17.10.00 | B20: A | C20: 43152.5 | D20: D0003 | E20: Organisation | F20: S0005 | G20: Gestion des postes | H20: E0082 | I20: Poste-US de rattachement | J20: Date de début du rattachement est saisie | K20: O_POS_DDLPUS [Saisi] <> Vide | L20: T0163 | M20: Poste-US de rattachement | N20: Création Modification | Q20: Stagiaire ou auditeur ou élève | R20: P0004 | S20: Général | T20: Passant | U20: 40725 | W20: GPO_C_001 ET GPO_C_002 ET GPO_C_003 | X20: GPO_C_001 | Y20: =VLOOKUP(X20,'Axe 2 Règles de gestion'!$D$2:$F$22,3, FALSE) -> La date de début du rattachement du poste à une unité structurelle doit être postérieure ou égale à la date de création du poste. | Z20: GPO_C_002 | AA20: =VLOOKUP(Z20,'Axe 2 Règles de gestion'!$D$2:$F$22,3, FALSE) -> La date de début du rattachement du poste à l'unité structurelle doit être postérieure ou égale à la date de création de l'unité structurelle. | AB20: GPO_C_003 | AC20: =VLOOKUP(AB20,'Axe 2 Règles de gestion'!$D$2:$F$22,3, FALSE) -> La date de fin du rattachement du poste à une unité structurelle doit être postérieure ou égale à la date de début du rattachement
A21: 17.10.00 | B21: A | C21: 43152.5 | D21: D0003 | E21: Organisation | F21: S0005 | G21: Gestion des postes | H21: E0082 | I21: Poste-US de rattachement | J21: Date de début du rattachement est saisie | K21: O_POS_DDLPUS [Saisi] <> Vide | L21: T0163 | M21: Poste-US de rattachement | N21: Création Modification | Q21: Ouvrier d'état | R21: P0005 | S21: Général | T21: Passant | U21: 40725 | W21: GPO_C_001 ET GPO_C_002 ET GPO_C_003 | X21: GPO_C_001 | Y21: =VLOOKUP(X21,'Axe 2 Règles de gestion'!$D$2:$F$22,3, FALSE) -> La date de début du rattachement du poste à une unité structurelle doit être postérieure ou égale à la date de création du poste. | Z21: GPO_C_002 | AA21: =VLOOKUP(Z21,'Axe 2 Règles de gestion'!$D$2:$F$22,3, FALSE) -> La date de début du rattachement du poste à l'unité structurelle doit être postérieure ou égale à la date de création de l'unité structurelle. | AB21: GPO_C_003 | AC21: =VLOOKUP(AB21,'Axe 2 Règles de gestion'!$D$2:$F$22,3, FALSE) -> La date de fin du rattachement du poste à une unité structurelle doit être postérieure ou égale à la date de début du rattachement
A22: 17.10.00 | B22: A | C22: 43152.5 | D22: D0003 | E22: Organisation | F22: S0005 | G22: Gestion des postes | H22: E0083 | I22: Attributs budgétaires du poste | J22: Identifiant des attributs budgétaires est saisi | K22: O_POS_IDEATB [Saisi] <> Vide | L22: T0165 | M22: Attributs budgétaires du poste | N22: Création Modification | Q22: Titulaire ou magistrat | R22: P0001 | S22: Général | T22: Passant | U22: 40725 | W22: GPO_C_017 | X22: GPO_C_017 | Y22: =VLOOKUP(X22,'Axe 2 Règles de gestion'!$D$2:$F$22,3, FALSE) -> La date de fin des attributs budgétaires doit être postérieure ou égale à la date de début des attributs budgétaires.
A23: 17.10.00 | B23: A | C23: 43152.5 | D23: D0003 | E23: Organisation | F23: S0005 | G23: Gestion des postes | H23: E0083 | I23: Attributs budgétaires du poste | J23: Identifiant des attributs budgétaires est saisi | K23: O_POS_IDEATB [Saisi] <> Vide | L23: T0165 | M23: Attributs budgétaires du poste | N23: Création Modification | Q23: Militaire | R23: P0002 | S23: Général | T23: Passant | U23: 40725 | W23: GPO_C_017 | X23: GPO_C_017 | Y23: =VLOOKUP(X23,'Axe 2 Règles de gestion'!$D$2:$F$22,3, FALSE) -> La date de fin des attributs budgétaires doit être postérieure ou égale à la date de début des attributs budgétaires.
A24: 17.10.00 | B24: A | C24: 43152.5 | D24: D0003 | E24: Organisation | F24: S0005 | G24: Gestion des postes | H24: E0083 | I24: Attributs budgétaires du poste | J24: Identifiant des attributs budgétaires est saisi | K24: O_POS_IDEATB [Saisi] <> Vide | L24: T0165 | M24: Attributs budgétaires du poste | N24: Création Modification | Q24: Contractuel | R24: P0003 | S24: Général | T24: Passant | U24: 40725 | W24: GPO_C_017 | X24: GPO_C_017 | Y24: =VLOOKUP(X24,'Axe 2 Règles de gestion'!$D$2:$F$22,3, FALSE) -> La date de fin des attributs budgétaires doit être postérieure ou égale à la date de début des attributs budgétaires.
A25: 17.10.00 | B25: A | C25: 43152.5 | D25: D0003 | E25: Organisation | F25: S0005 | G25: Gestion des postes | H25: E0083 | I25: Attributs budgétaires du poste | J25: Identifiant des attributs budgétaires est saisi | K25: O_POS_IDEATB [Saisi] <> Vide | L25: T0165 | M25: Attributs budgétaires du poste | N25: Création Modification | Q25: Stagiaire ou auditeur ou élève | R25: P0004 | S25: Général | T25: Passant | U25: 40725 | W25: GPO_C_017 | X25: GPO_C_017 | Y25: =VLOOKUP(X25,'Axe 2 Règles de gestion'!$D$2:$F$22,3, FALSE) -> La date de fin des attributs budgétaires doit être postérieure ou égale à la date de début des attributs budgétaires.
A26: 17.10.00 | B26: A | C26: 43152.5 | D26: D0003 | E26: Organisation | F26: S0005 | G26: Gestion des postes | H26: E0083 | I26: Attributs budgétaires du poste | J26: Identifiant des attributs budgétaires est saisi | K26: O_POS_IDEATB [Saisi] <> Vide | L26: T0165 | M26: Attributs budgétaires du poste | N26: Création Modification | Q26: Ouvrier d'état | R26: P0005 | S26: Général | T26: Passant | U26: 40725 | W26: GPO_C_017 | X26: GPO_C_017 | Y26: =VLOOKUP(X26,'Axe 2 Règles de gestion'!$D$2:$F$22,3, FALSE) -> La date de fin des attributs budgétaires doit être postérieure ou égale à la date de début des attributs budgétaires.
A27: 17.10.00 | B27: A | C27: 43152.5 | D27: D0003 | E27: Organisation | F27: S0005 | G27: Gestion des postes | H27: E0084 | I27: Lien poste/attributs budgétaires | J27: Date de début du lien est saisie | K27: O_POS_DDLATB [Saisi] <> Vide | L27: T0167 | M27: Lien poste/attributs budgétaires | N27: Création Modification | Q27: Titulaire ou magistrat | R27: P0001 | S27: Général | T27: Passant | U27: 40725 | W27: GPO_C_018 ET GPO_C_019 ET GPO_C_020 | X27: GPO_C_018 | Y27: =VLOOKUP(X27,'Axe 2 Règles de gestion'!$D$2:$F$22,3, FALSE) -> La date de début du lien entre le poste et les attributs budgétaires doit être postérieure ou égale à la date de création du poste. | Z27: GPO_C_019 | AA27: =VLOOKUP(Z27,'Axe 2 Règles de gestion'!$D$2:$F$22,3, FALSE) -> La date de fin du lien entre le poste et les attributs budgétaires doit être postérieure ou égale à la date de début du lien. | AB27: GPO_C_020 | AC27: =VLOOKUP(AB27,'Axe 2 Règles de gestion'!$D$2:$F$22,3, FALSE) -> La somme des pourcentages de rattachement poste/attributs budgétaires doit être égale à 100 %.
A28: 17.10.00 | B28: A | C28: 43152.5 | D28: D0003 | E28: Organisation | F28: S0005 | G28: Gestion des postes | H28: E0084 | I28: Lien poste/attributs budgétaires | J28: Date de début du lien est saisie | K28: O_POS_DDLATB [Saisi] <> Vide | L28: T0167 | M28: Lien poste/attributs budgétaires | N28: Création Modification | Q28: Militaire | R28: P0002 | S28: Général | T28: Passant | U28: 40725 | W28: GPO_C_018 ET GPO_C_019 ET GPO_C_020 | X28: GPO_C_018 | Y28: =VLOOKUP(X28,'Axe 2 Règles de gestion'!$D$2:$F$22,3, FALSE) -> La date de début du lien entre le poste et les attributs budgétaires doit être postérieure ou égale à la date de création du poste. | Z28: GPO_C_019 | AA28: =VLOOKUP(Z28,'Axe 2 Règles de gestion'!$D$2:$F$22,3, FALSE) -> La date de fin du lien entre le poste et les attributs budgétaires doit être postérieure ou égale à la date de début du lien. | AB28: GPO_C_020 | AC28: =VLOOKUP(AB28,'Axe 2 Règles de gestion'!$D$2:$F$22,3, FALSE) -> La somme des pourcentages de rattachement poste/attributs budgétaires doit être égale à 100 %.
A29: 17.10.00 | B29: A | C29: 43152.5 | D29: D0003 | E29: Organisation | F29: S0005 | G29: Gestion des postes | H29: E0084 | I29: Lien poste/attributs budgétaires | J29: Date de début du lien est saisie | K29: O_POS_DDLATB [Saisi] <> Vide | L29: T0167 | M29: Lien poste/attributs budgétaires | N29: Création Modification | Q29: Contractuel | R29: P0003 | S29: Général | T29: Passant | U29: 40725 | W29: GPO_C_018 ET GPO_C_019 ET GPO_C_020 | X29: GPO_C_018 | Y29: =VLOOKUP(X29,'Axe 2 Règles de gestion'!$D$2:$F$22,3, FALSE) -> La date de début du lien entre le poste et les attributs budgétaires doit être postérieure ou égale à la date de création du poste. | Z29: GPO_C_019 | AA29: =VLOOKUP(Z29,'Axe 2 Règles de gestion'!$D$2:$F$22,3, FALSE) -> La date de fin du lien entre le poste et les attributs budgétaires doit être postérieure ou égale à la date de début du lien. | AB29: GPO_C_020 | AC29: =VLOOKUP(AB29,'Axe 2 Règles de gestion'!$D$2:$F$22,3, FALSE) -> La somme des pourcentages de rattachement poste/attributs budgétaires doit être égale à 100 %.
A30: 17.10.00 | B30: A | C30: 43152.5 | D30: D0003 | E30: Organisation | F30: S0005 | G30: Gestion des postes | H30: E0084 | I30: Lien poste/attributs budgétaires | J30: Date de début du lien est saisie | K30: O_POS_DDLATB [Saisi] <> Vide | L30: T0167 | M30: Lien poste/attributs budgétaires | N30: Création Modification | Q30: Stagiaire ou auditeur ou élève | R30: P0004 | S30: Général | T30: Passant | U30: 40725 | W30: GPO_C_018 ET GPO_C_019 ET GPO_C_020 | X30: GPO_C_018 | Y30: =VLOOKUP(X30,'Axe 2 Règles de gestion'!$D$2:$F$22,3, FALSE) -> La date de début du lien entre le poste et les attributs budgétaires doit être postérieure ou égale à la date de création du poste. | Z30: GPO_C_019 | AA30: =VLOOKUP(Z30,'Axe 2 Règles de gestion'!$D$2:$F$22,3, FALSE) -> La date de fin du lien entre le poste et les attributs budgétaires doit être postérieure ou égale à la date de début du lien. | AB30: GPO_C_020 | AC30: =VLOOKUP(AB30,'Axe 2 Règles de gestion'!$D$2:$F$22,3, FALSE) -> La somme des pourcentages de rattachement poste/attributs budgétaires doit être égale à 100 %.
A31: 17.10.00 | B31: A | C31: 43152.5 | D31: D0003 | E31: Organisation | F31: S0005 | G31: Gestion des postes | H31: E0084 | I31: Lien poste/attributs budgétaires | J31: Date de début du lien est saisie | K31: O_POS_DDLATB [Saisi] <> Vide | L31: T0167 | M31: Lien poste/attributs budgétaires | N31: Création Modification | Q31: Ouvrier d'état | R31: P0005 | S31: Général | T31: Passant | U31: 40725 | W31: GPO_C_018 ET GPO_C_019 ET GPO_C_020 | X31: GPO_C_018 | Y31: =VLOOKUP(X31,'Axe 2 Règles de gestion'!$D$2:$F$22,3, FALSE) -> La date de début du lien entre le poste et les attributs budgétaires doit être postérieure ou égale à la date de création du poste. | Z31: GPO_C_019 | AA31: =VLOOKUP(Z31,'Axe 2 Règles de gestion'!$D$2:$F$22,3, FALSE) -> La date de fin du lien entre le poste et les attributs budgétaires doit être postérieure ou égale à la date de début du lien. | AB31: GPO_C_020 | AC31: =VLOOKUP(AB31,'Axe 2 Règles de gestion'!$D$2:$F$22,3, FALSE) -> La somme des pourcentages de rattachement poste/attributs budgétaires doit être égale à 100 %.
A32: 17.10.00 | B32: A | C32: 43152.5 | D32: D0003 | E32: Organisation | F32: S0005 | G32: Gestion des postes | H32: E0085 | I32: Lien poste/emploi-type | J32: Date de début du lien poste/emploi-type est saisie | K32: O_POS_DDLEMP [Saisi] <> Vide | L32: T0169 | M32: Lien poste/emploi-type | N32: Création Modification | Q32: Titulaire ou magistrat | R32: P0001 | S32: Général | T32: Passant | U32: 40725 | W32: GPO_C_004 ET GPO_C_005 | X32: GPO_C_004 | Y32: =VLOOKUP(X32,'Axe 2 Règles de gestion'!$D$2:$F$22,3, FALSE) -> La date de début du rattachement du poste à un emploi-type doit être postérieure ou égale à la date de création du poste. | Z32: GPO_C_005 | AA32: =VLOOKUP(Z32,'Axe 2 Règles de gestion'!$D$2:$F$22,3, FALSE) -> La date de fin du rattachement du poste à un emploi-type doit être postérieure ou égale à la date de début du lien.
A33: 17.10.00 | B33: A | C33: 43152.5 | D33: D0003 | E33: Organisation | F33: S0005 | G33: Gestion des postes | H33: E0085 | I33: Lien poste/emploi-type | J33: Date de début du lien poste/emploi-type est saisie | K33: O_POS_DDLEMP [Saisi] <> Vide | L33: T0169 | M33: Lien poste/emploi-type | N33: Création Modification | Q33: Militaire | R33: P0002 | S33: Général | T33: Passant | U33: 40725 | W33: GPO_C_004 ET GPO_C_005 | X33: GPO_C_004 | Y33: =VLOOKUP(X33,'Axe 2 Règles de gestion'!$D$2:$F$22,3, FALSE) -> La date de début du rattachement du poste à un emploi-type doit être postérieure ou égale à la date de création du poste. | Z33: GPO_C_005 | AA33: =VLOOKUP(Z33,'Axe 2 Règles de gestion'!$D$2:$F$22,3, FALSE) -> La date de fin du rattachement du poste à un emploi-type doit être postérieure ou égale à la date de début du lien.
A34: 17.10.00 | B34: A | C34: 43152.5 | D34: D0003 | E34: Organisation | F34: S0005 | G34: Gestion des postes | H34: E0085 | I34: Lien poste/emploi-type | J34: Date de début du lien poste/emploi-type est saisie | K34: O_POS_DDLEMP [Saisi] <> Vide | L34: T0169 | M34: Lien poste/emploi-type | N34: Création Modification | Q34: Contractuel | R34: P0003 | S34: Général | T34: Passant | U34: 40725 | W34: GPO_C_004 ET GPO_C_005 | X34: GPO_C_004 | Y34: =VLOOKUP(X34,'Axe 2 Règles de gestion'!$D$2:$F$22,3, FALSE) -> La date de début du rattachement du poste à un emploi-type doit être postérieure ou égale à la date de création du poste. | Z34: GPO_C_005 | AA34: =VLOOKUP(Z34,'Axe 2 Règles de gestion'!$D$2:$F$22,3, FALSE) -> La date de fin du rattachement du poste à un emploi-type doit être postérieure ou égale à la date de début du lien.
A35: 17.10.00 | B35: A | C35: 43152.5 | D35: D0003 | E35: Organisation | F35: S0005 | G35: Gestion des postes | H35: E0085 | I35: Lien poste/emploi-type | J35: Date de début du lien poste/emploi-type est saisie | K35: O_POS_DDLEMP [Saisi] <> Vide | L35: T0169 | M35: Lien poste/emploi-type | N35: Création Modification | Q35: Stagiaire ou auditeur ou élève | R35: P0004 | S35: Général | T35: Passant | U35: 40725 | W35: GPO_C_004 ET GPO_C_005 | X35: GPO_C_004 | Y35: =VLOOKUP(X35,'Axe 2 Règles de gestion'!$D$2:$F$22,3, FALSE) -> La date de début du rattachement du poste à un emploi-type doit être postérieure ou égale à la date de création du poste. | Z35: GPO_C_005 | AA35: =VLOOKUP(Z35,'Axe 2 Règles de gestion'!$D$2:$F$22,3, FALSE) -> La date de fin du rattachement du poste à un emploi-type doit être postérieure ou égale à la date de début du lien.
A36: 17.10.00 | B36: A | C36: 43152.5 | D36: D0003 | E36: Organisation | F36: S0005 | G36: Gestion des postes | H36: E0085 | I36: Lien poste/emploi-type | J36: Date de début du lien poste/emploi-type est saisie | K36: O_POS_DDLEMP [Saisi] <> Vide | L36: T0169 | M36: Lien poste/emploi-type | N36: Création Modification | Q36: Ouvrier d'état | R36: P0005 | S36: Général | T36: Passant | U36: 40725 | W36: GPO_C_004 ET GPO_C_005 | X36: GPO_C_004 | Y36: =VLOOKUP(X36,'Axe 2 Règles de gestion'!$D$2:$F$22,3, FALSE) -> La date de début du rattachement du poste à un emploi-type doit être postérieure ou égale à la date de création du poste. | Z36: GPO_C_005 | AA36: =VLOOKUP(Z36,'Axe 2 Règles de gestion'!$D$2:$F$22,3, FALSE) -> La date de fin du rattachement du poste à un emploi-type doit être postérieure ou égale à la date de début du lien.
A37: 17.10.00 | B37: A | C37: 43152.5 | D37: D0003 | E37: Organisation | F37: S0005 | G37: Gestion des postes | H37: E0086 | I37: Fonction du poste | J37: Date de début de validité de la fonction est saisie | K37: O_POS_DDLFON [Saisi] <> Vide | L37: T0171 | M37: Fonction du poste | N37: Création Modification | Q37: Titulaire ou magistrat | R37: P0001 | S37: Général | T37: Passant | U37: 40725 | W37: GPO_C_006 ET GPO_C_007 ET GPO_C_023 | X37: GPO_C_006 | Y37: =VLOOKUP(X37,'Axe 2 Règles de gestion'!$D$2:$F$22,3, FALSE) -> La date de début de validité de la fonction doit être postérieure ou égale à la date de création du poste. | Z37: GPO_C_007 | AA37: =VLOOKUP(Z37,'Axe 2 Règles de gestion'!$D$2:$F$22,3, FALSE) -> La date de fin du rattachement du poste à une fonction doit être postérieure ou égale à la date de début du lien. | AB37: GPO_C_023 | AC37: =VLOOKUP(AB37,'Axe 2 Règles de gestion'!$D$2:$F$22,3, FALSE) -> Toute fonction référencée au niveau du poste ne peut être que du type 'Fonction pour composante de rémunération hors prime de fonction et de résultat et nouvelle bonification indiciaire'
A38: 17.10.00 | B38: A | C38: 43152.5 | D38: D0003 | E38: Organisation | F38: S0005 | G38: Gestion des postes | H38: E0086 | I38: Fonction du poste | J38: Date de début de validité de la fonction est saisie | K38: O_POS_DDLFON [Saisi] <> Vide | L38: T0171 | M38: Fonction du poste | N38: Création Modification | Q38: Militaire | R38: P0002 | S38: Général | T38: Passant | U38: 40725 | W38: GPO_C_006 ET GPO_C_007 ET GPO_C_023 | X38: GPO_C_006 | Y38: =VLOOKUP(X38,'Axe 2 Règles de gestion'!$D$2:$F$22,3, FALSE) -> La date de début de validité de la fonction doit être postérieure ou égale à la date de création du poste. | Z38: GPO_C_007 | AA38: =VLOOKUP(Z38,'Axe 2 Règles de gestion'!$D$2:$F$22,3, FALSE) -> La date de fin du rattachement du poste à une fonction doit être postérieure ou égale à la date de début du lien. | AB38: GPO_C_023 | AC38: =VLOOKUP(AB38,'Axe 2 Règles de gestion'!$D$2:$F$22,3, FALSE) -> Toute fonction référencée au niveau du poste ne peut être que du type 'Fonction pour composante de rémunération hors prime de fonction et de résultat et nouvelle bonification indiciaire'
A39: 17.10.00 | B39: A | C39: 43152.5 | D39: D0003 | E39: Organisation | F39: S0005 | G39: Gestion des postes | H39: E0086 | I39: Fonction du poste | J39: Date de début de validité de la fonction est saisie | K39: O_POS_DDLFON [Saisi] <> Vide | L39: T0171 | M39: Fonction du poste | N39: Création Modification | Q39: Contractuel | R39: P0003 | S39: Général | T39: Passant | U39: 40725 | W39: GPO_C_006 ET GPO_C_007 ET GPO_C_023 | X39: GPO_C_006 | Y39: =VLOOKUP(X39,'Axe 2 Règles de gestion'!$D$2:$F$22,3, FALSE) -> La date de début de validité de la fonction doit être postérieure ou égale à la date de création du poste. | Z39: GPO_C_007 | AA39: =VLOOKUP(Z39,'Axe 2 Règles de gestion'!$D$2:$F$22,3, FALSE) -> La date de fin du rattachement du poste à une fonction doit être postérieure ou égale à la date de début du lien. | AB39: GPO_C_023 | AC39: =VLOOKUP(AB39,'Axe 2 Règles de gestion'!$D$2:$F$22,3, FALSE) -> Toute fonction référencée au niveau du poste ne peut être que du type 'Fonction pour composante de rémunération hors prime de fonction et de résultat et nouvelle bonification indiciaire'
A40: 17.10.00 | B40: A | C40: 43152.5 | D40: D0003 | E40: Organisation | F40: S0005 | G40: Gestion des postes | H40: E0086 | I40: Fonction du poste | J40: Date de début de validité de la fonction est saisie | K40: O_POS_DDLFON [Saisi] <> Vide | L40: T0171 | M40: Fonction du poste | N40: Création Modification | Q40: Stagiaire ou auditeur ou élève | R40: P0004 | S40: Général | T40: Passant | U40: 40725 | W40: GPO_C_006 ET GPO_C_007 ET GPO_C_023 | X40: GPO_C_006 | Y40: =VLOOKUP(X40,'Axe 2 Règles de gestion'!$D$2:$F$22,3, FALSE) -> La date de début de validité de la fonction doit être postérieure ou égale à la date de création du poste. | Z40: GPO_C_007 | AA40: =VLOOKUP(Z40,'Axe 2 Règles de gestion'!$D$2:$F$22,3, FALSE) -> La date de fin du rattachement du poste à une fonction doit être postérieure ou égale à la date de début du lien. | AB40: GPO_C_023 | AC40: =VLOOKUP(AB40,'Axe 2 Règles de gestion'!$D$2:$F$22,3, FALSE) -> Toute fonction référencée au niveau du poste ne peut être que du type 'Fonction pour composante de rémunération hors prime de fonction et de résultat et nouvelle bonification indiciaire'
...

Sheet Axe 1 Enchaînement RG Impact
A1: Version | B1: Type de mise à jour | C1: Date de mise à jour | D1: Identifiant Domaine | E1: Libellé du Domaine | F1: Identifiant Sous-domaine | G1: Libellé du Sous-domaine | H1: Identifiant Evénement | I1: Libellé de l'évènement | J1: Libellé condition déclenchement Evènement | K1: Condition déclenchement Evènement | L1: Identifiant type d'évènement | M1: Libellé type d'évènement | N1: Type de mise à jour | O1: Libellé condition déclenchement Type Evènement | P1: Condition déclenchement Type Evènement | Q1: Libellé Population | R1: Codification Population | S1: Général / Particulier | T1: Passant / Exclu | U1: Date de début | V1: Date de fin | W1: Impacts | X1: FIME | Y1: Statut de travail
A2: 17.10.00 | B2: A | C2: 43152.5 | D2: D0003 | E2: Organisation | F2: S0005 | G2: Gestion des postes | H2: E0081 | I2: Poste | J2: Identifiant du poste est saisi | K2: O_POS_IDENTI [Saisi] <> Vide | L2: T0161 | M2: Poste - Fermeture | N2: Modification | Q2: Titulaire ou magistrat | R2: P0001 | S2: Général | T2: Passant | U2: 40725
A3: 17.10.00 | B3: A | C3: 43152.5 | D3: D0003 | E3: Organisation | F3: S0005 | G3: Gestion des postes | H3: E0081 | I3: Poste | J3: Identifiant du poste est saisi | K3: O_POS_IDENTI [Saisi] <> Vide | L3: T0162 | M3: Poste - Suppression | N3: Suppression | Q3: Titulaire ou magistrat | R3: P0001 | S3: Général | T3: Passant | U3: 40725
A4: 17.10.00 | B4: A | C4: 43152.5 | D4: D0003 | E4: Organisation | F4: S0005 | G4: Gestion des postes | H4: E0081 | I4: Poste | J4: Identifiant du poste est saisi | K4: O_POS_IDENTI [Saisi] <> Vide | L4: T1682 | M4: Poste - Création | N4: Création | Q4: Titulaire ou magistrat | R4: P0001 | S4: Général | T4: Passant | U4: 40725
A5: 17.10.00 | B5: A | C5: 43152.5 | D5: D0003 | E5: Organisation | F5: S0005 | G5: Gestion des postes | H5: E0081 | I5: Poste | J5: Identifiant du poste est saisi | K5: O_POS_IDENTI [Saisi] <> Vide | L5: T0161 | M5: Poste - Fermeture | N5: Modification | Q5: Militaire | R5: P0002 | S5: Général | T5: Passant | U5: 40725
A6: 17.10.00 | B6: A | C6: 43152.5 | D6: D0003 | E6: Organisation | F6: S0005 | G6: Gestion des postes | H6: E0081 | I6: Poste | J6: Identifiant du poste est saisi | K6: O_POS_IDENTI [Saisi] <> Vide | L6: T0162 | M6: Poste - Suppression | N6: Suppression | Q6: Militaire | R6: P0002 | S6: Général | T6: Passant | U6: 40725
A7: 17.10.00 | B7: A | C7: 43152.5 | D7: D0003 | E7: Organisation | F7: S0005 | G7: Gestion des postes | H7: E0081 | I7: Poste | J7: Identifiant du poste est saisi | K7: O_POS_IDENTI [Saisi] <> Vide | L7: T1682 | M7: Poste - Création | N7: Création | Q7: Militaire | R7: P0002 | S7: Général | T7: Passant | U7: 40725
A8: 17.10.00 | B8: A | C8: 43152.5 | D8: D0003 | E8: Organisation | F8: S0005 | G8: Gestion des postes | H8: E0081 | I8: Poste | J8: Identifiant du poste est saisi | K8: O_POS_IDENTI [Saisi] <> Vide | L8: T0161 | M8: Poste - Fermeture | N8: Modification | Q8: Contractuel | R8: P0003 | S8: Général | T8: Passant | U8: 40725
A9: 17.10.00 | B9: A | C9: 43152.5 | D9: D0003 | E9: Organisation | F9: S0005 | G9: Gestion des postes | H9: E0081 | I9: Poste | J9: Identifiant du poste est saisi | K9: O_POS_IDENTI [Saisi] <> Vide | L9: T0162 | M9: Poste - Suppression | N9: Suppression | Q9: Contractuel | R9: P0003 | S9: Général | T9: Passant | U9: 40725
A10: 17.10.00 | B10: A | C10: 43152.5 | D10: D0003 | E10: Organisation | F10: S0005 | G10: Gestion des postes | H10: E0081 | I10: Poste | J10: Identifiant du poste est saisi | K10: O_POS_IDENTI [Saisi] <> Vide | L10: T1682 | M10: Poste - Création | N10: Création | Q10: Contractuel | R10: P0003 | S10: Général | T10: Passant | U10: 40725
A11: 17.10.00 | B11: A | C11: 43152.5 | D11: D0003 | E11: Organisation | F11: S0005 | G11: Gestion des postes | H11: E0081 | I11: Poste | J11: Identifiant du poste est saisi | K11: O_POS_IDENTI [Saisi] <> Vide | L11: T0161 | M11: Poste - Fermeture | N11: Modification | Q11: Stagiaire ou auditeur ou élève | R11: P0004 | S11: Général | T11: Passant | U11: 40725
A12: 17.10.00 | B12: A | C12: 43152.5 | D12: D0003 | E12: Organisation | F12: S0005 | G12: Gestion des postes | H12: E0081 | I12: Poste | J12: Identifiant du poste est saisi | K12: O_POS_IDENTI [Saisi] <> Vide | L12: T0162 | M12: Poste - Suppression | N12: Suppression | Q12: Stagiaire ou auditeur ou élève | R12: P0004 | S12: Général | T12: Passant | U12: 40725
A13: 17.10.00 | B13: A | C13: 43152.5 | D13: D0003 | E13: Organisation | F13: S0005 | G13: Gestion des postes | H13: E0081 | I13: Poste | J13: Identifiant du poste est saisi | K13: O_POS_IDENTI [Saisi] <> Vide | L13: T1682 | M13: Poste - Création | N13: Création | Q13: Stagiaire ou auditeur ou élève | R13: P0004 | S13: Général | T13: Passant | U13: 40725
... A56: 17.10.00 | B56: A | C56: 43152.5 | D56: D0003 | E56: Organisation | F56: S0005 | G56: Gestion des postes | H56: E0692 | I56: Poste fichier GEST | J56: Date de début du Poste fichier GEST est saisie | K56: O_POS_DDGEST [Saisi] <> Vide | L56: T1683 | M56: Poste fichier GEST | N56: Création Modification | Q56: Ouvrier d'état | R56: P0005 | S56: Général | T56: Passant | U56: 40725

Sheet Axe 1 Rattachement des actes
A1: Version | B1: Type de mise à jour | C1: Date de mise à jour | D1: Identifiant Domaine | E1: Libellé du Domaine | F1: Identifiant Sous-domaine | G1: Libellé du Sous-domaine | H1: Identifiant Evénement | I1: Libellé de l'évènement | J1: Libellé condition déclenchement Evènement | K1: Condition déclenchement Evènement | L1: Identifiant type d'évènement | M1: Libellé type d'évènement | N1: Type de mise à jour | O1: Libellé condition déclenchement Type Evènement | P1: Condition déclenchement Type Evènement | Q1: Libellé Population | R1: Codification Population | S1: Général / Particulier | T1: Passant / Exclu | U1: Date de début | V1: Date de fin | W1: Libellé condition de déclenchement 1 | X1: Condition de déclenchement 1 | Y1: Code nature 1 | Z1: Libellé nature 1 | AA1: Libellé condition de déclenchement 2 | AB1: Condition de déclenchement 2 | AC1: Code nature 2 | AD1: Libellé nature 2 | AE1: Libellé condition de déclenchement 3 | AF1: Condition de déclenchement 3 | AG1: Code nature 3 | AH1: Libellé nature 3 | AI1: Libellé condition de déclenchement 4 | AJ1: Condition de déclenchement 4 | AK1: Code nature 4 | AL1: Libellé nature 4 | AM1: Commentaire | AN1: FIME | AO1: Statut de travail
A2: 17.10.00 | B2: A | C2: 43152.5 | D2: D0003 | E2: Organisation | F2: S0005 | G2: Gestion des postes | H2: E0081 | I2: Poste | J2: Identifiant du poste est saisi | K2: O_POS_IDENTI [Saisi] <> Vide | L2: T0161 | M2: Poste - Fermeture | N2: Modification | Q2: Titulaire ou magistrat | R2: P0001 | S2: Général | T2: Passant | U2: 40725
A3: 17.10.00 | B3: A | C3: 43152.5 | D3: D0003 | E3: Organisation | F3: S0005 | G3: Gestion des postes | H3: E0081 | I3: Poste | J3: Identifiant du poste est saisi | K3: O_POS_IDENTI [Saisi] <> Vide | L3: T0162 | M3: Poste - Suppression | N3: Suppression | Q3: Titulaire ou magistrat | R3: P0001 | S3: Général | T3: Passant | U3: 40725
A4: 17.10.00 | B4: A | C4: 43152.5 | D4: D0003 | E4: Organisation | F4: S0005 | G4: Gestion des postes | H4: E0081 | I4: Poste | J4: Identifiant du poste est saisi | K4: O_POS_IDENTI [Saisi] <> Vide | L4: T1682 | M4: Poste - Création | N4: Création | Q4: Titulaire ou magistrat | R4: P0001 | S4: Général | T4: Passant | U4: 40725
A5: 17.10.00 | B5: A | C5: 43152.5 | D5: D0003 | E5: Organisation | F5: S0005 | G5: Gestion des postes | H5: E0081 | I5: Poste | J5: Identifiant du poste est saisi | K5: O_POS_IDENTI [Saisi] <> Vide | L5: T0161 | M5: Poste - Fermeture | N5: Modification | Q5: Militaire | R5: P0002 | S5: Général | T5: Passant | U5: 40725
A6: 17.10.00 | B6: A | C6: 43152.5 | D6: D0003 | E6: Organisation | F6: S0005 | G6: Gestion des postes | H6: E0081 | I6: Poste | J6: Identifiant du poste est saisi | K6: O_POS_IDENTI [Saisi] <> Vide | L6: T0162 | M6: Poste - Suppression | N6: Suppression | Q6: Militaire | R6: P0002 | S6: Général | T6: Passant | U6: 40725
A7: 17.10.00 | B7: A | C7: 43152.5 | D7: D0003 | E7: Organisation | F7: S0005 | G7: Gestion des postes | H7: E0081 | I7: Poste | J7: Identifiant du poste est saisi | K7: O_POS_IDENTI [Saisi] <> Vide | L7: T1682 | M7: Poste - Création | N7: Création | Q7: Militaire | R7: P0002 | S7: Général | T7: Passant | U7: 40725
A8: 17.10.00 | B8: A | C8: 43152.5 | D8: D0003 | E8: Organisation | F8: S0005 | G8: Gestion des postes | H8: E0081 | I8: Poste | J8: Identifiant du poste est saisi | K8: O_POS_IDENTI [Saisi] <> Vide | L8: T0161 | M8: Poste - Fermeture | N8: Modification | Q8: Contractuel | R8: P0003 | S8: Général | T8: Passant | U8: 40725
A9: 17.10.00 | B9: A | C9: 43152.5 | D9: D0003 | E9: Organisation | F9: S0005 | G9: Gestion des postes | H9: E0081 | I9: Poste | J9: Identifiant du poste est saisi | K9: O_POS_IDENTI [Saisi] <> Vide | L9: T0162 | M9: Poste - Suppression | N9: Suppression | Q9: Contractuel | R9: P0003 | S9: Général | T9: Passant | U9: 40725
A10: 17.10.00 | B10: A | C10: 43152.5 | D10: D0003 | E10: Organisation | F10: S0005 | G10: Gestion des postes | H10: E0081 | I10: Poste | J10: Identifiant du poste est saisi | K10: O_POS_IDENTI [Saisi] <> Vide | L10: T1682 | M10: Poste - Création | N10: Création | Q10: Contractuel | R10: P0003 | S10: Général | T10: Passant | U10: 40725
A11: 17.10.00 | B11: A | C11: 43152.5 | D11: D0003 | E11: Organisation | F11: S0005 | G11: Gestion des postes | H11: E0081 | I11: Poste | J11: Identifiant du poste est saisi | K11: O_POS_IDENTI [Saisi] <> Vide | L11: T0161 | M11: Poste - Fermeture | N11: Modification | Q11: Stagiaire ou auditeur ou élève | R11: P0004 | S11: Général | T11: Passant | U11: 40725
A12: 17.10.00 | B12: A | C12: 43152.5 | D12: D0003 | E12: Organisation | F12: S0005 | G12: Gestion des postes | H12: E0081 | I12: Poste | J12: Identifiant du poste est saisi | K12: O_POS_IDENTI [Saisi] <> Vide | L12: T0162 | M12: Poste - Suppression | N12: Suppression | Q12: Stagiaire ou auditeur ou élève | R12: P0004 | S12: Général | T12: Passant | U12: 40725
A13: 17.10.00 | B13: A | C13: 43152.5 | D13: D0003 | E13: Organisation | F13: S0005 | G13: Gestion des postes | H13: E0081 | I13: Poste | J13: Identifiant du poste est saisi | K13: O_POS_IDENTI [Saisi] <> Vide | L13: T1682 | M13: Poste - Création | N13: Création | Q13: Stagiaire ou auditeur ou élève | R13: P0004 | S13: Général | T13: Passant | U13: 40725
... A56: 17.10.00 | B56: A | C56: 43152.5 | D56: D0003 | E56: Organisation | F56: S0005 | G56: Gestion des postes | H56: E0692 | I56: Poste fichier GEST | J56: Date de début du Poste fichier GEST est saisie | K56: O_POS_DDGEST [Saisi] <> Vide | L56: T1683 | M56: Poste fichier GEST | N56: Création Modification | Q56: Ouvrier d'état | R56: P0005 | S56: Général | T56: Passant | U56: 40725

Sheet Axe 2 Règles de gestion
A1: Version | B1: Type de mise à jour | C1: Date de mise à jour | D1: Code de la règle | E1: Type de règle | F1: Règle littérale | G1: Références juridiques | H1: Date de début | I1: Date de fin | J1: Condition | K1: Articulation | L1: Type de contrôle | M1: Commentaire | N1: Typage RG condition | O1: Typage RG contrôle | P1: Typage RG intellectuel | Q1: Typage RG impact | R1: FIME | S1: Statut de travail | T1: Règle retenue | U1: Expression littérale
A2: 17.10.00 | B2: A | C2: 43152.5 | D2: GPO_C_001 | E2: Contrôle | F2: La date de début du rattachement du poste à une unité structurelle doit être postérieure ou égale à la date de création du poste. | H2: 40725 | K2: O_POS_DDLPUS [Saisi] >= O_POS_DCREAT [Dossier] | L2: Bloquant
A3: 17.10.00 | B3: A | C3: 43152.5 | D3: GPO_C_002 | E3: Contrôle | F3: La date de début du rattachement du poste à l'unité structurelle doit être postérieure ou égale à la date de création de l'unité structurelle. | H3: 40725 | K3: O_POS_DDLPUS [Saisi] >= O_UST_DCREAT [Dossier] | L3: Bloquant
A4: 17.10.00 | B4: A | C4: 43152.5 | D4: GPO_C_003 | E4: Contrôle | F4: La date de fin du rattachement du poste à une unité structurelle doit être postérieure ou égale à la date de début du rattachement | H4: 40725 | J4: SI O_POS_DFLPUS [Saisi] <> Vide | K4: O_POS_DFLPUS [Saisi] >= O_POS_DDLPUS [Saisi] | L4: Bloquant
A5: 17.10.00 | B5: A | C5: 43152.5 | D5: GPO_C_004 | E5: Contrôle | F5: La date de début du rattachement du poste à un emploi-type doit être postérieure ou égale à la date de création du poste. | H5: 40725 | K5: O_POS_DDLEMP [Saisi] >= O_POS_DCREAT [Dossier] | L5: Bloquant
A6: 17.10.00 | B6: A | C6: 43152.5 | D6: GPO_C_005 | E6: Contrôle | F6: La date de fin du rattachement du poste à un emploi-type doit être postérieure ou égale à la date de début du lien. | H6: 40725 | J6: SI O_POS_DFLEMP [Saisi] <> Vide | K6: O_POS_DFLEMP [Saisi] >= O_POS_DDLEMP [Saisi] | L6: Bloquant
A7: 17.10.00 | B7: A | C7: 43152.5 | D7: GPO_C_006 | E7: Contrôle | F7: La date de début de validité de la fonction doit être postérieure ou égale à la date de création du poste. | H7: 40725 | K7: O_POS_DDLFON [Saisi] >= O_POS_DCREAT [Dossier] | L7: Bloquant
A8: 17.10.00 | B8: A | C8: 43152.5 | D8: GPO_C_007 | E8: Contrôle | F8: La date de fin du rattachement du poste à une fonction doit être postérieure ou égale à la date de début du lien. | H8: 40725 | J8: SI O_POS_DFLFON [Saisi] <> Vide | K8: O_POS_DFLFON [Saisi] >= O_POS_DDLFON [Saisi] | L8: Bloquant
A9: 17.10.00 | B9: A | C9: 43152.5 | D9: GPO_C_008 | E9: Contrôle | F9: La date de début d'une propriété associée au poste doit être postérieure ou égale à la date de création du poste. | H9: 40725 | K9: O_POS_DDPROP [Saisi] >= O_POS_DCREAT [Dossier] | L9: Bloquant
A10: 17.10.00 | B10: A | C10: 43152.5 | D10: GPO_C_009 | E10: Contrôle | F10: La date de fin d'une propriété associée au poste doit être postérieure ou égale à la date de début. | H10: 40725 | J10: SI O_POS_DFPROP [Saisi] <> Vide | K10: O_POS_DFPROP [Saisi] >= O_POS_DDPROP [Saisi] | L10: Bloquant
A11: 17.10.00 | B11: A | C11: 43152.5 | D11: GPO_C_014 | E11: Contrôle | F11: Un poste ne peut être fermé que si aucun agent n'est affecté sur ce poste à la date de fermeture ou dans le futur. | H11: 40725 | J11: SI O_POS_DFERME [Saisi] <> Vide | K11: # Il n'existe aucune affectation opérationnelle active dans le SIRH qui pointe vers le poste qui va être fermé# (O_POS_IDENTI1 [Dossier] <> O_POS_IDENTI OU (O_AFF_DFIOCC [Dossier] <> Vide ET O_AFF_DFIOCC [Dossier] <= O_POS_DFERME)) | L11: Bloquant
A12: 17.10.00 | B12: A | C12: 43152.5 | D12: GPO_C_015 | E12: Contrôle | F12: La date de fermeture du poste doit être postérieure ou égale à sa date de création. | H12: 40725 | J12: SI O_POS_DFERME [Saisi] <> Vide | K12: O_POS_DFERME [Saisi] >= O_POS_DCREAT [Saisi] | L12: Bloquant
A13: 17.10.00 | B13: A | C13: 43152.5 | D13: GPO_C_016 | E13: Contrôle | F13: Un poste ne peut être supprimé que si aucun agent n'a jamais été affecté sur le poste. | H13: 40725 | K13: # Il n'existe aucune affectation opérationnelle dans le SIRH qui pointe vers le poste qui va être supprimé. # (O_POS_IDENTI1 [Dossier] <> O_POS_IDENTI) | L13: Bloquant
A14: 17.10.00 | B14: A | C14: 43152.5 | D14: GPO_C_017 | E14: Contrôle | F14: La date de fin des attributs budgétaires doit être postérieure ou égale à la date de début des attributs budgétaires. | H14: 40725 | J14: SI O_ATB_DFIATB [Saisi] <> Vide ET SI O_ATB_DDEATB [Saisi] <> Vide | K14: O_ATB_DFIATB [Saisi] >= O_ATB_DDEATB [Saisi] | L14: Bloquant
A15: 17.10.00 | B15: A | C15: 43152.5 | D15: GPO_C_018 | E15: Contrôle | F15: La date de début du lien entre le poste et les attributs budgétaires doit être postérieure ou égale à la date de création du poste. | H15: 40725 | K15: O_POS_DDLATB [Saisi] >= O_POS_DCREAT [Dossier] | L15: Bloquant
A16: 17.10.00 | B16: A | C16: 43152.5 | D16: GPO_C_019 | E16: Contrôle | F16: La date de fin du lien entre le poste et les attributs budgétaires doit être postérieure ou égale à la date de début du lien. | H16: 40725 | J16: SI O_POS_DFLATB [Saisi] <> Vide | K16: O_POS_DFLATB [Saisi] >= O_POS_DDLATB [Saisi] | L16: Bloquant
A17: 17.10.00 | B17: A | C17: 43152.5 | D17: GPO_C_020 | E17: Contrôle | F17: La somme des pourcentages de rattachement poste/attributs budgétaires doit être égale à 100 %. | H17: 40725 | J17: SI O_POS_POUATB [Saisi] <> Vide | K17: # La somme des pourcentages de rattachement O_POS_POUATB des occurrences de la sous-rubrique "Lien poste/attributs budgétaires" pour lesquelles la date de début O_POS_DDLATB est inférieure ou égale à la date de début O_POS_DDLATB de l'occurrence en cours de saisie et dont la date de fin O_POS_DFLATB est vide ou supérieure ou égale à la date de début O_POS_DDLATB de l'occurrence en cours de saisie, plus O_POS_POUATB [Saisi] doit être égale à 100 % # | L17: Bloquant
A18: 17.10.00 | B18: A | C18: 43152.5 | D18: GPO_C_021 | E18: Contrôle | F18: La date de début du lien poste/compétences doit être postérieure ou égale à la date de création du poste. | H18: 40725 | K18: O_POS_DDLCOM [Saisi] >= O_POS_DCREAT [Dossier] | L18: Bloquant
A19: 17.10.00 | B19: A | C19: 43152.5 | D19: GPO_C_022 | E19: Contrôle | F19: La date de fin du lien poste/compétences doit être postérieure ou égale à la date de début. | H19: 40725 | J19: SI O_POS_DFLCOM [Saisi] <> Vide | K19: O_POS_DFLCOM [Saisi] >= O_POS_DDLCOM [Saisi] | L19: Bloquant
A20: 17.10.00 | B20: A | C20: 43152.5 | D20: GPO_C_023 | E20: Contrôle | F20: Toute fonction référencée au niveau du poste ne peut être que du type 'Fonction pour composante de rémunération hors prime de fonction et de résultat et nouvelle bonification indiciaire' | H20: 40725 | J20: SI O_POS_IDFONC [Saisi] <> Vide | K20: O_POS_IDFONC [Saisi] = FONCTION.IDEN05 ET FONCTION.R_REL_TYPFON = 'FOAUT' | L20: Bloquant
A21: 17.10.00 | B21: A | C21: 43152.5 | D21: GPO_C_463 | E21: Contrôle | F21: La date de début du poste fichier GEST doit être postérieure ou égale à la date de création de l'unité structurelle. | H21: 40725 | K21: O_POS_DDGEST [Saisi] >= O_UST_DCREAT [Dossier] | L21: Bloquant
A22: 17.10.00 | B22: A | C22: 43152.5 | D22: GPO_C_963 | E22: Contrôle | F22: La date de fin du poste fichier GEST doit être postérieure ou égale à la date de début du poste fichier GEST. | H22: 40725 | J22: SI O_POS_DFGEST [Saisi] <> Vide | K22: O_POS_DFGEST [Saisi] >= O_POS_DDGEST [Saisi] | L22: Bloquant
