Workbook

Sheet Mode opératoire
B1: MODE OPERATOIRE
B2: Une fois l'ensemble des mouvements créés pour une remise de paie d'un mois donné, les contrôles s'effectuent successivement sur les mouvements de type 20 présents dans la remise de paie. Les contrôles d'alimentation automatique des zones du mouvement par les données du dossier agent sont portés par la modélisation du dictionnaire de données qui précise le cas échéant quelle donnée du dossier agent alimente la zone du mouvement avec ou sans transformation. Pour les zones concernées, ces contrôles doivent garantir la cohérence entre la donnée du dossier agent et la zone du mouvement. Ils ne sont pas redécrits dans les tableaux structurés de RG PAY.

Sheet Axe 1 Enchainement des RG
A1: Version | B1: Type de mise à jour | C1: Date de mise à jour | D1: Identifiant Domaine | E1: Libellé du Domaine | F1: Identifiant Sous-domaine | G1: Libellé du Sous-domaine | H1: Identifiant Evénement | I1: Libellé de l'évènement | J1: Libellé condition déclenchement Evènement | K1: Condition déclenchement Evènement | L1: Identifiant type d'évènement | M1: Libellé type d'évènement | N1: Type de mise à jour | O1: Libellé condition déclenchement Type Evènement | P1: Condition déclenchement Type Evènement | Q1: Libellé Population | R1: Codification Population | S1: Général / Particulier | T1: Passant / Exclu | U1: Date de début | V1: Date de fin | W1: Règles mobilisées | X1: Identifiant Règle de contrôle 1 | Y1: Libellé Règle de contrôle 1 | Z1: Identifiant Règle de contrôle 2 | AA1: Libellé Règle de contrôle 2 | AB1: Identifiant Règle de contrôle 3 | AC1: Libellé Règle de contrôle 3 | AD1: Identifiant Règle de contrôle 4 | AE1: Libellé Règle de contrôle 4 | AF1: Identifiant Règle de contrôle 5 | AG1: Libellé Règle de contrôle 5 | AH1: Identifiant Règle de contrôle 6 | AI1: Libellé Règle de contrôle 6 | AJ1: Identifiant Règle de contrôle 7 | AK1: Libellé Règle de contrôle 7 | AL1: Identifiant Règle de contrôle 8 | AM1: Libellé Règle de contrôle 8 | AN1: Identifiant Règle de contrôle 9 | AO1: Libellé Règle de contrôle 9 | AP1: Identifiant Règle de contrôle 10 | AQ1: Libellé Règle de contrôle 10 | AR1: Identifiant Règle de contrôle 11 | AS1: Libellé Règle de contrôle 11 | AT1: Identifiant Règle de contrôle 12 | AU1: Libellé Règle de contrôle 12 | AV1: Identifiant Règle de contrôle 13 | AW1: Libellé Règle de contrôle 13 | AX1: Identifiant Règle de contrôle 14 | AY1: Libellé Règle de contrôle 14 | AZ1: FIME | BA1: Statut de travail
A2: 25.00.00 | B2: A | C2: 45818.402 | D2: D0016 | E2: Contrôles PAY | F2: S0177 | G2: Mouvement 20 | H2: E1012 | I2: Contrôles d'alimentation du mouvement 20 | J2: Le code indemnité d'un mouvement 20 est saisi | K2: BG20_COD_IND [BG_Occurrence_courante] <> Vide | L2: T2445 | M2: Contrôles Précompte cotis. sal. RAFP | N2: Création Modification | O2: Le code indemnité saisi est 'Précompte cotis. sal. RAFP' | P2: BG20_COD_IND [BG_Occurrence_courante] = '0954' | Q2: Titulaire ou magistrat | R2: P0001 | S2: Général | T2: Passant | U2: 40725 | W2: G20_C_001 ET G20_C_003 ET G20_C_004 ET G20_C_005 ET G20_C_006 ET G20_C_007 ET G20_C_015 ET G20_C_016 ET G20_C_017 ET G20_C_021 ET G20_C_019 ET G20_C_020 | X2: G20_C_001 | Y2: =VLOOKUP(X2,'Axe 2 Règles de gestion'!$D$2:$F$23,3, FALSE) -> Le code origine doit être "0" (mois courant) pour l'indemnité '0954 - Précompte cotis. sal. RAFP'. | Z2: G20_C_003 | AA2: =VLOOKUP(Z2,'Axe 2 Règles de gestion'!$D$2:$F$23,3, FALSE) -> Il est interdit de codifier le sens 1 (sens contraire) si le code origine est 0 (mois courant). | AB2: G20_C_004 | AC2: =VLOOKUP(AB2,'Axe 2 Règles de gestion'!$D$2:$F$23,3, FALSE) -> Si le mode de calcul est "A - Montant précalculé", alors il faut laisser à vide la zone nombre d'unités. | AD2: G20_C_005 | AE2: =VLOOKUP(AD2,'Axe 2 Règles de gestion'!$D$2:$F$23,3, FALSE) -> Le terme « GREVE » ne doit pas être utilisé dans la zone "Libellé complémentaire". | AF2: G20_C_006 | AG2: =VLOOKUP(AF2,'Axe 2 Règles de gestion'!$D$2:$F$23,3, FALSE) -> Si le mode de calcul est "A - Montant précalculé", il faut que le montant soit différent de vide. | AH2: G20_C_007 | AI2: =VLOOKUP(AH2,'Axe 2 Règles de gestion'!$D$2:$F$23,3, FALSE) -> Si le mode de calcul est "B - Nombre d'unités x montant unitaire", il faut que le nombre d'unités et le montant soient différents de vide. | AJ2: G20_C_015 | AK2: =VLOOKUP(AJ2,'Axe 2 Règles de gestion'!$D$2:$F$23,3, FALSE) -> Le code sens est obligatoire. | AL2: G20_C_016 | AM2: =VLOOKUP(AL2,'Axe 2 Règles de gestion'!$D$2:$F$23,3, FALSE) -> Le code origine est obligatoire. | AN2: G20_C_017 | AO2: =VLOOKUP(AN2,'Axe 2 Règles de gestion'!$D$2:$F$23,3, FALSE) -> Seuls les modes de calcul "A - Montant précalculé", "B - Nombre d'unités x montant unitaire", "G - Indemnité à déduire" sont autorisés. | AP2: G20_C_021 | AQ2: =VLOOKUP(AP2,'Axe 2 Règles de gestion'!$D$2:$F$23,3, FALSE) -> Le nombre total de mouvements 20 pour le mois de paie en cours doit être inférieur ou égal à 30. | AR2: G20_C_019 | AS2: =VLOOKUP(AR2,'Axe 2 Règles de gestion'!$D$2:$F$23,3, FALSE) -> Si le mode de calcul est "G - Indemnité à déduire", alors il faut laisser vide la zone nombre d'unités. | AT2: G20_C_020 | AU2: =VLOOKUP(AT2,'Axe 2 Règles de gestion'!$D$2:$F$23,3, FALSE) -> Si le mode de calcul est "G - Indemnité à déduire", il faut que le montant soit différent de vide.
A3: 25.00.00 | B3: A | C3: 45818.403 | D3: D0016 | E3: Contrôles PAY | F3: S0177 | G3: Mouvement 20 | H3: E1012 | I3: Contrôles d'alimentation du mouvement 20 | J3: Le code indemnité d'un mouvement 20 est saisi | K3: BG20_COD_IND [BG_Occurrence_courante] <> Vide | L3: T2446 | M3: Contrôles Cotis. prefon | N3: Création Modification | O3: Le code indemnité saisi est 'Cotis. prefon' | P3: BG20_COD_IND [BG_Occurrence_courante] = '0879' | Q3: Titulaire ou magistrat | R3: P0001 | S3: Général | T3: Passant | U3: 40725 | W3: G20_C_002 ET G20_C_003 ET G20_C_005 ET G20_C_011 ET G20_C_012 ET G20_C_014 ET G20_C_015 ET G20_C_016 ET G20_C_021 | X3: G20_C_002 | Y3: =VLOOKUP(X3,'Axe 2 Règles de gestion'!$D$2:$F$23,3, FALSE) -> Lorsque la date de paye correspond au mois de janvier, le code origine "1" (année courante) ne doit pas être notifié. | Z3: G20_C_003 | AA3: =VLOOKUP(Z3,'Axe 2 Règles de gestion'!$D$2:$F$23,3, FALSE) -> Il est interdit de codifier le sens 1 (sens contraire) si le code origine est 0 (mois courant). | AB3: G20_C_005 | AC3: =VLOOKUP(AB3,'Axe 2 Règles de gestion'!$D$2:$F$23,3, FALSE) -> Le terme « GREVE » ne doit pas être utilisé dans la zone "Libellé complémentaire". | AD3: G20_C_011 | AE3: =VLOOKUP(AD3,'Axe 2 Règles de gestion'!$D$2:$F$23,3, FALSE) -> Si la zone mode de calcul est "Calcul PREFON" (MC = E), la zone "Nombre d'unités" doit être vide. | AF3: G20_C_012 | AG3: =VLOOKUP(AF3,'Axe 2 Règles de gestion'!$D$2:$F$23,3, FALSE) -> Pour la retenue PREFON (code '0879'), seuls les deux derniers caractères (positions 57 à 58) de la zone MONTANT doivent être servies. | AH3: G20_C_014 | AI3: =VLOOKUP(AH3,'Axe 2 Règles de gestion'!$D$2:$F$23,3, FALSE) -> Pour la retenue PREFON (code '0879'), le mode de calcul doit être "E - Calcul PREFON (code classe)". | AJ3: G20_C_015 | AK3: =VLOOKUP(AJ3,'Axe 2 Règles de gestion'!$D$2:$F$23,3, FALSE) -> Le code sens est obligatoire. | AL3: G20_C_016 | AM3: =VLOOKUP(AL3,'Axe 2 Règles de gestion'!$D$2:$F$23,3, FALSE) -> Le code origine est obligatoire. | AN3: G20_C_021 | AO3: =VLOOKUP(AN3,'Axe 2 Règles de gestion'!$D$2:$F$23,3, FALSE) -> Le nombre total de mouvements 20 pour le mois de paie en cours doit être inférieur ou égal à 30.
A4: 25.00.00 | B4: A | C4: 45818.407 | D4: D0016 | E4: Contrôles PAY | F4: S0177 | G4: Mouvement 20 | H4: E1012 | I4: Contrôles d'alimentation du mouvement 20 | J4: Le code indemnité d'un mouvement 20 est saisi | K4: BG20_COD_IND [BG_Occurrence_courante] <> Vide | L4: T2447 | M4: Contrôles Avantages en nature et Avantage en nature ntic et Avantage en nature nourriture et Avantage en nature véhicule et Avantages en nature divers | N4: Création Modification | O4: Le code indemnité saisi est 'Avantages en nature' ou 'Avantage en nature ntic' ou 'Avantage en nature nourriture' ou 'Avantage en nature véhicule' ou 'Avantages en nature divers' | P4: BG20_COD_IND [BG_Occurrence_courante] DANS ('0136', '1404', '1405', '1406', '1407') | Q4: Titulaire ou magistrat | R4: P0001 | S4: Général | T4: Passant | U4: 40725 | W4: G20_C_002 ET G20_C_003 ET G20_C_005 ET G20_C_008 ET G20_C_009 ET G20_C_013 ET G20_C_015 ET G20_C_016 ET G20_C_021 | X4: G20_C_002 | Y4: =VLOOKUP(X4,'Axe 2 Règles de gestion'!$D$2:$F$23,3, FALSE) -> Lorsque la date de paye correspond au mois de janvier, le code origine "1" (année courante) ne doit pas être notifié. | Z4: G20_C_003 | AA4: =VLOOKUP(Z4,'Axe 2 Règles de gestion'!$D$2:$F$23,3, FALSE) -> Il est interdit de codifier le sens 1 (sens contraire) si le code origine est 0 (mois courant). | AB4: G20_C_005 | AC4: =VLOOKUP(AB4,'Axe 2 Règles de gestion'!$D$2:$F$23,3, FALSE) -> Le terme « GREVE » ne doit pas être utilisé dans la zone "Libellé complémentaire". | AD4: G20_C_008 | AE4: =VLOOKUP(AD4,'Axe 2 Règles de gestion'!$D$2:$F$23,3, FALSE) -> Si le mode de calcul est "H - Indemnité à ne pas payer (avantage en nature)", il faut que le nombre d'unités soit vide. | AF4: G20_C_009 | AG4: =VLOOKUP(AF4,'Axe 2 Règles de gestion'!$D$2:$F$23,3, FALSE) -> Si le mode de calcul est "H - Indemnité à ne pas payer (avantage en nature)", il faut que le montant soit différent de vide. | AH4: G20_C_013 | AI4: =VLOOKUP(AH4,'Axe 2 Règles de gestion'!$D$2:$F$23,3, FALSE) -> Pour les avantages en nature (codes '0136','1404','1405','1406','1407), le mode de calcul doit être "H - Indemnité à ne pas payer (avantage en nature)". | AJ4: G20_C_015 | AK4: =VLOOKUP(AJ4,'Axe 2 Règles de gestion'!$D$2:$F$23,3, FALSE) -> Le code sens est obligatoire. | AL4: G20_C_016 | AM4: =VLOOKUP(AL4,'Axe 2 Règles de gestion'!$D$2:$F$23,3, FALSE) -> Le code origine est obligatoire. | AN4: G20_C_021 | AO4: =VLOOKUP(AN4,'Axe 2 Règles de gestion'!$D$2:$F$23,3, FALSE) -> Le nombre total de mouvements 20 pour le mois de paie en cours doit être inférieur ou égal à 30.
A5: 25.00.00 | B5: A | C5: 45818.408 | D5: D0016 | E5: Contrôles PAY | F5: S0177 | G5: Mouvement 20 | H5: E1012 | I5: Contrôles d'alimentation du mouvement 20 | J5: Le code indemnité d'un mouvement 20 est saisi | K5: BG20_COD_IND [BG_Occurrence_courante] <> Vide | L5: T2448 | M5: Contrôles Cotisation assurance chômage | N5: Création Modification | O5: Le code indemnité saisi est 'Cotisation assurance chômage' | P5: BG20_COD_IND [BG_Occurrence_courante] = '0870' | Q5: Titulaire ou magistrat | R5: P0001 | S5: Général | T5: Exclu | U5: 40725
A6: 25.00.00 | B6: A | C6: 45818.409 | D6: D0016 | E6: Contrôles PAY | F6: S0177 | G6: Mouvement 20 | H6: E1012 | I6: Contrôles d'alimentation du mouvement 20 | J6: Le code indemnité d'un mouvement 20 est saisi | K6: BG20_COD_IND [BG_Occurrence_courante] <> Vide | L6: T2449 | M6: Contrôles autres indemnités et retenues exceptionnelles | N6: Création Modification | O6: Le code indemnité/retenue saisi est différent de '0954', '0879', '0136', '1404', '1405', '1406', '1407', '0870' | P6: BG20_COD_IND [BG_Occurrence_courante] PAS DANS ('0954', '0879', '0136', '1404', '1405', '1406', '1407', '0870') | Q6: Titulaire ou magistrat | R6: P0001 | S6: Général | T6: Passant | U6: 40725 | W6: G20_C_002 ET G20_C_003 ET G20_C_004 ET G20_C_005 ET G20_C_006 ET G20_C_007 ET G20_C_015 ET G20_C_016 ET G20_C_017 ET G20_C_019 ET G20_C_020 ET G20_C_021 | X6: G20_C_002 | Y6: =VLOOKUP(X6,'Axe 2 Règles de gestion'!$D$2:$F$23,3, FALSE) -> Lorsque la date de paye correspond au mois de janvier, le code origine "1" (année courante) ne doit pas être notifié. | Z6: G20_C_003 | AA6: =VLOOKUP(Z6,'Axe 2 Règles de gestion'!$D$2:$F$23,3, FALSE) -> Il est interdit de codifier le sens 1 (sens contraire) si le code origine est 0 (mois courant). | AB6: G20_C_004 | AC6: =VLOOKUP(AB6,'Axe 2 Règles de gestion'!$D$2:$F$23,3, FALSE) -> Si le mode de calcul est "A - Montant précalculé", alors il faut laisser à vide la zone nombre d'unités. | AD6: G20_C_005 | AE6: =VLOOKUP(AD6,'Axe 2 Règles de gestion'!$D$2:$F$23,3, FALSE) -> Le terme « GREVE » ne doit pas être utilisé dans la zone "Libellé complémentaire". | AF6: G20_C_006 | AG6: =VLOOKUP(AF6,'Axe 2 Règles de gestion'!$D$2:$F$23,3, FALSE) -> Si le mode de calcul est "A - Montant précalculé", il faut que le montant soit différent de vide. | AH6: G20_C_007 | AI6: =VLOOKUP(AH6,'Axe 2 Règles de gestion'!$D$2:$F$23,3, FALSE) -> Si le mode de calcul est "B - Nombre d'unités x montant unitaire", il faut que le nombre d'unités et le montant soient différents de vide. | AJ6: G20_C_015 | AK6: =VLOOKUP(AJ6,'Axe 2 Règles de gestion'!$D$2:$F$23,3, FALSE) -> Le code sens est obligatoire. | AL6: G20_C_016 | AM6: =VLOOKUP(AL6,'Axe 2 Règles de gestion'!$D$2:$F$23,3, FALSE) -> Le code origine est obligatoire. | AN6: G20_C_017 | AO6: =VLOOKUP(AN6,'Axe 2 Règles de gestion'!$D$2:$F$23,3, FALSE) -> Seuls les modes de calcul "A - Montant précalculé", "B - Nombre d'unités x montant unitaire", "G - Indemnité à déduire" sont autorisés. | AP6: G20_C_019 | AQ6: =VLOOKUP(AP6,'Axe 2 Règles de gestion'!$D$2:$F$23,3, FALSE) -> Si le mode de calcul est "G - Indemnité à déduire", alors il faut laisser vide la zone nombre d'unités. | AR6: G20_C_020 | AS6: =VLOOKUP(AR6,'Axe 2 Règles de gestion'!$D$2:$F$23,3, FALSE) -> Si le mode de calcul est "G - Indemnité à déduire", il faut que le montant soit différent de vide. | AT6: G20_C_021 | AU6: =VLOOKUP(AT6,'Axe 2 Règles de gestion'!$D$2:$F$23,3, FALSE) -> Le nombre total de mouvements 20 pour le mois de paie en cours doit être inférieur ou égal à 30.
A7: 25.00.00 | B7: A | C7: 45818.402 | D7: D0016 | E7: Contrôles PAY | F7: S0177 | G7: Mouvement 20 | H7: E1012 | I7: Contrôles d'alimentation du mouvement 20 | J7: Le code indemnité d'un mouvement 20 est saisi | K7: BG20_COD_IND [BG_Occurrence_courante] <> Vide | L7: T2445 | M7: Contrôles Précompte cotis. sal. RAFP | N7: Création Modification | O7: Le code indemnité saisi est 'Précompte cotis. sal. RAFP' | P7: BG20_COD_IND [BG_Occurrence_courante] = '0954' | Q7: Militaire | R7: P0002 | S7: Général | T7: Passant | U7: 40725 | W7: G20_C_001 ET G20_C_003 ET G20_C_004 ET G20_C_005 ET G20_C_006 ET G20_C_007 ET G20_C_015 ET G20_C_016 ET G20_C_017 ET G20_C_021 ET G20_C_019 ET G20_C_020 | X7: G20_C_001 | Y7: =VLOOKUP(X7,'Axe 2 Règles de gestion'!$D$2:$F$23,3, FALSE) -> Le code origine doit être "0" (mois courant) pour l'indemnité '0954 - Précompte cotis. sal. RAFP'. | Z7: G20_C_003 | AA7: =VLOOKUP(Z7,'Axe 2 Règles de gestion'!$D$2:$F$23,3, FALSE) -> Il est interdit de codifier le sens 1 (sens contraire) si le code origine est 0 (mois courant). | AB7: G20_C_004 | AC7: =VLOOKUP(AB7,'Axe 2 Règles de gestion'!$D$2:$F$23,3, FALSE) -> Si le mode de calcul est "A - Montant précalculé", alors il faut laisser à vide la zone nombre d'unités. | AD7: G20_C_005 | AE7: =VLOOKUP(AD7,'Axe 2 Règles de gestion'!$D$2:$F$23,3, FALSE) -> Le terme « GREVE » ne doit pas être utilisé dans la zone "Libellé complémentaire". | AF7: G20_C_006 | AG7: =VLOOKUP(AF7,'Axe 2 Règles de gestion'!$D$2:$F$23,3, FALSE) -> Si le mode de calcul est "A - Montant précalculé", il faut que le montant soit différent de vide. | AH7: G20_C_007 | AI7: =VLOOKUP(AH7,'Axe 2 Règles de gestion'!$D$2:$F$23,3, FALSE) -> Si le mode de calcul est "B - Nombre d'unités x montant unitaire", il faut que le nombre d'unités et le montant soient différents de vide. | AJ7: G20_C_015 | AK7: =VLOOKUP(AJ7,'Axe 2 Règles de gestion'!$D$2:$F$23,3, FALSE) -> Le code sens est obligatoire. | AL7: G20_C_016 | AM7: =VLOOKUP(AL7,'Axe 2 Règles de gestion'!$D$2:$F$23,3, FALSE) -> Le code origine est obligatoire. | AN7: G20_C_017 | AO7: =VLOOKUP(AN7,'Axe 2 Règles de gestion'!$D$2:$F$23,3, FALSE) -> Seuls les modes de calcul "A - Montant précalculé", "B - Nombre d'unités x montant unitaire", "G - Indemnité à déduire" sont autorisés. | AP7: G20_C_021 | AQ7: =VLOOKUP(AP7,'Axe 2 Règles de gestion'!$D$2:$F$23,3, FALSE) -> Le nombre total de mouvements 20 pour le mois de paie en cours doit être inférieur ou égal à 30. | AR7: G20_C_019 | AS7: =VLOOKUP(AR7,'Axe 2 Règles de gestion'!$D$2:$F$23,3, FALSE) -> Si le mode de calcul est "G - Indemnité à déduire", alors il faut laisser vide la zone nombre d'unités. | AT7: G20_C_020 | AU7: =VLOOKUP(AT7,'Axe 2 Règles de gestion'!$D$2:$F$23,3, FALSE) -> Si le mode de calcul est "G - Indemnité à déduire", il faut que le montant soit différent de vide.
A8: 25.00.00 | B8: A | C8: 45818.404 | D8: D0016 | E8: Contrôles PAY | F8: S0177 | G8: Mouvement 20 | H8: E1012 | I8: Contrôles d'alimentation du mouvement 20 | J8: Le code indemnité d'un mouvement 20 est saisi | K8: BG20_COD_IND [BG_Occurrence_courante] <> Vide | L8: T2446 | M8: Contrôles Cotis. prefon | N8: Création Modification | O8: Le code indemnité saisi est 'Cotis. prefon' | P8: BG20_COD_IND [BG_Occurrence_courante] = '0879' | Q8: Militaire | R8: P0002 | S8: Général | T8: Passant | U8: 40725 | W8: G20_C_002 ET G20_C_003 ET G20_C_005 ET G20_C_011 ET G20_C_012 ET G20_C_014 ET G20_C_015 ET G20_C_016 ET G20_C_021 | X8: G20_C_002 | Y8: =VLOOKUP(X8,'Axe 2 Règles de gestion'!$D$2:$F$23,3, FALSE) -> Lorsque la date de paye correspond au mois de janvier, le code origine "1" (année courante) ne doit pas être notifié. | Z8: G20_C_003 | AA8: =VLOOKUP(Z8,'Axe 2 Règles de gestion'!$D$2:$F$23,3, FALSE) -> Il est interdit de codifier le sens 1 (sens contraire) si le code origine est 0 (mois courant). | AB8: G20_C_005 | AC8: =VLOOKUP(AB8,'Axe 2 Règles de gestion'!$D$2:$F$23,3, FALSE) -> Le terme « GREVE » ne doit pas être utilisé dans la zone "Libellé complémentaire". | AD8: G20_C_011 | AE8: =VLOOKUP(AD8,'Axe 2 Règles de gestion'!$D$2:$F$23,3, FALSE) -> Si la zone mode de calcul est "Calcul PREFON" (MC = E), la zone "Nombre d'unités" doit être vide. | AF8: G20_C_012 | AG8: =VLOOKUP(AF8,'Axe 2 Règles de gestion'!$D$2:$F$23,3, FALSE) -> Pour la retenue PREFON (code '0879'), seuls les deux derniers caractères (positions 57 à 58) de la zone MONTANT doivent être servies. | AH8: G20_C_014 | AI8: =VLOOKUP(AH8,'Axe 2 Règles de gestion'!$D$2:$F$23,3, FALSE) -> Pour la retenue PREFON (code '0879'), le mode de calcul doit être "E - Calcul PREFON (code classe)". | AJ8: G20_C_015 | AK8: =VLOOKUP(AJ8,'Axe 2 Règles de gestion'!$D$2:$F$23,3, FALSE) -> Le code sens est obligatoire. | AL8: G20_C_016 | AM8: =VLOOKUP(AL8,'Axe 2 Règles de gestion'!$D$2:$F$23,3, FALSE) -> Le code origine est obligatoire. | AN8: G20_C_021 | AO8: =VLOOKUP(AN8,'Axe 2 Règles de gestion'!$D$2:$F$23,3, FALSE) -> Le nombre total de mouvements 20 pour le mois de paie en cours doit être inférieur ou égal à 30.
A9: 25.00.00 | B9: A | C9: 45818.408 | D9: D0016 | E9: Contrôles PAY | F9: S0177 | G9: Mouvement 20 | H9: E1012 | I9: Contrôles d'alimentation du mouvement 20 | J9: Le code indemnité d'un mouvement 20 est saisi | K9: BG20_COD_IND [BG_Occurrence_courante] <> Vide | L9: T2447 | M9: Contrôles Avantages en nature et Avantage en nature ntic et Avantage en nature nourriture et Avantage en nature véhicule et Avantages en nature divers | N9: Création Modification | O9: Le code indemnité saisi est 'Avantages en nature' ou 'Avantage en nature ntic' ou 'Avantage en nature nourriture' ou 'Avantage en nature véhicule' ou 'Avantages en nature divers' | P9: BG20_COD_IND [BG_Occurrence_courante] DANS ('0136', '1404', '1405', '1406', '1407') | Q9: Militaire | R9: P0002 | S9: Général | T9: Passant | U9: 40725 | W9: G20_C_002 ET G20_C_003 ET G20_C_005 ET G20_C_008 ET G20_C_009 ET G20_C_013 ET G20_C_015 ET G20_C_016 ET G20_C_021 | X9: G20_C_002 | Y9: =VLOOKUP(X9,'Axe 2 Règles de gestion'!$D$2:$F$23,3, FALSE) -> Lorsque la date de paye correspond au mois de janvier, le code origine "1" (année courante) ne doit pas être notifié. | Z9: G20_C_003 | AA9: =VLOOKUP(Z9,'Axe 2 Règles de gestion'!$D$2:$F$23,3, FALSE) -> Il est interdit de codifier le sens 1 (sens contraire) si le code origine est 0 (mois courant). | AB9: G20_C_005 | AC9: =VLOOKUP(AB9,'Axe 2 Règles de gestion'!$D$2:$F$23,3, FALSE) -> Le terme « GREVE » ne doit pas être utilisé dans la zone "Libellé complémentaire". | AD9: G20_C_008 | AE9: =VLOOKUP(AD9,'Axe 2 Règles de gestion'!$D$2:$F$23,3, FALSE) -> Si le mode de calcul est "H - Indemnité à ne pas payer (avantage en nature)", il faut que le nombre d'unités soit vide. | AF9: G20_C_009 | AG9: =VLOOKUP(AF9,'Axe 2 Règles de gestion'!$D$2:$F$23,3, FALSE) -> Si le mode de calcul est "H - Indemnité à ne pas payer (avantage en nature)", il faut que le montant soit différent de vide. | AH9: G20_C_013 | AI9: =VLOOKUP(AH9,'Axe 2 Règles de gestion'!$D$2:$F$23,3, FALSE) -> Pour les avantages en nature (codes '0136','1404','1405','1406','1407), le mode de calcul doit être "H - Indemnité à ne pas payer (avantage en nature)". | AJ9: G20_C_015 | AK9: =VLOOKUP(AJ9,'Axe 2 Règles de gestion'!$D$2:$F$23,3, FALSE) -> Le code sens est obligatoire. | AL9: G20_C_016 | AM9: =VLOOKUP(AL9,'Axe 2 Règles de gestion'!$D$2:$F$23,3, FALSE) -> Le code origine est obligatoire. | AN9: G20_C_021 | AO9: =VLOOKUP(AN9,'Axe 2 Règles de gestion'!$D$2:$F$23,3, FALSE) -> Le nombre total de mouvements 20 pour le mois de paie en cours doit être inférieur ou égal à 30.
A10: 25.00.00 | B10: A | C10: 45818.408 | D10: D0016 | E10: Contrôles PAY | F10: S0177 | G10: Mouvement 20 | H10: E1012 | I10: Contrôles d'alimentation du mouvement 20 | J10: Le code indemnité d'un mouvement 20 est saisi | K10: BG20_COD_IND [BG_Occurrence_courante] <> Vide | L10: T2448 | M10: Contrôles Cotisation assurance chômage | N10: Création Modification | O10: Le code indemnité saisi est 'Cotisation assurance chômage' | P10: BG20_COD_IND [BG_Occurrence_courante] = '0870' | Q10: Militaire | R10: P0002 | S10: Général | T10: Exclu | U10: 40725
A11: 25.00.00 | B11: A | C11: 45818.41 | D11: D0016 | E11: Contrôles PAY | F11: S0177 | G11: Mouvement 20 | H11: E1012 | I11: Contrôles d'alimentation du mouvement 20 | J11: Le code indemnité d'un mouvement 20 est saisi | K11: BG20_COD_IND [BG_Occurrence_courante] <> Vide | L11: T2449 | M11: Contrôles autres indemnités et retenues exceptionnelles | N11: Création Modification | O11: Le code indemnité/retenue saisi est différent de '0954', '0879', '0136', '1404', '1405', '1406', '1407', '0870' | P11: BG20_COD_IND [BG_Occurrence_courante] PAS DANS ('0954', '0879', '0136', '1404', '1405', '1406', '1407', '0870') | Q11: Militaire | R11: P0002 | S11: Général | T11: Passant | U11: 40725 | W11: G20_C_002 ET G20_C_003 ET G20_C_004 ET G20_C_005 ET G20_C_006 ET G20_C_007 ET G20_C_015 ET G20_C_016 ET G20_C_017 ET G20_C_019 ET G20_C_020 ET G20_C_021 | X11: G20_C_002 | Y11: =VLOOKUP(X11,'Axe 2 Règles de gestion'!$D$2:$F$23,3, FALSE) -> Lorsque la date de paye correspond au mois de janvier, le code origine "1" (année courante) ne doit pas être notifié. | Z11: G20_C_003 | AA11: =VLOOKUP(Z11,'Axe 2 Règles de gestion'!$D$2:$F$23,3, FALSE) -> Il est interdit de codifier le sens 1 (sens contraire) si le code origine est 0 (mois courant). | AB11: G20_C_004 | AC11: =VLOOKUP(AB11,'Axe 2 Règles de gestion'!$D$2:$F$23,3, FALSE) -> Si le mode de calcul est "A - Montant précalculé", alors il faut laisser à vide la zone nombre d'unités. | AD11: G20_C_005 | AE11: =VLOOKUP(AD11,'Axe 2 Règles de gestion'!$D$2:$F$23,3, FALSE) -> Le terme « GREVE » ne doit pas être utilisé dans la zone "Libellé complémentaire". | AF11: G20_C_006 | AG11: =VLOOKUP(AF11,'Axe 2 Règles de gestion'!$D$2:$F$23,3, FALSE) -> Si le mode de calcul est "A - Montant précalculé", il faut que le montant soit différent de vide. | AH11: G20_C_007 | AI11: =VLOOKUP(AH11,'Axe 2 Règles de gestion'!$D$2:$F$23,3, FALSE) -> Si le mode de calcul est "B - Nombre d'unités x montant unitaire", il faut que le nombre d'unités et le montant soient différents de vide. | AJ11: G20_C_015 | AK11: =VLOOKUP(AJ11,'Axe 2 Règles de gestion'!$D$2:$F$23,3, FALSE) -> Le code sens est obligatoire. | AL11: G20_C_016 | AM11: =VLOOKUP(AL11,'Axe 2 Règles de gestion'!$D$2:$F$23,3, FALSE) -> Le code origine est obligatoire. | AN11: G20_C_017 | AO11: =VLOOKUP(AN11,'Axe 2 Règles de gestion'!$D$2:$F$23,3, FALSE) -> Seuls les modes de calcul "A - Montant précalculé", "B - Nombre d'unités x montant unitaire", "G - Indemnité à déduire" sont autorisés. | AP11: G20_C_019 | AQ11: =VLOOKUP(AP11,'Axe 2 Règles de gestion'!$D$2:$F$23,3, FALSE) -> Si le mode de calcul est "G - Indemnité à déduire", alors il faut laisser vide la zone nombre d'unités. | AR11: G20_C_020 | AS11: =VLOOKUP(AR11,'Axe 2 Règles de gestion'!$D$2:$F$23,3, FALSE) -> Si le mode de calcul est "G - Indemnité à déduire", il faut que le montant soit différent de vide. | AT11: G20_C_021 | AU11: =VLOOKUP(AT11,'Axe 2 Règles de gestion'!$D$2:$F$23,3, FALSE) -> Le nombre total de mouvements 20 pour le mois de paie en cours doit être inférieur ou égal à 30.
A12: 25.00.00 | B12: A | C12: 45818.403 | D12: D0016 | E12: Contrôles PAY | F12: S0177 | G12: Mouvement 20 | H12: E1012 | I12: Contrôles d'alimentation du mouvement 20 | J12: Le code indemnité d'un mouvement 20 est saisi | K12: BG20_COD_IND [BG_Occurrence_courante] <> Vide | L12: T2445 | M12: Contrôles Précompte cotis. sal. RAFP | N12: Création Modification | O12: Le code indemnité saisi est 'Précompte cotis. sal. RAFP' | P12: BG20_COD_IND [BG_Occurrence_courante] = '0954' | Q12: Contractuel | R12: P0003 | S12: Général | T12: Passant | U12: 40725 | W12: G20_C_025 ET G20_C_001 ET G20_C_003 ET G20_C_004 ET G20_C_005 ET G20_C_006 ET G20_C_007 ET G20_C_015 ET G20_C_016 ET G20_C_017 ET G20_C_021 ET G20_C_019 ET G20_C_020 | X12: G20_C_025 | Y12: =VLOOKUP(X12,'Axe 2 Règles de gestion'!$D$2:$F$23,3, FALSE) -> L'agent doit être détaché sur contrat. | Z12: G20_C_001 | AA12: =VLOOKUP(Z12,'Axe 2 Règles de gestion'!$D$2:$F$23,3, FALSE) -> Le code origine doit être "0" (mois courant) pour l'indemnité '0954 - Précompte cotis. sal. RAFP'. | AB12: G20_C_003 | AC12: =VLOOKUP(AB12,'Axe 2 Règles de gestion'!$D$2:$F$23,3, FALSE) -> Il est interdit de codifier le sens 1 (sens contraire) si le code origine est 0 (mois courant). | AD12: G20_C_004 | AE12: =VLOOKUP(AD12,'Axe 2 Règles de gestion'!$D$2:$F$23,3, FALSE) -> Si le mode de calcul est "A - Montant précalculé", alors il faut laisser à vide la zone nombre d'unités. | AF12: G20_C_005 | AG12: =VLOOKUP(AF12,'Axe 2 Règles de gestion'!$D$2:$F$23,3, FALSE) -> Le terme « GREVE » ne doit pas être utilisé dans la zone "Libellé complémentaire". | AH12: G20_C_006 | AI12: =VLOOKUP(AH12,'Axe 2 Règles de gestion'!$D$2:$F$23,3, FALSE) -> Si le mode de calcul est "A - Montant précalculé", il faut que le montant soit différent de vide. | AJ12: G20_C_007 | AK12: =VLOOKUP(AJ12,'Axe 2 Règles de gestion'!$D$2:$F$23,3, FALSE) -> Si le mode de calcul est "B - Nombre d'unités x montant unitaire", il faut que le nombre d'unités et le montant soient différents de vide. | AL12: G20_C_015 | AM12: =VLOOKUP(AL12,'Axe 2 Règles de gestion'!$D$2:$F$23,3, FALSE) -> Le code sens est obligatoire. | AN12: G20_C_016 | AO12: =VLOOKUP(AN12,'Axe 2 Règles de gestion'!$D$2:$F$23,3, FALSE) -> Le code origine est obligatoire. | AP12: G20_C_017 | AQ12: =VLOOKUP(AP12,'Axe 2 Règles de gestion'!$D$2:$F$23,3, FALSE) -> Seuls les modes de calcul "A - Montant précalculé", "B - Nombre d'unités x montant unitaire", "G - Indemnité à déduire" sont autorisés. | AR12: G20_C_021 | AS12: =VLOOKUP(AR12,'Axe 2 Règles de gestion'!$D$2:$F$23,3, FALSE) -> Le nombre total de mouvements 20 pour le mois de paie en cours doit être inférieur ou égal à 30. | AT12: G20_C_019 | AU12: =VLOOKUP(AT12,'Axe 2 Règles de gestion'!$D$2:$F$23,3, FALSE) -> Si le mode de calcul est "G - Indemnité à déduire", alors il faut laisser vide la zone nombre d'unités. | AV12: G20_C_020 | AW12: =VLOOKUP(AV12,'Axe 2 Règles de gestion'!$D$2:$F$23,3, FALSE) -> Si le mode de calcul est "G - Indemnité à déduire", il faut que le montant soit différent de vide.
A13: 25.00.00 | B13: A | C13: 45818.404 | D13: D0016 | E13: Contrôles PAY | F13: S0177 | G13: Mouvement 20 | H13: E1012 | I13: Contrôles d'alimentation du mouvement 20 | J13: Le code indemnité d'un mouvement 20 est saisi | K13: BG20_COD_IND [BG_Occurrence_courante] <> Vide | L13: T2446 | M13: Contrôles Cotis. prefon | N13: Création Modification | O13: Le code indemnité saisi est 'Cotis. prefon' | P13: BG20_COD_IND [BG_Occurrence_courante] = '0879' | Q13: Contractuel | R13: P0003 | S13: Général | T13: Passant | U13: 40725 | W13: G20_C_002 ET G20_C_003 ET G20_C_005 ET G20_C_011 ET G20_C_012 ET G20_C_014 ET G20_C_015 ET G20_C_016 ET G20_C_021 | X13: G20_C_002 | Y13: =VLOOKUP(X13,'Axe 2 Règles de gestion'!$D$2:$F$23,3, FALSE) -> Lorsque la date de paye correspond au mois de janvier, le code origine "1" (année courante) ne doit pas être notifié. | Z13: G20_C_003 | AA13: =VLOOKUP(Z13,'Axe 2 Règles de gestion'!$D$2:$F$23,3, FALSE) -> Il est interdit de codifier le sens 1 (sens contraire) si le code origine est 0 (mois courant). | AB13: G20_C_005 | AC13: =VLOOKUP(AB13,'Axe 2 Règles de gestion'!$D$2:$F$23,3, FALSE) -> Le terme « GREVE » ne doit pas être utilisé dans la zone "Libellé complémentaire". | AD13: G20_C_011 | AE13: =VLOOKUP(AD13,'Axe 2 Règles de gestion'!$D$2:$F$23,3, FALSE) -> Si la zone mode de calcul est "Calcul PREFON" (MC = E), la zone "Nombre d'unités" doit être vide. | AF13: G20_C_012 | AG13: =VLOOKUP(AF13,'Axe 2 Règles de gestion'!$D$2:$F$23,3, FALSE) -> Pour la retenue PREFON (code '0879'), seuls les deux derniers caractères (positions 57 à 58) de la zone MONTANT doivent être servies. | AH13: G20_C_014 | AI13: =VLOOKUP(AH13,'Axe 2 Règles de gestion'!$D$2:$F$23,3, FALSE) -> Pour la retenue PREFON (code '0879'), le mode de calcul doit être "E - Calcul PREFON (code classe)". | AJ13: G20_C_015 | AK13: =VLOOKUP(AJ13,'Axe 2 Règles de gestion'!$D$2:$F$23,3, FALSE) -> Le code sens est obligatoire. | AL13: G20_C_016 | AM13: =VLOOKUP(AL13,'Axe 2 Règles de gestion'!$D$2:$F$23,3, FALSE) -> Le code origine est obligatoire. | AN13: G20_C_021 | AO13: =VLOOKUP(AN13,'Axe 2 Règles de gestion'!$D$2:$F$23,3, FALSE) -> Le nombre total de mouvements 20 pour le mois de paie en cours doit être inférieur ou égal à 30.
A14: 25.00.00 | B14: A | C14: 45818.407 | D14: D0016 | E14: Contrôles PAY | F14: S0177 | G14: Mouvement 20 | H14: E1012 | I14: Contrôles d'alimentation du mouvement 20 | J14: Le code indemnité d'un mouvement 20 est saisi | K14: BG20_COD_IND [BG_Occurrence_courante] <> Vide | L14: T2447 | M14: Contrôles Avantages en nature et Avantage en nature ntic et Avantage en nature nourriture et Avantage en nature véhicule et Avantages en nature divers | N14: Création Modification | O14: Le code indemnité saisi est 'Avantages en nature' ou 'Avantage en nature ntic' ou 'Avantage en nature nourriture' ou 'Avantage en nature véhicule' ou 'Avantages en nature divers' | P14: BG20_COD_IND [BG_Occurrence_courante] DANS ('0136', '1404', '1405', '1406', '1407') | Q14: Contractuel | R14: P0003 | S14: Général | T14: Passant | U14: 40725 | W14: G20_C_002 ET G20_C_003 ET G20_C_005 ET G20_C_008 ET G20_C_009 ET G20_C_013 ET G20_C_015 ET G20_C_016 ET G20_C_021 | X14: G20_C_002 | Y14: =VLOOKUP(X14,'Axe 2 Règles de gestion'!$D$2:$F$23,3, FALSE) -> Lorsque la date de paye correspond au mois de janvier, le code origine "1" (année courante) ne doit pas être notifié. | Z14: G20_C_003 | AA14: =VLOOKUP(Z14,'Axe 2 Règles de gestion'!$D$2:$F$23,3, FALSE) -> Il est interdit de codifier le sens 1 (sens contraire) si le code origine est 0 (mois courant). | AB14: G20_C_005 | AC14: =VLOOKUP(AB14,'Axe 2 Règles de gestion'!$D$2:$F$23,3, FALSE) -> Le terme « GREVE » ne doit pas être utilisé dans la zone "Libellé complémentaire". | AD14: G20_C_008 | AE14: =VLOOKUP(AD14,'Axe 2 Règles de gestion'!$D$2:$F$23,3, FALSE) -> Si le mode de calcul est "H - Indemnité à ne pas payer (avantage en nature)", il faut que le nombre d'unités soit vide. | AF14: G20_C_009 | AG14: =VLOOKUP(AF14,'Axe 2 Règles de gestion'!$D$2:$F$23,3, FALSE) -> Si le mode de calcul est "H - Indemnité à ne pas payer (avantage en nature)", il faut que le montant soit différent de vide. | AH14: G20_C_013 | AI14: =VLOOKUP(AH14,'Axe 2 Règles de gestion'!$D$2:$F$23,3, FALSE) -> Pour les avantages en nature (codes '0136','1404','1405','1406','1407), le mode de calcul doit être "H - Indemnité à ne pas payer (avantage en nature)". | AJ14: G20_C_015 | AK14: =VLOOKUP(AJ14,'Axe 2 Règles de gestion'!$D$2:$F$23,3, FALSE) -> Le code sens est obligatoire. | AL14: G20_C_016 | AM14: =VLOOKUP(AL14,'Axe 2 Règles de gestion'!$D$2:$F$23,3, FALSE) -> Le code origine est obligatoire. | AN14: G20_C_021 | AO14: =VLOOKUP(AN14,'Axe 2 Règles de gestion'!$D$2:$F$23,3, FALSE) -> Le nombre total de mouvements 20 pour le mois de paie en cours doit être inférieur ou égal à 30.
A15: 25.00.00 | B15: A | C15: 45818.408 | D15: D0016 | E15: Contrôles PAY | F15: S0177 | G15: Mouvement 20 | H15: E1012 | I15: Contrôles d'alimentation du mouvement 20 | J15: Le code indemnité d'un mouvement 20 est saisi | K15: BG20_COD_IND [BG_Occurrence_courante] <> Vide | L15: T2448 | M15: Contrôles Cotisation assurance chômage | N15: Création Modification | O15: Le code indemnité saisi est 'Cotisation assurance chômage' | P15: BG20_COD_IND [BG_Occurrence_courante] = '0870' | Q15: Contractuel | R15: P0003 | S15: Général | T15: Exclu | U15: 40725
A16: 25.00.00 | B16: A | C16: 45818.41 | D16: D0016 | E16: Contrôles PAY | F16: S0177 | G16: Mouvement 20 | H16: E1012 | I16: Contrôles d'alimentation du mouvement 20 | J16: Le code indemnité d'un mouvement 20 est saisi | K16: BG20_COD_IND [BG_Occurrence_courante] <> Vide | L16: T2449 | M16: Contrôles autres indemnités et retenues exceptionnelles | N16: Création Modification | O16: Le code indemnité/retenue saisi est différent de '0954', '0879', '0136', '1404', '1405', '1406', '1407', '0870' | P16: BG20_COD_IND [BG_Occurrence_courante] PAS DANS ('0954', '0879', '0136', '1404', '1405', '1406', '1407', '0870') | Q16: Contractuel | R16: P0003 | S16: Général | T16: Passant | U16: 40725 | W16: G20_C_002 ET G20_C_003 ET G20_C_004 ET G20_C_005 ET G20_C_006 ET G20_C_007 ET G20_C_015 ET G20_C_016 ET G20_C_017 ET G20_C_019 ET G20_C_020 ET G20_C_021 | X16: G20_C_002 | Y16: =VLOOKUP(X16,'Axe 2 Règles de gestion'!$D$2:$F$23,3, FALSE) -> Lorsque la date de paye correspond au mois de janvier, le code origine "1" (année courante) ne doit pas être notifié. | Z16: G20_C_003 | AA16: =VLOOKUP(Z16,'Axe 2 Règles de gestion'!$D$2:$F$23,3, FALSE) -> Il est interdit de codifier le sens 1 (sens contraire) si le code origine est 0 (mois courant). | AB16: G20_C_004 | AC16: =VLOOKUP(AB16,'Axe 2 Règles de gestion'!$D$2:$F$23,3, FALSE) -> Si le mode de calcul est "A - Montant précalculé", alors il faut laisser à vide la zone nombre d'unités. | AD16: G20_C_005 | AE16: =VLOOKUP(AD16,'Axe 2 Règles de gestion'!$D$2:$F$23,3, FALSE) -> Le terme « GREVE » ne doit pas être utilisé dans la zone "Libellé complémentaire". | AF16: G20_C_006 | AG16: =VLOOKUP(AF16,'Axe 2 Règles de gestion'!$D$2:$F$23,3, FALSE) -> Si le mode de calcul est "A - Montant précalculé", il faut que le montant soit différent de vide. | AH16: G20_C_007 | AI16: =VLOOKUP(AH16,'Axe 2 Règles de gestion'!$D$2:$F$23,3, FALSE) -> Si le mode de calcul est "B - Nombre d'unités x montant unitaire", il faut que le nombre d'unités et le montant soient différents de vide. | AJ16: G20_C_015 | AK16: =VLOOKUP(AJ16,'Axe 2 Règles de gestion'!$D$2:$F$23,3, FALSE) -> Le code sens est obligatoire. | AL16: G20_C_016 | AM16: =VLOOKUP(AL16,'Axe 2 Règles de gestion'!$D$2:$F$23,3, FALSE) -> Le code origine est obligatoire. | AN16: G20_C_017 | AO16: =VLOOKUP(AN16,'Axe 2 Règles de gestion'!$D$2:$F$23,3, FALSE) -> Seuls les modes de calcul "A - Montant précalculé", "B - Nombre d'unités x montant unitaire", "G - Indemnité à déduire" sont autorisés. | AP16: G20_C_019 | AQ16: =VLOOKUP(AP16,'Axe 2 Règles de gestion'!$D$2:$F$23,3, FALSE) -> Si le mode de calcul est "G - Indemnité à déduire", alors il faut laisser vide la zone nombre d'unités. | AR16: G20_C_020 | AS16: =VLOOKUP(AR16,'Axe 2 Règles de gestion'!$D$2:$F$23,3, FALSE) -> Si le mode de calcul est "G - Indemnité à déduire", il faut que le montant soit différent de vide. | AT16: G20_C_021 | AU16: =VLOOKUP(AT16,'Axe 2 Règles de gestion'!$D$2:$F$23,3, FALSE) -> Le nombre total de mouvements 20 pour le mois de paie en cours doit être inférieur ou égal à 30.
A17: 25.00.00 | B17: A | C17: 45818.402 | D17: D0016 | E17: Contrôles PAY | F17: S0177 | G17: Mouvement 20 | H17: E1012 | I17: Contrôles d'alimentation du mouvement 20 | J17: Le code indemnité d'un mouvement 20 est saisi | K17: BG20_COD_IND [BG_Occurrence_courante] <> Vide | L17: T2445 | M17: Contrôles Précompte cotis. sal. RAFP | N17: Création Modification | O17: Le code indemnité saisi est 'Précompte cotis. sal. RAFP' | P17: BG20_COD_IND [BG_Occurrence_courante] = '0954' | Q17: Stagiaire ou auditeur ou élève | R17: P0004 | S17: Général | T17: Passant | U17: 40725 | W17: G20_C_001 ET G20_C_003 ET G20_C_004 ET G20_C_005 ET G20_C_006 ET G20_C_007 ET G20_C_015 ET G20_C_016 ET G20_C_017 ET G20_C_021 ET G20_C_019 ET G20_C_020 | X17: G20_C_001 | Y17: =VLOOKUP(X17,'Axe 2 Règles de gestion'!$D$2:$F$23,3, FALSE) -> Le code origine doit être "0" (mois courant) pour l'indemnité '0954 - Précompte cotis. sal. RAFP'. | Z17: G20_C_003 | AA17: =VLOOKUP(Z17,'Axe 2 Règles de gestion'!$D$2:$F$23,3, FALSE) -> Il est interdit de codifier le sens 1 (sens contraire) si le code origine est 0 (mois courant). | AB17: G20_C_004 | AC17: =VLOOKUP(AB17,'Axe 2 Règles de gestion'!$D$2:$F$23,3, FALSE) -> Si le mode de calcul est "A - Montant précalculé", alors il faut laisser à vide la zone nombre d'unités. | AD17: G20_C_005 | AE17: =VLOOKUP(AD17,'Axe 2 Règles de gestion'!$D$2:$F$23,3, FALSE) -> Le terme « GREVE » ne doit pas être utilisé dans la zone "Libellé complémentaire". | AF17: G20_C_006 | AG17: =VLOOKUP(AF17,'Axe 2 Règles de gestion'!$D$2:$F$23,3, FALSE) -> Si le mode de calcul est "A - Montant précalculé", il faut que le montant soit différent de vide. | AH17: G20_C_007 | AI17: =VLOOKUP(AH17,'Axe 2 Règles de gestion'!$D$2:$F$23,3, FALSE) -> Si le mode de calcul est "B - Nombre d'unités x montant unitaire", il faut que le nombre d'unités et le montant soient différents de vide. | AJ17: G20_C_015 | AK17: =VLOOKUP(AJ17,'Axe 2 Règles de gestion'!$D$2:$F$23,3, FALSE) -> Le code sens est obligatoire. | AL17: G20_C_016 | AM17: =VLOOKUP(AL17,'Axe 2 Règles de gestion'!$D$2:$F$23,3, FALSE) -> Le code origine est obligatoire. | AN17: G20_C_017 | AO17: =VLOOKUP(AN17,'Axe 2 Règles de gestion'!$D$2:$F$23,3, FALSE) -> Seuls les modes de calcul "A - Montant précalculé", "B - Nombre d'unités x montant unitaire", "G - Indemnité à déduire" sont autorisés. | AP17: G20_C_021 | AQ17: =VLOOKUP(AP17,'Axe 2 Règles de gestion'!$D$2:$F$23,3, FALSE) -> Le nombre total de mouvements 20 pour le mois de paie en cours doit être inférieur ou égal à 30. | AR17: G20_C_019 | AS17: =VLOOKUP(AR17,'Axe 2 Règles de gestion'!$D$2:$F$23,3, FALSE) -> Si le mode de calcul est "G - Indemnité à déduire", alors il faut laisser vide la zone nombre d'unités. | AT17: G20_C_020 | AU17: =VLOOKUP(AT17,'Axe 2 Règles de gestion'!$D$2:$F$23,3, FALSE) -> Si le mode de calcul est "G - Indemnité à déduire", il faut que le montant soit différent de vide.
A18: 25.00.00 | B18: A | C18: 45818.403 | D18: D0016 | E18: Contrôles PAY | F18: S0177 | G18: Mouvement 20 | H18: E1012 | I18: Contrôles d'alimentation du mouvement 20 | J18: Le code indemnité d'un mouvement 20 est saisi | K18: BG20_COD_IND [BG_Occurrence_courante] <> Vide | L18: T2446 | M18: Contrôles Cotis. prefon | N18: Création Modification | O18: Le code indemnité saisi est 'Cotis. prefon' | P18: BG20_COD_IND [BG_Occurrence_courante] = '0879' | Q18: Stagiaire ou auditeur ou élève | R18: P0004 | S18: Général | T18: Passant | U18: 40725 | W18: G20_C_002 ET G20_C_003 ET G20_C_005 ET G20_C_011 ET G20_C_012 ET G20_C_014 ET G20_C_015 ET G20_C_016 ET G20_C_021 | X18: G20_C_002 | Y18: =VLOOKUP(X18,'Axe 2 Règles de gestion'!$D$2:$F$23,3, FALSE) -> Lorsque la date de paye correspond au mois de janvier, le code origine "1" (année courante) ne doit pas être notifié. | Z18: G20_C_003 | AA18: =VLOOKUP(Z18,'Axe 2 Règles de gestion'!$D$2:$F$23,3, FALSE) -> Il est interdit de codifier le sens 1 (sens contraire) si le code origine est 0 (mois courant). | AB18: G20_C_005 | AC18: =VLOOKUP(AB18,'Axe 2 Règles de gestion'!$D$2:$F$23,3, FALSE) -> Le terme « GREVE » ne doit pas être utilisé dans la zone "Libellé complémentaire". | AD18: G20_C_011 | AE18: =VLOOKUP(AD18,'Axe 2 Règles de gestion'!$D$2:$F$23,3, FALSE) -> Si la zone mode de calcul est "Calcul PREFON" (MC = E), la zone "Nombre d'unités" doit être vide. | AF18: G20_C_012 | AG18: =VLOOKUP(AF18,'Axe 2 Règles de gestion'!$D$2:$F$23,3, FALSE) -> Pour la retenue PREFON (code '0879'), seuls les deux derniers caractères (positions 57 à 58) de la zone MONTANT doivent être servies. | AH18: G20_C_014 | AI18: =VLOOKUP(AH18,'Axe 2 Règles de gestion'!$D$2:$F$23,3, FALSE) -> Pour la retenue PREFON (code '0879'), le mode de calcul doit être "E - Calcul PREFON (code classe)". | AJ18: G20_C_015 | AK18: =VLOOKUP(AJ18,'Axe 2 Règles de gestion'!$D$2:$F$23,3, FALSE) -> Le code sens est obligatoire. | AL18: G20_C_016 | AM18: =VLOOKUP(AL18,'Axe 2 Règles de gestion'!$D$2:$F$23,3, FALSE) -> Le code origine est obligatoire. | AN18: G20_C_021 | AO18: =VLOOKUP(AN18,'Axe 2 Règles de gestion'!$D$2:$F$23,3, FALSE) -> Le nombre total de mouvements 20 pour le mois de paie en cours doit être inférieur ou égal à 30.
A19: 25.00.00 | B19: A | C19: 45818.407 | D19: D0016 | E19: Contrôles PAY | F19: S0177 | G19: Mouvement 20 | H19: E1012 | I19: Contrôles d'alimentation du mouvement 20 | J19: Le code indemnité d'un mouvement 20 est saisi | K19: BG20_COD_IND [BG_Occurrence_courante] <> Vide | L19: T2447 | M19: Contrôles Avantages en nature et Avantage en nature ntic et Avantage en nature nourriture et Avantage en nature véhicule et Avantages en nature divers | N19: Création Modification | O19: Le code indemnité saisi est 'Avantages en nature' ou 'Avantage en nature ntic' ou 'Avantage en nature nourriture' ou 'Avantage en nature véhicule' ou 'Avantages en nature divers' | P19: BG20_COD_IND [BG_Occurrence_courante] DANS ('0136', '1404', '1405', '1406', '1407') | Q19: Stagiaire ou auditeur ou élève | R19: P0004 | S19: Général | T19: Passant | U19: 40725 | W19: G20_C_002 ET G20_C_003 ET G20_C_005 ET G20_C_008 ET G20_C_009 ET G20_C_013 ET G20_C_015 ET G20_C_016 ET G20_C_021 | X19: G20_C_002 | Y19: =VLOOKUP(X19,'Axe 2 Règles de gestion'!$D$2:$F$23,3, FALSE) -> Lorsque la date de paye correspond au mois de janvier, le code origine "1" (année courante) ne doit pas être notifié. | Z19: G20_C_003 | AA19: =VLOOKUP(Z19,'Axe 2 Règles de gestion'!$D$2:$F$23,3, FALSE) -> Il est interdit de codifier le sens 1 (sens contraire) si le code origine est 0 (mois courant). | AB19: G20_C_005 | AC19: =VLOOKUP(AB19,'Axe 2 Règles de gestion'!$D$2:$F$23,3, FALSE) -> Le terme « GREVE » ne doit pas être utilisé dans la zone "Libellé complémentaire". | AD19: G20_C_008 | AE19: =VLOOKUP(AD19,'Axe 2 Règles de gestion'!$D$2:$F$23,3, FALSE) -> Si le mode de calcul est "H - Indemnité à ne pas payer (avantage en nature)", il faut que le nombre d'unités soit vide. | AF19: G20_C_009 | AG19: =VLOOKUP(AF19,'Axe 2 Règles de gestion'!$D$2:$F$23,3, FALSE) -> Si le mode de calcul est "H - Indemnité à ne pas payer (avantage en nature)", il faut que le montant soit différent de vide. | AH19: G20_C_013 | AI19: =VLOOKUP(AH19,'Axe 2 Règles de gestion'!$D$2:$F$23,3, FALSE) -> Pour les avantages en nature (codes '0136','1404','1405','1406','1407), le mode de calcul doit être "H - Indemnité à ne pas payer (avantage en nature)". | AJ19: G20_C_015 | AK19: =VLOOKUP(AJ19,'Axe 2 Règles de gestion'!$D$2:$F$23,3, FALSE) -> Le code sens est obligatoire. | AL19: G20_C_016 | AM19: =VLOOKUP(AL19,'Axe 2 Règles de gestion'!$D$2:$F$23,3, FALSE) -> Le code origine est obligatoire. | AN19: G20_C_021 | AO19: =VLOOKUP(AN19,'Axe 2 Règles de gestion'!$D$2:$F$23,3, FALSE) -> Le nombre total de mouvements 20 pour le mois de paie en cours doit être inférieur ou égal à 30.
A20: 25.00.00 | B20: A | C20: 45818.408 | D20: D0016 | E20: Contrôles PAY | F20: S0177 | G20: Mouvement 20 | H20: E1012 | I20: Contrôles d'alimentation du mouvement 20 | J20: Le code indemnité d'un mouvement 20 est saisi | K20: BG20_COD_IND [BG_Occurrence_courante] <> Vide | L20: T2448 | M20: Contrôles Cotisation assurance chômage | N20: Création Modification | O20: Le code indemnité saisi est 'Cotisation assurance chômage' | P20: BG20_COD_IND [BG_Occurrence_courante] = '0870' | Q20: Stagiaire ou auditeur ou élève | R20: P0004 | S20: Général | T20: Exclu | U20: 40725
A21: 25.00.00 | B21: A | C21: 45818.409 | D21: D0016 | E21: Contrôles PAY | F21: S0177 | G21: Mouvement 20 | H21: E1012 | I21: Contrôles d'alimentation du mouvement 20 | J21: Le code indemnité d'un mouvement 20 est saisi | K21: BG20_COD_IND [BG_Occurrence_courante] <> Vide | L21: T2449 | M21: Contrôles autres indemnités et retenues exceptionnelles | N21: Création Modification | O21: Le code indemnité/retenue saisi est différent de '0954', '0879', '0136', '1404', '1405', '1406', '1407', '0870' | P21: BG20_COD_IND [BG_Occurrence_courante] PAS DANS ('0954', '0879', '0136', '1404', '1405', '1406', '1407', '0870') | Q21: Stagiaire ou auditeur ou élève | R21: P0004 | S21: Général | T21: Passant | U21: 40725 | W21: G20_C_002 ET G20_C_003 ET G20_C_004 ET G20_C_005 ET G20_C_006 ET G20_C_007 ET G20_C_015 ET G20_C_016 ET G20_C_017 ET G20_C_019 ET G20_C_020 ET G20_C_021 | X21: G20_C_002 | Y21: =VLOOKUP(X21,'Axe 2 Règles de gestion'!$D$2:$F$23,3, FALSE) -> Lorsque la date de paye correspond au mois de janvier, le code origine "1" (année courante) ne doit pas être notifié. | Z21: G20_C_003 | AA21: =VLOOKUP(Z21,'Axe 2 Règles de gestion'!$D$2:$F$23,3, FALSE) -> Il est interdit de codifier le sens 1 (sens contraire) si le code origine est 0 (mois courant). | AB21: G20_C_004 | AC21: =VLOOKUP(AB21,'Axe 2 Règles de gestion'!$D$2:$F$23,3, FALSE) -> Si le mode de calcul est "A - Montant précalculé", alors il faut laisser à vide la zone nombre d'unités. | AD21: G20_C_005 | AE21: =VLOOKUP(AD21,'Axe 2 Règles de gestion'!$D$2:$F$23,3, FALSE) -> Le terme « GREVE » ne doit pas être utilisé dans la zone "Libellé complémentaire". | AF21: G20_C_006 | AG21: =VLOOKUP(AF21,'Axe 2 Règles de gestion'!$D$2:$F$23,3, FALSE) -> Si le mode de calcul est "A - Montant précalculé", il faut que le montant soit différent de vide. | AH21: G20_C_007 | AI21: =VLOOKUP(AH21,'Axe 2 Règles de gestion'!$D$2:$F$23,3, FALSE) -> Si le mode de calcul est "B - Nombre d'unités x montant unitaire", il faut que le nombre d'unités et le montant soient différents de vide. | AJ21: G20_C_015 | AK21: =VLOOKUP(AJ21,'Axe 2 Règles de gestion'!$D$2:$F$23,3, FALSE) -> Le code sens est obligatoire. | AL21: G20_C_016 | AM21: =VLOOKUP(AL21,'Axe 2 Règles de gestion'!$D$2:$F$23,3, FALSE) -> Le code origine est obligatoire. | AN21: G20_C_017 | AO21: =VLOOKUP(AN21,'Axe 2 Règles de gestion'!$D$2:$F$23,3, FALSE) -> Seuls les modes de calcul "A - Montant précalculé", "B - Nombre d'unités x montant unitaire", "G - Indemnité à déduire" sont autorisés. | AP21: G20_C_019 | AQ21: =VLOOKUP(AP21,'Axe 2 Règles de gestion'!$D$2:$F$23,3, FALSE) -> Si le mode de calcul est "G - Indemnité à déduire", alors il faut laisser vide la zone nombre d'unités. | AR21: G20_C_020 | AS21: =VLOOKUP(AR21,'Axe 2 Règles de gestion'!$D$2:$F$23,3, FALSE) -> Si le mode de calcul est "G - Indemnité à déduire", il faut que le montant soit différent de vide. | AT21: G20_C_021 | AU21: =VLOOKUP(AT21,'Axe 2 Règles de gestion'!$D$2:$F$23,3, FALSE) -> Le nombre total de mouvements 20 pour le mois de paie en cours doit être inférieur ou égal à 30.
A22: 25.00.00 | B22: A | C22: 45818.403 | D22: D0016 | E22: Contrôles PAY | F22: S0177 | G22: Mouvement 20 | H22: E1012 | I22: Contrôles d'alimentation du mouvement 20 | J22: Le code indemnité d'un mouvement 20 est saisi | K22: BG20_COD_IND [BG_Occurrence_courante] <> Vide | L22: T2445 | M22: Contrôles Précompte cotis. sal. RAFP | N22: Création Modification | O22: Le code indemnité saisi est 'Précompte cotis. sal. RAFP' | P22: BG20_COD_IND [BG_Occurrence_courante] = '0954' | Q22: Ouvrier d'état | R22: P0005 | S22: Général | T22: Exclu | U22: 40725
A23: 25.00.00 | B23: A | C23: 45818.404 | D23: D0016 | E23: Contrôles PAY | F23: S0177 | G23: Mouvement 20 | H23: E1012 | I23: Contrôles d'alimentation du mouvement 20 | J23: Le code indemnité d'un mouvement 20 est saisi | K23: BG20_COD_IND [BG_Occurrence_courante] <> Vide | L23: T2446 | M23: Contrôles Cotis. prefon | N23: Création Modification | O23: Le code indemnité saisi est 'Cotis. prefon' | P23: BG20_COD_IND [BG_Occurrence_courante] = '0879' | Q23: Ouvrier d'état | R23: P0005 | S23: Général | T23: Passant | U23: 40725 | W23: G20_C_002 ET G20_C_003 ET G20_C_005 ET G20_C_011 ET G20_C_012 ET G20_C_014 ET G20_C_015 ET G20_C_016 ET G20_C_021 | X23: G20_C_002 | Y23: =VLOOKUP(X23,'Axe 2 Règles de gestion'!$D$2:$F$23,3, FALSE) -> Lorsque la date de paye correspond au mois de janvier, le code origine "1" (année courante) ne doit pas être notifié. | Z23: G20_C_003 | AA23: =VLOOKUP(Z23,'Axe 2 Règles de gestion'!$D$2:$F$23,3, FALSE) -> Il est interdit de codifier le sens 1 (sens contraire) si le code origine est 0 (mois courant). | AB23: G20_C_005 | AC23: =VLOOKUP(AB23,'Axe 2 Règles de gestion'!$D$2:$F$23,3, FALSE) -> Le terme « GREVE » ne doit pas être utilisé dans la zone "Libellé complémentaire". | AD23: G20_C_011 | AE23: =VLOOKUP(AD23,'Axe 2 Règles de gestion'!$D$2:$F$23,3, FALSE) -> Si la zone mode de calcul est "Calcul PREFON" (MC = E), la zone "Nombre d'unités" doit être vide. | AF23: G20_C_012 | AG23: =VLOOKUP(AF23,'Axe 2 Règles de gestion'!$D$2:$F$23,3, FALSE) -> Pour la retenue PREFON (code '0879'), seuls les deux derniers caractères (positions 57 à 58) de la zone MONTANT doivent être servies. | AH23: G20_C_014 | AI23: =VLOOKUP(AH23,'Axe 2 Règles de gestion'!$D$2:$F$23,3, FALSE) -> Pour la retenue PREFON (code '0879'), le mode de calcul doit être "E - Calcul PREFON (code classe)". | AJ23: G20_C_015 | AK23: =VLOOKUP(AJ23,'Axe 2 Règles de gestion'!$D$2:$F$23,3, FALSE) -> Le code sens est obligatoire. | AL23: G20_C_016 | AM23: =VLOOKUP(AL23,'Axe 2 Règles de gestion'!$D$2:$F$23,3, FALSE) -> Le code origine est obligatoire. | AN23: G20_C_021 | AO23: =VLOOKUP(AN23,'Axe 2 Règles de gestion'!$D$2:$F$23,3, FALSE) -> Le nombre total de mouvements 20 pour le mois de paie en cours doit être inférieur ou égal à 30.
A24: 25.00.00 | B24: A | C24: 45818.407 | D24: D0016 | E24: Contrôles PAY | F24: S0177 | G24: Mouvement 20 | H24: E1012 | I24: Contrôles d'alimentation du mouvement 20 | J24: Le code indemnité d'un mouvement 20 est saisi | K24: BG20_COD_IND [BG_Occurrence_courante] <> Vide | L24: T2447 | M24: Contrôles Avantages en nature et Avantage en nature ntic et Avantage en nature nourriture et Avantage en nature véhicule et Avantages en nature divers | N24: Création Modification | O24: Le code indemnité saisi est 'Avantages en nature' ou 'Avantage en nature ntic' ou 'Avantage en nature nourriture' ou 'Avantage en nature véhicule' ou 'Avantages en nature divers' | P24: BG20_COD_IND [BG_Occurrence_courante] DANS ('0136', '1404', '1405', '1406', '1407') | Q24: Ouvrier d'état | R24: P0005 | S24: Général | T24: Passant | U24: 40725 | W24: G20_C_002 ET G20_C_003 ET G20_C_005 ET G20_C_008 ET G20_C_009 ET G20_C_013 ET G20_C_015 ET G20_C_016 ET G20_C_021 | X24: G20_C_002 | Y24: =VLOOKUP(X24,'Axe 2 Règles de gestion'!$D$2:$F$23,3, FALSE) -> Lorsque la date de paye correspond au mois de janvier, le code origine "1" (année courante) ne doit pas être notifié. | Z24: G20_C_003 | AA24: =VLOOKUP(Z24,'Axe 2 Règles de gestion'!$D$2:$F$23,3, FALSE) -> Il est interdit de codifier le sens 1 (sens contraire) si le code origine est 0 (mois courant). | AB24: G20_C_005 | AC24: =VLOOKUP(AB24,'Axe 2 Règles de gestion'!$D$2:$F$23,3, FALSE) -> Le terme « GREVE » ne doit pas être utilisé dans la zone "Libellé complémentaire". | AD24: G20_C_008 | AE24: =VLOOKUP(AD24,'Axe 2 Règles de gestion'!$D$2:$F$23,3, FALSE) -> Si le mode de calcul est "H - Indemnité à ne pas payer (avantage en nature)", il faut que le nombre d'unités soit vide. | AF24: G20_C_009 | AG24: =VLOOKUP(AF24,'Axe 2 Règles de gestion'!$D$2:$F$23,3, FALSE) -> Si le mode de calcul est "H - Indemnité à ne pas payer (avantage en nature)", il faut que le montant soit différent de vide. | AH24: G20_C_013 | AI24: =VLOOKUP(AH24,'Axe 2 Règles de gestion'!$D$2:$F$23,3, FALSE) -> Pour les avantages en nature (codes '0136','1404','1405','1406','1407), le mode de calcul doit être "H - Indemnité à ne pas payer (avantage en nature)". | AJ24: G20_C_015 | AK24: =VLOOKUP(AJ24,'Axe 2 Règles de gestion'!$D$2:$F$23,3, FALSE) -> Le code sens est obligatoire. | AL24: G20_C_016 | AM24: =VLOOKUP(AL24,'Axe 2 Règles de gestion'!$D$2:$F$23,3, FALSE) -> Le code origine est obligatoire. | AN24: G20_C_021 | AO24: =VLOOKUP(AN24,'Axe 2 Règles de gestion'!$D$2:$F$23,3, FALSE) -> Le nombre total de mouvements 20 pour le mois de paie en cours doit être inférieur ou égal à 30.
A25: 25.00.00 | B25: A | C25: 45818.409 | D25: D0016 | E25: Contrôles PAY | F25: S0177 | G25: Mouvement 20 | H25: E1012 | I25: Contrôles d'alimentation du mouvement 20 | J25: Le code indemnité d'un mouvement 20 est saisi | K25: BG20_COD_IND [BG_Occurrence_courante] <> Vide | L25: T2448 | M25: Contrôles Cotisation assurance chômage | N25: Création Modification | O25: Le code indemnité saisi est 'Cotisation assurance chômage' | P25: BG20_COD_IND [BG_Occurrence_courante] = '0870' | Q25: Ouvrier d'état | R25: P0005 | S25: Général | T25: Exclu | U25: 40725
A26: 25.00.00 | B26: A | C26: 45818.41 | D26: D0016 | E26: Contrôles PAY | F26: S0177 | G26: Mouvement 20 | H26: E1012 | I26: Contrôles d'alimentation du mouvement 20 | J26: Le code indemnité d'un mouvement 20 est saisi | K26: BG20_COD_IND [BG_Occurrence_courante] <> Vide | L26: T2449 | M26: Contrôles autres indemnités et retenues exceptionnelles | N26: Création Modification | O26: Le code indemnité/retenue saisi est différent de '0954', '0879', '0136', '1404', '1405', '1406', '1407', '0870' | P26: BG20_COD_IND [BG_Occurrence_courante] PAS DANS ('0954', '0879', '0136', '1404', '1405', '1406', '1407', '0870') | Q26: Ouvrier d'état | R26: P0005 | S26: Général | T26: Passant | U26: 40725 | W26: G20_C_002 ET G20_C_003 ET G20_C_004 ET G20_C_005 ET G20_C_006 ET G20_C_007 ET G20_C_015 ET G20_C_016 ET G20_C_017 ET G20_C_019 ET G20_C_020 ET G20_C_021 | X26: G20_C_002 | Y26: =VLOOKUP(X26,'Axe 2 Règles de gestion'!$D$2:$F$23,3, FALSE) -> Lorsque la date de paye correspond au mois de janvier, le code origine "1" (année courante) ne doit pas être notifié. | Z26: G20_C_003 | AA26: =VLOOKUP(Z26,'Axe 2 Règles de gestion'!$D$2:$F$23,3, FALSE) -> Il est interdit de codifier le sens 1 (sens contraire) si le code origine est 0 (mois courant). | AB26: G20_C_004 | AC26: =VLOOKUP(AB26,'Axe 2 Règles de gestion'!$D$2:$F$23,3, FALSE) -> Si le mode de calcul est "A - Montant précalculé", alors il faut laisser à vide la zone nombre d'unités. | AD26: G20_C_005 | AE26: =VLOOKUP(AD26,'Axe 2 Règles de gestion'!$D$2:$F$23,3, FALSE) -> Le terme « GREVE » ne doit pas être utilisé dans la zone "Libellé complémentaire". | AF26: G20_C_006 | AG26: =VLOOKUP(AF26,'Axe 2 Règles de gestion'!$D$2:$F$23,3, FALSE) -> Si le mode de calcul est "A - Montant précalculé", il faut que le montant soit différent de vide. | AH26: G20_C_007 | AI26: =VLOOKUP(AH26,'Axe 2 Règles de gestion'!$D$2:$F$23,3, FALSE) -> Si le mode de calcul est "B - Nombre d'unités x montant unitaire", il faut que le nombre d'unités et le montant soient différents de vide. | AJ26: G20_C_015 | AK26: =VLOOKUP(AJ26,'Axe 2 Règles de gestion'!$D$2:$F$23,3, FALSE) -> Le code sens est obligatoire. | AL26: G20_C_016 | AM26: =VLOOKUP(AL26,'Axe 2 Règles de gestion'!$D$2:$F$23,3, FALSE) -> Le code origine est obligatoire. | AN26: G20_C_017 | AO26: =VLOOKUP(AN26,'Axe 2 Règles de gestion'!$D$2:$F$23,3, FALSE) -> Seuls les modes de calcul "A - Montant précalculé", "B - Nombre d'unités x montant unitaire", "G - Indemnité à déduire" sont autorisés. | AP26: G20_C_019 | AQ26: =VLOOKUP(AP26,'Axe 2 Règles de gestion'!$D$2:$F$23,3, FALSE) -> Si le mode de calcul est "G - Indemnité à déduire", alors il faut laisser vide la zone nombre d'unités. | AR26: G20_C_020 | AS26: =VLOOKUP(AR26,'Axe 2 Règles de gestion'!$D$2:$F$23,3, FALSE) -> Si le mode de calcul est "G - Indemnité à déduire", il faut que le montant soit différent de vide. | AT26: G20_C_021 | AU26: =VLOOKUP(AT26,'Axe 2 Règles de gestion'!$D$2:$F$23,3, FALSE) -> Le nombre total de mouvements 20 pour le mois de paie en cours doit être inférieur ou égal à 30.
