Workbook
Name date_DIADC: 'Mode opératoire'!#REF!
Name notice_DIADC: 'Mode opératoire'!#REF!
Name notice_ENCHN: 'Mode opératoire'!$B$1:$B$4
Name notice_ICA: 'Mode opératoire'!#REF!

Sheet Mode opératoire
B1: MODE OPERATOIRE
B2: Une fois l'ensemble des mouvements créés pour une remise de paie d'un mois donné, les contrôles s'effectuent successivement sur les mouvements de type 03 présents dans la remise de paie. Les contrôles d'alimentation automatique des zones du mouvement par les données du dossier agent sont portés par la modélisation du dictionnaire de données qui précise le cas échéant quelle donnée du dossier agent alimente la zone du mouvement avec ou sans transformation. Pour les zones concernées, ces contrôles doivent garantir la cohérence entre la donnée du dossier agent et la zone du mouvement. Ils ne sont pas redécrits dans les tableaux structurés de RG PAY. Un type d'événement a été créé par code particulier. Exemple : - T0010 : Ouvrier de l'aviation civile, temps plein - T0011 : Ouvrier de l'aviation civile, temps partiel - T0012 : Contrat d'accompagnement dans l'emploi ...

Sheet Axe 1 Enchainement des RG
A1: Version | B1: Type de mise à jour | C1: Date de mise à jour | D1: Identifiant Domaine | E1: Libellé du Domaine | F1: Identifiant Sous-domaine | G1: Libellé du Sous-domaine | H1: Identifiant Evénement | I1: Libellé de l'évènement | J1: Libellé condition déclenchement Evènement | K1: Condition déclenchement Evènement | L1: Identifiant type d'évènement | M1: Libellé type d'évènement | N1: Type de mise à jour | O1: Libellé condition déclenchement Type Evènement | P1: Condition déclenchement Type Evènement | Q1: Libellé Population | R1: Codification Population | S1: Typologie de population | T1: Général / Particulier | U1: Passant / Exclu | V1: Date de début | W1: Date de fin | X1: Règles mobilisées | Y1: Identifiant Règle de contrôle 1 | Z1: Libellé Règle de contrôle 1 | AA1: Identifiant Règle de contrôle 2 | AB1: Libellé Règle de contrôle 2 | AC1: Identifiant Règle de contrôle 3 | AD1: Libellé Règle de contrôle 3 | AE1: Identifiant Règle de contrôle 4 | AF1: Libellé Règle de contrôle 4 | AG1: Identifiant Règle de contrôle 5 | AH1: Libellé Règle de contrôle 5 | AI1: Identifiant Règle de contrôle 6 | AJ1: Libellé Règle de contrôle 6 | AK1: Identifiant Règle de contrôle 7 | AL1: Libellé Règle de contrôle 7 | AM1: Identifiant Règle de contrôle 8 | AN1: Libellé Règle de contrôle 8 | AO1: Identifiant Règle de contrôle 9 | AP1: Libellé Règle de contrôle 9 | AQ1: Identifiant Règle de contrôle 10 | AR1: Libellé Règle de contrôle 10 | AS1: FIME | AT1: Statut de travail
A2: 25.00.00 | B2: A | C2: 45814.507 | D2: D0016 | E2: Contrôles PAY | F2: S0174 | G2: Mouvement 03 | H2: E1010 | I2: Contrôles d'alimentation du mouvement 03 | J2: La date d'effet d'un mouvement 03 est saisie | K2: BG03_DAT_EFF [BG_Occurrence_courante] <> Vide | L2: T2426 | M2: Ouvrier de l'aviation civile, temps plein | N2: Création Modification | O2: Le code saisi est égal à 'Ouvrier de l'aviation civile, temps plein' | P2: BG03_NJOUR [BG_Occurrence_courante] = 'AC' | Q2: Titulaire ou magistrat | R2: P0001 | S2: T | T2: Général | U2: Exclu | V2: 40725
A3: 25.00.00 | B3: A | C3: 45814.509 | D3: D0016 | E3: Contrôles PAY | F3: S0174 | G3: Mouvement 03 | H3: E1010 | I3: Contrôles d'alimentation du mouvement 03 | J3: La date d'effet d'un mouvement 03 est saisie | K3: BG03_DAT_EFF [BG_Occurrence_courante] <> Vide | L3: T2427 | M3: Ouvrier de l'aviation civile, temps partiel | N3: Création Modification | O3: Le code saisi est égal à 'Ouvrier de l'aviation civile, temps partiel' | P3: BG03_NJOUR [BG_Occurrence_courante] = 'BC' | Q3: Titulaire ou magistrat | R3: P0001 | S3: T | T3: Général | U3: Exclu | V3: 40725
A4: 25.00.00 | B4: A | C4: 45814.517 | D4: D0016 | E4: Contrôles PAY | F4: S0174 | G4: Mouvement 03 | H4: E1010 | I4: Contrôles d'alimentation du mouvement 03 | J4: La date d'effet d'un mouvement 03 est saisie | K4: BG03_DAT_EFF [BG_Occurrence_courante] <> Vide | L4: T2428 | M4: Contrat d'accompagnement dans l'emploi | N4: Création Modification | O4: Le code saisi est égal à 'CAE' | P4: BG03_NJOUR [BG_Occurrence_courante] = 'CA' | Q4: Titulaire ou magistrat | R4: P0001 | S4: T | T4: Général | U4: Exclu | V4: 40725
A5: 25.00.00 | B5: A | C5: 45814.519 | D5: D0016 | E5: Contrôles PAY | F5: S0174 | G5: Mouvement 03 | H5: E1010 | I5: Contrôles d'alimentation du mouvement 03 | J5: La date d'effet d'un mouvement 03 est saisie | K5: BG03_DAT_EFF [BG_Occurrence_courante] <> Vide | L5: T2429 | M5: Ouvrier de l'aviation civile, surcotisant | N5: Création Modification | O5: Le code saisi est égal à 'Ouvrier de l'aviation civile, surcotisant' | P5: BG03_NJOUR [BG_Occurrence_courante] = 'CC' | Q5: Titulaire ou magistrat | R5: P0001 | S5: T | T5: Général | U5: Exclu | V5: 40725
A6: 25.00.00 | B6: A | C6: 45814.546 | D6: D0016 | E6: Contrôles PAY | F6: S0174 | G6: Mouvement 03 | H6: E1010 | I6: Contrôles d'alimentation du mouvement 03 | J6: La date d'effet d'un mouvement 03 est saisie | K6: BG03_DAT_EFF [BG_Occurrence_courante] <> Vide | L6: T2430 | M6: Agent Handicapé, dont l'incapacité est de 80% au moins, surcotisant | N6: Création Modification | O6: Le code saisi est égal à 'Agent Handicapé, dont l'incapacité est de 80% au moins, surcotisant' | P6: BG03_NJOUR [BG_Occurrence_courante] = 'HA' | Q6: Titulaire ou magistrat | R6: P0001 | S6: T | T6: Général | U6: Passant | V6: 40725 | X6: G03_C_001 ET G03_C_002 ET G03_C_003 ET G03_C_005 ET G03_C_010 ET G03_C_011 ET G03_C_013 ET G03_C_016 ET G03_C_017 | Y6: G03_C_001 | Z6: =VLOOKUP(Y6,'Axe 2 Règles de gestion'!$D$2:$F$20,3, FALSE) -> La date d'effet du mouvement 03 ne peut être postérieure au 31 du mois de la paye. | AA6: G03_C_002 | AB6: =VLOOKUP(AA6,'Axe 2 Règles de gestion'!$D$2:$F$20,3, FALSE) -> La date d'effet du mouvement 03 ne peut être antérieure ou égale à la date de prise en charge. | AC6: G03_C_003 | AD6: =VLOOKUP(AC6,'Axe 2 Règles de gestion'!$D$2:$F$20,3, FALSE) -> La date d'effet du mouvement 03 ne peut être antérieure à 3 ans ou plus du 1er jour du mois de paie en cours. Pour un rappel remontant à la quatrième année, il convient d'envoyer un mouvement 42. | AE6: G03_C_005 | AF6: =VLOOKUP(AE6,'Axe 2 Règles de gestion'!$D$2:$F$20,3, FALSE) -> Le nombre de mouvements de type 03 est limité à 20 par mois de paie et par numéro de dossier (NUDOS). | AG6: G03_C_010 | AH6: =VLOOKUP(AG6,'Axe 2 Règles de gestion'!$D$2:$F$20,3, FALSE) -> L'agent surcotise. | AI6: G03_C_011 | AJ6: =VLOOKUP(AI6,'Axe 2 Règles de gestion'!$D$2:$F$20,3, FALSE) -> L'agent est handicapé à 80% ou plus. | AK6: G03_C_013 | AL6: =VLOOKUP(AK6,'Axe 2 Règles de gestion'!$D$2:$F$20,3, FALSE) -> L'agent doit être en temps partiel thérapeutique ou en temps partiel. | AM6: G03_C_016 | AN6: =VLOOKUP(AM6,'Axe 2 Règles de gestion'!$D$2:$F$20,3, FALSE) -> Le numérateur de la fraction de rémunération présent dans le dossier RH de l'agent est égal au numérateur de la fraction de rémunération saisi dans le mouvement 03. | AO6: G03_C_017 | AP6: =VLOOKUP(AO6,'Axe 2 Règles de gestion'!$D$2:$F$20,3, FALSE) -> Le dénominateur de la fraction de rémunération présent dans le dossier RH de l'agent est égal au dénominateur de la fraction de rémunération saisi dans le mouvement 03.
A7: 25.00.00 | B7: A | C7: 45814.548 | D7: D0016 | E7: Contrôles PAY | F7: S0174 | G7: Mouvement 03 | H7: E1010 | I7: Contrôles d'alimentation du mouvement 03 | J7: La date d'effet d'un mouvement 03 est saisie | K7: BG03_DAT_EFF [BG_Occurrence_courante] <> Vide | L7: T2431 | M7: Ouvrier (Cadre Général), à temps partiel, surcotisant, avec handicap d'au moins 80% | N7: Création Modification | O7: Le code saisi est égal à 'Ouvrier (Cadre Général), à temps partiel, surcotisant, avec handicap d'au moins 80%' | P7: BG03_NJOUR [BG_Occurrence_courante] = 'IP' | Q7: Titulaire ou magistrat | R7: P0001 | S7: T | T7: Général | U7: Exclu | V7: 40725
A8: 25.00.00 | B8: A | C8: 45814.549 | D8: D0016 | E8: Contrôles PAY | F8: S0174 | G8: Mouvement 03 | H8: E1010 | I8: Contrôles d'alimentation du mouvement 03 | J8: La date d'effet d'un mouvement 03 est saisie | K8: BG03_DAT_EFF [BG_Occurrence_courante] <> Vide | L8: T2432 | M8: Ouvrier Aviation Civile, à temps partiel, surcotisant, avec handicap d'au moins 80% | N8: Création Modification | O8: Le code saisi est égal à 'Ouvrier Aviation Civile, à temps partiel, surcotisant, avec handicap d'au moins 80%' | P8: BG03_NJOUR [BG_Occurrence_courante] = 'JC' | Q8: Titulaire ou magistrat | R8: P0001 | S8: T | T8: Général | U8: Exclu | V8: 40725
A9: 25.00.00 | B9: A | C9: 45814.551 | D9: D0016 | E9: Contrôles PAY | F9: S0174 | G9: Mouvement 03 | H9: E1010 | I9: Contrôles d'alimentation du mouvement 03 | J9: La date d'effet d'un mouvement 03 est saisie | K9: BG03_DAT_EFF [BG_Occurrence_courante] <> Vide | L9: T2433 | M9: Militaire DGA, pour proratisation de certains éléments | N9: Création Modification | O9: Le code saisi est égal à 'Militaire DGA, pour proratisation de certains éléments' | P9: BG03_NJOUR [BG_Occurrence_courante] = 'MI' | Q9: Titulaire ou magistrat | R9: P0001 | S9: T | T9: Général | U9: Exclu | V9: 40725
A10: 25.00.00 | B10: A | C10: 45814.554 | D10: D0016 | E10: Contrôles PAY | F10: S0174 | G10: Mouvement 03 | H10: E1010 | I10: Contrôles d'alimentation du mouvement 03 | J10: La date d'effet d'un mouvement 03 est saisie | K10: BG03_DAT_EFF [BG_Occurrence_courante] <> Vide | L10: T2434 | M10: Agent non titulaire surcotisant | N10: Création Modification | O10: Le code saisi est égal à 'Agent non titulaire surcotisant' | P10: BG03_NJOUR [BG_Occurrence_courante] = 'NP' | Q10: Titulaire ou magistrat | R10: P0001 | S10: T | T10: Général | U10: Exclu | V10: 40725
A11: 25.00.00 | B11: A | C11: 45814.57 | D11: D0016 | E11: Contrôles PAY | F11: S0174 | G11: Mouvement 03 | H11: E1010 | I11: Contrôles d'alimentation du mouvement 03 | J11: La date d'effet d'un mouvement 03 est saisie | K11: BG03_DAT_EFF [BG_Occurrence_courante] <> Vide | L11: T2435 | M11: Ouvrier (Cadre Général) surcotisant | N11: Création Modification | O11: Le code saisi est égal à 'Ouvrier (Cadre Général) surcotisant' | P11: BG03_NJOUR [BG_Occurrence_courante] = 'OP' | Q11: Titulaire ou magistrat | R11: P0001 | S11: T | T11: Général | U11: Exclu | V11: 40725
A12: 25.00.00 | B12: A | C12: 45814.572 | D12: D0016 | E12: Contrôles PAY | F12: S0174 | G12: Mouvement 03 | H12: E1010 | I12: Contrôles d'alimentation du mouvement 03 | J12: La date d'effet d'un mouvement 03 est saisie | K12: BG03_DAT_EFF [BG_Occurrence_courante] <> Vide | L12: T2436 | M12: Contractuel PACTE | N12: Création Modification | O12: Le code saisi est égal à 'PACTE' | P12: BG03_NJOUR [BG_Occurrence_courante] = 'PA' | Q12: Titulaire ou magistrat | R12: P0001 | S12: T | T12: Général | U12: Exclu | V12: 40725
A13: 25.00.00 | B13: A | C13: 45814.574 | D13: D0016 | E13: Contrôles PAY | F13: S0174 | G13: Mouvement 03 | H13: E1010 | I13: Contrôles d'alimentation du mouvement 03 | J13: La date d'effet d'un mouvement 03 est saisie | K13: BG03_DAT_EFF [BG_Occurrence_courante] <> Vide | L13: T2437 | M13: Surcotisation Douanes, Police, Pénitentiaire | N13: Création Modification | O13: Le code saisi est égal à 'Surcotisation Douanes, Police, Pénitentiaire' | P13: BG03_NJOUR [BG_Occurrence_courante] = 'PP' | Q13: Titulaire ou magistrat | R13: P0001 | S13: T | T13: Général | U13: Passant | V13: 40725 | X13: G03_C_001 ET G03_C_002 ET G03_C_003 ET G03_C_005 ET G03_C_010 ET G03_C_013 ET G03_C_016 ET G03_C_017 | Y13: G03_C_001 | Z13: =VLOOKUP(Y13,'Axe 2 Règles de gestion'!$D$2:$F$20,3, FALSE) -> La date d'effet du mouvement 03 ne peut être postérieure au 31 du mois de la paye. | AA13: G03_C_002 | AB13: =VLOOKUP(AA13,'Axe 2 Règles de gestion'!$D$2:$F$20,3, FALSE) -> La date d'effet du mouvement 03 ne peut être antérieure ou égale à la date de prise en charge. | AC13: G03_C_003 | AD13: =VLOOKUP(AC13,'Axe 2 Règles de gestion'!$D$2:$F$20,3, FALSE) -> La date d'effet du mouvement 03 ne peut être antérieure à 3 ans ou plus du 1er jour du mois de paie en cours. Pour un rappel remontant à la quatrième année, il convient d'envoyer un mouvement 42. | AE13: G03_C_005 | AF13: =VLOOKUP(AE13,'Axe 2 Règles de gestion'!$D$2:$F$20,3, FALSE) -> Le nombre de mouvements de type 03 est limité à 20 par mois de paie et par numéro de dossier (NUDOS). | AG13: G03_C_010 | AH13: =VLOOKUP(AG13,'Axe 2 Règles de gestion'!$D$2:$F$20,3, FALSE) -> L'agent surcotise. | AI13: G03_C_013 | AJ13: =VLOOKUP(AI13,'Axe 2 Règles de gestion'!$D$2:$F$20,3, FALSE) -> L'agent doit être en temps partiel thérapeutique ou en temps partiel. | AK13: G03_C_016 | AL13: =VLOOKUP(AK13,'Axe 2 Règles de gestion'!$D$2:$F$20,3, FALSE) -> Le numérateur de la fraction de rémunération présent dans le dossier RH de l'agent est égal au numérateur de la fraction de rémunération saisi dans le mouvement 03. | AM13: G03_C_017 | AN13: =VLOOKUP(AM13,'Axe 2 Règles de gestion'!$D$2:$F$20,3, FALSE) -> Le dénominateur de la fraction de rémunération présent dans le dossier RH de l'agent est égal au dénominateur de la fraction de rémunération saisi dans le mouvement 03.
A14: 25.00.00 | B14: A | C14: 45814.575 | D14: D0016 | E14: Contrôles PAY | F14: S0174 | G14: Mouvement 03 | H14: E1010 | I14: Contrôles d'alimentation du mouvement 03 | J14: La date d'effet d'un mouvement 03 est saisie | K14: BG03_DAT_EFF [BG_Occurrence_courante] <> Vide | L14: T2438 | M14: Surcotisant temps partiel | N14: Création Modification | O14: Le code saisi est égal à 'Surcotisant temps partiel' | P14: BG03_NJOUR [BG_Occurrence_courante] = 'SP' | Q14: Titulaire ou magistrat | R14: P0001 | S14: T | T14: Général | U14: Passant | V14: 40725 | X14: G03_C_001 ET G03_C_002 ET G03_C_003 ET G03_C_005 ET G03_C_010 ET G03_C_013 ET G03_C_015 ET G03_C_016 ET G03_C_017 | Y14: G03_C_001 | Z14: =VLOOKUP(Y14,'Axe 2 Règles de gestion'!$D$2:$F$20,3, FALSE) -> La date d'effet du mouvement 03 ne peut être postérieure au 31 du mois de la paye. | AA14: G03_C_002 | AB14: =VLOOKUP(AA14,'Axe 2 Règles de gestion'!$D$2:$F$20,3, FALSE) -> La date d'effet du mouvement 03 ne peut être antérieure ou égale à la date de prise en charge. | AC14: G03_C_003 | AD14: =VLOOKUP(AC14,'Axe 2 Règles de gestion'!$D$2:$F$20,3, FALSE) -> La date d'effet du mouvement 03 ne peut être antérieure à 3 ans ou plus du 1er jour du mois de paie en cours. Pour un rappel remontant à la quatrième année, il convient d'envoyer un mouvement 42. | AE14: G03_C_005 | AF14: =VLOOKUP(AE14,'Axe 2 Règles de gestion'!$D$2:$F$20,3, FALSE) -> Le nombre de mouvements de type 03 est limité à 20 par mois de paie et par numéro de dossier (NUDOS). | AG14: G03_C_010 | AH14: =VLOOKUP(AG14,'Axe 2 Règles de gestion'!$D$2:$F$20,3, FALSE) -> L'agent surcotise. | AI14: G03_C_013 | AJ14: =VLOOKUP(AI14,'Axe 2 Règles de gestion'!$D$2:$F$20,3, FALSE) -> L'agent doit être en temps partiel thérapeutique ou en temps partiel. | AK14: G03_C_015 | AL14: =VLOOKUP(AK14,'Axe 2 Règles de gestion'!$D$2:$F$20,3, FALSE) -> Si l'agent est handicapé alors il l'est à moins de 80%. | AM14: G03_C_016 | AN14: =VLOOKUP(AM14,'Axe 2 Règles de gestion'!$D$2:$F$20,3, FALSE) -> Le numérateur de la fraction de rémunération présent dans le dossier RH de l'agent est égal au numérateur de la fraction de rémunération saisi dans le mouvement 03. | AO14: G03_C_017 | AP14: =VLOOKUP(AO14,'Axe 2 Règles de gestion'!$D$2:$F$20,3, FALSE) -> Le dénominateur de la fraction de rémunération présent dans le dossier RH de l'agent est égal au dénominateur de la fraction de rémunération saisi dans le mouvement 03.
A15: 25.00.00 | B15: A | C15: 45814.578 | D15: D0016 | E15: Contrôles PAY | F15: S0174 | G15: Mouvement 03 | H15: E1010 | I15: Contrôles d'alimentation du mouvement 03 | J15: La date d'effet d'un mouvement 03 est saisie | K15: BG03_DAT_EFF [BG_Occurrence_courante] <> Vide | L15: T2439 | M15: Agent à temps partiel | N15: Création Modification | O15: Le code saisi est égal à 'Agent à temps partiel' | P15: BG03_NJOUR [BG_Occurrence_courante] = 'TP' | Q15: Titulaire ou magistrat | R15: P0001 | S15: T | T15: Général | U15: Passant | V15: 40725 | X15: G03_C_001 ET G03_C_002 ET G03_C_003 ET G03_C_005 ET G03_C_013 ET G03_C_014 ET G03_C_016 ET G03_C_017 | Y15: G03_C_001 | Z15: =VLOOKUP(Y15,'Axe 2 Règles de gestion'!$D$2:$F$20,3, FALSE) -> La date d'effet du mouvement 03 ne peut être postérieure au 31 du mois de la paye. | AA15: G03_C_002 | AB15: =VLOOKUP(AA15,'Axe 2 Règles de gestion'!$D$2:$F$20,3, FALSE) -> La date d'effet du mouvement 03 ne peut être antérieure ou égale à la date de prise en charge. | AC15: G03_C_003 | AD15: =VLOOKUP(AC15,'Axe 2 Règles de gestion'!$D$2:$F$20,3, FALSE) -> La date d'effet du mouvement 03 ne peut être antérieure à 3 ans ou plus du 1er jour du mois de paie en cours. Pour un rappel remontant à la quatrième année, il convient d'envoyer un mouvement 42. | AE15: G03_C_005 | AF15: =VLOOKUP(AE15,'Axe 2 Règles de gestion'!$D$2:$F$20,3, FALSE) -> Le nombre de mouvements de type 03 est limité à 20 par mois de paie et par numéro de dossier (NUDOS). | AG15: G03_C_013 | AH15: =VLOOKUP(AG15,'Axe 2 Règles de gestion'!$D$2:$F$20,3, FALSE) -> L'agent doit être en temps partiel thérapeutique ou en temps partiel. | AI15: G03_C_014 | AJ15: =VLOOKUP(AI15,'Axe 2 Règles de gestion'!$D$2:$F$20,3, FALSE) -> L'agent ne surcotise pas. | AK15: G03_C_016 | AL15: =VLOOKUP(AK15,'Axe 2 Règles de gestion'!$D$2:$F$20,3, FALSE) -> Le numérateur de la fraction de rémunération présent dans le dossier RH de l'agent est égal au numérateur de la fraction de rémunération saisi dans le mouvement 03. | AM15: G03_C_017 | AN15: =VLOOKUP(AM15,'Axe 2 Règles de gestion'!$D$2:$F$20,3, FALSE) -> Le dénominateur de la fraction de rémunération présent dans le dossier RH de l'agent est égal au dénominateur de la fraction de rémunération saisi dans le mouvement 03.
A16: 25.00.00 | B16: A | C16: 45814.58 | D16: D0016 | E16: Contrôles PAY | F16: S0174 | G16: Mouvement 03 | H16: E1010 | I16: Contrôles d'alimentation du mouvement 03 | J16: La date d'effet d'un mouvement 03 est saisie | K16: BG03_DAT_EFF [BG_Occurrence_courante] <> Vide | L16: T2440 | M16: Agent à temps incomplet | N16: Création Modification | O16: Le code saisi est égal à 'Agent à temps incomplet' | P16: BG03_NJOUR [BG_Occurrence_courante] = '00' | Q16: Titulaire ou magistrat | R16: P0001 | S16: T | T16: Général | U16: Exclu | V16: 40725
A17: 25.00.00 | B17: A | C17: 45814.581 | D17: D0016 | E17: Contrôles PAY | F17: S0174 | G17: Mouvement 03 | H17: E1010 | I17: Contrôles d'alimentation du mouvement 03 | J17: La date d'effet d'un mouvement 03 est saisie | K17: BG03_DAT_EFF [BG_Occurrence_courante] <> Vide | L17: T2441 | M17: Remise à blanc de la zone | N17: Création Modification | O17: Le code saisi est égal à 'Remise à blanc de la zone' | P17: BG03_NJOUR [BG_Occurrence_courante] = 'ZZ' | Q17: Titulaire ou magistrat | R17: P0001 | S17: T | T17: Général | U17: Passant | V17: 40725 | X17: G03_C_001 ET G03_C_002 ET G03_C_003 ET G03_C_005 ET G03_C_009 | Y17: G03_C_001 | Z17: =VLOOKUP(Y17,'Axe 2 Règles de gestion'!$D$2:$F$20,3, FALSE) -> La date d'effet du mouvement 03 ne peut être postérieure au 31 du mois de la paye. | AA17: G03_C_002 | AB17: =VLOOKUP(AA17,'Axe 2 Règles de gestion'!$D$2:$F$20,3, FALSE) -> La date d'effet du mouvement 03 ne peut être antérieure ou égale à la date de prise en charge. | AC17: G03_C_003 | AD17: =VLOOKUP(AC17,'Axe 2 Règles de gestion'!$D$2:$F$20,3, FALSE) -> La date d'effet du mouvement 03 ne peut être antérieure à 3 ans ou plus du 1er jour du mois de paie en cours. Pour un rappel remontant à la quatrième année, il convient d'envoyer un mouvement 42. | AE17: G03_C_005 | AF17: =VLOOKUP(AE17,'Axe 2 Règles de gestion'!$D$2:$F$20,3, FALSE) -> Le nombre de mouvements de type 03 est limité à 20 par mois de paie et par numéro de dossier (NUDOS). | AG17: G03_C_009 | AH17: =VLOOKUP(AG17,'Axe 2 Règles de gestion'!$D$2:$F$20,3, FALSE) -> La valeur 'ZZZZZ' doit être saisi dans le champ "Numérateur de la fraction de rémunération" et la valeur 'ZZZ' doit être saisi dans le champ "Dénominateur de la fraction de rémunération".
A18: 25.00.00 | B18: A | C18: 45814.585 | D18: D0016 | E18: Contrôles PAY | F18: S0174 | G18: Mouvement 03 | H18: E1010 | I18: Contrôles d'alimentation du mouvement 03 | J18: La date d'effet d'un mouvement 03 est saisie | K18: BG03_DAT_EFF [BG_Occurrence_courante] <> Vide | L18: T2442 | M18: Surcotisation CPA | N18: Création Modification | O18: Le code saisi est égal à 'Surcotisation CPA' | P18: BG03_NJOUR [BG_Occurrence_courante] = 'SO' | Q18: Titulaire ou magistrat | R18: P0001 | S18: T | T18: Général | U18: Passant | V18: 40725 | W18: 43555 | X18: G03_C_001 ET G03_C_002 ET G03_C_003 ET G03_C_005 ET G03_C_010 ET G03_C_016 ET G03_C_017 ET G03_C_020 | Y18: G03_C_001 | Z18: =VLOOKUP(Y18,'Axe 2 Règles de gestion'!$D$2:$F$20,3, FALSE) -> La date d'effet du mouvement 03 ne peut être postérieure au 31 du mois de la paye. | AA18: G03_C_002 | AB18: =VLOOKUP(AA18,'Axe 2 Règles de gestion'!$D$2:$F$20,3, FALSE) -> La date d'effet du mouvement 03 ne peut être antérieure ou égale à la date de prise en charge. | AC18: G03_C_003 | AD18: =VLOOKUP(AC18,'Axe 2 Règles de gestion'!$D$2:$F$20,3, FALSE) -> La date d'effet du mouvement 03 ne peut être antérieure à 3 ans ou plus du 1er jour du mois de paie en cours. Pour un rappel remontant à la quatrième année, il convient d'envoyer un mouvement 42. | AE18: G03_C_005 | AF18: =VLOOKUP(AE18,'Axe 2 Règles de gestion'!$D$2:$F$20,3, FALSE) -> Le nombre de mouvements de type 03 est limité à 20 par mois de paie et par numéro de dossier (NUDOS). | AG18: G03_C_010 | AH18: =VLOOKUP(AG18,'Axe 2 Règles de gestion'!$D$2:$F$20,3, FALSE) -> L'agent surcotise. | AI18: G03_C_016 | AJ18: =VLOOKUP(AI18,'Axe 2 Règles de gestion'!$D$2:$F$20,3, FALSE) -> Le numérateur de la fraction de rémunération présent dans le dossier RH de l'agent est égal au numérateur de la fraction de rémunération saisi dans le mouvement 03. | AK18: G03_C_017 | AL18: =VLOOKUP(AK18,'Axe 2 Règles de gestion'!$D$2:$F$20,3, FALSE) -> Le dénominateur de la fraction de rémunération présent dans le dossier RH de l'agent est égal au dénominateur de la fraction de rémunération saisi dans le mouvement 03. | AM18: G03_C_020 | AN18: =VLOOKUP(AM18,'Axe 2 Règles de gestion'!$D$2:$F$20,3, FALSE) -> L'agent doit être en cessation progressive d'activité.
A19: 25.00.00 | B19: A | C19: 45814.592 | D19: D0016 | E19: Contrôles PAY | F19: S0174 | G19: Mouvement 03 | H19: E1010 | I19: Contrôles d'alimentation du mouvement 03 | J19: La date d'effet d'un mouvement 03 est saisie | K19: BG03_DAT_EFF [BG_Occurrence_courante] <> Vide | L19: T2443 | M19: Maître de l'enseignement privé en CPA | N19: Création Modification | O19: Le code saisi est égal à 'Maître de l'enseignement privé en CPA' | P19: BG03_NJOUR [BG_Occurrence_courante] = 'EP' | Q19: Titulaire ou magistrat | R19: P0001 | S19: T | T19: Général | U19: Exclu | V19: 40725 | W19: 43555
A20: 25.00.00 | B20: A | C20: 45814.507 | D20: D0016 | E20: Contrôles PAY | F20: S0174 | G20: Mouvement 03 | H20: E1010 | I20: Contrôles d'alimentation du mouvement 03 | J20: La date d'effet d'un mouvement 03 est saisie | K20: BG03_DAT_EFF [BG_Occurrence_courante] <> Vide | L20: T2426 | M20: Ouvrier de l'aviation civile, temps plein | N20: Création Modification | O20: Le code saisi est égal à 'Ouvrier de l'aviation civile, temps plein' | P20: BG03_NJOUR [BG_Occurrence_courante] = 'AC' | Q20: Militaire | R20: P0002 | S20: M | T20: Général | U20: Exclu | V20: 40725
A21: 25.00.00 | B21: A | C21: 45814.515 | D21: D0016 | E21: Contrôles PAY | F21: S0174 | G21: Mouvement 03 | H21: E1010 | I21: Contrôles d'alimentation du mouvement 03 | J21: La date d'effet d'un mouvement 03 est saisie | K21: BG03_DAT_EFF [BG_Occurrence_courante] <> Vide | L21: T2427 | M21: Ouvrier de l'aviation civile, temps partiel | N21: Création Modification | O21: Le code saisi est égal à 'Ouvrier de l'aviation civile, temps partiel' | P21: BG03_NJOUR [BG_Occurrence_courante] = 'BC' | Q21: Militaire | R21: P0002 | S21: M | T21: Général | U21: Exclu | V21: 40725
A22: 25.00.00 | B22: A | C22: 45814.518 | D22: D0016 | E22: Contrôles PAY | F22: S0174 | G22: Mouvement 03 | H22: E1010 | I22: Contrôles d'alimentation du mouvement 03 | J22: La date d'effet d'un mouvement 03 est saisie | K22: BG03_DAT_EFF [BG_Occurrence_courante] <> Vide | L22: T2428 | M22: Contrat d'accompagnement dans l'emploi | N22: Création Modification | O22: Le code saisi est égal à 'CAE' | P22: BG03_NJOUR [BG_Occurrence_courante] = 'CA' | Q22: Militaire | R22: P0002 | S22: M | T22: Général | U22: Exclu | V22: 40725
A23: 25.00.00 | B23: A | C23: 45814.519 | D23: D0016 | E23: Contrôles PAY | F23: S0174 | G23: Mouvement 03 | H23: E1010 | I23: Contrôles d'alimentation du mouvement 03 | J23: La date d'effet d'un mouvement 03 est saisie | K23: BG03_DAT_EFF [BG_Occurrence_courante] <> Vide | L23: T2429 | M23: Ouvrier de l'aviation civile, surcotisant | N23: Création Modification | O23: Le code saisi est égal à 'Ouvrier de l'aviation civile, surcotisant' | P23: BG03_NJOUR [BG_Occurrence_courante] = 'CC' | Q23: Militaire | R23: P0002 | S23: M | T23: Général | U23: Exclu | V23: 40725
A24: 25.00.00 | B24: A | C24: 45814.547 | D24: D0016 | E24: Contrôles PAY | F24: S0174 | G24: Mouvement 03 | H24: E1010 | I24: Contrôles d'alimentation du mouvement 03 | J24: La date d'effet d'un mouvement 03 est saisie | K24: BG03_DAT_EFF [BG_Occurrence_courante] <> Vide | L24: T2430 | M24: Agent Handicapé, dont l'incapacité est de 80% au moins, surcotisant | N24: Création Modification | O24: Le code saisi est égal à 'Agent Handicapé, dont l'incapacité est de 80% au moins, surcotisant' | P24: BG03_NJOUR [BG_Occurrence_courante] = 'HA' | Q24: Militaire | R24: P0002 | S24: M | T24: Général | U24: Exclu | V24: 40725
A25: 25.00.00 | B25: A | C25: 45814.548 | D25: D0016 | E25: Contrôles PAY | F25: S0174 | G25: Mouvement 03 | H25: E1010 | I25: Contrôles d'alimentation du mouvement 03 | J25: La date d'effet d'un mouvement 03 est saisie | K25: BG03_DAT_EFF [BG_Occurrence_courante] <> Vide | L25: T2431 | M25: Ouvrier (Cadre Général), à temps partiel, surcotisant, avec handicap d'au moins 80% | N25: Création Modification | O25: Le code saisi est égal à 'Ouvrier (Cadre Général), à temps partiel, surcotisant, avec handicap d'au moins 80%' | P25: BG03_NJOUR [BG_Occurrence_courante] = 'IP' | Q25: Militaire | R25: P0002 | S25: M | T25: Général | U25: Exclu | V25: 40725
A26: 25.00.00 | B26: A | C26: 45814.549 | D26: D0016 | E26: Contrôles PAY | F26: S0174 | G26: Mouvement 03 | H26: E1010 | I26: Contrôles d'alimentation du mouvement 03 | J26: La date d'effet d'un mouvement 03 est saisie | K26: BG03_DAT_EFF [BG_Occurrence_courante] <> Vide | L26: T2432 | M26: Ouvrier Aviation Civile, à temps partiel, surcotisant, avec handicap d'au moins 80% | N26: Création Modification | O26: Le code saisi est égal à 'Ouvrier Aviation Civile, à temps partiel, surcotisant, avec handicap d'au moins 80%' | P26: BG03_NJOUR [BG_Occurrence_courante] = 'JC' | Q26: Militaire | R26: P0002 | S26: M | T26: Général | U26: Exclu | V26: 40725
A27: 25.00.00 | B27: A | C27: 45814.551 | D27: D0016 | E27: Contrôles PAY | F27: S0174 | G27: Mouvement 03 | H27: E1010 | I27: Contrôles d'alimentation du mouvement 03 | J27: La date d'effet d'un mouvement 03 est saisie | K27: BG03_DAT_EFF [BG_Occurrence_courante] <> Vide | L27: T2433 | M27: Militaire DGA, pour proratisation de certains éléments | N27: Création Modification | O27: Le code saisi est égal à 'Militaire DGA, pour proratisation de certains éléments' | P27: BG03_NJOUR [BG_Occurrence_courante] = 'MI' | Q27: Militaire | R27: P0002 | S27: M | T27: Général | U27: Exclu | V27: 40725
A28: 25.00.00 | B28: A | C28: 45814.555 | D28: D0016 | E28: Contrôles PAY | F28: S0174 | G28: Mouvement 03 | H28: E1010 | I28: Contrôles d'alimentation du mouvement 03 | J28: La date d'effet d'un mouvement 03 est saisie | K28: BG03_DAT_EFF [BG_Occurrence_courante] <> Vide | L28: T2434 | M28: Agent non titulaire surcotisant | N28: Création Modification | O28: Le code saisi est égal à 'Agent non titulaire surcotisant' | P28: BG03_NJOUR [BG_Occurrence_courante] = 'NP' | Q28: Militaire | R28: P0002 | S28: M | T28: Général | U28: Exclu | V28: 40725
A29: 25.00.00 | B29: A | C29: 45814.57 | D29: D0016 | E29: Contrôles PAY | F29: S0174 | G29: Mouvement 03 | H29: E1010 | I29: Contrôles d'alimentation du mouvement 03 | J29: La date d'effet d'un mouvement 03 est saisie | K29: BG03_DAT_EFF [BG_Occurrence_courante] <> Vide | L29: T2435 | M29: Ouvrier (Cadre Général) surcotisant | N29: Création Modification | O29: Le code saisi est égal à 'Ouvrier (Cadre Général) surcotisant' | P29: BG03_NJOUR [BG_Occurrence_courante] = 'OP' | Q29: Militaire | R29: P0002 | S29: M | T29: Général | U29: Exclu | V29: 40725
A30: 25.00.00 | B30: A | C30: 45814.573 | D30: D0016 | E30: Contrôles PAY | F30: S0174 | G30: Mouvement 03 | H30: E1010 | I30: Contrôles d'alimentation du mouvement 03 | J30: La date d'effet d'un mouvement 03 est saisie | K30: BG03_DAT_EFF [BG_Occurrence_courante] <> Vide | L30: T2436 | M30: Contractuel PACTE | N30: Création Modification | O30: Le code saisi est égal à 'PACTE' | P30: BG03_NJOUR [BG_Occurrence_courante] = 'PA' | Q30: Militaire | R30: P0002 | S30: M | T30: Général | U30: Exclu | V30: 40725
A31: 25.00.00 | B31: A | C31: 45814.574 | D31: D0016 | E31: Contrôles PAY | F31: S0174 | G31: Mouvement 03 | H31: E1010 | I31: Contrôles d'alimentation du mouvement 03 | J31: La date d'effet d'un mouvement 03 est saisie | K31: BG03_DAT_EFF [BG_Occurrence_courante] <> Vide | L31: T2437 | M31: Surcotisation Douanes, Police, Pénitentiaire | N31: Création Modification | O31: Le code saisi est égal à 'Surcotisation Douanes, Police, Pénitentiaire' | P31: BG03_NJOUR [BG_Occurrence_courante] = 'PP' | Q31: Militaire | R31: P0002 | S31: M | T31: Général | U31: Exclu | V31: 40725
A32: 25.00.00 | B32: A | C32: 45814.576 | D32: D0016 | E32: Contrôles PAY | F32: S0174 | G32: Mouvement 03 | H32: E1010 | I32: Contrôles d'alimentation du mouvement 03 | J32: La date d'effet d'un mouvement 03 est saisie | K32: BG03_DAT_EFF [BG_Occurrence_courante] <> Vide | L32: T2438 | M32: Surcotisant temps partiel | N32: Création Modification | O32: Le code saisi est égal à 'Surcotisant temps partiel' | P32: BG03_NJOUR [BG_Occurrence_courante] = 'SP' | Q32: Militaire | R32: P0002 | S32: M | T32: Général | U32: Exclu | V32: 40725
A33: 25.00.00 | B33: A | C33: 45814.579 | D33: D0016 | E33: Contrôles PAY | F33: S0174 | G33: Mouvement 03 | H33: E1010 | I33: Contrôles d'alimentation du mouvement 03 | J33: La date d'effet d'un mouvement 03 est saisie | K33: BG03_DAT_EFF [BG_Occurrence_courante] <> Vide | L33: T2439 | M33: Agent à temps partiel | N33: Création Modification | O33: Le code saisi est égal à 'Agent à temps partiel' | P33: BG03_NJOUR [BG_Occurrence_courante] = 'TP' | Q33: Militaire | R33: P0002 | S33: M | T33: Général | U33: Passant | V33: 40725 | X33: G03_C_001 ET G03_C_002 ET G03_C_003 ET G03_C_005 ET G03_C_013 ET G03_C_014 ET G03_C_016 ET G03_C_017 | Y33: G03_C_001 | Z33: =VLOOKUP(Y33,'Axe 2 Règles de gestion'!$D$2:$F$20,3, FALSE) -> La date d'effet du mouvement 03 ne peut être postérieure au 31 du mois de la paye. | AA33: G03_C_002 | AB33: =VLOOKUP(AA33,'Axe 2 Règles de gestion'!$D$2:$F$20,3, FALSE) -> La date d'effet du mouvement 03 ne peut être antérieure ou égale à la date de prise en charge. | AC33: G03_C_003 | AD33: =VLOOKUP(AC33,'Axe 2 Règles de gestion'!$D$2:$F$20,3, FALSE) -> La date d'effet du mouvement 03 ne peut être antérieure à 3 ans ou plus du 1er jour du mois de paie en cours. Pour un rappel remontant à la quatrième année, il convient d'envoyer un mouvement 42. | AE33: G03_C_005 | AF33: =VLOOKUP(AE33,'Axe 2 Règles de gestion'!$D$2:$F$20,3, FALSE) -> Le nombre de mouvements de type 03 est limité à 20 par mois de paie et par numéro de dossier (NUDOS). | AG33: G03_C_013 | AH33: =VLOOKUP(AG33,'Axe 2 Règles de gestion'!$D$2:$F$20,3, FALSE) -> L'agent doit être en temps partiel thérapeutique ou en temps partiel. | AI33: G03_C_014 | AJ33: =VLOOKUP(AI33,'Axe 2 Règles de gestion'!$D$2:$F$20,3, FALSE) -> L'agent ne surcotise pas. | AK33: G03_C_016 | AL33: =VLOOKUP(AK33,'Axe 2 Règles de gestion'!$D$2:$F$20,3, FALSE) -> Le numérateur de la fraction de rémunération présent dans le dossier RH de l'agent est égal au numérateur de la fraction de rémunération saisi dans le mouvement 03. | AM33: G03_C_017 | AN33: =VLOOKUP(AM33,'Axe 2 Règles de gestion'!$D$2:$F$20,3, FALSE) -> Le dénominateur de la fraction de rémunération présent dans le dossier RH de l'agent est égal au dénominateur de la fraction de rémunération saisi dans le mouvement 03.
A34: 25.00.00 | B34: A | C34: 45814.581 | D34: D0016 | E34: Contrôles PAY | F34: S0174 | G34: Mouvement 03 | H34: E1010 | I34: Contrôles d'alimentation du mouvement 03 | J34: La date d'effet d'un mouvement 03 est saisie | K34: BG03_DAT_EFF [BG_Occurrence_courante] <> Vide | L34: T2440 | M34: Agent à temps incomplet | N34: Création Modification | O34: Le code saisi est égal à 'Agent à temps incomplet' | P34: BG03_NJOUR [BG_Occurrence_courante] = '00' | Q34: Militaire | R34: P0002 | S34: M | T34: Général | U34: Exclu | V34: 40725
A35: 25.00.00 | B35: A | C35: 45814.583 | D35: D0016 | E35: Contrôles PAY | F35: S0174 | G35: Mouvement 03 | H35: E1010 | I35: Contrôles d'alimentation du mouvement 03 | J35: La date d'effet d'un mouvement 03 est saisie | K35: BG03_DAT_EFF [BG_Occurrence_courante] <> Vide | L35: T2441 | M35: Remise à blanc de la zone | N35: Création Modification | O35: Le code saisi est égal à 'Remise à blanc de la zone' | P35: BG03_NJOUR [BG_Occurrence_courante] = 'ZZ' | Q35: Militaire | R35: P0002 | S35: M | T35: Général | U35: Passant | V35: 40725 | X35: G03_C_001 ET G03_C_002 ET G03_C_003 ET G03_C_005 ET G03_C_009 | Y35: G03_C_001 | Z35: =VLOOKUP(Y35,'Axe 2 Règles de gestion'!$D$2:$F$20,3, FALSE) -> La date d'effet du mouvement 03 ne peut être postérieure au 31 du mois de la paye. | AA35: G03_C_002 | AB35: =VLOOKUP(AA35,'Axe 2 Règles de gestion'!$D$2:$F$20,3, FALSE) -> La date d'effet du mouvement 03 ne peut être antérieure ou égale à la date de prise en charge. | AC35: G03_C_003 | AD35: =VLOOKUP(AC35,'Axe 2 Règles de gestion'!$D$2:$F$20,3, FALSE) -> La date d'effet du mouvement 03 ne peut être antérieure à 3 ans ou plus du 1er jour du mois de paie en cours. Pour un rappel remontant à la quatrième année, il convient d'envoyer un mouvement 42. | AE35: G03_C_005 | AF35: =VLOOKUP(AE35,'Axe 2 Règles de gestion'!$D$2:$F$20,3, FALSE) -> Le nombre de mouvements de type 03 est limité à 20 par mois de paie et par numéro de dossier (NUDOS). | AG35: G03_C_009 | AH35: =VLOOKUP(AG35,'Axe 2 Règles de gestion'!$D$2:$F$20,3, FALSE) -> La valeur 'ZZZZZ' doit être saisi dans le champ "Numérateur de la fraction de rémunération" et la valeur 'ZZZ' doit être saisi dans le champ "Dénominateur de la fraction de rémunération".
A36: 25.00.00 | B36: A | C36: 45814.589 | D36: D0016 | E36: Contrôles PAY | F36: S0174 | G36: Mouvement 03 | H36: E1010 | I36: Contrôles d'alimentation du mouvement 03 | J36: La date d'effet d'un mouvement 03 est saisie | K36: BG03_DAT_EFF [BG_Occurrence_courante] <> Vide | L36: T2442 | M36: Surcotisation CPA | N36: Création Modification | O36: Le code saisi est égal à 'Surcotisation CPA' | P36: BG03_NJOUR [BG_Occurrence_courante] = 'SO' | Q36: Militaire | R36: P0002 | S36: M | T36: Général | U36: Exclu | V36: 40725 | W36: 43555
A37: 25.00.00 | B37: A | C37: 45814.593 | D37: D0016 | E37: Contrôles PAY | F37: S0174 | G37: Mouvement 03 | H37: E1010 | I37: Contrôles d'alimentation du mouvement 03 | J37: La date d'effet d'un mouvement 03 est saisie | K37: BG03_DAT_EFF [BG_Occurrence_courante] <> Vide | L37: T2443 | M37: Maître de l'enseignement privé en CPA | N37: Création Modification | O37: Le code saisi est égal à 'Maître de l'enseignement privé en CPA' | P37: BG03_NJOUR [BG_Occurrence_courante] = 'EP' | Q37: Militaire | R37: P0002 | S37: M | T37: Général | U37: Exclu | V37: 40725 | W37: 43555
A38: 25.00.00 | B38: A | C38: 45814.508 | D38: D0016 | E38: Contrôles PAY | F38: S0174 | G38: Mouvement 03 | H38: E1010 | I38: Contrôles d'alimentation du mouvement 03 | J38: La date d'effet d'un mouvement 03 est saisie | K38: BG03_DAT_EFF [BG_Occurrence_courante] <> Vide | L38: T2426 | M38: Ouvrier de l'aviation civile, temps plein | N38: Création Modification | O38: Le code saisi est égal à 'Ouvrier de l'aviation civile, temps plein' | P38: BG03_NJOUR [BG_Occurrence_courante] = 'AC' | Q38: Contractuel | R38: P0003 | S38: N | T38: Général | U38: Exclu | V38: 40725
A39: 25.00.00 | B39: A | C39: 45814.515 | D39: D0016 | E39: Contrôles PAY | F39: S0174 | G39: Mouvement 03 | H39: E1010 | I39: Contrôles d'alimentation du mouvement 03 | J39: La date d'effet d'un mouvement 03 est saisie | K39: BG03_DAT_EFF [BG_Occurrence_courante] <> Vide | L39: T2427 | M39: Ouvrier de l'aviation civile, temps partiel | N39: Création Modification | O39: Le code saisi est égal à 'Ouvrier de l'aviation civile, temps partiel' | P39: BG03_NJOUR [BG_Occurrence_courante] = 'BC' | Q39: Contractuel | R39: P0003 | S39: N | T39: Général | U39: Exclu | V39: 40725
A40: 25.00.00 | B40: A | C40: 45814.517 | D40: D0016 | E40: Contrôles PAY | F40: S0174 | G40: Mouvement 03 | H40: E1010 | I40: Contrôles d'alimentation du mouvement 03 | J40: La date d'effet d'un mouvement 03 est saisie | K40: BG03_DAT_EFF [BG_Occurrence_courante] <> Vide | L40: T2428 | M40: Contrat d'accompagnement dans l'emploi | N40: Création Modification | O40: Le code saisi est égal à 'CAE' | P40: BG03_NJOUR [BG_Occurrence_courante] = 'CA' | Q40: Contractuel | R40: P0003 | S40: N | T40: Général | U40: Exclu | V40: 40725
...

Sheet Axe 1 Enchaînement RG Impact
A1: Version | B1: Type de mise à jour | C1: Date de mise à jour | D1: Identifiant Domaine | E1: Libellé du Domaine | F1: Identifiant Sous-domaine | G1: Libellé du Sous-domaine | H1: Identifiant Evénement | I1: Libellé de l'évènement | J1: Libellé condition déclenchement Evènement | K1: Condition déclenchement Evènement | L1: Identifiant type d'évènement | M1: Libellé type d'évènement | N1: Type de mise à jour | O1: Libellé condition déclenchement Type Evènement | P1: Condition déclenchement Type Evènement | Q1: Libellé Population | R1: Codification Population | S1: Typologie de population | T1: Général / Particulier | U1: Passant / Exclu | V1: Date de début | W1: Date de fin | X1: Impacts | Y1: FIME | Z1: Statut de travail
A2: 25.00.00 | B2: A | C2: 45814.507 | D2: D0016 | E2: Contrôles PAY | F2: S0174 | G2: Mouvement 03 | H2: E1010 | I2: Contrôles d'alimentation du mouvement 03 | J2: La date d'effet d'un mouvement 03 est saisie | K2: BG03_DAT_EFF [BG_Occurrence_courante] <> Vide | L2: T2426 | M2: Ouvrier de l'aviation civile, temps plein | N2: Création Modification | O2: Le code saisi est égal à 'Ouvrier de l'aviation civile, temps plein' | P2: BG03_NJOUR [BG_Occurrence_courante] = 'AC' | Q2: Titulaire ou magistrat | R2: P0001 | S2: T | T2: Général | U2: Exclu | V2: 40725
A3: 25.00.00 | B3: A | C3: 45814.509 | D3: D0016 | E3: Contrôles PAY | F3: S0174 | G3: Mouvement 03 | H3: E1010 | I3: Contrôles d'alimentation du mouvement 03 | J3: La date d'effet d'un mouvement 03 est saisie | K3: BG03_DAT_EFF [BG_Occurrence_courante] <> Vide | L3: T2427 | M3: Ouvrier de l'aviation civile, temps partiel | N3: Création Modification | O3: Le code saisi est égal à 'Ouvrier de l'aviation civile, temps partiel' | P3: BG03_NJOUR [BG_Occurrence_courante] = 'BC' | Q3: Titulaire ou magistrat | R3: P0001 | S3: T | T3: Général | U3: Exclu | V3: 40725
A4: 25.00.00 | B4: A | C4: 45814.517 | D4: D0016 | E4: Contrôles PAY | F4: S0174 | G4: Mouvement 03 | H4: E1010 | I4: Contrôles d'alimentation du mouvement 03 | J4: La date d'effet d'un mouvement 03 est saisie | K4: BG03_DAT_EFF [BG_Occurrence_courante] <> Vide | L4: T2428 | M4: Contrat d'accompagnement dans l'emploi | N4: Création Modification | O4: Le code saisi est égal à 'CAE' | P4: BG03_NJOUR [BG_Occurrence_courante] = 'CA' | Q4: Titulaire ou magistrat | R4: P0001 | S4: T | T4: Général | U4: Exclu | V4: 40725
A5: 25.00.00 | B5: A | C5: 45814.519 | D5: D0016 | E5: Contrôles PAY | F5: S0174 | G5: Mouvement 03 | H5: E1010 | I5: Contrôles d'alimentation du mouvement 03 | J5: La date d'effet d'un mouvement 03 est saisie | K5: BG03_DAT_EFF [BG_Occurrence_courante] <> Vide | L5: T2429 | M5: Ouvrier de l'aviation civile, surcotisant | N5: Création Modification | O5: Le code saisi est égal à 'Ouvrier de l'aviation civile, surcotisant' | P5: BG03_NJOUR [BG_Occurrence_courante] = 'CC' | Q5: Titulaire ou magistrat | R5: P0001 | S5: T | T5: Général | U5: Exclu | V5: 40725
A6: 25.00.00 | B6: A | C6: 45814.546 | D6: D0016 | E6: Contrôles PAY | F6: S0174 | G6: Mouvement 03 | H6: E1010 | I6: Contrôles d'alimentation du mouvement 03 | J6: La date d'effet d'un mouvement 03 est saisie | K6: BG03_DAT_EFF [BG_Occurrence_courante] <> Vide | L6: T2430 | M6: Agent Handicapé, dont l'incapacité est de 80% au moins, surcotisant | N6: Création Modification | O6: Le code saisi est égal à 'Agent Handicapé, dont l'incapacité est de 80% au moins, surcotisant' | P6: BG03_NJOUR [BG_Occurrence_courante] = 'HA' | Q6: Titulaire ou magistrat | R6: P0001 | S6: T | T6: Général | U6: Passant | V6: 40725
A7: 25.00.00 | B7: A | C7: 45814.548 | D7: D0016 | E7: Contrôles PAY | F7: S0174 | G7: Mouvement 03 | H7: E1010 | I7: Contrôles d'alimentation du mouvement 03 | J7: La date d'effet d'un mouvement 03 est saisie | K7: BG03_DAT_EFF [BG_Occurrence_courante] <> Vide | L7: T2431 | M7: Ouvrier (Cadre Général), à temps partiel, surcotisant, avec handicap d'au moins 80% | N7: Création Modification | O7: Le code saisi est égal à 'Ouvrier (Cadre Général), à temps partiel, surcotisant, avec handicap d'au moins 80%' | P7: BG03_NJOUR [BG_Occurrence_courante] = 'IP' | Q7: Titulaire ou magistrat | R7: P0001 | S7: T | T7: Général | U7: Exclu | V7: 40725
A8: 25.00.00 | B8: A | C8: 45814.549 | D8: D0016 | E8: Contrôles PAY | F8: S0174 | G8: Mouvement 03 | H8: E1010 | I8: Contrôles d'alimentation du mouvement 03 | J8: La date d'effet d'un mouvement 03 est saisie | K8: BG03_DAT_EFF [BG_Occurrence_courante] <> Vide | L8: T2432 | M8: Ouvrier Aviation Civile, à temps partiel, surcotisant, avec handicap d'au moins 80% | N8: Création Modification | O8: Le code saisi est égal à 'Ouvrier Aviation Civile, à temps partiel, surcotisant, avec handicap d'au moins 80%' | P8: BG03_NJOUR [BG_Occurrence_courante] = 'JC' | Q8: Titulaire ou magistrat | R8: P0001 | S8: T | T8: Général | U8: Exclu | V8: 40725
A9: 25.00.00 | B9: A | C9: 45814.551 | D9: D0016 | E9: Contrôles PAY | F9: S0174 | G9: Mouvement 03 | H9: E1010 | I9: Contrôles d'alimentation du mouvement 03 | J9: La date d'effet d'un mouvement 03 est saisie | K9: BG03_DAT_EFF [BG_Occurrence_courante] <> Vide | L9: T2433 | M9: Militaire DGA, pour proratisation de certains éléments | N9: Création Modification | O9: Le code saisi est égal à 'Militaire DGA, pour proratisation de certains éléments' | P9: BG03_NJOUR [BG_Occurrence_courante] = 'MI' | Q9: Titulaire ou magistrat | R9: P0001 | S9: T | T9: Général | U9: Exclu | V9: 40725
A10: 25.00.00 | B10: A | C10: 45814.554 | D10: D0016 | E10: Contrôles PAY | F10: S0174 | G10: Mouvement 03 | H10: E1010 | I10: Contrôles d'alimentation du mouvement 03 | J10: La date d'effet d'un mouvement 03 est saisie | K10: BG03_DAT_EFF [BG_Occurrence_courante] <> Vide | L10: T2434 | M10: Agent non titulaire surcotisant | N10: Création Modification | O10: Le code saisi est égal à 'Agent non titulaire surcotisant' | P10: BG03_NJOUR [BG_Occurrence_courante] = 'NP' | Q10: Titulaire ou magistrat | R10: P0001 | S10: T | T10: Général | U10: Exclu | V10: 40725
A11: 25.00.00 | B11: A | C11: 45814.57 | D11: D0016 | E11: Contrôles PAY | F11: S0174 | G11: Mouvement 03 | H11: E1010 | I11: Contrôles d'alimentation du mouvement 03 | J11: La date d'effet d'un mouvement 03 est saisie | K11: BG03_DAT_EFF [BG_Occurrence_courante] <> Vide | L11: T2435 | M11: Ouvrier (Cadre Général) surcotisant | N11: Création Modification | O11: Le code saisi est égal à 'Ouvrier (Cadre Général) surcotisant' | P11: BG03_NJOUR [BG_Occurrence_courante] = 'OP' | Q11: Titulaire ou magistrat | R11: P0001 | S11: T | T11: Général | U11: Exclu | V11: 40725
A12: 25.00.00 | B12: A | C12: 45814.572 | D12: D0016 | E12: Contrôles PAY | F12: S0174 | G12: Mouvement 03 | H12: E1010 | I12: Contrôles d'alimentation du mouvement 03 | J12: La date d'effet d'un mouvement 03 est saisie | K12: BG03_DAT_EFF [BG_Occurrence_courante] <> Vide | L12: T2436 | M12: Contractuel PACTE | N12: Création Modification | O12: Le code saisi est égal à 'PACTE' | P12: BG03_NJOUR [BG_Occurrence_courante] = 'PA' | Q12: Titulaire ou magistrat | R12: P0001 | S12: T | T12: Général | U12: Exclu | V12: 40725
A13: 25.00.00 | B13: A | C13: 45814.574 | D13: D0016 | E13: Contrôles PAY | F13: S0174 | G13: Mouvement 03 | H13: E1010 | I13: Contrôles d'alimentation du mouvement 03 | J13: La date d'effet d'un mouvement 03 est saisie | K13: BG03_DAT_EFF [BG_Occurrence_courante] <> Vide | L13: T2437 | M13: Surcotisation Douanes, Police, Pénitentiaire | N13: Création Modification | O13: Le code saisi est égal à 'Surcotisation Douanes, Police, Pénitentiaire' | P13: BG03_NJOUR [BG_Occurrence_courante] = 'PP' | Q13: Titulaire ou magistrat | R13: P0001 | S13: T | T13: Général | U13: Passant | V13: 40725
... A17: 25.00.00 | B17: A | C17: 45814.581 | D17: D0016 | E17: Contrôles PAY | F17: S0174 | G17: Mouvement 03 | H17: E1010 | I17: Contrôles d'alimentation du mouvement 03 | J17: La date d'effet d'un mouvement 03 est saisie | K17: BG03_DAT_EFF [BG_Occurrence_courante] <> Vide | L17: T2441 | M17: Remise à blanc de la zone | N17: Création Modification | O17: Le code saisi est égal à 'Remise à blanc de la zone' | P17: BG03_NJOUR [BG_Occurrence_courante] = 'ZZ' | Q17: Titulaire ou magistrat | R17: P0001 | S17: T | T17: Général | U17: Passant | V17: 40725
A18: 25.00.00 | B18: A | C18: 45814.585 | D18: D0016 | E18: Contrôles PAY | F18: S0174 | G18: Mouvement 03 | H18: E1010 | I18: Contrôles d'alimentation du mouvement 03 | J18: La date d'effet d'un mouvement 03 est saisie | K18: BG03_DAT_EFF [BG_Occurrence_courante] <> Vide | L18: T2442 | M18: Surcotisation CPA | N18: Création Modification | O18: Le code saisi est égal à 'Surcotisation CPA' | P18: BG03_NJOUR [BG_Occurrence_courante] = 'SO' | Q18: Titulaire ou magistrat | R18: P0001 | S18: T | T18: Général | U18: Passant | V18: 40725 | W18: 43555
A19: 25.00.00 | B19: A | C19: 45814.592 | D19: D0016 | E19: Contrôles PAY | F19: S0174 | G19: Mouvement 03 | H19: E1010 | I19: Contrôles d'alimentation du mouvement 03 | J19: La date d'effet d'un mouvement 03 est saisie | K19: BG03_DAT_EFF [BG_Occurrence_courante] <> Vide | L19: T2443 | M19: Maître de l'enseignement privé en CPA | N19: Création Modification | O19: Le code saisi est égal à 'Maître de l'enseignement privé en CPA' | P19: BG03_NJOUR [BG_Occurrence_courante] = 'EP' | Q19: Titulaire ou magistrat | R19: P0001 | S19: T | T19: Général | U19: Exclu | V19: 40725 | W19: 43555
A20: 25.00.00 | B20: A | C20: 45814.507 | D20: D0016 | E20: Contrôles PAY | F20: S0174 | G20: Mouvement 03 | H20: E1010 | I20: Contrôles d'alimentation du mouvement 03 | J20: La date d'effet d'un mouvement 03 est saisie | K20: BG03_DAT_EFF [BG_Occurrence_courante] <> Vide | L20: T2426 | M20: Ouvrier de l'aviation civile, temps plein | N20: Création Modification | O20: Le code saisi est égal à 'Ouvrier de l'aviation civile, temps plein' | P20: BG03_NJOUR [BG_Occurrence_courante] = 'AC' | Q20: Militaire | R20: P0002 | S20: M | T20: Général | U20: Exclu | V20: 40725
A21: 25.00.00 | B21: A | C21: 45814.515 | D21: D0016 | E21: Contrôles PAY | F21: S0174 | G21: Mouvement 03 | H21: E1010 | I21: Contrôles d'alimentation du mouvement 03 | J21: La date d'effet d'un mouvement 03 est saisie | K21: BG03_DAT_EFF [BG_Occurrence_courante] <> Vide | L21: T2427 | M21: Ouvrier de l'aviation civile, temps partiel | N21: Création Modification | O21: Le code saisi est égal à 'Ouvrier de l'aviation civile, temps partiel' | P21: BG03_NJOUR [BG_Occurrence_courante] = 'BC' | Q21: Militaire | R21: P0002 | S21: M | T21: Général | U21: Exclu | V21: 40725
A22: 25.00.00 | B22: A | C22: 45814.518 | D22: D0016 | E22: Contrôles PAY | F22: S0174 | G22: Mouvement 03 | H22: E1010 | I22: Contrôles d'alimentation du mouvement 03 | J22: La date d'effet d'un mouvement 03 est saisie | K22: BG03_DAT_EFF [BG_Occurrence_courante] <> Vide | L22: T2428 | M22: Contrat d'accompagnement dans l'emploi | N22: Création Modification | O22: Le code saisi est égal à 'CAE' | P22: BG03_NJOUR [BG_Occurrence_courante] = 'CA' | Q22: Militaire | R22: P0002 | S22: M | T22: Général | U22: Exclu | V22: 40725
A23: 25.00.00 | B23: A | C23: 45814.519 | D23: D0016 | E23: Contrôles PAY | F23: S0174 | G23: Mouvement 03 | H23: E1010 | I23: Contrôles d'alimentation du mouvement 03 | J23: La date d'effet d'un mouvement 03 est saisie | K23: BG03_DAT_EFF [BG_Occurrence_courante] <> Vide | L23: T2429 | M23: Ouvrier de l'aviation civile, surcotisant | N23: Création Modification | O23: Le code saisi est égal à 'Ouvrier de l'aviation civile, surcotisant' | P23: BG03_NJOUR [BG_Occurrence_courante] = 'CC' | Q23: Militaire | R23: P0002 | S23: M | T23: Général | U23: Exclu | V23: 40725
A24: 25.00.00 | B24: A | C24: 45814.547 | D24: D0016 | E24: Contrôles PAY | F24: S0174 | G24: Mouvement 03 | H24: E1010 | I24: Contrôles d'alimentation du mouvement 03 | J24: La date d'effet d'un mouvement 03 est saisie | K24: BG03_DAT_EFF [BG_Occurrence_courante] <> Vide | L24: T2430 | M24: Agent Handicapé, dont l'incapacité est de 80% au moins, surcotisant | N24: Création Modification | O24: Le code saisi est égal à 'Agent Handicapé, dont l'incapacité est de 80% au moins, surcotisant' | P24: BG03_NJOUR [BG_Occurrence_courante] = 'HA' | Q24: Militaire | R24: P0002 | S24: M | T24: Général | U24: Exclu | V24: 40725
A25: 25.00.00 | B25: A | C25: 45814.548 | D25: D0016 | E25: Contrôles PAY | F25: S0174 | G25: Mouvement 03 | H25: E1010 | I25: Contrôles d'alimentation du mouvement 03 | J25: La date d'effet d'un mouvement 03 est saisie | K25: BG03_DAT_EFF [BG_Occurrence_courante] <> Vide | L25: T2431 | M25: Ouvrier (Cadre Général), à temps partiel, surcotisant, avec handicap d'au moins 80% | N25: Création Modification | O25: Le code saisi est égal à 'Ouvrier (Cadre Général), à temps partiel, surcotisant, avec handicap d'au moins 80%' | P25: BG03_NJOUR [BG_Occurrence_courante] = 'IP' | Q25: Militaire | R25: P0002 | S25: M | T25: Général | U25: Exclu | V25: 40725
A26: 25.00.00 | B26: A | C26: 45814.549 | D26: D0016 | E26: Contrôles PAY | F26: S0174 | G26: Mouvement 03 | H26: E1010 | I26: Contrôles d'alimentation du mouvement 03 | J26: La date d'effet d'un mouvement 03 est saisie | K26: BG03_DAT_EFF [BG_Occurrence_courante] <> Vide | L26: T2432 | M26: Ouvrier Aviation Civile, à temps partiel, surcotisant, avec handicap d'au moins 80% | N26: Création Modification | O26: Le code saisi est égal à 'Ouvrier Aviation Civile, à temps partiel, surcotisant, avec handicap d'au moins 80%' | P26: BG03_NJOUR [BG_Occurrence_courante] = 'JC' | Q26: Militaire | R26: P0002 | S26: M | T26: Général | U26: Exclu | V26: 40725
A27: 25.00.00 | B27: A | C27: 45814.551 | D27: D0016 | E27: Contrôles PAY | F27: S0174 | G27: Mouvement 03 | H27: E1010 | I27: Contrôles d'alimentation du mouvement 03 | J27: La date d'effet d'un mouvement 03 est saisie | K27: BG03_DAT_EFF [BG_Occurrence_courante] <> Vide | L27: T2433 | M27: Militaire DGA, pour proratisation de certains éléments | N27: Création Modification | O27: Le code saisi est égal à 'Militaire DGA, pour proratisation de certains éléments' | P27: BG03_NJOUR [BG_Occurrence_courante] = 'MI' | Q27: Militaire | R27: P0002 | S27: M | T27: Général | U27: Exclu | V27: 40725
A28: 25.00.00 | B28: A | C28: 45814.555 | D28: D0016 | E28: Contrôles PAY | F28: S0174 | G28: Mouvement 03 | H28: E1010 | I28: Contrôles d'alimentation du mouvement 03 | J28: La date d'effet d'un mouvement 03 est saisie | K28: BG03_DAT_EFF [BG_Occurrence_courante] <> Vide | L28: T2434 | M28: Agent non titulaire surcotisant | N28: Création Modification | O28: Le code saisi est égal à 'Agent non titulaire surcotisant' | P28: BG03_NJOUR [BG_Occurrence_courante] = 'NP' | Q28: Militaire | R28: P0002 | S28: M | T28: Général | U28: Exclu | V28: 40725
A29: 25.00.00 | B29: A | C29: 45814.57 | D29: D0016 | E29: Contrôles PAY | F29: S0174 | G29: Mouvement 03 | H29: E1010 | I29: Contrôles d'alimentation du mouvement 03 | J29: La date d'effet d'un mouvement 03 est saisie | K29: BG03_DAT_EFF [BG_Occurrence_courante] <> Vide | L29: T2435 | M29: Ouvrier (Cadre Général) surcotisant | N29: Création Modification | O29: Le code saisi est égal à 'Ouvrier (Cadre Général) surcotisant' | P29: BG03_NJOUR [BG_Occurrence_courante] = 'OP' | Q29: Militaire | R29: P0002 | S29: M | T29: Général | U29: Exclu | V29: 40725
A30: 25.00.00 | B30: A | C30: 45814.573 | D30: D0016 | E30: Contrôles PAY | F30: S0174 | G30: Mouvement 03 | H30: E1010 | I30: Contrôles d'alimentation du mouvement 03 | J30: La date d'effet d'un mouvement 03 est saisie | K30: BG03_DAT_EFF [BG_Occurrence_courante] <> Vide | L30: T2436 | M30: Contractuel PACTE | N30: Création Modification | O30: Le code saisi est égal à 'PACTE' | P30: BG03_NJOUR [BG_Occurrence_courante] = 'PA' | Q30: Militaire | R30: P0002 | S30: M | T30: Général | U30: Exclu | V30: 40725
A31: 25.00.00 | B31: A | C31: 45814.574 | D31: D0016 | E31: Contrôles PAY | F31: S0174 | G31: Mouvement 03 | H31: E1010 | I31: Contrôles d'alimentation du mouvement 03 | J31: La date d'effet d'un mouvement 03 est saisie | K31: BG03_DAT_EFF [BG_Occurrence_courante] <> Vide | L31: T2437 | M31: Surcotisation Douanes, Police, Pénitentiaire | N31: Création Modification | O31: Le code saisi est égal à 'Surcotisation Douanes, Police, Pénitentiaire' | P31: BG03_NJOUR [BG_Occurrence_courante] = 'PP' | Q31: Militaire | R31: P0002 | S31: M | T31: Général | U31: Exclu | V31: 40725
... A35: 25.00.00 | B35: A | C35: 45814.583 | D35: D0016 | E35: Contrôles PAY | F35: S0174 | G35: Mouvement 03 | H35: E1010 | I35: Contrôles d'alimentation du mouvement 03 | J35: La date d'effet d'un mouvement 03 est saisie | K35: BG03_DAT_EFF [BG_Occurrence_courante] <> Vide | L35: T2441 | M35: Remise à blanc de la zone | N35: Création Modification | O35: Le code saisi est égal à 'Remise à blanc de la zone' | P35: BG03_NJOUR [BG_Occurrence_courante] = 'ZZ' | Q35: Militaire | R35: P0002 | S35: M | T35: Général | U35: Passant | V35: 40725
A36: 25.00.00 | B36: A | C36: 45814.589 | D36: D0016 | E36: Contrôles PAY | F36: S0174 | G36: Mouvement 03 | H36: E1010 | I36: Contrôles d'alimentation du mouvement 03 | J36: La date d'effet d'un mouvement 03 est saisie | K36: BG03_DAT_EFF [BG_Occurrence_courante] <> Vide | L36: T2442 | M36: Surcotisation CPA | N36: Création Modification | O36: Le code saisi est égal à 'Surcotisation CPA' | P36: BG03_NJOUR [BG_Occurrence_courante] = 'SO' | Q36: Militaire | R36: P0002 | S36: M | T36: Général | U36: Exclu | V36: 40725 | W36: 43555
A37: 25.00.00 | B37: A | C37: 45814.593 | D37: D0016 | E37: Contrôles PAY | F37: S0174 | G37: Mouvement 03 | H37: E1010 | I37: Contrôles d'alimentation du mouvement 03 | J37: La date d'effet d'un mouvement 03 est saisie | K37: BG03_DAT_EFF [BG_Occurrence_courante] <> Vide | L37: T2443 | M37: Maître de l'enseignement privé en CPA | N37: Création Modification | O37: Le code saisi est égal à 'Maître de l'enseignement privé en CPA' | P37: BG03_NJOUR [BG_Occurrence_courante] = 'EP' | Q37: Militaire | R37: P0002 | S37: M | T37: Général | U37: Exclu | V37: 40725 | W37: 43555
A38: 25.00.00 | B38: A | C38: 45814.508 | D38: D0016 | E38: Contrôles PAY | F38: S0174 | G38: Mouvement 03 | H38: E1010 | I38: Contrôles d'alimentation du mouvement 03 | J38: La date d'effet d'un mouvement 03 est saisie | K38: BG03_DAT_EFF [BG_Occurrence_courante] <> Vide | L38: T2426 | M38: Ouvrier de l'aviation civile, temps plein | N38: Création Modification | O38: Le code saisi est égal à 'Ouvrier de l'aviation civile, temps plein' | P38: BG03_NJOUR [BG_Occurrence_courante] = 'AC' | Q38: Contractuel | R38: P0003 | S38: N | T38: Général | U38: Exclu | V38: 40725
A39: 25.00.00 | B39: A | C39: 45814.515 | D39: D0016 | E39: Contrôles PAY | F39: S0174 | G39: Mouvement 03 | H39: E1010 | I39: Contrôles d'alimentation du mouvement 03 | J39: La date d'effet d'un mouvement 03 est saisie | K39: BG03_DAT_EFF [BG_Occurrence_courante] <> Vide | L39: T2427 | M39: Ouvrier de l'aviation civile, temps partiel | N39: Création Modification | O39: Le code saisi est égal à 'Ouvrier de l'aviation civile, temps partiel' | P39: BG03_NJOUR [BG_Occurrence_courante] = 'BC' | Q39: Contractuel | R39: P0003 | S39: N | T39: Général | U39: Exclu | V39: 40725
A40: 25.00.00 | B40: A | C40: 45814.517 | D40: D0016 | E40: Contrôles PAY | F40: S0174 | G40: Mouvement 03 | H40: E1010 | I40: Contrôles d'alimentation du mouvement 03 | J40: La date d'effet d'un mouvement 03 est saisie | K40: BG03_DAT_EFF [BG_Occurrence_courante] <> Vide | L40: T2428 | M40: Contrat d'accompagnement dans l'emploi | N40: Création Modification | O40: Le code saisi est égal à 'CAE' | P40: BG03_NJOUR [BG_Occurrence_courante] = 'CA' | Q40: Contractuel | R40: P0003 | S40: N | T40: Général | U40: Exclu | V40: 40725
A41: 25.00.00 | B41: A | C41: 45814.519 | D41: D0016 | E41: Contrôles PAY | F41: S0174 | G41: Mouvement 03 | H41: E1010 | I41: Contrôles d'alimentation du mouvement 03 | J41: La date d'effet d'un mouvement 03 est saisie | K41: BG03_DAT_EFF [BG_Occurrence_courante] <> Vide | L41: T2429 | M41: Ouvrier de l'aviation civile, surcotisant | N41: Création Modification | O41: Le code saisi est égal à 'Ouvrier de l'aviation civile, surcotisant' | P41: BG03_NJOUR [BG_Occurrence_courante] = 'CC' | Q41: Contractuel | R41: P0003 | S41: N | T41: Général | U41: Exclu | V41: 40725
A42: 25.00.00 | B42: A | C42: 45814.546 | D42: D0016 | E42: Contrôles PAY | F42: S0174 | G42: Mouvement 03 | H42: E1010 | I42: Contrôles d'alimentation du mouvement 03 | J42: La date d'effet d'un mouvement 03 est saisie | K42: BG03_DAT_EFF [BG_Occurrence_courante] <> Vide | L42: T2430 | M42: Agent Handicapé, dont l'incapacité est de 80% au moins, surcotisant | N42: Création Modification | O42: Le code saisi est égal à 'Agent Handicapé, dont l'incapacité est de 80% au moins, surcotisant' | P42: BG03_NJOUR [BG_Occurrence_courante] = 'HA' | Q42: Contractuel | R42: P0003 | S42: N | T42: Général | U42: Passant | V42: 40725
A43: 25.00.00 | B43: A | C43: 45814.548 | D43: D0016 | E43: Contrôles PAY | F43: S0174 | G43: Mouvement 03 | H43: E1010 | I43: Contrôles d'alimentation du mouvement 03 | J43: La date d'effet d'un mouvement 03 est saisie | K43: BG03_DAT_EFF [BG_Occurrence_courante] <> Vide | L43: T2431 | M43: Ouvrier (Cadre Général), à temps partiel, surcotisant, avec handicap d'au moins 80% | N43: Création Modification | O43: Le code saisi est égal à 'Ouvrier (Cadre Général), à temps partiel, surcotisant, avec handicap d'au moins 80%' | P43: BG03_NJOUR [BG_Occurrence_courante] = 'IP' | Q43: Contractuel | R43: P0003 | S43: N | T43: Général | U43: Exclu | V43: 40725
A44: 25.00.00 | B44: A | C44: 45814.549 | D44: D0016 | E44: Contrôles PAY | F44: S0174 | G44: Mouvement 03 | H44: E1010 | I44: Contrôles d'alimentation du mouvement 03 | J44: La date d'effet d'un mouvement 03 est saisie | K44: BG03_DAT_EFF [BG_Occurrence_courante] <> Vide | L44: T2432 | M44: Ouvrier Aviation Civile, à temps partiel, surcotisant, avec handicap d'au moins 80% | N44: Création Modification | O44: Le code saisi est égal à 'Ouvrier Aviation Civile, à temps partiel, surcotisant, avec handicap d'au moins 80%' | P44: BG03_NJOUR [BG_Occurrence_courante] = 'JC' | Q44: Contractuel | R44: P0003 | S44: N | T44: Général | U44: Exclu | V44: 40725
