Workbook
Name date_DIADC: 'Mode opératoire'!#REF!
Name notice_DIADC: 'Mode opératoire'!#REF!
Name notice_ENCHN: 'Mode opératoire'!$B$1:$B$4
Name notice_ICA: 'Mode opératoire'!#REF!

Sheet Mode opératoire
B1: MODE OPERATOIRE
B2: La transaction s'effectue au niveau de la rubrique "Retraite progressive".

Sheet Axe 1 Enchainement des RG
A1: Version | B1: Type de mise à jour | C1: Date de mise à jour | D1: Identifiant Domaine | E1: Libellé du Domaine | F1: Identifiant Sous-domaine | G1: Libellé du Sous-domaine | H1: Identifiant Evénement | I1: Libellé de l'évènement | J1: Libellé condition déclenchement Evènement | K1: Condition déclenchement Evènement | L1: Identifiant type d'évènement | M1: Libellé type d'évènement | N1: Type de mise à jour | O1: Libellé condition déclenchement Type Evènement | P1: Condition déclenchement Type Evènement | Q1: Libellé Population | R1: Codification Population | S1: Typologie de population | T1: Général / Particulier | U1: Passant / Exclu | V1: Date de début | W1: Date de fin | X1: Règles mobilisées | Y1: Identifiant Règle de contrôle intellectuel 1 | Z1: Libellé Règle de contrôle intellectuel 1 | AA1: Identifiant Règle de contrôle intellectuel 2 | AB1: Libellé Règle de contrôle intellectuel 2 | AC1: Identifiant Règle de contrôle intellectuel 3 | AD1: Libellé Règle de contrôle intellectuel 3 | AE1: Identifiant Règle de contrôle intellectuel 4 | AF1: Libellé Règle de contrôle intellectuel 4 | AG1: Identifiant Règle de contrôle intellectuel 5 | AH1: Libellé Règle de contrôle intellectuel 5 | AI1: Identifiant Règle de contrôle intellectuel 6 | AJ1: Libellé Règle de contrôle intellectuel 6 | AK1: Identifiant Règle de contrôle intellectuel 7 | AL1: Libellé Règle de contrôle intellectuel 7 | AM1: Identifiant Règle de contrôle intellectuel 8 | AN1: Libellé Règle de contrôle intellectuel 8 | AO1: Identifiant Règle de contrôle intellectuel 9 | AP1: Libellé Règle de contrôle intellectuel 9 | AQ1: Identifiant Règle de contrôle intellectuel 10 | AR1: Libellé Règle de contrôle intellectuel 10 | AS1: Identifiant Règle de contrôle intellectuel 11 | AT1: Libellé Règle de contrôle intellectuel 11 | AU1: Identifiant Règle de contrôle intellectuel 12 | AV1: Libellé Règle de contrôle intellectuel 12 | AW1: Identifiant Règle de condition 1 | AX1: Libellé Règle de condition 1 | AY1: Identifiant Règle de condition 2 | AZ1: Libellé Règle de condition 2 | BA1: Identifiant Règle de contrôle 1 | BB1: Libellé Règle de contrôle 1 | BC1: Identifiant Règle de contrôle 2 | BD1: Libellé Règle de contrôle 2 | BE1: Identifiant Règle de contrôle 3 | BF1: Libellé Règle de contrôle 3 | BG1: Identifiant Règle de contrôle 4 | BH1: Libellé Règle de contrôle 4 | BI1: Identifiant Règle de contrôle 5 | BJ1: Libellé Règle de contrôle 5 | BK1: FIME | BL1: Statut de travail
A2: 25.10.00 | B2: M | C2: 45915.456 | D2: D0017 | E2: Retraite progressive | F2: S0182 | G2: Retraite progressive | H2: E0969 | I2: Retraite progressive | J2: La date de début retraite progressive saisie est différente de vide | K2: A_RPR_DDRPRO [Saisi] <> VIDE | L2: T2354 | M2: Retraite progressive - Demande | N2: Création | Q2: Titulaire ou magistrat | R2: P0001 | S2: T | T2: Général | U2: Passant | V2: 45170 | W2: 45900 | X2: RPR_I_004 ET RPR_I_013 ET RPR_I_005 ET RPR_I_011 ET RPR_I_002 ET RPR_I_003 ET RPR_I_001 ET RPR_I_009 ET RPR_I_014 ET RPR_I_015 ET RPR_I_016 ET RPR_I_018 ET RPR_D_001 ET RPR_D_002 ET RPR_C_001 ET RPR_C_002 ET RPR_C_003 | Y2: RPR_I_004 | Z2: =VLOOKUP(Y2,'Axe 2 Règles de gestion'!$D$2:$F$66,3, FALSE) -> L'agent doit avoir atteint l'âge plancher égal à son âge d'ouverture des droits diminué de 2 années, soit 62 ans, à l'issue de la montée en charge de la réforme. | AA2: RPR_I_013 | AB2: =VLOOKUP(AA2,'Axe 2 Règles de gestion'!$D$2:$F$66,3, FALSE) -> La condition d'age s'applique pour l'ensemble des agents sédentaires, actifs ou superactifs. | AC2: RPR_I_005 | AD2: =VLOOKUP(AC2,'Axe 2 Règles de gestion'!$D$2:$F$66,3, FALSE) -> L'agent doit justifier d'une durée d'assurance et de périodes reconnues équivalentes fixée à 150 trimestres auprès d'une ou plusieurs caisses de retraite de base. | AE2: RPR_I_011 | AF2: =VLOOKUP(AE2,'Axe 2 Règles de gestion'!$D$2:$F$66,3, FALSE) -> L'agent ne peut pas exercer d'activité accessoire. | AG2: RPR_I_002 | AH2: =VLOOKUP(AG2,'Axe 2 Règles de gestion'!$D$2:$F$66,3, FALSE) -> L'agent doit bénéficier d'une autorisation de temps partiel. | AI2: RPR_I_003 | AJ2: =VLOOKUP(AI2,'Axe 2 Règles de gestion'!$D$2:$F$66,3, FALSE) -> Les modalités de service à temps partiel éligibles sont : le temps partiel sur autorisation, de droit pour soins à conjoint, enfant, ascendant, de droit à l'occasion d'une naissance ou d'une adoption, de droit au profit des travailleurs handicapés. | AK2: RPR_I_001 | AL2: =VLOOKUP(AK2,'Axe 2 Règles de gestion'!$D$2:$F$66,3, FALSE) -> L'agent effectue sa demande de retraite progressive auprès du service des retraites de l'Etat. | AM2: RPR_I_009 | AN2: =VLOOKUP(AM2,'Axe 2 Règles de gestion'!$D$2:$F$66,3, FALSE) -> La demande contient la date d'effet souhaitée de la retraite progressive qui ne peut pas être antérieure à la date de cette demande. | AO2: RPR_I_014 | AP2: =VLOOKUP(AO2,'Axe 2 Règles de gestion'!$D$2:$F$66,3, FALSE) -> La demande de temps partiel et de retraite progressive doivent être effectuées par l'agent au moins 6 mois avant la date de départ en retraite progressive souhaitée. | AQ2: RPR_I_015 | AR2: =VLOOKUP(AQ2,'Axe 2 Règles de gestion'!$D$2:$F$66,3, FALSE) -> L'administration doit transmettre au moins 4 mois avant la date d'effet souhaitée l'autorisation de travail à temps partiel au service des retraites de l'Etat. | AS2: RPR_I_016 | AT2: =VLOOKUP(AS2,'Axe 2 Règles de gestion'!$D$2:$F$66,3, FALSE) -> Si l'agent bénéficie déjà d'un temps partiel au moment où il fait la demande de retraite progressive, il doit l'indiquer dans sa demande. | AU2: RPR_I_018 | AV2: =VLOOKUP(AU2,'Axe 2 Règles de gestion'!$D$2:$F$66,3, FALSE) -> La retraite progressive est notifiée à l'agent 1 mois avant la date d'effet souhaitée. | AW2: RPR_D_001 | AX2: =VLOOKUP(AW2,'Axe 2 Règles de gestion'!$D$2:$F$66,3, FALSE) -> L'agent doit bénéficier d'une autorisation de temps partiel : temps partiel sur autorisation, de droit pour soins à conjoint, enfant, ascendant, de droit à l'occasion d'une naissance ou d'une adoption, de droit au profit des travailleurs handicapés. | AY2: RPR_D_002 | AZ2: =VLOOKUP(AY2,'Axe 2 Règles de gestion'!$D$2:$F$66,3, FALSE) -> L'agent né à partir du 1er janvier 1968 doit avoir au moins 62 ans à la date de début de la retraite progressive. | BA2: RPR_C_001 | BB2: =VLOOKUP(BA2,'Axe 2 Règles de gestion'!$D$2:$F$66,3, FALSE) -> La date de début de la retraite progressive doit être postérieure ou égale à la date d'entrée dans la FPE ou dans la carrière militaire. | BC2: RPR_C_002 | BD2: =VLOOKUP(BC2,'Axe 2 Règles de gestion'!$D$2:$F$66,3, FALSE) -> La date de début de la retraite progressive doit être antérieure ou égale à la date de fin de la retraite progressive. | BE2: RPR_C_003 | BF2: =VLOOKUP(BE2,'Axe 2 Règles de gestion'!$D$2:$F$66,3, FALSE) -> La date de fin de la retraite progressive doit être antérieure à la date limite de départ à la retraite.
A3: 25.10.00 | B3: A | C3: 45915.461 | D3: D0017 | E3: Retraite progressive | F3: S0182 | G3: Retraite progressive | H3: E0969 | I3: Retraite progressive | J3: La date de début retraite progressive saisie est différente de vide | K3: A_RPR_DDRPRO [Saisi] <> VIDE | L3: T2354 | M3: Retraite progressive - Demande | N3: Création | Q3: Titulaire ou magistrat | R3: P0001 | S3: T | T3: Général | U3: Passant | V3: 45901 | X3: RPR_I_049 ET RPR_I_013 ET RPR_I_005 ET RPR_I_011 ET RPR_I_002 ET RPR_I_003 ET RPR_I_001 ET RPR_I_009 ET RPR_I_014 ET RPR_I_015 ET RPR_I_016 ET RPR_I_018 ET RPR_D_001 ET RPR_D_007 ET RPR_C_001 ET RPR_C_002 ET RPR_C_003 | Y3: RPR_I_049 | Z3: =VLOOKUP(Y3,'Axe 2 Règles de gestion'!$D$2:$F$66,3, FALSE) -> L'agent doit avoir 60 ans au moins à l'ouverture du droit à la retraite progressive. | AA3: RPR_I_013 | AB3: =VLOOKUP(AA3,'Axe 2 Règles de gestion'!$D$2:$F$66,3, FALSE) -> La condition d'age s'applique pour l'ensemble des agents sédentaires, actifs ou superactifs. | AC3: RPR_I_005 | AD3: =VLOOKUP(AC3,'Axe 2 Règles de gestion'!$D$2:$F$66,3, FALSE) -> L'agent doit justifier d'une durée d'assurance et de périodes reconnues équivalentes fixée à 150 trimestres auprès d'une ou plusieurs caisses de retraite de base. | AE3: RPR_I_011 | AF3: =VLOOKUP(AE3,'Axe 2 Règles de gestion'!$D$2:$F$66,3, FALSE) -> L'agent ne peut pas exercer d'activité accessoire. | AG3: RPR_I_002 | AH3: =VLOOKUP(AG3,'Axe 2 Règles de gestion'!$D$2:$F$66,3, FALSE) -> L'agent doit bénéficier d'une autorisation de temps partiel. | AI3: RPR_I_003 | AJ3: =VLOOKUP(AI3,'Axe 2 Règles de gestion'!$D$2:$F$66,3, FALSE) -> Les modalités de service à temps partiel éligibles sont : le temps partiel sur autorisation, de droit pour soins à conjoint, enfant, ascendant, de droit à l'occasion d'une naissance ou d'une adoption, de droit au profit des travailleurs handicapés. | AK3: RPR_I_001 | AL3: =VLOOKUP(AK3,'Axe 2 Règles de gestion'!$D$2:$F$66,3, FALSE) -> L'agent effectue sa demande de retraite progressive auprès du service des retraites de l'Etat. | AM3: RPR_I_009 | AN3: =VLOOKUP(AM3,'Axe 2 Règles de gestion'!$D$2:$F$66,3, FALSE) -> La demande contient la date d'effet souhaitée de la retraite progressive qui ne peut pas être antérieure à la date de cette demande. | AO3: RPR_I_014 | AP3: =VLOOKUP(AO3,'Axe 2 Règles de gestion'!$D$2:$F$66,3, FALSE) -> La demande de temps partiel et de retraite progressive doivent être effectuées par l'agent au moins 6 mois avant la date de départ en retraite progressive souhaitée. | AQ3: RPR_I_015 | AR3: =VLOOKUP(AQ3,'Axe 2 Règles de gestion'!$D$2:$F$66,3, FALSE) -> L'administration doit transmettre au moins 4 mois avant la date d'effet souhaitée l'autorisation de travail à temps partiel au service des retraites de l'Etat. | AS3: RPR_I_016 | AT3: =VLOOKUP(AS3,'Axe 2 Règles de gestion'!$D$2:$F$66,3, FALSE) -> Si l'agent bénéficie déjà d'un temps partiel au moment où il fait la demande de retraite progressive, il doit l'indiquer dans sa demande. | AU3: RPR_I_018 | AV3: =VLOOKUP(AU3,'Axe 2 Règles de gestion'!$D$2:$F$66,3, FALSE) -> La retraite progressive est notifiée à l'agent 1 mois avant la date d'effet souhaitée. | AW3: RPR_D_001 | AX3: =VLOOKUP(AW3,'Axe 2 Règles de gestion'!$D$2:$F$66,3, FALSE) -> L'agent doit bénéficier d'une autorisation de temps partiel : temps partiel sur autorisation, de droit pour soins à conjoint, enfant, ascendant, de droit à l'occasion d'une naissance ou d'une adoption, de droit au profit des travailleurs handicapés. | AY3: RPR_D_007 | AZ3: =VLOOKUP(AY3,'Axe 2 Règles de gestion'!$D$2:$F$66,3, FALSE) -> L'âge d'ouverture du droit à la retraite progressive est égal à 60 ans. | BA3: RPR_C_001 | BB3: =VLOOKUP(BA3,'Axe 2 Règles de gestion'!$D$2:$F$66,3, FALSE) -> La date de début de la retraite progressive doit être postérieure ou égale à la date d'entrée dans la FPE ou dans la carrière militaire. | BC3: RPR_C_002 | BD3: =VLOOKUP(BC3,'Axe 2 Règles de gestion'!$D$2:$F$66,3, FALSE) -> La date de début de la retraite progressive doit être antérieure ou égale à la date de fin de la retraite progressive. | BE3: RPR_C_003 | BF3: =VLOOKUP(BE3,'Axe 2 Règles de gestion'!$D$2:$F$66,3, FALSE) -> La date de fin de la retraite progressive doit être antérieure à la date limite de départ à la retraite.
A4: 24.10.00 | B4: A | C4: 45622.508 | D4: D0017 | E4: Retraite progressive | F4: S0182 | G4: Retraite progressive | H4: E0969 | I4: Retraite progressive | J4: La date de début retraite progressive saisie est différente de vide | K4: A_RPR_DDRPRO [Saisi] <> VIDE | L4: T2355 | M4: Retraite progressive - Modification / Fin | N4: Modification | Q4: Titulaire ou magistrat | R4: P0001 | S4: T | T4: Général | U4: Passant | V4: 45170 | X4: RPR_I_012 ET RPR_I_008 ET RPR_I_020 ET RPR_I_007 ET RPR_I_017 ET RPR_I_044 ET RPR_D_001 ET RPR_C_002 ET RPR_C_003 | Y4: RPR_I_012 | Z4: =VLOOKUP(Y4,'Axe 2 Règles de gestion'!$D$2:$F$66,3, FALSE) -> L'administration doit informer sans délai le service des retraites de l'Etat de toutes modifications (retour à temps plein, suspension, modification de la quotité de travail...) relatives à la retraite progressive. | AA4: RPR_I_008 | AB4: =VLOOKUP(AA4,'Axe 2 Règles de gestion'!$D$2:$F$66,3, FALSE) -> Dans certains cas, la retraite progressive peut être suspendue (période de formation au cours de laquelle l'agent exerce à temps plein). | AC4: RPR_I_020 | AD4: =VLOOKUP(AC4,'Axe 2 Règles de gestion'!$D$2:$F$66,3, FALSE) -> La suspension prend effet le 1er jour du mois suivant celui au cours duquel les conditions cessent d'être réunies ou le 1er jour du mois quand la suspension prend effet ce même jour. | AE4: RPR_I_007 | AF4: =VLOOKUP(AE4,'Axe 2 Règles de gestion'!$D$2:$F$66,3, FALSE) -> Si l'agent reprend une activité professionnelle à temps plein alors la retraite progressive cesse définitivement le 1er jour du mois suivant. | AG4: RPR_I_017 | AH4: =VLOOKUP(AG4,'Axe 2 Règles de gestion'!$D$2:$F$66,3, FALSE) -> Toutefois, si cette reprise intervient le 1er jour du mois, alors la cessation de la retraite progressive prend effet ce même jour. | AI4: RPR_I_044 | AJ4: =VLOOKUP(AI4,'Axe 2 Règles de gestion'!$D$2:$F$66,3, FALSE) -> Si l'agent demande sa retraite à taux plein, alors la retraite progressive cesse définitivement à compter de la date d'effet de la pension complète. | AW4: RPR_D_001 | AX4: =VLOOKUP(AW4,'Axe 2 Règles de gestion'!$D$2:$F$66,3, FALSE) -> L'agent doit bénéficier d'une autorisation de temps partiel : temps partiel sur autorisation, de droit pour soins à conjoint, enfant, ascendant, de droit à l'occasion d'une naissance ou d'une adoption, de droit au profit des travailleurs handicapés. | BA4: RPR_C_002 | BB4: =VLOOKUP(BA4,'Axe 2 Règles de gestion'!$D$2:$F$66,3, FALSE) -> La date de début de la retraite progressive doit être antérieure ou égale à la date de fin de la retraite progressive. | BC4: RPR_C_003 | BD4: =VLOOKUP(BC4,'Axe 2 Règles de gestion'!$D$2:$F$66,3, FALSE) -> La date de fin de la retraite progressive doit être antérieure à la date limite de départ à la retraite.
A5: 24.10.00 | B5: A | C5: 45622.508 | D5: D0017 | E5: Retraite progressive | F5: S0182 | G5: Retraite progressive | H5: E0969 | I5: Retraite progressive | J5: La date de début retraite progressive saisie est différente de vide | K5: A_RPR_DDRPRO [Saisi] <> VIDE | L5: T2354 | M5: Retraite progressive - Demande | N5: Création | Q5: Militaire | R5: P0002 | S5: M | T5: Général | U5: Exclu | V5: 45170
A6: 24.10.00 | B6: A | C6: 45622.508 | D6: D0017 | E6: Retraite progressive | F6: S0182 | G6: Retraite progressive | H6: E0969 | I6: Retraite progressive | J6: La date de début retraite progressive saisie est différente de vide | K6: A_RPR_DDRPRO [Saisi] <> VIDE | L6: T2355 | M6: Retraite progressive - Modification / Fin | N6: Modification | Q6: Militaire | R6: P0002 | S6: M | T6: Général | U6: Exclu | V6: 45170
A7: 25.00.00 | B7: M | C7: 45779.49 | D7: D0017 | E7: Retraite progressive | F7: S0182 | G7: Retraite progressive | H7: E0969 | I7: Retraite progressive | J7: La date de début retraite progressive saisie est différente de vide | K7: A_RPR_DDRPRO [Saisi] <> VIDE | L7: T2354 | M7: Retraite progressive - Demande | N7: Création | Q7: Contractuel | R7: P0003 | S7: N | T7: Général | U7: Passant | V7: 45170 | W7: 45709 | X7: RPR_I_034 ET RPR_I_035 ET RPR_I_036 ET RPR_I_042 ET RPR_I_037 ET RPR_D_006 ET RPR_D_005 ET RPR_C_001 ET RPR_C_004 ET RPR_C_002 ET RPR_C_003 ET RPR_C_005 | Y7: RPR_I_034 | Z7: =VLOOKUP(Y7,'Axe 2 Règles de gestion'!$D$2:$F$66,3, FALSE) -> L'agent doit avoir atteint l'âge plancher égal à son âge d'ouverture des droits diminué de 2 années, soit 62 ans, à l'issue de la montée en charge de la réforme. | AA7: RPR_I_035 | AB7: =VLOOKUP(AA7,'Axe 2 Règles de gestion'!$D$2:$F$66,3, FALSE) -> L'agent doit justifier d'une durée d'assurance et de périodes reconnues équivalentes fixée à 150 trimestres auprès d'une ou plusieurs caisses de retraite de base. | AC7: RPR_I_036 | AD7: =VLOOKUP(AC7,'Axe 2 Règles de gestion'!$D$2:$F$66,3, FALSE) -> L'agent doit effectuer une demande. | AE7: RPR_I_042 | AF7: =VLOOKUP(AE7,'Axe 2 Règles de gestion'!$D$2:$F$66,3, FALSE) -> Elle est accompagnée du contrat de travail, d'une déclaration sur l'honneur attestant qu'il n'exerce pas d'autre activité, d'une attestation de l'employeur indiquant la durée du travail à temps complet applicable et des 12 derniers bulletin de paie. | AG7: RPR_I_037 | AH7: =VLOOKUP(AG7,'Axe 2 Règles de gestion'!$D$2:$F$66,3, FALSE) -> L'agent doit adresser sa demande de retraite progressive à l'organisme, l'établissement ou le service gérant l'un des régimes auxquels il est affilié à la date de sa demande. | AW7: RPR_D_006 | AX7: =VLOOKUP(AW7,'Axe 2 Règles de gestion'!$D$2:$F$66,3, FALSE) -> L'agent doit être à temps partiel. | AY7: RPR_D_005 | AZ7: =VLOOKUP(AY7,'Axe 2 Règles de gestion'!$D$2:$F$66,3, FALSE) -> L'agent né à partir du 1er janvier 1968 doit avoir au moins 62 ans à la date de début de la retraite progressive. | BA7: RPR_C_001 | BB7: =VLOOKUP(BA7,'Axe 2 Règles de gestion'!$D$2:$F$66,3, FALSE) -> La date de début de la retraite progressive doit être postérieure ou égale à la date d'entrée dans la FPE ou dans la carrière militaire. | BC7: RPR_C_004 | BD7: =VLOOKUP(BC7,'Axe 2 Règles de gestion'!$D$2:$F$66,3, FALSE) -> La date de début de la retraite progressive doit être postérieure ou égale à la date de début du lien juridique. | BE7: RPR_C_002 | BF7: =VLOOKUP(BE7,'Axe 2 Règles de gestion'!$D$2:$F$66,3, FALSE) -> La date de début de la retraite progressive doit être antérieure ou égale à la date de fin de la retraite progressive. | BG7: RPR_C_003 | BH7: =VLOOKUP(BG7,'Axe 2 Règles de gestion'!$D$2:$F$66,3, FALSE) -> La date de fin de la retraite progressive doit être antérieure à la date limite de départ à la retraite. | BI7: RPR_C_005 | BJ7: =VLOOKUP(BI7,'Axe 2 Règles de gestion'!$D$2:$F$66,3, FALSE) -> La date de fin de la retraite progressive doit être antérieure ou égale à la date de fin du lien juridique.
A8: 25.10.00 | B8: M | C8: 45915.46 | D8: D0017 | E8: Retraite progressive | F8: S0182 | G8: Retraite progressive | H8: E0969 | I8: Retraite progressive | J8: La date de début retraite progressive saisie est différente de vide | K8: A_RPR_DDRPRO [Saisi] <> VIDE | L8: T2354 | M8: Retraite progressive - Demande | N8: Création | Q8: Contractuel | R8: P0003 | S8: N | T8: Général | U8: Passant | V8: 45710 | W8: 45900 | X8: RPR_I_034 ET RPR_I_035 ET RPR_I_036 ET RPR_I_042 ET RPR_I_048 ET RPR_I_045 ET RPR_D_006 ET RPR_D_005 ET RPR_C_001 ET RPR_C_004 ET RPR_C_002 ET RPR_C_003 ET RPR_C_005 | Y8: RPR_I_034 | Z8: =VLOOKUP(Y8,'Axe 2 Règles de gestion'!$D$2:$F$66,3, FALSE) -> L'agent doit avoir atteint l'âge plancher égal à son âge d'ouverture des droits diminué de 2 années, soit 62 ans, à l'issue de la montée en charge de la réforme. | AA8: RPR_I_035 | AB8: =VLOOKUP(AA8,'Axe 2 Règles de gestion'!$D$2:$F$66,3, FALSE) -> L'agent doit justifier d'une durée d'assurance et de périodes reconnues équivalentes fixée à 150 trimestres auprès d'une ou plusieurs caisses de retraite de base. | AC8: RPR_I_036 | AD8: =VLOOKUP(AC8,'Axe 2 Règles de gestion'!$D$2:$F$66,3, FALSE) -> L'agent doit effectuer une demande. | AE8: RPR_I_042 | AF8: =VLOOKUP(AE8,'Axe 2 Règles de gestion'!$D$2:$F$66,3, FALSE) -> Elle est accompagnée du contrat de travail, d'une déclaration sur l'honneur attestant qu'il n'exerce pas d'autre activité, d'une attestation de l'employeur indiquant la durée du travail à temps complet applicable et des 12 derniers bulletin de paie. | AG8: RPR_I_048 | AH8: =VLOOKUP(AG8,'Axe 2 Règles de gestion'!$D$2:$F$66,3, FALSE) -> L'agent doit adresser sa demande de retraite progressive au moyen d'un formulaire commun à l'organisme, l'établissement ou le service gérant l'un des régimes auxquels il est affilié à la date de sa demande. | AI8: RPR_I_045 | AJ8: =VLOOKUP(AI8,'Axe 2 Règles de gestion'!$D$2:$F$66,3, FALSE) -> L'agent reçoit un récépissé de sa demande et des pièces qui l'accompagnent. | AW8: RPR_D_006 | AX8: =VLOOKUP(AW8,'Axe 2 Règles de gestion'!$D$2:$F$66,3, FALSE) -> L'agent doit être à temps partiel. | AY8: RPR_D_005 | AZ8: =VLOOKUP(AY8,'Axe 2 Règles de gestion'!$D$2:$F$66,3, FALSE) -> L'agent né à partir du 1er janvier 1968 doit avoir au moins 62 ans à la date de début de la retraite progressive. | BA8: RPR_C_001 | BB8: =VLOOKUP(BA8,'Axe 2 Règles de gestion'!$D$2:$F$66,3, FALSE) -> La date de début de la retraite progressive doit être postérieure ou égale à la date d'entrée dans la FPE ou dans la carrière militaire. | BC8: RPR_C_004 | BD8: =VLOOKUP(BC8,'Axe 2 Règles de gestion'!$D$2:$F$66,3, FALSE) -> La date de début de la retraite progressive doit être postérieure ou égale à la date de début du lien juridique. | BE8: RPR_C_002 | BF8: =VLOOKUP(BE8,'Axe 2 Règles de gestion'!$D$2:$F$66,3, FALSE) -> La date de début de la retraite progressive doit être antérieure ou égale à la date de fin de la retraite progressive. | BG8: RPR_C_003 | BH8: =VLOOKUP(BG8,'Axe 2 Règles de gestion'!$D$2:$F$66,3, FALSE) -> La date de fin de la retraite progressive doit être antérieure à la date limite de départ à la retraite. | BI8: RPR_C_005 | BJ8: =VLOOKUP(BI8,'Axe 2 Règles de gestion'!$D$2:$F$66,3, FALSE) -> La date de fin de la retraite progressive doit être antérieure ou égale à la date de fin du lien juridique.
A9: 25.10.00 | B9: A | C9: 45915.46 | D9: D0017 | E9: Retraite progressive | F9: S0182 | G9: Retraite progressive | H9: E0969 | I9: Retraite progressive | J9: La date de début retraite progressive saisie est différente de vide | K9: A_RPR_DDRPRO [Saisi] <> VIDE | L9: T2354 | M9: Retraite progressive - Demande | N9: Création | Q9: Contractuel | R9: P0003 | S9: N | T9: Général | U9: Passant | V9: 45901 | X9: RPR_I_050 ET RPR_I_035 ET RPR_I_036 ET RPR_I_042 ET RPR_I_048 ET RPR_I_045 ET RPR_D_006 ET RPR_D_008 ET RPR_C_001 ET RPR_C_004 ET RPR_C_002 ET RPR_C_003 ET RPR_C_005 | Y9: RPR_I_050 | Z9: =VLOOKUP(Y9,'Axe 2 Règles de gestion'!$D$2:$F$66,3, FALSE) -> L'agent doit avoir 60 ans au moins à l'ouverture du droit à la retraite progressive. | AA9: RPR_I_035 | AB9: =VLOOKUP(AA9,'Axe 2 Règles de gestion'!$D$2:$F$66,3, FALSE) -> L'agent doit justifier d'une durée d'assurance et de périodes reconnues équivalentes fixée à 150 trimestres auprès d'une ou plusieurs caisses de retraite de base. | AC9: RPR_I_036 | AD9: =VLOOKUP(AC9,'Axe 2 Règles de gestion'!$D$2:$F$66,3, FALSE) -> L'agent doit effectuer une demande. | AE9: RPR_I_042 | AF9: =VLOOKUP(AE9,'Axe 2 Règles de gestion'!$D$2:$F$66,3, FALSE) -> Elle est accompagnée du contrat de travail, d'une déclaration sur l'honneur attestant qu'il n'exerce pas d'autre activité, d'une attestation de l'employeur indiquant la durée du travail à temps complet applicable et des 12 derniers bulletin de paie. | AG9: RPR_I_048 | AH9: =VLOOKUP(AG9,'Axe 2 Règles de gestion'!$D$2:$F$66,3, FALSE) -> L'agent doit adresser sa demande de retraite progressive au moyen d'un formulaire commun à l'organisme, l'établissement ou le service gérant l'un des régimes auxquels il est affilié à la date de sa demande. | AI9: RPR_I_045 | AJ9: =VLOOKUP(AI9,'Axe 2 Règles de gestion'!$D$2:$F$66,3, FALSE) -> L'agent reçoit un récépissé de sa demande et des pièces qui l'accompagnent. | AW9: RPR_D_006 | AX9: =VLOOKUP(AW9,'Axe 2 Règles de gestion'!$D$2:$F$66,3, FALSE) -> L'agent doit être à temps partiel. | AY9: RPR_D_008 | AZ9: =VLOOKUP(AY9,'Axe 2 Règles de gestion'!$D$2:$F$66,3, FALSE) -> L'âge d'ouverture du droit à la retraite progressive est égal à 60 ans. | BA9: RPR_C_001 | BB9: =VLOOKUP(BA9,'Axe 2 Règles de gestion'!$D$2:$F$66,3, FALSE) -> La date de début de la retraite progressive doit être postérieure ou égale à la date d'entrée dans la FPE ou dans la carrière militaire. | BC9: RPR_C_004 | BD9: =VLOOKUP(BC9,'Axe 2 Règles de gestion'!$D$2:$F$66,3, FALSE) -> La date de début de la retraite progressive doit être postérieure ou égale à la date de début du lien juridique. | BE9: RPR_C_002 | BF9: =VLOOKUP(BE9,'Axe 2 Règles de gestion'!$D$2:$F$66,3, FALSE) -> La date de début de la retraite progressive doit être antérieure ou égale à la date de fin de la retraite progressive. | BG9: RPR_C_003 | BH9: =VLOOKUP(BG9,'Axe 2 Règles de gestion'!$D$2:$F$66,3, FALSE) -> La date de fin de la retraite progressive doit être antérieure à la date limite de départ à la retraite. | BI9: RPR_C_005 | BJ9: =VLOOKUP(BI9,'Axe 2 Règles de gestion'!$D$2:$F$66,3, FALSE) -> La date de fin de la retraite progressive doit être antérieure ou égale à la date de fin du lien juridique.
A10: 24.10.00 | B10: A | C10: 45623.564 | D10: D0017 | E10: Retraite progressive | F10: S0182 | G10: Retraite progressive | H10: E0969 | I10: Retraite progressive | J10: La date de début retraite progressive saisie est différente de vide | K10: A_RPR_DDRPRO [Saisi] <> VIDE | L10: T2355 | M10: Retraite progressive - Modification / Fin | N10: Modification | Q10: Contractuel | R10: P0003 | S10: N | T10: Général | U10: Passant | V10: 45170 | X10: RPR_I_038 ET RPR_I_040 ET RPR_I_041 ET RPR_I_039 ET RPR_I_043 ET RPR_D_006 ET RPR_C_002 ET RPR_C_003 ET RPR_C_005 | Y10: RPR_I_038 | Z10: =VLOOKUP(Y10,'Axe 2 Règles de gestion'!$D$2:$F$66,3, FALSE) -> L'agent informe sa caisse de retraite de toutes modifications impactant sa retraite progressive. | AA10: RPR_I_040 | AB10: =VLOOKUP(AA10,'Axe 2 Règles de gestion'!$D$2:$F$66,3, FALSE) -> Dans certains cas, la retraite progressive peut être suspendue. | AC10: RPR_I_041 | AD10: =VLOOKUP(AC10,'Axe 2 Règles de gestion'!$D$2:$F$66,3, FALSE) -> La suspension prend effet le 1er jour du mois suivant celui au cours duquel les conditions cessent d'être réunies. | AE10: RPR_I_039 | AF10: =VLOOKUP(AE10,'Axe 2 Règles de gestion'!$D$2:$F$66,3, FALSE) -> Si l'agent reprend une activité professionnelle à temps plein alors la retraite progressive cesse définitivement le 1er jour du mois suivant. | AG10: RPR_I_043 | AH10: =VLOOKUP(AG10,'Axe 2 Règles de gestion'!$D$2:$F$66,3, FALSE) -> Si l'agent demande sa retraite à taux plein, alors la retraite progressive cesse définitivement. | AW10: RPR_D_006 | AX10: =VLOOKUP(AW10,'Axe 2 Règles de gestion'!$D$2:$F$66,3, FALSE) -> L'agent doit être à temps partiel. | BA10: RPR_C_002 | BB10: =VLOOKUP(BA10,'Axe 2 Règles de gestion'!$D$2:$F$66,3, FALSE) -> La date de début de la retraite progressive doit être antérieure ou égale à la date de fin de la retraite progressive. | BC10: RPR_C_003 | BD10: =VLOOKUP(BC10,'Axe 2 Règles de gestion'!$D$2:$F$66,3, FALSE) -> La date de fin de la retraite progressive doit être antérieure à la date limite de départ à la retraite. | BE10: RPR_C_005 | BF10: =VLOOKUP(BE10,'Axe 2 Règles de gestion'!$D$2:$F$66,3, FALSE) -> La date de fin de la retraite progressive doit être antérieure ou égale à la date de fin du lien juridique.
A11: 25.10.00 | B11: M | C11: 45915.457 | D11: D0017 | E11: Retraite progressive | F11: S0182 | G11: Retraite progressive | H11: E0969 | I11: Retraite progressive | J11: La date de début retraite progressive saisie est différente de vide | K11: A_RPR_DDRPRO [Saisi] <> VIDE | L11: T2354 | M11: Retraite progressive - Demande | N11: Création | Q11: Stagiaire ou auditeur ou élève | R11: P0004 | S11: S | T11: Général | U11: Passant | V11: 45170 | W11: 45900 | X11: RPR_I_004 ET RPR_I_013 ET RPR_I_005 ET RPR_I_011 ET RPR_I_002 ET RPR_I_003 ET RPR_I_001 ET RPR_I_009 ET RPR_I_014 ET RPR_I_015 ET RPR_I_016 ET RPR_I_018 ET RPR_D_001 ET RPR_D_002 ET RPR_C_001 ET RPR_C_002 ET RPR_C_003 | Y11: RPR_I_004 | Z11: =VLOOKUP(Y11,'Axe 2 Règles de gestion'!$D$2:$F$66,3, FALSE) -> L'agent doit avoir atteint l'âge plancher égal à son âge d'ouverture des droits diminué de 2 années, soit 62 ans, à l'issue de la montée en charge de la réforme. | AA11: RPR_I_013 | AB11: =VLOOKUP(AA11,'Axe 2 Règles de gestion'!$D$2:$F$66,3, FALSE) -> La condition d'age s'applique pour l'ensemble des agents sédentaires, actifs ou superactifs. | AC11: RPR_I_005 | AD11: =VLOOKUP(AC11,'Axe 2 Règles de gestion'!$D$2:$F$66,3, FALSE) -> L'agent doit justifier d'une durée d'assurance et de périodes reconnues équivalentes fixée à 150 trimestres auprès d'une ou plusieurs caisses de retraite de base. | AE11: RPR_I_011 | AF11: =VLOOKUP(AE11,'Axe 2 Règles de gestion'!$D$2:$F$66,3, FALSE) -> L'agent ne peut pas exercer d'activité accessoire. | AG11: RPR_I_002 | AH11: =VLOOKUP(AG11,'Axe 2 Règles de gestion'!$D$2:$F$66,3, FALSE) -> L'agent doit bénéficier d'une autorisation de temps partiel. | AI11: RPR_I_003 | AJ11: =VLOOKUP(AI11,'Axe 2 Règles de gestion'!$D$2:$F$66,3, FALSE) -> Les modalités de service à temps partiel éligibles sont : le temps partiel sur autorisation, de droit pour soins à conjoint, enfant, ascendant, de droit à l'occasion d'une naissance ou d'une adoption, de droit au profit des travailleurs handicapés. | AK11: RPR_I_001 | AL11: =VLOOKUP(AK11,'Axe 2 Règles de gestion'!$D$2:$F$66,3, FALSE) -> L'agent effectue sa demande de retraite progressive auprès du service des retraites de l'Etat. | AM11: RPR_I_009 | AN11: =VLOOKUP(AM11,'Axe 2 Règles de gestion'!$D$2:$F$66,3, FALSE) -> La demande contient la date d'effet souhaitée de la retraite progressive qui ne peut pas être antérieure à la date de cette demande. | AO11: RPR_I_014 | AP11: =VLOOKUP(AO11,'Axe 2 Règles de gestion'!$D$2:$F$66,3, FALSE) -> La demande de temps partiel et de retraite progressive doivent être effectuées par l'agent au moins 6 mois avant la date de départ en retraite progressive souhaitée. | AQ11: RPR_I_015 | AR11: =VLOOKUP(AQ11,'Axe 2 Règles de gestion'!$D$2:$F$66,3, FALSE) -> L'administration doit transmettre au moins 4 mois avant la date d'effet souhaitée l'autorisation de travail à temps partiel au service des retraites de l'Etat. | AS11: RPR_I_016 | AT11: =VLOOKUP(AS11,'Axe 2 Règles de gestion'!$D$2:$F$66,3, FALSE) -> Si l'agent bénéficie déjà d'un temps partiel au moment où il fait la demande de retraite progressive, il doit l'indiquer dans sa demande. | AU11: RPR_I_018 | AV11: =VLOOKUP(AU11,'Axe 2 Règles de gestion'!$D$2:$F$66,3, FALSE) -> La retraite progressive est notifiée à l'agent 1 mois avant la date d'effet souhaitée. | AW11: RPR_D_001 | AX11: =VLOOKUP(AW11,'Axe 2 Règles de gestion'!$D$2:$F$66,3, FALSE) -> L'agent doit bénéficier d'une autorisation de temps partiel : temps partiel sur autorisation, de droit pour soins à conjoint, enfant, ascendant, de droit à l'occasion d'une naissance ou d'une adoption, de droit au profit des travailleurs handicapés. | AY11: RPR_D_002 | AZ11: =VLOOKUP(AY11,'Axe 2 Règles de gestion'!$D$2:$F$66,3, FALSE) -> L'agent né à partir du 1er janvier 1968 doit avoir au moins 62 ans à la date de début de la retraite progressive. | BA11: RPR_C_001 | BB11: =VLOOKUP(BA11,'Axe 2 Règles de gestion'!$D$2:$F$66,3, FALSE) -> La date de début de la retraite progressive doit être postérieure ou égale à la date d'entrée dans la FPE ou dans la carrière militaire. | BC11: RPR_C_002 | BD11: =VLOOKUP(BC11,'Axe 2 Règles de gestion'!$D$2:$F$66,3, FALSE) -> La date de début de la retraite progressive doit être antérieure ou égale à la date de fin de la retraite progressive. | BE11: RPR_C_003 | BF11: =VLOOKUP(BE11,'Axe 2 Règles de gestion'!$D$2:$F$66,3, FALSE) -> La date de fin de la retraite progressive doit être antérieure à la date limite de départ à la retraite.
A12: 25.10.00 | B12: A | C12: 45915.461 | D12: D0017 | E12: Retraite progressive | F12: S0182 | G12: Retraite progressive | H12: E0969 | I12: Retraite progressive | J12: La date de début retraite progressive saisie est différente de vide | K12: A_RPR_DDRPRO [Saisi] <> VIDE | L12: T2354 | M12: Retraite progressive - Demande | N12: Création | Q12: Stagiaire ou auditeur ou élève | R12: P0004 | S12: S | T12: Général | U12: Passant | V12: 45901 | X12: RPR_I_049 ET RPR_I_013 ET RPR_I_005 ET RPR_I_011 ET RPR_I_002 ET RPR_I_003 ET RPR_I_001 ET RPR_I_009 ET RPR_I_014 ET RPR_I_015 ET RPR_I_016 ET RPR_I_018 ET RPR_D_001 ET RPR_D_007 ET RPR_C_001 ET RPR_C_002 ET RPR_C_003 | Y12: RPR_I_049 | Z12: =VLOOKUP(Y12,'Axe 2 Règles de gestion'!$D$2:$F$66,3, FALSE) -> L'agent doit avoir 60 ans au moins à l'ouverture du droit à la retraite progressive. | AA12: RPR_I_013 | AB12: =VLOOKUP(AA12,'Axe 2 Règles de gestion'!$D$2:$F$66,3, FALSE) -> La condition d'age s'applique pour l'ensemble des agents sédentaires, actifs ou superactifs. | AC12: RPR_I_005 | AD12: =VLOOKUP(AC12,'Axe 2 Règles de gestion'!$D$2:$F$66,3, FALSE) -> L'agent doit justifier d'une durée d'assurance et de périodes reconnues équivalentes fixée à 150 trimestres auprès d'une ou plusieurs caisses de retraite de base. | AE12: RPR_I_011 | AF12: =VLOOKUP(AE12,'Axe 2 Règles de gestion'!$D$2:$F$66,3, FALSE) -> L'agent ne peut pas exercer d'activité accessoire. | AG12: RPR_I_002 | AH12: =VLOOKUP(AG12,'Axe 2 Règles de gestion'!$D$2:$F$66,3, FALSE) -> L'agent doit bénéficier d'une autorisation de temps partiel. | AI12: RPR_I_003 | AJ12: =VLOOKUP(AI12,'Axe 2 Règles de gestion'!$D$2:$F$66,3, FALSE) -> Les modalités de service à temps partiel éligibles sont : le temps partiel sur autorisation, de droit pour soins à conjoint, enfant, ascendant, de droit à l'occasion d'une naissance ou d'une adoption, de droit au profit des travailleurs handicapés. | AK12: RPR_I_001 | AL12: =VLOOKUP(AK12,'Axe 2 Règles de gestion'!$D$2:$F$66,3, FALSE) -> L'agent effectue sa demande de retraite progressive auprès du service des retraites de l'Etat. | AM12: RPR_I_009 | AN12: =VLOOKUP(AM12,'Axe 2 Règles de gestion'!$D$2:$F$66,3, FALSE) -> La demande contient la date d'effet souhaitée de la retraite progressive qui ne peut pas être antérieure à la date de cette demande. | AO12: RPR_I_014 | AP12: =VLOOKUP(AO12,'Axe 2 Règles de gestion'!$D$2:$F$66,3, FALSE) -> La demande de temps partiel et de retraite progressive doivent être effectuées par l'agent au moins 6 mois avant la date de départ en retraite progressive souhaitée. | AQ12: RPR_I_015 | AR12: =VLOOKUP(AQ12,'Axe 2 Règles de gestion'!$D$2:$F$66,3, FALSE) -> L'administration doit transmettre au moins 4 mois avant la date d'effet souhaitée l'autorisation de travail à temps partiel au service des retraites de l'Etat. | AS12: RPR_I_016 | AT12: =VLOOKUP(AS12,'Axe 2 Règles de gestion'!$D$2:$F$66,3, FALSE) -> Si l'agent bénéficie déjà d'un temps partiel au moment où il fait la demande de retraite progressive, il doit l'indiquer dans sa demande. | AU12: RPR_I_018 | AV12: =VLOOKUP(AU12,'Axe 2 Règles de gestion'!$D$2:$F$66,3, FALSE) -> La retraite progressive est notifiée à l'agent 1 mois avant la date d'effet souhaitée. | AW12: RPR_D_001 | AX12: =VLOOKUP(AW12,'Axe 2 Règles de gestion'!$D$2:$F$66,3, FALSE) -> L'agent doit bénéficier d'une autorisation de temps partiel : temps partiel sur autorisation, de droit pour soins à conjoint, enfant, ascendant, de droit à l'occasion d'une naissance ou d'une adoption, de droit au profit des travailleurs handicapés. | AY12: RPR_D_007 | AZ12: =VLOOKUP(AY12,'Axe 2 Règles de gestion'!$D$2:$F$66,3, FALSE) -> L'âge d'ouverture du droit à la retraite progressive est égal à 60 ans. | BA12: RPR_C_001 | BB12: =VLOOKUP(BA12,'Axe 2 Règles de gestion'!$D$2:$F$66,3, FALSE) -> La date de début de la retraite progressive doit être postérieure ou égale à la date d'entrée dans la FPE ou dans la carrière militaire. | BC12: RPR_C_002 | BD12: =VLOOKUP(BC12,'Axe 2 Règles de gestion'!$D$2:$F$66,3, FALSE) -> La date de début de la retraite progressive doit être antérieure ou égale à la date de fin de la retraite progressive. | BE12: RPR_C_003 | BF12: =VLOOKUP(BE12,'Axe 2 Règles de gestion'!$D$2:$F$66,3, FALSE) -> La date de fin de la retraite progressive doit être antérieure à la date limite de départ à la retraite.
A13: 24.10.00 | B13: A | C13: 45623.565 | D13: D0017 | E13: Retraite progressive | F13: S0182 | G13: Retraite progressive | H13: E0969 | I13: Retraite progressive | J13: La date de début retraite progressive saisie est différente de vide | K13: A_RPR_DDRPRO [Saisi] <> VIDE | L13: T2355 | M13: Retraite progressive - Modification / Fin | N13: Modification | Q13: Stagiaire ou auditeur ou élève | R13: P0004 | S13: S | T13: Général | U13: Passant | V13: 45170 | X13: RPR_I_012 ET RPR_I_008 ET RPR_I_020 ET RPR_I_007 ET RPR_I_017 ET RPR_I_044 ET RPR_D_001 ET RPR_C_002 ET RPR_C_003 | Y13: RPR_I_012 | Z13: =VLOOKUP(Y13,'Axe 2 Règles de gestion'!$D$2:$F$66,3, FALSE) -> L'administration doit informer sans délai le service des retraites de l'Etat de toutes modifications (retour à temps plein, suspension, modification de la quotité de travail...) relatives à la retraite progressive. | AA13: RPR_I_008 | AB13: =VLOOKUP(AA13,'Axe 2 Règles de gestion'!$D$2:$F$66,3, FALSE) -> Dans certains cas, la retraite progressive peut être suspendue (période de formation au cours de laquelle l'agent exerce à temps plein). | AC13: RPR_I_020 | AD13: =VLOOKUP(AC13,'Axe 2 Règles de gestion'!$D$2:$F$66,3, FALSE) -> La suspension prend effet le 1er jour du mois suivant celui au cours duquel les conditions cessent d'être réunies ou le 1er jour du mois quand la suspension prend effet ce même jour. | AE13: RPR_I_007 | AF13: =VLOOKUP(AE13,'Axe 2 Règles de gestion'!$D$2:$F$66,3, FALSE) -> Si l'agent reprend une activité professionnelle à temps plein alors la retraite progressive cesse définitivement le 1er jour du mois suivant. | AG13: RPR_I_017 | AH13: =VLOOKUP(AG13,'Axe 2 Règles de gestion'!$D$2:$F$66,3, FALSE) -> Toutefois, si cette reprise intervient le 1er jour du mois, alors la cessation de la retraite progressive prend effet ce même jour. | AI13: RPR_I_044 | AJ13: =VLOOKUP(AI13,'Axe 2 Règles de gestion'!$D$2:$F$66,3, FALSE) -> Si l'agent demande sa retraite à taux plein, alors la retraite progressive cesse définitivement à compter de la date d'effet de la pension complète. | AW13: RPR_D_001 | AX13: =VLOOKUP(AW13,'Axe 2 Règles de gestion'!$D$2:$F$66,3, FALSE) -> L'agent doit bénéficier d'une autorisation de temps partiel : temps partiel sur autorisation, de droit pour soins à conjoint, enfant, ascendant, de droit à l'occasion d'une naissance ou d'une adoption, de droit au profit des travailleurs handicapés. | BA13: RPR_C_002 | BB13: =VLOOKUP(BA13,'Axe 2 Règles de gestion'!$D$2:$F$66,3, FALSE) -> La date de début de la retraite progressive doit être antérieure ou égale à la date de fin de la retraite progressive. | BC13: RPR_C_003 | BD13: =VLOOKUP(BC13,'Axe 2 Règles de gestion'!$D$2:$F$66,3, FALSE) -> La date de fin de la retraite progressive doit être antérieure à la date limite de départ à la retraite.
A14: 25.00.00 | B14: M | C14: 45779.494 | D14: D0017 | E14: Retraite progressive | F14: S0182 | G14: Retraite progressive | H14: E0969 | I14: Retraite progressive | J14: La date de début retraite progressive saisie est différente de vide | K14: A_RPR_DDRPRO [Saisi] <> VIDE | L14: T2354 | M14: Retraite progressive - Demande | N14: Création | Q14: Ouvrier d'état | R14: P0005 | S14: O | T14: Général | U14: Passant | V14: 45170 | W14: 45709 | X14: RPR_I_023 ET RPR_I_024 ET RPR_I_025 ET RPR_I_026 ET RPR_I_022 ET RPR_I_033 ET RPR_I_027 ET RPR_D_003 ET RPR_D_004 ET RPR_C_001 ET RPR_C_004 ET RPR_C_002 ET RPR_C_003 ET RPR_C_005 | Y14: RPR_I_023 | Z14: =VLOOKUP(Y14,'Axe 2 Règles de gestion'!$D$2:$F$66,3, FALSE) -> L'agent doit avoir atteint l'âge plancher égal à son âge d'ouverture des droits diminué de 2 années, soit 62 ans, à l'issue de la montée en charge de la réforme. | AA14: RPR_I_024 | AB14: =VLOOKUP(AA14,'Axe 2 Règles de gestion'!$D$2:$F$66,3, FALSE) -> L'agent doit justifier d'une durée d'assurance de 150 trimestres. | AC14: RPR_I_025 | AD14: =VLOOKUP(AC14,'Axe 2 Règles de gestion'!$D$2:$F$66,3, FALSE) -> L'agent doit bénéficier d'une autorisation de temps partiel. | AE14: RPR_I_026 | AF14: =VLOOKUP(AE14,'Axe 2 Règles de gestion'!$D$2:$F$66,3, FALSE) -> Les modalités de service à temps partiel éligbles sont : le temps partiel sur autorisation, de droit pour soins à conjoint, enfant, ascendant, de droit à l'occasion d'une naissance ou d'une adoption, de droit au profit des travailleurs handicapés. | AG14: RPR_I_022 | AH14: =VLOOKUP(AG14,'Axe 2 Règles de gestion'!$D$2:$F$66,3, FALSE) -> L'agent doit effectuer une demande auprès de l'administration. | AI14: RPR_I_033 | AJ14: =VLOOKUP(AI14,'Axe 2 Règles de gestion'!$D$2:$F$66,3, FALSE) -> La demande contient la date d'effet souhaitée de la retraite progressive qui ne peut pas être antérieure à la date de cette demande. | AK14: RPR_I_027 | AL14: =VLOOKUP(AK14,'Axe 2 Règles de gestion'!$D$2:$F$66,3, FALSE) -> L'agent doit adresser sa demande de retraite progressive à l'organisme, l'établissement ou le service gérant l'un des régimes auxquels il est affilié à la date de sa demande. | AW14: RPR_D_003 | AX14: =VLOOKUP(AW14,'Axe 2 Règles de gestion'!$D$2:$F$66,3, FALSE) -> L'agent doit bénéficier d'une autorisation de temps partiel : temps partiel sur autorisation, de droit pour soins à conjoint, enfant, ascendant, de droit à l'occasion d'une naissance ou d'une adoption, de droit au profit des travailleurs handicapés. | AY14: RPR_D_004 | AZ14: =VLOOKUP(AY14,'Axe 2 Règles de gestion'!$D$2:$F$66,3, FALSE) -> L'agent né à partir du 1er janvier 1968 doit avoir au moins 62 ans à la date de début de la retraite progressive. | BA14: RPR_C_001 | BB14: =VLOOKUP(BA14,'Axe 2 Règles de gestion'!$D$2:$F$66,3, FALSE) -> La date de début de la retraite progressive doit être postérieure ou égale à la date d'entrée dans la FPE ou dans la carrière militaire. | BC14: RPR_C_004 | BD14: =VLOOKUP(BC14,'Axe 2 Règles de gestion'!$D$2:$F$66,3, FALSE) -> La date de début de la retraite progressive doit être postérieure ou égale à la date de début du lien juridique. | BE14: RPR_C_002 | BF14: =VLOOKUP(BE14,'Axe 2 Règles de gestion'!$D$2:$F$66,3, FALSE) -> La date de début de la retraite progressive doit être antérieure ou égale à la date de fin de la retraite progressive. | BG14: RPR_C_003 | BH14: =VLOOKUP(BG14,'Axe 2 Règles de gestion'!$D$2:$F$66,3, FALSE) -> La date de fin de la retraite progressive doit être antérieure à la date limite de départ à la retraite. | BI14: RPR_C_005 | BJ14: =VLOOKUP(BI14,'Axe 2 Règles de gestion'!$D$2:$F$66,3, FALSE) -> La date de fin de la retraite progressive doit être antérieure ou égale à la date de fin du lien juridique.
A15: 25.10.00 | B15: M | C15: 45915.46 | D15: D0017 | E15: Retraite progressive | F15: S0182 | G15: Retraite progressive | H15: E0969 | I15: Retraite progressive | J15: La date de début retraite progressive saisie est différente de vide | K15: A_RPR_DDRPRO [Saisi] <> VIDE | L15: T2354 | M15: Retraite progressive - Demande | N15: Création | Q15: Ouvrier d'état | R15: P0005 | S15: O | T15: Général | U15: Passant | V15: 45710 | W15: 45900 | X15: RPR_I_023 ET RPR_I_024 ET RPR_I_025 ET RPR_I_026 ET RPR_I_022 ET RPR_I_033 ET RPR_I_047 ET RPR_I_046 ET RPR_D_003 ET RPR_D_004 ET RPR_C_001 ET RPR_C_004 ET RPR_C_002 ET RPR_C_003 ET RPR_C_005 | Y15: RPR_I_023 | Z15: =VLOOKUP(Y15,'Axe 2 Règles de gestion'!$D$2:$F$66,3, FALSE) -> L'agent doit avoir atteint l'âge plancher égal à son âge d'ouverture des droits diminué de 2 années, soit 62 ans, à l'issue de la montée en charge de la réforme. | AA15: RPR_I_024 | AB15: =VLOOKUP(AA15,'Axe 2 Règles de gestion'!$D$2:$F$66,3, FALSE) -> L'agent doit justifier d'une durée d'assurance de 150 trimestres. | AC15: RPR_I_025 | AD15: =VLOOKUP(AC15,'Axe 2 Règles de gestion'!$D$2:$F$66,3, FALSE) -> L'agent doit bénéficier d'une autorisation de temps partiel. | AE15: RPR_I_026 | AF15: =VLOOKUP(AE15,'Axe 2 Règles de gestion'!$D$2:$F$66,3, FALSE) -> Les modalités de service à temps partiel éligbles sont : le temps partiel sur autorisation, de droit pour soins à conjoint, enfant, ascendant, de droit à l'occasion d'une naissance ou d'une adoption, de droit au profit des travailleurs handicapés. | AG15: RPR_I_022 | AH15: =VLOOKUP(AG15,'Axe 2 Règles de gestion'!$D$2:$F$66,3, FALSE) -> L'agent doit effectuer une demande auprès de l'administration. | AI15: RPR_I_033 | AJ15: =VLOOKUP(AI15,'Axe 2 Règles de gestion'!$D$2:$F$66,3, FALSE) -> La demande contient la date d'effet souhaitée de la retraite progressive qui ne peut pas être antérieure à la date de cette demande. | AK15: RPR_I_047 | AL15: =VLOOKUP(AK15,'Axe 2 Règles de gestion'!$D$2:$F$66,3, FALSE) -> L'agent doit adresser sa demande de retraite progressive au moyen d'un formulaire commun à l'organisme, l'établissement ou le service gérant l'un des régimes auxquels il est affilié à la date de sa demande. | AM15: RPR_I_046 | AN15: =VLOOKUP(AM15,'Axe 2 Règles de gestion'!$D$2:$F$66,3, FALSE) -> L'agent reçoit un récépissé de sa demande et des pièces qui l'accompagnent. | AW15: RPR_D_003 | AX15: =VLOOKUP(AW15,'Axe 2 Règles de gestion'!$D$2:$F$66,3, FALSE) -> L'agent doit bénéficier d'une autorisation de temps partiel : temps partiel sur autorisation, de droit pour soins à conjoint, enfant, ascendant, de droit à l'occasion d'une naissance ou d'une adoption, de droit au profit des travailleurs handicapés. | AY15: RPR_D_004 | AZ15: =VLOOKUP(AY15,'Axe 2 Règles de gestion'!$D$2:$F$66,3, FALSE) -> L'agent né à partir du 1er janvier 1968 doit avoir au moins 62 ans à la date de début de la retraite progressive. | BA15: RPR_C_001 | BB15: =VLOOKUP(BA15,'Axe 2 Règles de gestion'!$D$2:$F$66,3, FALSE) -> La date de début de la retraite progressive doit être postérieure ou égale à la date d'entrée dans la FPE ou dans la carrière militaire. | BC15: RPR_C_004 | BD15: =VLOOKUP(BC15,'Axe 2 Règles de gestion'!$D$2:$F$66,3, FALSE) -> La date de début de la retraite progressive doit être postérieure ou égale à la date de début du lien juridique. | BE15: RPR_C_002 | BF15: =VLOOKUP(BE15,'Axe 2 Règles de gestion'!$D$2:$F$66,3, FALSE) -> La date de début de la retraite progressive doit être antérieure ou égale à la date de fin de la retraite progressive. | BG15: RPR_C_003 | BH15: =VLOOKUP(BG15,'Axe 2 Règles de gestion'!$D$2:$F$66,3, FALSE) -> La date de fin de la retraite progressive doit être antérieure à la date limite de départ à la retraite. | BI15: RPR_C_005 | BJ15: =VLOOKUP(BI15,'Axe 2 Règles de gestion'!$D$2:$F$66,3, FALSE) -> La date de fin de la retraite progressive doit être antérieure ou égale à la date de fin du lien juridique.
A16: 25.10.00 | B16: A | C16: 45915.461 | D16: D0017 | E16: Retraite progressive | F16: S0182 | G16: Retraite progressive | H16: E0969 | I16: Retraite progressive | J16: La date de début retraite progressive saisie est différente de vide | K16: A_RPR_DDRPRO [Saisi] <> VIDE | L16: T2354 | M16: Retraite progressive - Demande | N16: Création | Q16: Ouvrier d'état | R16: P0005 | S16: O | T16: Général | U16: Passant | V16: 45901 | X16: RPR_I_051 ET RPR_I_024 ET RPR_I_025 ET RPR_I_026 ET RPR_I_022 ET RPR_I_033 ET RPR_I_047 ET RPR_I_046 ET RPR_D_003 ET RPR_D_009 ET RPR_C_001 ET RPR_C_004 ET RPR_C_002 ET RPR_C_003 ET RPR_C_005 | Y16: RPR_I_051 | Z16: =VLOOKUP(Y16,'Axe 2 Règles de gestion'!$D$2:$F$66,3, FALSE) -> L'agent doit avoir 60 ans au moins à l'ouverture du droit à la retraite progressive. | AA16: RPR_I_024 | AB16: =VLOOKUP(AA16,'Axe 2 Règles de gestion'!$D$2:$F$66,3, FALSE) -> L'agent doit justifier d'une durée d'assurance de 150 trimestres. | AC16: RPR_I_025 | AD16: =VLOOKUP(AC16,'Axe 2 Règles de gestion'!$D$2:$F$66,3, FALSE) -> L'agent doit bénéficier d'une autorisation de temps partiel. | AE16: RPR_I_026 | AF16: =VLOOKUP(AE16,'Axe 2 Règles de gestion'!$D$2:$F$66,3, FALSE) -> Les modalités de service à temps partiel éligbles sont : le temps partiel sur autorisation, de droit pour soins à conjoint, enfant, ascendant, de droit à l'occasion d'une naissance ou d'une adoption, de droit au profit des travailleurs handicapés. | AG16: RPR_I_022 | AH16: =VLOOKUP(AG16,'Axe 2 Règles de gestion'!$D$2:$F$66,3, FALSE) -> L'agent doit effectuer une demande auprès de l'administration. | AI16: RPR_I_033 | AJ16: =VLOOKUP(AI16,'Axe 2 Règles de gestion'!$D$2:$F$66,3, FALSE) -> La demande contient la date d'effet souhaitée de la retraite progressive qui ne peut pas être antérieure à la date de cette demande. | AK16: RPR_I_047 | AL16: =VLOOKUP(AK16,'Axe 2 Règles de gestion'!$D$2:$F$66,3, FALSE) -> L'agent doit adresser sa demande de retraite progressive au moyen d'un formulaire commun à l'organisme, l'établissement ou le service gérant l'un des régimes auxquels il est affilié à la date de sa demande. | AM16: RPR_I_046 | AN16: =VLOOKUP(AM16,'Axe 2 Règles de gestion'!$D$2:$F$66,3, FALSE) -> L'agent reçoit un récépissé de sa demande et des pièces qui l'accompagnent. | AW16: RPR_D_003 | AX16: =VLOOKUP(AW16,'Axe 2 Règles de gestion'!$D$2:$F$66,3, FALSE) -> L'agent doit bénéficier d'une autorisation de temps partiel : temps partiel sur autorisation, de droit pour soins à conjoint, enfant, ascendant, de droit à l'occasion d'une naissance ou d'une adoption, de droit au profit des travailleurs handicapés. | AY16: RPR_D_009 | AZ16: =VLOOKUP(AY16,'Axe 2 Règles de gestion'!$D$2:$F$66,3, FALSE) -> L'âge d'ouverture du droit à la retraite progressive est égal à 60 ans. | BA16: RPR_C_001 | BB16: =VLOOKUP(BA16,'Axe 2 Règles de gestion'!$D$2:$F$66,3, FALSE) -> La date de début de la retraite progressive doit être postérieure ou égale à la date d'entrée dans la FPE ou dans la carrière militaire. | BC16: RPR_C_004 | BD16: =VLOOKUP(BC16,'Axe 2 Règles de gestion'!$D$2:$F$66,3, FALSE) -> La date de début de la retraite progressive doit être postérieure ou égale à la date de début du lien juridique. | BE16: RPR_C_002 | BF16: =VLOOKUP(BE16,'Axe 2 Règles de gestion'!$D$2:$F$66,3, FALSE) -> La date de début de la retraite progressive doit être antérieure ou égale à la date de fin de la retraite progressive. | BG16: RPR_C_003 | BH16: =VLOOKUP(BG16,'Axe 2 Règles de gestion'!$D$2:$F$66,3, FALSE) -> La date de fin de la retraite progressive doit être antérieure à la date limite de départ à la retraite. | BI16: RPR_C_005 | BJ16: =VLOOKUP(BI16,'Axe 2 Règles de gestion'!$D$2:$F$66,3, FALSE) -> La date de fin de la retraite progressive doit être antérieure ou égale à la date de fin du lien juridique.
A17: 24.10.00 | B17: A | C17: 45623.564 | D17: D0017 | E17: Retraite progressive | F17: S0182 | G17: Retraite progressive | H17: E0969 | I17: Retraite progressive | J17: La date de début retraite progressive saisie est différente de vide | K17: A_RPR_DDRPRO [Saisi] <> VIDE | L17: T2355 | M17: Retraite progressive - Modification / Fin | N17: Modification | Q17: Ouvrier d'état | R17: P0005 | S17: O | T17: Général | U17: Passant | V17: 45170 | X17: RPR_I_031 ET RPR_I_032 ET RPR_I_028 ET RPR_I_029 ET RPR_I_030 ET RPR_D_003 ET RPR_C_002 ET RPR_C_003 ET RPR_C_005 | Y17: RPR_I_031 | Z17: =VLOOKUP(Y17,'Axe 2 Règles de gestion'!$D$2:$F$66,3, FALSE) -> Dans certains cas, la retraite progressive peut être suspendue. | AA17: RPR_I_032 | AB17: =VLOOKUP(AA17,'Axe 2 Règles de gestion'!$D$2:$F$66,3, FALSE) -> La suspension prend effet le 1er jour du mois suivant celui au cours duquel les conditions cessent d'être réunies ou le 1er jour du mois quand la suspension prend effet ce même jour. | AC17: RPR_I_028 | AD17: =VLOOKUP(AC17,'Axe 2 Règles de gestion'!$D$2:$F$66,3, FALSE) -> Si l'agent reprend une activité professionnelle à temps plein alors la retraite progressive cesse définitivement le 1er jour du mois suivant. | AE17: RPR_I_029 | AF17: =VLOOKUP(AE17,'Axe 2 Règles de gestion'!$D$2:$F$66,3, FALSE) -> Toutefois, si cette reprise intervient le 1er jour du mois, alors la cessation de la retraite progressive prend effet ce même jour. | AG17: RPR_I_030 | AH17: =VLOOKUP(AG17,'Axe 2 Règles de gestion'!$D$2:$F$66,3, FALSE) -> Si l'agent demande sa retraite à taux plein, alors la retraite progressive cesse définitivement à la date de prise d'effet de la pension complète. | AW17: RPR_D_003 | AX17: =VLOOKUP(AW17,'Axe 2 Règles de gestion'!$D$2:$F$66,3, FALSE) -> L'agent doit bénéficier d'une autorisation de temps partiel : temps partiel sur autorisation, de droit pour soins à conjoint, enfant, ascendant, de droit à l'occasion d'une naissance ou d'une adoption, de droit au profit des travailleurs handicapés. | BA17: RPR_C_002 | BB17: =VLOOKUP(BA17,'Axe 2 Règles de gestion'!$D$2:$F$66,3, FALSE) -> La date de début de la retraite progressive doit être antérieure ou égale à la date de fin de la retraite progressive. | BC17: RPR_C_003 | BD17: =VLOOKUP(BC17,'Axe 2 Règles de gestion'!$D$2:$F$66,3, FALSE) -> La date de fin de la retraite progressive doit être antérieure à la date limite de départ à la retraite. | BE17: RPR_C_005 | BF17: =VLOOKUP(BE17,'Axe 2 Règles de gestion'!$D$2:$F$66,3, FALSE) -> La date de fin de la retraite progressive doit être antérieure ou égale à la date de fin du lien juridique.

Sheet Axe 1 Enchaînement RG Impact
A1: Version | B1: Type de mise à jour | C1: Date de mise à jour | D1: Identifiant Domaine | E1: Libellé du Domaine | F1: Identifiant Sous-domaine | G1: Libellé du Sous-domaine | H1: Identifiant Evénement | I1: Libellé de l'évènement | J1: Libellé condition déclenchement Evènement | K1: Condition déclenchement Evènement | L1: Identifiant type d'évènement | M1: Libellé type d'évènement | N1: Type de mise à jour | O1: Libellé condition déclenchement Type Evènement | P1: Condition déclenchement Type Evènement | Q1: Libellé Population | R1: Codification Population | S1: Typologie de population | T1: Général / Particulier | U1: Passant / Exclu | V1: Date de début | W1: Date de fin | X1: Impacts | Y1: Identifiant Impacts 1 | Z1: Libellé Impacts 1 | AA1: Identifiant Impacts 2 | AB1: Libellé Impacts 2 | AC1: FIME | AD1: Statut de travail
A2: 25.10.00 | B2: M | C2: 45915.456 | D2: D0017 | E2: Retraite progressive | F2: S0182 | G2: Retraite progressive | H2: E0969 | I2: Retraite progressive | J2: La date de début retraite progressive saisie est différente de vide | K2: A_RPR_DDRPRO [Saisi] <> VIDE | L2: T2354 | M2: Retraite progressive - Demande | N2: Création | Q2: Titulaire ou magistrat | R2: P0001 | S2: T | T2: Général | U2: Passant | V2: 45170 | W2: 45900 | X2: RPR_P_001 ET RPR_P_002 | Y2: RPR_P_001 | Z2: =VLOOKUP(Y2,'Axe 2 Règles de gestion'!$D$2:$F$66,3, FALSE) -> Pension : La fraction de pension de retraite versée à l'agent est égale à la différence entre 100 % et la quotité de travail à temps partiel. | AA2: RPR_P_002 | AB2: =VLOOKUP(AA2,'Axe 2 Règles de gestion'!$D$2:$F$66,3, FALSE) -> Retraite : L'agent continue de cotiser à la retraite.
A3: 25.10.00 | B3: A | C3: 45915.461 | D3: D0017 | E3: Retraite progressive | F3: S0182 | G3: Retraite progressive | H3: E0969 | I3: Retraite progressive | J3: La date de début retraite progressive saisie est différente de vide | K3: A_RPR_DDRPRO [Saisi] <> VIDE | L3: T2354 | M3: Retraite progressive - Demande | N3: Création | Q3: Titulaire ou magistrat | R3: P0001 | S3: T | T3: Général | U3: Passant | V3: 45901 | X3: RPR_P_001 ET RPR_P_002 | Y3: RPR_P_001 | Z3: =VLOOKUP(Y3,'Axe 2 Règles de gestion'!$D$2:$F$66,3, FALSE) -> Pension : La fraction de pension de retraite versée à l'agent est égale à la différence entre 100 % et la quotité de travail à temps partiel. | AA3: RPR_P_002 | AB3: =VLOOKUP(AA3,'Axe 2 Règles de gestion'!$D$2:$F$66,3, FALSE) -> Retraite : L'agent continue de cotiser à la retraite.
A4: 24.10.00 | B4: A | C4: 45622.508 | D4: D0017 | E4: Retraite progressive | F4: S0182 | G4: Retraite progressive | H4: E0969 | I4: Retraite progressive | J4: La date de début retraite progressive saisie est différente de vide | K4: A_RPR_DDRPRO [Saisi] <> VIDE | L4: T2355 | M4: Retraite progressive - Modification / Fin | N4: Modification | Q4: Titulaire ou magistrat | R4: P0001 | S4: T | T4: Général | U4: Passant | V4: 45170
A5: 24.10.00 | B5: A | C5: 45622.508 | D5: D0017 | E5: Retraite progressive | F5: S0182 | G5: Retraite progressive | H5: E0969 | I5: Retraite progressive | J5: La date de début retraite progressive saisie est différente de vide | K5: A_RPR_DDRPRO [Saisi] <> VIDE | L5: T2354 | M5: Retraite progressive - Demande | N5: Création | Q5: Militaire | R5: P0002 | S5: M | T5: Général | U5: Exclu | V5: 45170
A6: 24.10.00 | B6: A | C6: 45622.508 | D6: D0017 | E6: Retraite progressive | F6: S0182 | G6: Retraite progressive | H6: E0969 | I6: Retraite progressive | J6: La date de début retraite progressive saisie est différente de vide | K6: A_RPR_DDRPRO [Saisi] <> VIDE | L6: T2355 | M6: Retraite progressive - Modification / Fin | N6: Modification | Q6: Militaire | R6: P0002 | S6: M | T6: Général | U6: Exclu | V6: 45170
A7: 25.00.00 | B7: M | C7: 45779.49 | D7: D0017 | E7: Retraite progressive | F7: S0182 | G7: Retraite progressive | H7: E0969 | I7: Retraite progressive | J7: La date de début retraite progressive saisie est différente de vide | K7: A_RPR_DDRPRO [Saisi] <> VIDE | L7: T2354 | M7: Retraite progressive - Demande | N7: Création | Q7: Contractuel | R7: P0003 | S7: N | T7: Général | U7: Passant | V7: 45170 | W7: 45709 | X7: RPR_P_004 | Y7: RPR_P_004 | Z7: =VLOOKUP(Y7,'Axe 2 Règles de gestion'!$D$2:$F$66,3, FALSE) -> Pension : La fraction de pension de retraite versée à l'agent est égale à la différence entre 100 % et la quotité de travail à temps partiel.
A8: 25.10.00 | B8: M | C8: 45915.46 | D8: D0017 | E8: Retraite progressive | F8: S0182 | G8: Retraite progressive | H8: E0969 | I8: Retraite progressive | J8: La date de début retraite progressive saisie est différente de vide | K8: A_RPR_DDRPRO [Saisi] <> VIDE | L8: T2354 | M8: Retraite progressive - Demande | N8: Création | Q8: Contractuel | R8: P0003 | S8: N | T8: Général | U8: Passant | V8: 45710 | W8: 45900 | X8: RPR_P_004 | Y8: RPR_P_004 | Z8: =VLOOKUP(Y8,'Axe 2 Règles de gestion'!$D$2:$F$66,3, FALSE) -> Pension : La fraction de pension de retraite versée à l'agent est égale à la différence entre 100 % et la quotité de travail à temps partiel.
A9: 25.10.00 | B9: A | C9: 45915.46 | D9: D0017 | E9: Retraite progressive | F9: S0182 | G9: Retraite progressive | H9: E0969 | I9: Retraite progressive | J9: La date de début retraite progressive saisie est différente de vide | K9: A_RPR_DDRPRO [Saisi] <> VIDE | L9: T2354 | M9: Retraite progressive - Demande | N9: Création | Q9: Contractuel | R9: P0003 | S9: N | T9: Général | U9: Passant | V9: 45901 | X9: RPR_P_004 | Y9: RPR_P_004 | Z9: =VLOOKUP(Y9,'Axe 2 Règles de gestion'!$D$2:$F$66,3, FALSE) -> Pension : La fraction de pension de retraite versée à l'agent est égale à la différence entre 100 % et la quotité de travail à temps partiel.
A10: 24.10.00 | B10: A | C10: 45623.564 | D10: D0017 | E10: Retraite progressive | F10: S0182 | G10: Retraite progressive | H10: E0969 | I10: Retraite progressive | J10: La date de début retraite progressive saisie est différente de vide | K10: A_RPR_DDRPRO [Saisi] <> VIDE | L10: T2355 | M10: Retraite progressive - Modification / Fin | N10: Modification | Q10: Contractuel | R10: P0003 | S10: N | T10: Général | U10: Passant | V10: 45170
A11: 25.10.00 | B11: M | C11: 45915.457 | D11: D0017 | E11: Retraite progressive | F11: S0182 | G11: Retraite progressive | H11: E0969 | I11: Retraite progressive | J11: La date de début retraite progressive saisie est différente de vide | K11: A_RPR_DDRPRO [Saisi] <> VIDE | L11: T2354 | M11: Retraite progressive - Demande | N11: Création | Q11: Stagiaire ou auditeur ou élève | R11: P0004 | S11: S | T11: Général | U11: Passant | V11: 45170 | W11: 45900 | X11: RPR_P_001 ET RPR_P_002 | Y11: RPR_P_001 | Z11: =VLOOKUP(Y11,'Axe 2 Règles de gestion'!$D$2:$F$66,3, FALSE) -> Pension : La fraction de pension de retraite versée à l'agent est égale à la différence entre 100 % et la quotité de travail à temps partiel. | AA11: RPR_P_002 | AB11: =VLOOKUP(AA11,'Axe 2 Règles de gestion'!$D$2:$F$66,3, FALSE) -> Retraite : L'agent continue de cotiser à la retraite.
